ts_recv,ts_event,rtype,publisher_id,instrument_id,action,side,depth,price,size,flags,ts_in_delta,sequence,bid_px_00,ask_px_00,bid_sz_00,ask_sz_00,bid_ct_00,ask_ct_00,bid_px_01,ask_px_01,bid_sz_01,ask_sz_01,bid_ct_01,ask_ct_01,bid_px_02,ask_px_02,bid_sz_02,ask_sz_02,bid_ct_02,ask_ct_02,bid_px_03,ask_px_03,bid_sz_03,ask_sz_03,bid_ct_03,ask_ct_03,bid_px_04,ask_px_04,bid_sz_04,ask_sz_04,bid_ct_04,ask_ct_04,bid_px_05,ask_px_05,bid_sz_05,ask_sz_05,bid_ct_05,ask_ct_05,bid_px_06,ask_px_06,bid_sz_06,ask_sz_06,bid_ct_06,ask_ct_06,bid_px_07,ask_px_07,bid_sz_07,ask_sz_07,bid_ct_07,ask_ct_07,bid_px_08,ask_px_08,bid_sz_08,ask_sz_08,bid_ct_08,ask_ct_08,bid_px_09,ask_px_09,bid_sz_09,ask_sz_09,bid_ct_09,ask_ct_09,symbol,best_level_ofi,ofi_00,ofi_01,ofi_02,ofi_03,ofi_04,ofi_05,ofi_06,ofi_07,ofi_08,ofi_09,integrated_ofi,cross_asset_ofi
2024-10-21T12:08:39.069902920Z,2024-10-21T12:08:39.069736562Z,10,2,38,A,B,0,233.75,200,130,166358,12160501,233.75,233.94,229,94,2,1,233.7,233.98,1200,44,1,3,233.66,234.0,1,154,1,7,233.58,234.06,505,400,2,1,233.53,234.07,10,29,1,1,233.45,234.13,15,400,1,1,233.4,234.17,110,1,2,1,233.39,234.25,10,50,1,1,233.31,234.41,110,600,2,2,233.3,234.43,100,5,1,1,AAPL,200.0,200.0,-200.0,-1200.0,-1.0,-505.0,-10.0,-15.0,-110.0,-10.0,-110.0,-212.3574690749579,
2024-10-21T12:08:39.162940859Z,2024-10-21T12:08:39.162773976Z,10,2,38,A,B,0,233.76,200,130,166883,12160573,233.76,233.94,200,94,1,1,233.75,233.98,29,44,1,3,233.7,234.0,1200,154,1,7,233.66,234.06,1,400,1,1,233.58,234.07,505,29,2,1,233.53,234.13,10,400,1,1,233.45,234.17,15,1,1,1,233.4,234.25,110,50,2,1,233.39,234.41,10,600,1,2,233.31,234.43,110,5,2,1,AAPL,200.0,200.0,29.0,1200.0,1.0,505.0,10.0,15.0,110.0,10.0,110.0,209.4655382896712,
2024-10-21T12:08:41.638694239Z,2024-10-21T12:08:41.638527966Z,10,2,38,A,B,0,233.77,200,130,166273,12161762,233.77,233.94,200,94,1,1,233.75,233.98,29,44,1,3,233.7,234.0,1200,154,1,7,233.66,234.06,1,400,1,1,233.58,234.07,505,29,2,1,233.53,234.13,10,400,1,1,233.45,234.17,15,1,1,1,233.4,234.25,110,50,2,1,233.39,234.41,10,600,1,2,233.31,234.43,110,5,2,1,AAPL,200.0,200.0,0.0,0.0,0.0,0.0,0.0,0.0,0.0,0.0,0.0,3.9761165292250036,
2024-10-21T12:08:41.645478168Z,2024-10-21T12:08:41.645312053Z,10,2,38,A,B,1,233.76,28,130,166115,12161778,233.77,233.94,200,94,1,1,233.76,233.98,28,44,1,3,233.75,234.0,29,154,1,7,233.7,234.06,1200,400,1,1,233.66,234.07,1,29,1,1,233.58,234.13,505,400,2,1,233.53,234.17,10,1,1,1,233.45,234.25,15,50,1,1,233.4,234.41,110,600,2,2,233.39,234.43,10,5,1,1,AAPL,0.0,0.0,28.0,29.0,1200.0,1.0,505.0,10.0,15.0,110.0,10.0,331.4650060971712,
2024-10-21T12:08:41.701463079Z,2024-10-21T12:08:41.701297052Z,10,2,38,C,B,1,233.76,28,130,166027,12161796,233.77,233.94,200,94,1,1,233.75,233.98,29,44,1,3,233.7,234.0,1200,154,1,7,233.66,234.06,1,400,1,1,233.58,234.07,505,29,2,1,233.53,234.13,10,400,1,1,233.45,234.17,15,1,1,1,233.4,234.25,110,50,2,1,233.39,234.41,10,600,1,2,233.31,234.43,110,5,2,1,AAPL,0.0,0.0,-28.0,-29.0,-1200.0,-1.0,-505.0,-10.0,-15.0,-110.0,-10.0,-331.4650060971712,
2024-10-21T12:08:41.701486252Z,2024-10-21T12:08:41.701320255Z,10,2,38,C,B,1,233.75,29,130,165997,12161797,233.77,233.94,200,94,1,1,233.7,233.98,1200,44,1,3,233.66,234.0,1,154,1,7,233.58,234.06,505,400,2,1,233.53,234.07,10,29,1,1,233.45,234.13,15,400,1,1,233.4,234.17,110,1,2,1,233.39,234.25,10,50,1,1,233.31,234.41,110,600,2,2,233.3,234.43,100,5,1,1,AAPL,0.0,0.0,-29.0,-1200.0,-1.0,-505.0,-10.0,-15.0,-110.0,-10.0,-110.0,-205.48942176044622,
2024-10-21T12:08:41.701557283Z,2024-10-21T12:08:41.701391064Z,10,2,38,A,B,1,233.76,30,130,166219,12161798,233.77,233.94,200,94,1,1,233.76,233.98,30,44,1,3,233.7,234.0,1200,154,1,7,233.66,234.06,1,400,1,1,233.58,234.07,505,29,2,1,233.53,234.13,10,400,1,1,233.45,234.17,15,1,1,1,233.4,234.25,110,50,2,1,233.39,234.41,10,600,1,2,233.31,234.43,110,5,2,1,AAPL,0.0,0.0,30.0,1200.0,1.0,505.0,10.0,15.0,110.0,10.0,110.0,205.5528379232751,
2024-10-21T12:08:44.045945399Z,2024-10-21T12:08:44.045776235Z,10,2,38,T,B,0,233.94,94,0,169164,12162738,233.77,233.94,200,94,1,1,233.76,233.98,30,44,1,3,233.7,234.0,1200,154,1,7,233.66,234.06,1,400,1,1,233.58,234.07,505,29,2,1,233.53,234.13,10,400,1,1,233.45,234.17,15,1,1,1,233.4,234.25,110,50,2,1,233.39,234.41,10,600,1,2,233.31,234.43,110,5,2,1,AAPL,0.0,0.0,0.0,0.0,0.0,0.0,0.0,0.0,0.0,0.0,0.0,0.0,
2024-10-21T12:08:44.045945399Z,2024-10-21T12:08:44.045776717Z,10,2,38,T,N,0,233.94,94,130,168682,12162739,233.77,233.98,200,44,1,3,233.76,234.0,30,154,1,7,233.7,234.06,1200,400,1,1,233.66,234.07,1,29,1,1,233.58,234.13,505,400,2,1,233.53,234.17,10,1,1,1,233.45,234.25,15,50,1,1,233.4,234.41,110,600,2,2,233.39,234.43,10,5,1,1,233.31,234.5,110,63,2,4,AAPL,44.0,44.0,154.0,400.0,29.0,400.0,1.0,50.0,600.0,5.0,63.0,175.4048188588441,
2024-10-21T12:08:44.045968264Z,2024-10-21T12:08:44.045799937Z,10,2,38,A,B,0,233.86,100,130,168327,12162740,233.86,233.98,100,44,1,3,233.77,234.0,200,154,1,7,233.76,234.06,30,400,1,1,233.7,234.07,1200,29,1,1,233.66,234.13,1,400,1,1,233.58,234.17,505,1,2,1,233.53,234.25,10,50,1,1,233.45,234.41,15,600,1,2,233.4,234.43,110,5,2,1,233.39,234.5,10,63,1,4,AAPL,100.0,100.0,200.0,30.0,1200.0,1.0,505.0,10.0,15.0,110.0,10.0,344.4622269490853,
2024-10-21T12:08:44.045981222Z,2024-10-21T12:08:44.045814276Z,10,2,38,A,B,1,233.81,100,130,166946,12162742,233.86,233.98,100,44,1,3,233.81,234.0,100,154,1,7,233.77,234.06,200,400,1,1,233.76,234.07,30,29,1,1,233.7,234.13,1200,400,1,1,233.66,234.17,1,1,1,1,233.58,234.25,505,50,2,1,233.53,234.41,10,600,1,2,233.45,234.43,15,5,1,1,233.4,234.5,110,63,2,4,AAPL,0.0,0.0,100.0,200.0,30.0,1200.0,1.0,505.0,10.0,15.0,110.0,240.05371905915376,
2024-10-21T12:08:44.045992597Z,2024-10-21T12:08:44.045826034Z,10,2,38,C,B,0,233.86,100,130,166563,12162744,233.85,233.98,57,44,1,3,233.81,234.0,100,154,1,7,233.77,234.06,200,400,1,1,233.76,234.07,30,29,1,1,233.7,234.13,1200,400,1,1,233.66,234.17,1,1,1,1,233.58,234.25,505,50,2,1,233.53,234.41,10,600,1,2,233.45,234.43,15,5,1,1,233.4,234.5,110,63,2,4,AAPL,-100.0,-100.0,0.0,0.0,0.0,0.0,0.0,0.0,0.0,0.0,0.0,-1.9880582646125018,
2024-10-21T12:08:44.046005890Z,2024-10-21T12:08:44.045839714Z,10,2,38,A,B,1,233.8,57,130,166176,12162746,233.85,233.98,57,44,1,3,233.8,234.0,57,154,1,7,233.77,234.06,200,400,1,1,233.76,234.07,30,29,1,1,233.7,234.13,1200,400,1,1,233.66,234.17,1,1,1,1,233.58,234.25,505,50,2,1,233.53,234.41,10,600,1,2,233.45,234.43,15,5,1,1,233.4,234.5,110,63,2,4,AAPL,0.0,0.0,-100.0,0.0,0.0,0.0,0.0,0.0,0.0,0.0,0.0,-6.3416162828869584,
2024-10-21T12:08:44.046241847Z,2024-10-21T12:08:44.046075488Z,10,2,38,A,B,0,233.88,100,130,166359,12162751,233.88,233.98,100,44,1,3,233.85,234.0,57,154,1,7,233.8,234.06,57,400,1,1,233.77,234.07,200,29,1,1,233.76,234.13,30,400,1,1,233.7,234.17,1200,1,1,1,233.66,234.25,1,50,1,1,233.58,234.41,505,600,2,2,233.53,234.43,10,5,1,1,233.45,234.5,15,63,1,4,AAPL,100.0,100.0,57.0,57.0,200.0,30.0,1200.0,1.0,505.0,10.0,15.0,274.31992092865306,
2024-10-21T12:08:44.046743441Z,2024-10-21T12:08:44.046577511Z,10,2,38,C,B,0,233.88,100,130,165930,12162753,233.85,233.98,57,44,1,3,233.8,234.0,57,154,1,7,233.77,234.06,200,400,1,1,233.76,234.07,30,29,1,1,233.7,234.13,1200,400,1,1,233.66,234.17,1,1,1,1,233.58,234.25,505,50,2,1,233.53,234.41,10,600,1,2,233.45,234.43,15,5,1,1,233.4,234.5,110,63,2,4,AAPL,-100.0,-100.0,-57.0,-57.0,-200.0,-30.0,-1200.0,-1.0,-505.0,-10.0,-15.0,-274.31992092865306,
2024-10-21T12:08:44.062866261Z,2024-10-21T12:08:44.062697315Z,10,2,38,T,N,0,233.94,44,130,168946,12162795,233.85,233.98,57,44,1,3,233.8,234.0,57,154,1,7,233.77,234.06,200,400,1,1,233.76,234.07,30,29,1,1,233.7,234.13,1200,400,1,1,233.66,234.17,1,1,1,1,233.58,234.25,505,50,2,1,233.53,234.41,10,600,1,2,233.45,234.43,15,5,1,1,233.4,234.5,110,63,2,4,AAPL,0.0,0.0,0.0,0.0,0.0,0.0,0.0,0.0,0.0,0.0,0.0,0.0,
2024-10-21T12:08:44.062883209Z,2024-10-21T12:08:44.062714891Z,10,2,38,T,N,0,233.94,27,0,168318,12162796,233.85,233.98,57,44,1,3,233.8,234.0,57,154,1,7,233.77,234.06,200,400,1,1,233.76,234.07,30,29,1,1,233.7,234.13,1200,400,1,1,233.66,234.17,1,1,1,1,233.58,234.25,505,50,2,1,233.53,234.41,10,600,1,2,233.45,234.43,15,5,1,1,233.4,234.5,110,63,2,4,AAPL,0.0,0.0,0.0,0.0,0.0,0.0,0.0,0.0,0.0,0.0,0.0,0.0,
2024-10-21T12:08:44.062883209Z,2024-10-21T12:08:44.062714891Z,10,2,38,T,N,0,233.95,17,130,168318,12162797,233.85,233.98,57,44,1,3,233.8,234.0,57,154,1,7,233.77,234.06,200,400,1,1,233.76,234.07,30,29,1,1,233.7,234.13,1200,400,1,1,233.66,234.17,1,1,1,1,233.58,234.25,505,50,2,1,233.53,234.41,10,600,1,2,233.45,234.43,15,5,1,1,233.4,234.5,110,63,2,4,AAPL,0.0,0.0,0.0,0.0,0.0,0.0,0.0,0.0,0.0,0.0,0.0,0.0,
2024-10-21T12:08:44.071158229Z,2024-10-21T12:08:44.070991133Z,10,2,38,T,N,0,233.95,37,130,167096,12162801,233.85,233.98,57,44,1,3,233.8,234.0,57,154,1,7,233.77,234.06,200,400,1,1,233.76,234.07,30,29,1,1,233.7,234.13,1200,400,1,1,233.66,234.17,1,1,1,1,233.58,234.25,505,50,2,1,233.53,234.41,10,600,1,2,233.45,234.43,15,5,1,1,233.4,234.5,110,63,2,4,AAPL,0.0,0.0,0.0,0.0,0.0,0.0,0.0,0.0,0.0,0.0,0.0,0.0,
2024-10-21T12:08:44.071167823Z,2024-10-21T12:08:44.071001755Z,10,2,38,A,B,0,233.89,100,130,166068,12162802,233.89,233.98,100,44,1,3,233.85,234.0,57,154,1,7,233.8,234.06,57,400,1,1,233.77,234.07,200,29,1,1,233.76,234.13,30,400,1,1,233.7,234.17,1200,1,1,1,233.66,234.25,1,50,1,1,233.58,234.41,505,600,2,2,233.53,234.43,10,5,1,1,233.45,234.5,15,63,1,4,AAPL,100.0,100.0,57.0,57.0,200.0,30.0,1200.0,1.0,505.0,10.0,15.0,274.31992092865306,
2024-10-21T12:08:44.071413124Z,2024-10-21T12:08:44.071247115Z,10,2,38,C,B,0,233.89,100,130,166009,12162803,233.85,233.98,57,44,1,3,233.8,234.0,57,154,1,7,233.77,234.06,200,400,1,1,233.76,234.07,30,29,1,1,233.7,234.13,1200,400,1,1,233.66,234.17,1,1,1,1,233.58,234.25,505,50,2,1,233.53,234.41,10,600,1,2,233.45,234.43,15,5,1,1,233.4,234.5,110,63,2,4,AAPL,-100.0,-100.0,-57.0,-57.0,-200.0,-30.0,-1200.0,-1.0,-505.0,-10.0,-15.0,-274.31992092865306,
2024-10-21T12:08:44.078888724Z,2024-10-21T12:08:44.078717275Z,10,2,38,C,A,0,233.98,31,130,171449,12162808,233.85,234.0,57,154,1,7,233.8,234.06,57,400,1,1,233.77,234.07,200,29,1,1,233.76,234.13,30,400,1,1,233.7,234.17,1200,1,1,1,233.66,234.25,1,50,1,1,233.58,234.41,505,600,2,2,233.53,234.43,10,5,1,1,233.45,234.5,15,63,1,4,233.4,234.75,110,1,2,1,AAPL,154.0,154.0,400.0,29.0,400.0,1.0,50.0,600.0,5.0,63.0,1.0,193.75448865616744,
2024-10-21T12:08:44.078888724Z,2024-10-21T12:08:44.078717275Z,10,2,38,T,B,0,233.98,9,0,171449,12162807,233.85,233.98,57,40,1,2,233.8,234.0,57,154,1,7,233.77,234.06,200,400,1,1,233.76,234.07,30,29,1,1,233.7,234.13,1200,400,1,1,233.66,234.17,1,1,1,1,233.58,234.25,505,50,2,1,233.53,234.41,10,600,1,2,233.45,234.43,15,5,1,1,233.4,234.5,110,63,2,4,AAPL,-154.0,-154.0,-400.0,-29.0,-400.0,-1.0,-50.0,-600.0,-5.0,-63.0,-1.0,-193.75448865616744,
2024-10-21T12:08:44.078888724Z,2024-10-21T12:08:44.078717275Z,10,2,38,T,B,0,233.98,31,130,171449,12162808,233.85,233.98,57,31,1,1,233.8,234.0,57,154,1,7,233.77,234.06,200,400,1,1,233.76,234.07,30,29,1,1,233.7,234.13,1200,400,1,1,233.66,234.17,1,1,1,1,233.58,234.25,505,50,2,1,233.53,234.41,10,600,1,2,233.45,234.43,15,5,1,1,233.4,234.5,110,63,2,4,AAPL,9.0,9.0,0.0,0.0,0.0,0.0,0.0,0.0,0.0,0.0,0.0,0.17892524381512517,
2024-10-21T12:08:44.078888724Z,2024-10-21T12:08:44.078717275Z,10,2,38,T,N,0,233.96,10,0,171449,12162805,233.85,233.98,57,44,1,3,233.8,234.0,57,154,1,7,233.77,234.06,200,400,1,1,233.76,234.07,30,29,1,1,233.7,234.13,1200,400,1,1,233.66,234.17,1,1,1,1,233.58,234.25,505,50,2,1,233.53,234.41,10,600,1,2,233.45,234.43,15,5,1,1,233.4,234.5,110,63,2,4,AAPL,-13.0,-13.0,0.0,0.0,0.0,0.0,0.0,0.0,0.0,0.0,0.0,-0.25844757439962524,
2024-10-21T12:08:44.078888724Z,2024-10-21T12:08:44.078717275Z,10,2,38,T,B,0,233.98,4,0,171449,12162806,233.85,233.98,57,44,1,3,233.8,234.0,57,154,1,7,233.77,234.06,200,400,1,1,233.76,234.07,30,29,1,1,233.7,234.13,1200,400,1,1,233.66,234.17,1,1,1,1,233.58,234.25,505,50,2,1,233.53,234.41,10,600,1,2,233.45,234.43,15,5,1,1,233.4,234.5,110,63,2,4,AAPL,0.0,0.0,0.0,0.0,0.0,0.0,0.0,0.0,0.0,0.0,0.0,0.0,
2024-10-21T12:08:44.078888724Z,2024-10-21T12:08:44.078717275Z,10,2,38,T,N,0,233.95,46,0,171449,12162804,233.85,233.98,57,44,1,3,233.8,234.0,57,154,1,7,233.77,234.06,200,400,1,1,233.76,234.07,30,29,1,1,233.7,234.13,1200,400,1,1,233.66,234.17,1,1,1,1,233.58,234.25,505,50,2,1,233.53,234.41,10,600,1,2,233.45,234.43,15,5,1,1,233.4,234.5,110,63,2,4,AAPL,0.0,0.0,0.0,0.0,0.0,0.0,0.0,0.0,0.0,0.0,0.0,0.0,
2024-10-21T12:08:44.078913355Z,2024-10-21T12:08:44.078746374Z,10,2,38,A,B,0,233.92,100,130,166981,12162809,233.92,234.0,100,154,1,7,233.85,234.06,57,400,1,1,233.8,234.07,57,29,1,1,233.77,234.13,200,400,1,1,233.76,234.17,30,1,1,1,233.7,234.25,1200,50,1,1,233.66,234.41,1,600,1,2,233.58,234.43,505,5,2,1,233.53,234.5,10,63,1,4,233.45,234.75,15,1,1,1,AAPL,254.0,254.0,457.0,86.0,600.0,31.0,1250.0,601.0,510.0,73.0,16.0,468.0744095848205,
2024-10-21T12:08:44.078924745Z,2024-10-21T12:08:44.078758339Z,10,2,38,A,B,1,233.91,57,130,166406,12162811,233.92,234.0,100,154,1,7,233.91,234.06,57,400,1,1,233.88,234.07,100,29,1,1,233.85,234.13,57,400,1,1,233.8,234.17,57,1,1,1,233.77,234.25,200,50,1,1,233.76,234.41,30,600,1,2,233.7,234.43,1200,5,1,1,233.66,234.5,1,63,1,4,233.58,234.75,505,1,2,1,AAPL,0.0,0.0,57.0,100.0,57.0,57.0,200.0,30.0,1200.0,1.0,505.0,220.9300263742702,
2024-10-21T12:08:44.078926114Z,2024-10-21T12:08:44.078760028Z,10,2,38,A,B,2,233.88,100,130,166086,12162812,233.92,234.0,100,154,1,7,233.91,234.06,57,400,1,1,233.88,234.07,200,29,2,1,233.85,234.13,57,400,1,1,233.8,234.17,57,1,1,1,233.77,234.25,200,50,1,1,233.76,234.41,30,600,1,2,233.7,234.43,1200,5,1,1,233.66,234.5,1,63,1,4,233.58,234.75,505,1,2,1,AAPL,0.0,0.0,0.0,100.0,0.0,0.0,0.0,0.0,0.0,0.0,0.0,10.15825807360052,
2024-10-21T12:08:44.078938721Z,2024-10-21T12:08:44.078772524Z,10,2,38,A,B,0,233.87,57,130,166197,12162814,233.91,234.0,57,154,1,7,233.88,234.06,200,400,2,1,233.87,234.07,57,29,1,1,233.85,234.13,57,400,1,1,233.8,234.17,57,1,1,1,233.77,234.25,200,50,1,1,233.76,234.41,30,600,1,2,233.7,234.43,1200,5,1,1,233.66,234.5,1,63,1,4,233.58,234.75,505,1,2,1,AAPL,-100.0,-100.0,-57.0,-200.0,0.0,0.0,0.0,0.0,0.0,0.0,0.0,-25.919295693059105,
2024-10-21T12:08:44.078950012Z,2024-10-21T12:08:44.078783923Z,10,2,38,C,B,1,233.88,100,130,166089,12162816,233.91,234.0,57,154,1,7,233.87,234.06,57,400,1,1,233.85,234.07,57,29,1,1,233.8,234.13,57,400,1,1,233.77,234.17,200,1,1,1,233.76,234.25,30,50,1,1,233.7,234.41,1200,600,1,2,233.66,234.43,1,5,1,1,233.58,234.5,505,63,2,4,233.53,234.75,10,1,1,1,AAPL,0.0,0.0,-200.0,-57.0,-57.0,-57.0,-200.0,-30.0,-1200.0,-1.0,-505.0,-225.63048668715032,
2024-10-21T12:08:44.115378536Z,2024-10-21T12:08:44.115212449Z,10,2,38,C,A,2,234.07,29,130,166087,12162846,233.91,234.0,57,154,1,7,233.87,234.06,57,400,1,1,233.85,234.13,57,400,1,1,233.8,234.17,57,1,1,1,233.77,234.25,200,50,1,1,233.76,234.41,30,600,1,2,233.7,234.43,1200,5,1,1,233.66,234.5,1,63,1,4,233.58,234.75,505,1,2,1,233.53,234.79,10,2000,1,1,AAPL,0.0,0.0,0.0,400.0,1.0,50.0,600.0,5.0,63.0,1.0,2000.0,278.3580237270519,
2024-10-21T12:08:44.115433457Z,2024-10-21T12:08:44.115267046Z,10,2,38,A,A,2,234.13,29,130,166411,12162847,233.91,234.0,57,154,1,7,233.87,234.06,57,400,1,1,233.85,234.13,57,429,1,2,233.8,234.17,57,1,1,1,233.77,234.25,200,50,1,1,233.76,234.41,30,600,1,2,233.7,234.43,1200,5,1,1,233.66,234.5,1,63,1,4,233.58,234.75,505,1,2,1,233.53,234.79,10,2000,1,1,AAPL,0.0,0.0,0.0,-29.0,0.0,0.0,0.0,0.0,0.0,0.0,0.0,-2.945894841344151,
2024-10-21T12:08:44.149362032Z,2024-10-21T12:08:44.149196088Z,10,2,38,C,B,3,233.8,57,130,165944,12162860,233.91,234.0,57,154,1,7,233.87,234.06,57,400,1,1,233.85,234.13,57,429,1,2,233.77,234.17,200,1,1,1,233.76,234.25,30,50,1,1,233.7,234.41,1200,600,1,2,233.66,234.43,1,5,1,1,233.58,234.5,505,63,2,4,233.53,234.75,10,1,1,1,233.45,234.79,15,2000,1,1,AAPL,0.0,0.0,0.0,0.0,-57.0,-200.0,-30.0,-1200.0,-1.0,-505.0,-10.0,-211.72144814498537,
2024-10-21T12:08:44.179575366Z,2024-10-21T12:08:44.179409160Z,10,2,38,C,B,1,233.87,57,130,166206,12162872,233.91,234.0,57,154,1,7,233.85,234.06,57,400,1,1,233.77,234.13,200,429,1,2,233.76,234.17,30,1,1,1,233.7,234.25,1200,50,1,1,233.66,234.41,1,600,1,2,233.58,234.43,505,5,2,1,233.53,234.5,10,63,1,4,233.45,234.75,15,1,1,1,233.4,234.79,110,2000,2,1,AAPL,0.0,0.0,-57.0,-57.0,-200.0,-30.0,-1200.0,-1.0,-505.0,-10.0,-15.0,-272.33186266404056,
2024-10-21T12:08:44.303932890Z,2024-10-21T12:08:44.303766562Z,10,2,38,C,B,1,233.85,57,130,166328,12162939,233.91,234.0,57,154,1,7,233.77,234.06,200,400,1,1,233.76,234.13,30,429,1,2,233.7,234.17,1200,1,1,1,233.66,234.25,1,50,1,1,233.58,234.41,505,600,2,2,233.53,234.43,10,5,1,1,233.45,234.5,15,63,1,4,233.4,234.75,110,1,2,1,233.39,234.79,10,2000,1,1,AAPL,0.0,0.0,-57.0,-200.0,-30.0,-1200.0,-1.0,-505.0,-10.0,-15.0,-110.0,-237.32682405751237,
2024-10-21T12:08:44.333929473Z,2024-10-21T12:08:44.333763421Z,10,2,38,C,B,0,233.91,57,130,166052,12162944,233.77,234.0,200,154,1,7,233.76,234.06,30,400,1,1,233.7,234.13,1200,429,1,2,233.66,234.17,1,1,1,1,233.58,234.25,505,50,2,1,233.53,234.41,10,600,1,2,233.45,234.43,15,5,1,1,233.4,234.5,110,63,2,4,233.39,234.75,10,1,1,1,233.31,234.79,110,2000,2,1,AAPL,-57.0,-57.0,-200.0,-30.0,-1200.0,-1.0,-505.0,-10.0,-15.0,-110.0,-10.0,-343.6073618953019,
2024-10-21T12:08:45.555160782Z,2024-10-21T12:08:45.554994588Z,10,2,38,A,A,6,234.43,100,130,166194,12163887,233.77,234.0,200,154,1,7,233.76,234.06,30,400,1,1,233.7,234.13,1200,429,1,2,233.66,234.17,1,1,1,1,233.58,234.25,505,50,2,1,233.53,234.41,10,600,1,2,233.45,234.43,15,105,1,2,233.4,234.5,110,63,2,4,233.39,234.75,10,1,1,1,233.31,234.79,110,2000,2,1,AAPL,0.0,0.0,0.0,0.0,0.0,0.0,0.0,-100.0,0.0,0.0,0.0,-11.400389497039825,
2024-10-21T12:08:46.627106793Z,2024-10-21T12:08:46.626940215Z,10,2,38,A,B,0,233.9,1,130,166578,12164437,233.9,234.0,1,154,1,7,233.77,234.06,200,400,1,1,233.76,234.13,30,429,1,2,233.7,234.17,1200,1,1,1,233.66,234.25,1,50,1,1,233.58,234.41,505,600,2,2,233.53,234.43,10,105,1,2,233.45,234.5,15,63,1,4,233.4,234.75,110,1,2,1,233.39,234.79,10,2000,1,1,AAPL,1.0,1.0,200.0,30.0,1200.0,1.0,505.0,10.0,15.0,110.0,10.0,342.4940492671189,
2024-10-21T12:08:56.736557653Z,2024-10-21T12:08:56.736391728Z,10,2,38,C,B,0,233.9,1,130,165925,12171166,233.77,234.0,200,154,1,7,233.76,234.06,30,400,1,1,233.7,234.13,1200,429,1,2,233.66,234.17,1,1,1,1,233.58,234.25,505,50,2,1,233.53,234.41,10,600,1,2,233.45,234.43,15,105,1,2,233.4,234.5,110,63,2,4,233.39,234.75,10,1,1,1,233.31,234.79,110,2000,2,1,AAPL,-1.0,-1.0,-200.0,-30.0,-1200.0,-1.0,-505.0,-10.0,-15.0,-110.0,-10.0,-342.4940492671189,
2024-10-21T12:09:01.138408018Z,2024-10-21T12:09:01.138241817Z,10,2,38,C,B,0,233.77,200,130,166201,12174514,233.76,234.0,30,154,1,7,233.7,234.06,1200,400,1,1,233.66,234.13,1,429,1,2,233.58,234.17,505,1,2,1,233.53,234.25,10,50,1,1,233.45,234.41,15,600,1,2,233.4,234.43,110,105,2,2,233.39,234.5,10,63,1,4,233.31,234.75,110,1,2,1,233.3,234.79,100,2000,1,1,AAPL,-200.0,-200.0,-30.0,-1200.0,-1.0,-505.0,-10.0,-15.0,-110.0,-10.0,-110.0,-209.5289544525001,
2024-10-21T12:09:01.138421298Z,2024-10-21T12:09:01.138255251Z,10,2,38,A,B,1,233.73,200,130,166047,12174515,233.76,234.0,30,154,1,7,233.73,234.06,200,400,1,1,233.7,234.13,1200,429,1,2,233.66,234.17,1,1,1,1,233.58,234.25,505,50,2,1,233.53,234.41,10,600,1,2,233.45,234.43,15,105,1,2,233.4,234.5,110,63,2,4,233.39,234.75,10,1,1,1,233.31,234.79,110,2000,2,1,AAPL,0.0,0.0,200.0,1200.0,1.0,505.0,10.0,15.0,110.0,10.0,110.0,216.3335856041829,
2024-10-21T12:09:01.157563262Z,2024-10-21T12:09:01.157397025Z,10,2,38,A,B,2,233.7,30,130,166237,12174545,233.76,234.0,30,154,1,7,233.73,234.06,200,400,1,1,233.7,234.13,1230,429,2,2,233.66,234.17,1,1,1,1,233.58,234.25,505,50,2,1,233.53,234.41,10,600,1,2,233.45,234.43,15,105,1,2,233.4,234.5,110,63,2,4,233.39,234.75,10,1,1,1,233.31,234.79,110,2000,2,1,AAPL,0.0,0.0,0.0,30.0,0.0,0.0,0.0,0.0,0.0,0.0,0.0,3.047477422080156,
2024-10-21T12:09:01.157592129Z,2024-10-21T12:09:01.157426276Z,10,2,38,C,B,0,233.76,30,130,165853,12174546,233.73,234.0,200,154,1,7,233.7,234.06,1230,400,2,1,233.66,234.13,1,429,1,2,233.58,234.17,505,1,2,1,233.53,234.25,10,50,1,1,233.45,234.41,15,600,1,2,233.4,234.43,110,105,2,2,233.39,234.5,10,63,1,4,233.31,234.75,110,1,2,1,233.3,234.79,100,2000,1,1,AAPL,-30.0,-30.0,-200.0,-1230.0,-1.0,-505.0,-10.0,-15.0,-110.0,-10.0,-110.0,-219.9774805056468,
2024-10-21T12:09:02.549604073Z,2024-10-21T12:09:02.549437699Z,10,2,38,A,A,1,234.05,400,130,166374,12175916,233.73,234.0,200,154,1,7,233.7,234.05,1230,400,2,1,233.66,234.13,1,429,1,2,233.58,234.17,505,1,2,1,233.53,234.25,10,50,1,1,233.45,234.41,15,600,1,2,233.4,234.43,110,105,2,2,233.39,234.5,10,63,1,4,233.31,234.75,110,1,2,1,233.3,234.79,100,2000,1,1,AAPL,0.0,0.0,-400.0,0.0,0.0,0.0,0.0,0.0,0.0,0.0,0.0,-25.366465131547834,
2024-10-21T12:09:02.576676374Z,2024-10-21T12:09:02.576510264Z,10,2,38,C,A,2,234.13,29,130,166110,12176238,233.73,234.0,200,154,1,7,233.7,234.05,1230,400,2,1,233.66,234.13,1,400,1,1,233.58,234.17,505,1,2,1,233.53,234.25,10,50,1,1,233.45,234.41,15,600,1,2,233.4,234.43,110,105,2,2,233.39,234.5,10,63,1,4,233.31,234.75,110,1,2,1,233.3,234.79,100,2000,1,1,AAPL,0.0,0.0,0.0,29.0,0.0,0.0,0.0,0.0,0.0,0.0,0.0,2.945894841344151,
2024-10-21T12:09:02.576729551Z,2024-10-21T12:09:02.576563332Z,10,2,38,A,A,2,234.12,29,130,166219,12176242,233.73,234.0,200,154,1,7,233.7,234.05,1230,400,2,1,233.66,234.12,1,29,1,1,233.58,234.13,505,400,2,1,233.53,234.17,10,1,1,1,233.45,234.25,15,50,1,1,233.4,234.41,110,600,2,2,233.39,234.43,10,105,1,2,233.31,234.5,110,63,2,4,233.3,234.75,100,1,1,1,AAPL,0.0,0.0,0.0,-400.0,-1.0,-50.0,-600.0,-105.0,-63.0,-1.0,-2000.0,-289.7584132240917,
2024-10-21T12:09:04.139010031Z,2024-10-21T12:09:04.138843955Z,10,2,38,C,B,1,233.7,30,130,166076,12177517,233.73,234.0,200,154,1,7,233.7,234.05,1200,400,1,1,233.66,234.12,1,29,1,1,233.58,234.13,505,400,2,1,233.53,234.17,10,1,1,1,233.45,234.25,15,50,1,1,233.4,234.41,110,600,2,2,233.39,234.43,10,105,1,2,233.31,234.5,110,63,2,4,233.3,234.75,100,1,1,1,AAPL,0.0,0.0,-30.0,0.0,0.0,0.0,0.0,0.0,0.0,0.0,0.0,-1.9024848848660874,
2024-10-21T12:09:04.139060689Z,2024-10-21T12:09:04.138894379Z,10,2,38,A,B,0,233.75,30,130,166310,12177518,233.75,234.0,30,154,1,7,233.73,234.05,200,400,1,1,233.7,234.12,1200,29,1,1,233.66,234.13,1,400,1,1,233.58,234.17,505,1,2,1,233.53,234.25,10,50,1,1,233.45,234.41,15,600,1,2,233.4,234.43,110,105,2,2,233.39,234.5,10,63,1,4,233.31,234.75,110,1,2,1,AAPL,30.0,30.0,200.0,1200.0,1.0,505.0,10.0,15.0,110.0,10.0,110.0,216.93000308356665,
2024-10-21T12:09:04.194772872Z,2024-10-21T12:09:04.194606283Z,10,2,38,A,B,0,233.81,200,130,166589,12177532,233.81,234.0,200,154,1,7,233.75,234.05,30,400,1,1,233.7,234.12,1200,29,1,1,233.66,234.13,1,400,1,1,233.58,234.17,505,1,2,1,233.53,234.25,10,50,1,1,233.45,234.41,15,600,1,2,233.4,234.43,110,105,2,2,233.39,234.5,10,63,1,4,233.31,234.75,110,1,2,1,AAPL,200.0,200.0,30.0,0.0,0.0,0.0,0.0,0.0,0.0,0.0,0.0,5.878601414091091,
2024-10-21T12:09:06.506770293Z,2024-10-21T12:09:06.506604143Z,10,2,38,C,B,1,233.75,30,130,166150,12179760,233.81,234.0,200,154,1,7,233.7,234.05,1200,400,1,1,233.66,234.12,1,29,1,1,233.58,234.13,505,400,2,1,233.53,234.17,10,1,1,1,233.45,234.25,15,50,1,1,233.4,234.41,110,600,2,2,233.39,234.43,10,105,1,2,233.31,234.5,110,63,2,4,233.3,234.75,100,1,1,1,AAPL,0.0,0.0,-30.0,-1200.0,-1.0,-505.0,-10.0,-15.0,-110.0,-10.0,-110.0,-205.5528379232751,
2024-10-21T12:09:06.565190241Z,2024-10-21T12:09:06.565023952Z,10,2,38,A,B,1,233.76,30,130,166289,12179817,233.81,234.0,200,154,1,7,233.76,234.05,30,400,1,1,233.7,234.12,1200,29,1,1,233.66,234.13,1,400,1,1,233.58,234.17,505,1,2,1,233.53,234.25,10,50,1,1,233.45,234.41,15,600,1,2,233.4,234.43,110,105,2,2,233.39,234.5,10,63,1,4,233.31,234.75,110,1,2,1,AAPL,0.0,0.0,30.0,1200.0,1.0,505.0,10.0,15.0,110.0,10.0,110.0,205.5528379232751,
2024-10-21T12:09:06.773559043Z,2024-10-21T12:09:06.773392628Z,10,2,38,A,B,0,233.82,200,130,166415,12180059,233.82,234.0,200,154,1,7,233.76,234.05,30,400,1,1,233.7,234.12,1200,29,1,1,233.66,234.13,1,400,1,1,233.58,234.17,505,1,2,1,233.53,234.25,10,50,1,1,233.45,234.41,15,600,1,2,233.4,234.43,110,105,2,2,233.39,234.5,10,63,1,4,233.31,234.75,110,1,2,1,AAPL,200.0,200.0,0.0,0.0,0.0,0.0,0.0,0.0,0.0,0.0,0.0,3.9761165292250036,
2024-10-21T12:09:10.542697180Z,2024-10-21T12:09:10.542530771Z,10,2,38,A,B,0,233.9,10,130,166409,12183116,233.9,234.0,10,154,1,7,233.82,234.05,200,400,1,1,233.76,234.12,30,29,1,1,233.7,234.13,1200,400,1,1,233.66,234.17,1,1,1,1,233.58,234.25,505,50,2,1,233.53,234.41,10,600,1,2,233.45,234.43,15,105,1,2,233.4,234.5,110,63,2,4,233.39,234.75,10,1,1,1,AAPL,10.0,10.0,200.0,30.0,1200.0,1.0,505.0,10.0,15.0,110.0,10.0,342.672974510934,
2024-10-21T12:09:12.689323526Z,2024-10-21T12:09:12.689157352Z,10,2,38,C,A,1,234.05,400,130,166174,12184428,233.9,234.0,10,154,1,7,233.82,234.12,200,29,1,1,233.76,234.13,30,400,1,1,233.7,234.17,1200,1,1,1,233.66,234.25,1,50,1,1,233.58,234.41,505,600,2,2,233.53,234.43,10,105,1,2,233.45,234.5,15,63,1,4,233.4,234.75,110,1,2,1,233.39,234.79,10,2000,1,1,AAPL,0.0,0.0,29.0,400.0,1.0,50.0,600.0,105.0,63.0,1.0,2000.0,291.59748194612894,
2024-10-21T12:09:12.689337452Z,2024-10-21T12:09:12.689170703Z,10,2,38,A,A,1,234.06,200,130,166749,12184429,233.9,234.0,10,154,1,7,233.82,234.06,200,200,1,1,233.76,234.12,30,29,1,1,233.7,234.13,1200,400,1,1,233.66,234.17,1,1,1,1,233.58,234.25,505,50,2,1,233.53,234.41,10,600,1,2,233.45,234.43,15,105,1,2,233.4,234.5,110,63,2,4,233.39,234.75,10,1,1,1,AAPL,0.0,0.0,-29.0,-400.0,-1.0,-50.0,-600.0,-105.0,-63.0,-1.0,-2000.0,-291.59748194612894,
2024-10-21T12:09:12.782742680Z,2024-10-21T12:09:12.782576498Z,10,2,38,A,A,1,234.06,200,130,166182,12184538,233.9,234.0,10,154,1,7,233.82,234.06,200,400,1,2,233.76,234.12,30,29,1,1,233.7,234.13,1200,400,1,1,233.66,234.17,1,1,1,1,233.58,234.25,505,50,2,1,233.53,234.41,10,600,1,2,233.45,234.43,15,105,1,2,233.4,234.5,110,63,2,4,233.39,234.75,10,1,1,1,AAPL,0.0,0.0,-200.0,0.0,0.0,0.0,0.0,0.0,0.0,0.0,0.0,-12.683232565773917,
2024-10-21T12:09:13.223660901Z,2024-10-21T12:09:13.223494596Z,10,2,38,A,B,1,233.83,200,130,166305,12185116,233.9,234.0,10,154,1,7,233.83,234.06,200,400,1,2,233.76,234.12,30,29,1,1,233.7,234.13,1200,400,1,1,233.66,234.17,1,1,1,1,233.58,234.25,505,50,2,1,233.53,234.41,10,600,1,2,233.45,234.43,15,105,1,2,233.4,234.5,110,63,2,4,233.39,234.75,10,1,1,1,AAPL,0.0,0.0,200.0,0.0,0.0,0.0,0.0,0.0,0.0,0.0,0.0,12.683232565773917,
2024-10-21T12:09:13.231090564Z,2024-10-21T12:09:13.230924474Z,10,2,38,C,B,2,233.76,30,130,166090,12185219,233.9,234.0,10,154,1,7,233.83,234.06,200,400,1,2,233.7,234.12,1200,29,1,1,233.66,234.13,1,400,1,1,233.58,234.17,505,1,2,1,233.53,234.25,10,50,1,1,233.45,234.41,15,600,1,2,233.4,234.43,110,105,2,2,233.39,234.5,10,63,1,4,233.31,234.75,110,1,2,1,AAPL,0.0,0.0,0.0,-30.0,-1200.0,-1.0,-505.0,-10.0,-15.0,-110.0,-10.0,-329.7909361186988,
2024-10-21T12:09:13.231145907Z,2024-10-21T12:09:13.230979969Z,10,2,38,A,B,2,233.77,27,130,165938,12185224,233.9,234.0,10,154,1,7,233.83,234.06,200,400,1,2,233.77,234.12,27,29,1,1,233.7,234.13,1200,400,1,1,233.66,234.17,1,1,1,1,233.58,234.25,505,50,2,1,233.53,234.41,10,600,1,2,233.45,234.43,15,105,1,2,233.4,234.5,110,63,2,4,233.39,234.75,10,1,1,1,AAPL,0.0,0.0,0.0,27.0,1200.0,1.0,505.0,10.0,15.0,110.0,10.0,329.4861883764908,
2024-10-21T12:09:13.352430022Z,2024-10-21T12:09:13.352263576Z,10,2,38,C,A,2,234.12,29,130,166446,12185591,233.9,234.0,10,154,1,7,233.83,234.06,200,400,1,2,233.77,234.13,27,400,1,1,233.7,234.17,1200,1,1,1,233.66,234.25,1,50,1,1,233.58,234.41,505,600,2,2,233.53,234.43,10,105,1,2,233.45,234.5,15,63,1,4,233.4,234.75,110,1,2,1,233.39,234.79,10,2000,1,1,AAPL,0.0,0.0,0.0,400.0,1.0,50.0,600.0,105.0,63.0,1.0,2000.0,289.7584132240917,
2024-10-21T12:09:13.352490529Z,2024-10-21T12:09:13.352324097Z,10,2,38,A,A,3,234.14,28,130,166432,12185592,233.9,234.0,10,154,1,7,233.83,234.06,200,400,1,2,233.77,234.13,27,400,1,1,233.7,234.14,1200,28,1,1,233.66,234.17,1,1,1,1,233.58,234.25,505,50,2,1,233.53,234.41,10,600,1,2,233.45,234.43,15,105,1,2,233.4,234.5,110,63,2,4,233.39,234.75,10,1,1,1,AAPL,0.0,0.0,0.0,0.0,-1.0,-50.0,-600.0,-105.0,-63.0,-1.0,-2000.0,-249.12538092968964,
2024-10-21T12:09:14.174425372Z,2024-10-21T12:09:14.174258870Z,10,2,38,C,A,1,234.06,200,130,166502,12186227,233.9,234.0,10,154,1,7,233.83,234.06,200,200,1,1,233.77,234.13,27,400,1,1,233.7,234.14,1200,28,1,1,233.66,234.17,1,1,1,1,233.58,234.25,505,50,2,1,233.53,234.41,10,600,1,2,233.45,234.43,15,105,1,2,233.4,234.5,110,63,2,4,233.39,234.75,10,1,1,1,AAPL,0.0,0.0,200.0,0.0,0.0,0.0,0.0,0.0,0.0,0.0,0.0,12.683232565773917,
2024-10-21T12:09:14.174436198Z,2024-10-21T12:09:14.174269739Z,10,2,38,C,A,1,234.06,200,130,166459,12186228,233.9,234.0,10,154,1,7,233.83,234.13,200,400,1,1,233.77,234.14,27,28,1,1,233.7,234.17,1200,1,1,1,233.66,234.25,1,50,1,1,233.58,234.41,505,600,2,2,233.53,234.43,10,105,1,2,233.45,234.5,15,63,1,4,233.4,234.75,110,1,2,1,233.39,234.79,10,2000,1,1,AAPL,0.0,0.0,400.0,28.0,1.0,50.0,600.0,105.0,63.0,1.0,2000.0,277.33615832184563,
2024-10-21T12:09:14.199575399Z,2024-10-21T12:09:14.199409178Z,10,2,38,A,A,1,234.07,200,130,166221,12186266,233.9,234.0,10,154,1,7,233.83,234.07,200,200,1,1,233.77,234.13,27,400,1,1,233.7,234.14,1200,28,1,1,233.66,234.17,1,1,1,1,233.58,234.25,505,50,2,1,233.53,234.41,10,600,1,2,233.45,234.43,15,105,1,2,233.4,234.5,110,63,2,4,233.39,234.75,10,1,1,1,AAPL,0.0,0.0,-400.0,-28.0,-1.0,-50.0,-600.0,-105.0,-63.0,-1.0,-2000.0,-277.33615832184563,
2024-10-21T12:09:15.368534989Z,2024-10-21T12:09:15.368368108Z,10,2,38,C,B,1,233.83,200,130,166881,12187413,233.9,234.0,10,154,1,7,233.77,234.07,27,200,1,1,233.7,234.13,1200,400,1,1,233.66,234.14,1,28,1,1,233.58,234.17,505,1,2,1,233.53,234.25,10,50,1,1,233.45,234.41,15,600,1,2,233.4,234.43,110,105,2,2,233.39,234.5,10,63,1,4,233.31,234.75,110,1,2,1,AAPL,0.0,0.0,-200.0,-27.0,-1200.0,-1.0,-505.0,-10.0,-15.0,-110.0,-10.0,-342.16942094226476,
2024-10-21T12:09:15.368547658Z,2024-10-21T12:09:15.368381335Z,10,2,38,A,B,2,233.74,400,130,166323,12187414,233.9,234.0,10,154,1,7,233.77,234.07,27,200,1,1,233.74,234.13,400,400,1,1,233.7,234.14,1200,28,1,1,233.66,234.17,1,1,1,1,233.58,234.25,505,50,2,1,233.53,234.41,10,600,1,2,233.45,234.43,15,105,1,2,233.4,234.5,110,63,2,4,233.39,234.75,10,1,1,1,AAPL,0.0,0.0,0.0,400.0,1200.0,1.0,505.0,10.0,15.0,110.0,10.0,367.3764909910208,
2024-10-21T12:09:15.369048334Z,2024-10-21T12:09:15.368882161Z,10,2,38,C,B,1,233.77,27,130,166173,12187416,233.9,234.0,10,154,1,7,233.74,234.07,400,200,1,1,233.7,234.13,1200,400,1,1,233.66,234.14,1,28,1,1,233.58,234.17,505,1,2,1,233.53,234.25,10,50,1,1,233.45,234.41,15,600,1,2,233.4,234.43,110,105,2,2,233.39,234.5,10,63,1,4,233.31,234.75,110,1,2,1,AAPL,0.0,0.0,-27.0,-400.0,-1200.0,-1.0,-505.0,-10.0,-15.0,-110.0,-10.0,-369.08872738740024,
2024-10-21T12:09:15.369149972Z,2024-10-21T12:09:15.368983400Z,10,2,38,A,B,2,233.72,28,130,166572,12187417,233.9,234.0,10,154,1,7,233.74,234.07,400,200,1,1,233.72,234.13,28,400,1,1,233.7,234.14,1200,28,1,1,233.66,234.17,1,1,1,1,233.58,234.25,505,50,2,1,233.53,234.41,10,600,1,2,233.45,234.43,15,105,1,2,233.4,234.5,110,63,2,4,233.39,234.75,10,1,1,1,AAPL,0.0,0.0,0.0,28.0,1200.0,1.0,505.0,10.0,15.0,110.0,10.0,329.58777095722684,
2024-10-21T12:09:15.972968249Z,2024-10-21T12:09:15.972801291Z,10,2,38,T,N,0,233.98,30,130,166958,12187912,233.9,234.0,10,154,1,7,233.74,234.07,400,200,1,1,233.72,234.13,28,400,1,1,233.7,234.14,1200,28,1,1,233.66,234.17,1,1,1,1,233.58,234.25,505,50,2,1,233.53,234.41,10,600,1,2,233.45,234.43,15,105,1,2,233.4,234.5,110,63,2,4,233.39,234.75,10,1,1,1,AAPL,0.0,0.0,0.0,0.0,0.0,0.0,0.0,0.0,0.0,0.0,0.0,0.0,
2024-10-21T12:09:16.178222372Z,2024-10-21T12:09:16.178054946Z,10,2,38,T,N,0,233.98,50,130,167426,12188119,233.9,234.0,10,154,1,7,233.74,234.07,400,200,1,1,233.72,234.13,28,400,1,1,233.7,234.14,1200,28,1,1,233.66,234.17,1,1,1,1,233.58,234.25,505,50,2,1,233.53,234.41,10,600,1,2,233.45,234.43,15,105,1,2,233.4,234.5,110,63,2,4,233.39,234.75,10,1,1,1,AAPL,0.0,0.0,0.0,0.0,0.0,0.0,0.0,0.0,0.0,0.0,0.0,0.0,
2024-10-21T12:09:17.673807276Z,2024-10-21T12:09:17.673639410Z,10,2,38,T,N,0,233.98,3,130,167866,12189121,233.9,234.0,10,154,1,7,233.74,234.07,400,200,1,1,233.72,234.13,28,400,1,1,233.7,234.14,1200,28,1,1,233.66,234.17,1,1,1,1,233.58,234.25,505,50,2,1,233.53,234.41,10,600,1,2,233.45,234.43,15,105,1,2,233.4,234.5,110,63,2,4,233.39,234.75,10,1,1,1,AAPL,0.0,0.0,0.0,0.0,0.0,0.0,0.0,0.0,0.0,0.0,0.0,0.0,
2024-10-21T12:09:18.369511364Z,2024-10-21T12:09:18.369344833Z,10,2,38,A,B,1,233.77,26,130,166531,12189523,233.9,234.0,10,154,1,7,233.77,234.07,26,200,1,1,233.74,234.13,400,400,1,1,233.72,234.14,28,28,1,1,233.7,234.17,1200,1,1,1,233.66,234.25,1,50,1,1,233.58,234.41,505,600,2,2,233.53,234.43,10,105,1,2,233.45,234.5,15,63,1,4,233.4,234.75,110,1,2,1,AAPL,0.0,0.0,26.0,400.0,28.0,1200.0,1.0,505.0,10.0,15.0,110.0,255.26728504697022,
2024-10-21T12:09:18.369536160Z,2024-10-21T12:09:18.369370009Z,10,2,38,C,B,3,233.72,28,130,166151,12189524,233.9,234.0,10,154,1,7,233.77,234.07,26,200,1,1,233.74,234.13,400,400,1,1,233.7,234.14,1200,28,1,1,233.66,234.17,1,1,1,1,233.58,234.25,505,50,2,1,233.53,234.41,10,600,1,2,233.45,234.43,15,105,1,2,233.4,234.5,110,63,2,4,233.39,234.75,10,1,1,1,AAPL,0.0,0.0,0.0,0.0,-28.0,-1200.0,-1.0,-505.0,-10.0,-15.0,-110.0,-212.98543251901754,
2024-10-21T12:09:18.424192189Z,2024-10-21T12:09:18.424025933Z,10,2,38,A,B,1,233.83,200,130,166256,12189542,233.9,234.0,10,154,1,7,233.83,234.07,200,200,1,1,233.77,234.13,26,400,1,1,233.7,234.14,1200,28,1,1,233.66,234.17,1,1,1,1,233.58,234.25,505,50,2,1,233.53,234.41,10,600,1,2,233.45,234.43,15,105,1,2,233.4,234.5,110,63,2,4,233.39,234.75,10,1,1,1,AAPL,0.0,0.0,200.0,26.0,0.0,0.0,0.0,0.0,0.0,0.0,0.0,15.324379664910053,
2024-10-21T12:09:26.336527240Z,2024-10-21T12:09:26.336360989Z,10,2,38,C,B,1,233.83,200,130,166251,12194498,233.9,234.0,10,154,1,7,233.77,234.07,26,200,1,1,233.7,234.13,1200,400,1,1,233.66,234.14,1,28,1,1,233.58,234.17,505,1,2,1,233.53,234.25,10,50,1,1,233.45,234.41,15,600,1,2,233.4,234.43,110,105,2,2,233.39,234.5,10,63,1,4,233.31,234.75,110,1,2,1,AAPL,0.0,0.0,-200.0,-26.0,-1200.0,-1.0,-505.0,-10.0,-15.0,-110.0,-10.0,-342.06783836152874,
2024-10-21T12:09:26.336539345Z,2024-10-21T12:09:26.336373029Z,10,2,38,A,B,1,233.81,200,130,166316,12194499,233.9,234.0,10,154,1,7,233.81,234.07,200,200,1,1,233.77,234.13,26,400,1,1,233.7,234.14,1200,28,1,1,233.66,234.17,1,1,1,1,233.58,234.25,505,50,2,1,233.53,234.41,10,600,1,2,233.45,234.43,15,105,1,2,233.4,234.5,110,63,2,4,233.39,234.75,10,1,1,1,AAPL,0.0,0.0,200.0,26.0,1200.0,1.0,505.0,10.0,15.0,110.0,10.0,342.06783836152874,
2024-10-21T12:09:26.336551701Z,2024-10-21T12:09:26.336385729Z,10,2,38,A,A,1,234.07,200,130,165972,12194500,233.9,234.0,10,154,1,7,233.81,234.07,200,400,1,2,233.77,234.13,26,400,1,1,233.7,234.14,1200,28,1,1,233.66,234.17,1,1,1,1,233.58,234.25,505,50,2,1,233.53,234.41,10,600,1,2,233.45,234.43,15,105,1,2,233.4,234.5,110,63,2,4,233.39,234.75,10,1,1,1,AAPL,0.0,0.0,-200.0,0.0,0.0,0.0,0.0,0.0,0.0,0.0,0.0,-12.683232565773917,
2024-10-21T12:09:26.402049735Z,2024-10-21T12:09:26.401883038Z,10,2,38,A,B,1,233.82,200,130,166697,12194620,233.9,234.0,10,154,1,7,233.82,234.07,200,400,1,2,233.77,234.13,26,400,1,1,233.7,234.14,1200,28,1,1,233.66,234.17,1,1,1,1,233.58,234.25,505,50,2,1,233.53,234.41,10,600,1,2,233.45,234.43,15,105,1,2,233.4,234.5,110,63,2,4,233.39,234.75,10,1,1,1,AAPL,0.0,0.0,200.0,0.0,0.0,0.0,0.0,0.0,0.0,0.0,0.0,12.683232565773917,
2024-10-21T12:09:30.048934813Z,2024-10-21T12:09:30.048768796Z,10,2,38,C,A,1,234.07,200,130,166017,12197231,233.9,234.0,10,154,1,7,233.82,234.07,200,200,1,1,233.77,234.13,26,400,1,1,233.7,234.14,1200,28,1,1,233.66,234.17,1,1,1,1,233.58,234.25,505,50,2,1,233.53,234.41,10,600,1,2,233.45,234.43,15,105,1,2,233.4,234.5,110,63,2,4,233.39,234.75,10,1,1,1,AAPL,0.0,0.0,200.0,0.0,0.0,0.0,0.0,0.0,0.0,0.0,0.0,12.683232565773917,
2024-10-21T12:09:30.048946954Z,2024-10-21T12:09:30.048780765Z,10,2,38,A,A,1,234.06,200,130,166189,12197232,233.9,234.0,10,154,1,7,233.82,234.06,200,200,1,1,233.77,234.13,26,400,1,1,233.7,234.14,1200,28,1,1,233.66,234.17,1,1,1,1,233.58,234.25,505,50,2,1,233.53,234.41,10,600,1,2,233.45,234.43,15,105,1,2,233.4,234.5,110,63,2,4,233.39,234.75,10,1,1,1,AAPL,0.0,0.0,-200.0,0.0,0.0,0.0,0.0,0.0,0.0,0.0,0.0,-12.683232565773917,
2024-10-21T12:09:30.065649441Z,2024-10-21T12:09:30.065483395Z,10,2,38,C,A,3,234.14,28,130,166046,12197308,233.9,234.0,10,154,1,7,233.82,234.06,200,200,1,1,233.77,234.13,26,400,1,1,233.7,234.17,1200,1,1,1,233.66,234.25,1,50,1,1,233.58,234.41,505,600,2,2,233.53,234.43,10,105,1,2,233.45,234.5,15,63,1,4,233.4,234.75,110,1,2,1,233.39,234.79,10,2000,1,1,AAPL,0.0,0.0,0.0,0.0,1.0,50.0,600.0,105.0,63.0,1.0,2000.0,249.12538092968964,
2024-10-21T12:09:30.066411685Z,2024-10-21T12:09:30.066245031Z,10,2,38,A,A,2,234.13,30,130,166654,12197309,233.9,234.0,10,154,1,7,233.82,234.06,200,200,1,1,233.77,234.13,26,430,1,2,233.7,234.17,1200,1,1,1,233.66,234.25,1,50,1,1,233.58,234.41,505,600,2,2,233.53,234.43,10,105,1,2,233.45,234.5,15,63,1,4,233.4,234.75,110,1,2,1,233.39,234.79,10,2000,1,1,AAPL,0.0,0.0,0.0,-30.0,0.0,0.0,0.0,0.0,0.0,0.0,0.0,-3.047477422080156,
2024-10-21T12:09:32.078130281Z,2024-10-21T12:09:32.077963808Z,10,2,38,A,B,0,233.9,1,130,166473,12199244,233.9,234.0,11,154,2,7,233.82,234.06,200,200,1,1,233.77,234.13,26,430,1,2,233.7,234.17,1200,1,1,1,233.66,234.25,1,50,1,1,233.58,234.41,505,600,2,2,233.53,234.43,10,105,1,2,233.45,234.5,15,63,1,4,233.4,234.75,110,1,2,1,233.39,234.79,10,2000,1,1,AAPL,1.0,1.0,0.0,0.0,0.0,0.0,0.0,0.0,0.0,0.0,0.0,0.01988058264612502,
2024-10-21T12:09:37.644521809Z,2024-10-21T12:09:37.644355301Z,10,2,38,A,B,1,233.83,200,130,166508,12202648,233.9,234.0,11,154,2,7,233.83,234.06,200,200,1,1,233.77,234.13,26,430,1,2,233.7,234.17,1200,1,1,1,233.66,234.25,1,50,1,1,233.58,234.41,505,600,2,2,233.53,234.43,10,105,1,2,233.45,234.5,15,63,1,4,233.4,234.75,110,1,2,1,233.39,234.79,10,2000,1,1,AAPL,0.0,0.0,200.0,0.0,0.0,0.0,0.0,0.0,0.0,0.0,0.0,12.683232565773917,
2024-10-21T12:09:38.208305707Z,2024-10-21T12:09:38.208139554Z,10,2,38,A,B,0,233.97,2,130,166153,12203420,233.97,234.0,2,154,1,7,233.9,234.06,11,200,2,1,233.83,234.13,200,430,1,2,233.77,234.17,26,1,1,1,233.7,234.25,1200,50,1,1,233.66,234.41,1,600,1,2,233.58,234.43,505,105,2,2,233.53,234.5,10,63,1,4,233.45,234.75,15,1,1,1,233.4,234.79,110,2000,2,1,AAPL,2.0,2.0,11.0,200.0,26.0,1200.0,1.0,505.0,10.0,15.0,110.0,233.62913351258015,
2024-10-21T12:09:42.372781724Z,2024-10-21T12:09:42.372615871Z,10,2,38,C,A,1,234.06,200,130,165853,12205636,233.97,234.0,2,154,1,7,233.9,234.13,11,430,2,2,233.83,234.17,200,1,1,1,233.77,234.25,26,50,1,1,233.7,234.41,1200,600,1,2,233.66,234.43,1,105,1,2,233.58,234.5,505,63,2,4,233.53,234.75,10,1,1,1,233.45,234.79,15,2000,1,1,233.4,234.89,110,2,2,2,AAPL,0.0,0.0,430.0,1.0,50.0,600.0,105.0,63.0,1.0,2000.0,2.0,267.9831263152147,
2024-10-21T12:09:42.372793881Z,2024-10-21T12:09:42.372627823Z,10,2,38,A,A,1,234.07,200,130,166058,12205637,233.97,234.0,2,154,1,7,233.9,234.07,11,200,2,1,233.83,234.13,200,430,1,2,233.77,234.17,26,1,1,1,233.7,234.25,1200,50,1,1,233.66,234.41,1,600,1,2,233.58,234.43,505,105,2,2,233.53,234.5,10,63,1,4,233.45,234.75,15,1,1,1,233.4,234.79,110,2000,2,1,AAPL,0.0,0.0,-430.0,-1.0,-50.0,-600.0,-105.0,-63.0,-1.0,-2000.0,-2.0,-267.9831263152147,
2024-10-21T12:09:43.901481889Z,2024-10-21T12:09:43.901315169Z,10,2,38,A,B,1,233.95,10,130,166720,12207173,233.97,234.0,2,154,1,7,233.95,234.07,10,200,1,1,233.9,234.13,11,430,2,2,233.83,234.17,200,1,1,1,233.77,234.25,26,50,1,1,233.7,234.41,1200,600,1,2,233.66,234.43,1,105,1,2,233.58,234.5,505,63,2,4,233.53,234.75,10,1,1,1,233.45,234.79,15,2000,1,1,AAPL,0.0,0.0,10.0,11.0,200.0,26.0,1200.0,1.0,505.0,10.0,15.0,264.2129535478707,
2024-10-21T12:09:45.133575558Z,2024-10-21T12:09:45.133407519Z,10,2,38,T,N,0,233.98,17,130,168039,12207963,233.97,234.0,2,154,1,7,233.95,234.07,10,200,1,1,233.9,234.13,11,430,2,2,233.83,234.17,200,1,1,1,233.77,234.25,26,50,1,1,233.7,234.41,1200,600,1,2,233.66,234.43,1,105,1,2,233.58,234.5,505,63,2,4,233.53,234.75,10,1,1,1,233.45,234.79,15,2000,1,1,AAPL,0.0,0.0,0.0,0.0,0.0,0.0,0.0,0.0,0.0,0.0,0.0,0.0,
2024-10-21T12:09:45.628746056Z,2024-10-21T12:09:45.628579880Z,10,2,38,A,B,9,233.5,100,130,166176,12208190,233.97,234.0,2,154,1,7,233.95,234.07,10,200,1,1,233.9,234.13,11,430,2,2,233.83,234.17,200,1,1,1,233.77,234.25,26,50,1,1,233.7,234.41,1200,600,1,2,233.66,234.43,1,105,1,2,233.58,234.5,505,63,2,4,233.53,234.75,10,1,1,1,233.5,234.79,100,2000,1,1,AAPL,0.0,0.0,0.0,0.0,0.0,0.0,0.0,0.0,0.0,0.0,100.0,7.102190039077244,
2024-10-21T12:09:48.089517540Z,2024-10-21T12:09:48.089350946Z,10,2,38,A,A,1,234.07,200,130,166594,12210108,233.97,234.0,2,154,1,7,233.95,234.07,10,400,1,2,233.9,234.13,11,430,2,2,233.83,234.17,200,1,1,1,233.77,234.25,26,50,1,1,233.7,234.41,1200,600,1,2,233.66,234.43,1,105,1,2,233.58,234.5,505,63,2,4,233.53,234.75,10,1,1,1,233.5,234.79,100,2000,1,1,AAPL,0.0,0.0,-200.0,0.0,0.0,0.0,0.0,0.0,0.0,0.0,0.0,-12.683232565773917,
2024-10-21T12:09:48.587196262Z,2024-10-21T12:09:48.587030358Z,10,2,38,C,A,1,234.07,200,130,165904,12210833,233.97,234.0,2,154,1,7,233.95,234.07,10,200,1,1,233.9,234.13,11,430,2,2,233.83,234.17,200,1,1,1,233.77,234.25,26,50,1,1,233.7,234.41,1200,600,1,2,233.66,234.43,1,105,1,2,233.58,234.5,505,63,2,4,233.53,234.75,10,1,1,1,233.5,234.79,100,2000,1,1,AAPL,0.0,0.0,200.0,0.0,0.0,0.0,0.0,0.0,0.0,0.0,0.0,12.683232565773917,
2024-10-21T12:09:48.587209868Z,2024-10-21T12:09:48.587043020Z,10,2,38,A,A,1,234.06,200,130,166848,12210834,233.97,234.0,2,154,1,7,233.95,234.06,10,200,1,1,233.9,234.13,11,430,2,2,233.83,234.17,200,1,1,1,233.77,234.25,26,50,1,1,233.7,234.41,1200,600,1,2,233.66,234.43,1,105,1,2,233.58,234.5,505,63,2,4,233.53,234.75,10,1,1,1,233.5,234.79,100,2000,1,1,AAPL,0.0,0.0,-200.0,0.0,0.0,0.0,0.0,0.0,0.0,0.0,0.0,-12.683232565773917,
2024-10-21T12:09:49.792890933Z,2024-10-21T12:09:49.792724444Z,10,2,38,A,A,1,234.06,200,130,166489,12211836,233.97,234.0,2,154,1,7,233.95,234.06,10,400,1,2,233.9,234.13,11,430,2,2,233.83,234.17,200,1,1,1,233.77,234.25,26,50,1,1,233.7,234.41,1200,600,1,2,233.66,234.43,1,105,1,2,233.58,234.5,505,63,2,4,233.53,234.75,10,1,1,1,233.5,234.79,100,2000,1,1,AAPL,0.0,0.0,-200.0,0.0,0.0,0.0,0.0,0.0,0.0,0.0,0.0,-12.683232565773917,
2024-10-21T12:09:53.122619723Z,2024-10-21T12:09:53.122453611Z,10,2,38,C,B,0,233.97,2,130,166112,12214081,233.95,234.0,10,154,1,7,233.9,234.06,11,400,2,2,233.83,234.13,200,430,1,2,233.77,234.17,26,1,1,1,233.7,234.25,1200,50,1,1,233.66,234.41,1,600,1,2,233.58,234.43,505,105,2,2,233.53,234.5,10,63,1,4,233.5,234.75,100,1,1,1,233.45,234.79,15,2000,1,1,AAPL,-2.0,-2.0,-10.0,-11.0,-200.0,-26.0,-1200.0,-1.0,-505.0,-10.0,-100.0,-270.28957624637866,
2024-10-21T12:09:53.247175609Z,2024-10-21T12:09:53.247009420Z,10,2,38,A,B,3,233.81,30,130,166189,12214171,233.95,234.0,10,154,1,7,233.9,234.06,11,400,2,2,233.83,234.13,200,430,1,2,233.81,234.17,30,1,1,1,233.77,234.25,26,50,1,1,233.7,234.41,1200,600,1,2,233.66,234.43,1,105,1,2,233.58,234.5,505,63,2,4,233.53,234.75,10,1,1,1,233.5,234.79,100,2000,1,1,AAPL,0.0,0.0,0.0,0.0,30.0,26.0,1200.0,1.0,505.0,10.0,100.0,233.63514571060148,
2024-10-21T12:09:53.247209179Z,2024-10-21T12:09:53.247043259Z,10,2,38,C,B,4,233.77,26,130,165920,12214172,233.95,234.0,10,154,1,7,233.9,234.06,11,400,2,2,233.83,234.13,200,430,1,2,233.81,234.17,30,1,1,1,233.7,234.25,1200,50,1,1,233.66,234.41,1,600,1,2,233.58,234.43,505,105,2,2,233.53,234.5,10,63,1,4,233.5,234.75,100,1,1,1,233.45,234.79,15,2000,1,1,AAPL,0.0,0.0,0.0,0.0,0.0,-26.0,-1200.0,-1.0,-505.0,-10.0,-100.0,-227.48283405987792,
2024-10-21T12:09:53.300084898Z,2024-10-21T12:09:53.299918437Z,10,2,38,A,B,2,233.86,200,130,166461,12214205,233.95,234.0,10,154,1,7,233.9,234.06,11,400,2,2,233.86,234.13,200,430,1,2,233.81,234.17,30,1,1,1,233.7,234.25,1200,50,1,1,233.66,234.41,1,600,1,2,233.58,234.43,505,105,2,2,233.53,234.5,10,63,1,4,233.5,234.75,100,1,1,1,233.45,234.79,15,2000,1,1,AAPL,0.0,0.0,0.0,200.0,0.0,0.0,0.0,0.0,0.0,0.0,0.0,20.31651614720104,
2024-10-21T12:09:54.364146144Z,2024-10-21T12:09:54.363979828Z,10,2,38,C,A,1,234.06,200,130,166316,12214797,233.95,234.0,10,154,1,7,233.9,234.06,11,200,2,1,233.86,234.13,200,430,1,2,233.81,234.17,30,1,1,1,233.7,234.25,1200,50,1,1,233.66,234.41,1,600,1,2,233.58,234.43,505,105,2,2,233.53,234.5,10,63,1,4,233.5,234.75,100,1,1,1,233.45,234.79,15,2000,1,1,AAPL,0.0,0.0,200.0,0.0,0.0,0.0,0.0,0.0,0.0,0.0,0.0,12.683232565773917,
2024-10-21T12:09:54.364156991Z,2024-10-21T12:09:54.363990119Z,10,2,38,C,A,1,234.06,200,130,166872,12214798,233.95,234.0,10,154,1,7,233.9,234.13,11,430,2,2,233.86,234.17,200,1,1,1,233.81,234.25,30,50,1,1,233.7,234.41,1200,600,1,2,233.66,234.43,1,105,1,2,233.58,234.5,505,63,2,4,233.53,234.75,10,1,1,1,233.5,234.79,100,2000,1,1,233.45,234.89,15,2,1,2,AAPL,0.0,0.0,430.0,1.0,50.0,600.0,105.0,63.0,1.0,2000.0,2.0,267.9831263152147,
2024-10-21T12:09:54.402511703Z,2024-10-21T12:09:54.402345010Z,10,2,38,A,A,1,234.06,200,130,166693,12214808,233.95,234.0,10,154,1,7,233.9,234.06,11,200,2,1,233.86,234.13,200,430,1,2,233.81,234.17,30,1,1,1,233.7,234.25,1200,50,1,1,233.66,234.41,1,600,1,2,233.58,234.43,505,105,2,2,233.53,234.5,10,63,1,4,233.5,234.75,100,1,1,1,233.45,234.79,15,2000,1,1,AAPL,0.0,0.0,-430.0,-1.0,-50.0,-600.0,-105.0,-63.0,-1.0,-2000.0,-2.0,-267.9831263152147,
2024-10-21T12:09:57.392768641Z,2024-10-21T12:09:57.392602293Z,10,2,38,A,A,1,234.05,200,130,166348,12217320,233.95,234.0,10,154,1,7,233.9,234.05,11,200,2,1,233.86,234.13,200,430,1,2,233.81,234.17,30,1,1,1,233.7,234.25,1200,50,1,1,233.66,234.41,1,600,1,2,233.58,234.43,505,105,2,2,233.53,234.5,10,63,1,4,233.5,234.75,100,1,1,1,233.45,234.79,15,2000,1,1,AAPL,0.0,0.0,-200.0,0.0,0.0,0.0,0.0,0.0,0.0,0.0,0.0,-12.683232565773917,
2024-10-21T12:09:57.433120140Z,2024-10-21T12:09:57.432954262Z,10,2,38,C,A,2,234.13,30,130,165878,12217490,233.95,234.0,10,154,1,7,233.9,234.05,11,200,2,1,233.86,234.13,200,400,1,1,233.81,234.17,30,1,1,1,233.7,234.25,1200,50,1,1,233.66,234.41,1,600,1,2,233.58,234.43,505,105,2,2,233.53,234.5,10,63,1,4,233.5,234.75,100,1,1,1,233.45,234.79,15,2000,1,1,AAPL,0.0,0.0,0.0,30.0,0.0,0.0,0.0,0.0,0.0,0.0,0.0,3.047477422080156,
2024-10-21T12:09:57.433181540Z,2024-10-21T12:09:57.433015324Z,10,2,38,A,A,2,234.12,27,130,166216,12217491,233.95,234.0,10,154,1,7,233.9,234.05,11,200,2,1,233.86,234.12,200,27,1,1,233.81,234.13,30,400,1,1,233.7,234.17,1200,1,1,1,233.66,234.25,1,50,1,1,233.58,234.41,505,600,2,2,233.53,234.43,10,105,1,2,233.5,234.5,100,63,1,4,233.45,234.75,15,1,1,1,AAPL,0.0,0.0,0.0,-400.0,-1.0,-50.0,-600.0,-105.0,-63.0,-1.0,-2000.0,-289.7584132240917,
2024-10-21T12:10:00.023985986Z,2024-10-21T12:10:00.023818184Z,10,2,38,T,N,0,233.98,2,130,167802,12219639,233.95,234.0,10,154,1,7,233.9,234.05,11,200,2,1,233.86,234.12,200,27,1,1,233.81,234.13,30,400,1,1,233.7,234.17,1200,1,1,1,233.66,234.25,1,50,1,1,233.58,234.41,505,600,2,2,233.53,234.43,10,105,1,2,233.5,234.5,100,63,1,4,233.45,234.75,15,1,1,1,AAPL,0.0,0.0,0.0,0.0,0.0,0.0,0.0,0.0,0.0,0.0,0.0,0.0,
2024-10-21T12:10:01.648468232Z,2024-10-21T12:10:01.648302231Z,10,2,38,C,B,2,233.86,200,130,166001,12221707,233.95,234.0,10,154,1,7,233.9,234.05,11,200,2,1,233.81,234.12,30,27,1,1,233.7,234.13,1200,400,1,1,233.66,234.17,1,1,1,1,233.58,234.25,505,50,2,1,233.53,234.41,10,600,1,2,233.5,234.43,100,105,1,2,233.45,234.5,15,63,1,4,233.4,234.75,110,1,2,1,AAPL,0.0,0.0,0.0,-200.0,-30.0,-1200.0,-1.0,-505.0,-10.0,-100.0,-15.0,-232.85732847277077,
2024-10-21T12:10:01.648480569Z,2024-10-21T12:10:01.648314395Z,10,2,38,A,B,2,233.84,200,130,166174,12221708,233.95,234.0,10,154,1,7,233.9,234.05,11,200,2,1,233.84,234.12,200,27,1,1,233.81,234.13,30,400,1,1,233.7,234.17,1200,1,1,1,233.66,234.25,1,50,1,1,233.58,234.41,505,600,2,2,233.53,234.43,10,105,1,2,233.5,234.5,100,63,1,4,233.45,234.75,15,1,1,1,AAPL,0.0,0.0,0.0,200.0,30.0,1200.0,1.0,505.0,10.0,100.0,15.0,232.85732847277077,
2024-10-21T12:10:01.702740055Z,2024-10-21T12:10:01.702573654Z,10,2,38,A,A,1,234.04,200,130,166401,12221881,233.95,234.0,10,154,1,7,233.9,234.04,11,200,2,1,233.84,234.12,200,27,1,1,233.81,234.13,30,400,1,1,233.7,234.17,1200,1,1,1,233.66,234.25,1,50,1,1,233.58,234.41,505,600,2,2,233.53,234.43,10,105,1,2,233.5,234.5,100,63,1,4,233.45,234.75,15,1,1,1,AAPL,0.0,0.0,-200.0,0.0,0.0,0.0,0.0,0.0,0.0,0.0,0.0,-12.683232565773917,
2024-10-21T12:10:01.719186937Z,2024-10-21T12:10:01.719020950Z,10,2,38,C,A,1,234.04,200,130,165987,12221965,233.95,234.0,10,154,1,7,233.9,234.12,11,27,2,1,233.84,234.13,200,400,1,1,233.81,234.17,30,1,1,1,233.7,234.25,1200,50,1,1,233.66,234.41,1,600,1,2,233.58,234.43,505,105,2,2,233.53,234.5,10,63,1,4,233.5,234.75,100,1,1,1,233.45,234.79,15,2000,1,1,AAPL,0.0,0.0,27.0,400.0,1.0,50.0,600.0,105.0,63.0,1.0,2000.0,291.47064962047125,
2024-10-21T12:10:01.719199386Z,2024-10-21T12:10:01.719033080Z,10,2,38,A,A,1,234.09,200,130,166306,12221966,233.95,234.0,10,154,1,7,233.9,234.09,11,200,2,1,233.84,234.12,200,27,1,1,233.81,234.13,30,400,1,1,233.7,234.17,1200,1,1,1,233.66,234.25,1,50,1,1,233.58,234.41,505,600,2,2,233.53,234.43,10,105,1,2,233.5,234.5,100,63,1,4,233.45,234.75,15,1,1,1,AAPL,0.0,0.0,-27.0,-400.0,-1.0,-50.0,-600.0,-105.0,-63.0,-1.0,-2000.0,-291.47064962047125,
2024-10-21T12:10:01.724794250Z,2024-10-21T12:10:01.724626959Z,10,2,38,A,A,2,234.11,29,130,167291,12222034,233.95,234.0,10,154,1,7,233.9,234.09,11,200,2,1,233.84,234.11,200,29,1,1,233.81,234.12,30,27,1,1,233.7,234.13,1200,400,1,1,233.66,234.17,1,1,1,1,233.58,234.25,505,50,2,1,233.53,234.41,10,600,1,2,233.5,234.43,100,105,1,2,233.45,234.5,15,63,1,4,AAPL,0.0,0.0,0.0,-27.0,-400.0,-1.0,-50.0,-600.0,-105.0,-63.0,-1.0,-175.2848768013471,
2024-10-21T12:10:01.726233514Z,2024-10-21T12:10:01.726066241Z,10,2,38,A,B,2,233.84,200,128,167273,12222037,233.95,234.0,10,154,1,7,233.9,234.09,11,200,2,1,233.84,234.11,400,29,2,1,233.81,234.12,30,27,1,1,233.7,234.13,1200,400,1,1,233.66,234.17,1,1,1,1,233.58,234.25,505,50,2,1,233.53,234.41,10,600,1,2,233.5,234.43,100,105,1,2,233.45,234.5,15,63,1,4,AAPL,0.0,0.0,0.0,200.0,0.0,0.0,0.0,0.0,0.0,0.0,0.0,20.31651614720104,
2024-10-21T12:10:01.752007708Z,2024-10-21T12:10:01.751841665Z,10,2,38,C,A,2,234.11,29,130,166043,12222181,233.95,234.0,10,154,1,7,233.9,234.09,11,200,2,1,233.84,234.12,400,27,2,1,233.81,234.13,30,400,1,1,233.7,234.17,1200,1,1,1,233.66,234.25,1,50,1,1,233.58,234.41,505,600,2,2,233.53,234.43,10,105,1,2,233.5,234.5,100,63,1,4,233.45,234.75,15,1,1,1,AAPL,0.0,0.0,0.0,27.0,400.0,1.0,50.0,600.0,105.0,63.0,1.0,175.2848768013471,
2024-10-21T12:10:01.781827461Z,2024-10-21T12:10:01.781661443Z,10,2,38,C,B,2,233.84,200,130,166018,12222265,233.95,234.0,10,154,1,7,233.9,234.09,11,200,2,1,233.84,234.12,200,27,1,1,233.81,234.13,30,400,1,1,233.7,234.17,1200,1,1,1,233.66,234.25,1,50,1,1,233.58,234.41,505,600,2,2,233.53,234.43,10,105,1,2,233.5,234.5,100,63,1,4,233.45,234.75,15,1,1,1,AAPL,0.0,0.0,0.0,-200.0,0.0,0.0,0.0,0.0,0.0,0.0,0.0,-20.31651614720104,
2024-10-21T12:10:01.781840313Z,2024-10-21T12:10:01.781673802Z,10,2,38,A,B,2,233.87,400,130,166511,12222266,233.95,234.0,10,154,1,7,233.9,234.09,11,200,2,1,233.87,234.12,400,27,1,1,233.81,234.13,30,400,1,1,233.7,234.17,1200,1,1,1,233.66,234.25,1,50,1,1,233.58,234.41,505,600,2,2,233.53,234.43,10,105,1,2,233.5,234.5,100,63,1,4,233.45,234.75,15,1,1,1,AAPL,0.0,0.0,0.0,400.0,0.0,0.0,0.0,0.0,0.0,0.0,0.0,40.63303229440208,
2024-10-21T12:10:01.842942268Z,2024-10-21T12:10:01.842775879Z,10,2,38,C,A,2,234.12,27,130,166389,12222352,233.95,234.0,10,154,1,7,233.9,234.09,11,200,2,1,233.87,234.13,400,400,1,1,233.81,234.17,30,1,1,1,233.7,234.25,1200,50,1,1,233.66,234.41,1,600,1,2,233.58,234.43,505,105,2,2,233.53,234.5,10,63,1,4,233.5,234.75,100,1,1,1,233.45,234.79,15,2000,1,1,AAPL,0.0,0.0,0.0,400.0,1.0,50.0,600.0,105.0,63.0,1.0,2000.0,289.7584132240917,
2024-10-21T12:10:02.294263964Z,2024-10-21T12:10:02.294097461Z,10,2,38,A,A,3,234.16,27,130,166503,12222991,233.95,234.0,10,154,1,7,233.9,234.09,11,200,2,1,233.87,234.13,400,400,1,1,233.81,234.16,30,27,1,1,233.7,234.17,1200,1,1,1,233.66,234.25,1,50,1,1,233.58,234.41,505,600,2,2,233.53,234.43,10,105,1,2,233.5,234.5,100,63,1,4,233.45,234.75,15,1,1,1,AAPL,0.0,0.0,0.0,0.0,-1.0,-50.0,-600.0,-105.0,-63.0,-1.0,-2000.0,-249.12538092968964,
2024-10-21T12:10:03.086305082Z,2024-10-21T12:10:03.086137168Z,10,2,38,T,N,0,233.99,9,130,167914,12223722,233.95,234.0,10,154,1,7,233.9,234.09,11,200,2,1,233.87,234.13,400,400,1,1,233.81,234.16,30,27,1,1,233.7,234.17,1200,1,1,1,233.66,234.25,1,50,1,1,233.58,234.41,505,600,2,2,233.53,234.43,10,105,1,2,233.5,234.5,100,63,1,4,233.45,234.75,15,1,1,1,AAPL,0.0,0.0,0.0,0.0,0.0,0.0,0.0,0.0,0.0,0.0,0.0,0.0,
2024-10-21T12:10:03.188762601Z,2024-10-21T12:10:03.188596704Z,10,2,38,C,B,2,233.87,400,130,165897,12223900,233.95,234.0,10,154,1,7,233.9,234.09,11,200,2,1,233.81,234.13,30,400,1,1,233.7,234.16,1200,27,1,1,233.66,234.17,1,1,1,1,233.58,234.25,505,50,2,1,233.53,234.41,10,600,1,2,233.5,234.43,100,105,1,2,233.45,234.5,15,63,1,4,233.4,234.75,110,1,2,1,AAPL,0.0,0.0,0.0,-400.0,-30.0,-1200.0,-1.0,-505.0,-10.0,-100.0,-15.0,-253.17384461997182,
2024-10-21T12:10:03.188775201Z,2024-10-21T12:10:03.188608784Z,10,2,38,A,B,2,233.86,400,130,166417,12223901,233.95,234.0,10,154,1,7,233.9,234.09,11,200,2,1,233.86,234.13,400,400,1,1,233.81,234.16,30,27,1,1,233.7,234.17,1200,1,1,1,233.66,234.25,1,50,1,1,233.58,234.41,505,600,2,2,233.53,234.43,10,105,1,2,233.5,234.5,100,63,1,4,233.45,234.75,15,1,1,1,AAPL,0.0,0.0,0.0,400.0,30.0,1200.0,1.0,505.0,10.0,100.0,15.0,253.17384461997182,
2024-10-21T12:10:03.188787374Z,2024-10-21T12:10:03.188621108Z,10,2,38,A,A,1,234.09,200,130,166266,12223902,233.95,234.0,10,154,1,7,233.9,234.09,11,400,2,2,233.86,234.13,400,400,1,1,233.81,234.16,30,27,1,1,233.7,234.17,1200,1,1,1,233.66,234.25,1,50,1,1,233.58,234.41,505,600,2,2,233.53,234.43,10,105,1,2,233.5,234.5,100,63,1,4,233.45,234.75,15,1,1,1,AAPL,0.0,0.0,-200.0,0.0,0.0,0.0,0.0,0.0,0.0,0.0,0.0,-12.683232565773917,
2024-10-21T12:10:03.197697662Z,2024-10-21T12:10:03.197531287Z,10,2,38,A,B,4,233.79,26,130,166375,12224056,233.95,234.0,10,154,1,7,233.9,234.09,11,400,2,2,233.86,234.13,400,400,1,1,233.81,234.16,30,27,1,1,233.79,234.17,26,1,1,1,233.7,234.25,1200,50,1,1,233.66,234.41,1,600,1,2,233.58,234.43,505,105,2,2,233.53,234.5,10,63,1,4,233.5,234.75,100,1,1,1,AAPL,0.0,0.0,0.0,0.0,0.0,26.0,1200.0,1.0,505.0,10.0,100.0,227.48283405987792,
2024-10-21T12:10:03.247897243Z,2024-10-21T12:10:03.247731199Z,10,2,38,C,A,1,234.09,200,130,166044,12224474,233.95,234.0,10,154,1,7,233.9,234.09,11,200,2,1,233.86,234.13,400,400,1,1,233.81,234.16,30,27,1,1,233.79,234.17,26,1,1,1,233.7,234.25,1200,50,1,1,233.66,234.41,1,600,1,2,233.58,234.43,505,105,2,2,233.53,234.5,10,63,1,4,233.5,234.75,100,1,1,1,AAPL,0.0,0.0,200.0,0.0,0.0,0.0,0.0,0.0,0.0,0.0,0.0,12.683232565773917,
2024-10-21T12:10:03.247911445Z,2024-10-21T12:10:03.247744906Z,10,2,38,A,A,1,234.08,400,130,166539,12224475,233.95,234.0,10,154,1,7,233.9,234.08,11,400,2,1,233.86,234.13,400,400,1,1,233.81,234.16,30,27,1,1,233.79,234.17,26,1,1,1,233.7,234.25,1200,50,1,1,233.66,234.41,1,600,1,2,233.58,234.43,505,105,2,2,233.53,234.5,10,63,1,4,233.5,234.75,100,1,1,1,AAPL,0.0,0.0,-200.0,0.0,0.0,0.0,0.0,0.0,0.0,0.0,0.0,-12.683232565773917,
2024-10-21T12:10:03.255171170Z,2024-10-21T12:10:03.255005064Z,10,2,38,C,B,3,233.81,30,130,166106,12224539,233.95,234.0,10,154,1,7,233.9,234.08,11,400,2,1,233.86,234.13,400,400,1,1,233.79,234.16,26,27,1,1,233.7,234.17,1200,1,1,1,233.66,234.25,1,50,1,1,233.58,234.41,505,600,2,2,233.53,234.43,10,105,1,2,233.5,234.5,100,63,1,4,233.45,234.75,15,1,1,1,AAPL,0.0,0.0,0.0,0.0,-30.0,-26.0,-1200.0,-1.0,-505.0,-10.0,-100.0,-233.63514571060148,
2024-10-21T12:10:03.258081034Z,2024-10-21T12:10:03.257914828Z,10,2,38,C,A,3,234.16,27,130,166206,12224582,233.95,234.0,10,154,1,7,233.9,234.08,11,400,2,1,233.86,234.13,400,400,1,1,233.79,234.17,26,1,1,1,233.7,234.25,1200,50,1,1,233.66,234.41,1,600,1,2,233.58,234.43,505,105,2,2,233.53,234.5,10,63,1,4,233.5,234.75,100,1,1,1,233.45,234.79,15,2000,1,1,AAPL,0.0,0.0,0.0,0.0,1.0,50.0,600.0,105.0,63.0,1.0,2000.0,249.12538092968964,
2024-10-21T12:10:03.460121633Z,2024-10-21T12:10:03.459955473Z,10,2,38,C,A,1,234.08,400,130,166160,12225012,233.95,234.0,10,154,1,7,233.9,234.13,11,400,2,1,233.86,234.17,400,1,1,1,233.79,234.25,26,50,1,1,233.7,234.41,1200,600,1,2,233.66,234.43,1,105,1,2,233.58,234.5,505,63,2,4,233.53,234.75,10,1,1,1,233.5,234.79,100,2000,1,1,233.45,234.89,15,2,1,2,AAPL,0.0,0.0,400.0,1.0,50.0,600.0,105.0,63.0,1.0,2000.0,2.0,266.08064143034863,
2024-10-21T12:10:03.460133284Z,2024-10-21T12:10:03.459967128Z,10,2,38,A,A,1,234.1,400,130,166156,12225013,233.95,234.0,10,154,1,7,233.9,234.1,11,400,2,1,233.86,234.13,400,400,1,1,233.79,234.17,26,1,1,1,233.7,234.25,1200,50,1,1,233.66,234.41,1,600,1,2,233.58,234.43,505,105,2,2,233.53,234.5,10,63,1,4,233.5,234.75,100,1,1,1,233.45,234.79,15,2000,1,1,AAPL,0.0,0.0,-400.0,-1.0,-50.0,-600.0,-105.0,-63.0,-1.0,-2000.0,-2.0,-266.08064143034863,
2024-10-21T12:10:03.515049550Z,2024-10-21T12:10:03.514882942Z,10,2,38,A,B,2,233.87,400,130,166608,12225080,233.95,234.0,10,154,1,7,233.9,234.1,11,400,2,1,233.87,234.13,400,400,1,1,233.79,234.17,26,1,1,1,233.7,234.25,1200,50,1,1,233.66,234.41,1,600,1,2,233.58,234.43,505,105,2,2,233.53,234.5,10,63,1,4,233.5,234.75,100,1,1,1,233.45,234.79,15,2000,1,1,AAPL,0.0,0.0,0.0,400.0,0.0,0.0,0.0,0.0,0.0,0.0,0.0,40.63303229440208,
2024-10-21T12:10:12.928144456Z,2024-10-21T12:10:12.927978411Z,10,2,38,C,B,3,233.79,26,130,166045,12232536,233.95,234.0,10,154,1,7,233.9,234.1,11,400,2,1,233.87,234.13,400,400,1,1,233.7,234.17,1200,1,1,1,233.66,234.25,1,50,1,1,233.58,234.41,505,600,2,2,233.53,234.43,10,105,1,2,233.5,234.5,100,63,1,4,233.45,234.75,15,1,1,1,233.4,234.79,110,2000,2,1,AAPL,0.0,0.0,0.0,0.0,-26.0,-1200.0,-1.0,-505.0,-10.0,-100.0,-15.0,-211.72050410547325,
2024-10-21T12:10:12.928202744Z,2024-10-21T12:10:12.928036467Z,10,2,38,A,B,3,233.8,29,130,166277,12232537,233.95,234.0,10,154,1,7,233.9,234.1,11,400,2,1,233.87,234.13,400,400,1,1,233.8,234.17,29,1,1,1,233.7,234.25,1200,50,1,1,233.66,234.41,1,600,1,2,233.58,234.43,505,105,2,2,233.53,234.5,10,63,1,4,233.5,234.75,100,1,1,1,233.45,234.79,15,2000,1,1,AAPL,0.0,0.0,0.0,0.0,29.0,1200.0,1.0,505.0,10.0,100.0,15.0,212.3357352705456,
2024-10-21T12:10:12.928233491Z,2024-10-21T12:10:12.928066550Z,10,2,38,A,A,3,234.16,28,130,166941,12232538,233.95,234.0,10,154,1,7,233.9,234.1,11,400,2,1,233.87,234.13,400,400,1,1,233.8,234.16,29,28,1,1,233.7,234.17,1200,1,1,1,233.66,234.25,1,50,1,1,233.58,234.41,505,600,2,2,233.53,234.43,10,105,1,2,233.5,234.5,100,63,1,4,233.45,234.75,15,1,1,1,AAPL,0.0,0.0,0.0,0.0,-1.0,-50.0,-600.0,-105.0,-63.0,-1.0,-2000.0,-249.12538092968964,
2024-10-21T12:10:13.161907732Z,2024-10-21T12:10:13.161741583Z,10,2,38,C,B,2,233.87,400,130,166149,12232708,233.95,234.0,10,154,1,7,233.9,234.1,11,400,2,1,233.8,234.13,29,400,1,1,233.7,234.16,1200,28,1,1,233.66,234.17,1,1,1,1,233.58,234.25,505,50,2,1,233.53,234.41,10,600,1,2,233.5,234.43,100,105,1,2,233.45,234.5,15,63,1,4,233.4,234.75,110,1,2,1,AAPL,0.0,0.0,0.0,-400.0,-29.0,-1200.0,-1.0,-505.0,-10.0,-100.0,-15.0,-252.96876756494768,
2024-10-21T12:10:13.161920820Z,2024-10-21T12:10:13.161754596Z,10,2,38,A,B,2,233.84,200,130,166224,12232709,233.95,234.0,10,154,1,7,233.9,234.1,11,400,2,1,233.84,234.13,200,400,1,1,233.8,234.16,29,28,1,1,233.7,234.17,1200,1,1,1,233.66,234.25,1,50,1,1,233.58,234.41,505,600,2,2,233.53,234.43,10,105,1,2,233.5,234.5,100,63,1,4,233.45,234.75,15,1,1,1,AAPL,0.0,0.0,0.0,200.0,29.0,1200.0,1.0,505.0,10.0,100.0,15.0,232.65225141774664,
2024-10-21T12:10:17.086600126Z,2024-10-21T12:10:17.086432603Z,10,2,38,T,N,0,233.99,2,130,167523,12235454,233.95,234.0,10,154,1,7,233.9,234.1,11,400,2,1,233.84,234.13,200,400,1,1,233.8,234.16,29,28,1,1,233.7,234.17,1200,1,1,1,233.66,234.25,1,50,1,1,233.58,234.41,505,600,2,2,233.53,234.43,10,105,1,2,233.5,234.5,100,63,1,4,233.45,234.75,15,1,1,1,AAPL,0.0,0.0,0.0,0.0,0.0,0.0,0.0,0.0,0.0,0.0,0.0,0.0,
2024-10-21T12:10:20.742434348Z,2024-10-21T12:10:20.742267983Z,10,2,38,A,B,0,233.96,20,130,166365,12237424,233.96,234.0,20,154,1,7,233.95,234.1,10,400,1,1,233.9,234.13,11,400,2,1,233.84,234.16,200,28,1,1,233.8,234.17,29,1,1,1,233.7,234.25,1200,50,1,1,233.66,234.41,1,600,1,2,233.58,234.43,505,105,2,2,233.53,234.5,10,63,1,4,233.5,234.75,100,1,1,1,AAPL,20.0,20.0,10.0,11.0,200.0,29.0,1200.0,1.0,505.0,10.0,100.0,270.99658979602646,
2024-10-21T12:10:22.089103804Z,2024-10-21T12:10:22.088936277Z,10,2,38,T,N,0,233.99,5,130,167527,12238033,233.96,234.0,20,154,1,7,233.95,234.1,10,400,1,1,233.9,234.13,11,400,2,1,233.84,234.16,200,28,1,1,233.8,234.17,29,1,1,1,233.7,234.25,1200,50,1,1,233.66,234.41,1,600,1,2,233.58,234.43,505,105,2,2,233.53,234.5,10,63,1,4,233.5,234.75,100,1,1,1,AAPL,0.0,0.0,0.0,0.0,0.0,0.0,0.0,0.0,0.0,0.0,0.0,0.0,
2024-10-21T12:10:23.455861213Z,2024-10-21T12:10:23.455694731Z,10,2,38,A,B,3,233.84,200,130,166482,12239081,233.96,234.0,20,154,1,7,233.95,234.1,10,400,1,1,233.9,234.13,11,400,2,1,233.84,234.16,400,28,2,1,233.8,234.17,29,1,1,1,233.7,234.25,1200,50,1,1,233.66,234.41,1,600,1,2,233.58,234.43,505,105,2,2,233.53,234.5,10,63,1,4,233.5,234.75,100,1,1,1,AAPL,0.0,0.0,0.0,0.0,200.0,0.0,0.0,0.0,0.0,0.0,0.0,41.015411004823704,
2024-10-21T12:10:23.510715158Z,2024-10-21T12:10:23.510549173Z,10,2,38,C,B,3,233.84,200,130,165985,12239119,233.96,234.0,20,154,1,7,233.95,234.1,10,400,1,1,233.9,234.13,11,400,2,1,233.84,234.16,200,28,1,1,233.8,234.17,29,1,1,1,233.7,234.25,1200,50,1,1,233.66,234.41,1,600,1,2,233.58,234.43,505,105,2,2,233.53,234.5,10,63,1,4,233.5,234.75,100,1,1,1,AAPL,0.0,0.0,0.0,0.0,-200.0,0.0,0.0,0.0,0.0,0.0,0.0,-41.015411004823704,
2024-10-21T12:10:23.510728355Z,2024-10-21T12:10:23.510561501Z,10,2,38,A,B,3,233.87,400,130,166854,12239120,233.96,234.0,20,154,1,7,233.95,234.1,10,400,1,1,233.9,234.13,11,400,2,1,233.87,234.16,400,28,1,1,233.8,234.17,29,1,1,1,233.7,234.25,1200,50,1,1,233.66,234.41,1,600,1,2,233.58,234.43,505,105,2,2,233.53,234.5,10,63,1,4,233.5,234.75,100,1,1,1,AAPL,0.0,0.0,0.0,0.0,400.0,0.0,0.0,0.0,0.0,0.0,0.0,82.03082200964741,
2024-10-21T12:10:24.014692972Z,2024-10-21T12:10:24.014526498Z,10,2,38,A,B,3,233.88,400,130,166474,12239510,233.96,234.0,20,154,1,7,233.95,234.1,10,400,1,1,233.9,234.13,11,400,2,1,233.88,234.16,400,28,1,1,233.8,234.17,29,1,1,1,233.7,234.25,1200,50,1,1,233.66,234.41,1,600,1,2,233.58,234.43,505,105,2,2,233.53,234.5,10,63,1,4,233.5,234.75,100,1,1,1,AAPL,0.0,0.0,0.0,0.0,400.0,0.0,0.0,0.0,0.0,0.0,0.0,82.03082200964741,
2024-10-21T12:10:29.983091413Z,2024-10-21T12:10:29.982925320Z,10,2,38,C,B,1,233.95,10,130,166093,12243847,233.96,234.0,20,154,1,7,233.9,234.1,11,400,2,1,233.88,234.13,400,400,1,1,233.8,234.16,29,28,1,1,233.7,234.17,1200,1,1,1,233.66,234.25,1,50,1,1,233.58,234.41,505,600,2,2,233.53,234.43,10,105,1,2,233.5,234.5,100,63,1,4,233.45,234.75,15,1,1,1,AAPL,0.0,0.0,-10.0,-11.0,-400.0,-29.0,-1200.0,-1.0,-505.0,-10.0,-100.0,-311.6143891479277,
2024-10-21T12:10:32.696700045Z,2024-10-21T12:10:32.696534026Z,10,2,38,C,B,3,233.8,29,130,166019,12245508,233.96,234.0,20,154,1,7,233.9,234.1,11,400,2,1,233.88,234.13,400,400,1,1,233.7,234.16,1200,28,1,1,233.66,234.17,1,1,1,1,233.58,234.25,505,50,2,1,233.53,234.41,10,600,1,2,233.5,234.43,100,105,1,2,233.45,234.5,15,63,1,4,233.4,234.75,110,1,2,1,AAPL,0.0,0.0,0.0,0.0,-29.0,-1200.0,-1.0,-505.0,-10.0,-100.0,-15.0,-212.3357352705456,
2024-10-21T12:10:32.696757970Z,2024-10-21T12:10:32.696591804Z,10,2,38,A,B,3,233.81,28,130,166166,12245509,233.96,234.0,20,154,1,7,233.9,234.1,11,400,2,1,233.88,234.13,400,400,1,1,233.81,234.16,28,28,1,1,233.7,234.17,1200,1,1,1,233.66,234.25,1,50,1,1,233.58,234.41,505,600,2,2,233.53,234.43,10,105,1,2,233.5,234.5,100,63,1,4,233.45,234.75,15,1,1,1,AAPL,0.0,0.0,0.0,0.0,28.0,1200.0,1.0,505.0,10.0,100.0,15.0,212.1306582155215,
2024-10-21T12:10:36.255935226Z,2024-10-21T12:10:36.255768918Z,10,2,38,C,B,2,233.88,200,130,166308,12247980,233.96,234.0,20,154,1,7,233.9,234.1,11,400,2,1,233.88,234.13,200,400,1,1,233.81,234.16,28,28,1,1,233.7,234.17,1200,1,1,1,233.66,234.25,1,50,1,1,233.58,234.41,505,600,2,2,233.53,234.43,10,105,1,2,233.5,234.5,100,63,1,4,233.45,234.75,15,1,1,1,AAPL,0.0,0.0,0.0,-200.0,0.0,0.0,0.0,0.0,0.0,0.0,0.0,-20.31651614720104,
2024-10-21T12:10:36.668045674Z,2024-10-21T12:10:36.667879809Z,10,2,38,C,A,1,234.1,400,130,165865,12248362,233.96,234.0,20,154,1,7,233.9,234.13,11,400,2,1,233.88,234.16,200,28,1,1,233.81,234.17,28,1,1,1,233.7,234.25,1200,50,1,1,233.66,234.41,1,600,1,2,233.58,234.43,505,105,2,2,233.53,234.5,10,63,1,4,233.5,234.75,100,1,1,1,233.45,234.79,15,2000,1,1,AAPL,0.0,0.0,400.0,28.0,1.0,50.0,600.0,105.0,63.0,1.0,2000.0,277.33615832184563,
2024-10-21T12:10:36.668056804Z,2024-10-21T12:10:36.667890580Z,10,2,38,A,A,1,234.12,400,130,166224,12248363,233.96,234.0,20,154,1,7,233.9,234.12,11,400,2,1,233.88,234.13,200,400,1,1,233.81,234.16,28,28,1,1,233.7,234.17,1200,1,1,1,233.66,234.25,1,50,1,1,233.58,234.41,505,600,2,2,233.53,234.43,10,105,1,2,233.5,234.5,100,63,1,4,233.45,234.75,15,1,1,1,AAPL,0.0,0.0,-400.0,-28.0,-1.0,-50.0,-600.0,-105.0,-63.0,-1.0,-2000.0,-277.33615832184563,
2024-10-21T12:10:36.719005890Z,2024-10-21T12:10:36.718839166Z,10,2,38,A,B,2,233.89,200,130,166724,12248396,233.96,234.0,20,154,1,7,233.9,234.12,11,400,2,1,233.89,234.13,200,400,1,1,233.81,234.16,28,28,1,1,233.7,234.17,1200,1,1,1,233.66,234.25,1,50,1,1,233.58,234.41,505,600,2,2,233.53,234.43,10,105,1,2,233.5,234.5,100,63,1,4,233.45,234.75,15,1,1,1,AAPL,0.0,0.0,0.0,200.0,0.0,0.0,0.0,0.0,0.0,0.0,0.0,20.31651614720104,
2024-10-21T12:10:36.744053051Z,2024-10-21T12:10:36.743886554Z,10,2,38,C,A,3,234.16,28,130,166497,12248576,233.96,234.0,20,154,1,7,233.9,234.12,11,400,2,1,233.89,234.13,200,400,1,1,233.81,234.17,28,1,1,1,233.7,234.25,1200,50,1,1,233.66,234.41,1,600,1,2,233.58,234.43,505,105,2,2,233.53,234.5,10,63,1,4,233.5,234.75,100,1,1,1,233.45,234.79,15,2000,1,1,AAPL,0.0,0.0,0.0,0.0,1.0,50.0,600.0,105.0,63.0,1.0,2000.0,249.12538092968964,
2024-10-21T12:10:36.744163347Z,2024-10-21T12:10:36.743997154Z,10,2,38,A,A,4,234.18,29,130,166193,12248578,233.96,234.0,20,154,1,7,233.9,234.12,11,400,2,1,233.89,234.13,200,400,1,1,233.81,234.17,28,1,1,1,233.7,234.18,1200,29,1,1,233.66,234.25,1,50,1,1,233.58,234.41,505,600,2,2,233.53,234.43,10,105,1,2,233.5,234.5,100,63,1,4,233.45,234.75,15,1,1,1,AAPL,0.0,0.0,0.0,0.0,0.0,-50.0,-600.0,-105.0,-63.0,-1.0,-2000.0,-248.92030387466554,
2024-10-21T12:10:42.064904504Z,2024-10-21T12:10:42.064737913Z,10,2,38,C,B,2,233.89,200,130,166591,12252326,233.96,234.0,20,154,1,7,233.9,234.12,11,400,2,1,233.81,234.13,28,400,1,1,233.7,234.17,1200,1,1,1,233.66,234.18,1,29,1,1,233.58,234.25,505,50,2,1,233.53,234.41,10,600,1,2,233.5,234.43,100,105,1,2,233.45,234.5,15,63,1,4,233.4,234.75,110,1,2,1,AAPL,0.0,0.0,0.0,-200.0,-28.0,-1200.0,-1.0,-505.0,-10.0,-100.0,-15.0,-232.44717436272254,
2024-10-21T12:10:42.064917654Z,2024-10-21T12:10:42.064751203Z,10,2,38,A,B,2,233.86,200,130,166451,12252327,233.96,234.0,20,154,1,7,233.9,234.12,11,400,2,1,233.86,234.13,200,400,1,1,233.81,234.17,28,1,1,1,233.7,234.18,1200,29,1,1,233.66,234.25,1,50,1,1,233.58,234.41,505,600,2,2,233.53,234.43,10,105,1,2,233.5,234.5,100,63,1,4,233.45,234.75,15,1,1,1,AAPL,0.0,0.0,0.0,200.0,28.0,1200.0,1.0,505.0,10.0,100.0,15.0,232.44717436272254,
2024-10-21T12:10:43.289815837Z,2024-10-21T12:10:43.289649676Z,10,2,38,A,A,1,234.11,400,130,166161,12253919,233.96,234.0,20,154,1,7,233.9,234.11,11,400,2,1,233.86,234.13,200,400,1,1,233.81,234.17,28,1,1,1,233.7,234.18,1200,29,1,1,233.66,234.25,1,50,1,1,233.58,234.41,505,600,2,2,233.53,234.43,10,105,1,2,233.5,234.5,100,63,1,4,233.45,234.75,15,1,1,1,AAPL,0.0,0.0,-400.0,0.0,0.0,0.0,0.0,0.0,0.0,0.0,0.0,-25.366465131547834,
2024-10-21T12:10:43.377959609Z,2024-10-21T12:10:43.377793688Z,10,2,38,C,A,4,234.18,29,130,165921,12254130,233.96,234.0,20,154,1,7,233.9,234.11,11,400,2,1,233.86,234.13,200,400,1,1,233.81,234.17,28,1,1,1,233.7,234.25,1200,50,1,1,233.66,234.41,1,600,1,2,233.58,234.43,505,105,2,2,233.53,234.5,10,63,1,4,233.5,234.75,100,1,1,1,233.45,234.79,15,2000,1,1,AAPL,0.0,0.0,0.0,0.0,0.0,50.0,600.0,105.0,63.0,1.0,2000.0,248.92030387466554,
2024-10-21T12:10:43.378040281Z,2024-10-21T12:10:43.377874040Z,10,2,38,A,A,3,234.17,28,130,166241,12254131,233.96,234.0,20,154,1,7,233.9,234.11,11,400,2,1,233.86,234.13,200,400,1,1,233.81,234.17,28,29,1,2,233.7,234.25,1200,50,1,1,233.66,234.41,1,600,1,2,233.58,234.43,505,105,2,2,233.53,234.5,10,63,1,4,233.5,234.75,100,1,1,1,233.45,234.79,15,2000,1,1,AAPL,0.0,0.0,0.0,0.0,-28.0,0.0,0.0,0.0,0.0,0.0,0.0,-5.7421575406753185,
2024-10-21T12:10:45.117465225Z,2024-10-21T12:10:45.117298924Z,10,2,38,A,B,2,233.88,200,130,166301,12255855,233.96,234.0,20,154,1,7,233.9,234.11,11,400,2,1,233.88,234.13,200,400,1,1,233.81,234.17,28,29,1,2,233.7,234.25,1200,50,1,1,233.66,234.41,1,600,1,2,233.58,234.43,505,105,2,2,233.53,234.5,10,63,1,4,233.5,234.75,100,1,1,1,233.45,234.79,15,2000,1,1,AAPL,0.0,0.0,0.0,200.0,0.0,0.0,0.0,0.0,0.0,0.0,0.0,20.31651614720104,
2024-10-21T12:10:50.850117869Z,2024-10-21T12:10:50.849951366Z,10,2,38,A,B,2,233.89,200,130,166503,12260865,233.96,234.0,20,154,1,7,233.9,234.11,11,400,2,1,233.89,234.13,200,400,1,1,233.81,234.17,28,29,1,2,233.7,234.25,1200,50,1,1,233.66,234.41,1,600,1,2,233.58,234.43,505,105,2,2,233.53,234.5,10,63,1,4,233.5,234.75,100,1,1,1,233.45,234.79,15,2000,1,1,AAPL,0.0,0.0,0.0,200.0,0.0,0.0,0.0,0.0,0.0,0.0,0.0,20.31651614720104,
2024-10-21T12:10:52.970762824Z,2024-10-21T12:10:52.970596564Z,10,2,38,C,A,4,234.25,50,130,166260,12262701,233.96,234.0,20,154,1,7,233.9,234.11,11,400,2,1,233.89,234.13,200,400,1,1,233.81,234.17,28,29,1,2,233.7,234.41,1200,600,1,2,233.66,234.43,1,105,1,2,233.58,234.5,505,63,2,4,233.53,234.75,10,1,1,1,233.5,234.79,100,2000,1,1,233.45,234.89,15,2,1,2,AAPL,0.0,0.0,0.0,0.0,0.0,600.0,105.0,63.0,1.0,2000.0,2.0,230.35874096685887,
2024-10-21T12:10:53.810450187Z,2024-10-21T12:10:53.810283344Z,10,2,38,C,B,0,233.96,20,130,166843,12263307,233.9,234.0,11,154,2,7,233.89,234.11,200,400,1,1,233.81,234.13,28,400,1,1,233.7,234.17,1200,29,1,2,233.66,234.41,1,600,1,2,233.58,234.43,505,105,2,2,233.53,234.5,10,63,1,4,233.5,234.75,100,1,1,1,233.45,234.79,15,2000,1,1,233.4,234.89,110,2,2,2,AAPL,-20.0,-20.0,-11.0,-200.0,-28.0,-1200.0,-1.0,-505.0,-10.0,-100.0,-15.0,-233.54236380676258,
2024-10-21T12:10:53.881603970Z,2024-10-21T12:10:53.881437911Z,10,2,38,C,B,1,233.89,200,130,166059,12263356,233.9,234.0,11,154,2,7,233.81,234.11,28,400,1,1,233.7,234.13,1200,400,1,1,233.66,234.17,1,29,1,2,233.58,234.41,505,600,2,2,233.53,234.43,10,105,1,2,233.5,234.5,100,63,1,4,233.45,234.75,15,1,1,1,233.4,234.79,110,2000,2,1,233.39,234.89,10,2,1,2,AAPL,0.0,0.0,-200.0,-28.0,-1200.0,-1.0,-505.0,-10.0,-100.0,-15.0,-110.0,-351.42505877122426,
2024-10-21T12:10:53.881616413Z,2024-10-21T12:10:53.881449961Z,10,2,38,A,B,1,233.86,200,130,166452,12263357,233.9,234.0,11,154,2,7,233.86,234.11,200,400,1,1,233.81,234.13,28,400,1,1,233.7,234.17,1200,29,1,2,233.66,234.41,1,600,1,2,233.58,234.43,505,105,2,2,233.53,234.5,10,63,1,4,233.5,234.75,100,1,1,1,233.45,234.79,15,2000,1,1,233.4,234.89,110,2,2,2,AAPL,0.0,0.0,200.0,28.0,1200.0,1.0,505.0,10.0,100.0,15.0,110.0,351.42505877122426,
2024-10-21T12:10:54.127813980Z,2024-10-21T12:10:54.127647992Z,10,2,38,C,B,1,233.86,200,130,165988,12263603,233.9,234.0,11,154,2,7,233.81,234.11,28,400,1,1,233.7,234.13,1200,400,1,1,233.66,234.17,1,29,1,2,233.58,234.41,505,600,2,2,233.53,234.43,10,105,1,2,233.5,234.5,100,63,1,4,233.45,234.75,15,1,1,1,233.4,234.79,110,2000,2,1,233.39,234.89,10,2,1,2,AAPL,0.0,0.0,-200.0,-28.0,-1200.0,-1.0,-505.0,-10.0,-100.0,-15.0,-110.0,-351.42505877122426,
2024-10-21T12:10:54.127826075Z,2024-10-21T12:10:54.127659727Z,10,2,38,A,B,2,233.78,400,130,166348,12263604,233.9,234.0,11,154,2,7,233.81,234.11,28,400,1,1,233.78,234.13,400,400,1,1,233.7,234.17,1200,29,1,2,233.66,234.41,1,600,1,2,233.58,234.43,505,105,2,2,233.53,234.5,10,63,1,4,233.5,234.75,100,1,1,1,233.45,234.79,15,2000,1,1,233.4,234.89,110,2,2,2,AAPL,0.0,0.0,0.0,400.0,1200.0,1.0,505.0,10.0,100.0,15.0,110.0,376.5305462392443,
2024-10-21T12:10:54.147013785Z,2024-10-21T12:10:54.146847471Z,10,2,38,C,B,1,233.81,28,130,166314,12263624,233.9,234.0,11,154,2,7,233.78,234.11,400,400,1,1,233.7,234.13,1200,400,1,1,233.66,234.17,1,29,1,2,233.58,234.41,505,600,2,2,233.53,234.43,10,105,1,2,233.5,234.5,100,63,1,4,233.45,234.75,15,1,1,1,233.4,234.79,110,2000,2,1,233.39,234.89,10,2,1,2,AAPL,0.0,0.0,-28.0,-400.0,-1200.0,-1.0,-505.0,-10.0,-100.0,-15.0,-110.0,-378.3061987984526,
2024-10-21T12:10:54.147055569Z,2024-10-21T12:10:54.146889193Z,10,2,38,A,B,2,233.76,27,130,166376,12263625,233.9,234.0,11,154,2,7,233.78,234.11,400,400,1,1,233.76,234.13,27,400,1,1,233.7,234.17,1200,29,1,2,233.66,234.41,1,600,1,2,233.58,234.43,505,105,2,2,233.53,234.5,10,63,1,4,233.5,234.75,100,1,1,1,233.45,234.79,15,2000,1,1,233.4,234.89,110,2,2,2,AAPL,0.0,0.0,0.0,27.0,1200.0,1.0,505.0,10.0,100.0,15.0,110.0,338.64024362471434,
2024-10-21T12:10:54.147097290Z,2024-10-21T12:10:54.146930519Z,10,2,38,A,A,2,234.13,27,130,166771,12263626,233.9,234.0,11,154,2,7,233.78,234.11,400,400,1,1,233.76,234.13,27,427,1,2,233.7,234.17,1200,29,1,2,233.66,234.41,1,600,1,2,233.58,234.43,505,105,2,2,233.53,234.5,10,63,1,4,233.5,234.75,100,1,1,1,233.45,234.79,15,2000,1,1,233.4,234.89,110,2,2,2,AAPL,0.0,0.0,0.0,-27.0,0.0,0.0,0.0,0.0,0.0,0.0,0.0,-2.74272967987214,
2024-10-21T12:10:54.147208464Z,2024-10-21T12:10:54.147042446Z,10,2,38,C,A,3,234.17,28,130,166018,12263627,233.9,234.0,11,154,2,7,233.78,234.11,400,400,1,1,233.76,234.13,27,427,1,2,233.7,234.17,1200,1,1,1,233.66,234.41,1,600,1,2,233.58,234.43,505,105,2,2,233.53,234.5,10,63,1,4,233.5,234.75,100,1,1,1,233.45,234.79,15,2000,1,1,233.4,234.89,110,2,2,2,AAPL,0.0,0.0,0.0,0.0,28.0,0.0,0.0,0.0,0.0,0.0,0.0,5.7421575406753185,
2024-10-21T12:10:54.198522999Z,2024-10-21T12:10:54.198356340Z,10,2,38,A,A,1,234.06,200,130,166659,12263665,233.9,234.0,11,154,2,7,233.78,234.06,400,200,1,1,233.76,234.13,27,427,1,2,233.7,234.17,1200,1,1,1,233.66,234.41,1,600,1,2,233.58,234.43,505,105,2,2,233.53,234.5,10,63,1,4,233.5,234.75,100,1,1,1,233.45,234.79,15,2000,1,1,233.4,234.89,110,2,2,2,AAPL,0.0,0.0,-400.0,0.0,0.0,0.0,0.0,0.0,0.0,0.0,0.0,-25.366465131547834,
2024-10-21T12:10:57.184898920Z,2024-10-21T12:10:57.184732013Z,10,2,38,A,B,1,233.82,200,130,166907,12265734,233.9,234.0,11,154,2,7,233.82,234.06,200,200,1,1,233.76,234.13,27,427,1,2,233.7,234.17,1200,1,1,1,233.66,234.41,1,600,1,2,233.58,234.43,505,105,2,2,233.53,234.5,10,63,1,4,233.5,234.75,100,1,1,1,233.45,234.79,15,2000,1,1,233.4,234.89,110,2,2,2,AAPL,0.0,0.0,200.0,0.0,0.0,0.0,0.0,0.0,0.0,0.0,0.0,12.683232565773917,
2024-10-21T12:10:57.590098060Z,2024-10-21T12:10:57.589931819Z,10,2,38,A,B,1,233.83,200,130,166241,12266072,233.9,234.0,11,154,2,7,233.83,234.06,200,200,1,1,233.76,234.13,27,427,1,2,233.7,234.17,1200,1,1,1,233.66,234.41,1,600,1,2,233.58,234.43,505,105,2,2,233.53,234.5,10,63,1,4,233.5,234.75,100,1,1,1,233.45,234.79,15,2000,1,1,233.4,234.89,110,2,2,2,AAPL,0.0,0.0,200.0,0.0,0.0,0.0,0.0,0.0,0.0,0.0,0.0,12.683232565773917,
2024-10-21T12:10:57.806772384Z,2024-10-21T12:10:57.806606311Z,10,2,38,C,B,1,233.83,200,130,166073,12266374,233.9,234.0,11,154,2,7,233.76,234.06,27,200,1,1,233.7,234.13,1200,427,1,2,233.66,234.17,1,1,1,1,233.58,234.41,505,600,2,2,233.53,234.43,10,105,1,2,233.5,234.5,100,63,1,4,233.45,234.75,15,1,1,1,233.4,234.79,110,2000,2,1,233.39,234.89,10,2,1,2,AAPL,0.0,0.0,-200.0,-27.0,-1200.0,-1.0,-505.0,-10.0,-100.0,-15.0,-110.0,-351.3234761904883,
2024-10-21T12:10:57.806785593Z,2024-10-21T12:10:57.806619389Z,10,2,38,A,B,1,233.78,400,130,166204,12266375,233.9,234.0,11,154,2,7,233.78,234.06,400,200,1,1,233.76,234.13,27,427,1,2,233.7,234.17,1200,1,1,1,233.66,234.41,1,600,1,2,233.58,234.43,505,105,2,2,233.53,234.5,10,63,1,4,233.5,234.75,100,1,1,1,233.45,234.79,15,2000,1,1,233.4,234.89,110,2,2,2,AAPL,0.0,0.0,400.0,27.0,1200.0,1.0,505.0,10.0,100.0,15.0,110.0,364.0067087562622,
2024-10-21T12:10:59.771275683Z,2024-10-21T12:10:59.771109174Z,10,2,38,C,B,2,233.76,27,130,166509,12268147,233.9,234.0,11,154,2,7,233.78,234.06,400,200,1,1,233.7,234.13,1200,427,1,2,233.66,234.17,1,1,1,1,233.58,234.41,505,600,2,2,233.53,234.43,10,105,1,2,233.5,234.5,100,63,1,4,233.45,234.75,15,1,1,1,233.4,234.79,110,2000,2,1,233.39,234.89,10,2,1,2,AAPL,0.0,0.0,0.0,-27.0,-1200.0,-1.0,-505.0,-10.0,-100.0,-15.0,-110.0,-338.64024362471434,
2024-10-21T12:10:59.771327492Z,2024-10-21T12:10:59.771161194Z,10,2,38,A,B,2,233.77,30,130,166298,12268148,233.9,234.0,11,154,2,7,233.78,234.06,400,200,1,1,233.77,234.13,30,427,1,2,233.7,234.17,1200,1,1,1,233.66,234.41,1,600,1,2,233.58,234.43,505,105,2,2,233.53,234.5,10,63,1,4,233.5,234.75,100,1,1,1,233.45,234.79,15,2000,1,1,233.4,234.89,110,2,2,2,AAPL,0.0,0.0,0.0,30.0,1200.0,1.0,505.0,10.0,100.0,15.0,110.0,338.94499136692235,
2024-10-21T12:11:00.807783551Z,2024-10-21T12:11:00.807617417Z,10,2,38,C,B,2,233.77,30,130,166134,12269676,233.9,234.0,11,154,2,7,233.78,234.06,400,200,1,1,233.7,234.13,1200,427,1,2,233.66,234.17,1,1,1,1,233.58,234.41,505,600,2,2,233.53,234.43,10,105,1,2,233.5,234.5,100,63,1,4,233.45,234.75,15,1,1,1,233.4,234.79,110,2000,2,1,233.39,234.89,10,2,1,2,AAPL,0.0,0.0,0.0,-30.0,-1200.0,-1.0,-505.0,-10.0,-100.0,-15.0,-110.0,-338.94499136692235,
2024-10-21T12:11:00.807824165Z,2024-10-21T12:11:00.807657573Z,10,2,38,A,B,1,233.82,26,130,166592,12269677,233.9,234.0,11,154,2,7,233.82,234.06,26,200,1,1,233.78,234.13,400,427,1,2,233.7,234.17,1200,1,1,1,233.66,234.41,1,600,1,2,233.58,234.43,505,105,2,2,233.53,234.5,10,63,1,4,233.5,234.75,100,1,1,1,233.45,234.79,15,2000,1,1,233.4,234.89,110,2,2,2,AAPL,0.0,0.0,26.0,400.0,1200.0,1.0,505.0,10.0,100.0,15.0,110.0,378.1793664727949,
2024-10-21T12:11:00.863321742Z,2024-10-21T12:11:00.863155159Z,10,2,38,A,B,1,233.87,200,130,166583,12269733,233.9,234.0,11,154,2,7,233.87,234.06,200,200,1,1,233.82,234.13,26,427,1,2,233.7,234.17,1200,1,1,1,233.66,234.41,1,600,1,2,233.58,234.43,505,105,2,2,233.53,234.5,10,63,1,4,233.5,234.75,100,1,1,1,233.45,234.79,15,2000,1,1,233.4,234.89,110,2,2,2,AAPL,0.0,0.0,200.0,26.0,0.0,0.0,0.0,0.0,0.0,0.0,0.0,15.324379664910053,
2024-10-21T12:11:02.807267623Z,2024-10-21T12:11:02.807100841Z,10,2,38,A,B,1,233.88,200,130,166782,12271687,233.9,234.0,11,154,2,7,233.88,234.06,200,200,1,1,233.82,234.13,26,427,1,2,233.7,234.17,1200,1,1,1,233.66,234.41,1,600,1,2,233.58,234.43,505,105,2,2,233.53,234.5,10,63,1,4,233.5,234.75,100,1,1,1,233.45,234.79,15,2000,1,1,233.4,234.89,110,2,2,2,AAPL,0.0,0.0,200.0,0.0,0.0,0.0,0.0,0.0,0.0,0.0,0.0,12.683232565773917,
2024-10-21T12:11:08.220481984Z,2024-10-21T12:11:08.220315875Z,10,2,38,C,B,1,233.88,200,130,166109,12275485,233.9,234.0,11,154,2,7,233.82,234.06,26,200,1,1,233.7,234.13,1200,427,1,2,233.66,234.17,1,1,1,1,233.58,234.41,505,600,2,2,233.53,234.43,10,105,1,2,233.5,234.5,100,63,1,4,233.45,234.75,15,1,1,1,233.4,234.79,110,2000,2,1,233.39,234.89,10,2,1,2,AAPL,0.0,0.0,-200.0,-26.0,-1200.0,-1.0,-505.0,-10.0,-100.0,-15.0,-110.0,-351.22189360975227,
2024-10-21T12:11:08.291615657Z,2024-10-21T12:11:08.291449117Z,10,2,38,A,B,2,233.78,400,130,166540,12275506,233.9,234.0,11,154,2,7,233.82,234.06,26,200,1,1,233.78,234.13,400,427,1,2,233.7,234.17,1200,1,1,1,233.66,234.41,1,600,1,2,233.58,234.43,505,105,2,2,233.53,234.5,10,63,1,4,233.5,234.75,100,1,1,1,233.45,234.79,15,2000,1,1,233.4,234.89,110,2,2,2,AAPL,0.0,0.0,0.0,400.0,1200.0,1.0,505.0,10.0,100.0,15.0,110.0,376.5305462392443,
2024-10-21T12:11:08.292173149Z,2024-10-21T12:11:08.292006615Z,10,2,38,A,B,3,233.76,27,130,166534,12275507,233.9,234.0,11,154,2,7,233.82,234.06,26,200,1,1,233.78,234.13,400,427,1,2,233.76,234.17,27,1,1,1,233.7,234.41,1200,600,1,2,233.66,234.43,1,105,1,2,233.58,234.5,505,63,2,4,233.53,234.75,10,1,1,1,233.5,234.79,100,2000,1,1,233.45,234.89,15,2,1,2,AAPL,0.0,0.0,0.0,0.0,27.0,1200.0,1.0,505.0,10.0,100.0,15.0,211.92558116049736,
2024-10-21T12:11:08.292210524Z,2024-10-21T12:11:08.292044305Z,10,2,38,C,B,1,233.82,26,130,166219,12275508,233.9,234.0,11,154,2,7,233.78,234.06,400,200,1,1,233.76,234.13,27,427,1,2,233.7,234.17,1200,1,1,1,233.66,234.41,1,600,1,2,233.58,234.43,505,105,2,2,233.53,234.5,10,63,1,4,233.5,234.75,100,1,1,1,233.45,234.79,15,2000,1,1,233.4,234.89,110,2,2,2,AAPL,0.0,0.0,-26.0,-400.0,-27.0,-1200.0,-1.0,-505.0,-10.0,-100.0,-15.0,-254.20743368845007,
2024-10-21T12:11:10.442776750Z,2024-10-21T12:11:10.442610415Z,10,2,38,A,B,1,233.79,400,130,166335,12277136,233.9,234.0,11,154,2,7,233.79,234.06,400,200,1,1,233.76,234.13,27,427,1,2,233.7,234.17,1200,1,1,1,233.66,234.41,1,600,1,2,233.58,234.43,505,105,2,2,233.53,234.5,10,63,1,4,233.5,234.75,100,1,1,1,233.45,234.79,15,2000,1,1,233.4,234.89,110,2,2,2,AAPL,0.0,0.0,400.0,0.0,0.0,0.0,0.0,0.0,0.0,0.0,0.0,25.366465131547834,
2024-10-21T12:11:10.454952399Z,2024-10-21T12:11:10.454786222Z,10,2,38,C,B,2,233.76,27,130,166177,12277212,233.9,234.0,11,154,2,7,233.79,234.06,400,200,1,1,233.7,234.13,1200,427,1,2,233.66,234.17,1,1,1,1,233.58,234.41,505,600,2,2,233.53,234.43,10,105,1,2,233.5,234.5,100,63,1,4,233.45,234.75,15,1,1,1,233.4,234.79,110,2000,2,1,233.39,234.89,10,2,1,2,AAPL,0.0,0.0,0.0,-27.0,-1200.0,-1.0,-505.0,-10.0,-100.0,-15.0,-110.0,-338.64024362471434,
2024-10-21T12:11:10.455002886Z,2024-10-21T12:11:10.454836386Z,10,2,38,A,B,2,233.77,27,130,166500,12277213,233.9,234.0,11,154,2,7,233.79,234.06,400,200,1,1,233.77,234.13,27,427,1,2,233.7,234.17,1200,1,1,1,233.66,234.41,1,600,1,2,233.58,234.43,505,105,2,2,233.53,234.5,10,63,1,4,233.5,234.75,100,1,1,1,233.45,234.79,15,2000,1,1,233.4,234.89,110,2,2,2,AAPL,0.0,0.0,0.0,27.0,1200.0,1.0,505.0,10.0,100.0,15.0,110.0,338.64024362471434,
2024-10-21T12:11:11.346401450Z,2024-10-21T12:11:11.346234393Z,10,2,38,A,B,1,233.83,200,130,167057,12278338,233.9,234.0,11,154,2,7,233.83,234.06,200,200,1,1,233.77,234.13,27,427,1,2,233.7,234.17,1200,1,1,1,233.66,234.41,1,600,1,2,233.58,234.43,505,105,2,2,233.53,234.5,10,63,1,4,233.5,234.75,100,1,1,1,233.45,234.79,15,2000,1,1,233.4,234.89,110,2,2,2,AAPL,0.0,0.0,200.0,0.0,0.0,0.0,0.0,0.0,0.0,0.0,0.0,12.683232565773917,
2024-10-21T12:11:18.869806122Z,2024-10-21T12:11:18.869640062Z,10,2,38,C,B,1,233.83,200,130,166060,12284656,233.9,234.0,11,154,2,7,233.77,234.06,27,200,1,1,233.7,234.13,1200,427,1,2,233.66,234.17,1,1,1,1,233.58,234.41,505,600,2,2,233.53,234.43,10,105,1,2,233.5,234.5,100,63,1,4,233.45,234.75,15,1,1,1,233.4,234.79,110,2000,2,1,233.39,234.89,10,2,1,2,AAPL,0.0,0.0,-200.0,-27.0,-1200.0,-1.0,-505.0,-10.0,-100.0,-15.0,-110.0,-351.3234761904883,
2024-10-21T12:11:18.869819499Z,2024-10-21T12:11:18.869653217Z,10,2,38,A,B,1,233.78,400,130,166282,12284657,233.9,234.0,11,154,2,7,233.78,234.06,400,200,1,1,233.77,234.13,27,427,1,2,233.7,234.17,1200,1,1,1,233.66,234.41,1,600,1,2,233.58,234.43,505,105,2,2,233.53,234.5,10,63,1,4,233.5,234.75,100,1,1,1,233.45,234.79,15,2000,1,1,233.4,234.89,110,2,2,2,AAPL,0.0,0.0,400.0,27.0,1200.0,1.0,505.0,10.0,100.0,15.0,110.0,364.0067087562622,
2024-10-21T12:11:21.873509615Z,2024-10-21T12:11:21.873343400Z,10,2,38,C,B,2,233.77,27,130,166215,12287082,233.9,234.0,11,154,2,7,233.78,234.06,400,200,1,1,233.7,234.13,1200,427,1,2,233.66,234.17,1,1,1,1,233.58,234.41,505,600,2,2,233.53,234.43,10,105,1,2,233.5,234.5,100,63,1,4,233.45,234.75,15,1,1,1,233.4,234.79,110,2000,2,1,233.39,234.89,10,2,1,2,AAPL,0.0,0.0,0.0,-27.0,-1200.0,-1.0,-505.0,-10.0,-100.0,-15.0,-110.0,-338.64024362471434,
2024-10-21T12:11:21.873599230Z,2024-10-21T12:11:21.873432987Z,10,2,38,A,B,1,233.81,26,130,166243,12287083,233.9,234.0,11,154,2,7,233.81,234.06,26,200,1,1,233.78,234.13,400,427,1,2,233.7,234.17,1200,1,1,1,233.66,234.41,1,600,1,2,233.58,234.43,505,105,2,2,233.53,234.5,10,63,1,4,233.5,234.75,100,1,1,1,233.45,234.79,15,2000,1,1,233.4,234.89,110,2,2,2,AAPL,0.0,0.0,26.0,400.0,1200.0,1.0,505.0,10.0,100.0,15.0,110.0,378.1793664727949,
2024-10-21T12:11:21.928420269Z,2024-10-21T12:11:21.928253749Z,10,2,38,A,B,1,233.86,200,130,166520,12287102,233.9,234.0,11,154,2,7,233.86,234.06,200,200,1,1,233.81,234.13,26,427,1,2,233.7,234.17,1200,1,1,1,233.66,234.41,1,600,1,2,233.58,234.43,505,105,2,2,233.53,234.5,10,63,1,4,233.5,234.75,100,1,1,1,233.45,234.79,15,2000,1,1,233.4,234.89,110,2,2,2,AAPL,0.0,0.0,200.0,26.0,0.0,0.0,0.0,0.0,0.0,0.0,0.0,15.324379664910053,
2024-10-21T12:11:22.072521728Z,2024-10-21T12:11:22.072355634Z,10,2,38,C,B,1,233.86,200,130,166094,12287179,233.9,234.0,11,154,2,7,233.81,234.06,26,200,1,1,233.7,234.13,1200,427,1,2,233.66,234.17,1,1,1,1,233.58,234.41,505,600,2,2,233.53,234.43,10,105,1,2,233.5,234.5,100,63,1,4,233.45,234.75,15,1,1,1,233.4,234.79,110,2000,2,1,233.39,234.89,10,2,1,2,AAPL,0.0,0.0,-200.0,-26.0,-1200.0,-1.0,-505.0,-10.0,-100.0,-15.0,-110.0,-351.22189360975227,
2024-10-21T12:11:22.072534773Z,2024-10-21T12:11:22.072368471Z,10,2,38,A,B,2,233.78,400,130,166302,12287180,233.9,234.0,11,154,2,7,233.81,234.06,26,200,1,1,233.78,234.13,400,427,1,2,233.7,234.17,1200,1,1,1,233.66,234.41,1,600,1,2,233.58,234.43,505,105,2,2,233.53,234.5,10,63,1,4,233.5,234.75,100,1,1,1,233.45,234.79,15,2000,1,1,233.4,234.89,110,2,2,2,AAPL,0.0,0.0,0.0,400.0,1200.0,1.0,505.0,10.0,100.0,15.0,110.0,376.5305462392443,
2024-10-21T12:11:22.073030139Z,2024-10-21T12:11:22.072864187Z,10,2,38,C,B,1,233.81,26,130,165952,12287181,233.9,234.0,11,154,2,7,233.78,234.06,400,200,1,1,233.7,234.13,1200,427,1,2,233.66,234.17,1,1,1,1,233.58,234.41,505,600,2,2,233.53,234.43,10,105,1,2,233.5,234.5,100,63,1,4,233.45,234.75,15,1,1,1,233.4,234.79,110,2000,2,1,233.39,234.89,10,2,1,2,AAPL,0.0,0.0,-26.0,-400.0,-1200.0,-1.0,-505.0,-10.0,-100.0,-15.0,-110.0,-378.1793664727949,
2024-10-21T12:11:22.938136138Z,2024-10-21T12:11:22.937969054Z,10,2,38,T,N,0,233.98,4,130,167084,12287694,233.9,234.0,11,154,2,7,233.78,234.06,400,200,1,1,233.7,234.13,1200,427,1,2,233.66,234.17,1,1,1,1,233.58,234.41,505,600,2,2,233.53,234.43,10,105,1,2,233.5,234.5,100,63,1,4,233.45,234.75,15,1,1,1,233.4,234.79,110,2000,2,1,233.39,234.89,10,2,1,2,AAPL,0.0,0.0,0.0,0.0,0.0,0.0,0.0,0.0,0.0,0.0,0.0,0.0,
2024-10-21T12:11:23.001029527Z,2024-10-21T12:11:23.000862969Z,10,2,38,A,B,2,233.76,30,130,166558,12287720,233.9,234.0,11,154,2,7,233.78,234.06,400,200,1,1,233.76,234.13,30,427,1,2,233.7,234.17,1200,1,1,1,233.66,234.41,1,600,1,2,233.58,234.43,505,105,2,2,233.53,234.5,10,63,1,4,233.5,234.75,100,1,1,1,233.45,234.79,15,2000,1,1,233.4,234.89,110,2,2,2,AAPL,0.0,0.0,0.0,30.0,1200.0,1.0,505.0,10.0,100.0,15.0,110.0,338.94499136692235,
2024-10-21T12:11:25.073082417Z,2024-10-21T12:11:25.072916074Z,10,2,38,C,A,1,234.06,200,130,166343,12288985,233.9,234.0,11,154,2,7,233.78,234.13,400,427,1,2,233.76,234.17,30,1,1,1,233.7,234.41,1200,600,1,2,233.66,234.43,1,105,1,2,233.58,234.5,505,63,2,4,233.53,234.75,10,1,1,1,233.5,234.79,100,2000,1,1,233.45,234.89,15,2,1,2,233.4,235.0,110,213,2,6,AAPL,0.0,0.0,427.0,1.0,600.0,105.0,63.0,1.0,2000.0,2.0,213.0,389.7347328754314,
2024-10-21T12:11:25.073096247Z,2024-10-21T12:11:25.072929618Z,10,2,38,A,A,1,234.12,400,130,166629,12288986,233.9,234.0,11,154,2,7,233.78,234.12,400,400,1,1,233.76,234.13,30,427,1,2,233.7,234.17,1200,1,1,1,233.66,234.41,1,600,1,2,233.58,234.43,505,105,2,2,233.53,234.5,10,63,1,4,233.5,234.75,100,1,1,1,233.45,234.79,15,2000,1,1,233.4,234.89,110,2,2,2,AAPL,0.0,0.0,-427.0,-1.0,-600.0,-105.0,-63.0,-1.0,-2000.0,-2.0,-213.0,-389.7347328754314,
2024-10-21T12:11:25.073458008Z,2024-10-21T12:11:25.073291984Z,10,2,38,C,B,2,233.76,30,130,166024,12288987,233.9,234.0,11,154,2,7,233.78,234.12,400,400,1,1,233.7,234.13,1200,427,1,2,233.66,234.17,1,1,1,1,233.58,234.41,505,600,2,2,233.53,234.43,10,105,1,2,233.5,234.5,100,63,1,4,233.45,234.75,15,1,1,1,233.4,234.79,110,2000,2,1,233.39,234.89,10,2,1,2,AAPL,0.0,0.0,0.0,-30.0,-1200.0,-1.0,-505.0,-10.0,-100.0,-15.0,-110.0,-338.94499136692235,
2024-10-21T12:11:25.073555014Z,2024-10-21T12:11:25.073388717Z,10,2,38,A,B,1,233.81,26,130,166297,12288988,233.9,234.0,11,154,2,7,233.81,234.12,26,400,1,1,233.78,234.13,400,427,1,2,233.7,234.17,1200,1,1,1,233.66,234.41,1,600,1,2,233.58,234.43,505,105,2,2,233.53,234.5,10,63,1,4,233.5,234.75,100,1,1,1,233.45,234.79,15,2000,1,1,233.4,234.89,110,2,2,2,AAPL,0.0,0.0,26.0,400.0,1200.0,1.0,505.0,10.0,100.0,15.0,110.0,378.1793664727949,
2024-10-21T12:11:25.074138845Z,2024-10-21T12:11:25.073972612Z,10,2,38,C,A,2,234.13,27,130,166233,12288989,233.9,234.0,11,154,2,7,233.81,234.12,26,400,1,1,233.78,234.13,400,400,1,1,233.7,234.17,1200,1,1,1,233.66,234.41,1,600,1,2,233.58,234.43,505,105,2,2,233.53,234.5,10,63,1,4,233.5,234.75,100,1,1,1,233.45,234.79,15,2000,1,1,233.4,234.89,110,2,2,2,AAPL,0.0,0.0,0.0,27.0,0.0,0.0,0.0,0.0,0.0,0.0,0.0,2.74272967987214,
2024-10-21T12:11:25.074266365Z,2024-10-21T12:11:25.074100004Z,10,2,38,A,A,4,234.18,30,130,166361,12288990,233.9,234.0,11,154,2,7,233.81,234.12,26,400,1,1,233.78,234.13,400,400,1,1,233.7,234.17,1200,1,1,1,233.66,234.18,1,30,1,1,233.58,234.41,505,600,2,2,233.53,234.43,10,105,1,2,233.5,234.5,100,63,1,4,233.45,234.75,15,1,1,1,233.4,234.79,110,2000,2,1,AAPL,0.0,0.0,0.0,0.0,0.0,-600.0,-105.0,-63.0,-1.0,-2000.0,-2.0,-230.35874096685887,
2024-10-21T12:11:25.129461870Z,2024-10-21T12:11:25.129294511Z,10,2,38,A,B,1,233.86,200,130,167359,12289009,233.9,234.0,11,154,2,7,233.86,234.12,200,400,1,1,233.81,234.13,26,400,1,1,233.7,234.17,1200,1,1,1,233.66,234.18,1,30,1,1,233.58,234.41,505,600,2,2,233.53,234.43,10,105,1,2,233.5,234.5,100,63,1,4,233.45,234.75,15,1,1,1,233.4,234.79,110,2000,2,1,AAPL,0.0,0.0,200.0,26.0,0.0,0.0,0.0,0.0,0.0,0.0,0.0,15.324379664910053,
2024-10-21T12:11:27.120171307Z,2024-10-21T12:11:27.120005157Z,10,2,38,C,B,1,233.86,200,130,166150,12290119,233.9,234.0,11,154,2,7,233.81,234.12,26,400,1,1,233.7,234.13,1200,400,1,1,233.66,234.17,1,1,1,1,233.58,234.18,505,30,2,1,233.53,234.41,10,600,1,2,233.5,234.43,100,105,1,2,233.45,234.5,15,63,1,4,233.4,234.75,110,1,2,1,233.39,234.79,10,2000,1,1,AAPL,0.0,0.0,-200.0,-26.0,-1200.0,-1.0,-505.0,-10.0,-100.0,-15.0,-110.0,-351.22189360975227,
2024-10-21T12:11:27.120184761Z,2024-10-21T12:11:27.120018111Z,10,2,38,A,B,2,233.78,400,130,166650,12290120,233.9,234.0,11,154,2,7,233.81,234.12,26,400,1,1,233.78,234.13,400,400,1,1,233.7,234.17,1200,1,1,1,233.66,234.18,1,30,1,1,233.58,234.41,505,600,2,2,233.53,234.43,10,105,1,2,233.5,234.5,100,63,1,4,233.45,234.75,15,1,1,1,233.4,234.79,110,2000,2,1,AAPL,0.0,0.0,0.0,400.0,1200.0,1.0,505.0,10.0,100.0,15.0,110.0,376.5305462392443,
2024-10-21T12:11:27.120673190Z,2024-10-21T12:11:27.120506757Z,10,2,38,C,B,1,233.81,26,130,166433,12290123,233.9,234.0,11,154,2,7,233.78,234.12,400,400,1,1,233.7,234.13,1200,400,1,1,233.66,234.17,1,1,1,1,233.58,234.18,505,30,2,1,233.53,234.41,10,600,1,2,233.5,234.43,100,105,1,2,233.45,234.5,15,63,1,4,233.4,234.75,110,1,2,1,233.39,234.79,10,2000,1,1,AAPL,0.0,0.0,-26.0,-400.0,-1200.0,-1.0,-505.0,-10.0,-100.0,-15.0,-110.0,-378.1793664727949,
2024-10-21T12:11:27.120714598Z,2024-10-21T12:11:27.120548454Z,10,2,38,A,B,2,233.76,29,130,166144,12290124,233.9,234.0,11,154,2,7,233.78,234.12,400,400,1,1,233.76,234.13,29,400,1,1,233.7,234.17,1200,1,1,1,233.66,234.18,1,30,1,1,233.58,234.41,505,600,2,2,233.53,234.43,10,105,1,2,233.5,234.5,100,63,1,4,233.45,234.75,15,1,1,1,233.4,234.79,110,2000,2,1,AAPL,0.0,0.0,0.0,29.0,1200.0,1.0,505.0,10.0,100.0,15.0,110.0,338.84340878618633,
2024-10-21T12:11:27.120816314Z,2024-10-21T12:11:27.120650159Z,10,2,38,A,A,2,234.13,27,130,166155,12290125,233.9,234.0,11,154,2,7,233.78,234.12,400,400,1,1,233.76,234.13,29,427,1,2,233.7,234.17,1200,1,1,1,233.66,234.18,1,30,1,1,233.58,234.41,505,600,2,2,233.53,234.43,10,105,1,2,233.5,234.5,100,63,1,4,233.45,234.75,15,1,1,1,233.4,234.79,110,2000,2,1,AAPL,0.0,0.0,0.0,-27.0,0.0,0.0,0.0,0.0,0.0,0.0,0.0,-2.74272967987214,
2024-10-21T12:11:27.120886583Z,2024-10-21T12:11:27.120720548Z,10,2,38,C,A,4,234.18,30,130,166035,12290126,233.9,234.0,11,154,2,7,233.78,234.12,400,400,1,1,233.76,234.13,29,427,1,2,233.7,234.17,1200,1,1,1,233.66,234.41,1,600,1,2,233.58,234.43,505,105,2,2,233.53,234.5,10,63,1,4,233.5,234.75,100,1,1,1,233.45,234.79,15,2000,1,1,233.4,234.89,110,2,2,2,AAPL,0.0,0.0,0.0,0.0,0.0,600.0,105.0,63.0,1.0,2000.0,2.0,230.35874096685887,
2024-10-21T12:11:27.177695699Z,2024-10-21T12:11:27.177529449Z,10,2,38,A,A,1,234.06,200,130,166250,12290153,233.9,234.0,11,154,2,7,233.78,234.06,400,200,1,1,233.76,234.13,29,427,1,2,233.7,234.17,1200,1,1,1,233.66,234.41,1,600,1,2,233.58,234.43,505,105,2,2,233.53,234.5,10,63,1,4,233.5,234.75,100,1,1,1,233.45,234.79,15,2000,1,1,233.4,234.89,110,2,2,2,AAPL,0.0,0.0,-400.0,0.0,0.0,0.0,0.0,0.0,0.0,0.0,0.0,-25.366465131547834,
2024-10-21T12:11:30.179271563Z,2024-10-21T12:11:30.179103980Z,10,2,38,A,B,1,233.82,200,130,167583,12292157,233.9,234.0,11,154,2,7,233.82,234.06,200,200,1,1,233.76,234.13,29,427,1,2,233.7,234.17,1200,1,1,1,233.66,234.41,1,600,1,2,233.58,234.43,505,105,2,2,233.53,234.5,10,63,1,4,233.5,234.75,100,1,1,1,233.45,234.79,15,2000,1,1,233.4,234.89,110,2,2,2,AAPL,0.0,0.0,200.0,0.0,0.0,0.0,0.0,0.0,0.0,0.0,0.0,12.683232565773917,
2024-10-21T12:11:34.156557363Z,2024-10-21T12:11:34.156391256Z,10,2,38,C,B,1,233.82,200,130,166107,12294618,233.9,234.0,11,154,2,7,233.76,234.06,29,200,1,1,233.7,234.13,1200,427,1,2,233.66,234.17,1,1,1,1,233.58,234.41,505,600,2,2,233.53,234.43,10,105,1,2,233.5,234.5,100,63,1,4,233.45,234.75,15,1,1,1,233.4,234.79,110,2000,2,1,233.39,234.89,10,2,1,2,AAPL,0.0,0.0,-200.0,-29.0,-1200.0,-1.0,-505.0,-10.0,-100.0,-15.0,-110.0,-351.5266413519603,
2024-10-21T12:11:34.156569858Z,2024-10-21T12:11:34.156403417Z,10,2,38,A,B,1,233.78,400,130,166441,12294619,233.9,234.0,11,154,2,7,233.78,234.06,400,200,1,1,233.76,234.13,29,427,1,2,233.7,234.17,1200,1,1,1,233.66,234.41,1,600,1,2,233.58,234.43,505,105,2,2,233.53,234.5,10,63,1,4,233.5,234.75,100,1,1,1,233.45,234.79,15,2000,1,1,233.4,234.89,110,2,2,2,AAPL,0.0,0.0,400.0,29.0,1200.0,1.0,505.0,10.0,100.0,15.0,110.0,364.20987391773417,
2024-10-21T12:11:36.738842101Z,2024-10-21T12:11:36.738675617Z,10,2,38,C,B,0,233.9,1,130,166484,12295779,233.9,234.0,10,154,1,7,233.78,234.06,400,200,1,1,233.76,234.13,29,427,1,2,233.7,234.17,1200,1,1,1,233.66,234.41,1,600,1,2,233.58,234.43,505,105,2,2,233.53,234.5,10,63,1,4,233.5,234.75,100,1,1,1,233.45,234.79,15,2000,1,1,233.4,234.89,110,2,2,2,AAPL,-1.0,-1.0,0.0,0.0,0.0,0.0,0.0,0.0,0.0,0.0,0.0,-0.01988058264612502,
2024-10-21T12:11:37.211098382Z,2024-10-21T12:11:37.210931791Z,10,2,38,A,B,1,233.82,200,130,166591,12295954,233.9,234.0,10,154,1,7,233.82,234.06,200,200,1,1,233.76,234.13,29,427,1,2,233.7,234.17,1200,1,1,1,233.66,234.41,1,600,1,2,233.58,234.43,505,105,2,2,233.53,234.5,10,63,1,4,233.5,234.75,100,1,1,1,233.45,234.79,15,2000,1,1,233.4,234.89,110,2,2,2,AAPL,0.0,0.0,200.0,0.0,0.0,0.0,0.0,0.0,0.0,0.0,0.0,12.683232565773917,
2024-10-21T12:11:40.138648473Z,2024-10-21T12:11:40.138482175Z,10,2,38,C,B,1,233.82,200,130,166298,12298108,233.9,234.0,10,154,1,7,233.76,234.06,29,200,1,1,233.7,234.13,1200,427,1,2,233.66,234.17,1,1,1,1,233.58,234.41,505,600,2,2,233.53,234.43,10,105,1,2,233.5,234.5,100,63,1,4,233.45,234.75,15,1,1,1,233.4,234.79,110,2000,2,1,233.39,234.89,10,2,1,2,AAPL,0.0,0.0,-200.0,-29.0,-1200.0,-1.0,-505.0,-10.0,-100.0,-15.0,-110.0,-351.5266413519603,
2024-10-21T12:11:40.138664034Z,2024-10-21T12:11:40.138496802Z,10,2,38,A,B,1,233.78,400,130,167232,12298109,233.9,234.0,10,154,1,7,233.78,234.06,400,200,1,1,233.76,234.13,29,427,1,2,233.7,234.17,1200,1,1,1,233.66,234.41,1,600,1,2,233.58,234.43,505,105,2,2,233.53,234.5,10,63,1,4,233.5,234.75,100,1,1,1,233.45,234.79,15,2000,1,1,233.4,234.89,110,2,2,2,AAPL,0.0,0.0,400.0,29.0,1200.0,1.0,505.0,10.0,100.0,15.0,110.0,364.20987391773417,
2024-10-21T12:11:43.193642005Z,2024-10-21T12:11:43.193475620Z,10,2,38,A,B,1,233.82,200,130,166385,12299803,233.9,234.0,10,154,1,7,233.82,234.06,200,200,1,1,233.76,234.13,29,427,1,2,233.7,234.17,1200,1,1,1,233.66,234.41,1,600,1,2,233.58,234.43,505,105,2,2,233.53,234.5,10,63,1,4,233.5,234.75,100,1,1,1,233.45,234.79,15,2000,1,1,233.4,234.89,110,2,2,2,AAPL,0.0,0.0,200.0,0.0,0.0,0.0,0.0,0.0,0.0,0.0,0.0,12.683232565773917,
2024-10-21T12:11:45.774890873Z,2024-10-21T12:11:45.774723015Z,10,2,38,T,N,0,233.98,50,130,167858,12301317,233.9,234.0,10,154,1,7,233.82,234.06,200,200,1,1,233.76,234.13,29,427,1,2,233.7,234.17,1200,1,1,1,233.66,234.41,1,600,1,2,233.58,234.43,505,105,2,2,233.53,234.5,10,63,1,4,233.5,234.75,100,1,1,1,233.45,234.79,15,2000,1,1,233.4,234.89,110,2,2,2,AAPL,0.0,0.0,0.0,0.0,0.0,0.0,0.0,0.0,0.0,0.0,0.0,0.0,
2024-10-21T12:11:45.844109427Z,2024-10-21T12:11:45.843943302Z,10,2,38,C,B,1,233.82,200,130,166125,12301621,233.9,234.0,10,154,1,7,233.76,234.06,29,200,1,1,233.7,234.13,1200,427,1,2,233.66,234.17,1,1,1,1,233.58,234.41,505,600,2,2,233.53,234.43,10,105,1,2,233.5,234.5,100,63,1,4,233.45,234.75,15,1,1,1,233.4,234.79,110,2000,2,1,233.39,234.89,10,2,1,2,AAPL,0.0,0.0,-200.0,-29.0,-1200.0,-1.0,-505.0,-10.0,-100.0,-15.0,-110.0,-351.5266413519603,
2024-10-21T12:11:45.844122189Z,2024-10-21T12:11:45.843955896Z,10,2,38,A,B,1,233.78,400,130,166293,12301622,233.9,234.0,10,154,1,7,233.78,234.06,400,200,1,1,233.76,234.13,29,427,1,2,233.7,234.17,1200,1,1,1,233.66,234.41,1,600,1,2,233.58,234.43,505,105,2,2,233.53,234.5,10,63,1,4,233.5,234.75,100,1,1,1,233.45,234.79,15,2000,1,1,233.4,234.89,110,2,2,2,AAPL,0.0,0.0,400.0,29.0,1200.0,1.0,505.0,10.0,100.0,15.0,110.0,364.20987391773417,
2024-10-21T12:11:48.580889153Z,2024-10-21T12:11:48.580722768Z,10,2,38,A,B,1,233.79,400,130,166385,12303381,233.9,234.0,10,154,1,7,233.79,234.06,400,200,1,1,233.76,234.13,29,427,1,2,233.7,234.17,1200,1,1,1,233.66,234.41,1,600,1,2,233.58,234.43,505,105,2,2,233.53,234.5,10,63,1,4,233.5,234.75,100,1,1,1,233.45,234.79,15,2000,1,1,233.4,234.89,110,2,2,2,AAPL,0.0,0.0,400.0,0.0,0.0,0.0,0.0,0.0,0.0,0.0,0.0,25.366465131547834,
2024-10-21T12:11:48.598638403Z,2024-10-21T12:11:48.598471411Z,10,2,38,C,B,2,233.76,29,130,166992,12303469,233.9,234.0,10,154,1,7,233.79,234.06,400,200,1,1,233.7,234.13,1200,427,1,2,233.66,234.17,1,1,1,1,233.58,234.41,505,600,2,2,233.53,234.43,10,105,1,2,233.5,234.5,100,63,1,4,233.45,234.75,15,1,1,1,233.4,234.79,110,2000,2,1,233.39,234.89,10,2,1,2,AAPL,0.0,0.0,0.0,-29.0,-1200.0,-1.0,-505.0,-10.0,-100.0,-15.0,-110.0,-338.84340878618633,
2024-10-21T12:11:48.598681245Z,2024-10-21T12:11:48.598514970Z,10,2,38,A,B,2,233.77,28,130,166275,12303470,233.9,234.0,10,154,1,7,233.79,234.06,400,200,1,1,233.77,234.13,28,427,1,2,233.7,234.17,1200,1,1,1,233.66,234.41,1,600,1,2,233.58,234.43,505,105,2,2,233.53,234.5,10,63,1,4,233.5,234.75,100,1,1,1,233.45,234.79,15,2000,1,1,233.4,234.89,110,2,2,2,AAPL,0.0,0.0,0.0,28.0,1200.0,1.0,505.0,10.0,100.0,15.0,110.0,338.74182620545037,
2024-10-21T12:11:48.899213107Z,2024-10-21T12:11:48.899046660Z,10,2,38,A,B,1,233.83,200,130,166447,12303858,233.9,234.0,10,154,1,7,233.83,234.06,200,200,1,1,233.77,234.13,28,427,1,2,233.7,234.17,1200,1,1,1,233.66,234.41,1,600,1,2,233.58,234.43,505,105,2,2,233.53,234.5,10,63,1,4,233.5,234.75,100,1,1,1,233.45,234.79,15,2000,1,1,233.4,234.89,110,2,2,2,AAPL,0.0,0.0,200.0,0.0,0.0,0.0,0.0,0.0,0.0,0.0,0.0,12.683232565773917,
2024-10-21T12:11:50.835087071Z,2024-10-21T12:11:50.834920978Z,10,2,38,C,B,1,233.83,200,130,166093,12305321,233.9,234.0,10,154,1,7,233.77,234.06,28,200,1,1,233.7,234.13,1200,427,1,2,233.66,234.17,1,1,1,1,233.58,234.41,505,600,2,2,233.53,234.43,10,105,1,2,233.5,234.5,100,63,1,4,233.45,234.75,15,1,1,1,233.4,234.79,110,2000,2,1,233.39,234.89,10,2,1,2,AAPL,0.0,0.0,-200.0,-28.0,-1200.0,-1.0,-505.0,-10.0,-100.0,-15.0,-110.0,-351.42505877122426,
2024-10-21T12:11:50.924256645Z,2024-10-21T12:11:50.924089402Z,10,2,38,A,B,1,233.83,200,130,167243,12305429,233.9,234.0,10,154,1,7,233.83,234.06,200,200,1,1,233.77,234.13,28,427,1,2,233.7,234.17,1200,1,1,1,233.66,234.41,1,600,1,2,233.58,234.43,505,105,2,2,233.53,234.5,10,63,1,4,233.5,234.75,100,1,1,1,233.45,234.79,15,2000,1,1,233.4,234.89,110,2,2,2,AAPL,0.0,0.0,200.0,28.0,1200.0,1.0,505.0,10.0,100.0,15.0,110.0,351.42505877122426,
2024-10-21T12:11:53.326738713Z,2024-10-21T12:11:53.326572732Z,10,2,38,C,B,1,233.83,200,130,165981,12306983,233.9,234.0,10,154,1,7,233.77,234.06,28,200,1,1,233.7,234.13,1200,427,1,2,233.66,234.17,1,1,1,1,233.58,234.41,505,600,2,2,233.53,234.43,10,105,1,2,233.5,234.5,100,63,1,4,233.45,234.75,15,1,1,1,233.4,234.79,110,2000,2,1,233.39,234.89,10,2,1,2,AAPL,0.0,0.0,-200.0,-28.0,-1200.0,-1.0,-505.0,-10.0,-100.0,-15.0,-110.0,-351.42505877122426,
2024-10-21T12:11:53.326752130Z,2024-10-21T12:11:53.326585955Z,10,2,38,A,B,1,233.79,400,130,166175,12306984,233.9,234.0,10,154,1,7,233.79,234.06,400,200,1,1,233.77,234.13,28,427,1,2,233.7,234.17,1200,1,1,1,233.66,234.41,1,600,1,2,233.58,234.43,505,105,2,2,233.53,234.5,10,63,1,4,233.5,234.75,100,1,1,1,233.45,234.79,15,2000,1,1,233.4,234.89,110,2,2,2,AAPL,0.0,0.0,400.0,28.0,1200.0,1.0,505.0,10.0,100.0,15.0,110.0,364.1082913369982,
2024-10-21T12:11:56.382644560Z,2024-10-21T12:11:56.382477901Z,10,2,38,A,B,1,233.83,200,130,166659,12309100,233.9,234.0,10,154,1,7,233.83,234.06,200,200,1,1,233.77,234.13,28,427,1,2,233.7,234.17,1200,1,1,1,233.66,234.41,1,600,1,2,233.58,234.43,505,105,2,2,233.53,234.5,10,63,1,4,233.5,234.75,100,1,1,1,233.45,234.79,15,2000,1,1,233.4,234.89,110,2,2,2,AAPL,0.0,0.0,200.0,0.0,0.0,0.0,0.0,0.0,0.0,0.0,0.0,12.683232565773917,
2024-10-21T12:12:02.086696137Z,2024-10-21T12:12:02.086529609Z,10,2,38,A,A,0,233.97,20,130,166528,12315842,233.9,233.97,10,20,1,1,233.83,234.0,200,154,1,7,233.77,234.06,28,200,1,1,233.7,234.13,1200,427,1,2,233.66,234.17,1,1,1,1,233.58,234.41,505,600,2,2,233.53,234.43,10,105,1,2,233.5,234.5,100,63,1,4,233.45,234.75,15,1,1,1,233.4,234.79,110,2000,2,1,AAPL,-154.0,-154.0,-200.0,-427.0,-1.0,-600.0,-105.0,-63.0,-1.0,-2000.0,-2.0,-289.68442228943434,
2024-10-21T12:12:02.213968660Z,2024-10-21T12:12:02.213802116Z,10,2,38,C,B,1,233.83,200,130,166544,12315992,233.9,233.97,10,20,1,1,233.77,234.0,28,154,1,7,233.7,234.06,1200,200,1,1,233.66,234.13,1,427,1,2,233.58,234.17,505,1,2,1,233.53,234.41,10,600,1,2,233.5,234.43,100,105,1,2,233.45,234.5,15,63,1,4,233.4,234.75,110,1,2,1,233.39,234.79,10,2000,1,1,AAPL,0.0,0.0,-200.0,-28.0,-1200.0,-1.0,-505.0,-10.0,-100.0,-15.0,-110.0,-351.42505877122426,
2024-10-21T12:12:02.316815369Z,2024-10-21T12:12:02.316648939Z,10,2,38,A,B,1,233.82,200,130,166430,12316513,233.9,233.97,10,20,1,1,233.82,234.0,200,154,1,7,233.77,234.06,28,200,1,1,233.7,234.13,1200,427,1,2,233.66,234.17,1,1,1,1,233.58,234.41,505,600,2,2,233.53,234.43,10,105,1,2,233.5,234.5,100,63,1,4,233.45,234.75,15,1,1,1,233.4,234.79,110,2000,2,1,AAPL,0.0,0.0,200.0,28.0,1200.0,1.0,505.0,10.0,100.0,15.0,110.0,351.42505877122426,
2024-10-21T12:12:08.967352049Z,2024-10-21T12:12:08.967185824Z,10,2,38,C,A,0,233.97,20,130,166225,12322349,233.9,234.0,10,154,1,7,233.82,234.06,200,200,1,1,233.77,234.13,28,427,1,2,233.7,234.17,1200,1,1,1,233.66,234.41,1,600,1,2,233.58,234.43,505,105,2,2,233.53,234.5,10,63,1,4,233.5,234.75,100,1,1,1,233.45,234.79,15,2000,1,1,233.4,234.89,110,2,2,2,AAPL,154.0,154.0,200.0,427.0,1.0,600.0,105.0,63.0,1.0,2000.0,2.0,289.68442228943434,
2024-10-21T12:12:08.996872145Z,2024-10-21T12:12:08.996704242Z,10,2,38,T,N,0,233.96,4,130,167903,12322367,233.9,234.0,10,154,1,7,233.82,234.06,200,200,1,1,233.77,234.13,28,427,1,2,233.7,234.17,1200,1,1,1,233.66,234.41,1,600,1,2,233.58,234.43,505,105,2,2,233.53,234.5,10,63,1,4,233.5,234.75,100,1,1,1,233.45,234.79,15,2000,1,1,233.4,234.89,110,2,2,2,AAPL,0.0,0.0,0.0,0.0,0.0,0.0,0.0,0.0,0.0,0.0,0.0,0.0,
2024-10-21T12:12:08.996899848Z,2024-10-21T12:12:08.996733815Z,10,2,38,C,B,1,233.82,200,130,166033,12322368,233.9,234.0,10,154,1,7,233.77,234.06,28,200,1,1,233.7,234.13,1200,427,1,2,233.66,234.17,1,1,1,1,233.58,234.41,505,600,2,2,233.53,234.43,10,105,1,2,233.5,234.5,100,63,1,4,233.45,234.75,15,1,1,1,233.4,234.79,110,2000,2,1,233.39,234.89,10,2,1,2,AAPL,0.0,0.0,-200.0,-28.0,-1200.0,-1.0,-505.0,-10.0,-100.0,-15.0,-110.0,-351.42505877122426,
2024-10-21T12:12:09.099905611Z,2024-10-21T12:12:09.099739392Z,10,2,38,A,B,1,233.82,200,130,166219,12322505,233.9,234.0,10,154,1,7,233.82,234.06,200,200,1,1,233.77,234.13,28,427,1,2,233.7,234.17,1200,1,1,1,233.66,234.41,1,600,1,2,233.58,234.43,505,105,2,2,233.53,234.5,10,63,1,4,233.5,234.75,100,1,1,1,233.45,234.79,15,2000,1,1,233.4,234.89,110,2,2,2,AAPL,0.0,0.0,200.0,28.0,1200.0,1.0,505.0,10.0,100.0,15.0,110.0,351.42505877122426,
2024-10-21T12:12:10.232857553Z,2024-10-21T12:12:10.232691130Z,10,2,38,A,B,1,233.83,200,130,166423,12324515,233.9,234.0,10,154,1,7,233.83,234.06,200,200,1,1,233.77,234.13,28,427,1,2,233.7,234.17,1200,1,1,1,233.66,234.41,1,600,1,2,233.58,234.43,505,105,2,2,233.53,234.5,10,63,1,4,233.5,234.75,100,1,1,1,233.45,234.79,15,2000,1,1,233.4,234.89,110,2,2,2,AAPL,0.0,0.0,200.0,0.0,0.0,0.0,0.0,0.0,0.0,0.0,0.0,12.683232565773917,
2024-10-21T12:12:22.882293776Z,2024-10-21T12:12:22.882127538Z,10,2,38,C,B,1,233.83,200,130,166238,12335502,233.9,234.0,10,154,1,7,233.77,234.06,28,200,1,1,233.7,234.13,1200,427,1,2,233.66,234.17,1,1,1,1,233.58,234.41,505,600,2,2,233.53,234.43,10,105,1,2,233.5,234.5,100,63,1,4,233.45,234.75,15,1,1,1,233.4,234.79,110,2000,2,1,233.39,234.89,10,2,1,2,AAPL,0.0,0.0,-200.0,-28.0,-1200.0,-1.0,-505.0,-10.0,-100.0,-15.0,-110.0,-351.42505877122426,
2024-10-21T12:12:22.882306926Z,2024-10-21T12:12:22.882140909Z,10,2,38,A,B,1,233.78,400,130,166017,12335503,233.9,234.0,10,154,1,7,233.78,234.06,400,200,1,1,233.77,234.13,28,427,1,2,233.7,234.17,1200,1,1,1,233.66,234.41,1,600,1,2,233.58,234.43,505,105,2,2,233.53,234.5,10,63,1,4,233.5,234.75,100,1,1,1,233.45,234.79,15,2000,1,1,233.4,234.89,110,2,2,2,AAPL,0.0,0.0,400.0,28.0,1200.0,1.0,505.0,10.0,100.0,15.0,110.0,364.1082913369982,
2024-10-21T12:12:25.937011711Z,2024-10-21T12:12:25.936845190Z,10,2,38,A,B,1,233.82,200,130,166521,12338576,233.9,234.0,10,154,1,7,233.82,234.06,200,200,1,1,233.77,234.13,28,427,1,2,233.7,234.17,1200,1,1,1,233.66,234.41,1,600,1,2,233.58,234.43,505,105,2,2,233.53,234.5,10,63,1,4,233.5,234.75,100,1,1,1,233.45,234.79,15,2000,1,1,233.4,234.89,110,2,2,2,AAPL,0.0,0.0,200.0,0.0,0.0,0.0,0.0,0.0,0.0,0.0,0.0,12.683232565773917,
2024-10-21T12:12:28.133938919Z,2024-10-21T12:12:28.133772380Z,10,2,38,A,B,1,233.83,200,130,166539,12339995,233.9,234.0,10,154,1,7,233.83,234.06,200,200,1,1,233.77,234.13,28,427,1,2,233.7,234.17,1200,1,1,1,233.66,234.41,1,600,1,2,233.58,234.43,505,105,2,2,233.53,234.5,10,63,1,4,233.5,234.75,100,1,1,1,233.45,234.79,15,2000,1,1,233.4,234.89,110,2,2,2,AAPL,0.0,0.0,200.0,0.0,0.0,0.0,0.0,0.0,0.0,0.0,0.0,12.683232565773917,
2024-10-21T12:12:28.677615324Z,2024-10-21T12:12:28.677449361Z,10,2,38,C,B,1,233.83,200,130,165963,12340411,233.9,234.0,10,154,1,7,233.77,234.06,28,200,1,1,233.7,234.13,1200,427,1,2,233.66,234.17,1,1,1,1,233.58,234.41,505,600,2,2,233.53,234.43,10,105,1,2,233.5,234.5,100,63,1,4,233.45,234.75,15,1,1,1,233.4,234.79,110,2000,2,1,233.39,234.89,10,2,1,2,AAPL,0.0,0.0,-200.0,-28.0,-1200.0,-1.0,-505.0,-10.0,-100.0,-15.0,-110.0,-351.42505877122426,
2024-10-21T12:12:28.677627803Z,2024-10-21T12:12:28.677461375Z,10,2,38,A,B,1,233.78,400,130,166428,12340412,233.9,234.0,10,154,1,7,233.78,234.06,400,200,1,1,233.77,234.13,28,427,1,2,233.7,234.17,1200,1,1,1,233.66,234.41,1,600,1,2,233.58,234.43,505,105,2,2,233.53,234.5,10,63,1,4,233.5,234.75,100,1,1,1,233.45,234.79,15,2000,1,1,233.4,234.89,110,2,2,2,AAPL,0.0,0.0,400.0,28.0,1200.0,1.0,505.0,10.0,100.0,15.0,110.0,364.1082913369982,
2024-10-21T12:12:31.318989443Z,2024-10-21T12:12:31.318823338Z,10,2,38,C,A,1,234.06,200,130,166105,12341951,233.9,234.0,10,154,1,7,233.78,234.13,400,427,1,2,233.77,234.17,28,1,1,1,233.7,234.41,1200,600,1,2,233.66,234.43,1,105,1,2,233.58,234.5,505,63,2,4,233.53,234.75,10,1,1,1,233.5,234.79,100,2000,1,1,233.45,234.89,15,2,1,2,233.4,235.0,110,213,2,6,AAPL,0.0,0.0,427.0,1.0,600.0,105.0,63.0,1.0,2000.0,2.0,213.0,389.7347328754314,
2024-10-21T12:12:31.398006757Z,2024-10-21T12:12:31.397839079Z,10,2,38,T,N,0,233.98,50,130,167678,12342316,233.9,234.0,10,154,1,7,233.78,234.13,400,427,1,2,233.77,234.17,28,1,1,1,233.7,234.41,1200,600,1,2,233.66,234.43,1,105,1,2,233.58,234.5,505,63,2,4,233.53,234.75,10,1,1,1,233.5,234.79,100,2000,1,1,233.45,234.89,15,2,1,2,233.4,235.0,110,213,2,6,AAPL,0.0,0.0,0.0,0.0,0.0,0.0,0.0,0.0,0.0,0.0,0.0,0.0,
2024-10-21T12:12:31.425970357Z,2024-10-21T12:12:31.425804077Z,10,2,38,A,A,1,234.07,200,130,166280,12342547,233.9,234.0,10,154,1,7,233.78,234.07,400,200,1,1,233.77,234.13,28,427,1,2,233.7,234.17,1200,1,1,1,233.66,234.41,1,600,1,2,233.58,234.43,505,105,2,2,233.53,234.5,10,63,1,4,233.5,234.75,100,1,1,1,233.45,234.79,15,2000,1,1,233.4,234.89,110,2,2,2,AAPL,0.0,0.0,-427.0,-1.0,-600.0,-105.0,-63.0,-1.0,-2000.0,-2.0,-213.0,-389.7347328754314,
2024-10-21T12:12:31.454024371Z,2024-10-21T12:12:31.453857757Z,10,2,38,A,B,1,233.79,400,130,166614,12342589,233.9,234.0,10,154,1,7,233.79,234.07,400,200,1,1,233.77,234.13,28,427,1,2,233.7,234.17,1200,1,1,1,233.66,234.41,1,600,1,2,233.58,234.43,505,105,2,2,233.53,234.5,10,63,1,4,233.5,234.75,100,1,1,1,233.45,234.79,15,2000,1,1,233.4,234.89,110,2,2,2,AAPL,0.0,0.0,400.0,0.0,0.0,0.0,0.0,0.0,0.0,0.0,0.0,25.366465131547834,
2024-10-21T12:12:31.679118349Z,2024-10-21T12:12:31.678952187Z,10,2,38,C,B,2,233.77,28,130,166162,12343225,233.9,234.0,10,154,1,7,233.79,234.07,400,200,1,1,233.7,234.13,1200,427,1,2,233.66,234.17,1,1,1,1,233.58,234.41,505,600,2,2,233.53,234.43,10,105,1,2,233.5,234.5,100,63,1,4,233.45,234.75,15,1,1,1,233.4,234.79,110,2000,2,1,233.39,234.89,10,2,1,2,AAPL,0.0,0.0,0.0,-28.0,-1200.0,-1.0,-505.0,-10.0,-100.0,-15.0,-110.0,-338.74182620545037,
2024-10-21T12:12:31.679174617Z,2024-10-21T12:12:31.679008317Z,10,2,38,A,B,1,233.82,30,130,166300,12343226,233.9,234.0,10,154,1,7,233.82,234.07,30,200,1,1,233.79,234.13,400,427,1,2,233.7,234.17,1200,1,1,1,233.66,234.41,1,600,1,2,233.58,234.43,505,105,2,2,233.53,234.5,10,63,1,4,233.5,234.75,100,1,1,1,233.45,234.79,15,2000,1,1,233.4,234.89,110,2,2,2,AAPL,0.0,0.0,30.0,400.0,1200.0,1.0,505.0,10.0,100.0,15.0,110.0,378.43303112411036,
2024-10-21T12:12:31.733543975Z,2024-10-21T12:12:31.733377635Z,10,2,38,A,B,1,233.87,200,130,166340,12343455,233.9,234.0,10,154,1,7,233.87,234.07,200,200,1,1,233.82,234.13,30,427,1,2,233.7,234.17,1200,1,1,1,233.66,234.41,1,600,1,2,233.58,234.43,505,105,2,2,233.53,234.5,10,63,1,4,233.5,234.75,100,1,1,1,233.45,234.79,15,2000,1,1,233.4,234.89,110,2,2,2,AAPL,0.0,0.0,200.0,30.0,0.0,0.0,0.0,0.0,0.0,0.0,0.0,15.730709987854073,
2024-10-21T12:12:41.238878627Z,2024-10-21T12:12:41.238712131Z,10,2,38,A,A,1,234.06,200,130,166496,12350539,233.9,234.0,10,154,1,7,233.87,234.06,200,200,1,1,233.82,234.13,30,427,1,2,233.7,234.17,1200,1,1,1,233.66,234.41,1,600,1,2,233.58,234.43,505,105,2,2,233.53,234.5,10,63,1,4,233.5,234.75,100,1,1,1,233.45,234.79,15,2000,1,1,233.4,234.89,110,2,2,2,AAPL,0.0,0.0,-200.0,0.0,0.0,0.0,0.0,0.0,0.0,0.0,0.0,-12.683232565773917,
2024-10-21T12:12:43.651514581Z,2024-10-21T12:12:43.651347870Z,10,2,38,C,B,1,233.87,200,130,166711,12352115,233.9,234.0,10,154,1,7,233.82,234.06,30,200,1,1,233.7,234.13,1200,427,1,2,233.66,234.17,1,1,1,1,233.58,234.41,505,600,2,2,233.53,234.43,10,105,1,2,233.5,234.5,100,63,1,4,233.45,234.75,15,1,1,1,233.4,234.79,110,2000,2,1,233.39,234.89,10,2,1,2,AAPL,0.0,0.0,-200.0,-30.0,-1200.0,-1.0,-505.0,-10.0,-100.0,-15.0,-110.0,-351.6282239326963,
2024-10-21T12:12:43.731298274Z,2024-10-21T12:12:43.731132036Z,10,2,38,A,B,2,233.78,400,130,166238,12352210,233.9,234.0,10,154,1,7,233.82,234.06,30,200,1,1,233.78,234.13,400,427,1,2,233.7,234.17,1200,1,1,1,233.66,234.41,1,600,1,2,233.58,234.43,505,105,2,2,233.53,234.5,10,63,1,4,233.5,234.75,100,1,1,1,233.45,234.79,15,2000,1,1,233.4,234.89,110,2,2,2,AAPL,0.0,0.0,0.0,400.0,1200.0,1.0,505.0,10.0,100.0,15.0,110.0,376.5305462392443,
2024-10-21T12:12:43.731821725Z,2024-10-21T12:12:43.731655758Z,10,2,38,C,B,1,233.82,30,130,165967,12352211,233.9,234.0,10,154,1,7,233.78,234.06,400,200,1,1,233.7,234.13,1200,427,1,2,233.66,234.17,1,1,1,1,233.58,234.41,505,600,2,2,233.53,234.43,10,105,1,2,233.5,234.5,100,63,1,4,233.45,234.75,15,1,1,1,233.4,234.79,110,2000,2,1,233.39,234.89,10,2,1,2,AAPL,0.0,0.0,-30.0,-400.0,-1200.0,-1.0,-505.0,-10.0,-100.0,-15.0,-110.0,-378.43303112411036,
2024-10-21T12:12:43.731951886Z,2024-10-21T12:12:43.731785539Z,10,2,38,A,B,2,233.76,29,130,166347,12352212,233.9,234.0,10,154,1,7,233.78,234.06,400,200,1,1,233.76,234.13,29,427,1,2,233.7,234.17,1200,1,1,1,233.66,234.41,1,600,1,2,233.58,234.43,505,105,2,2,233.53,234.5,10,63,1,4,233.5,234.75,100,1,1,1,233.45,234.79,15,2000,1,1,233.4,234.89,110,2,2,2,AAPL,0.0,0.0,0.0,29.0,1200.0,1.0,505.0,10.0,100.0,15.0,110.0,338.84340878618633,
2024-10-21T12:12:46.780539855Z,2024-10-21T12:12:46.780372537Z,10,2,38,A,B,1,233.82,200,128,167318,12353700,233.9,234.0,10,154,1,7,233.82,234.06,200,200,1,1,233.76,234.13,29,427,1,2,233.7,234.17,1200,1,1,1,233.66,234.41,1,600,1,2,233.58,234.43,505,105,2,2,233.53,234.5,10,63,1,4,233.5,234.75,100,1,1,1,233.45,234.79,15,2000,1,1,233.4,234.89,110,2,2,2,AAPL,0.0,0.0,200.0,0.0,0.0,0.0,0.0,0.0,0.0,0.0,0.0,12.683232565773917,
2024-10-21T12:12:47.484642192Z,2024-10-21T12:12:47.484476304Z,10,2,38,C,B,1,233.82,200,130,165888,12353973,233.9,234.0,10,154,1,7,233.76,234.06,29,200,1,1,233.7,234.13,1200,427,1,2,233.66,234.17,1,1,1,1,233.58,234.41,505,600,2,2,233.53,234.43,10,105,1,2,233.5,234.5,100,63,1,4,233.45,234.75,15,1,1,1,233.4,234.79,110,2000,2,1,233.39,234.89,10,2,1,2,AAPL,0.0,0.0,-200.0,-29.0,-1200.0,-1.0,-505.0,-10.0,-100.0,-15.0,-110.0,-351.5266413519603,
2024-10-21T12:12:47.484860069Z,2024-10-21T12:12:47.484693420Z,10,2,38,A,A,0,233.99,100,130,166649,12353975,233.9,233.99,10,100,1,1,233.76,234.0,29,154,1,7,233.7,234.06,1200,200,1,1,233.66,234.13,1,427,1,2,233.58,234.17,505,1,2,1,233.53,234.41,10,600,1,2,233.5,234.43,100,105,1,2,233.45,234.5,15,63,1,4,233.4,234.75,110,1,2,1,233.39,234.79,10,2000,1,1,AAPL,-154.0,-154.0,-200.0,-427.0,-1.0,-600.0,-105.0,-63.0,-1.0,-2000.0,-2.0,-289.68442228943434,
2024-10-21T12:12:47.485189477Z,2024-10-21T12:12:47.485023375Z,10,2,38,C,A,0,233.99,100,130,166102,12353978,233.9,234.0,10,154,1,7,233.76,234.06,29,200,1,1,233.7,234.13,1200,427,1,2,233.66,234.17,1,1,1,1,233.58,234.41,505,600,2,2,233.53,234.43,10,105,1,2,233.5,234.5,100,63,1,4,233.45,234.75,15,1,1,1,233.4,234.79,110,2000,2,1,233.39,234.89,10,2,1,2,AAPL,154.0,154.0,200.0,427.0,1.0,600.0,105.0,63.0,1.0,2000.0,2.0,289.68442228943434,
2024-10-21T12:12:47.604634522Z,2024-10-21T12:12:47.604468075Z,10,2,38,A,B,1,233.78,400,130,166447,12354240,233.9,234.0,10,154,1,7,233.78,234.06,400,200,1,1,233.76,234.13,29,427,1,2,233.7,234.17,1200,1,1,1,233.66,234.41,1,600,1,2,233.58,234.43,505,105,2,2,233.53,234.5,10,63,1,4,233.5,234.75,100,1,1,1,233.45,234.79,15,2000,1,1,233.4,234.89,110,2,2,2,AAPL,0.0,0.0,400.0,29.0,1200.0,1.0,505.0,10.0,100.0,15.0,110.0,364.20987391773417,
2024-10-21T12:12:47.736357741Z,2024-10-21T12:12:47.736191420Z,10,2,38,A,A,1,234.06,200,130,166321,12354295,233.9,234.0,10,154,1,7,233.78,234.06,400,400,1,2,233.76,234.13,29,427,1,2,233.7,234.17,1200,1,1,1,233.66,234.41,1,600,1,2,233.58,234.43,505,105,2,2,233.53,234.5,10,63,1,4,233.5,234.75,100,1,1,1,233.45,234.79,15,2000,1,1,233.4,234.89,110,2,2,2,AAPL,0.0,0.0,-200.0,0.0,0.0,0.0,0.0,0.0,0.0,0.0,0.0,-12.683232565773917,
2024-10-21T12:12:48.104314520Z,2024-10-21T12:12:48.104146428Z,10,2,38,T,A,0,233.9,10,130,168092,12354546,233.9,234.0,10,154,1,7,233.78,234.06,400,400,1,2,233.76,234.13,29,427,1,2,233.7,234.17,1200,1,1,1,233.66,234.41,1,600,1,2,233.58,234.43,505,105,2,2,233.53,234.5,10,63,1,4,233.5,234.75,100,1,1,1,233.45,234.79,15,2000,1,1,233.4,234.89,110,2,2,2,AAPL,0.0,0.0,0.0,0.0,0.0,0.0,0.0,0.0,0.0,0.0,0.0,0.0,
2024-10-21T12:12:48.104314520Z,2024-10-21T12:12:48.104146428Z,10,2,38,C,B,0,233.9,10,130,168092,12354546,233.78,234.0,400,154,1,7,233.76,234.06,29,400,1,2,233.7,234.13,1200,427,1,2,233.66,234.17,1,1,1,1,233.58,234.41,505,600,2,2,233.53,234.43,10,105,1,2,233.5,234.5,100,63,1,4,233.45,234.75,15,1,1,1,233.4,234.79,110,2000,2,1,233.39,234.89,10,2,1,2,AAPL,-10.0,-10.0,-400.0,-29.0,-1200.0,-1.0,-505.0,-10.0,-100.0,-15.0,-110.0,-364.40867974419547,
2024-10-21T12:12:48.104334124Z,2024-10-21T12:12:48.104167967Z,10,2,38,A,A,0,233.98,100,130,166157,12354547,233.78,233.98,400,100,1,1,233.76,234.0,29,154,1,7,233.7,234.06,1200,400,1,2,233.66,234.13,1,427,1,2,233.58,234.17,505,1,2,1,233.53,234.41,10,600,1,2,233.5,234.43,100,105,1,2,233.45,234.5,15,63,1,4,233.4,234.75,110,1,2,1,233.39,234.79,10,2000,1,1,AAPL,-154.0,-154.0,-400.0,-427.0,-1.0,-600.0,-105.0,-63.0,-1.0,-2000.0,-2.0,-302.3676548552083,
2024-10-21T12:12:48.104345015Z,2024-10-21T12:12:48.104178898Z,10,2,38,C,B,0,233.78,400,130,166117,12354548,233.76,233.98,29,100,1,1,233.7,234.0,1200,154,1,7,233.66,234.06,1,400,1,2,233.58,234.13,505,427,2,2,233.53,234.17,10,1,1,1,233.5,234.41,100,600,1,2,233.45,234.43,15,105,1,2,233.4,234.5,110,63,2,4,233.39,234.75,10,1,1,1,233.31,234.79,110,2000,2,1,AAPL,-400.0,-400.0,-29.0,-1200.0,-1.0,-505.0,-10.0,-100.0,-15.0,-110.0,-10.0,-213.30837407562322,
2024-10-21T12:12:48.104347234Z,2024-10-21T12:12:48.104181225Z,10,2,38,A,A,0,233.98,100,130,166009,12354549,233.76,233.98,29,200,1,2,233.7,234.0,1200,154,1,7,233.66,234.06,1,400,1,2,233.58,234.13,505,427,2,2,233.53,234.17,10,1,1,1,233.5,234.41,100,600,1,2,233.45,234.43,15,105,1,2,233.4,234.5,110,63,2,4,233.39,234.75,10,1,1,1,233.31,234.79,110,2000,2,1,AAPL,-100.0,-100.0,0.0,0.0,0.0,0.0,0.0,0.0,0.0,0.0,0.0,-1.9880582646125018,
2024-10-21T12:12:48.104351926Z,2024-10-21T12:12:48.104185923Z,10,2,38,C,A,0,233.98,100,130,166003,12354550,233.76,233.98,29,100,1,1,233.7,234.0,1200,154,1,7,233.66,234.06,1,400,1,2,233.58,234.13,505,427,2,2,233.53,234.17,10,1,1,1,233.5,234.41,100,600,1,2,233.45,234.43,15,105,1,2,233.4,234.5,110,63,2,4,233.39,234.75,10,1,1,1,233.31,234.79,110,2000,2,1,AAPL,100.0,100.0,0.0,0.0,0.0,0.0,0.0,0.0,0.0,0.0,0.0,1.9880582646125018,
2024-10-21T12:12:48.104356853Z,2024-10-21T12:12:48.104190565Z,10,2,38,A,A,0,233.95,14,130,166288,12354552,233.76,233.95,29,14,1,1,233.7,233.98,1200,100,1,1,233.66,234.0,1,154,1,7,233.58,234.06,505,400,2,2,233.53,234.13,10,427,1,2,233.5,234.17,100,1,1,1,233.45,234.41,15,600,1,2,233.4,234.43,110,105,2,2,233.39,234.5,10,63,1,4,233.31,234.75,110,1,2,1,AAPL,-100.0,-100.0,-154.0,-400.0,-427.0,-1.0,-600.0,-105.0,-63.0,-1.0,-2000.0,-383.1723893250045,
2024-10-21T12:12:48.104362882Z,2024-10-21T12:12:48.104196514Z,10,2,38,A,A,0,233.95,16,130,166368,12354553,233.76,233.95,29,30,1,2,233.7,233.98,1200,100,1,1,233.66,234.0,1,154,1,7,233.58,234.06,505,400,2,2,233.53,234.13,10,427,1,2,233.5,234.17,100,1,1,1,233.45,234.41,15,600,1,2,233.4,234.43,110,105,2,2,233.39,234.5,10,63,1,4,233.31,234.75,110,1,2,1,AAPL,-16.0,-16.0,0.0,0.0,0.0,0.0,0.0,0.0,0.0,0.0,0.0,-0.3180893223380003,
2024-10-21T12:12:48.104375784Z,2024-10-21T12:12:48.104209602Z,10,2,38,A,A,1,233.98,16,130,166182,12354554,233.76,233.95,29,30,1,2,233.7,233.98,1200,116,1,2,233.66,234.0,1,154,1,7,233.58,234.06,505,400,2,2,233.53,234.13,10,427,1,2,233.5,234.17,100,1,1,1,233.45,234.41,15,600,1,2,233.4,234.43,110,105,2,2,233.39,234.5,10,63,1,4,233.31,234.75,110,1,2,1,AAPL,0.0,0.0,-16.0,0.0,0.0,0.0,0.0,0.0,0.0,0.0,0.0,-1.0146586052619133,
2024-10-21T12:12:48.104385015Z,2024-10-21T12:12:48.104217612Z,10,2,38,C,A,1,233.98,100,130,167403,12354555,233.76,233.95,29,30,1,2,233.7,233.98,1200,16,1,1,233.66,234.0,1,154,1,7,233.58,234.06,505,400,2,2,233.53,234.13,10,427,1,2,233.5,234.17,100,1,1,1,233.45,234.41,15,600,1,2,233.4,234.43,110,105,2,2,233.39,234.5,10,63,1,4,233.31,234.75,110,1,2,1,AAPL,0.0,0.0,100.0,0.0,0.0,0.0,0.0,0.0,0.0,0.0,0.0,6.3416162828869584,
2024-10-21T12:12:48.176341448Z,2024-10-21T12:12:48.176175311Z,10,2,38,A,B,1,233.71,27,130,166137,12354620,233.76,233.95,29,30,1,2,233.71,233.98,27,16,1,1,233.7,234.0,1200,154,1,7,233.66,234.06,1,400,1,2,233.58,234.13,505,427,2,2,233.53,234.17,10,1,1,1,233.5,234.41,100,600,1,2,233.45,234.43,15,105,1,2,233.4,234.5,110,63,2,4,233.39,234.75,10,1,1,1,AAPL,0.0,0.0,27.0,1200.0,1.0,505.0,10.0,100.0,15.0,110.0,10.0,205.2293086915155,
2024-10-21T12:12:48.176370376Z,2024-10-21T12:12:48.176204532Z,10,2,38,C,B,0,233.76,29,130,165844,12354621,233.71,233.95,27,30,1,2,233.7,233.98,1200,16,1,1,233.66,234.0,1,154,1,7,233.58,234.06,505,400,2,2,233.53,234.13,10,427,1,2,233.5,234.17,100,1,1,1,233.45,234.41,15,600,1,2,233.4,234.43,110,105,2,2,233.39,234.5,10,63,1,4,233.31,234.75,110,1,2,1,AAPL,-29.0,-29.0,-27.0,-1200.0,-1.0,-505.0,-10.0,-100.0,-15.0,-110.0,-10.0,-205.8058455882531,
2024-10-21T12:12:48.177018480Z,2024-10-21T12:12:48.176852661Z,10,2,38,C,B,0,233.71,27,130,165819,12354624,233.7,233.95,1200,30,1,2,233.66,233.98,1,16,1,1,233.58,234.0,505,154,2,7,233.53,234.06,10,400,1,2,233.5,234.13,100,427,1,2,233.45,234.17,15,1,1,1,233.4,234.41,110,600,2,2,233.39,234.43,10,105,1,2,233.31,234.5,110,63,2,4,233.3,234.75,100,1,1,1,AAPL,-27.0,-27.0,-1200.0,-1.0,-505.0,-10.0,-100.0,-15.0,-110.0,-10.0,-110.0,-216.62827477529595,
2024-10-21T12:12:48.180095554Z,2024-10-21T12:12:48.179929431Z,10,2,38,A,A,4,234.08,29,130,166123,12354625,233.7,233.95,1200,30,1,2,233.66,233.98,1,16,1,1,233.58,234.0,505,154,2,7,233.53,234.06,10,400,1,2,233.5,234.08,100,29,1,1,233.45,234.13,15,427,1,2,233.4,234.17,110,1,2,1,233.39,234.41,10,600,1,2,233.31,234.43,110,105,2,2,233.3,234.5,100,63,1,4,AAPL,0.0,0.0,0.0,0.0,0.0,-427.0,-1.0,-600.0,-105.0,-63.0,-1.0,-133.3455422929158,
2024-10-21T12:12:48.180133214Z,2024-10-21T12:12:48.179967058Z,10,2,38,C,A,5,234.13,27,130,166156,12354626,233.7,233.95,1200,30,1,2,233.66,233.98,1,16,1,1,233.58,234.0,505,154,2,7,233.53,234.06,10,400,1,2,233.5,234.08,100,29,1,1,233.45,234.13,15,400,1,1,233.4,234.17,110,1,2,1,233.39,234.41,10,600,1,2,233.31,234.43,110,105,2,2,233.3,234.5,100,63,1,4,AAPL,0.0,0.0,0.0,0.0,0.0,0.0,27.0,0.0,0.0,0.0,0.0,3.7177003242031197,
2024-10-21T12:12:48.204420400Z,2024-10-21T12:12:48.204254179Z,10,2,38,C,A,0,233.95,14,130,166221,12354640,233.7,233.95,1200,16,1,1,233.66,233.98,1,16,1,1,233.58,234.0,505,154,2,7,233.53,234.06,10,400,1,2,233.5,234.08,100,29,1,1,233.45,234.13,15,400,1,1,233.4,234.17,110,1,2,1,233.39,234.41,10,600,1,2,233.31,234.43,110,105,2,2,233.3,234.5,100,63,1,4,AAPL,14.0,14.0,0.0,0.0,0.0,0.0,0.0,0.0,0.0,0.0,0.0,0.27832815704575026,
2024-10-21T12:12:48.204447035Z,2024-10-21T12:12:48.204281167Z,10,2,38,C,A,1,233.98,16,130,165868,12354641,233.7,233.95,1200,16,1,1,233.66,234.0,1,154,1,7,233.58,234.06,505,400,2,2,233.53,234.08,10,29,1,1,233.5,234.13,100,400,1,1,233.45,234.17,15,1,1,1,233.4,234.41,110,600,2,2,233.39,234.43,10,105,1,2,233.31,234.5,110,63,2,4,233.3,234.75,100,1,1,1,AAPL,0.0,0.0,154.0,400.0,29.0,400.0,1.0,600.0,105.0,63.0,1.0,186.54943070050516,
2024-10-21T12:12:48.214127843Z,2024-10-21T12:12:48.213961498Z,10,2,38,A,B,1,233.67,400,130,166345,12354647,233.7,233.95,1200,16,1,1,233.67,234.0,400,154,1,7,233.66,234.06,1,400,1,2,233.58,234.08,505,29,2,1,233.53,234.13,10,400,1,1,233.5,234.17,100,1,1,1,233.45,234.41,15,600,1,2,233.4,234.43,110,105,2,2,233.39,234.5,10,63,1,4,233.31,234.75,110,1,2,1,AAPL,0.0,0.0,400.0,1.0,505.0,10.0,100.0,15.0,110.0,10.0,110.0,165.3585687807549,
2024-10-21T12:12:48.233136592Z,2024-10-21T12:12:48.232970230Z,10,2,38,C,A,2,234.06,200,130,166362,12354661,233.7,233.95,1200,16,1,1,233.67,234.0,400,154,1,7,233.66,234.06,1,200,1,1,233.58,234.08,505,29,2,1,233.53,234.13,10,400,1,1,233.5,234.17,100,1,1,1,233.45,234.41,15,600,1,2,233.4,234.43,110,105,2,2,233.39,234.5,10,63,1,4,233.31,234.75,110,1,2,1,AAPL,0.0,0.0,0.0,200.0,0.0,0.0,0.0,0.0,0.0,0.0,0.0,20.31651614720104,
2024-10-21T12:12:48.233149556Z,2024-10-21T12:12:48.232983049Z,10,2,38,A,A,2,234.01,200,130,166507,12354662,233.7,233.95,1200,16,1,1,233.67,234.0,400,154,1,7,233.66,234.01,1,200,1,1,233.58,234.08,505,29,2,1,233.53,234.13,10,400,1,1,233.5,234.17,100,1,1,1,233.45,234.41,15,600,1,2,233.4,234.43,110,105,2,2,233.39,234.5,10,63,1,4,233.31,234.75,110,1,2,1,AAPL,0.0,0.0,0.0,-200.0,0.0,0.0,0.0,0.0,0.0,0.0,0.0,-20.31651614720104,
2024-10-21T12:12:48.247502164Z,2024-10-21T12:12:48.247336117Z,10,2,38,C,B,1,233.67,400,130,166047,12354665,233.7,233.95,1200,16,1,1,233.66,234.0,1,154,1,7,233.58,234.01,505,200,2,1,233.53,234.08,10,29,1,1,233.5,234.13,100,400,1,1,233.45,234.17,15,1,1,1,233.4,234.41,110,600,2,2,233.39,234.43,10,105,1,2,233.31,234.5,110,63,2,4,233.3,234.75,100,1,1,1,AAPL,0.0,0.0,-400.0,-1.0,-505.0,-10.0,-100.0,-15.0,-110.0,-10.0,-110.0,-165.3585687807549,
2024-10-21T12:12:48.247514656Z,2024-10-21T12:12:48.247348435Z,10,2,38,A,B,2,233.62,400,130,166221,12354666,233.7,233.95,1200,16,1,1,233.66,234.0,1,154,1,7,233.62,234.01,400,200,1,1,233.58,234.08,505,29,2,1,233.53,234.13,10,400,1,1,233.5,234.17,100,1,1,1,233.45,234.41,15,600,1,2,233.4,234.43,110,105,2,2,233.39,234.5,10,63,1,4,233.31,234.75,110,1,2,1,AAPL,0.0,0.0,0.0,400.0,505.0,10.0,100.0,15.0,110.0,10.0,110.0,180.52355336287314,
2024-10-21T12:12:48.307017573Z,2024-10-21T12:12:48.306851049Z,10,2,38,A,B,0,233.72,400,130,166524,12354670,233.72,233.95,400,16,1,1,233.7,234.0,1200,154,1,7,233.66,234.01,1,200,1,1,233.58,234.08,505,29,2,1,233.53,234.13,10,400,1,1,233.5,234.17,100,1,1,1,233.45,234.41,15,600,1,2,233.4,234.43,110,105,2,2,233.39,234.5,10,63,1,4,233.31,234.75,110,1,2,1,AAPL,400.0,400.0,1200.0,1.0,0.0,0.0,0.0,0.0,0.0,0.0,0.0,84.1532110338295,
2024-10-21T12:12:48.348045881Z,2024-10-21T12:12:48.347879918Z,10,2,38,C,A,2,234.01,200,130,165963,12354690,233.72,233.95,400,16,1,1,233.7,234.0,1200,154,1,7,233.66,234.08,1,29,1,1,233.58,234.13,505,400,2,1,233.53,234.17,10,1,1,1,233.5,234.41,100,600,1,2,233.45,234.43,15,105,1,2,233.4,234.5,110,63,2,4,233.39,234.75,10,1,1,1,233.31,234.79,110,2000,2,1,AAPL,0.0,0.0,0.0,29.0,400.0,1.0,600.0,105.0,63.0,1.0,2000.0,328.19402404603693,
2024-10-21T12:12:48.348059124Z,2024-10-21T12:12:48.347893041Z,10,2,38,A,A,2,234.06,400,130,166083,12354691,233.72,233.95,400,16,1,1,233.7,234.0,1200,154,1,7,233.66,234.06,1,400,1,1,233.58,234.08,505,29,2,1,233.53,234.13,10,400,1,1,233.5,234.17,100,1,1,1,233.45,234.41,15,600,1,2,233.4,234.43,110,105,2,2,233.39,234.5,10,63,1,4,233.31,234.75,110,1,2,1,AAPL,0.0,0.0,0.0,-29.0,-400.0,-1.0,-600.0,-105.0,-63.0,-1.0,-2000.0,-328.19402404603693,
2024-10-21T12:12:48.363929061Z,2024-10-21T12:12:48.363762750Z,10,2,38,C,A,0,233.95,16,130,166311,12354719,233.72,234.0,400,154,1,7,233.7,234.06,1200,400,1,1,233.66,234.08,1,29,1,1,233.58,234.13,505,400,2,1,233.53,234.17,10,1,1,1,233.5,234.41,100,600,1,2,233.45,234.43,15,105,1,2,233.4,234.5,110,63,2,4,233.39,234.75,10,1,1,1,233.31,234.79,110,2000,2,1,AAPL,154.0,154.0,400.0,29.0,400.0,1.0,600.0,105.0,63.0,1.0,2000.0,356.622098905088,
2024-10-21T12:12:49.107440196Z,2024-10-21T12:12:49.107274312Z,10,2,38,C,B,0,233.72,400,130,165884,12355060,233.7,234.0,1200,154,1,7,233.66,234.06,1,400,1,1,233.58,234.08,505,29,2,1,233.53,234.13,10,400,1,1,233.5,234.17,100,1,1,1,233.45,234.41,15,600,1,2,233.4,234.43,110,105,2,2,233.39,234.5,10,63,1,4,233.31,234.75,110,1,2,1,233.3,234.79,100,2000,1,1,AAPL,-400.0,-400.0,-1200.0,-1.0,-505.0,-10.0,-100.0,-15.0,-110.0,-10.0,-110.0,-224.04373210230057,
2024-10-21T12:12:49.117722704Z,2024-10-21T12:12:49.117556478Z,10,2,38,A,B,0,233.72,200,130,166226,12355064,233.72,234.0,200,154,1,7,233.7,234.06,1200,400,1,1,233.66,234.08,1,29,1,1,233.58,234.13,505,400,2,1,233.53,234.17,10,1,1,1,233.5,234.41,100,600,1,2,233.45,234.43,15,105,1,2,233.4,234.5,110,63,2,4,233.39,234.75,10,1,1,1,233.31,234.79,110,2000,2,1,AAPL,200.0,200.0,1200.0,1.0,505.0,10.0,100.0,15.0,110.0,10.0,110.0,220.06761557307559,
2024-10-21T12:12:49.170261083Z,2024-10-21T12:12:49.170094147Z,10,2,38,A,B,3,233.65,28,130,166936,12355076,233.72,234.0,200,154,1,7,233.7,234.06,1200,400,1,1,233.66,234.08,1,29,1,1,233.65,234.13,28,400,1,1,233.58,234.17,505,1,2,1,233.53,234.41,10,600,1,2,233.5,234.43,100,105,1,2,233.45,234.5,15,63,1,4,233.4,234.75,110,1,2,1,233.39,234.79,10,2000,1,1,AAPL,0.0,0.0,0.0,0.0,28.0,505.0,10.0,100.0,15.0,110.0,10.0,87.15505589758098,
2024-10-21T12:12:49.179734911Z,2024-10-21T12:12:49.179568062Z,10,2,38,A,B,0,233.72,200,130,166849,12355080,233.72,234.0,400,154,2,7,233.7,234.06,1200,400,1,1,233.66,234.08,1,29,1,1,233.65,234.13,28,400,1,1,233.58,234.17,505,1,2,1,233.53,234.41,10,600,1,2,233.5,234.43,100,105,1,2,233.45,234.5,15,63,1,4,233.4,234.75,110,1,2,1,233.39,234.79,10,2000,1,1,AAPL,200.0,200.0,0.0,0.0,0.0,0.0,0.0,0.0,0.0,0.0,0.0,3.9761165292250036,
2024-10-21T12:12:50.108822491Z,2024-10-21T12:12:50.108656247Z,10,2,38,C,B,0,233.72,200,130,166244,12355613,233.72,234.0,200,154,1,7,233.7,234.06,1200,400,1,1,233.66,234.08,1,29,1,1,233.65,234.13,28,400,1,1,233.58,234.17,505,1,2,1,233.53,234.41,10,600,1,2,233.5,234.43,100,105,1,2,233.45,234.5,15,63,1,4,233.4,234.75,110,1,2,1,233.39,234.79,10,2000,1,1,AAPL,-200.0,-200.0,0.0,0.0,0.0,0.0,0.0,0.0,0.0,0.0,0.0,-3.9761165292250036,
2024-10-21T12:12:50.108831892Z,2024-10-21T12:12:50.108666090Z,10,2,38,C,B,0,233.72,200,130,165802,12355614,233.7,234.0,1200,154,1,7,233.66,234.06,1,400,1,1,233.65,234.08,28,29,1,1,233.58,234.13,505,400,2,1,233.53,234.17,10,1,1,1,233.5,234.41,100,600,1,2,233.45,234.43,15,105,1,2,233.4,234.5,110,63,2,4,233.39,234.75,10,1,1,1,233.31,234.79,110,2000,2,1,AAPL,-200.0,-200.0,-1200.0,-1.0,-28.0,-505.0,-10.0,-100.0,-15.0,-110.0,-10.0,-167.3321504021855,
2024-10-21T12:12:50.212341929Z,2024-10-21T12:12:50.212175433Z,10,2,38,A,B,0,233.72,400,130,166496,12355646,233.72,234.0,400,154,1,7,233.7,234.06,1200,400,1,1,233.66,234.08,1,29,1,1,233.65,234.13,28,400,1,1,233.58,234.17,505,1,2,1,233.53,234.41,10,600,1,2,233.5,234.43,100,105,1,2,233.45,234.5,15,63,1,4,233.4,234.75,110,1,2,1,233.39,234.79,10,2000,1,1,AAPL,400.0,400.0,1200.0,1.0,28.0,505.0,10.0,100.0,15.0,110.0,10.0,171.3082669314105,
2024-10-21T12:12:50.565470381Z,2024-10-21T12:12:50.565304171Z,10,2,38,C,B,3,233.65,28,130,166210,12355988,233.72,234.0,400,154,1,7,233.7,234.06,1200,400,1,1,233.66,234.08,1,29,1,1,233.58,234.13,505,400,2,1,233.53,234.17,10,1,1,1,233.5,234.41,100,600,1,2,233.45,234.43,15,105,1,2,233.4,234.5,110,63,2,4,233.39,234.75,10,1,1,1,233.31,234.79,110,2000,2,1,AAPL,0.0,0.0,0.0,0.0,-28.0,-505.0,-10.0,-100.0,-15.0,-110.0,-10.0,-87.15505589758098,
2024-10-21T12:12:50.565594035Z,2024-10-21T12:12:50.565427767Z,10,2,38,A,B,1,233.71,26,130,166268,12355989,233.72,234.0,400,154,1,7,233.71,234.06,26,400,1,1,233.7,234.08,1200,29,1,1,233.66,234.13,1,400,1,1,233.58,234.17,505,1,2,1,233.53,234.41,10,600,1,2,233.5,234.43,100,105,1,2,233.45,234.5,15,63,1,4,233.4,234.75,110,1,2,1,233.39,234.79,10,2000,1,1,AAPL,0.0,0.0,26.0,1200.0,1.0,505.0,10.0,100.0,15.0,110.0,10.0,205.1658925286866,
2024-10-21T12:12:50.565667034Z,2024-10-21T12:12:50.565500981Z,10,2,38,C,A,2,234.08,29,130,166053,12355990,233.72,234.0,400,154,1,7,233.71,234.06,26,400,1,1,233.7,234.13,1200,400,1,1,233.66,234.17,1,1,1,1,233.58,234.41,505,600,2,2,233.53,234.43,10,105,1,2,233.5,234.5,100,63,1,4,233.45,234.75,15,1,1,1,233.4,234.79,110,2000,2,1,233.39,234.89,10,2,1,2,AAPL,0.0,0.0,0.0,400.0,1.0,600.0,105.0,63.0,1.0,2000.0,2.0,271.19685031628507,
2024-10-21T12:12:50.565721409Z,2024-10-21T12:12:50.565554902Z,10,2,38,A,A,2,234.13,30,130,166507,12355991,233.72,234.0,400,154,1,7,233.71,234.06,26,400,1,1,233.7,234.13,1200,430,1,2,233.66,234.17,1,1,1,1,233.58,234.41,505,600,2,2,233.53,234.43,10,105,1,2,233.5,234.5,100,63,1,4,233.45,234.75,15,1,1,1,233.4,234.79,110,2000,2,1,233.39,234.89,10,2,1,2,AAPL,0.0,0.0,0.0,-30.0,0.0,0.0,0.0,0.0,0.0,0.0,0.0,-3.047477422080156,
2024-10-21T12:12:50.574010932Z,2024-10-21T12:12:50.573844808Z,10,2,38,C,B,0,233.72,200,130,166124,12355992,233.72,234.0,200,154,1,7,233.71,234.06,26,400,1,1,233.7,234.13,1200,430,1,2,233.66,234.17,1,1,1,1,233.58,234.41,505,600,2,2,233.53,234.43,10,105,1,2,233.5,234.5,100,63,1,4,233.45,234.75,15,1,1,1,233.4,234.79,110,2000,2,1,233.39,234.89,10,2,1,2,AAPL,-200.0,-200.0,0.0,0.0,0.0,0.0,0.0,0.0,0.0,0.0,0.0,-3.9761165292250036,
2024-10-21T12:12:50.619715566Z,2024-10-21T12:12:50.619549454Z,10,2,38,C,B,0,233.72,200,130,166112,12355999,233.71,234.0,26,154,1,7,233.7,234.06,1200,400,1,1,233.66,234.13,1,430,1,2,233.58,234.17,505,1,2,1,233.53,234.41,10,600,1,2,233.5,234.43,100,105,1,2,233.45,234.5,15,63,1,4,233.4,234.75,110,1,2,1,233.39,234.79,10,2000,1,1,233.31,234.89,110,2,2,2,AAPL,-200.0,-200.0,-26.0,-1200.0,-1.0,-505.0,-10.0,-100.0,-15.0,-110.0,-10.0,-209.14200905791162,
2024-10-21T12:12:50.619728644Z,2024-10-21T12:12:50.619562205Z,10,2,38,A,A,1,234.05,200,130,166439,12356000,233.71,234.0,26,154,1,7,233.7,234.05,1200,200,1,1,233.66,234.13,1,430,1,2,233.58,234.17,505,1,2,1,233.53,234.41,10,600,1,2,233.5,234.43,100,105,1,2,233.45,234.5,15,63,1,4,233.4,234.75,110,1,2,1,233.39,234.79,10,2000,1,1,233.31,234.89,110,2,2,2,AAPL,0.0,0.0,-400.0,0.0,0.0,0.0,0.0,0.0,0.0,0.0,0.0,-25.366465131547834,
2024-10-21T12:12:50.622790340Z,2024-10-21T12:12:50.622623771Z,10,2,38,A,A,1,234.01,200,130,166569,12356003,233.71,234.0,26,154,1,7,233.7,234.01,1200,200,1,1,233.66,234.13,1,430,1,2,233.58,234.17,505,1,2,1,233.53,234.41,10,600,1,2,233.5,234.43,100,105,1,2,233.45,234.5,15,63,1,4,233.4,234.75,110,1,2,1,233.39,234.79,10,2000,1,1,233.31,234.89,110,2,2,2,AAPL,0.0,0.0,-200.0,0.0,0.0,0.0,0.0,0.0,0.0,0.0,0.0,-12.683232565773917,
2024-10-21T12:12:50.641720668Z,2024-10-21T12:12:50.641554545Z,10,2,38,A,B,0,233.77,200,130,166123,12356008,233.77,234.0,200,154,1,7,233.71,234.01,26,200,1,1,233.7,234.13,1200,430,1,2,233.66,234.17,1,1,1,1,233.58,234.41,505,600,2,2,233.53,234.43,10,105,1,2,233.5,234.5,100,63,1,4,233.45,234.75,15,1,1,1,233.4,234.79,110,2000,2,1,233.39,234.89,10,2,1,2,AAPL,200.0,200.0,26.0,1200.0,1.0,505.0,10.0,100.0,15.0,110.0,10.0,209.14200905791162,
2024-10-21T12:12:50.682530531Z,2024-10-21T12:12:50.682363924Z,10,2,38,C,A,1,234.01,200,130,166607,12356017,233.77,234.0,200,154,1,7,233.71,234.13,26,430,1,2,233.7,234.17,1200,1,1,1,233.66,234.41,1,600,1,2,233.58,234.43,505,105,2,2,233.53,234.5,10,63,1,4,233.5,234.75,100,1,1,1,233.45,234.79,15,2000,1,1,233.4,234.89,110,2,2,2,233.39,235.0,10,213,1,6,AAPL,0.0,0.0,430.0,1.0,600.0,105.0,63.0,1.0,2000.0,2.0,213.0,389.924981363918,
2024-10-21T12:12:50.682542775Z,2024-10-21T12:12:50.682376586Z,10,2,38,A,A,1,234.06,400,130,166189,12356018,233.77,234.0,200,154,1,7,233.71,234.06,26,400,1,1,233.7,234.13,1200,430,1,2,233.66,234.17,1,1,1,1,233.58,234.41,505,600,2,2,233.53,234.43,10,105,1,2,233.5,234.5,100,63,1,4,233.45,234.75,15,1,1,1,233.4,234.79,110,2000,2,1,233.39,234.89,10,2,1,2,AAPL,0.0,0.0,-430.0,-1.0,-600.0,-105.0,-63.0,-1.0,-2000.0,-2.0,-213.0,-389.924981363918,
2024-10-21T12:12:50.736679110Z,2024-10-21T12:12:50.736513051Z,10,2,38,C,B,0,233.77,200,130,166059,12356039,233.71,234.0,26,154,1,7,233.7,234.06,1200,400,1,1,233.66,234.13,1,430,1,2,233.58,234.17,505,1,2,1,233.53,234.41,10,600,1,2,233.5,234.43,100,105,1,2,233.45,234.5,15,63,1,4,233.4,234.75,110,1,2,1,233.39,234.79,10,2000,1,1,233.31,234.89,110,2,2,2,AAPL,-200.0,-200.0,-26.0,-1200.0,-1.0,-505.0,-10.0,-100.0,-15.0,-110.0,-10.0,-209.14200905791162,
2024-10-21T12:12:50.837873116Z,2024-10-21T12:12:50.837707032Z,10,2,38,A,B,0,233.77,200,130,166084,12356086,233.77,234.0,200,154,1,7,233.71,234.06,26,400,1,1,233.7,234.13,1200,430,1,2,233.66,234.17,1,1,1,1,233.58,234.41,505,600,2,2,233.53,234.43,10,105,1,2,233.5,234.5,100,63,1,4,233.45,234.75,15,1,1,1,233.4,234.79,110,2000,2,1,233.39,234.89,10,2,1,2,AAPL,200.0,200.0,26.0,1200.0,1.0,505.0,10.0,100.0,15.0,110.0,10.0,209.14200905791162,
2024-10-21T12:12:50.886653895Z,2024-10-21T12:12:50.886487788Z,10,2,38,C,B,0,233.77,200,130,166107,12356099,233.71,234.0,26,154,1,7,233.7,234.06,1200,400,1,1,233.66,234.13,1,430,1,2,233.58,234.17,505,1,2,1,233.53,234.41,10,600,1,2,233.5,234.43,100,105,1,2,233.45,234.5,15,63,1,4,233.4,234.75,110,1,2,1,233.39,234.79,10,2000,1,1,233.31,234.89,110,2,2,2,AAPL,-200.0,-200.0,-26.0,-1200.0,-1.0,-505.0,-10.0,-100.0,-15.0,-110.0,-10.0,-209.14200905791162,
2024-10-21T12:12:50.986944410Z,2024-10-21T12:12:50.986777714Z,10,2,38,A,B,0,233.77,200,130,166696,12356148,233.77,234.0,200,154,1,7,233.71,234.06,26,400,1,1,233.7,234.13,1200,430,1,2,233.66,234.17,1,1,1,1,233.58,234.41,505,600,2,2,233.53,234.43,10,105,1,2,233.5,234.5,100,63,1,4,233.45,234.75,15,1,1,1,233.4,234.79,110,2000,2,1,233.39,234.89,10,2,1,2,AAPL,200.0,200.0,26.0,1200.0,1.0,505.0,10.0,100.0,15.0,110.0,10.0,209.14200905791162,
2024-10-21T12:12:51.039503151Z,2024-10-21T12:12:51.039337327Z,10,2,38,C,B,0,233.77,200,130,165824,12356173,233.71,234.0,26,154,1,7,233.7,234.06,1200,400,1,1,233.66,234.13,1,430,1,2,233.58,234.17,505,1,2,1,233.53,234.41,10,600,1,2,233.5,234.43,100,105,1,2,233.45,234.5,15,63,1,4,233.4,234.75,110,1,2,1,233.39,234.79,10,2000,1,1,233.31,234.89,110,2,2,2,AAPL,-200.0,-200.0,-26.0,-1200.0,-1.0,-505.0,-10.0,-100.0,-15.0,-110.0,-10.0,-209.14200905791162,
2024-10-21T12:12:51.148063732Z,2024-10-21T12:12:51.147897247Z,10,2,38,A,B,0,233.77,200,130,166485,12356223,233.77,234.0,200,154,1,7,233.71,234.06,26,400,1,1,233.7,234.13,1200,430,1,2,233.66,234.17,1,1,1,1,233.58,234.41,505,600,2,2,233.53,234.43,10,105,1,2,233.5,234.5,100,63,1,4,233.45,234.75,15,1,1,1,233.4,234.79,110,2000,2,1,233.39,234.89,10,2,1,2,AAPL,200.0,200.0,26.0,1200.0,1.0,505.0,10.0,100.0,15.0,110.0,10.0,209.14200905791162,
2024-10-21T12:12:51.221545416Z,2024-10-21T12:12:51.221379329Z,10,2,38,C,B,0,233.77,200,130,166087,12356261,233.71,234.0,26,154,1,7,233.7,234.06,1200,400,1,1,233.66,234.13,1,430,1,2,233.58,234.17,505,1,2,1,233.53,234.41,10,600,1,2,233.5,234.43,100,105,1,2,233.45,234.5,15,63,1,4,233.4,234.75,110,1,2,1,233.39,234.79,10,2000,1,1,233.31,234.89,110,2,2,2,AAPL,-200.0,-200.0,-26.0,-1200.0,-1.0,-505.0,-10.0,-100.0,-15.0,-110.0,-10.0,-209.14200905791162,
2024-10-21T12:12:51.330104268Z,2024-10-21T12:12:51.329937404Z,10,2,38,A,B,0,233.77,200,130,166864,12356295,233.77,234.0,200,154,1,7,233.71,234.06,26,400,1,1,233.7,234.13,1200,430,1,2,233.66,234.17,1,1,1,1,233.58,234.41,505,600,2,2,233.53,234.43,10,105,1,2,233.5,234.5,100,63,1,4,233.45,234.75,15,1,1,1,233.4,234.79,110,2000,2,1,233.39,234.89,10,2,1,2,AAPL,200.0,200.0,26.0,1200.0,1.0,505.0,10.0,100.0,15.0,110.0,10.0,209.14200905791162,
2024-10-21T12:12:51.374577807Z,2024-10-21T12:12:51.374411634Z,10,2,38,C,B,0,233.77,200,130,166173,12356317,233.71,234.0,26,154,1,7,233.7,234.06,1200,400,1,1,233.66,234.13,1,430,1,2,233.58,234.17,505,1,2,1,233.53,234.41,10,600,1,2,233.5,234.43,100,105,1,2,233.45,234.5,15,63,1,4,233.4,234.75,110,1,2,1,233.39,234.79,10,2000,1,1,233.31,234.89,110,2,2,2,AAPL,-200.0,-200.0,-26.0,-1200.0,-1.0,-505.0,-10.0,-100.0,-15.0,-110.0,-10.0,-209.14200905791162,
2024-10-21T12:12:51.475205660Z,2024-10-21T12:12:51.475039269Z,10,2,38,A,B,0,233.77,200,130,166391,12356344,233.77,234.0,200,154,1,7,233.71,234.06,26,400,1,1,233.7,234.13,1200,430,1,2,233.66,234.17,1,1,1,1,233.58,234.41,505,600,2,2,233.53,234.43,10,105,1,2,233.5,234.5,100,63,1,4,233.45,234.75,15,1,1,1,233.4,234.79,110,2000,2,1,233.39,234.89,10,2,1,2,AAPL,200.0,200.0,26.0,1200.0,1.0,505.0,10.0,100.0,15.0,110.0,10.0,209.14200905791162,
2024-10-21T12:12:51.507242100Z,2024-10-21T12:12:51.507076220Z,10,2,38,C,B,0,233.77,200,130,165880,12356356,233.71,234.0,26,154,1,7,233.7,234.06,1200,400,1,1,233.66,234.13,1,430,1,2,233.58,234.17,505,1,2,1,233.53,234.41,10,600,1,2,233.5,234.43,100,105,1,2,233.45,234.5,15,63,1,4,233.4,234.75,110,1,2,1,233.39,234.79,10,2000,1,1,233.31,234.89,110,2,2,2,AAPL,-200.0,-200.0,-26.0,-1200.0,-1.0,-505.0,-10.0,-100.0,-15.0,-110.0,-10.0,-209.14200905791162,
2024-10-21T12:12:51.709392937Z,2024-10-21T12:12:51.709226597Z,10,2,38,A,B,0,233.77,200,130,166340,12356415,233.77,234.0,200,154,1,7,233.71,234.06,26,400,1,1,233.7,234.13,1200,430,1,2,233.66,234.17,1,1,1,1,233.58,234.41,505,600,2,2,233.53,234.43,10,105,1,2,233.5,234.5,100,63,1,4,233.45,234.75,15,1,1,1,233.4,234.79,110,2000,2,1,233.39,234.89,10,2,1,2,AAPL,200.0,200.0,26.0,1200.0,1.0,505.0,10.0,100.0,15.0,110.0,10.0,209.14200905791162,
2024-10-21T12:12:52.481412276Z,2024-10-21T12:12:52.481246232Z,10,2,38,C,B,0,233.77,200,130,166044,12356788,233.71,234.0,26,154,1,7,233.7,234.06,1200,400,1,1,233.66,234.13,1,430,1,2,233.58,234.17,505,1,2,1,233.53,234.41,10,600,1,2,233.5,234.43,100,105,1,2,233.45,234.5,15,63,1,4,233.4,234.75,110,1,2,1,233.39,234.79,10,2000,1,1,233.31,234.89,110,2,2,2,AAPL,-200.0,-200.0,-26.0,-1200.0,-1.0,-505.0,-10.0,-100.0,-15.0,-110.0,-10.0,-209.14200905791162,
2024-10-21T12:12:52.583011665Z,2024-10-21T12:12:52.582845276Z,10,2,38,A,B,0,233.77,200,130,166389,12356899,233.77,234.0,200,154,1,7,233.71,234.06,26,400,1,1,233.7,234.13,1200,430,1,2,233.66,234.17,1,1,1,1,233.58,234.41,505,600,2,2,233.53,234.43,10,105,1,2,233.5,234.5,100,63,1,4,233.45,234.75,15,1,1,1,233.4,234.79,110,2000,2,1,233.39,234.89,10,2,1,2,AAPL,200.0,200.0,26.0,1200.0,1.0,505.0,10.0,100.0,15.0,110.0,10.0,209.14200905791162,
2024-10-21T12:12:53.923027418Z,2024-10-21T12:12:53.922861024Z,10,2,38,C,B,1,233.71,26,130,166394,12357591,233.77,234.0,200,154,1,7,233.7,234.06,1200,400,1,1,233.66,234.13,1,430,1,2,233.58,234.17,505,1,2,1,233.53,234.41,10,600,1,2,233.5,234.43,100,105,1,2,233.45,234.5,15,63,1,4,233.4,234.75,110,1,2,1,233.39,234.79,10,2000,1,1,233.31,234.89,110,2,2,2,AAPL,0.0,0.0,-26.0,-1200.0,-1.0,-505.0,-10.0,-100.0,-15.0,-110.0,-10.0,-205.1658925286866,
2024-10-21T12:12:53.923129817Z,2024-10-21T12:12:53.922963386Z,10,2,38,A,B,1,233.76,27,130,166431,12357592,233.77,234.0,200,154,1,7,233.76,234.06,27,400,1,1,233.7,234.13,1200,430,1,2,233.66,234.17,1,1,1,1,233.58,234.41,505,600,2,2,233.53,234.43,10,105,1,2,233.5,234.5,100,63,1,4,233.45,234.75,15,1,1,1,233.4,234.79,110,2000,2,1,233.39,234.89,10,2,1,2,AAPL,0.0,0.0,27.0,1200.0,1.0,505.0,10.0,100.0,15.0,110.0,10.0,205.2293086915155,
2024-10-21T12:12:59.629031962Z,2024-10-21T12:12:59.628865467Z,10,2,38,A,B,0,233.78,200,130,166495,12361324,233.78,234.0,200,154,1,7,233.76,234.06,27,400,1,1,233.7,234.13,1200,430,1,2,233.66,234.17,1,1,1,1,233.58,234.41,505,600,2,2,233.53,234.43,10,105,1,2,233.5,234.5,100,63,1,4,233.45,234.75,15,1,1,1,233.4,234.79,110,2000,2,1,233.39,234.89,10,2,1,2,AAPL,200.0,200.0,0.0,0.0,0.0,0.0,0.0,0.0,0.0,0.0,0.0,3.9761165292250036,
2024-10-21T12:12:59.643903867Z,2024-10-21T12:12:59.643737494Z,10,2,38,A,B,1,233.77,26,130,166373,12361417,233.78,234.0,200,154,1,7,233.77,234.06,26,400,1,1,233.76,234.13,27,430,1,2,233.7,234.17,1200,1,1,1,233.66,234.41,1,600,1,2,233.58,234.43,505,105,2,2,233.53,234.5,10,63,1,4,233.5,234.75,100,1,1,1,233.45,234.79,15,2000,1,1,233.4,234.89,110,2,2,2,AAPL,0.0,0.0,26.0,27.0,1200.0,1.0,505.0,10.0,100.0,15.0,110.0,340.28906385826497,
2024-10-21T12:12:59.691792264Z,2024-10-21T12:12:59.691625988Z,10,2,38,C,B,2,233.76,27,130,166276,12361539,233.78,234.0,200,154,1,7,233.77,234.06,26,400,1,1,233.7,234.13,1200,430,1,2,233.66,234.17,1,1,1,1,233.58,234.41,505,600,2,2,233.53,234.43,10,105,1,2,233.5,234.5,100,63,1,4,233.45,234.75,15,1,1,1,233.4,234.79,110,2000,2,1,233.39,234.89,10,2,1,2,AAPL,0.0,0.0,0.0,-27.0,-1200.0,-1.0,-505.0,-10.0,-100.0,-15.0,-110.0,-338.64024362471434,
2024-10-21T12:12:59.691815700Z,2024-10-21T12:12:59.691649558Z,10,2,38,C,B,1,233.77,26,130,166142,12361540,233.78,234.0,200,154,1,7,233.7,234.06,1200,400,1,1,233.66,234.13,1,430,1,2,233.58,234.17,505,1,2,1,233.53,234.41,10,600,1,2,233.5,234.43,100,105,1,2,233.45,234.5,15,63,1,4,233.4,234.75,110,1,2,1,233.39,234.79,10,2000,1,1,233.31,234.89,110,2,2,2,AAPL,0.0,0.0,-26.0,-1200.0,-1.0,-505.0,-10.0,-100.0,-15.0,-110.0,-10.0,-205.1658925286866,
2024-10-21T12:12:59.691888302Z,2024-10-21T12:12:59.691721965Z,10,2,38,A,B,1,233.77,26,130,166337,12361541,233.78,234.0,200,154,1,7,233.77,234.06,26,400,1,1,233.7,234.13,1200,430,1,2,233.66,234.17,1,1,1,1,233.58,234.41,505,600,2,2,233.53,234.43,10,105,1,2,233.5,234.5,100,63,1,4,233.45,234.75,15,1,1,1,233.4,234.79,110,2000,2,1,233.39,234.89,10,2,1,2,AAPL,0.0,0.0,26.0,1200.0,1.0,505.0,10.0,100.0,15.0,110.0,10.0,205.1658925286866,
2024-10-21T12:13:11.883895663Z,2024-10-21T12:13:11.883729412Z,10,2,38,C,A,1,234.06,400,130,166251,12371151,233.78,234.0,200,154,1,7,233.77,234.13,26,430,1,2,233.7,234.17,1200,1,1,1,233.66,234.41,1,600,1,2,233.58,234.43,505,105,2,2,233.53,234.5,10,63,1,4,233.5,234.75,100,1,1,1,233.45,234.79,15,2000,1,1,233.4,234.89,110,2,2,2,233.39,235.0,10,213,1,6,AAPL,0.0,0.0,430.0,1.0,600.0,105.0,63.0,1.0,2000.0,2.0,213.0,389.924981363918,
2024-10-21T12:13:11.920775720Z,2024-10-21T12:13:11.920609443Z,10,2,38,A,A,1,234.06,200,130,166277,12371429,233.78,234.0,200,154,1,7,233.77,234.06,26,200,1,1,233.7,234.13,1200,430,1,2,233.66,234.17,1,1,1,1,233.58,234.41,505,600,2,2,233.53,234.43,10,105,1,2,233.5,234.5,100,63,1,4,233.45,234.75,15,1,1,1,233.4,234.79,110,2000,2,1,233.39,234.89,10,2,1,2,AAPL,0.0,0.0,-430.0,-1.0,-600.0,-105.0,-63.0,-1.0,-2000.0,-2.0,-213.0,-389.924981363918,
2024-10-21T12:13:11.948803197Z,2024-10-21T12:13:11.948637105Z,10,2,38,A,A,1,234.06,200,130,166092,12371519,233.78,234.0,200,154,1,7,233.77,234.06,26,400,1,2,233.7,234.13,1200,430,1,2,233.66,234.17,1,1,1,1,233.58,234.41,505,600,2,2,233.53,234.43,10,105,1,2,233.5,234.5,100,63,1,4,233.45,234.75,15,1,1,1,233.4,234.79,110,2000,2,1,233.39,234.89,10,2,1,2,AAPL,0.0,0.0,-200.0,0.0,0.0,0.0,0.0,0.0,0.0,0.0,0.0,-12.683232565773917,
2024-10-21T12:13:21.543158873Z,2024-10-21T12:13:21.542992246Z,10,2,38,C,A,1,234.06,200,130,166627,12379437,233.78,234.0,200,154,1,7,233.77,234.06,26,200,1,1,233.7,234.13,1200,430,1,2,233.66,234.17,1,1,1,1,233.58,234.41,505,600,2,2,233.53,234.43,10,105,1,2,233.5,234.5,100,63,1,4,233.45,234.75,15,1,1,1,233.4,234.79,110,2000,2,1,233.39,234.89,10,2,1,2,AAPL,0.0,0.0,200.0,0.0,0.0,0.0,0.0,0.0,0.0,0.0,0.0,12.683232565773917,
2024-10-21T12:13:21.543168132Z,2024-10-21T12:13:21.543002194Z,10,2,38,C,A,1,234.06,200,130,165938,12379438,233.78,234.0,200,154,1,7,233.77,234.13,26,430,1,2,233.7,234.17,1200,1,1,1,233.66,234.41,1,600,1,2,233.58,234.43,505,105,2,2,233.53,234.5,10,63,1,4,233.5,234.75,100,1,1,1,233.45,234.79,15,2000,1,1,233.4,234.89,110,2,2,2,233.39,235.0,10,213,1,6,AAPL,0.0,0.0,430.0,1.0,600.0,105.0,63.0,1.0,2000.0,2.0,213.0,389.924981363918,
2024-10-21T12:13:21.543179396Z,2024-10-21T12:13:21.543013145Z,10,2,38,A,A,1,234.08,400,130,166251,12379439,233.78,234.0,200,154,1,7,233.77,234.08,26,400,1,1,233.7,234.13,1200,430,1,2,233.66,234.17,1,1,1,1,233.58,234.41,505,600,2,2,233.53,234.43,10,105,1,2,233.5,234.5,100,63,1,4,233.45,234.75,15,1,1,1,233.4,234.79,110,2000,2,1,233.39,234.89,10,2,1,2,AAPL,0.0,0.0,-430.0,-1.0,-600.0,-105.0,-63.0,-1.0,-2000.0,-2.0,-213.0,-389.924981363918,
2024-10-21T12:13:21.617302321Z,2024-10-21T12:13:21.617135979Z,10,2,38,C,B,1,233.77,26,130,166342,12379657,233.78,234.0,200,154,1,7,233.7,234.08,1200,400,1,1,233.66,234.13,1,430,1,2,233.58,234.17,505,1,2,1,233.53,234.41,10,600,1,2,233.5,234.43,100,105,1,2,233.45,234.5,15,63,1,4,233.4,234.75,110,1,2,1,233.39,234.79,10,2000,1,1,233.31,234.89,110,2,2,2,AAPL,0.0,0.0,-26.0,-1200.0,-1.0,-505.0,-10.0,-100.0,-15.0,-110.0,-10.0,-205.1658925286866,
2024-10-21T12:13:21.617386770Z,2024-10-21T12:13:21.617220419Z,10,2,38,A,B,1,233.72,26,130,166351,12379659,233.78,234.0,200,154,1,7,233.72,234.08,26,400,1,1,233.7,234.13,1200,430,1,2,233.66,234.17,1,1,1,1,233.58,234.41,505,600,2,2,233.53,234.43,10,105,1,2,233.5,234.5,100,63,1,4,233.45,234.75,15,1,1,1,233.4,234.79,110,2000,2,1,233.39,234.89,10,2,1,2,AAPL,0.0,0.0,26.0,1200.0,1.0,505.0,10.0,100.0,15.0,110.0,10.0,205.1658925286866,
2024-10-21T12:13:22.557998386Z,2024-10-21T12:13:22.557831797Z,10,2,38,A,A,1,234.07,400,130,166589,12380655,233.78,234.0,200,154,1,7,233.72,234.07,26,400,1,1,233.7,234.13,1200,430,1,2,233.66,234.17,1,1,1,1,233.58,234.41,505,600,2,2,233.53,234.43,10,105,1,2,233.5,234.5,100,63,1,4,233.45,234.75,15,1,1,1,233.4,234.79,110,2000,2,1,233.39,234.89,10,2,1,2,AAPL,0.0,0.0,-400.0,0.0,0.0,0.0,0.0,0.0,0.0,0.0,0.0,-25.366465131547834,
2024-10-21T12:13:25.372097284Z,2024-10-21T12:13:25.371930587Z,10,2,38,A,B,0,233.79,200,130,166697,12382998,233.79,234.0,200,154,1,7,233.72,234.07,26,400,1,1,233.7,234.13,1200,430,1,2,233.66,234.17,1,1,1,1,233.58,234.41,505,600,2,2,233.53,234.43,10,105,1,2,233.5,234.5,100,63,1,4,233.45,234.75,15,1,1,1,233.4,234.79,110,2000,2,1,233.39,234.89,10,2,1,2,AAPL,200.0,200.0,0.0,0.0,0.0,0.0,0.0,0.0,0.0,0.0,0.0,3.9761165292250036,
2024-10-21T12:13:25.495708682Z,2024-10-21T12:13:25.495542627Z,10,2,38,C,B,1,233.72,26,130,166055,12383140,233.79,234.0,200,154,1,7,233.7,234.07,1200,400,1,1,233.66,234.13,1,430,1,2,233.58,234.17,505,1,2,1,233.53,234.41,10,600,1,2,233.5,234.43,100,105,1,2,233.45,234.5,15,63,1,4,233.4,234.75,110,1,2,1,233.39,234.79,10,2000,1,1,233.31,234.89,110,2,2,2,AAPL,0.0,0.0,-26.0,-1200.0,-1.0,-505.0,-10.0,-100.0,-15.0,-110.0,-10.0,-205.1658925286866,
2024-10-21T12:13:25.495754875Z,2024-10-21T12:13:25.495588580Z,10,2,38,A,B,1,233.73,27,130,166295,12383141,233.79,234.0,200,154,1,7,233.73,234.07,27,400,1,1,233.7,234.13,1200,430,1,2,233.66,234.17,1,1,1,1,233.58,234.41,505,600,2,2,233.53,234.43,10,105,1,2,233.5,234.5,100,63,1,4,233.45,234.75,15,1,1,1,233.4,234.79,110,2000,2,1,233.39,234.89,10,2,1,2,AAPL,0.0,0.0,27.0,1200.0,1.0,505.0,10.0,100.0,15.0,110.0,10.0,205.2293086915155,
2024-10-21T12:13:29.150506254Z,2024-10-21T12:13:29.150340169Z,10,2,38,A,A,3,234.15,30,130,166085,12386039,233.79,234.0,200,154,1,7,233.73,234.07,27,400,1,1,233.7,234.13,1200,430,1,2,233.66,234.15,1,30,1,1,233.58,234.17,505,1,2,1,233.53,234.41,10,600,1,2,233.5,234.43,100,105,1,2,233.45,234.5,15,63,1,4,233.4,234.75,110,1,2,1,233.39,234.79,10,2000,1,1,AAPL,0.0,0.0,0.0,0.0,-1.0,-600.0,-105.0,-63.0,-1.0,-2000.0,-2.0,-230.56381802188298,
2024-10-21T12:13:29.268802068Z,2024-10-21T12:13:29.268636112Z,10,2,38,C,A,2,234.13,30,130,165956,12386279,233.79,234.0,200,154,1,7,233.73,234.07,27,400,1,1,233.7,234.13,1200,400,1,1,233.66,234.15,1,30,1,1,233.58,234.17,505,1,2,1,233.53,234.41,10,600,1,2,233.5,234.43,100,105,1,2,233.45,234.5,15,63,1,4,233.4,234.75,110,1,2,1,233.39,234.79,10,2000,1,1,AAPL,0.0,0.0,0.0,30.0,0.0,0.0,0.0,0.0,0.0,0.0,0.0,3.047477422080156,
2024-10-21T12:13:32.213848825Z,2024-10-21T12:13:32.213682828Z,10,2,38,C,A,1,234.07,400,130,165997,12388761,233.79,234.0,200,154,1,7,233.73,234.13,27,400,1,1,233.7,234.15,1200,30,1,1,233.66,234.17,1,1,1,1,233.58,234.41,505,600,2,2,233.53,234.43,10,105,1,2,233.5,234.5,100,63,1,4,233.45,234.75,15,1,1,1,233.4,234.79,110,2000,2,1,233.39,234.89,10,2,1,2,AAPL,0.0,0.0,400.0,30.0,1.0,600.0,105.0,63.0,1.0,2000.0,2.0,258.97776057551096,
2024-10-21T12:13:32.213862106Z,2024-10-21T12:13:32.213695191Z,10,2,38,A,A,1,234.09,400,130,166915,12388762,233.79,234.0,200,154,1,7,233.73,234.09,27,400,1,1,233.7,234.13,1200,400,1,1,233.66,234.15,1,30,1,1,233.58,234.17,505,1,2,1,233.53,234.41,10,600,1,2,233.5,234.43,100,105,1,2,233.45,234.5,15,63,1,4,233.4,234.75,110,1,2,1,233.39,234.79,10,2000,1,1,AAPL,0.0,0.0,-400.0,-30.0,-1.0,-600.0,-105.0,-63.0,-1.0,-2000.0,-2.0,-258.97776057551096,
2024-10-21T12:13:32.278971542Z,2024-10-21T12:13:32.278804796Z,10,2,38,A,B,0,233.8,200,130,166746,12388939,233.8,234.0,200,154,1,7,233.73,234.09,27,400,1,1,233.7,234.13,1200,400,1,1,233.66,234.15,1,30,1,1,233.58,234.17,505,1,2,1,233.53,234.41,10,600,1,2,233.5,234.43,100,105,1,2,233.45,234.5,15,63,1,4,233.4,234.75,110,1,2,1,233.39,234.79,10,2000,1,1,AAPL,200.0,200.0,0.0,0.0,0.0,0.0,0.0,0.0,0.0,0.0,0.0,3.9761165292250036,
2024-10-21T12:13:32.362493854Z,2024-10-21T12:13:32.362327800Z,10,2,38,C,A,3,234.15,30,130,166054,12389254,233.8,234.0,200,154,1,7,233.73,234.09,27,400,1,1,233.7,234.13,1200,400,1,1,233.66,234.17,1,1,1,1,233.58,234.41,505,600,2,2,233.53,234.43,10,105,1,2,233.5,234.5,100,63,1,4,233.45,234.75,15,1,1,1,233.4,234.79,110,2000,2,1,233.39,234.89,10,2,1,2,AAPL,0.0,0.0,0.0,0.0,1.0,600.0,105.0,63.0,1.0,2000.0,2.0,230.56381802188298,
2024-10-21T12:13:32.402038108Z,2024-10-21T12:13:32.401872088Z,10,2,38,C,B,1,233.73,27,130,166020,12389357,233.8,234.0,200,154,1,7,233.7,234.09,1200,400,1,1,233.66,234.13,1,400,1,1,233.58,234.17,505,1,2,1,233.53,234.41,10,600,1,2,233.5,234.43,100,105,1,2,233.45,234.5,15,63,1,4,233.4,234.75,110,1,2,1,233.39,234.79,10,2000,1,1,233.31,234.89,110,2,2,2,AAPL,0.0,0.0,-27.0,-1200.0,-1.0,-505.0,-10.0,-100.0,-15.0,-110.0,-10.0,-205.2293086915155,
2024-10-21T12:13:32.412797711Z,2024-10-21T12:13:32.412631196Z,10,2,38,A,A,2,234.11,27,130,166515,12389377,233.8,234.0,200,154,1,7,233.7,234.09,1200,400,1,1,233.66,234.11,1,27,1,1,233.58,234.13,505,400,2,1,233.53,234.17,10,1,1,1,233.5,234.41,100,600,1,2,233.45,234.43,15,105,1,2,233.4,234.5,110,63,2,4,233.39,234.75,10,1,1,1,233.31,234.79,110,2000,2,1,AAPL,0.0,0.0,0.0,-400.0,-1.0,-600.0,-105.0,-63.0,-1.0,-2000.0,-2.0,-271.19685031628507,
2024-10-21T12:13:34.144890619Z,2024-10-21T12:13:34.144724456Z,10,2,38,A,B,0,233.89,100,130,166163,12390756,233.89,234.0,100,154,1,7,233.8,234.09,200,400,1,1,233.7,234.11,1200,27,1,1,233.66,234.13,1,400,1,1,233.58,234.17,505,1,2,1,233.53,234.41,10,600,1,2,233.5,234.43,100,105,1,2,233.45,234.5,15,63,1,4,233.4,234.75,110,1,2,1,233.39,234.79,10,2000,1,1,AAPL,100.0,100.0,200.0,1200.0,1.0,505.0,10.0,100.0,15.0,110.0,10.0,218.18836312552244,
2024-10-21T12:13:34.145338999Z,2024-10-21T12:13:34.145172866Z,10,2,38,C,B,0,233.89,100,130,166133,12390759,233.8,234.0,200,154,1,7,233.7,234.09,1200,400,1,1,233.66,234.11,1,27,1,1,233.58,234.13,505,400,2,1,233.53,234.17,10,1,1,1,233.5,234.41,100,600,1,2,233.45,234.43,15,105,1,2,233.4,234.5,110,63,2,4,233.39,234.75,10,1,1,1,233.31,234.79,110,2000,2,1,AAPL,-100.0,-100.0,-200.0,-1200.0,-1.0,-505.0,-10.0,-100.0,-15.0,-110.0,-10.0,-218.18836312552244,
2024-10-21T12:13:34.215444342Z,2024-10-21T12:13:34.215278319Z,10,2,38,C,A,2,234.11,27,130,166023,12390798,233.8,234.0,200,154,1,7,233.7,234.09,1200,400,1,1,233.66,234.13,1,400,1,1,233.58,234.17,505,1,2,1,233.53,234.41,10,600,1,2,233.5,234.43,100,105,1,2,233.45,234.5,15,63,1,4,233.4,234.75,110,1,2,1,233.39,234.79,10,2000,1,1,233.31,234.89,110,2,2,2,AAPL,0.0,0.0,0.0,400.0,1.0,600.0,105.0,63.0,1.0,2000.0,2.0,271.19685031628507,
2024-10-21T12:13:34.277590859Z,2024-10-21T12:13:34.277424242Z,10,2,38,A,A,1,234.06,200,130,166617,12390835,233.8,234.0,200,154,1,7,233.7,234.06,1200,200,1,1,233.66,234.13,1,400,1,1,233.58,234.17,505,1,2,1,233.53,234.41,10,600,1,2,233.5,234.43,100,105,1,2,233.45,234.5,15,63,1,4,233.4,234.75,110,1,2,1,233.39,234.79,10,2000,1,1,233.31,234.89,110,2,2,2,AAPL,0.0,0.0,-400.0,0.0,0.0,0.0,0.0,0.0,0.0,0.0,0.0,-25.366465131547834,
2024-10-21T12:13:35.061243869Z,2024-10-21T12:13:35.061077358Z,10,2,38,A,B,0,233.81,200,130,166511,12391575,233.81,234.0,200,154,1,7,233.7,234.06,1200,200,1,1,233.66,234.13,1,400,1,1,233.58,234.17,505,1,2,1,233.53,234.41,10,600,1,2,233.5,234.43,100,105,1,2,233.45,234.5,15,63,1,4,233.4,234.75,110,1,2,1,233.39,234.79,10,2000,1,1,233.31,234.89,110,2,2,2,AAPL,200.0,200.0,0.0,0.0,0.0,0.0,0.0,0.0,0.0,0.0,0.0,3.9761165292250036,
2024-10-21T12:13:35.075339842Z,2024-10-21T12:13:35.075174042Z,10,2,38,C,B,0,233.81,200,130,165800,12391728,233.7,234.0,1200,154,1,7,233.66,234.06,1,200,1,1,233.58,234.13,505,400,2,1,233.53,234.17,10,1,1,1,233.5,234.41,100,600,1,2,233.45,234.43,15,105,1,2,233.4,234.5,110,63,2,4,233.39,234.75,10,1,1,1,233.31,234.79,110,2000,2,1,233.3,234.89,100,2,1,2,AAPL,-200.0,-200.0,-1200.0,-1.0,-505.0,-10.0,-100.0,-15.0,-110.0,-10.0,-110.0,-220.06761557307559,
2024-10-21T12:13:35.075350085Z,2024-10-21T12:13:35.075183720Z,10,2,38,A,B,0,233.74,200,130,166365,12391729,233.74,234.0,200,154,1,7,233.7,234.06,1200,200,1,1,233.66,234.13,1,400,1,1,233.58,234.17,505,1,2,1,233.53,234.41,10,600,1,2,233.5,234.43,100,105,1,2,233.45,234.5,15,63,1,4,233.4,234.75,110,1,2,1,233.39,234.79,10,2000,1,1,233.31,234.89,110,2,2,2,AAPL,200.0,200.0,1200.0,1.0,505.0,10.0,100.0,15.0,110.0,10.0,110.0,220.06761557307559,
2024-10-21T12:13:35.077639622Z,2024-10-21T12:13:35.077473825Z,10,2,38,C,A,1,234.06,200,130,165797,12391777,233.74,234.0,200,154,1,7,233.7,234.13,1200,400,1,1,233.66,234.17,1,1,1,1,233.58,234.41,505,600,2,2,233.53,234.43,10,105,1,2,233.5,234.5,100,63,1,4,233.45,234.75,15,1,1,1,233.4,234.79,110,2000,2,1,233.39,234.89,10,2,1,2,233.31,235.0,110,213,2,6,AAPL,0.0,0.0,400.0,1.0,600.0,105.0,63.0,1.0,2000.0,2.0,213.0,388.02249647905194,
2024-10-21T12:13:35.077651330Z,2024-10-21T12:13:35.077485044Z,10,2,38,A,A,1,234.08,200,130,166286,12391778,233.74,234.0,200,154,1,7,233.7,234.08,1200,200,1,1,233.66,234.13,1,400,1,1,233.58,234.17,505,1,2,1,233.53,234.41,10,600,1,2,233.5,234.43,100,105,1,2,233.45,234.5,15,63,1,4,233.4,234.75,110,1,2,1,233.39,234.79,10,2000,1,1,233.31,234.89,110,2,2,2,AAPL,0.0,0.0,-400.0,-1.0,-600.0,-105.0,-63.0,-1.0,-2000.0,-2.0,-213.0,-388.02249647905194,
2024-10-21T12:13:35.086732850Z,2024-10-21T12:13:35.086566953Z,10,2,38,C,B,0,233.74,200,130,165897,12391883,233.7,234.0,1200,154,1,7,233.66,234.08,1,200,1,1,233.58,234.13,505,400,2,1,233.53,234.17,10,1,1,1,233.5,234.41,100,600,1,2,233.45,234.43,15,105,1,2,233.4,234.5,110,63,2,4,233.39,234.75,10,1,1,1,233.31,234.79,110,2000,2,1,233.3,234.89,100,2,1,2,AAPL,-200.0,-200.0,-1200.0,-1.0,-505.0,-10.0,-100.0,-15.0,-110.0,-10.0,-110.0,-220.06761557307559,
2024-10-21T12:13:35.086745457Z,2024-10-21T12:13:35.086579076Z,10,2,38,A,B,0,233.72,400,130,166381,12391884,233.72,234.0,400,154,1,7,233.7,234.08,1200,200,1,1,233.66,234.13,1,400,1,1,233.58,234.17,505,1,2,1,233.53,234.41,10,600,1,2,233.5,234.43,100,105,1,2,233.45,234.5,15,63,1,4,233.4,234.75,110,1,2,1,233.39,234.79,10,2000,1,1,233.31,234.89,110,2,2,2,AAPL,400.0,400.0,1200.0,1.0,505.0,10.0,100.0,15.0,110.0,10.0,110.0,224.04373210230057,
2024-10-21T12:13:35.108265805Z,2024-10-21T12:13:35.108095991Z,10,2,38,T,N,0,233.94,50,0,169814,12392002,233.72,234.0,400,154,1,7,233.7,234.08,1200,200,1,1,233.66,234.13,1,400,1,1,233.58,234.17,505,1,2,1,233.53,234.41,10,600,1,2,233.5,234.43,100,105,1,2,233.45,234.5,15,63,1,4,233.4,234.75,110,1,2,1,233.39,234.79,10,2000,1,1,233.31,234.89,110,2,2,2,AAPL,0.0,0.0,0.0,0.0,0.0,0.0,0.0,0.0,0.0,0.0,0.0,0.0,
2024-10-21T12:13:35.108265805Z,2024-10-21T12:13:35.108095991Z,10,2,38,T,N,0,233.93,50,0,169814,12392003,233.72,234.0,400,154,1,7,233.7,234.08,1200,200,1,1,233.66,234.13,1,400,1,1,233.58,234.17,505,1,2,1,233.53,234.41,10,600,1,2,233.5,234.43,100,105,1,2,233.45,234.5,15,63,1,4,233.4,234.75,110,1,2,1,233.39,234.79,10,2000,1,1,233.31,234.89,110,2,2,2,AAPL,0.0,0.0,0.0,0.0,0.0,0.0,0.0,0.0,0.0,0.0,0.0,0.0,
2024-10-21T12:13:35.108265805Z,2024-10-21T12:13:35.108095991Z,10,2,38,T,N,0,233.9,250,130,169814,12392004,233.72,234.0,400,154,1,7,233.7,234.08,1200,200,1,1,233.66,234.13,1,400,1,1,233.58,234.17,505,1,2,1,233.53,234.41,10,600,1,2,233.5,234.43,100,105,1,2,233.45,234.5,15,63,1,4,233.4,234.75,110,1,2,1,233.39,234.79,10,2000,1,1,233.31,234.89,110,2,2,2,AAPL,0.0,0.0,0.0,0.0,0.0,0.0,0.0,0.0,0.0,0.0,0.0,0.0,
2024-10-21T12:13:35.146538430Z,2024-10-21T12:13:35.146372690Z,10,2,38,C,B,0,233.72,400,130,165740,12392297,233.7,234.0,1200,154,1,7,233.66,234.08,1,200,1,1,233.58,234.13,505,400,2,1,233.53,234.17,10,1,1,1,233.5,234.41,100,600,1,2,233.45,234.43,15,105,1,2,233.4,234.5,110,63,2,4,233.39,234.75,10,1,1,1,233.31,234.79,110,2000,2,1,233.3,234.89,100,2,1,2,AAPL,-400.0,-400.0,-1200.0,-1.0,-505.0,-10.0,-100.0,-15.0,-110.0,-10.0,-110.0,-224.04373210230057,
2024-10-21T12:13:35.146551508Z,2024-10-21T12:13:35.146384339Z,10,2,38,A,B,0,233.7,200,128,167169,12392298,233.7,234.0,1400,154,2,7,233.66,234.08,1,200,1,1,233.58,234.13,505,400,2,1,233.53,234.17,10,1,1,1,233.5,234.41,100,600,1,2,233.45,234.43,15,105,1,2,233.4,234.5,110,63,2,4,233.39,234.75,10,1,1,1,233.31,234.79,110,2000,2,1,233.3,234.89,100,2,1,2,AAPL,200.0,200.0,0.0,0.0,0.0,0.0,0.0,0.0,0.0,0.0,0.0,3.9761165292250036,
2024-10-21T12:13:35.168035257Z,2024-10-21T12:13:35.167869345Z,10,2,38,C,B,0,233.7,200,130,165912,12392426,233.7,234.0,1200,154,1,7,233.66,234.08,1,200,1,1,233.58,234.13,505,400,2,1,233.53,234.17,10,1,1,1,233.5,234.41,100,600,1,2,233.45,234.43,15,105,1,2,233.4,234.5,110,63,2,4,233.39,234.75,10,1,1,1,233.31,234.79,110,2000,2,1,233.3,234.89,100,2,1,2,AAPL,-200.0,-200.0,0.0,0.0,0.0,0.0,0.0,0.0,0.0,0.0,0.0,-3.9761165292250036,
2024-10-21T12:13:35.175958206Z,2024-10-21T12:13:35.175791647Z,10,2,38,A,B,2,233.64,200,130,166559,12392448,233.7,234.0,1200,154,1,7,233.66,234.08,1,200,1,1,233.64,234.13,200,400,1,1,233.58,234.17,505,1,2,1,233.53,234.41,10,600,1,2,233.5,234.43,100,105,1,2,233.45,234.5,15,63,1,4,233.4,234.75,110,1,2,1,233.39,234.79,10,2000,1,1,233.31,234.89,110,2,2,2,AAPL,0.0,0.0,0.0,200.0,505.0,10.0,100.0,15.0,110.0,10.0,110.0,160.2070372156721,
2024-10-21T12:13:35.334095780Z,2024-10-21T12:13:35.333929432Z,10,2,38,A,B,2,233.65,200,130,166348,12392747,233.7,234.0,1200,154,1,7,233.66,234.08,1,200,1,1,233.65,234.13,200,400,1,1,233.58,234.17,505,1,2,1,233.53,234.41,10,600,1,2,233.5,234.43,100,105,1,2,233.45,234.5,15,63,1,4,233.4,234.75,110,1,2,1,233.39,234.79,10,2000,1,1,233.31,234.89,110,2,2,2,AAPL,0.0,0.0,0.0,200.0,0.0,0.0,0.0,0.0,0.0,0.0,0.0,20.31651614720104,
2024-10-21T12:13:35.352463215Z,2024-10-21T12:13:35.352296693Z,10,2,38,A,B,0,233.7,200,130,166522,12392766,233.7,234.0,1400,154,2,7,233.66,234.08,1,200,1,1,233.58,234.13,505,400,2,1,233.53,234.17,10,1,1,1,233.5,234.41,100,600,1,2,233.45,234.43,15,105,1,2,233.4,234.5,110,63,2,4,233.39,234.75,10,1,1,1,233.31,234.79,110,2000,2,1,233.3,234.89,100,2,1,2,AAPL,200.0,200.0,0.0,-200.0,-505.0,-10.0,-100.0,-15.0,-110.0,-10.0,-110.0,-156.2309206864471,
2024-10-21T12:13:35.424517936Z,2024-10-21T12:13:35.424351548Z,10,2,38,A,B,0,233.72,200,130,166388,12392793,233.72,234.0,200,154,1,7,233.7,234.08,1200,200,1,1,233.66,234.13,1,400,1,1,233.58,234.17,505,1,2,1,233.53,234.41,10,600,1,2,233.5,234.43,100,105,1,2,233.45,234.5,15,63,1,4,233.4,234.75,110,1,2,1,233.39,234.79,10,2000,1,1,233.31,234.89,110,2,2,2,AAPL,200.0,200.0,1200.0,1.0,505.0,10.0,100.0,15.0,110.0,10.0,110.0,220.06761557307559,
2024-10-21T12:13:38.132138622Z,2024-10-21T12:13:38.131971887Z,10,2,38,A,B,0,233.77,200,130,166735,12394618,233.77,234.0,200,154,1,7,233.7,234.08,1200,200,1,1,233.66,234.13,1,400,1,1,233.58,234.17,505,1,2,1,233.53,234.41,10,600,1,2,233.5,234.43,100,105,1,2,233.45,234.5,15,63,1,4,233.4,234.75,110,1,2,1,233.39,234.79,10,2000,1,1,233.31,234.89,110,2,2,2,AAPL,200.0,200.0,0.0,0.0,0.0,0.0,0.0,0.0,0.0,0.0,0.0,3.9761165292250036,
2024-10-21T12:13:42.509253965Z,2024-10-21T12:13:42.509087486Z,10,2,38,A,B,1,233.76,29,130,166479,12397192,233.77,234.0,200,154,1,7,233.76,234.08,29,200,1,1,233.7,234.13,1200,400,1,1,233.66,234.17,1,1,1,1,233.58,234.41,505,600,2,2,233.53,234.43,10,105,1,2,233.5,234.5,100,63,1,4,233.45,234.75,15,1,1,1,233.4,234.79,110,2000,2,1,233.39,234.89,10,2,1,2,AAPL,0.0,0.0,29.0,1200.0,1.0,505.0,10.0,100.0,15.0,110.0,10.0,205.35614101717326,
2024-10-21T12:13:42.509287026Z,2024-10-21T12:13:42.509120725Z,10,2,38,A,A,2,234.13,29,130,166301,12397193,233.77,234.0,200,154,1,7,233.76,234.08,29,200,1,1,233.7,234.13,1200,429,1,2,233.66,234.17,1,1,1,1,233.58,234.41,505,600,2,2,233.53,234.43,10,105,1,2,233.5,234.5,100,63,1,4,233.45,234.75,15,1,1,1,233.4,234.79,110,2000,2,1,233.39,234.89,10,2,1,2,AAPL,0.0,0.0,0.0,-29.0,0.0,0.0,0.0,0.0,0.0,0.0,0.0,-2.945894841344151,
2024-10-21T12:13:45.327521347Z,2024-10-21T12:13:45.327353906Z,10,2,38,A,A,1,234.07,200,130,167441,12399281,233.77,234.0,200,154,1,7,233.76,234.07,29,200,1,1,233.7,234.13,1200,429,1,2,233.66,234.17,1,1,1,1,233.58,234.41,505,600,2,2,233.53,234.43,10,105,1,2,233.5,234.5,100,63,1,4,233.45,234.75,15,1,1,1,233.4,234.79,110,2000,2,1,233.39,234.89,10,2,1,2,AAPL,0.0,0.0,-200.0,0.0,0.0,0.0,0.0,0.0,0.0,0.0,0.0,-12.683232565773917,
2024-10-21T12:13:45.348446565Z,2024-10-21T12:13:45.348280342Z,10,2,38,C,A,2,234.13,29,130,166223,12399379,233.77,234.0,200,154,1,7,233.76,234.07,29,200,1,1,233.7,234.13,1200,400,1,1,233.66,234.17,1,1,1,1,233.58,234.41,505,600,2,2,233.53,234.43,10,105,1,2,233.5,234.5,100,63,1,4,233.45,234.75,15,1,1,1,233.4,234.79,110,2000,2,1,233.39,234.89,10,2,1,2,AAPL,0.0,0.0,0.0,29.0,0.0,0.0,0.0,0.0,0.0,0.0,0.0,2.945894841344151,
2024-10-21T12:13:45.348489295Z,2024-10-21T12:13:45.348322946Z,10,2,38,A,A,2,234.12,26,130,166349,12399380,233.77,234.0,200,154,1,7,233.76,234.07,29,200,1,1,233.7,234.12,1200,26,1,1,233.66,234.13,1,400,1,1,233.58,234.17,505,1,2,1,233.53,234.41,10,600,1,2,233.5,234.43,100,105,1,2,233.45,234.5,15,63,1,4,233.4,234.75,110,1,2,1,233.39,234.79,10,2000,1,1,AAPL,0.0,0.0,0.0,-400.0,-1.0,-600.0,-105.0,-63.0,-1.0,-2000.0,-2.0,-271.19685031628507,
2024-10-21T12:13:45.469223815Z,2024-10-21T12:13:45.469056600Z,10,2,38,T,N,0,233.98,18,130,167215,12399561,233.77,234.0,200,154,1,7,233.76,234.07,29,200,1,1,233.7,234.12,1200,26,1,1,233.66,234.13,1,400,1,1,233.58,234.17,505,1,2,1,233.53,234.41,10,600,1,2,233.5,234.43,100,105,1,2,233.45,234.5,15,63,1,4,233.4,234.75,110,1,2,1,233.39,234.79,10,2000,1,1,AAPL,0.0,0.0,0.0,0.0,0.0,0.0,0.0,0.0,0.0,0.0,0.0,0.0,
2024-10-21T12:13:45.811636426Z,2024-10-21T12:13:45.811467280Z,10,2,38,C,A,0,234.0,3,130,169146,12400067,233.77,234.0,200,131,1,6,233.76,234.07,29,200,1,1,233.7,234.12,1200,26,1,1,233.66,234.13,1,400,1,1,233.58,234.17,505,1,2,1,233.53,234.41,10,600,1,2,233.5,234.43,100,105,1,2,233.45,234.5,15,63,1,4,233.4,234.75,110,1,2,1,233.39,234.79,10,2000,1,1,AAPL,23.0,23.0,0.0,0.0,0.0,0.0,0.0,0.0,0.0,0.0,0.0,0.45725340086087546,
2024-10-21T12:13:45.811636426Z,2024-10-21T12:13:45.811467280Z,10,2,38,T,B,0,234.0,3,130,169146,12400067,233.77,234.0,200,134,1,6,233.76,234.07,29,200,1,1,233.7,234.12,1200,26,1,1,233.66,234.13,1,400,1,1,233.58,234.17,505,1,2,1,233.53,234.41,10,600,1,2,233.5,234.43,100,105,1,2,233.45,234.5,15,63,1,4,233.4,234.75,110,1,2,1,233.39,234.79,10,2000,1,1,AAPL,-3.0,-3.0,0.0,0.0,0.0,0.0,0.0,0.0,0.0,0.0,0.0,-0.05964174793837505,
2024-10-21T12:13:45.811636426Z,2024-10-21T12:13:45.811467280Z,10,2,38,T,N,0,233.98,77,0,169146,12400065,233.77,234.0,200,154,1,7,233.76,234.07,29,200,1,1,233.7,234.12,1200,26,1,1,233.66,234.13,1,400,1,1,233.58,234.17,505,1,2,1,233.53,234.41,10,600,1,2,233.5,234.43,100,105,1,2,233.45,234.5,15,63,1,4,233.4,234.75,110,1,2,1,233.39,234.79,10,2000,1,1,AAPL,-20.0,-20.0,0.0,0.0,0.0,0.0,0.0,0.0,0.0,0.0,0.0,-0.3976116529225004,
2024-10-21T12:13:45.811636426Z,2024-10-21T12:13:45.811467280Z,10,2,38,T,B,0,234.0,20,0,169146,12400066,233.77,234.0,200,154,1,7,233.76,234.07,29,200,1,1,233.7,234.12,1200,26,1,1,233.66,234.13,1,400,1,1,233.58,234.17,505,1,2,1,233.53,234.41,10,600,1,2,233.5,234.43,100,105,1,2,233.45,234.5,15,63,1,4,233.4,234.75,110,1,2,1,233.39,234.79,10,2000,1,1,AAPL,0.0,0.0,0.0,0.0,0.0,0.0,0.0,0.0,0.0,0.0,0.0,0.0,
2024-10-21T12:13:45.811643125Z,2024-10-21T12:13:45.811476289Z,10,2,38,C,A,1,234.07,200,130,166836,12400068,233.77,234.0,200,131,1,6,233.76,234.12,29,26,1,1,233.7,234.13,1200,400,1,1,233.66,234.17,1,1,1,1,233.58,234.41,505,600,2,2,233.53,234.43,10,105,1,2,233.5,234.5,100,63,1,4,233.45,234.75,15,1,1,1,233.4,234.79,110,2000,2,1,233.39,234.89,10,2,1,2,AAPL,23.0,23.0,26.0,400.0,1.0,600.0,105.0,63.0,1.0,2000.0,2.0,273.30292395069654,
2024-10-21T12:13:45.811657243Z,2024-10-21T12:13:45.811491355Z,10,2,38,A,B,0,233.9,100,130,165888,12400070,233.9,234.0,100,131,1,6,233.77,234.12,200,26,1,1,233.76,234.13,29,400,1,1,233.7,234.17,1200,1,1,1,233.66,234.41,1,600,1,2,233.58,234.43,505,105,2,2,233.53,234.5,10,63,1,4,233.5,234.75,100,1,1,1,233.45,234.79,15,2000,1,1,233.4,234.89,110,2,2,2,AAPL,100.0,100.0,200.0,29.0,1200.0,1.0,505.0,10.0,100.0,15.0,110.0,353.5146996165728,
2024-10-21T12:13:45.811666921Z,2024-10-21T12:13:45.811500957Z,10,2,38,A,B,0,233.92,100,130,165964,12400071,233.92,234.0,100,131,1,6,233.9,234.12,100,26,1,1,233.77,234.13,200,400,1,1,233.76,234.17,29,1,1,1,233.7,234.41,1200,600,1,2,233.66,234.43,1,105,1,2,233.58,234.5,505,63,2,4,233.53,234.75,10,1,1,1,233.5,234.79,100,2000,1,1,233.45,234.89,15,2,1,2,AAPL,100.0,100.0,100.0,200.0,29.0,1200.0,1.0,505.0,10.0,100.0,15.0,240.9819259652461,
2024-10-21T12:13:45.811683758Z,2024-10-21T12:13:45.811510984Z,10,2,38,T,B,0,234.0,50,0,172774,12400076,233.92,234.0,100,51,1,2,233.9,234.12,100,26,1,1,233.77,234.13,200,400,1,1,233.76,234.17,29,1,1,1,233.7,234.41,1200,600,1,2,233.66,234.43,1,105,1,2,233.58,234.5,505,63,2,4,233.53,234.75,10,1,1,1,233.5,234.79,100,2000,1,1,233.45,234.89,15,2,1,2,AAPL,80.0,80.0,0.0,0.0,0.0,0.0,0.0,0.0,0.0,0.0,0.0,1.5904466116900016,
2024-10-21T12:13:45.811683758Z,2024-10-21T12:13:45.811510984Z,10,2,38,T,B,0,234.0,27,0,172774,12400072,233.92,234.0,100,131,1,6,233.9,234.12,100,26,1,1,233.77,234.13,200,400,1,1,233.76,234.17,29,1,1,1,233.7,234.41,1200,600,1,2,233.66,234.43,1,105,1,2,233.58,234.5,505,63,2,4,233.53,234.75,10,1,1,1,233.5,234.79,100,2000,1,1,233.45,234.89,15,2,1,2,AAPL,-80.0,-80.0,0.0,0.0,0.0,0.0,0.0,0.0,0.0,0.0,0.0,-1.5904466116900016,
2024-10-21T12:13:45.811683758Z,2024-10-21T12:13:45.811510984Z,10,2,38,T,B,0,234.0,50,0,172774,12400073,233.92,234.0,100,104,1,5,233.9,234.12,100,26,1,1,233.77,234.13,200,400,1,1,233.76,234.17,29,1,1,1,233.7,234.41,1200,600,1,2,233.66,234.43,1,105,1,2,233.58,234.5,505,63,2,4,233.53,234.75,10,1,1,1,233.5,234.79,100,2000,1,1,233.45,234.89,15,2,1,2,AAPL,27.0,27.0,0.0,0.0,0.0,0.0,0.0,0.0,0.0,0.0,0.0,0.5367757314453755,
2024-10-21T12:13:45.811683758Z,2024-10-21T12:13:45.811510984Z,10,2,38,T,B,0,234.0,2,0,172774,12400074,233.92,234.0,100,54,1,4,233.9,234.12,100,26,1,1,233.77,234.13,200,400,1,1,233.76,234.17,29,1,1,1,233.7,234.41,1200,600,1,2,233.66,234.43,1,105,1,2,233.58,234.5,505,63,2,4,233.53,234.75,10,1,1,1,233.5,234.79,100,2000,1,1,233.45,234.89,15,2,1,2,AAPL,50.0,50.0,0.0,0.0,0.0,0.0,0.0,0.0,0.0,0.0,0.0,0.9940291323062509,
2024-10-21T12:13:45.811683758Z,2024-10-21T12:13:45.811510984Z,10,2,38,T,B,0,234.0,1,0,172774,12400075,233.92,234.0,100,52,1,3,233.9,234.12,100,26,1,1,233.77,234.13,200,400,1,1,233.76,234.17,29,1,1,1,233.7,234.41,1200,600,1,2,233.66,234.43,1,105,1,2,233.58,234.5,505,63,2,4,233.53,234.75,10,1,1,1,233.5,234.79,100,2000,1,1,233.45,234.89,15,2,1,2,AAPL,2.0,2.0,0.0,0.0,0.0,0.0,0.0,0.0,0.0,0.0,0.0,0.03976116529225004,
2024-10-21T12:13:45.811683758Z,2024-10-21T12:13:45.811510984Z,10,2,38,T,B,0,234.0,1,130,172774,12400077,233.92,234.0,100,1,1,1,233.9,234.12,100,26,1,1,233.77,234.13,200,400,1,1,233.76,234.17,29,1,1,1,233.7,234.41,1200,600,1,2,233.66,234.43,1,105,1,2,233.58,234.5,505,63,2,4,233.53,234.75,10,1,1,1,233.5,234.79,100,2000,1,1,233.45,234.89,15,2,1,2,AAPL,51.0,51.0,0.0,0.0,0.0,0.0,0.0,0.0,0.0,0.0,0.0,1.013909714952376,
2024-10-21T12:13:45.811683758Z,2024-10-21T12:13:45.811510984Z,10,2,38,C,A,0,234.0,1,130,172774,12400077,233.92,234.12,100,26,1,1,233.9,234.13,100,400,1,1,233.77,234.17,200,1,1,1,233.76,234.41,29,600,1,2,233.7,234.43,1200,105,1,2,233.66,234.5,1,63,1,4,233.58,234.75,505,1,2,1,233.53,234.79,10,2000,1,1,233.5,234.89,100,2,1,2,233.45,235.0,15,213,1,6,AAPL,26.0,26.0,400.0,1.0,600.0,105.0,63.0,1.0,2000.0,2.0,213.0,388.53939162785116,
2024-10-21T12:13:45.811695806Z,2024-10-21T12:13:45.811530148Z,10,2,38,C,B,1,233.9,100,130,165658,12400078,233.92,234.12,100,26,1,1,233.77,234.13,200,400,1,1,233.76,234.17,29,1,1,1,233.7,234.41,1200,600,1,2,233.66,234.43,1,105,1,2,233.58,234.5,505,63,2,4,233.53,234.75,10,1,1,1,233.5,234.79,100,2000,1,1,233.45,234.89,15,2,1,2,233.4,235.0,110,213,2,6,AAPL,0.0,0.0,-100.0,-200.0,-29.0,-1200.0,-1.0,-505.0,-10.0,-100.0,-15.0,-238.9938677006336,
2024-10-21T12:13:45.811710080Z,2024-10-21T12:13:45.811542984Z,10,2,38,A,B,0,233.96,100,130,167096,12400079,233.96,234.12,100,26,1,1,233.92,234.13,100,400,1,1,233.77,234.17,200,1,1,1,233.76,234.41,29,600,1,2,233.7,234.43,1200,105,1,2,233.66,234.5,1,63,1,4,233.58,234.75,505,1,2,1,233.53,234.79,10,2000,1,1,233.5,234.89,100,2,1,2,233.45,235.0,15,213,1,6,AAPL,100.0,100.0,100.0,200.0,29.0,1200.0,1.0,505.0,10.0,100.0,15.0,240.9819259652461,
2024-10-21T12:13:45.811712078Z,2024-10-21T12:13:45.811544514Z,10,2,38,A,B,0,233.96,24,130,167564,12400080,233.96,234.12,124,26,2,1,233.92,234.13,100,400,1,1,233.77,234.17,200,1,1,1,233.76,234.41,29,600,1,2,233.7,234.43,1200,105,1,2,233.66,234.5,1,63,1,4,233.58,234.75,505,1,2,1,233.53,234.79,10,2000,1,1,233.5,234.89,100,2,1,2,233.45,235.0,15,213,1,6,AAPL,24.0,24.0,0.0,0.0,0.0,0.0,0.0,0.0,0.0,0.0,0.0,0.4771339835070004,
2024-10-21T12:13:45.811715761Z,2024-10-21T12:13:45.811549682Z,10,2,38,A,B,1,233.94,100,130,166079,12400081,233.96,234.12,124,26,2,1,233.94,234.13,100,400,1,1,233.92,234.17,100,1,1,1,233.77,234.41,200,600,1,2,233.76,234.43,29,105,1,2,233.7,234.5,1200,63,1,4,233.66,234.75,1,1,1,1,233.58,234.79,505,2000,2,1,233.53,234.89,10,2,1,2,233.5,235.0,100,213,1,6,AAPL,0.0,0.0,100.0,100.0,200.0,29.0,1200.0,1.0,505.0,10.0,100.0,285.3472824832067,
2024-10-21T12:13:45.811718296Z,2024-10-21T12:13:45.811550754Z,10,2,38,A,B,0,233.96,28,130,167542,12400082,233.96,234.12,152,26,3,1,233.94,234.13,100,400,1,1,233.92,234.17,100,1,1,1,233.77,234.41,200,600,1,2,233.76,234.43,29,105,1,2,233.7,234.5,1200,63,1,4,233.66,234.75,1,1,1,1,233.58,234.79,505,2000,2,1,233.53,234.89,10,2,1,2,233.5,235.0,100,213,1,6,AAPL,28.0,28.0,0.0,0.0,0.0,0.0,0.0,0.0,0.0,0.0,0.0,0.5566563140915005,
2024-10-21T12:13:45.811721349Z,2024-10-21T12:13:45.811554820Z,10,2,38,A,B,0,233.96,100,130,166529,12400083,233.96,234.12,252,26,4,1,233.94,234.13,100,400,1,1,233.92,234.17,100,1,1,1,233.77,234.41,200,600,1,2,233.76,234.43,29,105,1,2,233.7,234.5,1200,63,1,4,233.66,234.75,1,1,1,1,233.58,234.79,505,2000,2,1,233.53,234.89,10,2,1,2,233.5,235.0,100,213,1,6,AAPL,100.0,100.0,0.0,0.0,0.0,0.0,0.0,0.0,0.0,0.0,0.0,1.9880582646125018,
2024-10-21T12:13:45.811732936Z,2024-10-21T12:13:45.811565809Z,10,2,38,A,B,0,233.96,100,128,167127,12400085,233.96,234.12,352,26,5,1,233.94,234.13,100,400,1,1,233.93,234.17,28,1,1,1,233.92,234.41,100,600,1,2,233.77,234.43,200,105,1,2,233.76,234.5,29,63,1,4,233.7,234.75,1200,1,1,1,233.66,234.79,1,2000,1,1,233.58,234.89,505,2,2,2,233.53,235.0,10,213,1,6,AAPL,100.0,100.0,0.0,28.0,100.0,200.0,29.0,1200.0,1.0,505.0,10.0,225.23443943164304,
2024-10-21T12:13:45.811742859Z,2024-10-21T12:13:45.811576962Z,10,2,38,A,B,0,233.96,100,130,165897,12400087,233.96,234.12,452,26,6,1,233.94,234.13,100,400,1,1,233.93,234.17,28,1,1,1,233.92,234.41,100,600,1,2,233.77,234.43,200,105,1,2,233.76,234.5,29,63,1,4,233.7,234.75,1200,1,1,1,233.66,234.79,1,2000,1,1,233.58,234.89,505,2,2,2,233.53,235.0,10,213,1,6,AAPL,100.0,100.0,0.0,0.0,0.0,0.0,0.0,0.0,0.0,0.0,0.0,1.9880582646125018,
2024-10-21T12:13:45.811753896Z,2024-10-21T12:13:45.811587865Z,10,2,38,A,B,0,233.96,100,130,166031,12400088,233.96,234.12,552,26,7,1,233.94,234.13,100,400,1,1,233.93,234.17,28,1,1,1,233.92,234.41,100,600,1,2,233.77,234.43,200,105,1,2,233.76,234.5,29,63,1,4,233.7,234.75,1200,1,1,1,233.66,234.79,1,2000,1,1,233.58,234.89,505,2,2,2,233.53,235.0,10,213,1,6,AAPL,100.0,100.0,0.0,0.0,0.0,0.0,0.0,0.0,0.0,0.0,0.0,1.9880582646125018,
2024-10-21T12:13:45.811765786Z,2024-10-21T12:13:45.811599315Z,10,2,38,A,B,1,233.94,100,130,166471,12400089,233.96,234.12,552,26,7,1,233.94,234.13,200,400,2,1,233.93,234.17,28,1,1,1,233.92,234.41,100,600,1,2,233.77,234.43,200,105,1,2,233.76,234.5,29,63,1,4,233.7,234.75,1200,1,1,1,233.66,234.79,1,2000,1,1,233.58,234.89,505,2,2,2,233.53,235.0,10,213,1,6,AAPL,0.0,0.0,100.0,0.0,0.0,0.0,0.0,0.0,0.0,0.0,0.0,6.3416162828869584,
2024-10-21T12:13:45.811791584Z,2024-10-21T12:13:45.811625820Z,10,2,38,C,B,0,233.96,100,130,165764,12400091,233.96,234.12,452,26,6,1,233.94,234.13,200,400,2,1,233.93,234.17,28,1,1,1,233.92,234.41,100,600,1,2,233.77,234.43,200,105,1,2,233.76,234.5,29,63,1,4,233.7,234.75,1200,1,1,1,233.66,234.79,1,2000,1,1,233.58,234.89,505,2,2,2,233.53,235.0,10,213,1,6,AAPL,-100.0,-100.0,0.0,0.0,0.0,0.0,0.0,0.0,0.0,0.0,0.0,-1.9880582646125018,
2024-10-21T12:13:45.811800458Z,2024-10-21T12:13:45.811631245Z,10,2,38,T,N,0,234.0,145,130,169213,12400092,233.96,234.12,452,26,6,1,233.94,234.13,200,400,2,1,233.93,234.17,28,1,1,1,233.92,234.41,100,600,1,2,233.77,234.43,200,105,1,2,233.76,234.5,29,63,1,4,233.7,234.75,1200,1,1,1,233.66,234.79,1,2000,1,1,233.58,234.89,505,2,2,2,233.53,235.0,10,213,1,6,AAPL,0.0,0.0,0.0,0.0,0.0,0.0,0.0,0.0,0.0,0.0,0.0,0.0,
2024-10-21T12:13:45.811805292Z,2024-10-21T12:13:45.811639570Z,10,2,38,C,B,1,233.94,100,130,165722,12400093,233.96,234.12,452,26,6,1,233.94,234.13,100,400,1,1,233.93,234.17,28,1,1,1,233.92,234.41,100,600,1,2,233.77,234.43,200,105,1,2,233.76,234.5,29,63,1,4,233.7,234.75,1200,1,1,1,233.66,234.79,1,2000,1,1,233.58,234.89,505,2,2,2,233.53,235.0,10,213,1,6,AAPL,0.0,0.0,-100.0,0.0,0.0,0.0,0.0,0.0,0.0,0.0,0.0,-6.3416162828869584,
2024-10-21T12:13:45.811808010Z,2024-10-21T12:13:45.811642361Z,10,2,38,C,B,0,233.96,100,130,165649,12400094,233.96,234.12,352,26,5,1,233.94,234.13,100,400,1,1,233.93,234.17,28,1,1,1,233.92,234.41,100,600,1,2,233.77,234.43,200,105,1,2,233.76,234.5,29,63,1,4,233.7,234.75,1200,1,1,1,233.66,234.79,1,2000,1,1,233.58,234.89,505,2,2,2,233.53,235.0,10,213,1,6,AAPL,-100.0,-100.0,0.0,0.0,0.0,0.0,0.0,0.0,0.0,0.0,0.0,-1.9880582646125018,
2024-10-21T12:13:45.811822560Z,2024-10-21T12:13:45.811656818Z,10,2,38,C,B,0,233.96,100,130,165742,12400095,233.96,234.12,252,26,4,1,233.94,234.13,100,400,1,1,233.93,234.17,28,1,1,1,233.92,234.41,100,600,1,2,233.77,234.43,200,105,1,2,233.76,234.5,29,63,1,4,233.7,234.75,1200,1,1,1,233.66,234.79,1,2000,1,1,233.58,234.89,505,2,2,2,233.53,235.0,10,213,1,6,AAPL,-100.0,-100.0,0.0,0.0,0.0,0.0,0.0,0.0,0.0,0.0,0.0,-1.9880582646125018,
2024-10-21T12:13:45.811837891Z,2024-10-21T12:13:45.811672313Z,10,2,38,C,B,0,233.96,100,130,165578,12400096,233.96,234.12,152,26,3,1,233.94,234.13,100,400,1,1,233.93,234.17,28,1,1,1,233.92,234.41,100,600,1,2,233.77,234.43,200,105,1,2,233.76,234.5,29,63,1,4,233.7,234.75,1200,1,1,1,233.66,234.79,1,2000,1,1,233.58,234.89,505,2,2,2,233.53,235.0,10,213,1,6,AAPL,-100.0,-100.0,0.0,0.0,0.0,0.0,0.0,0.0,0.0,0.0,0.0,-1.9880582646125018,
2024-10-21T12:13:45.811853381Z,2024-10-21T12:13:45.811687403Z,10,2,38,C,B,0,233.96,100,130,165978,12400097,233.96,234.12,52,26,2,1,233.94,234.13,100,400,1,1,233.93,234.17,28,1,1,1,233.92,234.41,100,600,1,2,233.77,234.43,200,105,1,2,233.76,234.5,29,63,1,4,233.7,234.75,1200,1,1,1,233.66,234.79,1,2000,1,1,233.58,234.89,505,2,2,2,233.53,235.0,10,213,1,6,AAPL,-100.0,-100.0,0.0,0.0,0.0,0.0,0.0,0.0,0.0,0.0,0.0,-1.9880582646125018,
2024-10-21T12:13:45.811867704Z,2024-10-21T12:13:45.811702067Z,10,2,38,C,B,1,233.94,100,130,165637,12400098,233.96,234.12,52,26,2,1,233.93,234.13,28,400,1,1,233.92,234.17,100,1,1,1,233.77,234.41,200,600,1,2,233.76,234.43,29,105,1,2,233.7,234.5,1200,63,1,4,233.66,234.75,1,1,1,1,233.58,234.79,505,2000,2,1,233.53,234.89,10,2,1,2,233.5,235.0,100,213,1,6,AAPL,0.0,0.0,-100.0,-28.0,-100.0,-200.0,-29.0,-1200.0,-1.0,-505.0,-10.0,-229.58799744991748,
2024-10-21T12:13:45.812203001Z,2024-10-21T12:13:45.812035805Z,10,2,38,A,B,3,233.9,100,130,167196,12400100,233.96,234.12,52,26,2,1,233.93,234.13,28,400,1,1,233.92,234.17,100,1,1,1,233.9,234.41,100,600,1,2,233.77,234.43,200,105,1,2,233.76,234.5,29,63,1,4,233.7,234.75,1200,1,1,1,233.66,234.79,1,2000,1,1,233.58,234.89,505,2,2,2,233.53,235.0,10,213,1,6,AAPL,0.0,0.0,0.0,0.0,100.0,200.0,29.0,1200.0,1.0,505.0,10.0,220.4020689064224,
2024-10-21T12:13:45.812647427Z,2024-10-21T12:13:45.812481448Z,10,2,38,C,B,3,233.9,100,130,165979,12400102,233.96,234.12,52,26,2,1,233.93,234.13,28,400,1,1,233.92,234.17,100,1,1,1,233.77,234.41,200,600,1,2,233.76,234.43,29,105,1,2,233.7,234.5,1200,63,1,4,233.66,234.75,1,1,1,1,233.58,234.79,505,2000,2,1,233.53,234.89,10,2,1,2,233.5,235.0,100,213,1,6,AAPL,0.0,0.0,0.0,0.0,-100.0,-200.0,-29.0,-1200.0,-1.0,-505.0,-10.0,-220.4020689064224,
2024-10-21T12:13:45.813181508Z,2024-10-21T12:13:45.813014463Z,10,2,38,T,N,0,234.08,1,130,167045,12400103,233.96,234.12,52,26,2,1,233.93,234.13,28,400,1,1,233.92,234.17,100,1,1,1,233.77,234.41,200,600,1,2,233.76,234.43,29,105,1,2,233.7,234.5,1200,63,1,4,233.66,234.75,1,1,1,1,233.58,234.79,505,2000,2,1,233.53,234.89,10,2,1,2,233.5,235.0,100,213,1,6,AAPL,0.0,0.0,0.0,0.0,0.0,0.0,0.0,0.0,0.0,0.0,0.0,0.0,
2024-10-21T12:13:45.813988388Z,2024-10-21T12:13:45.813822327Z,10,2,38,C,B,2,233.92,100,130,166061,12400110,233.96,234.12,52,26,2,1,233.93,234.13,28,400,1,1,233.77,234.17,200,1,1,1,233.76,234.41,29,600,1,2,233.7,234.43,1200,105,1,2,233.66,234.5,1,63,1,4,233.58,234.75,505,1,2,1,233.53,234.79,10,2000,1,1,233.5,234.89,100,2,1,2,233.45,235.0,15,213,1,6,AAPL,0.0,0.0,0.0,-100.0,-200.0,-29.0,-1200.0,-1.0,-505.0,-10.0,-100.0,-279.00566620031975,
2024-10-21T12:13:45.885716957Z,2024-10-21T12:13:45.885550872Z,10,2,38,C,A,0,234.12,26,130,166085,12401368,233.96,234.13,52,400,2,1,233.93,234.17,28,1,1,1,233.77,234.41,200,600,1,2,233.76,234.43,29,105,1,2,233.7,234.5,1200,63,1,4,233.66,234.75,1,1,1,1,233.58,234.79,505,2000,2,1,233.53,234.89,10,2,1,2,233.5,235.0,100,213,1,6,233.45,235.03,15,2,1,1,AAPL,400.0,400.0,1.0,600.0,105.0,63.0,1.0,2000.0,2.0,213.0,2.0,341.08689786124745,
2024-10-21T12:13:45.885769234Z,2024-10-21T12:13:45.885603142Z,10,2,38,A,A,2,234.18,27,130,166092,12401370,233.96,234.13,52,400,2,1,233.93,234.17,28,1,1,1,233.77,234.18,200,27,1,1,233.76,234.41,29,600,1,2,233.7,234.43,1200,105,1,2,233.66,234.5,1,63,1,4,233.58,234.75,505,1,2,1,233.53,234.79,10,2000,1,1,233.5,234.89,100,2,1,2,233.45,235.0,15,213,1,6,AAPL,0.0,0.0,0.0,-600.0,-105.0,-63.0,-1.0,-2000.0,-2.0,-213.0,-2.0,-333.07124863996853,
2024-10-21T12:13:45.911785815Z,2024-10-21T12:13:45.911619430Z,10,2,38,C,B,0,233.96,24,130,166385,12401559,233.96,234.13,28,400,1,1,233.93,234.17,28,1,1,1,233.77,234.18,200,27,1,1,233.76,234.41,29,600,1,2,233.7,234.43,1200,105,1,2,233.66,234.5,1,63,1,4,233.58,234.75,505,1,2,1,233.53,234.79,10,2000,1,1,233.5,234.89,100,2,1,2,233.45,235.0,15,213,1,6,AAPL,-24.0,-24.0,0.0,0.0,0.0,0.0,0.0,0.0,0.0,0.0,0.0,-0.4771339835070004,
2024-10-21T12:13:45.911812280Z,2024-10-21T12:13:45.911645974Z,10,2,38,C,B,1,233.93,28,130,166306,12401560,233.96,234.13,28,400,1,1,233.77,234.17,200,1,1,1,233.76,234.18,29,27,1,1,233.7,234.41,1200,600,1,2,233.66,234.43,1,105,1,2,233.58,234.5,505,63,2,4,233.53,234.75,10,1,1,1,233.5,234.79,100,2000,1,1,233.45,234.89,15,2,1,2,233.4,235.0,110,213,2,6,AAPL,0.0,0.0,-28.0,-200.0,-29.0,-1200.0,-1.0,-505.0,-10.0,-100.0,-15.0,-234.427903976955,
2024-10-21T12:13:45.935434703Z,2024-10-21T12:13:45.935267342Z,10,2,38,A,B,1,233.78,200,128,167361,12401727,233.96,234.13,28,400,1,1,233.78,234.17,200,1,1,1,233.76,234.18,29,27,1,1,233.7,234.41,1200,600,1,2,233.66,234.43,1,105,1,2,233.58,234.5,505,63,2,4,233.53,234.75,10,1,1,1,233.5,234.79,100,2000,1,1,233.45,234.89,15,2,1,2,233.4,235.0,110,213,2,6,AAPL,0.0,0.0,200.0,0.0,0.0,0.0,0.0,0.0,0.0,0.0,0.0,12.683232565773917,
2024-10-21T12:13:45.969762895Z,2024-10-21T12:13:45.969596688Z,10,2,38,A,A,0,234.12,200,130,166207,12401874,233.96,234.12,28,200,1,1,233.78,234.13,200,400,1,1,233.76,234.17,29,1,1,1,233.7,234.18,1200,27,1,1,233.66,234.41,1,600,1,2,233.58,234.43,505,105,2,2,233.53,234.5,10,63,1,4,233.5,234.75,100,1,1,1,233.45,234.79,15,2000,1,1,233.4,234.89,110,2,2,2,AAPL,-400.0,-400.0,-1.0,-27.0,-600.0,-105.0,-63.0,-1.0,-2000.0,-2.0,-213.0,-373.3128276679191,
2024-10-21T12:13:45.972375870Z,2024-10-21T12:13:45.972210032Z,10,2,38,C,A,0,234.12,200,130,165838,12401877,233.96,234.13,28,400,1,1,233.78,234.17,200,1,1,1,233.76,234.18,29,27,1,1,233.7,234.41,1200,600,1,2,233.66,234.43,1,105,1,2,233.58,234.5,505,63,2,4,233.53,234.75,10,1,1,1,233.5,234.79,100,2000,1,1,233.45,234.89,15,2,1,2,233.4,235.0,110,213,2,6,AAPL,400.0,400.0,1.0,27.0,600.0,105.0,63.0,1.0,2000.0,2.0,213.0,373.3128276679191,
2024-10-21T12:13:45.973746612Z,2024-10-21T12:13:45.973580511Z,10,2,38,A,A,3,234.19,200,130,166101,12401884,233.96,234.13,28,400,1,1,233.78,234.17,200,1,1,1,233.76,234.18,29,27,1,1,233.7,234.19,1200,200,1,1,233.66,234.41,1,600,1,2,233.58,234.43,505,105,2,2,233.53,234.5,10,63,1,4,233.5,234.75,100,1,1,1,233.45,234.79,15,2000,1,1,233.4,234.89,110,2,2,2,AAPL,0.0,0.0,0.0,0.0,-600.0,-105.0,-63.0,-1.0,-2000.0,-2.0,-213.0,-362.5544487667681,
2024-10-21T12:13:46.001542260Z,2024-10-21T12:13:46.001375930Z,10,2,38,A,A,3,234.19,200,130,166330,12401962,233.96,234.13,28,400,1,1,233.78,234.17,200,1,1,1,233.76,234.18,29,27,1,1,233.7,234.19,1200,400,1,2,233.66,234.41,1,600,1,2,233.58,234.43,505,105,2,2,233.53,234.5,10,63,1,4,233.5,234.75,100,1,1,1,233.45,234.79,15,2000,1,1,233.4,234.89,110,2,2,2,AAPL,0.0,0.0,0.0,0.0,-200.0,0.0,0.0,0.0,0.0,0.0,0.0,-41.015411004823704,
2024-10-21T12:13:46.030544628Z,2024-10-21T12:13:46.030378750Z,10,2,38,C,A,3,234.19,200,130,165878,12402092,233.96,234.13,28,400,1,1,233.78,234.17,200,1,1,1,233.76,234.18,29,27,1,1,233.7,234.19,1200,200,1,1,233.66,234.41,1,600,1,2,233.58,234.43,505,105,2,2,233.53,234.5,10,63,1,4,233.5,234.75,100,1,1,1,233.45,234.79,15,2000,1,1,233.4,234.89,110,2,2,2,AAPL,0.0,0.0,0.0,0.0,200.0,0.0,0.0,0.0,0.0,0.0,0.0,41.015411004823704,
2024-10-21T12:13:46.030557325Z,2024-10-21T12:13:46.030391116Z,10,2,38,A,A,0,234.12,400,130,166209,12402093,233.96,234.12,28,400,1,1,233.78,234.13,200,400,1,1,233.76,234.17,29,1,1,1,233.7,234.18,1200,27,1,1,233.66,234.41,1,600,1,2,233.58,234.43,505,105,2,2,233.53,234.5,10,63,1,4,233.5,234.75,100,1,1,1,233.45,234.79,15,2000,1,1,233.4,234.89,110,2,2,2,AAPL,-400.0,-400.0,-1.0,-27.0,-200.0,0.0,0.0,0.0,0.0,0.0,0.0,-51.77378990597472,
2024-10-21T12:13:46.063401404Z,2024-10-21T12:13:46.063235483Z,10,2,38,C,B,0,233.96,28,130,165921,12402125,233.78,234.12,200,400,1,1,233.76,234.13,29,400,1,1,233.7,234.17,1200,1,1,1,233.66,234.18,1,27,1,1,233.58,234.41,505,600,2,2,233.53,234.43,10,105,1,2,233.5,234.5,100,63,1,4,233.45,234.75,15,1,1,1,233.4,234.79,110,2000,2,1,233.39,234.89,10,2,1,2,AAPL,-28.0,-28.0,-200.0,-29.0,-1200.0,-1.0,-505.0,-10.0,-100.0,-15.0,-110.0,-352.0832976660518,
2024-10-21T12:13:46.072888556Z,2024-10-21T12:13:46.072722298Z,10,2,38,C,A,0,234.12,400,130,166258,12402143,233.78,234.13,200,400,1,1,233.76,234.17,29,1,1,1,233.7,234.18,1200,27,1,1,233.66,234.41,1,600,1,2,233.58,234.43,505,105,2,2,233.53,234.5,10,63,1,4,233.5,234.75,100,1,1,1,233.45,234.79,15,2000,1,1,233.4,234.89,110,2,2,2,233.39,235.0,10,213,1,6,AAPL,400.0,400.0,1.0,27.0,600.0,105.0,63.0,1.0,2000.0,2.0,213.0,373.3128276679191,
2024-10-21T12:13:46.072911952Z,2024-10-21T12:13:46.072745549Z,10,2,38,A,A,0,234.13,200,130,166403,12402144,233.78,234.13,200,600,1,2,233.76,234.17,29,1,1,1,233.7,234.18,1200,27,1,1,233.66,234.41,1,600,1,2,233.58,234.43,505,105,2,2,233.53,234.5,10,63,1,4,233.5,234.75,100,1,1,1,233.45,234.79,15,2000,1,1,233.4,234.89,110,2,2,2,233.39,235.0,10,213,1,6,AAPL,-200.0,-200.0,0.0,0.0,0.0,0.0,0.0,0.0,0.0,0.0,0.0,-3.9761165292250036,
2024-10-21T12:13:46.073218239Z,2024-10-21T12:13:46.073052339Z,10,2,38,C,B,1,233.76,29,130,165900,12402146,233.78,234.13,200,600,1,2,233.7,234.17,1200,1,1,1,233.66,234.18,1,27,1,1,233.58,234.41,505,600,2,2,233.53,234.43,10,105,1,2,233.5,234.5,100,63,1,4,233.45,234.75,15,1,1,1,233.4,234.79,110,2000,2,1,233.39,234.89,10,2,1,2,233.31,235.0,110,213,2,6,AAPL,0.0,0.0,-29.0,-1200.0,-1.0,-505.0,-10.0,-100.0,-15.0,-110.0,-10.0,-205.35614101717326,
2024-10-21T12:13:46.073303600Z,2024-10-21T12:13:46.073137112Z,10,2,38,A,B,0,233.81,27,130,166488,12402147,233.81,234.13,27,600,1,2,233.78,234.17,200,1,1,1,233.7,234.18,1200,27,1,1,233.66,234.41,1,600,1,2,233.58,234.43,505,105,2,2,233.53,234.5,10,63,1,4,233.5,234.75,100,1,1,1,233.45,234.79,15,2000,1,1,233.4,234.89,110,2,2,2,233.39,235.0,10,213,1,6,AAPL,27.0,27.0,200.0,1200.0,1.0,505.0,10.0,100.0,15.0,110.0,10.0,216.73708059235528,
2024-10-21T12:13:46.123490913Z,2024-10-21T12:13:46.123324204Z,10,2,38,A,B,0,233.83,200,130,166709,12402220,233.83,234.13,200,600,1,2,233.81,234.17,27,1,1,1,233.7,234.18,1200,27,1,1,233.66,234.41,1,600,1,2,233.58,234.43,505,105,2,2,233.53,234.5,10,63,1,4,233.5,234.75,100,1,1,1,233.45,234.79,15,2000,1,1,233.4,234.89,110,2,2,2,233.39,235.0,10,213,1,6,AAPL,200.0,200.0,27.0,0.0,0.0,0.0,0.0,0.0,0.0,0.0,0.0,5.688352925604482,
2024-10-21T12:13:46.134519400Z,2024-10-21T12:13:46.134353286Z,10,2,38,C,B,0,233.83,200,130,166114,12402230,233.81,234.13,27,600,1,2,233.7,234.17,1200,1,1,1,233.66,234.18,1,27,1,1,233.58,234.41,505,600,2,2,233.53,234.43,10,105,1,2,233.5,234.5,100,63,1,4,233.45,234.75,15,1,1,1,233.4,234.79,110,2000,2,1,233.39,234.89,10,2,1,2,233.31,235.0,110,213,2,6,AAPL,-200.0,-200.0,-27.0,-1200.0,-1.0,-505.0,-10.0,-100.0,-15.0,-110.0,-10.0,-209.20542522074052,
2024-10-21T12:13:46.134533664Z,2024-10-21T12:13:46.134366429Z,10,2,38,A,B,1,233.78,200,130,167235,12402231,233.81,234.13,27,600,1,2,233.78,234.17,200,1,1,1,233.7,234.18,1200,27,1,1,233.66,234.41,1,600,1,2,233.58,234.43,505,105,2,2,233.53,234.5,10,63,1,4,233.5,234.75,100,1,1,1,233.45,234.79,15,2000,1,1,233.4,234.89,110,2,2,2,233.39,235.0,10,213,1,6,AAPL,0.0,0.0,200.0,1200.0,1.0,505.0,10.0,100.0,15.0,110.0,10.0,216.20030486090994,
2024-10-21T12:13:46.134975052Z,2024-10-21T12:13:46.134809159Z,10,2,38,C,B,0,233.81,27,130,165893,12402233,233.78,234.13,200,600,1,2,233.7,234.17,1200,1,1,1,233.66,234.18,1,27,1,1,233.58,234.41,505,600,2,2,233.53,234.43,10,105,1,2,233.5,234.5,100,63,1,4,233.45,234.75,15,1,1,1,233.4,234.79,110,2000,2,1,233.39,234.89,10,2,1,2,233.31,235.0,110,213,2,6,AAPL,-27.0,-27.0,-200.0,-1200.0,-1.0,-505.0,-10.0,-100.0,-15.0,-110.0,-10.0,-216.73708059235528,
2024-10-21T12:13:47.415528384Z,2024-10-21T12:13:47.415362307Z,10,2,38,A,B,1,233.76,27,130,166077,12403393,233.78,234.13,200,600,1,2,233.76,234.17,27,1,1,1,233.7,234.18,1200,27,1,1,233.66,234.41,1,600,1,2,233.58,234.43,505,105,2,2,233.53,234.5,10,63,1,4,233.5,234.75,100,1,1,1,233.45,234.79,15,2000,1,1,233.4,234.89,110,2,2,2,233.39,235.0,10,213,1,6,AAPL,0.0,0.0,27.0,1200.0,1.0,505.0,10.0,100.0,15.0,110.0,10.0,205.2293086915155,
2024-10-21T12:13:48.136535794Z,2024-10-21T12:13:48.136368928Z,10,2,38,C,A,0,234.13,200,130,166866,12404229,233.78,234.13,200,400,1,1,233.76,234.17,27,1,1,1,233.7,234.18,1200,27,1,1,233.66,234.41,1,600,1,2,233.58,234.43,505,105,2,2,233.53,234.5,10,63,1,4,233.5,234.75,100,1,1,1,233.45,234.79,15,2000,1,1,233.4,234.89,110,2,2,2,233.39,235.0,10,213,1,6,AAPL,200.0,200.0,0.0,0.0,0.0,0.0,0.0,0.0,0.0,0.0,0.0,3.9761165292250036,
2024-10-21T12:13:48.136548342Z,2024-10-21T12:13:48.136382005Z,10,2,38,A,A,1,234.16,200,130,166337,12404230,233.78,234.13,200,400,1,1,233.76,234.16,27,200,1,1,233.7,234.17,1200,1,1,1,233.66,234.18,1,27,1,1,233.58,234.41,505,600,2,2,233.53,234.43,10,105,1,2,233.5,234.5,100,63,1,4,233.45,234.75,15,1,1,1,233.4,234.79,110,2000,2,1,233.39,234.89,10,2,1,2,AAPL,0.0,0.0,-1.0,-27.0,-600.0,-105.0,-63.0,-1.0,-2000.0,-2.0,-213.0,-365.3605946094691,
2024-10-21T12:13:54.483454950Z,2024-10-21T12:13:54.483288659Z,10,2,38,A,A,1,234.16,200,130,166291,12409382,233.78,234.13,200,400,1,1,233.76,234.16,27,400,1,2,233.7,234.17,1200,1,1,1,233.66,234.18,1,27,1,1,233.58,234.41,505,600,2,2,233.53,234.43,10,105,1,2,233.5,234.5,100,63,1,4,233.45,234.75,15,1,1,1,233.4,234.79,110,2000,2,1,233.39,234.89,10,2,1,2,AAPL,0.0,0.0,-200.0,0.0,0.0,0.0,0.0,0.0,0.0,0.0,0.0,-12.683232565773917,
2024-10-21T12:13:54.519925421Z,2024-10-21T12:13:54.519759447Z,10,2,38,C,A,1,234.16,200,130,165974,12409407,233.78,234.13,200,400,1,1,233.76,234.16,27,200,1,1,233.7,234.17,1200,1,1,1,233.66,234.18,1,27,1,1,233.58,234.41,505,600,2,2,233.53,234.43,10,105,1,2,233.5,234.5,100,63,1,4,233.45,234.75,15,1,1,1,233.4,234.79,110,2000,2,1,233.39,234.89,10,2,1,2,AAPL,0.0,0.0,200.0,0.0,0.0,0.0,0.0,0.0,0.0,0.0,0.0,12.683232565773917,
2024-10-21T12:13:54.519938916Z,2024-10-21T12:13:54.519772638Z,10,2,38,A,A,1,234.15,200,130,166278,12409408,233.78,234.13,200,400,1,1,233.76,234.15,27,200,1,1,233.7,234.17,1200,1,1,1,233.66,234.18,1,27,1,1,233.58,234.41,505,600,2,2,233.53,234.43,10,105,1,2,233.5,234.5,100,63,1,4,233.45,234.75,15,1,1,1,233.4,234.79,110,2000,2,1,233.39,234.89,10,2,1,2,AAPL,0.0,0.0,-200.0,0.0,0.0,0.0,0.0,0.0,0.0,0.0,0.0,-12.683232565773917,
2024-10-21T12:13:55.034277634Z,2024-10-21T12:13:55.034111535Z,10,2,38,C,A,3,234.18,27,130,166099,12410122,233.78,234.13,200,400,1,1,233.76,234.15,27,200,1,1,233.7,234.17,1200,1,1,1,233.66,234.41,1,600,1,2,233.58,234.43,505,105,2,2,233.53,234.5,10,63,1,4,233.5,234.75,100,1,1,1,233.45,234.79,15,2000,1,1,233.4,234.89,110,2,2,2,233.39,235.0,10,213,1,6,AAPL,0.0,0.0,0.0,0.0,600.0,105.0,63.0,1.0,2000.0,2.0,213.0,362.5544487667681,
2024-10-21T12:13:55.034369213Z,2024-10-21T12:13:55.034202690Z,10,2,38,A,A,2,234.17,28,130,166523,12410123,233.78,234.13,200,400,1,1,233.76,234.15,27,200,1,1,233.7,234.17,1200,29,1,2,233.66,234.41,1,600,1,2,233.58,234.43,505,105,2,2,233.53,234.5,10,63,1,4,233.5,234.75,100,1,1,1,233.45,234.79,15,2000,1,1,233.4,234.89,110,2,2,2,233.39,235.0,10,213,1,6,AAPL,0.0,0.0,0.0,-28.0,0.0,0.0,0.0,0.0,0.0,0.0,0.0,-2.8443122606081452,
2024-10-21T12:13:56.094704759Z,2024-10-21T12:13:56.094538941Z,10,2,38,C,B,0,233.78,200,130,165818,12410937,233.76,234.13,27,400,1,1,233.7,234.15,1200,200,1,1,233.66,234.17,1,29,1,2,233.58,234.41,505,600,2,2,233.53,234.43,10,105,1,2,233.5,234.5,100,63,1,4,233.45,234.75,15,1,1,1,233.4,234.79,110,2000,2,1,233.39,234.89,10,2,1,2,233.31,235.0,110,213,2,6,AAPL,-200.0,-200.0,-27.0,-1200.0,-1.0,-505.0,-10.0,-100.0,-15.0,-110.0,-10.0,-209.20542522074052,
2024-10-21T12:13:56.094717739Z,2024-10-21T12:13:56.094551306Z,10,2,38,A,B,0,233.76,200,130,166433,12410939,233.76,234.13,227,400,2,1,233.7,234.15,1200,200,1,1,233.66,234.17,1,29,1,2,233.58,234.41,505,600,2,2,233.53,234.43,10,105,1,2,233.5,234.5,100,63,1,4,233.45,234.75,15,1,1,1,233.4,234.79,110,2000,2,1,233.39,234.89,10,2,1,2,233.31,235.0,110,213,2,6,AAPL,200.0,200.0,0.0,0.0,0.0,0.0,0.0,0.0,0.0,0.0,0.0,3.9761165292250036,
2024-10-21T12:13:56.154373830Z,2024-10-21T12:13:56.154206963Z,10,2,38,A,A,1,234.15,200,130,166867,12411142,233.76,234.13,227,400,2,1,233.7,234.15,1200,400,1,2,233.66,234.17,1,29,1,2,233.58,234.41,505,600,2,2,233.53,234.43,10,105,1,2,233.5,234.5,100,63,1,4,233.45,234.75,15,1,1,1,233.4,234.79,110,2000,2,1,233.39,234.89,10,2,1,2,233.31,235.0,110,213,2,6,AAPL,0.0,0.0,-200.0,0.0,0.0,0.0,0.0,0.0,0.0,0.0,0.0,-12.683232565773917,
2024-10-21T12:13:56.211883968Z,2024-10-21T12:13:56.211718188Z,10,2,38,C,A,1,234.15,200,130,165780,12411252,233.76,234.13,227,400,2,1,233.7,234.15,1200,200,1,1,233.66,234.17,1,29,1,2,233.58,234.41,505,600,2,2,233.53,234.43,10,105,1,2,233.5,234.5,100,63,1,4,233.45,234.75,15,1,1,1,233.4,234.79,110,2000,2,1,233.39,234.89,10,2,1,2,233.31,235.0,110,213,2,6,AAPL,0.0,0.0,200.0,0.0,0.0,0.0,0.0,0.0,0.0,0.0,0.0,12.683232565773917,
2024-10-21T12:13:56.211897481Z,2024-10-21T12:13:56.211731379Z,10,2,38,A,A,1,234.14,200,130,166102,12411253,233.76,234.13,227,400,2,1,233.7,234.14,1200,200,1,1,233.66,234.17,1,29,1,2,233.58,234.41,505,600,2,2,233.53,234.43,10,105,1,2,233.5,234.5,100,63,1,4,233.45,234.75,15,1,1,1,233.4,234.79,110,2000,2,1,233.39,234.89,10,2,1,2,233.31,235.0,110,213,2,6,AAPL,0.0,0.0,-200.0,0.0,0.0,0.0,0.0,0.0,0.0,0.0,0.0,-12.683232565773917,
2024-10-21T12:14:01.071130699Z,2024-10-21T12:14:01.070964390Z,10,2,38,C,A,2,234.17,28,130,166309,12416529,233.76,234.13,227,400,2,1,233.7,234.14,1200,200,1,1,233.66,234.17,1,1,1,1,233.58,234.41,505,600,2,2,233.53,234.43,10,105,1,2,233.5,234.5,100,63,1,4,233.45,234.75,15,1,1,1,233.4,234.79,110,2000,2,1,233.39,234.89,10,2,1,2,233.31,235.0,110,213,2,6,AAPL,0.0,0.0,0.0,28.0,0.0,0.0,0.0,0.0,0.0,0.0,0.0,2.8443122606081452,
2024-10-21T12:14:01.071182062Z,2024-10-21T12:14:01.071015450Z,10,2,38,A,A,2,234.16,27,130,166612,12416530,233.76,234.13,227,400,2,1,233.7,234.14,1200,200,1,1,233.66,234.16,1,27,1,1,233.58,234.17,505,1,2,1,233.53,234.41,10,600,1,2,233.5,234.43,100,105,1,2,233.45,234.5,15,63,1,4,233.4,234.75,110,1,2,1,233.39,234.79,10,2000,1,1,233.31,234.89,110,2,2,2,AAPL,0.0,0.0,0.0,-1.0,-600.0,-105.0,-63.0,-1.0,-2000.0,-2.0,-213.0,-362.6560313475041,
2024-10-21T12:14:01.088302919Z,2024-10-21T12:14:01.088137086Z,10,2,38,C,B,0,233.76,27,130,165833,12416650,233.76,234.13,200,400,1,1,233.7,234.14,1200,200,1,1,233.66,234.16,1,27,1,1,233.58,234.17,505,1,2,1,233.53,234.41,10,600,1,2,233.5,234.43,100,105,1,2,233.45,234.5,15,63,1,4,233.4,234.75,110,1,2,1,233.39,234.79,10,2000,1,1,233.31,234.89,110,2,2,2,AAPL,-27.0,-27.0,0.0,0.0,0.0,0.0,0.0,0.0,0.0,0.0,0.0,-0.5367757314453755,
2024-10-21T12:14:06.103621053Z,2024-10-21T12:14:06.103454338Z,10,2,38,A,B,0,233.97,5,130,166715,12421860,233.97,234.13,5,400,1,1,233.76,234.14,200,200,1,1,233.7,234.16,1200,27,1,1,233.66,234.17,1,1,1,1,233.58,234.41,505,600,2,2,233.53,234.43,10,105,1,2,233.5,234.5,100,63,1,4,233.45,234.75,15,1,1,1,233.4,234.79,110,2000,2,1,233.39,234.89,10,2,1,2,AAPL,5.0,5.0,200.0,1200.0,1.0,505.0,10.0,100.0,15.0,110.0,10.0,216.29970777414056,
2024-10-21T12:14:07.746906258Z,2024-10-21T12:14:07.746740079Z,10,2,38,C,B,1,233.76,200,130,166179,12423513,233.97,234.13,5,400,1,1,233.7,234.14,1200,200,1,1,233.66,234.16,1,27,1,1,233.58,234.17,505,1,2,1,233.53,234.41,10,600,1,2,233.5,234.43,100,105,1,2,233.45,234.5,15,63,1,4,233.4,234.75,110,1,2,1,233.39,234.79,10,2000,1,1,233.31,234.89,110,2,2,2,AAPL,0.0,0.0,-200.0,-1200.0,-1.0,-505.0,-10.0,-100.0,-15.0,-110.0,-10.0,-216.20030486090994,
2024-10-21T12:14:07.746920572Z,2024-10-21T12:14:07.746754069Z,10,2,38,A,B,1,233.73,200,130,166503,12423514,233.97,234.13,5,400,1,1,233.73,234.14,200,200,1,1,233.7,234.16,1200,27,1,1,233.66,234.17,1,1,1,1,233.58,234.41,505,600,2,2,233.53,234.43,10,105,1,2,233.5,234.5,100,63,1,4,233.45,234.75,15,1,1,1,233.4,234.79,110,2000,2,1,233.39,234.89,10,2,1,2,AAPL,0.0,0.0,200.0,1200.0,1.0,505.0,10.0,100.0,15.0,110.0,10.0,216.20030486090994,
2024-10-21T12:14:10.801508542Z,2024-10-21T12:14:10.801342166Z,10,2,38,A,B,1,233.8,200,130,166376,12425721,233.97,234.13,5,400,1,1,233.8,234.14,200,200,1,1,233.7,234.16,1200,27,1,1,233.66,234.17,1,1,1,1,233.58,234.41,505,600,2,2,233.53,234.43,10,105,1,2,233.5,234.5,100,63,1,4,233.45,234.75,15,1,1,1,233.4,234.79,110,2000,2,1,233.39,234.89,10,2,1,2,AAPL,0.0,0.0,200.0,0.0,0.0,0.0,0.0,0.0,0.0,0.0,0.0,12.683232565773917,
2024-10-21T12:14:17.947604712Z,2024-10-21T12:14:17.947438449Z,10,2,38,A,B,1,233.81,200,130,166263,12431541,233.97,234.13,5,400,1,1,233.81,234.14,200,200,1,1,233.7,234.16,1200,27,1,1,233.66,234.17,1,1,1,1,233.58,234.41,505,600,2,2,233.53,234.43,10,105,1,2,233.5,234.5,100,63,1,4,233.45,234.75,15,1,1,1,233.4,234.79,110,2000,2,1,233.39,234.89,10,2,1,2,AAPL,0.0,0.0,200.0,0.0,0.0,0.0,0.0,0.0,0.0,0.0,0.0,12.683232565773917,
2024-10-21T12:14:17.957549086Z,2024-10-21T12:14:17.957382887Z,10,2,38,C,B,1,233.81,200,130,166199,12431585,233.97,234.13,5,400,1,1,233.7,234.14,1200,200,1,1,233.66,234.16,1,27,1,1,233.58,234.17,505,1,2,1,233.53,234.41,10,600,1,2,233.5,234.43,100,105,1,2,233.45,234.5,15,63,1,4,233.4,234.75,110,1,2,1,233.39,234.79,10,2000,1,1,233.31,234.89,110,2,2,2,AAPL,0.0,0.0,-200.0,-1200.0,-1.0,-505.0,-10.0,-100.0,-15.0,-110.0,-10.0,-216.20030486090994,
2024-10-21T12:14:17.957562118Z,2024-10-21T12:14:17.957395933Z,10,2,38,A,B,1,233.74,200,130,166185,12431586,233.97,234.13,5,400,1,1,233.74,234.14,200,200,1,1,233.7,234.16,1200,27,1,1,233.66,234.17,1,1,1,1,233.58,234.41,505,600,2,2,233.53,234.43,10,105,1,2,233.5,234.5,100,63,1,4,233.45,234.75,15,1,1,1,233.4,234.79,110,2000,2,1,233.39,234.89,10,2,1,2,AAPL,0.0,0.0,200.0,1200.0,1.0,505.0,10.0,100.0,15.0,110.0,10.0,216.20030486090994,
2024-10-21T12:14:17.957619401Z,2024-10-21T12:14:17.957453277Z,10,2,38,C,A,1,234.14,200,130,166124,12431587,233.97,234.13,5,400,1,1,233.74,234.16,200,27,1,1,233.7,234.17,1200,1,1,1,233.66,234.41,1,600,1,2,233.58,234.43,505,105,2,2,233.53,234.5,10,63,1,4,233.5,234.75,100,1,1,1,233.45,234.79,15,2000,1,1,233.4,234.89,110,2,2,2,233.39,235.0,10,213,1,6,AAPL,0.0,0.0,27.0,1.0,600.0,105.0,63.0,1.0,2000.0,2.0,213.0,364.36826774388356,
2024-10-21T12:14:17.957631871Z,2024-10-21T12:14:17.957465815Z,10,2,38,A,A,1,234.15,200,130,166056,12431588,233.97,234.13,5,400,1,1,233.74,234.15,200,200,1,1,233.7,234.16,1200,27,1,1,233.66,234.17,1,1,1,1,233.58,234.41,505,600,2,2,233.53,234.43,10,105,1,2,233.5,234.5,100,63,1,4,233.45,234.75,15,1,1,1,233.4,234.79,110,2000,2,1,233.39,234.89,10,2,1,2,AAPL,0.0,0.0,-27.0,-1.0,-600.0,-105.0,-63.0,-1.0,-2000.0,-2.0,-213.0,-364.36826774388356,
2024-10-21T12:14:18.057051301Z,2024-10-21T12:14:18.056884935Z,10,2,38,A,B,1,233.75,200,130,166366,12431913,233.97,234.13,5,400,1,1,233.75,234.15,200,200,1,1,233.7,234.16,1200,27,1,1,233.66,234.17,1,1,1,1,233.58,234.41,505,600,2,2,233.53,234.43,10,105,1,2,233.5,234.5,100,63,1,4,233.45,234.75,15,1,1,1,233.4,234.79,110,2000,2,1,233.39,234.89,10,2,1,2,AAPL,0.0,0.0,200.0,0.0,0.0,0.0,0.0,0.0,0.0,0.0,0.0,12.683232565773917,
2024-10-21T12:14:21.022420708Z,2024-10-21T12:14:21.022254267Z,10,2,38,A,B,1,233.77,200,130,166441,12433640,233.97,234.13,5,400,1,1,233.77,234.15,200,200,1,1,233.7,234.16,1200,27,1,1,233.66,234.17,1,1,1,1,233.58,234.41,505,600,2,2,233.53,234.43,10,105,1,2,233.5,234.5,100,63,1,4,233.45,234.75,15,1,1,1,233.4,234.79,110,2000,2,1,233.39,234.89,10,2,1,2,AAPL,0.0,0.0,200.0,0.0,0.0,0.0,0.0,0.0,0.0,0.0,0.0,12.683232565773917,
2024-10-21T12:14:21.336855528Z,2024-10-21T12:14:21.336689135Z,10,2,38,C,A,1,234.15,200,130,166393,12433903,233.97,234.13,5,400,1,1,233.77,234.16,200,27,1,1,233.7,234.17,1200,1,1,1,233.66,234.41,1,600,1,2,233.58,234.43,505,105,2,2,233.53,234.5,10,63,1,4,233.5,234.75,100,1,1,1,233.45,234.79,15,2000,1,1,233.4,234.89,110,2,2,2,233.39,235.0,10,213,1,6,AAPL,0.0,0.0,27.0,1.0,600.0,105.0,63.0,1.0,2000.0,2.0,213.0,364.36826774388356,
2024-10-21T12:14:21.336867325Z,2024-10-21T12:14:21.336700928Z,10,2,38,A,A,2,234.17,200,130,166397,12433905,233.97,234.13,5,400,1,1,233.77,234.16,200,27,1,1,233.7,234.17,1200,201,1,2,233.66,234.41,1,600,1,2,233.58,234.43,505,105,2,2,233.53,234.5,10,63,1,4,233.5,234.75,100,1,1,1,233.45,234.79,15,2000,1,1,233.4,234.89,110,2,2,2,233.39,235.0,10,213,1,6,AAPL,0.0,0.0,0.0,-200.0,0.0,0.0,0.0,0.0,0.0,0.0,0.0,-20.31651614720104,
2024-10-21T12:14:21.392793975Z,2024-10-21T12:14:21.392627701Z,10,2,38,A,B,1,233.78,200,130,166274,12433982,233.97,234.13,5,400,1,1,233.78,234.16,200,27,1,1,233.7,234.17,1200,201,1,2,233.66,234.41,1,600,1,2,233.58,234.43,505,105,2,2,233.53,234.5,10,63,1,4,233.5,234.75,100,1,1,1,233.45,234.79,15,2000,1,1,233.4,234.89,110,2,2,2,233.39,235.0,10,213,1,6,AAPL,0.0,0.0,200.0,0.0,0.0,0.0,0.0,0.0,0.0,0.0,0.0,12.683232565773917,
2024-10-21T12:14:21.427147627Z,2024-10-21T12:14:21.426981432Z,10,2,38,C,A,1,234.16,27,130,166195,12434166,233.97,234.13,5,400,1,1,233.78,234.17,200,201,1,2,233.7,234.41,1200,600,1,2,233.66,234.43,1,105,1,2,233.58,234.5,505,63,2,4,233.53,234.75,10,1,1,1,233.5,234.79,100,2000,1,1,233.45,234.89,15,2,1,2,233.4,235.0,110,213,2,6,233.39,235.03,10,2,1,1,AAPL,0.0,0.0,201.0,600.0,105.0,63.0,1.0,2000.0,2.0,213.0,2.0,345.8178973685714,
