ts_recv,ts_event,rtype,publisher_id,instrument_id,action,side,depth,price,size,flags,ts_in_delta,sequence,bid_px_00,ask_px_00,bid_sz_00,ask_sz_00,bid_ct_00,ask_ct_00,bid_px_01,ask_px_01,bid_sz_01,ask_sz_01,bid_ct_01,ask_ct_01,bid_px_02,ask_px_02,bid_sz_02,ask_sz_02,bid_ct_02,ask_ct_02,bid_px_03,ask_px_03,bid_sz_03,ask_sz_03,bid_ct_03,ask_ct_03,bid_px_04,ask_px_04,bid_sz_04,ask_sz_04,bid_ct_04,ask_ct_04,bid_px_05,ask_px_05,bid_sz_05,ask_sz_05,bid_ct_05,ask_ct_05,bid_px_06,ask_px_06,bid_sz_06,ask_sz_06,bid_ct_06,ask_ct_06,bid_px_07,ask_px_07,bid_sz_07,ask_sz_07,bid_ct_07,ask_ct_07,bid_px_08,ask_px_08,bid_sz_08,ask_sz_08,bid_ct_08,ask_ct_08,bid_px_09,ask_px_09,bid_sz_09,ask_sz_09,bid_ct_09,ask_ct_09,symbol,best_level_ofi,ofi_00,ofi_01,ofi_02,ofi_03,ofi_04,ofi_05,ofi_06,ofi_07,ofi_08,ofi_09,integrated_ofi,cross_asset_ofi
2024-10-21T12:14:21.740752948Z,2024-10-21T12:14:21.740586460Z,10,2,38,A,B,2,233.76,29,130,166488,12434650,233.97,234.13,5,400,1,1,233.78,234.17,200,201,1,2,233.76,234.41,29,600,1,2,233.7,234.43,1200,105,1,2,233.66,234.5,1,63,1,4,233.58,234.75,505,1,2,1,233.53,234.79,10,2000,1,1,233.5,234.89,100,2,1,2,233.45,235.0,15,213,1,6,233.4,235.03,110,2,2,1,AAPL,0.0,0.0,0.0,29.0,1200.0,1.0,505.0,10.0,100.0,15.0,110.0,338.84340878618633,
2024-10-21T12:14:21.740783568Z,2024-10-21T12:14:21.740617322Z,10,2,38,A,A,2,234.18,28,130,166246,12434651,233.97,234.13,5,400,1,1,233.78,234.17,200,201,1,2,233.76,234.18,29,28,1,1,233.7,234.41,1200,600,1,2,233.66,234.43,1,105,1,2,233.58,234.5,505,63,2,4,233.53,234.75,10,1,1,1,233.5,234.79,100,2000,1,1,233.45,234.89,15,2,1,2,233.4,235.0,110,213,2,6,AAPL,0.0,0.0,0.0,-600.0,-105.0,-63.0,-1.0,-2000.0,-2.0,-213.0,-2.0,-333.07124863996853,
2024-10-21T12:14:28.747385812Z,2024-10-21T12:14:28.747219089Z,10,2,38,A,B,1,233.79,200,130,166723,12439708,233.97,234.13,5,400,1,1,233.79,234.17,200,201,1,2,233.76,234.18,29,28,1,1,233.7,234.41,1200,600,1,2,233.66,234.43,1,105,1,2,233.58,234.5,505,63,2,4,233.53,234.75,10,1,1,1,233.5,234.79,100,2000,1,1,233.45,234.89,15,2,1,2,233.4,235.0,110,213,2,6,AAPL,0.0,0.0,200.0,0.0,0.0,0.0,0.0,0.0,0.0,0.0,0.0,12.683232565773917,
2024-10-21T12:14:37.348331123Z,2024-10-21T12:14:37.348164372Z,10,2,38,C,B,1,233.79,200,130,166751,12446142,233.97,234.13,5,400,1,1,233.76,234.17,29,201,1,2,233.7,234.18,1200,28,1,1,233.66,234.41,1,600,1,2,233.58,234.43,505,105,2,2,233.53,234.5,10,63,1,4,233.5,234.75,100,1,1,1,233.45,234.79,15,2000,1,1,233.4,234.89,110,2,2,2,233.39,235.0,10,213,1,6,AAPL,0.0,0.0,-200.0,-29.0,-1200.0,-1.0,-505.0,-10.0,-100.0,-15.0,-110.0,-351.5266413519603,
2024-10-21T12:14:37.348344285Z,2024-10-21T12:14:37.348177626Z,10,2,38,A,B,1,233.77,200,130,166659,12446143,233.97,234.13,5,400,1,1,233.77,234.17,200,201,1,2,233.76,234.18,29,28,1,1,233.7,234.41,1200,600,1,2,233.66,234.43,1,105,1,2,233.58,234.5,505,63,2,4,233.53,234.75,10,1,1,1,233.5,234.79,100,2000,1,1,233.45,234.89,15,2,1,2,233.4,235.0,110,213,2,6,AAPL,0.0,0.0,200.0,29.0,1200.0,1.0,505.0,10.0,100.0,15.0,110.0,351.5266413519603,
2024-10-21T12:14:37.485597454Z,2024-10-21T12:14:37.485431160Z,10,2,38,A,B,1,233.78,200,130,166294,12446234,233.97,234.13,5,400,1,1,233.78,234.17,200,201,1,2,233.76,234.18,29,28,1,1,233.7,234.41,1200,600,1,2,233.66,234.43,1,105,1,2,233.58,234.5,505,63,2,4,233.53,234.75,10,1,1,1,233.5,234.79,100,2000,1,1,233.45,234.89,15,2,1,2,233.4,235.0,110,213,2,6,AAPL,0.0,0.0,200.0,0.0,0.0,0.0,0.0,0.0,0.0,0.0,0.0,12.683232565773917,
2024-10-21T12:14:41.549332947Z,2024-10-21T12:14:41.549166803Z,10,2,38,C,B,2,233.76,29,130,166144,12448595,233.97,234.13,5,400,1,1,233.78,234.17,200,201,1,2,233.7,234.18,1200,28,1,1,233.66,234.41,1,600,1,2,233.58,234.43,505,105,2,2,233.53,234.5,10,63,1,4,233.5,234.75,100,1,1,1,233.45,234.79,15,2000,1,1,233.4,234.89,110,2,2,2,233.39,235.0,10,213,1,6,AAPL,0.0,0.0,0.0,-29.0,-1200.0,-1.0,-505.0,-10.0,-100.0,-15.0,-110.0,-338.84340878618633,
2024-10-21T12:14:41.549378383Z,2024-10-21T12:14:41.549212050Z,10,2,38,A,B,1,233.81,28,130,166333,12448596,233.97,234.13,5,400,1,1,233.81,234.17,28,201,1,2,233.78,234.18,200,28,1,1,233.7,234.41,1200,600,1,2,233.66,234.43,1,105,1,2,233.58,234.5,505,63,2,4,233.53,234.75,10,1,1,1,233.5,234.79,100,2000,1,1,233.45,234.89,15,2,1,2,233.4,235.0,110,213,2,6,AAPL,0.0,0.0,28.0,200.0,1200.0,1.0,505.0,10.0,100.0,15.0,110.0,357.9896826512516,
2024-10-21T12:14:41.599757577Z,2024-10-21T12:14:41.599590898Z,10,2,38,A,B,1,233.87,200,130,166679,12448666,233.97,234.13,5,400,1,1,233.87,234.17,200,201,1,2,233.81,234.18,28,28,1,1,233.7,234.41,1200,600,1,2,233.66,234.43,1,105,1,2,233.58,234.5,505,63,2,4,233.53,234.75,10,1,1,1,233.5,234.79,100,2000,1,1,233.45,234.89,15,2,1,2,233.4,235.0,110,213,2,6,AAPL,0.0,0.0,200.0,28.0,0.0,0.0,0.0,0.0,0.0,0.0,0.0,15.527544826382062,
2024-10-21T12:14:43.206124405Z,2024-10-21T12:14:43.205958056Z,10,2,38,A,A,1,234.16,200,130,166349,12449507,233.97,234.13,5,400,1,1,233.87,234.16,200,200,1,1,233.81,234.17,28,1,1,1,233.7,234.18,1200,28,1,1,233.66,234.41,1,600,1,2,233.58,234.43,505,105,2,2,233.53,234.5,10,63,1,4,233.5,234.75,100,1,1,1,233.45,234.79,15,2000,1,1,233.4,234.89,110,2,2,2,AAPL,0.0,0.0,-201.0,-28.0,-600.0,-105.0,-63.0,-1.0,-2000.0,-2.0,-213.0,-378.145409755979,
2024-10-21T12:14:49.824860694Z,2024-10-21T12:14:49.824694031Z,10,2,38,A,A,1,234.16,200,130,166663,12453535,233.97,234.13,5,400,1,1,233.87,234.16,200,400,1,2,233.81,234.17,28,1,1,1,233.7,234.18,1200,28,1,1,233.66,234.41,1,600,1,2,233.58,234.43,505,105,2,2,233.53,234.5,10,63,1,4,233.5,234.75,100,1,1,1,233.45,234.79,15,2000,1,1,233.4,234.89,110,2,2,2,AAPL,0.0,0.0,-200.0,0.0,0.0,0.0,0.0,0.0,0.0,0.0,0.0,-12.683232565773917,
2024-10-21T12:14:52.414059791Z,2024-10-21T12:14:52.413893215Z,10,2,38,C,B,1,233.87,200,130,166576,12455999,233.97,234.13,5,400,1,1,233.81,234.16,28,400,1,2,233.7,234.17,1200,1,1,1,233.66,234.18,1,28,1,1,233.58,234.41,505,600,2,2,233.53,234.43,10,105,1,2,233.5,234.5,100,63,1,4,233.45,234.75,15,1,1,1,233.4,234.79,110,2000,2,1,233.39,234.89,10,2,1,2,AAPL,0.0,0.0,-200.0,-28.0,-1200.0,-1.0,-505.0,-10.0,-100.0,-15.0,-110.0,-351.42505877122426,
2024-10-21T12:14:52.414071390Z,2024-10-21T12:14:52.413904869Z,10,2,38,A,B,1,233.85,200,130,166521,12456000,233.97,234.13,5,400,1,1,233.85,234.16,200,400,1,2,233.81,234.17,28,1,1,1,233.7,234.18,1200,28,1,1,233.66,234.41,1,600,1,2,233.58,234.43,505,105,2,2,233.53,234.5,10,63,1,4,233.5,234.75,100,1,1,1,233.45,234.79,15,2000,1,1,233.4,234.89,110,2,2,2,AAPL,0.0,0.0,200.0,28.0,1200.0,1.0,505.0,10.0,100.0,15.0,110.0,351.42505877122426,
2024-10-21T12:14:52.473505418Z,2024-10-21T12:14:52.473339217Z,10,2,38,C,A,1,234.16,200,130,166201,12456232,233.97,234.13,5,400,1,1,233.85,234.16,200,200,1,1,233.81,234.17,28,1,1,1,233.7,234.18,1200,28,1,1,233.66,234.41,1,600,1,2,233.58,234.43,505,105,2,2,233.53,234.5,10,63,1,4,233.5,234.75,100,1,1,1,233.45,234.79,15,2000,1,1,233.4,234.89,110,2,2,2,AAPL,0.0,0.0,200.0,0.0,0.0,0.0,0.0,0.0,0.0,0.0,0.0,12.683232565773917,
2024-10-21T12:14:52.473518693Z,2024-10-21T12:14:52.473352225Z,10,2,38,A,A,1,234.15,200,130,166468,12456234,233.97,234.13,5,400,1,1,233.85,234.15,200,200,1,1,233.81,234.17,28,1,1,1,233.7,234.18,1200,28,1,1,233.66,234.41,1,600,1,2,233.58,234.43,505,105,2,2,233.53,234.5,10,63,1,4,233.5,234.75,100,1,1,1,233.45,234.79,15,2000,1,1,233.4,234.89,110,2,2,2,AAPL,0.0,0.0,-200.0,0.0,0.0,0.0,0.0,0.0,0.0,0.0,0.0,-12.683232565773917,
2024-10-21T12:14:52.474565706Z,2024-10-21T12:14:52.474399706Z,10,2,38,C,A,3,234.18,28,130,166000,12456246,233.97,234.13,5,400,1,1,233.85,234.15,200,200,1,1,233.81,234.17,28,1,1,1,233.7,234.41,1200,600,1,2,233.66,234.43,1,105,1,2,233.58,234.5,505,63,2,4,233.53,234.75,10,1,1,1,233.5,234.79,100,2000,1,1,233.45,234.89,15,2,1,2,233.4,235.0,110,213,2,6,AAPL,0.0,0.0,0.0,0.0,600.0,105.0,63.0,1.0,2000.0,2.0,213.0,362.5544487667681,
2024-10-21T12:14:52.474619355Z,2024-10-21T12:14:52.474453011Z,10,2,38,A,A,2,234.17,29,130,166344,12456247,233.97,234.13,5,400,1,1,233.85,234.15,200,200,1,1,233.81,234.17,28,30,1,2,233.7,234.41,1200,600,1,2,233.66,234.43,1,105,1,2,233.58,234.5,505,63,2,4,233.53,234.75,10,1,1,1,233.5,234.79,100,2000,1,1,233.45,234.89,15,2,1,2,233.4,235.0,110,213,2,6,AAPL,0.0,0.0,0.0,-29.0,0.0,0.0,0.0,0.0,0.0,0.0,0.0,-2.945894841344151,
2024-10-21T12:14:53.024832003Z,2024-10-21T12:14:53.024665699Z,10,2,38,A,A,1,234.15,200,130,166304,12457068,233.97,234.13,5,400,1,1,233.85,234.15,200,400,1,2,233.81,234.17,28,30,1,2,233.7,234.41,1200,600,1,2,233.66,234.43,1,105,1,2,233.58,234.5,505,63,2,4,233.53,234.75,10,1,1,1,233.5,234.79,100,2000,1,1,233.45,234.89,15,2,1,2,233.4,235.0,110,213,2,6,AAPL,0.0,0.0,-200.0,0.0,0.0,0.0,0.0,0.0,0.0,0.0,0.0,-12.683232565773917,
2024-10-21T12:14:59.069231899Z,2024-10-21T12:14:59.069065580Z,10,2,38,A,B,1,233.86,200,130,166319,12461167,233.97,234.13,5,400,1,1,233.86,234.15,200,400,1,2,233.81,234.17,28,30,1,2,233.7,234.41,1200,600,1,2,233.66,234.43,1,105,1,2,233.58,234.5,505,63,2,4,233.53,234.75,10,1,1,1,233.5,234.79,100,2000,1,1,233.45,234.89,15,2,1,2,233.4,235.0,110,213,2,6,AAPL,0.0,0.0,200.0,0.0,0.0,0.0,0.0,0.0,0.0,0.0,0.0,12.683232565773917,
2024-10-21T12:15:05.174166268Z,2024-10-21T12:15:05.174000161Z,10,2,38,C,A,1,234.15,200,130,166107,12470009,233.97,234.13,5,400,1,1,233.86,234.15,200,200,1,1,233.81,234.17,28,30,1,2,233.7,234.41,1200,600,1,2,233.66,234.43,1,105,1,2,233.58,234.5,505,63,2,4,233.53,234.75,10,1,1,1,233.5,234.79,100,2000,1,1,233.45,234.89,15,2,1,2,233.4,235.0,110,213,2,6,AAPL,0.0,0.0,200.0,0.0,0.0,0.0,0.0,0.0,0.0,0.0,0.0,12.683232565773917,
2024-10-21T12:15:05.174176083Z,2024-10-21T12:15:05.174010189Z,10,2,38,C,A,1,234.15,200,130,165894,12470010,233.97,234.13,5,400,1,1,233.86,234.17,200,30,1,2,233.81,234.41,28,600,1,2,233.7,234.43,1200,105,1,2,233.66,234.5,1,63,1,4,233.58,234.75,505,1,2,1,233.53,234.79,10,2000,1,1,233.5,234.89,100,2,1,2,233.45,235.0,15,213,1,6,233.4,235.03,110,2,2,1,AAPL,0.0,0.0,30.0,600.0,105.0,63.0,1.0,2000.0,2.0,213.0,2.0,334.97373352483464,
2024-10-21T12:15:05.174191104Z,2024-10-21T12:15:05.174024191Z,10,2,38,A,A,1,234.16,200,130,166913,12470011,233.97,234.13,5,400,1,1,233.86,234.16,200,200,1,1,233.81,234.17,28,30,1,2,233.7,234.41,1200,600,1,2,233.66,234.43,1,105,1,2,233.58,234.5,505,63,2,4,233.53,234.75,10,1,1,1,233.5,234.79,100,2000,1,1,233.45,234.89,15,2,1,2,233.4,235.0,110,213,2,6,AAPL,0.0,0.0,-30.0,-600.0,-105.0,-63.0,-1.0,-2000.0,-2.0,-213.0,-2.0,-334.97373352483464,
2024-10-21T12:15:08.174832295Z,2024-10-21T12:15:08.174665588Z,10,2,38,A,A,1,234.16,200,130,166707,12472897,233.97,234.13,5,400,1,1,233.86,234.16,200,400,1,2,233.81,234.17,28,30,1,2,233.7,234.41,1200,600,1,2,233.66,234.43,1,105,1,2,233.58,234.5,505,63,2,4,233.53,234.75,10,1,1,1,233.5,234.79,100,2000,1,1,233.45,234.89,15,2,1,2,233.4,235.0,110,213,2,6,AAPL,0.0,0.0,-200.0,0.0,0.0,0.0,0.0,0.0,0.0,0.0,0.0,-12.683232565773917,
2024-10-21T12:15:12.192782193Z,2024-10-21T12:15:12.192615974Z,10,2,38,A,A,0,234.07,100,130,166219,12475949,233.97,234.07,5,100,1,1,233.86,234.13,200,400,1,1,233.81,234.16,28,400,1,2,233.7,234.17,1200,30,1,2,233.66,234.41,1,600,1,2,233.58,234.43,505,105,2,2,233.53,234.5,10,63,1,4,233.5,234.75,100,1,1,1,233.45,234.79,15,2000,1,1,233.4,234.89,110,2,2,2,AAPL,-400.0,-400.0,-400.0,-30.0,-600.0,-105.0,-63.0,-1.0,-2000.0,-2.0,-213.0,-398.92062437884607,
2024-10-21T12:15:12.193180932Z,2024-10-21T12:15:12.193015032Z,10,2,38,C,A,0,234.07,100,130,165900,12475950,233.97,234.13,5,400,1,1,233.86,234.16,200,400,1,2,233.81,234.17,28,30,1,2,233.7,234.41,1200,600,1,2,233.66,234.43,1,105,1,2,233.58,234.5,505,63,2,4,233.53,234.75,10,1,1,1,233.5,234.79,100,2000,1,1,233.45,234.89,15,2,1,2,233.4,235.0,110,213,2,6,AAPL,400.0,400.0,400.0,30.0,600.0,105.0,63.0,1.0,2000.0,2.0,213.0,398.92062437884607,
2024-10-21T12:15:12.197936547Z,2024-10-21T12:15:12.197769369Z,10,2,38,A,A,0,234.07,148,128,167178,12475955,233.97,234.07,5,148,1,1,233.86,234.13,200,400,1,1,233.81,234.16,28,400,1,2,233.7,234.17,1200,30,1,2,233.66,234.41,1,600,1,2,233.58,234.43,505,105,2,2,233.53,234.5,10,63,1,4,233.5,234.75,100,1,1,1,233.45,234.79,15,2000,1,1,233.4,234.89,110,2,2,2,AAPL,-400.0,-400.0,-400.0,-30.0,-600.0,-105.0,-63.0,-1.0,-2000.0,-2.0,-213.0,-398.92062437884607,
2024-10-21T12:15:12.197969503Z,2024-10-21T12:15:12.197802997Z,10,2,38,C,B,1,233.86,200,130,166506,12475958,233.97,234.07,5,148,1,1,233.81,234.13,28,400,1,1,233.7,234.16,1200,400,1,2,233.66,234.17,1,30,1,2,233.58,234.41,505,600,2,2,233.53,234.43,10,105,1,2,233.5,234.5,100,63,1,4,233.45,234.75,15,1,1,1,233.4,234.79,110,2000,2,1,233.39,234.89,10,2,1,2,AAPL,0.0,0.0,-200.0,-28.0,-1200.0,-1.0,-505.0,-10.0,-100.0,-15.0,-110.0,-351.42505877122426,
2024-10-21T12:15:12.202040946Z,2024-10-21T12:15:12.201874823Z,10,2,38,C,A,0,234.07,148,130,166123,12475962,233.97,234.13,5,400,1,1,233.81,234.16,28,400,1,2,233.7,234.17,1200,30,1,2,233.66,234.41,1,600,1,2,233.58,234.43,505,105,2,2,233.53,234.5,10,63,1,4,233.5,234.75,100,1,1,1,233.45,234.79,15,2000,1,1,233.4,234.89,110,2,2,2,233.39,235.0,10,213,1,6,AAPL,400.0,400.0,400.0,30.0,600.0,105.0,63.0,1.0,2000.0,2.0,213.0,398.92062437884607,
2024-10-21T12:15:12.264617436Z,2024-10-21T12:15:12.264450843Z,10,2,38,A,B,2,233.75,28,130,166593,12476000,233.97,234.13,5,400,1,1,233.81,234.16,28,400,1,2,233.75,234.17,28,30,1,2,233.7,234.41,1200,600,1,2,233.66,234.43,1,105,1,2,233.58,234.5,505,63,2,4,233.53,234.75,10,1,1,1,233.5,234.79,100,2000,1,1,233.45,234.89,15,2,1,2,233.4,235.0,110,213,2,6,AAPL,0.0,0.0,0.0,28.0,1200.0,1.0,505.0,10.0,100.0,15.0,110.0,338.74182620545037,
2024-10-21T12:15:12.264644369Z,2024-10-21T12:15:12.264477828Z,10,2,38,C,B,1,233.81,28,130,166541,12476001,233.97,234.13,5,400,1,1,233.75,234.16,28,400,1,2,233.7,234.17,1200,30,1,2,233.66,234.41,1,600,1,2,233.58,234.43,505,105,2,2,233.53,234.5,10,63,1,4,233.5,234.75,100,1,1,1,233.45,234.79,15,2000,1,1,233.4,234.89,110,2,2,2,233.39,235.0,10,213,1,6,AAPL,0.0,0.0,-28.0,-28.0,-1200.0,-1.0,-505.0,-10.0,-100.0,-15.0,-110.0,-340.5174787646587,
2024-10-21T12:15:12.268501792Z,2024-10-21T12:15:12.268335051Z,10,2,38,A,B,4,233.63,200,130,166741,12476005,233.97,234.13,5,400,1,1,233.75,234.16,28,400,1,2,233.7,234.17,1200,30,1,2,233.66,234.41,1,600,1,2,233.63,234.43,200,105,1,2,233.58,234.5,505,63,2,4,233.53,234.75,10,1,1,1,233.5,234.79,100,2000,1,1,233.45,234.89,15,2,1,2,233.4,235.0,110,213,2,6,AAPL,0.0,0.0,0.0,0.0,0.0,200.0,505.0,10.0,100.0,15.0,110.0,112.96619769639827,
2024-10-21T12:15:12.268802483Z,2024-10-21T12:15:12.268635983Z,10,2,38,C,B,1,233.75,28,130,166500,12476006,233.97,234.13,5,400,1,1,233.7,234.16,1200,400,1,2,233.66,234.17,1,30,1,2,233.63,234.41,200,600,1,2,233.58,234.43,505,105,2,2,233.53,234.5,10,63,1,4,233.5,234.75,100,1,1,1,233.45,234.79,15,2000,1,1,233.4,234.89,110,2,2,2,233.39,235.0,10,213,1,6,AAPL,0.0,0.0,-28.0,-1200.0,-1.0,-200.0,-505.0,-10.0,-100.0,-15.0,-110.0,-236.84602419383697,
2024-10-21T12:15:12.270394146Z,2024-10-21T12:15:12.270227323Z,10,2,38,C,A,2,234.17,29,130,166823,12476010,233.97,234.13,5,400,1,1,233.7,234.16,1200,400,1,2,233.66,234.17,1,1,1,1,233.63,234.41,200,600,1,2,233.58,234.43,505,105,2,2,233.53,234.5,10,63,1,4,233.5,234.75,100,1,1,1,233.45,234.79,15,2000,1,1,233.4,234.89,110,2,2,2,233.39,235.0,10,213,1,6,AAPL,0.0,0.0,0.0,29.0,0.0,0.0,0.0,0.0,0.0,0.0,0.0,2.945894841344151,
2024-10-21T12:15:12.270492635Z,2024-10-21T12:15:12.270326143Z,10,2,38,A,A,0,234.12,27,130,166492,12476011,233.97,234.12,5,27,1,1,233.7,234.13,1200,400,1,1,233.66,234.16,1,400,1,2,233.63,234.17,200,1,1,1,233.58,234.41,505,600,2,2,233.53,234.43,10,105,1,2,233.5,234.5,100,63,1,4,233.45,234.75,15,1,1,1,233.4,234.79,110,2000,2,1,233.39,234.89,10,2,1,2,AAPL,-400.0,-400.0,-400.0,-1.0,-600.0,-105.0,-63.0,-1.0,-2000.0,-2.0,-213.0,-395.97472953750196,
2024-10-21T12:15:12.270531958Z,2024-10-21T12:15:12.270365637Z,10,2,38,A,A,2,234.15,26,130,166321,12476012,233.97,234.12,5,27,1,1,233.7,234.13,1200,400,1,1,233.66,234.15,1,26,1,1,233.63,234.16,200,400,1,2,233.58,234.17,505,1,2,1,233.53,234.41,10,600,1,2,233.5,234.43,100,105,1,2,233.45,234.5,15,63,1,4,233.4,234.75,110,1,2,1,233.39,234.79,10,2000,1,1,AAPL,0.0,0.0,0.0,-400.0,-1.0,-600.0,-105.0,-63.0,-1.0,-2000.0,-2.0,-271.19685031628507,
2024-10-21T12:15:12.319033039Z,2024-10-21T12:15:12.318866641Z,10,2,38,A,B,3,233.64,200,130,166398,12476109,233.97,234.12,5,27,1,1,233.7,234.13,1200,400,1,1,233.66,234.15,1,26,1,1,233.64,234.16,200,400,1,2,233.58,234.17,505,1,2,1,233.53,234.41,10,600,1,2,233.5,234.43,100,105,1,2,233.45,234.5,15,63,1,4,233.4,234.75,110,1,2,1,233.39,234.79,10,2000,1,1,AAPL,0.0,0.0,0.0,0.0,200.0,0.0,0.0,0.0,0.0,0.0,0.0,41.015411004823704,
2024-10-21T12:15:12.319045020Z,2024-10-21T12:15:12.318878820Z,10,2,38,C,A,3,234.16,200,130,166200,12476110,233.97,234.12,5,27,1,1,233.7,234.13,1200,400,1,1,233.66,234.15,1,26,1,1,233.64,234.16,200,200,1,1,233.58,234.17,505,1,2,1,233.53,234.41,10,600,1,2,233.5,234.43,100,105,1,2,233.45,234.5,15,63,1,4,233.4,234.75,110,1,2,1,233.39,234.79,10,2000,1,1,AAPL,0.0,0.0,0.0,0.0,200.0,0.0,0.0,0.0,0.0,0.0,0.0,41.015411004823704,
2024-10-21T12:15:12.319057841Z,2024-10-21T12:15:12.318890689Z,10,2,38,A,A,2,234.15,400,130,167152,12476111,233.97,234.12,5,27,1,1,233.7,234.13,1200,400,1,1,233.66,234.15,1,426,1,2,233.64,234.17,200,1,1,1,233.58,234.41,505,600,2,2,233.53,234.43,10,105,1,2,233.5,234.5,100,63,1,4,233.45,234.75,15,1,1,1,233.4,234.79,110,2000,2,1,233.39,234.89,10,2,1,2,AAPL,0.0,0.0,0.0,-400.0,1.0,600.0,105.0,63.0,1.0,2000.0,2.0,189.9307857274809,
2024-10-21T12:15:12.327981136Z,2024-10-21T12:15:12.327814809Z,10,2,38,A,A,0,234.05,200,130,166327,12476126,233.97,234.05,5,200,1,1,233.7,234.12,1200,27,1,1,233.66,234.13,1,400,1,1,233.64,234.15,200,26,1,1,233.58,234.17,505,1,2,1,233.53,234.41,10,600,1,2,233.5,234.43,100,105,1,2,233.45,234.5,15,63,1,4,233.4,234.75,110,1,2,1,233.39,234.79,10,2000,1,1,AAPL,-27.0,-27.0,-400.0,-426.0,-1.0,-600.0,-105.0,-63.0,-1.0,-2000.0,-2.0,-299.7412382784144,
2024-10-21T12:15:12.391178086Z,2024-10-21T12:15:12.391011950Z,10,2,38,C,A,1,234.12,27,130,166136,12476246,233.97,234.05,5,200,1,1,233.7,234.13,1200,400,1,1,233.66,234.15,1,26,1,1,233.64,234.17,200,1,1,1,233.58,234.41,505,600,2,2,233.53,234.43,10,105,1,2,233.5,234.5,100,63,1,4,233.45,234.75,15,1,1,1,233.4,234.79,110,2000,2,1,233.39,234.89,10,2,1,2,AAPL,0.0,0.0,400.0,26.0,1.0,600.0,105.0,63.0,1.0,2000.0,2.0,258.571430252567,
2024-10-21T12:15:12.404855221Z,2024-10-21T12:15:12.404688523Z,10,2,38,A,B,3,233.65,200,130,166698,12476254,233.97,234.05,5,200,1,1,233.7,234.13,1200,400,1,1,233.66,234.15,1,26,1,1,233.65,234.17,200,1,1,1,233.58,234.41,505,600,2,2,233.53,234.43,10,105,1,2,233.5,234.5,100,63,1,4,233.45,234.75,15,1,1,1,233.4,234.79,110,2000,2,1,233.39,234.89,10,2,1,2,AAPL,0.0,0.0,0.0,0.0,200.0,0.0,0.0,0.0,0.0,0.0,0.0,41.015411004823704,
2024-10-21T12:15:12.446982743Z,2024-10-21T12:15:12.446815675Z,10,2,38,A,B,2,233.69,200,130,167068,12476283,233.97,234.05,5,200,1,1,233.7,234.13,1200,400,1,1,233.69,234.15,200,26,1,1,233.66,234.17,1,1,1,1,233.58,234.41,505,600,2,2,233.53,234.43,10,105,1,2,233.5,234.5,100,63,1,4,233.45,234.75,15,1,1,1,233.4,234.79,110,2000,2,1,233.39,234.89,10,2,1,2,AAPL,0.0,0.0,0.0,200.0,1.0,0.0,0.0,0.0,0.0,0.0,0.0,20.52159320222516,
2024-10-21T12:15:12.518924447Z,2024-10-21T12:15:12.518757844Z,10,2,38,A,B,2,233.69,200,130,166603,12476376,233.97,234.05,5,200,1,1,233.7,234.13,1200,400,1,1,233.69,234.15,400,26,2,1,233.66,234.17,1,1,1,1,233.58,234.41,505,600,2,2,233.53,234.43,10,105,1,2,233.5,234.5,100,63,1,4,233.45,234.75,15,1,1,1,233.4,234.79,110,2000,2,1,233.39,234.89,10,2,1,2,AAPL,0.0,0.0,0.0,200.0,0.0,0.0,0.0,0.0,0.0,0.0,0.0,20.31651614720104,
2024-10-21T12:15:12.519057354Z,2024-10-21T12:15:12.518889885Z,10,2,38,C,A,0,234.05,200,130,167469,12476377,233.97,234.13,5,400,1,1,233.7,234.15,1200,26,1,1,233.69,234.17,400,1,2,1,233.66,234.41,1,600,1,2,233.58,234.43,505,105,2,2,233.53,234.5,10,63,1,4,233.5,234.75,100,1,1,1,233.45,234.79,15,2000,1,1,233.4,234.89,110,2,2,2,233.39,235.0,10,213,1,6,AAPL,400.0,400.0,26.0,1.0,600.0,105.0,63.0,1.0,2000.0,2.0,213.0,372.2570846395047,
2024-10-21T12:15:12.519068158Z,2024-10-21T12:15:12.518901713Z,10,2,38,A,A,0,234.1,400,130,166445,12476378,233.97,234.1,5,400,1,1,233.7,234.13,1200,400,1,1,233.69,234.15,400,26,2,1,233.66,234.17,1,1,1,1,233.58,234.41,505,600,2,2,233.53,234.43,10,105,1,2,233.5,234.5,100,63,1,4,233.45,234.75,15,1,1,1,233.4,234.79,110,2000,2,1,233.39,234.89,10,2,1,2,AAPL,-400.0,-400.0,-26.0,-1.0,-600.0,-105.0,-63.0,-1.0,-2000.0,-2.0,-213.0,-372.2570846395047,
2024-10-21T12:15:12.521808610Z,2024-10-21T12:15:12.521642022Z,10,2,38,C,A,0,234.1,200,130,166588,12476383,233.97,234.1,5,200,1,1,233.7,234.13,1200,400,1,1,233.69,234.15,400,26,2,1,233.66,234.17,1,1,1,1,233.58,234.41,505,600,2,2,233.53,234.43,10,105,1,2,233.5,234.5,100,63,1,4,233.45,234.75,15,1,1,1,233.4,234.79,110,2000,2,1,233.39,234.89,10,2,1,2,AAPL,200.0,200.0,0.0,0.0,0.0,0.0,0.0,0.0,0.0,0.0,0.0,3.9761165292250036,
2024-10-21T12:15:12.529759184Z,2024-10-21T12:15:12.529592990Z,10,2,38,C,B,2,233.69,200,130,166194,12476384,233.97,234.1,5,200,1,1,233.7,234.13,1200,400,1,1,233.69,234.15,200,26,1,1,233.66,234.17,1,1,1,1,233.58,234.41,505,600,2,2,233.53,234.43,10,105,1,2,233.5,234.5,100,63,1,4,233.45,234.75,15,1,1,1,233.4,234.79,110,2000,2,1,233.39,234.89,10,2,1,2,AAPL,0.0,0.0,0.0,-200.0,0.0,0.0,0.0,0.0,0.0,0.0,0.0,-20.31651614720104,
2024-10-21T12:15:12.529771785Z,2024-10-21T12:15:12.529605412Z,10,2,38,A,B,1,233.7,400,130,166373,12476385,233.97,234.1,5,200,1,1,233.7,234.13,1600,400,2,1,233.66,234.15,1,26,1,1,233.58,234.17,505,1,2,1,233.53,234.41,10,600,1,2,233.5,234.43,100,105,1,2,233.45,234.5,15,63,1,4,233.4,234.75,110,1,2,1,233.39,234.79,10,2000,1,1,233.31,234.89,110,2,2,2,AAPL,0.0,0.0,400.0,-200.0,-1.0,-505.0,-10.0,-100.0,-15.0,-110.0,-10.0,-76.56802642758298,
2024-10-21T12:15:12.575269816Z,2024-10-21T12:15:12.575103526Z,10,2,38,A,B,1,233.87,400,130,166290,12476419,233.97,234.1,5,200,1,1,233.87,234.13,400,400,1,1,233.7,234.15,1200,26,1,1,233.66,234.17,1,1,1,1,233.58,234.41,505,600,2,2,233.53,234.43,10,105,1,2,233.5,234.5,100,63,1,4,233.45,234.75,15,1,1,1,233.4,234.79,110,2000,2,1,233.39,234.89,10,2,1,2,AAPL,0.0,0.0,400.0,1200.0,1.0,505.0,10.0,100.0,15.0,110.0,10.0,228.88353742668383,
2024-10-21T12:15:12.619539368Z,2024-10-21T12:15:12.619373396Z,10,2,38,C,A,0,234.1,200,130,165972,12476439,233.97,234.13,5,400,1,1,233.87,234.15,400,26,1,1,233.7,234.17,1200,1,1,1,233.66,234.41,1,600,1,2,233.58,234.43,505,105,2,2,233.53,234.5,10,63,1,4,233.5,234.75,100,1,1,1,233.45,234.79,15,2000,1,1,233.4,234.89,110,2,2,2,233.39,235.0,10,213,1,6,AAPL,400.0,400.0,26.0,1.0,600.0,105.0,63.0,1.0,2000.0,2.0,213.0,372.2570846395047,
2024-10-21T12:15:12.619552121Z,2024-10-21T12:15:12.619385902Z,10,2,38,A,A,1,234.15,200,130,166219,12476440,233.97,234.13,5,400,1,1,233.87,234.15,400,226,1,2,233.7,234.17,1200,1,1,1,233.66,234.41,1,600,1,2,233.58,234.43,505,105,2,2,233.53,234.5,10,63,1,4,233.5,234.75,100,1,1,1,233.45,234.79,15,2000,1,1,233.4,234.89,110,2,2,2,233.39,235.0,10,213,1,6,AAPL,0.0,0.0,-200.0,0.0,0.0,0.0,0.0,0.0,0.0,0.0,0.0,-12.683232565773917,
2024-10-21T12:15:12.656104126Z,2024-10-21T12:15:12.655937741Z,10,2,38,C,A,1,234.15,26,130,166385,12476454,233.97,234.13,5,400,1,1,233.87,234.15,400,200,1,1,233.7,234.17,1200,1,1,1,233.66,234.41,1,600,1,2,233.58,234.43,505,105,2,2,233.53,234.5,10,63,1,4,233.5,234.75,100,1,1,1,233.45,234.79,15,2000,1,1,233.4,234.89,110,2,2,2,233.39,235.0,10,213,1,6,AAPL,0.0,0.0,26.0,0.0,0.0,0.0,0.0,0.0,0.0,0.0,0.0,1.6488202335506092,
2024-10-21T12:15:12.669851013Z,2024-10-21T12:15:12.669684284Z,10,2,38,A,B,1,233.9,200,130,166729,12476460,233.97,234.13,5,400,1,1,233.9,234.15,200,200,1,1,233.7,234.17,1200,1,1,1,233.66,234.41,1,600,1,2,233.58,234.43,505,105,2,2,233.53,234.5,10,63,1,4,233.5,234.75,100,1,1,1,233.45,234.79,15,2000,1,1,233.4,234.89,110,2,2,2,233.39,235.0,10,213,1,6,AAPL,0.0,0.0,200.0,0.0,0.0,0.0,0.0,0.0,0.0,0.0,0.0,12.683232565773917,
2024-10-21T12:15:13.051742504Z,2024-10-21T12:15:13.051576352Z,10,2,38,A,A,3,234.22,30,130,166152,12476843,233.97,234.13,5,400,1,1,233.9,234.15,200,200,1,1,233.7,234.17,1200,1,1,1,233.66,234.22,1,30,1,1,233.58,234.41,505,600,2,2,233.53,234.43,10,105,1,2,233.5,234.5,100,63,1,4,233.45,234.75,15,1,1,1,233.4,234.79,110,2000,2,1,233.39,234.89,10,2,1,2,AAPL,0.0,0.0,0.0,0.0,-600.0,-105.0,-63.0,-1.0,-2000.0,-2.0,-213.0,-362.5544487667681,
2024-10-21T12:15:13.051772118Z,2024-10-21T12:15:13.051605161Z,10,2,38,A,B,2,233.85,27,130,166957,12476844,233.97,234.13,5,400,1,1,233.9,234.15,200,200,1,1,233.85,234.17,27,1,1,1,233.7,234.22,1200,30,1,1,233.66,234.41,1,600,1,2,233.58,234.43,505,105,2,2,233.53,234.5,10,63,1,4,233.5,234.75,100,1,1,1,233.45,234.79,15,2000,1,1,233.4,234.89,110,2,2,2,AAPL,0.0,0.0,0.0,27.0,1200.0,1.0,505.0,10.0,100.0,15.0,110.0,338.64024362471434,
2024-10-21T12:15:13.946134251Z,2024-10-21T12:15:13.945967888Z,10,2,38,A,A,1,234.15,200,130,166363,12477920,233.97,234.13,5,400,1,1,233.9,234.15,200,400,1,2,233.85,234.17,27,1,1,1,233.7,234.22,1200,30,1,1,233.66,234.41,1,600,1,2,233.58,234.43,505,105,2,2,233.53,234.5,10,63,1,4,233.5,234.75,100,1,1,1,233.45,234.79,15,2000,1,1,233.4,234.89,110,2,2,2,AAPL,0.0,0.0,-200.0,0.0,0.0,0.0,0.0,0.0,0.0,0.0,0.0,-12.683232565773917,
2024-10-21T12:15:13.946655760Z,2024-10-21T12:15:13.946489728Z,10,2,38,C,A,3,234.22,30,130,166032,12477923,233.97,234.13,5,400,1,1,233.9,234.15,200,400,1,2,233.85,234.17,27,1,1,1,233.7,234.41,1200,600,1,2,233.66,234.43,1,105,1,2,233.58,234.5,505,63,2,4,233.53,234.75,10,1,1,1,233.5,234.79,100,2000,1,1,233.45,234.89,15,2,1,2,233.4,235.0,110,213,2,6,AAPL,0.0,0.0,0.0,0.0,600.0,105.0,63.0,1.0,2000.0,2.0,213.0,362.5544487667681,
2024-10-21T12:15:13.946698478Z,2024-10-21T12:15:13.946532120Z,10,2,38,A,A,2,234.17,27,130,166358,12477924,233.97,234.13,5,400,1,1,233.9,234.15,200,400,1,2,233.85,234.17,27,28,1,2,233.7,234.41,1200,600,1,2,233.66,234.43,1,105,1,2,233.58,234.5,505,63,2,4,233.53,234.75,10,1,1,1,233.5,234.79,100,2000,1,1,233.45,234.89,15,2,1,2,233.4,235.0,110,213,2,6,AAPL,0.0,0.0,0.0,-27.0,0.0,0.0,0.0,0.0,0.0,0.0,0.0,-2.74272967987214,
2024-10-21T12:15:14.001175416Z,2024-10-21T12:15:14.001009338Z,10,2,38,C,A,1,234.15,200,130,166078,12478031,233.97,234.13,5,400,1,1,233.9,234.15,200,200,1,1,233.85,234.17,27,28,1,2,233.7,234.41,1200,600,1,2,233.66,234.43,1,105,1,2,233.58,234.5,505,63,2,4,233.53,234.75,10,1,1,1,233.5,234.79,100,2000,1,1,233.45,234.89,15,2,1,2,233.4,235.0,110,213,2,6,AAPL,0.0,0.0,200.0,0.0,0.0,0.0,0.0,0.0,0.0,0.0,0.0,12.683232565773917,
2024-10-21T12:15:14.001188780Z,2024-10-21T12:15:14.001022189Z,10,2,38,A,A,0,234.1,400,130,166591,12478032,233.97,234.1,5,400,1,1,233.9,234.13,200,400,1,1,233.85,234.17,27,28,1,2,233.7,234.41,1200,600,1,2,233.66,234.43,1,105,1,2,233.58,234.5,505,63,2,4,233.53,234.75,10,1,1,1,233.5,234.79,100,2000,1,1,233.45,234.89,15,2,1,2,233.4,235.0,110,213,2,6,AAPL,-400.0,-400.0,-200.0,0.0,0.0,0.0,0.0,0.0,0.0,0.0,0.0,-20.635465624223926,
2024-10-21T12:15:14.207349948Z,2024-10-21T12:15:14.207183672Z,10,2,38,A,B,1,233.9,100,130,166276,12478133,233.97,234.1,5,400,1,1,233.9,234.13,300,400,2,1,233.85,234.17,27,28,1,2,233.7,234.41,1200,600,1,2,233.66,234.43,1,105,1,2,233.58,234.5,505,63,2,4,233.53,234.75,10,1,1,1,233.5,234.79,100,2000,1,1,233.45,234.89,15,2,1,2,233.4,235.0,110,213,2,6,AAPL,0.0,0.0,100.0,0.0,0.0,0.0,0.0,0.0,0.0,0.0,0.0,6.3416162828869584,
2024-10-21T12:15:14.207645338Z,2024-10-21T12:15:14.207479344Z,10,2,38,C,B,1,233.9,100,130,165994,12478134,233.97,234.1,5,400,1,1,233.9,234.13,200,400,1,1,233.85,234.17,27,28,1,2,233.7,234.41,1200,600,1,2,233.66,234.43,1,105,1,2,233.58,234.5,505,63,2,4,233.53,234.75,10,1,1,1,233.5,234.79,100,2000,1,1,233.45,234.89,15,2,1,2,233.4,235.0,110,213,2,6,AAPL,0.0,0.0,-100.0,0.0,0.0,0.0,0.0,0.0,0.0,0.0,0.0,-6.3416162828869584,
2024-10-21T12:15:14.278543569Z,2024-10-21T12:15:14.278377067Z,10,2,38,C,A,0,234.1,200,130,166502,12478168,233.97,234.1,5,200,1,1,233.9,234.13,200,400,1,1,233.85,234.17,27,28,1,2,233.7,234.41,1200,600,1,2,233.66,234.43,1,105,1,2,233.58,234.5,505,63,2,4,233.53,234.75,10,1,1,1,233.5,234.79,100,2000,1,1,233.45,234.89,15,2,1,2,233.4,235.0,110,213,2,6,AAPL,200.0,200.0,0.0,0.0,0.0,0.0,0.0,0.0,0.0,0.0,0.0,3.9761165292250036,
2024-10-21T12:15:14.278726070Z,2024-10-21T12:15:14.278559734Z,10,2,38,C,A,0,234.1,200,130,166336,12478169,233.97,234.13,5,400,1,1,233.9,234.17,200,28,1,2,233.85,234.41,27,600,1,2,233.7,234.43,1200,105,1,2,233.66,234.5,1,63,1,4,233.58,234.75,505,1,2,1,233.53,234.79,10,2000,1,1,233.5,234.89,100,2,1,2,233.45,235.0,15,213,1,6,233.4,235.03,110,2,2,1,AAPL,400.0,400.0,28.0,600.0,105.0,63.0,1.0,2000.0,2.0,213.0,2.0,342.7991342576269,
2024-10-21T12:15:14.278738674Z,2024-10-21T12:15:14.278572418Z,10,2,38,A,A,1,234.16,200,130,166256,12478170,233.97,234.13,5,400,1,1,233.9,234.16,200,200,1,1,233.85,234.17,27,28,1,2,233.7,234.41,1200,600,1,2,233.66,234.43,1,105,1,2,233.58,234.5,505,63,2,4,233.53,234.75,10,1,1,1,233.5,234.79,100,2000,1,1,233.45,234.89,15,2,1,2,233.4,235.0,110,213,2,6,AAPL,0.0,0.0,-28.0,-600.0,-105.0,-63.0,-1.0,-2000.0,-2.0,-213.0,-2.0,-334.8469011991769,
2024-10-21T12:15:14.279136295Z,2024-10-21T12:15:14.278970387Z,10,2,38,C,A,2,234.17,27,130,165908,12478171,233.97,234.13,5,400,1,1,233.9,234.16,200,200,1,1,233.85,234.17,27,1,1,1,233.7,234.41,1200,600,1,2,233.66,234.43,1,105,1,2,233.58,234.5,505,63,2,4,233.53,234.75,10,1,1,1,233.5,234.79,100,2000,1,1,233.45,234.89,15,2,1,2,233.4,235.0,110,213,2,6,AAPL,0.0,0.0,0.0,27.0,0.0,0.0,0.0,0.0,0.0,0.0,0.0,2.74272967987214,
2024-10-21T12:15:14.280757598Z,2024-10-21T12:15:14.280591359Z,10,2,38,A,A,1,234.16,200,130,166239,12478172,233.97,234.13,5,400,1,1,233.9,234.16,200,400,1,2,233.85,234.17,27,1,1,1,233.7,234.41,1200,600,1,2,233.66,234.43,1,105,1,2,233.58,234.5,505,63,2,4,233.53,234.75,10,1,1,1,233.5,234.79,100,2000,1,1,233.45,234.89,15,2,1,2,233.4,235.0,110,213,2,6,AAPL,0.0,0.0,-200.0,0.0,0.0,0.0,0.0,0.0,0.0,0.0,0.0,-12.683232565773917,
2024-10-21T12:15:15.249067573Z,2024-10-21T12:15:15.248901194Z,10,2,38,C,A,1,234.16,200,130,166379,12479022,233.97,234.13,5,400,1,1,233.9,234.16,200,200,1,1,233.85,234.17,27,1,1,1,233.7,234.41,1200,600,1,2,233.66,234.43,1,105,1,2,233.58,234.5,505,63,2,4,233.53,234.75,10,1,1,1,233.5,234.79,100,2000,1,1,233.45,234.89,15,2,1,2,233.4,235.0,110,213,2,6,AAPL,0.0,0.0,200.0,0.0,0.0,0.0,0.0,0.0,0.0,0.0,0.0,12.683232565773917,
2024-10-21T12:15:15.249079309Z,2024-10-21T12:15:15.248912868Z,10,2,38,A,A,1,234.15,400,130,166441,12479023,233.97,234.13,5,400,1,1,233.9,234.15,200,400,1,1,233.85,234.17,27,1,1,1,233.7,234.41,1200,600,1,2,233.66,234.43,1,105,1,2,233.58,234.5,505,63,2,4,233.53,234.75,10,1,1,1,233.5,234.79,100,2000,1,1,233.45,234.89,15,2,1,2,233.4,235.0,110,213,2,6,AAPL,0.0,0.0,-200.0,0.0,0.0,0.0,0.0,0.0,0.0,0.0,0.0,-12.683232565773917,
2024-10-21T12:15:17.923200888Z,2024-10-21T12:15:17.923034484Z,10,2,38,A,A,3,234.22,27,130,166404,12482317,233.97,234.13,5,400,1,1,233.9,234.15,200,400,1,1,233.85,234.17,27,1,1,1,233.7,234.22,1200,27,1,1,233.66,234.41,1,600,1,2,233.58,234.43,505,105,2,2,233.53,234.5,10,63,1,4,233.5,234.75,100,1,1,1,233.45,234.79,15,2000,1,1,233.4,234.89,110,2,2,2,AAPL,0.0,0.0,0.0,0.0,-600.0,-105.0,-63.0,-1.0,-2000.0,-2.0,-213.0,-362.5544487667681,
2024-10-21T12:15:24.014356772Z,2024-10-21T12:15:24.014190176Z,10,2,38,C,B,1,233.9,200,130,166596,12489125,233.97,234.13,5,400,1,1,233.85,234.15,27,400,1,1,233.7,234.17,1200,1,1,1,233.66,234.22,1,27,1,1,233.58,234.41,505,600,2,2,233.53,234.43,10,105,1,2,233.5,234.5,100,63,1,4,233.45,234.75,15,1,1,1,233.4,234.79,110,2000,2,1,233.39,234.89,10,2,1,2,AAPL,0.0,0.0,-200.0,-27.0,-1200.0,-1.0,-505.0,-10.0,-100.0,-15.0,-110.0,-351.3234761904883,
2024-10-21T12:15:24.014368498Z,2024-10-21T12:15:24.014202142Z,10,2,38,A,B,1,233.87,400,130,166356,12489126,233.97,234.13,5,400,1,1,233.87,234.15,400,400,1,1,233.85,234.17,27,1,1,1,233.7,234.22,1200,27,1,1,233.66,234.41,1,600,1,2,233.58,234.43,505,105,2,2,233.53,234.5,10,63,1,4,233.5,234.75,100,1,1,1,233.45,234.79,15,2000,1,1,233.4,234.89,110,2,2,2,AAPL,0.0,0.0,400.0,27.0,1200.0,1.0,505.0,10.0,100.0,15.0,110.0,364.0067087562622,
2024-10-21T12:15:24.015016662Z,2024-10-21T12:15:24.014850794Z,10,2,38,C,B,2,233.85,27,130,165868,12489129,233.97,234.13,5,400,1,1,233.87,234.15,400,400,1,1,233.7,234.17,1200,1,1,1,233.66,234.22,1,27,1,1,233.58,234.41,505,600,2,2,233.53,234.43,10,105,1,2,233.5,234.5,100,63,1,4,233.45,234.75,15,1,1,1,233.4,234.79,110,2000,2,1,233.39,234.89,10,2,1,2,AAPL,0.0,0.0,0.0,-27.0,-1200.0,-1.0,-505.0,-10.0,-100.0,-15.0,-110.0,-338.64024362471434,
2024-10-21T12:15:24.015063463Z,2024-10-21T12:15:24.014897264Z,10,2,38,A,B,2,233.79,29,130,166199,12489130,233.97,234.13,5,400,1,1,233.87,234.15,400,400,1,1,233.79,234.17,29,1,1,1,233.7,234.22,1200,27,1,1,233.66,234.41,1,600,1,2,233.58,234.43,505,105,2,2,233.53,234.5,10,63,1,4,233.5,234.75,100,1,1,1,233.45,234.79,15,2000,1,1,233.4,234.89,110,2,2,2,AAPL,0.0,0.0,0.0,29.0,1200.0,1.0,505.0,10.0,100.0,15.0,110.0,338.84340878618633,
2024-10-21T12:15:24.015171797Z,2024-10-21T12:15:24.015005588Z,10,2,38,C,A,3,234.22,27,130,166209,12489131,233.97,234.13,5,400,1,1,233.87,234.15,400,400,1,1,233.79,234.17,29,1,1,1,233.7,234.41,1200,600,1,2,233.66,234.43,1,105,1,2,233.58,234.5,505,63,2,4,233.53,234.75,10,1,1,1,233.5,234.79,100,2000,1,1,233.45,234.89,15,2,1,2,233.4,235.0,110,213,2,6,AAPL,0.0,0.0,0.0,0.0,600.0,105.0,63.0,1.0,2000.0,2.0,213.0,362.5544487667681,
2024-10-21T12:15:24.015226111Z,2024-10-21T12:15:24.015059897Z,10,2,38,A,A,2,234.17,30,130,166214,12489132,233.97,234.13,5,400,1,1,233.87,234.15,400,400,1,1,233.79,234.17,29,31,1,2,233.7,234.41,1200,600,1,2,233.66,234.43,1,105,1,2,233.58,234.5,505,63,2,4,233.53,234.75,10,1,1,1,233.5,234.79,100,2000,1,1,233.45,234.89,15,2,1,2,233.4,235.0,110,213,2,6,AAPL,0.0,0.0,0.0,-30.0,0.0,0.0,0.0,0.0,0.0,0.0,0.0,-3.047477422080156,
2024-10-21T12:15:24.066676377Z,2024-10-21T12:15:24.066509814Z,10,2,38,A,A,0,234.1,200,130,166563,12489179,233.97,234.1,5,200,1,1,233.87,234.13,400,400,1,1,233.79,234.17,29,31,1,2,233.7,234.41,1200,600,1,2,233.66,234.43,1,105,1,2,233.58,234.5,505,63,2,4,233.53,234.75,10,1,1,1,233.5,234.79,100,2000,1,1,233.45,234.89,15,2,1,2,233.4,235.0,110,213,2,6,AAPL,-400.0,-400.0,-400.0,0.0,0.0,0.0,0.0,0.0,0.0,0.0,0.0,-33.31869818999784,
2024-10-21T12:15:27.519404999Z,2024-10-21T12:15:27.519238798Z,10,2,38,C,B,1,233.87,400,130,166201,12491655,233.97,234.1,5,200,1,1,233.79,234.13,29,400,1,1,233.7,234.17,1200,31,1,2,233.66,234.41,1,600,1,2,233.58,234.43,505,105,2,2,233.53,234.5,10,63,1,4,233.5,234.75,100,1,1,1,233.45,234.79,15,2000,1,1,233.4,234.89,110,2,2,2,233.39,235.0,10,213,1,6,AAPL,0.0,0.0,-400.0,-29.0,-1200.0,-1.0,-505.0,-10.0,-100.0,-15.0,-110.0,-364.20987391773417,
2024-10-21T12:15:27.519418174Z,2024-10-21T12:15:27.519251700Z,10,2,38,A,B,1,233.84,200,130,166474,12491656,233.97,234.1,5,200,1,1,233.84,234.13,200,400,1,1,233.79,234.17,29,31,1,2,233.7,234.41,1200,600,1,2,233.66,234.43,1,105,1,2,233.58,234.5,505,63,2,4,233.53,234.75,10,1,1,1,233.5,234.79,100,2000,1,1,233.45,234.89,15,2,1,2,233.4,235.0,110,213,2,6,AAPL,0.0,0.0,200.0,29.0,1200.0,1.0,505.0,10.0,100.0,15.0,110.0,351.5266413519603,
2024-10-21T12:15:29.175384059Z,2024-10-21T12:15:29.175215826Z,10,2,38,A,N,0,233.95,295,130,168233,12493181,233.84,233.95,200,295,1,1,233.79,234.1,29,200,1,1,233.7,234.13,1200,400,1,1,233.66,234.17,1,31,1,2,233.58,234.41,505,600,2,2,233.53,234.43,10,105,1,2,233.5,234.5,100,63,1,4,233.45,234.75,15,1,1,1,233.4,234.79,110,2000,2,1,233.39,234.89,10,2,1,2,AAPL,-205.0,-205.0,-600.0,-60.0,-1800.0,-106.0,-568.0,-11.0,-2100.0,-17.0,-323.0,-746.6721346955479,
2024-10-21T12:15:29.175384059Z,2024-10-21T12:15:29.175215826Z,10,2,38,T,A,0,233.97,5,0,168233,12493180,233.97,234.1,5,200,1,1,233.84,234.13,200,400,1,1,233.79,234.17,29,31,1,2,233.7,234.41,1200,600,1,2,233.66,234.43,1,105,1,2,233.58,234.5,505,63,2,4,233.53,234.75,10,1,1,1,233.5,234.79,100,2000,1,1,233.45,234.89,15,2,1,2,233.4,235.0,110,213,2,6,AAPL,205.0,205.0,600.0,60.0,1800.0,106.0,568.0,11.0,2100.0,17.0,323.0,746.6721346955479,
2024-10-21T12:15:29.175406869Z,2024-10-21T12:15:29.175239385Z,10,2,38,A,A,1,234.07,100,130,167484,12493182,233.84,233.95,200,295,1,1,233.79,234.07,29,100,1,1,233.7,234.1,1200,200,1,1,233.66,234.13,1,400,1,1,233.58,234.17,505,31,2,2,233.53,234.41,10,600,1,2,233.5,234.43,100,105,1,2,233.45,234.5,15,63,1,4,233.4,234.75,110,1,2,1,233.39,234.79,10,2000,1,1,AAPL,-205.0,-205.0,-600.0,-60.0,-1800.0,-106.0,-568.0,-11.0,-2100.0,-17.0,-323.0,-746.6721346955479,
2024-10-21T12:15:29.175410757Z,2024-10-21T12:15:29.175244705Z,10,2,38,A,A,1,234.04,38,130,166052,12493183,233.84,233.95,200,295,1,1,233.79,234.04,29,38,1,1,233.7,234.07,1200,100,1,1,233.66,234.1,1,200,1,1,233.58,234.13,505,400,2,1,233.53,234.17,10,31,1,2,233.5,234.41,100,600,1,2,233.45,234.43,15,105,1,2,233.4,234.5,110,63,2,4,233.39,234.75,10,1,1,1,AAPL,0.0,0.0,-100.0,-200.0,-400.0,-31.0,-600.0,-105.0,-63.0,-1.0,-2000.0,-355.39789225495633,
2024-10-21T12:15:29.175418381Z,2024-10-21T12:15:29.175252395Z,10,2,38,A,A,2,234.07,100,130,165986,12493184,233.84,233.95,200,295,1,1,233.79,234.04,29,38,1,1,233.7,234.07,1200,200,1,2,233.66,234.1,1,200,1,1,233.58,234.13,505,400,2,1,233.53,234.17,10,31,1,2,233.5,234.41,100,600,1,2,233.45,234.43,15,105,1,2,233.4,234.5,110,63,2,4,233.39,234.75,10,1,1,1,AAPL,0.0,0.0,0.0,-100.0,0.0,0.0,0.0,0.0,0.0,0.0,0.0,-10.15825807360052,
2024-10-21T12:15:29.175428571Z,2024-10-21T12:15:29.175261243Z,10,2,38,T,B,0,233.95,187,130,167328,12493185,233.84,233.95,200,295,1,1,233.79,234.04,29,38,1,1,233.7,234.07,1200,200,1,2,233.66,234.1,1,200,1,1,233.58,234.13,505,400,2,1,233.53,234.17,10,31,1,2,233.5,234.41,100,600,1,2,233.45,234.43,15,105,1,2,233.4,234.5,110,63,2,4,233.39,234.75,10,1,1,1,AAPL,0.0,0.0,0.0,0.0,0.0,0.0,0.0,0.0,0.0,0.0,0.0,0.0,
2024-10-21T12:15:29.175428571Z,2024-10-21T12:15:29.175261243Z,10,2,38,C,A,0,233.95,187,130,167328,12493185,233.84,233.95,200,108,1,1,233.79,234.04,29,38,1,1,233.7,234.07,1200,200,1,2,233.66,234.1,1,200,1,1,233.58,234.13,505,400,2,1,233.53,234.17,10,31,1,2,233.5,234.41,100,600,1,2,233.45,234.43,15,105,1,2,233.4,234.5,110,63,2,4,233.39,234.75,10,1,1,1,AAPL,187.0,187.0,0.0,0.0,0.0,0.0,0.0,0.0,0.0,0.0,0.0,3.7176689548253785,
2024-10-21T12:15:29.175431546Z,2024-10-21T12:15:29.175265540Z,10,2,38,A,A,1,234.04,38,130,166006,12493186,233.84,233.95,200,108,1,1,233.79,234.04,29,76,1,2,233.7,234.07,1200,200,1,2,233.66,234.1,1,200,1,1,233.58,234.13,505,400,2,1,233.53,234.17,10,31,1,2,233.5,234.41,100,600,1,2,233.45,234.43,15,105,1,2,233.4,234.5,110,63,2,4,233.39,234.75,10,1,1,1,AAPL,0.0,0.0,-38.0,0.0,0.0,0.0,0.0,0.0,0.0,0.0,0.0,-2.409814187497044,
2024-10-21T12:15:29.175437237Z,2024-10-21T12:15:29.175269965Z,10,2,38,T,B,0,233.95,108,130,167272,12493187,233.84,233.95,200,108,1,1,233.79,234.04,29,76,1,2,233.7,234.07,1200,200,1,2,233.66,234.1,1,200,1,1,233.58,234.13,505,400,2,1,233.53,234.17,10,31,1,2,233.5,234.41,100,600,1,2,233.45,234.43,15,105,1,2,233.4,234.5,110,63,2,4,233.39,234.75,10,1,1,1,AAPL,0.0,0.0,0.0,0.0,0.0,0.0,0.0,0.0,0.0,0.0,0.0,0.0,
2024-10-21T12:15:29.175437237Z,2024-10-21T12:15:29.175269965Z,10,2,38,C,A,0,233.95,108,130,167272,12493187,233.84,234.04,200,76,1,2,233.79,234.07,29,200,1,2,233.7,234.1,1200,200,1,1,233.66,234.13,1,400,1,1,233.58,234.17,505,31,2,2,233.53,234.41,10,600,1,2,233.5,234.43,100,105,1,2,233.45,234.5,15,63,1,4,233.4,234.75,110,1,2,1,233.39,234.79,10,2000,1,1,AAPL,76.0,76.0,200.0,200.0,400.0,31.0,600.0,105.0,63.0,1.0,2000.0,363.25043281894887,
2024-10-21T12:15:29.175453602Z,2024-10-21T12:15:29.175287761Z,10,2,38,C,A,1,234.07,100,130,165841,12493188,233.84,234.04,200,76,1,2,233.79,234.07,29,100,1,1,233.7,234.1,1200,200,1,1,233.66,234.13,1,400,1,1,233.58,234.17,505,31,2,2,233.53,234.41,10,600,1,2,233.5,234.43,100,105,1,2,233.45,234.5,15,63,1,4,233.4,234.75,110,1,2,1,233.39,234.79,10,2000,1,1,AAPL,0.0,0.0,100.0,0.0,0.0,0.0,0.0,0.0,0.0,0.0,0.0,6.3416162828869584,
2024-10-21T12:15:29.175459603Z,2024-10-21T12:15:29.175293157Z,10,2,38,C,A,0,234.04,38,130,166446,12493190,233.84,234.04,200,38,1,1,233.79,234.07,29,100,1,1,233.7,234.1,1200,200,1,1,233.66,234.13,1,400,1,1,233.58,234.17,505,31,2,2,233.53,234.41,10,600,1,2,233.5,234.43,100,105,1,2,233.45,234.5,15,63,1,4,233.4,234.75,110,1,2,1,233.39,234.79,10,2000,1,1,AAPL,38.0,38.0,0.0,0.0,0.0,0.0,0.0,0.0,0.0,0.0,0.0,0.7554621405527507,
2024-10-21T12:15:29.175464536Z,2024-10-21T12:15:29.175298862Z,10,2,38,C,A,1,234.07,100,130,165674,12493191,233.84,234.04,200,38,1,1,233.79,234.1,29,200,1,1,233.7,234.13,1200,400,1,1,233.66,234.17,1,31,1,2,233.58,234.41,505,600,2,2,233.53,234.43,10,105,1,2,233.5,234.5,100,63,1,4,233.45,234.75,15,1,1,1,233.4,234.79,110,2000,2,1,233.39,234.89,10,2,1,2,AAPL,0.0,0.0,200.0,400.0,31.0,600.0,105.0,63.0,1.0,2000.0,2.0,290.0323945327825,
2024-10-21T12:15:29.175475521Z,2024-10-21T12:15:29.175307953Z,10,2,38,A,A,1,234.08,38,130,167568,12493192,233.84,234.04,200,38,1,1,233.79,234.08,29,38,1,1,233.7,234.1,1200,200,1,1,233.66,234.13,1,400,1,1,233.58,234.17,505,31,2,2,233.53,234.41,10,600,1,2,233.5,234.43,100,105,1,2,233.45,234.5,15,63,1,4,233.4,234.75,110,1,2,1,233.39,234.79,10,2000,1,1,AAPL,0.0,0.0,-200.0,-400.0,-31.0,-600.0,-105.0,-63.0,-1.0,-2000.0,-2.0,-290.0323945327825,
2024-10-21T12:15:29.175484200Z,2024-10-21T12:15:29.175318339Z,10,2,38,C,A,2,234.1,200,130,165861,12493193,233.84,234.04,200,38,1,1,233.79,234.08,29,38,1,1,233.7,234.13,1200,400,1,1,233.66,234.17,1,31,1,2,233.58,234.41,505,600,2,2,233.53,234.43,10,105,1,2,233.5,234.5,100,63,1,4,233.45,234.75,15,1,1,1,233.4,234.79,110,2000,2,1,233.39,234.89,10,2,1,2,AAPL,0.0,0.0,0.0,400.0,31.0,600.0,105.0,63.0,1.0,2000.0,2.0,277.3491619670086,
2024-10-21T12:15:29.175542211Z,2024-10-21T12:15:29.175376083Z,10,2,38,A,B,0,233.89,38,130,166128,12493194,233.89,234.04,38,38,1,1,233.84,234.08,200,38,1,1,233.79,234.13,29,400,1,1,233.7,234.17,1200,31,1,2,233.66,234.41,1,600,1,2,233.58,234.43,505,105,2,2,233.53,234.5,10,63,1,4,233.5,234.75,100,1,1,1,233.45,234.79,15,2000,1,1,233.4,234.89,110,2,2,2,AAPL,38.0,38.0,200.0,29.0,1200.0,1.0,505.0,10.0,100.0,15.0,110.0,352.28210349251304,
2024-10-21T12:15:29.175555082Z,2024-10-21T12:15:29.175388906Z,10,2,38,A,B,1,233.86,38,130,166176,12493195,233.89,234.04,38,38,1,1,233.86,234.08,38,38,1,1,233.84,234.13,200,400,1,1,233.79,234.17,29,31,1,2,233.7,234.41,1200,600,1,2,233.66,234.43,1,105,1,2,233.58,234.5,505,63,2,4,233.53,234.75,10,1,1,1,233.5,234.79,100,2000,1,1,233.45,234.89,15,2,1,2,AAPL,0.0,0.0,38.0,200.0,29.0,1200.0,1.0,505.0,10.0,100.0,15.0,235.0620656052437,
2024-10-21T12:15:29.246556838Z,2024-10-21T12:15:29.246390784Z,10,2,38,C,B,2,233.84,200,130,166054,12493277,233.89,234.04,38,38,1,1,233.86,234.08,38,38,1,1,233.79,234.13,29,400,1,1,233.7,234.17,1200,31,1,2,233.66,234.41,1,600,1,2,233.58,234.43,505,105,2,2,233.53,234.5,10,63,1,4,233.5,234.75,100,1,1,1,233.45,234.79,15,2000,1,1,233.4,234.89,110,2,2,2,AAPL,0.0,0.0,0.0,-200.0,-29.0,-1200.0,-1.0,-505.0,-10.0,-100.0,-15.0,-232.65225141774664,
2024-10-21T12:15:29.246589766Z,2024-10-21T12:15:29.246423576Z,10,2,38,A,B,3,233.76,400,130,166190,12493278,233.89,234.04,38,38,1,1,233.86,234.08,38,38,1,1,233.79,234.13,29,400,1,1,233.76,234.17,400,31,1,2,233.7,234.41,1200,600,1,2,233.66,234.43,1,105,1,2,233.58,234.5,505,63,2,4,233.53,234.75,10,1,1,1,233.5,234.79,100,2000,1,1,233.45,234.89,15,2,1,2,AAPL,0.0,0.0,0.0,0.0,400.0,1200.0,1.0,505.0,10.0,100.0,15.0,288.4193226844936,
2024-10-21T12:15:29.246983004Z,2024-10-21T12:15:29.246816914Z,10,2,38,C,B,2,233.79,29,130,166090,12493279,233.89,234.04,38,38,1,1,233.86,234.08,38,38,1,1,233.76,234.13,400,400,1,1,233.7,234.17,1200,31,1,2,233.66,234.41,1,600,1,2,233.58,234.43,505,105,2,2,233.53,234.5,10,63,1,4,233.5,234.75,100,1,1,1,233.45,234.79,15,2000,1,1,233.4,234.89,110,2,2,2,AAPL,0.0,0.0,0.0,-29.0,-400.0,-1200.0,-1.0,-505.0,-10.0,-100.0,-15.0,-291.36521752583775,
2024-10-21T12:15:29.247077109Z,2024-10-21T12:15:29.246910849Z,10,2,38,A,B,3,233.74,28,130,166260,12493280,233.89,234.04,38,38,1,1,233.86,234.08,38,38,1,1,233.76,234.13,400,400,1,1,233.74,234.17,28,31,1,2,233.7,234.41,1200,600,1,2,233.66,234.43,1,105,1,2,233.58,234.5,505,63,2,4,233.53,234.75,10,1,1,1,233.5,234.79,100,2000,1,1,233.45,234.89,15,2,1,2,AAPL,0.0,0.0,0.0,0.0,28.0,1200.0,1.0,505.0,10.0,100.0,15.0,212.1306582155215,
2024-10-21T12:15:29.283930892Z,2024-10-21T12:15:29.283764753Z,10,2,38,C,A,1,234.08,38,130,166139,12493295,233.89,234.04,38,38,1,1,233.86,234.13,38,400,1,1,233.76,234.17,400,31,1,2,233.74,234.41,28,600,1,2,233.7,234.43,1200,105,1,2,233.66,234.5,1,63,1,4,233.58,234.75,505,1,2,1,233.53,234.79,10,2000,1,1,233.5,234.89,100,2,1,2,233.45,235.0,15,213,1,6,AAPL,0.0,0.0,400.0,31.0,600.0,105.0,63.0,1.0,2000.0,2.0,213.0,391.0699739011321,
2024-10-21T12:15:29.283941482Z,2024-10-21T12:15:29.283775550Z,10,2,38,C,B,1,233.86,38,130,165932,12493296,233.89,234.04,38,38,1,1,233.76,234.13,400,400,1,1,233.74,234.17,28,31,1,2,233.7,234.41,1200,600,1,2,233.66,234.43,1,105,1,2,233.58,234.5,505,63,2,4,233.53,234.75,10,1,1,1,233.5,234.79,100,2000,1,1,233.45,234.89,15,2,1,2,233.4,235.0,110,213,2,6,AAPL,0.0,0.0,-38.0,-400.0,-28.0,-1200.0,-1.0,-505.0,-10.0,-100.0,-15.0,-255.1735046974206,
2024-10-21T12:15:29.283989568Z,2024-10-21T12:15:29.283823523Z,10,2,38,A,A,1,234.1,400,130,166045,12493297,233.89,234.04,38,38,1,1,233.76,234.1,400,400,1,1,233.74,234.13,28,400,1,1,233.7,234.17,1200,31,1,2,233.66,234.41,1,600,1,2,233.58,234.43,505,105,2,2,233.53,234.5,10,63,1,4,233.5,234.75,100,1,1,1,233.45,234.79,15,2000,1,1,233.4,234.89,110,2,2,2,AAPL,0.0,0.0,-400.0,-31.0,-600.0,-105.0,-63.0,-1.0,-2000.0,-2.0,-213.0,-391.0699739011321,
2024-10-21T12:15:29.425498174Z,2024-10-21T12:15:29.425332139Z,10,2,38,C,A,0,234.04,38,130,166035,12493515,233.89,234.1,38,400,1,1,233.76,234.13,400,400,1,1,233.74,234.17,28,31,1,2,233.7,234.41,1200,600,1,2,233.66,234.43,1,105,1,2,233.58,234.5,505,63,2,4,233.53,234.75,10,1,1,1,233.5,234.79,100,2000,1,1,233.45,234.89,15,2,1,2,233.4,235.0,110,213,2,6,AAPL,400.0,400.0,400.0,31.0,600.0,105.0,63.0,1.0,2000.0,2.0,213.0,399.02220695958204,
2024-10-21T12:15:29.425509152Z,2024-10-21T12:15:29.425342648Z,10,2,38,C,B,0,233.89,38,130,166504,12493516,233.76,234.1,400,400,1,1,233.74,234.13,28,400,1,1,233.7,234.17,1200,31,1,2,233.66,234.41,1,600,1,2,233.58,234.43,505,105,2,2,233.53,234.5,10,63,1,4,233.5,234.75,100,1,1,1,233.45,234.79,15,2000,1,1,233.4,234.89,110,2,2,2,233.39,235.0,10,213,1,6,AAPL,-38.0,-38.0,-400.0,-28.0,-1200.0,-1.0,-505.0,-10.0,-100.0,-15.0,-110.0,-364.863753477551,
2024-10-21T12:15:29.496660616Z,2024-10-21T12:15:29.496494580Z,10,2,38,C,B,0,233.76,200,130,166036,12493549,233.76,234.1,200,400,1,1,233.74,234.13,28,400,1,1,233.7,234.17,1200,31,1,2,233.66,234.41,1,600,1,2,233.58,234.43,505,105,2,2,233.53,234.5,10,63,1,4,233.5,234.75,100,1,1,1,233.45,234.79,15,2000,1,1,233.4,234.89,110,2,2,2,233.39,235.0,10,213,1,6,AAPL,-200.0,-200.0,0.0,0.0,0.0,0.0,0.0,0.0,0.0,0.0,0.0,-3.9761165292250036,
2024-10-21T12:15:38.712982908Z,2024-10-21T12:15:38.712816410Z,10,2,38,C,A,0,234.1,200,130,166498,12503722,233.76,234.1,200,200,1,1,233.74,234.13,28,400,1,1,233.7,234.17,1200,31,1,2,233.66,234.41,1,600,1,2,233.58,234.43,505,105,2,2,233.53,234.5,10,63,1,4,233.5,234.75,100,1,1,1,233.45,234.79,15,2000,1,1,233.4,234.89,110,2,2,2,233.39,235.0,10,213,1,6,AAPL,200.0,200.0,0.0,0.0,0.0,0.0,0.0,0.0,0.0,0.0,0.0,3.9761165292250036,
2024-10-21T12:15:38.816780965Z,2024-10-21T12:15:38.816614723Z,10,2,38,A,A,0,234.1,200,130,166242,12504039,233.76,234.1,200,400,1,2,233.74,234.13,28,400,1,1,233.7,234.17,1200,31,1,2,233.66,234.41,1,600,1,2,233.58,234.43,505,105,2,2,233.53,234.5,10,63,1,4,233.5,234.75,100,1,1,1,233.45,234.79,15,2000,1,1,233.4,234.89,110,2,2,2,233.39,235.0,10,213,1,6,AAPL,-200.0,-200.0,0.0,0.0,0.0,0.0,0.0,0.0,0.0,0.0,0.0,-3.9761165292250036,
2024-10-21T12:15:39.207247997Z,2024-10-21T12:15:39.207080252Z,10,2,38,A,A,0,234.0,22,130,167745,12504453,233.76,234.0,200,22,1,1,233.74,234.1,28,400,1,2,233.7,234.13,1200,400,1,1,233.66,234.17,1,31,1,2,233.58,234.41,505,600,2,2,233.53,234.43,10,105,1,2,233.5,234.5,100,63,1,4,233.45,234.75,15,1,1,1,233.4,234.79,110,2000,2,1,233.39,234.89,10,2,1,2,AAPL,-400.0,-400.0,-400.0,-31.0,-600.0,-105.0,-63.0,-1.0,-2000.0,-2.0,-213.0,-399.02220695958204,
2024-10-21T12:15:39.207269463Z,2024-10-21T12:15:39.207103673Z,10,2,38,C,B,0,233.76,200,130,165790,12504456,233.74,234.0,28,22,1,1,233.7,234.1,1200,400,1,2,233.66,234.13,1,400,1,1,233.58,234.17,505,31,2,2,233.53,234.41,10,600,1,2,233.5,234.43,100,105,1,2,233.45,234.5,15,63,1,4,233.4,234.75,110,1,2,1,233.39,234.79,10,2000,1,1,233.31,234.89,110,2,2,2,AAPL,-200.0,-200.0,-28.0,-1200.0,-1.0,-505.0,-10.0,-100.0,-15.0,-110.0,-10.0,-209.26884138356937,
2024-10-21T12:15:39.207333984Z,2024-10-21T12:15:39.207167970Z,10,2,38,C,A,1,234.1,200,130,166014,12504459,233.74,234.0,28,22,1,1,233.7,234.1,1200,200,1,1,233.66,234.13,1,400,1,1,233.58,234.17,505,31,2,2,233.53,234.41,10,600,1,2,233.5,234.43,100,105,1,2,233.45,234.5,15,63,1,4,233.4,234.75,110,1,2,1,233.39,234.79,10,2000,1,1,233.31,234.89,110,2,2,2,AAPL,0.0,0.0,200.0,0.0,0.0,0.0,0.0,0.0,0.0,0.0,0.0,12.683232565773917,
2024-10-21T12:15:39.207408030Z,2024-10-21T12:15:39.207241805Z,10,2,38,C,A,1,234.1,200,130,166225,12504461,233.74,234.0,28,22,1,1,233.7,234.13,1200,400,1,1,233.66,234.17,1,31,1,2,233.58,234.41,505,600,2,2,233.53,234.43,10,105,1,2,233.5,234.5,100,63,1,4,233.45,234.75,15,1,1,1,233.4,234.79,110,2000,2,1,233.39,234.89,10,2,1,2,233.31,235.0,110,213,2,6,AAPL,0.0,0.0,400.0,31.0,600.0,105.0,63.0,1.0,2000.0,2.0,213.0,391.0699739011321,
2024-10-21T12:15:39.207701481Z,2024-10-21T12:15:39.207535631Z,10,2,38,C,A,0,234.0,22,130,165850,12504467,233.74,234.13,28,400,1,1,233.7,234.17,1200,31,1,2,233.66,234.41,1,600,1,2,233.58,234.43,505,105,2,2,233.53,234.5,10,63,1,4,233.5,234.75,100,1,1,1,233.45,234.79,15,2000,1,1,233.4,234.89,110,2,2,2,233.39,235.0,10,213,1,6,233.31,235.03,110,2,2,1,AAPL,400.0,400.0,31.0,600.0,105.0,63.0,1.0,2000.0,2.0,213.0,2.0,342.9893827461135,
2024-10-21T12:15:39.274873761Z,2024-10-21T12:15:39.274707573Z,10,2,38,C,B,0,233.74,28,130,166188,12504518,233.7,234.13,1200,400,1,1,233.66,234.17,1,31,1,2,233.58,234.41,505,600,2,2,233.53,234.43,10,105,1,2,233.5,234.5,100,63,1,4,233.45,234.75,15,1,1,1,233.4,234.79,110,2000,2,1,233.39,234.89,10,2,1,2,233.31,235.0,110,213,2,6,233.3,235.03,100,2,1,1,AAPL,-28.0,-28.0,-1200.0,-1.0,-505.0,-10.0,-100.0,-15.0,-110.0,-10.0,-110.0,-216.64815535794207,
2024-10-21T12:15:39.274960881Z,2024-10-21T12:15:39.274794258Z,10,2,38,A,B,1,233.69,28,130,166623,12504519,233.7,234.13,1200,400,1,1,233.69,234.17,28,31,1,2,233.66,234.41,1,600,1,2,233.58,234.43,505,105,2,2,233.53,234.5,10,63,1,4,233.5,234.75,100,1,1,1,233.45,234.79,15,2000,1,1,233.4,234.89,110,2,2,2,233.39,235.0,10,213,1,6,233.31,235.03,110,2,2,1,AAPL,0.0,0.0,28.0,1.0,505.0,10.0,100.0,15.0,110.0,10.0,110.0,141.76775620841542,
2024-10-21T12:15:39.314289508Z,2024-10-21T12:15:39.314122970Z,10,2,38,A,B,0,233.76,200,130,166538,12504563,233.76,234.13,200,400,1,1,233.7,234.17,1200,31,1,2,233.69,234.41,28,600,1,2,233.66,234.43,1,105,1,2,233.58,234.5,505,63,2,4,233.53,234.75,10,1,1,1,233.5,234.79,100,2000,1,1,233.45,234.89,15,2,1,2,233.4,235.0,110,213,2,6,233.39,235.03,10,2,1,1,AAPL,200.0,200.0,1200.0,28.0,1.0,505.0,10.0,100.0,15.0,110.0,10.0,164.53779959640644,
2024-10-21T12:15:39.314303543Z,2024-10-21T12:15:39.314137186Z,10,2,38,A,A,0,234.1,400,130,166357,12504564,233.76,234.1,200,400,1,1,233.7,234.13,1200,400,1,1,233.69,234.17,28,31,1,2,233.66,234.41,1,600,1,2,233.58,234.43,505,105,2,2,233.53,234.5,10,63,1,4,233.5,234.75,100,1,1,1,233.45,234.79,15,2000,1,1,233.4,234.89,110,2,2,2,233.39,235.0,10,213,1,6,AAPL,-400.0,-400.0,-31.0,-600.0,-105.0,-63.0,-1.0,-2000.0,-2.0,-213.0,-2.0,-342.9893827461135,
2024-10-21T12:15:40.360705214Z,2024-10-21T12:15:40.360537773Z,10,2,38,C,A,0,234.1,400,130,167441,12505301,233.76,234.13,200,400,1,1,233.7,234.17,1200,31,1,2,233.69,234.41,28,600,1,2,233.66,234.43,1,105,1,2,233.58,234.5,505,63,2,4,233.53,234.75,10,1,1,1,233.5,234.79,100,2000,1,1,233.45,234.89,15,2,1,2,233.4,235.0,110,213,2,6,233.39,235.03,10,2,1,1,AAPL,400.0,400.0,31.0,600.0,105.0,63.0,1.0,2000.0,2.0,213.0,2.0,342.9893827461135,
2024-10-21T12:15:40.360715053Z,2024-10-21T12:15:40.360548894Z,10,2,38,A,A,1,234.15,400,130,166159,12505302,233.76,234.13,200,400,1,1,233.7,234.15,1200,400,1,1,233.69,234.17,28,31,1,2,233.66,234.41,1,600,1,2,233.58,234.43,505,105,2,2,233.53,234.5,10,63,1,4,233.5,234.75,100,1,1,1,233.45,234.79,15,2000,1,1,233.4,234.89,110,2,2,2,233.39,235.0,10,213,1,6,AAPL,0.0,0.0,-31.0,-600.0,-105.0,-63.0,-1.0,-2000.0,-2.0,-213.0,-2.0,-335.0371496876635,
2024-10-21T12:15:40.361263637Z,2024-10-21T12:15:40.361097351Z,10,2,38,C,A,2,234.17,30,130,166286,12505308,233.76,234.13,200,400,1,1,233.7,234.15,1200,400,1,1,233.69,234.17,28,1,1,1,233.66,234.41,1,600,1,2,233.58,234.43,505,105,2,2,233.53,234.5,10,63,1,4,233.5,234.75,100,1,1,1,233.45,234.79,15,2000,1,1,233.4,234.89,110,2,2,2,233.39,235.0,10,213,1,6,AAPL,0.0,0.0,0.0,30.0,0.0,0.0,0.0,0.0,0.0,0.0,0.0,3.047477422080156,
2024-10-21T12:15:40.361312977Z,2024-10-21T12:15:40.361146693Z,10,2,38,A,A,3,234.22,27,130,166284,12505309,233.76,234.13,200,400,1,1,233.7,234.15,1200,400,1,1,233.69,234.17,28,1,1,1,233.66,234.22,1,27,1,1,233.58,234.41,505,600,2,2,233.53,234.43,10,105,1,2,233.5,234.5,100,63,1,4,233.45,234.75,15,1,1,1,233.4,234.79,110,2000,2,1,233.39,234.89,10,2,1,2,AAPL,0.0,0.0,0.0,0.0,-600.0,-105.0,-63.0,-1.0,-2000.0,-2.0,-213.0,-362.5544487667681,
2024-10-21T12:15:43.401012118Z,2024-10-21T12:15:43.400846263Z,10,2,38,C,B,0,233.76,200,130,165855,12511389,233.7,234.13,1200,400,1,1,233.69,234.15,28,400,1,1,233.66,234.17,1,1,1,1,233.58,234.22,505,27,2,1,233.53,234.41,10,600,1,2,233.5,234.43,100,105,1,2,233.45,234.5,15,63,1,4,233.4,234.75,110,1,2,1,233.39,234.79,10,2000,1,1,233.31,234.89,110,2,2,2,AAPL,-200.0,-200.0,-1200.0,-28.0,-1.0,-505.0,-10.0,-100.0,-15.0,-110.0,-10.0,-164.53779959640644,
2024-10-21T12:15:43.401025404Z,2024-10-21T12:15:43.400859035Z,10,2,38,A,B,0,233.74,200,130,166369,12511390,233.74,234.13,200,400,1,1,233.7,234.15,1200,400,1,1,233.69,234.17,28,1,1,1,233.66,234.22,1,27,1,1,233.58,234.41,505,600,2,2,233.53,234.43,10,105,1,2,233.5,234.5,100,63,1,4,233.45,234.75,15,1,1,1,233.4,234.79,110,2000,2,1,233.39,234.89,10,2,1,2,AAPL,200.0,200.0,1200.0,28.0,1.0,505.0,10.0,100.0,15.0,110.0,10.0,164.53779959640644,
2024-10-21T12:15:43.425571225Z,2024-10-21T12:15:43.425405296Z,10,2,38,C,A,3,234.22,27,130,165929,12511697,233.74,234.13,200,400,1,1,233.7,234.15,1200,400,1,1,233.69,234.17,28,1,1,1,233.66,234.41,1,600,1,2,233.58,234.43,505,105,2,2,233.53,234.5,10,63,1,4,233.5,234.75,100,1,1,1,233.45,234.79,15,2000,1,1,233.4,234.89,110,2,2,2,233.39,235.0,10,213,1,6,AAPL,0.0,0.0,0.0,0.0,600.0,105.0,63.0,1.0,2000.0,2.0,213.0,362.5544487667681,
2024-10-21T12:15:43.425623021Z,2024-10-21T12:15:43.425456541Z,10,2,38,A,A,3,234.21,26,130,166480,12511698,233.74,234.13,200,400,1,1,233.7,234.15,1200,400,1,1,233.69,234.17,28,1,1,1,233.66,234.21,1,26,1,1,233.58,234.41,505,600,2,2,233.53,234.43,10,105,1,2,233.5,234.5,100,63,1,4,233.45,234.75,15,1,1,1,233.4,234.79,110,2000,2,1,233.39,234.89,10,2,1,2,AAPL,0.0,0.0,0.0,0.0,-600.0,-105.0,-63.0,-1.0,-2000.0,-2.0,-213.0,-362.5544487667681,
2024-10-21T12:15:43.454501811Z,2024-10-21T12:15:43.454335483Z,10,2,38,A,A,1,234.14,400,130,166328,12511807,233.74,234.13,200,400,1,1,233.7,234.14,1200,400,1,1,233.69,234.17,28,1,1,1,233.66,234.21,1,26,1,1,233.58,234.41,505,600,2,2,233.53,234.43,10,105,1,2,233.5,234.5,100,63,1,4,233.45,234.75,15,1,1,1,233.4,234.79,110,2000,2,1,233.39,234.89,10,2,1,2,AAPL,0.0,0.0,-400.0,0.0,0.0,0.0,0.0,0.0,0.0,0.0,0.0,-25.366465131547834,
2024-10-21T12:15:43.462491808Z,2024-10-21T12:15:43.462325554Z,10,2,38,A,A,0,234.13,400,130,166254,12511952,233.74,234.13,200,800,1,2,233.7,234.17,1200,1,1,1,233.69,234.21,28,26,1,1,233.66,234.41,1,600,1,2,233.58,234.43,505,105,2,2,233.53,234.5,10,63,1,4,233.5,234.75,100,1,1,1,233.45,234.79,15,2000,1,1,233.4,234.89,110,2,2,2,233.39,235.0,10,213,1,6,AAPL,-400.0,-400.0,1.0,26.0,600.0,105.0,63.0,1.0,2000.0,2.0,213.0,357.30677897028306,
2024-10-21T12:15:43.490633387Z,2024-10-21T12:15:43.490467184Z,10,2,38,A,B,3,233.66,30,130,166203,12512344,233.74,234.13,200,800,1,2,233.7,234.17,1200,1,1,1,233.69,234.21,28,26,1,1,233.66,234.41,31,600,2,2,233.58,234.43,505,105,2,2,233.53,234.5,10,63,1,4,233.5,234.75,100,1,1,1,233.45,234.79,15,2000,1,1,233.4,234.89,110,2,2,2,233.39,235.0,10,213,1,6,AAPL,0.0,0.0,0.0,0.0,30.0,0.0,0.0,0.0,0.0,0.0,0.0,6.152311650723556,
2024-10-21T12:15:43.546265076Z,2024-10-21T12:15:43.546099003Z,10,2,38,C,B,2,233.69,28,130,166073,12512634,233.74,234.13,200,800,1,2,233.7,234.17,1200,1,1,1,233.66,234.21,31,26,2,1,233.58,234.41,505,600,2,2,233.53,234.43,10,105,1,2,233.5,234.5,100,63,1,4,233.45,234.75,15,1,1,1,233.4,234.79,110,2000,2,1,233.39,234.89,10,2,1,2,233.31,235.0,110,213,2,6,AAPL,0.0,0.0,0.0,-28.0,-31.0,-505.0,-10.0,-100.0,-15.0,-110.0,-10.0,-90.61459932326147,
2024-10-21T12:15:43.594979866Z,2024-10-21T12:15:43.594813115Z,10,2,38,A,A,0,234.12,200,130,166751,12512827,233.74,234.12,200,200,1,1,233.7,234.13,1200,400,1,1,233.66,234.17,31,1,2,1,233.58,234.21,505,26,2,1,233.53,234.41,10,600,1,2,233.5,234.43,100,105,1,2,233.45,234.5,15,63,1,4,233.4,234.75,110,1,2,1,233.39,234.79,10,2000,1,1,233.31,234.89,110,2,2,2,AAPL,-800.0,-800.0,-1.0,-26.0,-600.0,-105.0,-63.0,-1.0,-2000.0,-2.0,-213.0,-381.1634781456331,
2024-10-21T12:15:43.981450269Z,2024-10-21T12:15:43.981284269Z,10,2,38,A,A,3,234.19,28,130,166000,12513411,233.74,234.12,200,200,1,1,233.7,234.13,1200,400,1,1,233.66,234.17,31,1,2,1,233.58,234.19,505,28,2,1,233.53,234.21,10,26,1,1,233.5,234.41,100,600,1,2,233.45,234.43,15,105,1,2,233.4,234.5,110,63,2,4,233.39,234.75,10,1,1,1,233.31,234.79,110,2000,2,1,AAPL,0.0,0.0,0.0,0.0,-26.0,-600.0,-105.0,-63.0,-1.0,-2000.0,-2.0,-235.69074439748596,
2024-10-21T12:15:43.981745796Z,2024-10-21T12:15:43.981579878Z,10,2,38,C,A,4,234.21,26,130,165918,12513419,233.74,234.12,200,200,1,1,233.7,234.13,1200,400,1,1,233.66,234.17,31,1,2,1,233.58,234.19,505,28,2,1,233.53,234.41,10,600,1,2,233.5,234.43,100,105,1,2,233.45,234.5,15,63,1,4,233.4,234.75,110,1,2,1,233.39,234.79,10,2000,1,1,233.31,234.89,110,2,2,2,AAPL,0.0,0.0,0.0,0.0,0.0,600.0,105.0,63.0,1.0,2000.0,2.0,230.35874096685887,
2024-10-21T12:15:46.504609799Z,2024-10-21T12:15:46.504444030Z,10,2,38,C,B,0,233.74,200,130,165769,12517721,233.7,234.12,1200,200,1,1,233.66,234.13,31,400,2,1,233.58,234.17,505,1,2,1,233.53,234.19,10,28,1,1,233.5,234.41,100,600,1,2,233.45,234.43,15,105,1,2,233.4,234.5,110,63,2,4,233.39,234.75,10,1,1,1,233.31,234.79,110,2000,2,1,233.3,234.89,100,2,1,2,AAPL,-200.0,-200.0,-1200.0,-31.0,-505.0,-10.0,-100.0,-15.0,-110.0,-10.0,-110.0,-223.11509299515572,
2024-10-21T12:15:46.504623049Z,2024-10-21T12:15:46.504456348Z,10,2,38,A,B,0,233.73,200,130,166701,12517722,233.73,234.12,200,200,1,1,233.7,234.13,1200,400,1,1,233.66,234.17,31,1,2,1,233.58,234.19,505,28,2,1,233.53,234.41,10,600,1,2,233.5,234.43,100,105,1,2,233.45,234.5,15,63,1,4,233.4,234.75,110,1,2,1,233.39,234.79,10,2000,1,1,233.31,234.89,110,2,2,2,AAPL,200.0,200.0,1200.0,31.0,505.0,10.0,100.0,15.0,110.0,10.0,110.0,223.11509299515572,
2024-10-21T12:15:46.504635795Z,2024-10-21T12:15:46.504469490Z,10,2,38,A,A,0,234.12,200,130,166305,12517724,233.73,234.12,200,400,1,2,233.7,234.13,1200,400,1,1,233.66,234.17,31,1,2,1,233.58,234.19,505,28,2,1,233.53,234.41,10,600,1,2,233.5,234.43,100,105,1,2,233.45,234.5,15,63,1,4,233.4,234.75,110,1,2,1,233.39,234.79,10,2000,1,1,233.31,234.89,110,2,2,2,AAPL,-200.0,-200.0,0.0,0.0,0.0,0.0,0.0,0.0,0.0,0.0,0.0,-3.9761165292250036,
2024-10-21T12:15:46.593857210Z,2024-10-21T12:15:46.593690522Z,10,2,38,A,A,3,234.18,30,130,166688,12518020,233.73,234.12,200,400,1,2,233.7,234.13,1200,400,1,1,233.66,234.17,31,1,2,1,233.58,234.18,505,30,2,1,233.53,234.19,10,28,1,1,233.5,234.41,100,600,1,2,233.45,234.43,15,105,1,2,233.4,234.5,110,63,2,4,233.39,234.75,10,1,1,1,233.31,234.79,110,2000,2,1,AAPL,0.0,0.0,0.0,0.0,-28.0,-600.0,-105.0,-63.0,-1.0,-2000.0,-2.0,-236.10089850753417,
2024-10-21T12:15:46.594225497Z,2024-10-21T12:15:46.594059334Z,10,2,38,C,A,4,234.19,28,130,166163,12518032,233.73,234.12,200,400,1,2,233.7,234.13,1200,400,1,1,233.66,234.17,31,1,2,1,233.58,234.18,505,30,2,1,233.53,234.41,10,600,1,2,233.5,234.43,100,105,1,2,233.45,234.5,15,63,1,4,233.4,234.75,110,1,2,1,233.39,234.79,10,2000,1,1,233.31,234.89,110,2,2,2,AAPL,0.0,0.0,0.0,0.0,0.0,600.0,105.0,63.0,1.0,2000.0,2.0,230.35874096685887,
2024-10-21T12:15:50.469902981Z,2024-10-21T12:15:50.469736889Z,10,2,38,C,A,0,234.12,200,130,166092,12522085,233.73,234.12,200,200,1,1,233.7,234.13,1200,400,1,1,233.66,234.17,31,1,2,1,233.58,234.18,505,30,2,1,233.53,234.41,10,600,1,2,233.5,234.43,100,105,1,2,233.45,234.5,15,63,1,4,233.4,234.75,110,1,2,1,233.39,234.79,10,2000,1,1,233.31,234.89,110,2,2,2,AAPL,200.0,200.0,0.0,0.0,0.0,0.0,0.0,0.0,0.0,0.0,0.0,3.9761165292250036,
2024-10-21T12:15:55.593624526Z,2024-10-21T12:15:55.593458354Z,10,2,38,C,B,2,233.66,30,130,166172,12526601,233.73,234.12,200,200,1,1,233.7,234.13,1200,400,1,1,233.66,234.17,1,1,1,1,233.58,234.18,505,30,2,1,233.53,234.41,10,600,1,2,233.5,234.43,100,105,1,2,233.45,234.5,15,63,1,4,233.4,234.75,110,1,2,1,233.39,234.79,10,2000,1,1,233.31,234.89,110,2,2,2,AAPL,0.0,0.0,0.0,-30.0,0.0,0.0,0.0,0.0,0.0,0.0,0.0,-3.047477422080156,
2024-10-21T12:15:55.594134274Z,2024-10-21T12:15:55.593967834Z,10,2,38,A,B,1,233.71,29,130,166440,12526613,233.73,234.12,200,200,1,1,233.71,234.13,29,400,1,1,233.7,234.17,1200,1,1,1,233.66,234.18,1,30,1,1,233.58,234.41,505,600,2,2,233.53,234.43,10,105,1,2,233.5,234.5,100,63,1,4,233.45,234.75,15,1,1,1,233.4,234.79,110,2000,2,1,233.39,234.89,10,2,1,2,AAPL,0.0,0.0,29.0,1200.0,1.0,505.0,10.0,100.0,15.0,110.0,10.0,205.35614101717326,
2024-10-21T12:15:55.643690186Z,2024-10-21T12:15:55.643523614Z,10,2,38,A,B,0,233.77,200,130,166572,12526664,233.77,234.12,200,200,1,1,233.71,234.13,29,400,1,1,233.7,234.17,1200,1,1,1,233.66,234.18,1,30,1,1,233.58,234.41,505,600,2,2,233.53,234.43,10,105,1,2,233.5,234.5,100,63,1,4,233.45,234.75,15,1,1,1,233.4,234.79,110,2000,2,1,233.39,234.89,10,2,1,2,AAPL,200.0,200.0,0.0,0.0,0.0,0.0,0.0,0.0,0.0,0.0,0.0,3.9761165292250036,
2024-10-21T12:16:00.253510382Z,2024-10-21T12:16:00.253343668Z,10,2,38,A,A,0,234.11,200,130,166714,12533252,233.77,234.11,200,200,1,1,233.71,234.13,29,400,1,1,233.7,234.17,1200,1,1,1,233.66,234.18,1,30,1,1,233.58,234.41,505,600,2,2,233.53,234.43,10,105,1,2,233.5,234.5,100,63,1,4,233.45,234.75,15,1,1,1,233.4,234.79,110,2000,2,1,233.39,234.89,10,2,1,2,AAPL,-200.0,-200.0,0.0,0.0,0.0,0.0,0.0,0.0,0.0,0.0,0.0,-3.9761165292250036,
2024-10-21T12:16:02.523286908Z,2024-10-21T12:16:02.523121028Z,10,2,38,C,B,0,233.77,200,130,165880,12536233,233.71,234.11,29,200,1,1,233.7,234.13,1200,400,1,1,233.66,234.17,1,1,1,1,233.58,234.18,505,30,2,1,233.53,234.41,10,600,1,2,233.5,234.43,100,105,1,2,233.45,234.5,15,63,1,4,233.4,234.75,110,1,2,1,233.39,234.79,10,2000,1,1,233.31,234.89,110,2,2,2,AAPL,-200.0,-200.0,-29.0,-1200.0,-1.0,-505.0,-10.0,-100.0,-15.0,-110.0,-10.0,-209.33225754639824,
2024-10-21T12:16:02.523299016Z,2024-10-21T12:16:02.523132984Z,10,2,38,A,B,0,233.76,200,130,166032,12536234,233.76,234.11,200,200,1,1,233.71,234.13,29,400,1,1,233.7,234.17,1200,1,1,1,233.66,234.18,1,30,1,1,233.58,234.41,505,600,2,2,233.53,234.43,10,105,1,2,233.5,234.5,100,63,1,4,233.45,234.75,15,1,1,1,233.4,234.79,110,2000,2,1,233.39,234.89,10,2,1,2,AAPL,200.0,200.0,29.0,1200.0,1.0,505.0,10.0,100.0,15.0,110.0,10.0,209.33225754639824,
2024-10-21T12:16:02.593082475Z,2024-10-21T12:16:02.592915859Z,10,2,38,A,A,2,234.17,27,130,166616,12536503,233.76,234.11,200,200,1,1,233.71,234.13,29,400,1,1,233.7,234.17,1200,28,1,2,233.66,234.18,1,30,1,1,233.58,234.41,505,600,2,2,233.53,234.43,10,105,1,2,233.5,234.5,100,63,1,4,233.45,234.75,15,1,1,1,233.4,234.79,110,2000,2,1,233.39,234.89,10,2,1,2,AAPL,0.0,0.0,0.0,-27.0,0.0,0.0,0.0,0.0,0.0,0.0,0.0,-2.74272967987214,
2024-10-21T12:16:02.697524299Z,2024-10-21T12:16:02.697358278Z,10,2,38,C,A,3,234.18,30,130,166021,12536650,233.76,234.11,200,200,1,1,233.71,234.13,29,400,1,1,233.7,234.17,1200,28,1,2,233.66,234.41,1,600,1,2,233.58,234.43,505,105,2,2,233.53,234.5,10,63,1,4,233.5,234.75,100,1,1,1,233.45,234.79,15,2000,1,1,233.4,234.89,110,2,2,2,233.39,235.0,10,213,1,6,AAPL,0.0,0.0,0.0,0.0,600.0,105.0,63.0,1.0,2000.0,2.0,213.0,362.5544487667681,
2024-10-21T12:16:04.305857113Z,2024-10-21T12:16:04.305690771Z,10,2,38,A,B,0,233.77,200,130,166342,12539302,233.77,234.11,200,200,1,1,233.71,234.13,29,400,1,1,233.7,234.17,1200,28,1,2,233.66,234.41,1,600,1,2,233.58,234.43,505,105,2,2,233.53,234.5,10,63,1,4,233.5,234.75,100,1,1,1,233.45,234.79,15,2000,1,1,233.4,234.89,110,2,2,2,233.39,235.0,10,213,1,6,AAPL,200.0,200.0,0.0,0.0,0.0,0.0,0.0,0.0,0.0,0.0,0.0,3.9761165292250036,
2024-10-21T12:16:08.452361078Z,2024-10-21T12:16:08.452195034Z,10,2,38,C,B,0,233.77,200,130,166044,12544790,233.71,234.11,29,200,1,1,233.7,234.13,1200,400,1,1,233.66,234.17,1,28,1,2,233.58,234.41,505,600,2,2,233.53,234.43,10,105,1,2,233.5,234.5,100,63,1,4,233.45,234.75,15,1,1,1,233.4,234.79,110,2000,2,1,233.39,234.89,10,2,1,2,233.31,235.0,110,213,2,6,AAPL,-200.0,-200.0,-29.0,-1200.0,-1.0,-505.0,-10.0,-100.0,-15.0,-110.0,-10.0,-209.33225754639824,
2024-10-21T12:16:08.452373943Z,2024-10-21T12:16:08.452206841Z,10,2,38,A,B,0,233.76,200,130,167102,12544791,233.76,234.11,200,200,1,1,233.71,234.13,29,400,1,1,233.7,234.17,1200,28,1,2,233.66,234.41,1,600,1,2,233.58,234.43,505,105,2,2,233.53,234.5,10,63,1,4,233.5,234.75,100,1,1,1,233.45,234.79,15,2000,1,1,233.4,234.89,110,2,2,2,233.39,235.0,10,213,1,6,AAPL,200.0,200.0,29.0,1200.0,1.0,505.0,10.0,100.0,15.0,110.0,10.0,209.33225754639824,
2024-10-21T12:16:09.449971056Z,2024-10-21T12:16:09.449805017Z,10,2,38,C,B,1,233.71,29,130,166039,12545654,233.76,234.11,200,200,1,1,233.7,234.13,1200,400,1,1,233.66,234.17,1,28,1,2,233.58,234.41,505,600,2,2,233.53,234.43,10,105,1,2,233.5,234.5,100,63,1,4,233.45,234.75,15,1,1,1,233.4,234.79,110,2000,2,1,233.39,234.89,10,2,1,2,233.31,235.0,110,213,2,6,AAPL,0.0,0.0,-29.0,-1200.0,-1.0,-505.0,-10.0,-100.0,-15.0,-110.0,-10.0,-205.35614101717326,
2024-10-21T12:16:09.450027355Z,2024-10-21T12:16:09.449860480Z,10,2,38,A,B,2,233.69,30,130,166875,12545655,233.76,234.11,200,200,1,1,233.7,234.13,1200,400,1,1,233.69,234.17,30,28,1,2,233.66,234.41,1,600,1,2,233.58,234.43,505,105,2,2,233.53,234.5,10,63,1,4,233.5,234.75,100,1,1,1,233.45,234.79,15,2000,1,1,233.4,234.89,110,2,2,2,233.39,235.0,10,213,1,6,AAPL,0.0,0.0,0.0,30.0,1.0,505.0,10.0,100.0,15.0,110.0,10.0,84.66545283400993,
2024-10-21T12:16:09.753978514Z,2024-10-21T12:16:09.753811454Z,10,2,38,C,B,0,233.76,200,130,167060,12546012,233.7,234.11,1200,200,1,1,233.69,234.13,30,400,1,1,233.66,234.17,1,28,1,2,233.58,234.41,505,600,2,2,233.53,234.43,10,105,1,2,233.5,234.5,100,63,1,4,233.45,234.75,15,1,1,1,233.4,234.79,110,2000,2,1,233.39,234.89,10,2,1,2,233.31,235.0,110,213,2,6,AAPL,-200.0,-200.0,-1200.0,-30.0,-1.0,-505.0,-10.0,-100.0,-15.0,-110.0,-10.0,-164.74096475787846,
2024-10-21T12:16:09.753989713Z,2024-10-21T12:16:09.753823460Z,10,2,38,A,B,0,233.74,200,130,166253,12546013,233.74,234.11,200,200,1,1,233.7,234.13,1200,400,1,1,233.69,234.17,30,28,1,2,233.66,234.41,1,600,1,2,233.58,234.43,505,105,2,2,233.53,234.5,10,63,1,4,233.5,234.75,100,1,1,1,233.45,234.79,15,2000,1,1,233.4,234.89,110,2,2,2,233.39,235.0,10,213,1,6,AAPL,200.0,200.0,1200.0,30.0,1.0,505.0,10.0,100.0,15.0,110.0,10.0,164.74096475787846,
2024-10-21T12:16:09.794247866Z,2024-10-21T12:16:09.794081348Z,10,2,38,A,A,0,234.1,200,130,166518,12546087,233.74,234.1,200,200,1,1,233.7,234.13,1200,400,1,1,233.69,234.17,30,28,1,2,233.66,234.41,1,600,1,2,233.58,234.43,505,105,2,2,233.53,234.5,10,63,1,4,233.5,234.75,100,1,1,1,233.45,234.79,15,2000,1,1,233.4,234.89,110,2,2,2,233.39,235.0,10,213,1,6,AAPL,-200.0,-200.0,0.0,0.0,0.0,0.0,0.0,0.0,0.0,0.0,0.0,-3.9761165292250036,
2024-10-21T12:16:09.813187546Z,2024-10-21T12:16:09.813020869Z,10,2,38,A,B,0,233.75,200,130,166677,12546174,233.75,234.1,200,200,1,1,233.7,234.13,1200,400,1,1,233.69,234.17,30,28,1,2,233.66,234.41,1,600,1,2,233.58,234.43,505,105,2,2,233.53,234.5,10,63,1,4,233.5,234.75,100,1,1,1,233.45,234.79,15,2000,1,1,233.4,234.89,110,2,2,2,233.39,235.0,10,213,1,6,AAPL,200.0,200.0,0.0,0.0,0.0,0.0,0.0,0.0,0.0,0.0,0.0,3.9761165292250036,
2024-10-21T12:16:10.366670967Z,2024-10-21T12:16:10.366504475Z,10,2,38,A,A,0,234.09,200,130,166492,12546733,233.75,234.09,200,200,1,1,233.7,234.13,1200,400,1,1,233.69,234.17,30,28,1,2,233.66,234.41,1,600,1,2,233.58,234.43,505,105,2,2,233.53,234.5,10,63,1,4,233.5,234.75,100,1,1,1,233.45,234.79,15,2000,1,1,233.4,234.89,110,2,2,2,233.39,235.0,10,213,1,6,AAPL,-200.0,-200.0,0.0,0.0,0.0,0.0,0.0,0.0,0.0,0.0,0.0,-3.9761165292250036,
2024-10-21T12:16:10.387245860Z,2024-10-21T12:16:10.387079865Z,10,2,38,C,A,2,234.17,27,130,165995,12546807,233.75,234.09,200,200,1,1,233.7,234.13,1200,400,1,1,233.69,234.17,30,1,1,1,233.66,234.41,1,600,1,2,233.58,234.43,505,105,2,2,233.53,234.5,10,63,1,4,233.5,234.75,100,1,1,1,233.45,234.79,15,2000,1,1,233.4,234.89,110,2,2,2,233.39,235.0,10,213,1,6,AAPL,0.0,0.0,0.0,27.0,0.0,0.0,0.0,0.0,0.0,0.0,0.0,2.74272967987214,
2024-10-21T12:16:10.387302448Z,2024-10-21T12:16:10.387136109Z,10,2,38,A,A,2,234.16,29,130,166339,12546808,233.75,234.09,200,200,1,1,233.7,234.13,1200,400,1,1,233.69,234.16,30,29,1,1,233.66,234.17,1,1,1,1,233.58,234.41,505,600,2,2,233.53,234.43,10,105,1,2,233.5,234.5,100,63,1,4,233.45,234.75,15,1,1,1,233.4,234.79,110,2000,2,1,233.39,234.89,10,2,1,2,AAPL,0.0,0.0,0.0,-1.0,-600.0,-105.0,-63.0,-1.0,-2000.0,-2.0,-213.0,-362.6560313475041,
2024-10-21T12:16:12.011187719Z,2024-10-21T12:16:12.011021598Z,10,2,38,C,A,0,234.09,200,130,166121,12547958,233.75,234.13,200,400,1,1,233.7,234.16,1200,29,1,1,233.69,234.17,30,1,1,1,233.66,234.41,1,600,1,2,233.58,234.43,505,105,2,2,233.53,234.5,10,63,1,4,233.5,234.75,100,1,1,1,233.45,234.79,15,2000,1,1,233.4,234.89,110,2,2,2,233.39,235.0,10,213,1,6,AAPL,400.0,400.0,29.0,1.0,600.0,105.0,63.0,1.0,2000.0,2.0,213.0,372.4473331279913,
2024-10-21T12:16:12.011200956Z,2024-10-21T12:16:12.011034600Z,10,2,38,A,A,0,234.11,200,130,166356,12547959,233.75,234.11,200,200,1,1,233.7,234.13,1200,400,1,1,233.69,234.16,30,29,1,1,233.66,234.17,1,1,1,1,233.58,234.41,505,600,2,2,233.53,234.43,10,105,1,2,233.5,234.5,100,63,1,4,233.45,234.75,15,1,1,1,233.4,234.79,110,2000,2,1,233.39,234.89,10,2,1,2,AAPL,-400.0,-400.0,-29.0,-1.0,-600.0,-105.0,-63.0,-1.0,-2000.0,-2.0,-213.0,-372.4473331279913,
2024-10-21T12:16:12.100747677Z,2024-10-21T12:16:12.100581387Z,10,2,38,A,A,0,234.1,200,130,166290,12548144,233.75,234.1,200,200,1,1,233.7,234.13,1200,400,1,1,233.69,234.16,30,29,1,1,233.66,234.17,1,1,1,1,233.58,234.41,505,600,2,2,233.53,234.43,10,105,1,2,233.5,234.5,100,63,1,4,233.45,234.75,15,1,1,1,233.4,234.79,110,2000,2,1,233.39,234.89,10,2,1,2,AAPL,-200.0,-200.0,0.0,0.0,0.0,0.0,0.0,0.0,0.0,0.0,0.0,-3.9761165292250036,
2024-10-21T12:16:13.573877503Z,2024-10-21T12:16:13.573710917Z,10,2,38,A,A,0,234.09,200,130,166586,12549200,233.75,234.09,200,200,1,1,233.7,234.13,1200,400,1,1,233.69,234.16,30,29,1,1,233.66,234.17,1,1,1,1,233.58,234.41,505,600,2,2,233.53,234.43,10,105,1,2,233.5,234.5,100,63,1,4,233.45,234.75,15,1,1,1,233.4,234.79,110,2000,2,1,233.39,234.89,10,2,1,2,AAPL,-200.0,-200.0,0.0,0.0,0.0,0.0,0.0,0.0,0.0,0.0,0.0,-3.9761165292250036,
2024-10-21T12:16:14.439317152Z,2024-10-21T12:16:14.439151195Z,10,2,38,C,A,0,234.09,200,130,165957,12549789,233.75,234.13,200,400,1,1,233.7,234.16,1200,29,1,1,233.69,234.17,30,1,1,1,233.66,234.41,1,600,1,2,233.58,234.43,505,105,2,2,233.53,234.5,10,63,1,4,233.5,234.75,100,1,1,1,233.45,234.79,15,2000,1,1,233.4,234.89,110,2,2,2,233.39,235.0,10,213,1,6,AAPL,400.0,400.0,29.0,1.0,600.0,105.0,63.0,1.0,2000.0,2.0,213.0,372.4473331279913,
2024-10-21T12:16:14.439329197Z,2024-10-21T12:16:14.439163159Z,10,2,38,A,A,0,234.1,200,130,166038,12549790,233.75,234.1,200,200,1,1,233.7,234.13,1200,400,1,1,233.69,234.16,30,29,1,1,233.66,234.17,1,1,1,1,233.58,234.41,505,600,2,2,233.53,234.43,10,105,1,2,233.5,234.5,100,63,1,4,233.45,234.75,15,1,1,1,233.4,234.79,110,2000,2,1,233.39,234.89,10,2,1,2,AAPL,-400.0,-400.0,-29.0,-1.0,-600.0,-105.0,-63.0,-1.0,-2000.0,-2.0,-213.0,-372.4473331279913,
2024-10-21T12:16:14.647379555Z,2024-10-21T12:16:14.647213365Z,10,2,38,A,A,0,234.09,200,130,166190,12550175,233.75,234.09,200,200,1,1,233.7,234.13,1200,400,1,1,233.69,234.16,30,29,1,1,233.66,234.17,1,1,1,1,233.58,234.41,505,600,2,2,233.53,234.43,10,105,1,2,233.5,234.5,100,63,1,4,233.45,234.75,15,1,1,1,233.4,234.79,110,2000,2,1,233.39,234.89,10,2,1,2,AAPL,-200.0,-200.0,0.0,0.0,0.0,0.0,0.0,0.0,0.0,0.0,0.0,-3.9761165292250036,
2024-10-21T12:16:20.281941255Z,2024-10-21T12:16:20.281774908Z,10,2,38,C,B,0,233.75,200,130,166347,12556695,233.7,234.09,1200,200,1,1,233.69,234.13,30,400,1,1,233.66,234.16,1,29,1,1,233.58,234.17,505,1,2,1,233.53,234.41,10,600,1,2,233.5,234.43,100,105,1,2,233.45,234.5,15,63,1,4,233.4,234.75,110,1,2,1,233.39,234.79,10,2000,1,1,233.31,234.89,110,2,2,2,AAPL,-200.0,-200.0,-1200.0,-30.0,-1.0,-505.0,-10.0,-100.0,-15.0,-110.0,-10.0,-164.74096475787846,
2024-10-21T12:16:20.281953090Z,2024-10-21T12:16:20.281786576Z,10,2,38,A,B,0,233.73,200,130,166514,12556696,233.73,234.09,200,200,1,1,233.7,234.13,1200,400,1,1,233.69,234.16,30,29,1,1,233.66,234.17,1,1,1,1,233.58,234.41,505,600,2,2,233.53,234.43,10,105,1,2,233.5,234.5,100,63,1,4,233.45,234.75,15,1,1,1,233.4,234.79,110,2000,2,1,233.39,234.89,10,2,1,2,AAPL,200.0,200.0,1200.0,30.0,1.0,505.0,10.0,100.0,15.0,110.0,10.0,164.74096475787846,
2024-10-21T12:16:20.339335090Z,2024-10-21T12:16:20.339168043Z,10,2,38,A,B,0,233.74,200,130,167047,12556816,233.74,234.09,200,200,1,1,233.7,234.13,1200,400,1,1,233.69,234.16,30,29,1,1,233.66,234.17,1,1,1,1,233.58,234.41,505,600,2,2,233.53,234.43,10,105,1,2,233.5,234.5,100,63,1,4,233.45,234.75,15,1,1,1,233.4,234.79,110,2000,2,1,233.39,234.89,10,2,1,2,AAPL,200.0,200.0,0.0,0.0,0.0,0.0,0.0,0.0,0.0,0.0,0.0,3.9761165292250036,
2024-10-21T12:16:20.352255989Z,2024-10-21T12:16:20.352089791Z,10,2,38,A,B,0,233.74,200,130,166198,12556912,233.74,234.09,400,200,2,1,233.7,234.13,1200,400,1,1,233.69,234.16,30,29,1,1,233.66,234.17,1,1,1,1,233.58,234.41,505,600,2,2,233.53,234.43,10,105,1,2,233.5,234.5,100,63,1,4,233.45,234.75,15,1,1,1,233.4,234.79,110,2000,2,1,233.39,234.89,10,2,1,2,AAPL,200.0,200.0,0.0,0.0,0.0,0.0,0.0,0.0,0.0,0.0,0.0,3.9761165292250036,
2024-10-21T12:16:20.353221672Z,2024-10-21T12:16:20.353055730Z,10,2,38,C,B,0,233.74,200,130,165942,12556917,233.74,234.09,200,200,1,1,233.7,234.13,1200,400,1,1,233.69,234.16,30,29,1,1,233.66,234.17,1,1,1,1,233.58,234.41,505,600,2,2,233.53,234.43,10,105,1,2,233.5,234.5,100,63,1,4,233.45,234.75,15,1,1,1,233.4,234.79,110,2000,2,1,233.39,234.89,10,2,1,2,AAPL,-200.0,-200.0,0.0,0.0,0.0,0.0,0.0,0.0,0.0,0.0,0.0,-3.9761165292250036,
2024-10-21T12:16:20.448635525Z,2024-10-21T12:16:20.448469192Z,10,2,38,A,A,0,234.08,200,130,166333,12557144,233.74,234.08,200,200,1,1,233.7,234.13,1200,400,1,1,233.69,234.16,30,29,1,1,233.66,234.17,1,1,1,1,233.58,234.41,505,600,2,2,233.53,234.43,10,105,1,2,233.5,234.5,100,63,1,4,233.45,234.75,15,1,1,1,233.4,234.79,110,2000,2,1,233.39,234.89,10,2,1,2,AAPL,-200.0,-200.0,0.0,0.0,0.0,0.0,0.0,0.0,0.0,0.0,0.0,-3.9761165292250036,
2024-10-21T12:16:34.456477234Z,2024-10-21T12:16:34.456311187Z,10,2,38,C,A,2,234.16,29,130,166047,12569933,233.74,234.08,200,200,1,1,233.7,234.13,1200,400,1,1,233.69,234.17,30,1,1,1,233.66,234.41,1,600,1,2,233.58,234.43,505,105,2,2,233.53,234.5,10,63,1,4,233.5,234.75,100,1,1,1,233.45,234.79,15,2000,1,1,233.4,234.89,110,2,2,2,233.39,235.0,10,213,1,6,AAPL,0.0,0.0,0.0,1.0,600.0,105.0,63.0,1.0,2000.0,2.0,213.0,362.6560313475041,
2024-10-21T12:16:34.456534808Z,2024-10-21T12:16:34.456367935Z,10,2,38,A,A,2,234.15,30,130,166873,12569937,233.74,234.08,200,200,1,1,233.7,234.13,1200,400,1,1,233.69,234.15,30,30,1,1,233.66,234.17,1,1,1,1,233.58,234.41,505,600,2,2,233.53,234.43,10,105,1,2,233.5,234.5,100,63,1,4,233.45,234.75,15,1,1,1,233.4,234.79,110,2000,2,1,233.39,234.89,10,2,1,2,AAPL,0.0,0.0,0.0,-1.0,-600.0,-105.0,-63.0,-1.0,-2000.0,-2.0,-213.0,-362.6560313475041,
2024-10-21T12:16:35.928291181Z,2024-10-21T12:16:35.928124957Z,10,2,38,C,B,2,233.69,30,130,166224,12572168,233.74,234.08,200,200,1,1,233.7,234.13,1200,400,1,1,233.66,234.15,1,30,1,1,233.58,234.17,505,1,2,1,233.53,234.41,10,600,1,2,233.5,234.43,100,105,1,2,233.45,234.5,15,63,1,4,233.4,234.75,110,1,2,1,233.39,234.79,10,2000,1,1,233.31,234.89,110,2,2,2,AAPL,0.0,0.0,0.0,-30.0,-1.0,-505.0,-10.0,-100.0,-15.0,-110.0,-10.0,-84.66545283400993,
2024-10-21T12:16:35.928342407Z,2024-10-21T12:16:35.928176126Z,10,2,38,A,B,2,233.67,28,130,166281,12572169,233.74,234.08,200,200,1,1,233.7,234.13,1200,400,1,1,233.67,234.15,28,30,1,1,233.66,234.17,1,1,1,1,233.58,234.41,505,600,2,2,233.53,234.43,10,105,1,2,233.5,234.5,100,63,1,4,233.45,234.75,15,1,1,1,233.4,234.79,110,2000,2,1,233.39,234.89,10,2,1,2,AAPL,0.0,0.0,0.0,28.0,1.0,505.0,10.0,100.0,15.0,110.0,10.0,84.46228767253793,
2024-10-21T12:16:36.290257872Z,2024-10-21T12:16:36.290091431Z,10,2,38,A,A,1,234.1,100,130,166441,12572429,233.74,234.08,200,200,1,1,233.7,234.1,1200,100,1,1,233.67,234.13,28,400,1,1,233.66,234.15,1,30,1,1,233.58,234.17,505,1,2,1,233.53,234.41,10,600,1,2,233.5,234.43,100,105,1,2,233.45,234.5,15,63,1,4,233.4,234.75,110,1,2,1,233.39,234.79,10,2000,1,1,AAPL,0.0,0.0,-400.0,-30.0,-1.0,-600.0,-105.0,-63.0,-1.0,-2000.0,-2.0,-258.97776057551096,
2024-10-21T12:16:37.672891891Z,2024-10-21T12:16:37.672726079Z,10,2,38,C,B,2,233.67,28,130,165812,12574327,233.74,234.08,200,200,1,1,233.7,234.1,1200,100,1,1,233.66,234.13,1,400,1,1,233.58,234.15,505,30,2,1,233.53,234.17,10,1,1,1,233.5,234.41,100,600,1,2,233.45,234.43,15,105,1,2,233.4,234.5,110,63,2,4,233.39,234.75,10,1,1,1,233.31,234.79,110,2000,2,1,AAPL,0.0,0.0,0.0,-28.0,-1.0,-505.0,-10.0,-100.0,-15.0,-110.0,-10.0,-84.46228767253793,
2024-10-21T12:16:37.673069955Z,2024-10-21T12:16:37.672903531Z,10,2,38,A,B,2,233.68,27,130,166424,12574328,233.74,234.08,200,200,1,1,233.7,234.1,1200,100,1,1,233.68,234.13,27,400,1,1,233.66,234.15,1,30,1,1,233.58,234.17,505,1,2,1,233.53,234.41,10,600,1,2,233.5,234.43,100,105,1,2,233.45,234.5,15,63,1,4,233.4,234.75,110,1,2,1,233.39,234.79,10,2000,1,1,AAPL,0.0,0.0,0.0,27.0,1.0,505.0,10.0,100.0,15.0,110.0,10.0,84.36070509180192,
2024-10-21T12:16:41.311074051Z,2024-10-21T12:16:41.310907658Z,10,2,38,C,B,0,233.74,200,130,166393,12577924,233.7,234.08,1200,200,1,1,233.68,234.1,27,100,1,1,233.66,234.13,1,400,1,1,233.58,234.15,505,30,2,1,233.53,234.17,10,1,1,1,233.5,234.41,100,600,1,2,233.45,234.43,15,105,1,2,233.4,234.5,110,63,2,4,233.39,234.75,10,1,1,1,233.31,234.79,110,2000,2,1,AAPL,-200.0,-200.0,-1200.0,-27.0,-1.0,-505.0,-10.0,-100.0,-15.0,-110.0,-10.0,-164.43621701567045,
2024-10-21T12:16:41.311087986Z,2024-10-21T12:16:41.310921026Z,10,2,38,A,B,1,233.69,200,130,166960,12577925,233.7,234.08,1200,200,1,1,233.69,234.1,200,100,1,1,233.68,234.13,27,400,1,1,233.66,234.15,1,30,1,1,233.58,234.17,505,1,2,1,233.53,234.41,10,600,1,2,233.5,234.43,100,105,1,2,233.45,234.5,15,63,1,4,233.4,234.75,110,1,2,1,233.39,234.79,10,2000,1,1,AAPL,0.0,0.0,200.0,27.0,1.0,505.0,10.0,100.0,15.0,110.0,10.0,97.04393765757582,
2024-10-21T12:16:42.498174235Z,2024-10-21T12:16:42.498007357Z,10,2,38,A,A,5,234.25,100,130,166878,12578938,233.7,234.08,1200,200,1,1,233.69,234.1,200,100,1,1,233.68,234.13,27,400,1,1,233.66,234.15,1,30,1,1,233.58,234.17,505,1,2,1,233.53,234.25,10,100,1,1,233.5,234.41,100,600,1,2,233.45,234.43,15,105,1,2,233.4,234.5,110,63,2,4,233.39,234.75,10,1,1,1,AAPL,0.0,0.0,0.0,0.0,0.0,0.0,-600.0,-105.0,-63.0,-1.0,-2000.0,-243.10091950770615,
2024-10-21T12:16:44.366676689Z,2024-10-21T12:16:44.366509790Z,10,2,38,A,B,0,233.74,200,130,166899,12580824,233.74,234.08,200,200,1,1,233.7,234.1,1200,100,1,1,233.68,234.13,27,400,1,1,233.66,234.15,1,30,1,1,233.58,234.17,505,1,2,1,233.53,234.25,10,100,1,1,233.5,234.41,100,600,1,2,233.45,234.43,15,105,1,2,233.4,234.5,110,63,2,4,233.39,234.75,10,1,1,1,AAPL,200.0,200.0,1200.0,0.0,0.0,0.0,0.0,0.0,0.0,0.0,0.0,80.0755119238685,
2024-10-21T12:16:44.533960641Z,2024-10-21T12:16:44.533794596Z,10,2,38,A,A,0,233.9,18,130,166045,12580968,233.74,233.9,200,18,1,1,233.7,234.08,1200,200,1,1,233.68,234.1,27,100,1,1,233.66,234.13,1,400,1,1,233.58,234.15,505,30,2,1,233.53,234.17,10,1,1,1,233.5,234.25,100,100,1,1,233.45,234.41,15,600,1,2,233.4,234.43,110,105,2,2,233.39,234.5,10,63,1,4,AAPL,-200.0,-200.0,-100.0,-400.0,-30.0,-1.0,-100.0,-600.0,-105.0,-63.0,-1.0,-154.49903209907092,
2024-10-21T12:16:44.802698042Z,2024-10-21T12:16:44.802532155Z,10,2,38,C,A,4,234.15,30,130,165887,12581165,233.74,233.9,200,18,1,1,233.7,234.08,1200,200,1,1,233.68,234.1,27,100,1,1,233.66,234.13,1,400,1,1,233.58,234.17,505,1,2,1,233.53,234.25,10,100,1,1,233.5,234.41,100,600,1,2,233.45,234.43,15,105,1,2,233.4,234.5,110,63,2,4,233.39,234.75,10,1,1,1,AAPL,0.0,0.0,0.0,0.0,0.0,1.0,100.0,600.0,105.0,63.0,1.0,97.39595534183331,
2024-10-21T12:16:44.802744697Z,2024-10-21T12:16:44.802578420Z,10,2,38,A,A,3,234.11,27,130,166277,12581166,233.74,233.9,200,18,1,1,233.7,234.08,1200,200,1,1,233.68,234.1,27,100,1,1,233.66,234.11,1,27,1,1,233.58,234.13,505,400,2,1,233.53,234.17,10,1,1,1,233.5,234.25,100,100,1,1,233.45,234.41,15,600,1,2,233.4,234.43,110,105,2,2,233.39,234.5,10,63,1,4,AAPL,0.0,0.0,0.0,0.0,-400.0,-1.0,-100.0,-600.0,-105.0,-63.0,-1.0,-179.42677735148075,
2024-10-21T12:16:47.612405002Z,2024-10-21T12:16:47.612239006Z,10,2,38,A,A,1,234.08,200,130,165996,12583335,233.74,233.9,200,18,1,1,233.7,234.08,1200,400,1,2,233.68,234.1,27,100,1,1,233.66,234.11,1,27,1,1,233.58,234.13,505,400,2,1,233.53,234.17,10,1,1,1,233.5,234.25,100,100,1,1,233.45,234.41,15,600,1,2,233.4,234.43,110,105,2,2,233.39,234.5,10,63,1,4,AAPL,0.0,0.0,-200.0,0.0,0.0,0.0,0.0,0.0,0.0,0.0,0.0,-12.683232565773917,
2024-10-21T12:16:47.667042872Z,2024-10-21T12:16:47.666876898Z,10,2,38,C,A,1,234.08,200,130,165974,12583345,233.74,233.9,200,18,1,1,233.7,234.08,1200,200,1,1,233.68,234.1,27,100,1,1,233.66,234.11,1,27,1,1,233.58,234.13,505,400,2,1,233.53,234.17,10,1,1,1,233.5,234.25,100,100,1,1,233.45,234.41,15,600,1,2,233.4,234.43,110,105,2,2,233.39,234.5,10,63,1,4,AAPL,0.0,0.0,200.0,0.0,0.0,0.0,0.0,0.0,0.0,0.0,0.0,12.683232565773917,
2024-10-21T12:16:47.667056416Z,2024-10-21T12:16:47.666890051Z,10,2,38,A,A,1,234.04,200,130,166365,12583346,233.74,233.9,200,18,1,1,233.7,234.04,1200,200,1,1,233.68,234.1,27,100,1,1,233.66,234.11,1,27,1,1,233.58,234.13,505,400,2,1,233.53,234.17,10,1,1,1,233.5,234.25,100,100,1,1,233.45,234.41,15,600,1,2,233.4,234.43,110,105,2,2,233.39,234.5,10,63,1,4,AAPL,0.0,0.0,-200.0,0.0,0.0,0.0,0.0,0.0,0.0,0.0,0.0,-12.683232565773917,
2024-10-21T12:16:47.926963883Z,2024-10-21T12:16:47.926797838Z,10,2,38,C,B,0,233.74,200,130,166045,12583828,233.7,233.9,1200,18,1,1,233.68,234.04,27,200,1,1,233.66,234.1,1,100,1,1,233.58,234.11,505,27,2,1,233.53,234.13,10,400,1,1,233.5,234.17,100,1,1,1,233.45,234.25,15,100,1,1,233.4,234.41,110,600,2,2,233.39,234.43,10,105,1,2,233.31,234.5,110,63,2,4,AAPL,-200.0,-200.0,-1200.0,-27.0,-1.0,-505.0,-10.0,-100.0,-15.0,-110.0,-10.0,-164.43621701567045,
2024-10-21T12:16:47.926976599Z,2024-10-21T12:16:47.926810269Z,10,2,38,A,B,1,233.68,200,130,166330,12583829,233.7,233.9,1200,18,1,1,233.68,234.04,227,200,2,1,233.66,234.1,1,100,1,1,233.58,234.11,505,27,2,1,233.53,234.13,10,400,1,1,233.5,234.17,100,1,1,1,233.45,234.25,15,100,1,1,233.4,234.41,110,600,2,2,233.39,234.43,10,105,1,2,233.31,234.5,110,63,2,4,AAPL,0.0,0.0,200.0,0.0,0.0,0.0,0.0,0.0,0.0,0.0,0.0,12.683232565773917,
2024-10-21T12:16:48.065770361Z,2024-10-21T12:16:48.065603630Z,10,2,38,C,A,3,234.11,27,130,166731,12584067,233.7,233.9,1200,18,1,1,233.68,234.04,227,200,2,1,233.66,234.1,1,100,1,1,233.58,234.13,505,400,2,1,233.53,234.17,10,1,1,1,233.5,234.25,100,100,1,1,233.45,234.41,15,600,1,2,233.4,234.43,110,105,2,2,233.39,234.5,10,63,1,4,233.31,234.75,110,1,2,1,AAPL,0.0,0.0,0.0,0.0,400.0,1.0,100.0,600.0,105.0,63.0,1.0,179.42677735148075,
2024-10-21T12:16:48.065827712Z,2024-10-21T12:16:48.065661214Z,10,2,38,A,A,2,234.06,29,130,166498,12584068,233.7,233.9,1200,18,1,1,233.68,234.04,227,200,2,1,233.66,234.06,1,29,1,1,233.58,234.1,505,100,2,1,233.53,234.13,10,400,1,1,233.5,234.17,100,1,1,1,233.45,234.25,15,100,1,1,233.4,234.41,110,600,2,2,233.39,234.43,10,105,1,2,233.31,234.5,110,63,2,4,AAPL,0.0,0.0,0.0,-100.0,-400.0,-1.0,-100.0,-600.0,-105.0,-63.0,-1.0,-189.58503542508126,
2024-10-21T12:16:48.123133937Z,2024-10-21T12:16:48.122967378Z,10,2,38,A,A,1,234.01,200,130,166559,12584094,233.7,233.9,1200,18,1,1,233.68,234.01,227,200,2,1,233.66,234.06,1,29,1,1,233.58,234.1,505,100,2,1,233.53,234.13,10,400,1,1,233.5,234.17,100,1,1,1,233.45,234.25,15,100,1,1,233.4,234.41,110,600,2,2,233.39,234.43,10,105,1,2,233.31,234.5,110,63,2,4,AAPL,0.0,0.0,-200.0,0.0,0.0,0.0,0.0,0.0,0.0,0.0,0.0,-12.683232565773917,
2024-10-21T12:16:48.228533367Z,2024-10-21T12:16:48.228366485Z,10,2,38,A,A,1,234.01,200,130,166882,12584254,233.7,233.9,1200,18,1,1,233.68,234.01,227,400,2,2,233.66,234.06,1,29,1,1,233.58,234.1,505,100,2,1,233.53,234.13,10,400,1,1,233.5,234.17,100,1,1,1,233.45,234.25,15,100,1,1,233.4,234.41,110,600,2,2,233.39,234.43,10,105,1,2,233.31,234.5,110,63,2,4,AAPL,0.0,0.0,-200.0,0.0,0.0,0.0,0.0,0.0,0.0,0.0,0.0,-12.683232565773917,
2024-10-21T12:16:48.283326363Z,2024-10-21T12:16:48.283159712Z,10,2,38,C,A,1,234.01,200,130,166651,12584287,233.7,233.9,1200,18,1,1,233.68,234.01,227,200,2,1,233.66,234.06,1,29,1,1,233.58,234.1,505,100,2,1,233.53,234.13,10,400,1,1,233.5,234.17,100,1,1,1,233.45,234.25,15,100,1,1,233.4,234.41,110,600,2,2,233.39,234.43,10,105,1,2,233.31,234.5,110,63,2,4,AAPL,0.0,0.0,200.0,0.0,0.0,0.0,0.0,0.0,0.0,0.0,0.0,12.683232565773917,
2024-10-21T12:16:48.283339638Z,2024-10-21T12:16:48.283173265Z,10,2,38,A,A,1,233.98,200,130,166373,12584288,233.7,233.9,1200,18,1,1,233.68,233.98,227,200,2,1,233.66,234.06,1,29,1,1,233.58,234.1,505,100,2,1,233.53,234.13,10,400,1,1,233.5,234.17,100,1,1,1,233.45,234.25,15,100,1,1,233.4,234.41,110,600,2,2,233.39,234.43,10,105,1,2,233.31,234.5,110,63,2,4,AAPL,0.0,0.0,-200.0,0.0,0.0,0.0,0.0,0.0,0.0,0.0,0.0,-12.683232565773917,
2024-10-21T12:16:49.563943091Z,2024-10-21T12:16:49.563776410Z,10,2,38,C,A,0,233.9,18,130,166681,12585847,233.7,233.98,1200,200,1,1,233.68,234.06,227,29,2,1,233.66,234.1,1,100,1,1,233.58,234.13,505,400,2,1,233.53,234.17,10,1,1,1,233.5,234.25,100,100,1,1,233.45,234.41,15,600,1,2,233.4,234.43,110,105,2,2,233.39,234.5,10,63,1,4,233.31,234.75,110,1,2,1,AAPL,200.0,200.0,29.0,100.0,400.0,1.0,100.0,600.0,105.0,63.0,1.0,195.40022067634348,
2024-10-21T12:16:49.564921505Z,2024-10-21T12:16:49.564755651Z,10,2,38,C,B,1,233.68,200,130,165854,12585849,233.7,233.98,1200,200,1,1,233.68,234.06,27,29,1,1,233.66,234.1,1,100,1,1,233.58,234.13,505,400,2,1,233.53,234.17,10,1,1,1,233.5,234.25,100,100,1,1,233.45,234.41,15,600,1,2,233.4,234.43,110,105,2,2,233.39,234.5,10,63,1,4,233.31,234.75,110,1,2,1,AAPL,0.0,0.0,-200.0,0.0,0.0,0.0,0.0,0.0,0.0,0.0,0.0,-12.683232565773917,
2024-10-21T12:16:49.635290441Z,2024-10-21T12:16:49.635124163Z,10,2,38,C,A,0,233.98,200,130,166278,12585962,233.7,234.06,1200,29,1,1,233.68,234.1,27,100,1,1,233.66,234.13,1,400,1,1,233.58,234.17,505,1,2,1,233.53,234.25,10,100,1,1,233.5,234.41,100,600,1,2,233.45,234.43,15,105,1,2,233.4,234.5,110,63,2,4,233.39,234.75,10,1,1,1,233.31,234.79,110,2000,2,1,AAPL,29.0,29.0,100.0,400.0,1.0,100.0,600.0,105.0,63.0,1.0,2000.0,302.4959507706757,
2024-10-21T12:16:49.635302899Z,2024-10-21T12:16:49.635136826Z,10,2,38,A,A,0,234.04,400,130,166073,12585963,233.7,234.04,1200,400,1,1,233.68,234.06,27,29,1,1,233.66,234.1,1,100,1,1,233.58,234.13,505,400,2,1,233.53,234.17,10,1,1,1,233.5,234.25,100,100,1,1,233.45,234.41,15,600,1,2,233.4,234.43,110,105,2,2,233.39,234.5,10,63,1,4,233.31,234.75,110,1,2,1,AAPL,-29.0,-29.0,-100.0,-400.0,-1.0,-100.0,-600.0,-105.0,-63.0,-1.0,-2000.0,-302.4959507706757,
2024-10-21T12:16:49.635707853Z,2024-10-21T12:16:49.635541646Z,10,2,38,C,A,1,234.06,29,130,166207,12585964,233.7,234.04,1200,400,1,1,233.68,234.1,27,100,1,1,233.66,234.13,1,400,1,1,233.58,234.17,505,1,2,1,233.53,234.25,10,100,1,1,233.5,234.41,100,600,1,2,233.45,234.43,15,105,1,2,233.4,234.5,110,63,2,4,233.39,234.75,10,1,1,1,233.31,234.79,110,2000,2,1,AAPL,0.0,0.0,100.0,400.0,1.0,100.0,600.0,105.0,63.0,1.0,2000.0,301.9194138739381,
2024-10-21T12:16:49.635803361Z,2024-10-21T12:16:49.635636984Z,10,2,38,A,A,2,234.11,29,130,166377,12585965,233.7,234.04,1200,400,1,1,233.68,234.1,27,100,1,1,233.66,234.11,1,29,1,1,233.58,234.13,505,400,2,1,233.53,234.17,10,1,1,1,233.5,234.25,100,100,1,1,233.45,234.41,15,600,1,2,233.4,234.43,110,105,2,2,233.39,234.5,10,63,1,4,233.31,234.75,110,1,2,1,AAPL,0.0,0.0,0.0,-400.0,-1.0,-100.0,-600.0,-105.0,-63.0,-1.0,-2000.0,-295.5777975910511,
2024-10-21T12:16:49.669662206Z,2024-10-21T12:16:49.669495875Z,10,2,38,A,B,1,233.68,200,130,166331,12585982,233.7,234.04,1200,400,1,1,233.68,234.1,227,100,2,1,233.66,234.11,1,29,1,1,233.58,234.13,505,400,2,1,233.53,234.17,10,1,1,1,233.5,234.25,100,100,1,1,233.45,234.41,15,600,1,2,233.4,234.43,110,105,2,2,233.39,234.5,10,63,1,4,233.31,234.75,110,1,2,1,AAPL,0.0,0.0,200.0,0.0,0.0,0.0,0.0,0.0,0.0,0.0,0.0,12.683232565773917,
2024-10-21T12:16:49.706410056Z,2024-10-21T12:16:49.706243840Z,10,2,38,C,A,0,234.04,200,130,166216,12585991,233.7,234.04,1200,200,1,1,233.68,234.1,227,100,2,1,233.66,234.11,1,29,1,1,233.58,234.13,505,400,2,1,233.53,234.17,10,1,1,1,233.5,234.25,100,100,1,1,233.45,234.41,15,600,1,2,233.4,234.43,110,105,2,2,233.39,234.5,10,63,1,4,233.31,234.75,110,1,2,1,AAPL,200.0,200.0,0.0,0.0,0.0,0.0,0.0,0.0,0.0,0.0,0.0,3.9761165292250036,
2024-10-21T12:16:49.706607779Z,2024-10-21T12:16:49.706441749Z,10,2,38,C,A,0,234.04,200,130,166030,12585992,233.7,234.1,1200,100,1,1,233.68,234.11,227,29,2,1,233.66,234.13,1,400,1,1,233.58,234.17,505,1,2,1,233.53,234.25,10,100,1,1,233.5,234.41,100,600,1,2,233.45,234.43,15,105,1,2,233.4,234.5,110,63,2,4,233.39,234.75,10,1,1,1,233.31,234.79,110,2000,2,1,AAPL,100.0,100.0,29.0,400.0,1.0,100.0,600.0,105.0,63.0,1.0,2000.0,299.40492457770085,
2024-10-21T12:16:49.706619859Z,2024-10-21T12:16:49.706453582Z,10,2,38,A,A,0,234.09,200,130,166277,12585993,233.7,234.09,1200,200,1,1,233.68,234.1,227,100,2,1,233.66,234.11,1,29,1,1,233.58,234.13,505,400,2,1,233.53,234.17,10,1,1,1,233.5,234.25,100,100,1,1,233.45,234.41,15,600,1,2,233.4,234.43,110,105,2,2,233.39,234.5,10,63,1,4,233.31,234.75,110,1,2,1,AAPL,-100.0,-100.0,-29.0,-400.0,-1.0,-100.0,-600.0,-105.0,-63.0,-1.0,-2000.0,-299.40492457770085,
2024-10-21T12:16:49.707217404Z,2024-10-21T12:16:49.707051448Z,10,2,38,C,A,2,234.11,29,130,165956,12585994,233.7,234.09,1200,200,1,1,233.68,234.1,227,100,2,1,233.66,234.13,1,400,1,1,233.58,234.17,505,1,2,1,233.53,234.25,10,100,1,1,233.5,234.41,100,600,1,2,233.45,234.43,15,105,1,2,233.4,234.5,110,63,2,4,233.39,234.75,10,1,1,1,233.31,234.79,110,2000,2,1,AAPL,0.0,0.0,0.0,400.0,1.0,100.0,600.0,105.0,63.0,1.0,2000.0,295.5777975910511,
2024-10-21T12:16:49.709612912Z,2024-10-21T12:16:49.709446277Z,10,2,38,A,A,0,234.09,200,130,166635,12585999,233.7,234.09,1200,400,1,2,233.68,234.1,227,100,2,1,233.66,234.13,1,400,1,1,233.58,234.17,505,1,2,1,233.53,234.25,10,100,1,1,233.5,234.41,100,600,1,2,233.45,234.43,15,105,1,2,233.4,234.5,110,63,2,4,233.39,234.75,10,1,1,1,233.31,234.79,110,2000,2,1,AAPL,-200.0,-200.0,0.0,0.0,0.0,0.0,0.0,0.0,0.0,0.0,0.0,-3.9761165292250036,
2024-10-21T12:16:50.277429428Z,2024-10-21T12:16:50.277262708Z,10,2,38,C,B,1,233.68,27,130,166720,12586408,233.7,234.09,1200,400,1,2,233.68,234.1,200,100,1,1,233.66,234.13,1,400,1,1,233.58,234.17,505,1,2,1,233.53,234.25,10,100,1,1,233.5,234.41,100,600,1,2,233.45,234.43,15,105,1,2,233.4,234.5,110,63,2,4,233.39,234.75,10,1,1,1,233.31,234.79,110,2000,2,1,AAPL,0.0,0.0,-27.0,0.0,0.0,0.0,0.0,0.0,0.0,0.0,0.0,-1.7122363963794787,
2024-10-21T12:16:50.277516325Z,2024-10-21T12:16:50.277350058Z,10,2,38,A,A,3,234.17,27,130,166267,12586409,233.7,234.09,1200,400,1,2,233.68,234.1,200,100,1,1,233.66,234.13,1,400,1,1,233.58,234.17,505,28,2,2,233.53,234.25,10,100,1,1,233.5,234.41,100,600,1,2,233.45,234.43,15,105,1,2,233.4,234.5,110,63,2,4,233.39,234.75,10,1,1,1,233.31,234.79,110,2000,2,1,AAPL,0.0,0.0,0.0,0.0,-27.0,0.0,0.0,0.0,0.0,0.0,0.0,-5.5370804856512,
2024-10-21T12:16:50.277547866Z,2024-10-21T12:16:50.277381197Z,10,2,38,A,B,1,233.69,27,130,166669,12586410,233.7,234.09,1200,400,1,2,233.69,234.1,27,100,1,1,233.68,234.13,200,400,1,1,233.66,234.17,1,28,1,2,233.58,234.25,505,100,2,1,233.53,234.41,10,600,1,2,233.5,234.43,100,105,1,2,233.45,234.5,15,63,1,4,233.4,234.75,110,1,2,1,233.39,234.79,10,2000,1,1,AAPL,0.0,0.0,27.0,200.0,1.0,505.0,10.0,100.0,15.0,110.0,10.0,103.64672795551029,
2024-10-21T12:16:50.981625530Z,2024-10-21T12:16:50.981459165Z,10,2,38,A,B,0,233.7,200,130,166365,12587468,233.7,234.09,1400,400,2,2,233.69,234.1,27,100,1,1,233.66,234.13,1,400,1,1,233.58,234.17,505,28,2,2,233.53,234.25,10,100,1,1,233.5,234.41,100,600,1,2,233.45,234.43,15,105,1,2,233.4,234.5,110,63,2,4,233.39,234.75,10,1,1,1,233.31,234.79,110,2000,2,1,AAPL,200.0,200.0,0.0,-200.0,-1.0,-505.0,-10.0,-100.0,-15.0,-110.0,-10.0,-97.95837502990581,
2024-10-21T12:16:51.768939105Z,2024-10-21T12:16:51.768772781Z,10,2,38,A,B,0,233.85,141,130,166324,12588253,233.85,234.09,141,400,1,2,233.7,234.1,1400,100,2,1,233.69,234.13,27,400,1,1,233.66,234.17,1,28,1,2,233.58,234.25,505,100,2,1,233.53,234.41,10,600,1,2,233.5,234.43,100,105,1,2,233.45,234.5,15,63,1,4,233.4,234.75,110,1,2,1,233.39,234.79,10,2000,1,1,AAPL,141.0,141.0,1400.0,27.0,1.0,505.0,10.0,100.0,15.0,110.0,10.0,175.94649520532298,
2024-10-21T12:16:54.799926585Z,2024-10-21T12:16:54.799759269Z,10,2,38,T,N,0,233.86,13,130,167316,12591024,233.85,234.09,141,400,1,2,233.7,234.1,1400,100,2,1,233.69,234.13,27,400,1,1,233.66,234.17,1,28,1,2,233.58,234.25,505,100,2,1,233.53,234.41,10,600,1,2,233.5,234.43,100,105,1,2,233.45,234.5,15,63,1,4,233.4,234.75,110,1,2,1,233.39,234.79,10,2000,1,1,AAPL,0.0,0.0,0.0,0.0,0.0,0.0,0.0,0.0,0.0,0.0,0.0,0.0,
2024-10-21T12:16:54.862694065Z,2024-10-21T12:16:54.862528040Z,10,2,38,C,A,3,234.17,27,130,166025,12591058,233.85,234.09,141,400,1,2,233.7,234.1,1400,100,2,1,233.69,234.13,27,400,1,1,233.66,234.17,1,1,1,1,233.58,234.25,505,100,2,1,233.53,234.41,10,600,1,2,233.5,234.43,100,105,1,2,233.45,234.5,15,63,1,4,233.4,234.75,110,1,2,1,233.39,234.79,10,2000,1,1,AAPL,0.0,0.0,0.0,0.0,27.0,0.0,0.0,0.0,0.0,0.0,0.0,5.5370804856512,
2024-10-21T12:16:54.862819345Z,2024-10-21T12:16:54.862652964Z,10,2,38,A,A,3,234.16,30,130,166381,12591059,233.85,234.09,141,400,1,2,233.7,234.1,1400,100,2,1,233.69,234.13,27,400,1,1,233.66,234.16,1,30,1,1,233.58,234.17,505,1,2,1,233.53,234.25,10,100,1,1,233.5,234.41,100,600,1,2,233.45,234.43,15,105,1,2,233.4,234.5,110,63,2,4,233.39,234.75,10,1,1,1,AAPL,0.0,0.0,0.0,0.0,-1.0,-100.0,-600.0,-105.0,-63.0,-1.0,-2000.0,-254.94476529664902,
2024-10-21T12:17:02.456671669Z,2024-10-21T12:17:02.456505763Z,10,2,38,C,A,0,234.09,200,130,165906,12600010,233.85,234.09,141,200,1,1,233.7,234.1,1400,100,2,1,233.69,234.13,27,400,1,1,233.66,234.16,1,30,1,1,233.58,234.17,505,1,2,1,233.53,234.25,10,100,1,1,233.5,234.41,100,600,1,2,233.45,234.43,15,105,1,2,233.4,234.5,110,63,2,4,233.39,234.75,10,1,1,1,AAPL,200.0,200.0,0.0,0.0,0.0,0.0,0.0,0.0,0.0,0.0,0.0,3.9761165292250036,
2024-10-21T12:17:02.456684400Z,2024-10-21T12:17:02.456518211Z,10,2,38,A,A,0,234.08,400,130,166189,12600011,233.85,234.08,141,400,1,1,233.7,234.1,1400,100,2,1,233.69,234.13,27,400,1,1,233.66,234.16,1,30,1,1,233.58,234.17,505,1,2,1,233.53,234.25,10,100,1,1,233.5,234.41,100,600,1,2,233.45,234.43,15,105,1,2,233.4,234.5,110,63,2,4,233.39,234.75,10,1,1,1,AAPL,-200.0,-200.0,0.0,0.0,0.0,0.0,0.0,0.0,0.0,0.0,0.0,-3.9761165292250036,
2024-10-21T12:17:02.692870111Z,2024-10-21T12:17:02.692703742Z,10,2,38,A,B,1,233.7,200,130,166369,12600199,233.85,234.08,141,400,1,1,233.7,234.1,1600,100,3,1,233.69,234.13,27,400,1,1,233.66,234.16,1,30,1,1,233.58,234.17,505,1,2,1,233.53,234.25,10,100,1,1,233.5,234.41,100,600,1,2,233.45,234.43,15,105,1,2,233.4,234.5,110,63,2,4,233.39,234.75,10,1,1,1,AAPL,0.0,0.0,200.0,0.0,0.0,0.0,0.0,0.0,0.0,0.0,0.0,12.683232565773917,
2024-10-21T12:17:02.695901737Z,2024-10-21T12:17:02.695735412Z,10,2,38,A,B,1,233.73,27,130,166325,12600202,233.85,234.08,141,400,1,1,233.73,234.1,27,100,1,1,233.7,234.13,1600,400,3,1,233.69,234.16,27,30,1,1,233.66,234.17,1,1,1,1,233.58,234.25,505,100,2,1,233.53,234.41,10,600,1,2,233.5,234.43,100,105,1,2,233.45,234.5,15,63,1,4,233.4,234.75,110,1,2,1,AAPL,0.0,0.0,27.0,1600.0,27.0,1.0,505.0,10.0,100.0,15.0,110.0,259.58649397553893,
2024-10-21T12:17:02.695928779Z,2024-10-21T12:17:02.695762734Z,10,2,38,C,B,3,233.69,27,130,166045,12600203,233.85,234.08,141,400,1,1,233.73,234.1,27,100,1,1,233.7,234.13,1600,400,3,1,233.66,234.16,1,30,1,1,233.58,234.17,505,1,2,1,233.53,234.25,10,100,1,1,233.5,234.41,100,600,1,2,233.45,234.43,15,105,1,2,233.4,234.5,110,63,2,4,233.39,234.75,10,1,1,1,AAPL,0.0,0.0,0.0,0.0,-27.0,-1.0,-505.0,-10.0,-100.0,-15.0,-110.0,-95.34212840155115,
2024-10-21T12:17:02.744107650Z,2024-10-21T12:17:02.743941560Z,10,2,38,C,B,2,233.7,200,130,166090,12600243,233.85,234.08,141,400,1,1,233.73,234.1,27,100,1,1,233.7,234.13,1400,400,2,1,233.66,234.16,1,30,1,1,233.58,234.17,505,1,2,1,233.53,234.25,10,100,1,1,233.5,234.41,100,600,1,2,233.45,234.43,15,105,1,2,233.4,234.5,110,63,2,4,233.39,234.75,10,1,1,1,AAPL,0.0,0.0,0.0,-200.0,0.0,0.0,0.0,0.0,0.0,0.0,0.0,-20.31651614720104,
2024-10-21T12:17:02.744120623Z,2024-10-21T12:17:02.743954174Z,10,2,38,A,B,1,233.77,200,130,166449,12600244,233.85,234.08,141,400,1,1,233.77,234.1,200,100,1,1,233.73,234.13,27,400,1,1,233.7,234.16,1200,30,1,1,233.66,234.17,1,1,1,1,233.58,234.25,505,100,2,1,233.53,234.41,10,600,1,2,233.5,234.43,100,105,1,2,233.45,234.5,15,63,1,4,233.4,234.75,110,1,2,1,AAPL,0.0,0.0,200.0,27.0,1200.0,1.0,505.0,10.0,100.0,15.0,110.0,351.3234761904883,
2024-10-21T12:17:04.308892470Z,2024-10-21T12:17:04.308725875Z,10,2,38,C,A,3,234.16,30,130,166595,12602099,233.85,234.08,141,400,1,1,233.77,234.1,200,100,1,1,233.73,234.13,27,400,1,1,233.7,234.17,1200,1,1,1,233.66,234.25,1,100,1,1,233.58,234.41,505,600,2,2,233.53,234.43,10,105,1,2,233.5,234.5,100,63,1,4,233.45,234.75,15,1,1,1,233.4,234.79,110,2000,2,1,AAPL,0.0,0.0,0.0,0.0,1.0,100.0,600.0,105.0,63.0,1.0,2000.0,254.94476529664902,
2024-10-21T12:17:04.308942951Z,2024-10-21T12:17:04.308776780Z,10,2,38,A,A,3,234.15,26,130,166171,12602100,233.85,234.08,141,400,1,1,233.77,234.1,200,100,1,1,233.73,234.13,27,400,1,1,233.7,234.15,1200,26,1,1,233.66,234.17,1,1,1,1,233.58,234.25,505,100,2,1,233.53,234.41,10,600,1,2,233.5,234.43,100,105,1,2,233.45,234.5,15,63,1,4,233.4,234.75,110,1,2,1,AAPL,0.0,0.0,0.0,0.0,-1.0,-100.0,-600.0,-105.0,-63.0,-1.0,-2000.0,-254.94476529664902,
2024-10-21T12:17:06.048460890Z,2024-10-21T12:17:06.048294911Z,10,2,38,C,B,1,233.77,200,130,165979,12604816,233.85,234.08,141,400,1,1,233.73,234.1,27,100,1,1,233.7,234.13,1200,400,1,1,233.66,234.15,1,26,1,1,233.58,234.17,505,1,2,1,233.53,234.25,10,100,1,1,233.5,234.41,100,600,1,2,233.45,234.43,15,105,1,2,233.4,234.5,110,63,2,4,233.39,234.75,10,1,1,1,AAPL,0.0,0.0,-200.0,-27.0,-1200.0,-1.0,-505.0,-10.0,-100.0,-15.0,-110.0,-351.3234761904883,
2024-10-21T12:17:06.048474822Z,2024-10-21T12:17:06.048308319Z,10,2,38,A,B,1,233.74,200,130,166503,12604817,233.85,234.08,141,400,1,1,233.74,234.1,200,100,1,1,233.73,234.13,27,400,1,1,233.7,234.15,1200,26,1,1,233.66,234.17,1,1,1,1,233.58,234.25,505,100,2,1,233.53,234.41,10,600,1,2,233.5,234.43,100,105,1,2,233.45,234.5,15,63,1,4,233.4,234.75,110,1,2,1,AAPL,0.0,0.0,200.0,27.0,1200.0,1.0,505.0,10.0,100.0,15.0,110.0,351.3234761904883,
2024-10-21T12:17:07.404034239Z,2024-10-21T12:17:07.403868087Z,10,2,38,A,B,1,233.74,200,130,166152,12606471,233.85,234.08,141,400,1,1,233.74,234.1,400,100,2,1,233.73,234.13,27,400,1,1,233.7,234.15,1200,26,1,1,233.66,234.17,1,1,1,1,233.58,234.25,505,100,2,1,233.53,234.41,10,600,1,2,233.5,234.43,100,105,1,2,233.45,234.5,15,63,1,4,233.4,234.75,110,1,2,1,AAPL,0.0,0.0,200.0,0.0,0.0,0.0,0.0,0.0,0.0,0.0,0.0,12.683232565773917,
2024-10-21T12:17:07.458838488Z,2024-10-21T12:17:07.458672320Z,10,2,38,C,B,1,233.74,200,130,166168,12606559,233.85,234.08,141,400,1,1,233.74,234.1,200,100,1,1,233.73,234.13,27,400,1,1,233.7,234.15,1200,26,1,1,233.66,234.17,1,1,1,1,233.58,234.25,505,100,2,1,233.53,234.41,10,600,1,2,233.5,234.43,100,105,1,2,233.45,234.5,15,63,1,4,233.4,234.75,110,1,2,1,AAPL,0.0,0.0,-200.0,0.0,0.0,0.0,0.0,0.0,0.0,0.0,0.0,-12.683232565773917,
2024-10-21T12:17:07.458851802Z,2024-10-21T12:17:07.458684918Z,10,2,38,A,B,1,233.77,200,130,166884,12606560,233.85,234.08,141,400,1,1,233.77,234.1,200,100,1,1,233.73,234.13,27,400,1,1,233.7,234.15,1200,26,1,1,233.66,234.17,1,1,1,1,233.58,234.25,505,100,2,1,233.53,234.41,10,600,1,2,233.5,234.43,100,105,1,2,233.45,234.5,15,63,1,4,233.4,234.75,110,1,2,1,AAPL,0.0,0.0,200.0,0.0,0.0,0.0,0.0,0.0,0.0,0.0,0.0,12.683232565773917,
2024-10-21T12:17:10.980236242Z,2024-10-21T12:17:10.980069944Z,10,2,38,C,B,1,233.77,200,130,166298,12610019,233.85,234.08,141,400,1,1,233.73,234.1,27,100,1,1,233.7,234.13,1200,400,1,1,233.66,234.15,1,26,1,1,233.58,234.17,505,1,2,1,233.53,234.25,10,100,1,1,233.5,234.41,100,600,1,2,233.45,234.43,15,105,1,2,233.4,234.5,110,63,2,4,233.39,234.75,10,1,1,1,AAPL,0.0,0.0,-200.0,-27.0,-1200.0,-1.0,-505.0,-10.0,-100.0,-15.0,-110.0,-351.3234761904883,
2024-10-21T12:17:10.980249439Z,2024-10-21T12:17:10.980083268Z,10,2,38,A,B,1,233.74,200,130,166171,12610020,233.85,234.08,141,400,1,1,233.74,234.1,200,100,1,1,233.73,234.13,27,400,1,1,233.7,234.15,1200,26,1,1,233.66,234.17,1,1,1,1,233.58,234.25,505,100,2,1,233.53,234.41,10,600,1,2,233.5,234.43,100,105,1,2,233.45,234.5,15,63,1,4,233.4,234.75,110,1,2,1,AAPL,0.0,0.0,200.0,27.0,1200.0,1.0,505.0,10.0,100.0,15.0,110.0,351.3234761904883,
2024-10-21T12:17:16.047057825Z,2024-10-21T12:17:16.046891679Z,10,2,38,A,B,1,233.74,200,130,166146,12615898,233.85,234.08,141,400,1,1,233.74,234.1,400,100,2,1,233.73,234.13,27,400,1,1,233.7,234.15,1200,26,1,1,233.66,234.17,1,1,1,1,233.58,234.25,505,100,2,1,233.53,234.41,10,600,1,2,233.5,234.43,100,105,1,2,233.45,234.5,15,63,1,4,233.4,234.75,110,1,2,1,AAPL,0.0,0.0,200.0,0.0,0.0,0.0,0.0,0.0,0.0,0.0,0.0,12.683232565773917,
2024-10-21T12:17:16.101486118Z,2024-10-21T12:17:16.101320234Z,10,2,38,C,B,1,233.74,200,130,165884,12616034,233.85,234.08,141,400,1,1,233.74,234.1,200,100,1,1,233.73,234.13,27,400,1,1,233.7,234.15,1200,26,1,1,233.66,234.17,1,1,1,1,233.58,234.25,505,100,2,1,233.53,234.41,10,600,1,2,233.5,234.43,100,105,1,2,233.45,234.5,15,63,1,4,233.4,234.75,110,1,2,1,AAPL,0.0,0.0,-200.0,0.0,0.0,0.0,0.0,0.0,0.0,0.0,0.0,-12.683232565773917,
2024-10-21T12:17:16.101498861Z,2024-10-21T12:17:16.101332500Z,10,2,38,A,B,1,233.77,200,130,166361,12616035,233.85,234.08,141,400,1,1,233.77,234.1,200,100,1,1,233.73,234.13,27,400,1,1,233.7,234.15,1200,26,1,1,233.66,234.17,1,1,1,1,233.58,234.25,505,100,2,1,233.53,234.41,10,600,1,2,233.5,234.43,100,105,1,2,233.45,234.5,15,63,1,4,233.4,234.75,110,1,2,1,AAPL,0.0,0.0,200.0,0.0,0.0,0.0,0.0,0.0,0.0,0.0,0.0,12.683232565773917,
2024-10-21T12:17:18.814393783Z,2024-10-21T12:17:18.814227520Z,10,2,38,A,B,0,233.9,10,130,166263,12619312,233.9,234.08,10,400,1,1,233.85,234.1,141,100,1,1,233.77,234.13,200,400,1,1,233.73,234.15,27,26,1,1,233.7,234.17,1200,1,1,1,233.66,234.25,1,100,1,1,233.58,234.41,505,600,2,2,233.53,234.43,10,105,1,2,233.5,234.5,100,63,1,4,233.45,234.75,15,1,1,1,AAPL,10.0,10.0,141.0,200.0,27.0,1200.0,1.0,505.0,10.0,100.0,15.0,241.38258209303027,
2024-10-21T12:17:20.656989311Z,2024-10-21T12:17:20.656823195Z,10,2,38,C,B,2,233.77,200,130,166116,12621045,233.9,234.08,10,400,1,1,233.85,234.1,141,100,1,1,233.73,234.13,27,400,1,1,233.7,234.15,1200,26,1,1,233.66,234.17,1,1,1,1,233.58,234.25,505,100,2,1,233.53,234.41,10,600,1,2,233.5,234.43,100,105,1,2,233.45,234.5,15,63,1,4,233.4,234.75,110,1,2,1,AAPL,0.0,0.0,0.0,-200.0,-27.0,-1200.0,-1.0,-505.0,-10.0,-100.0,-15.0,-232.2420973076984,
2024-10-21T12:17:20.662449680Z,2024-10-21T12:17:20.662283454Z,10,2,38,A,A,0,234.05,100,130,166226,12621054,233.9,234.05,10,100,1,1,233.85,234.08,141,400,1,1,233.73,234.1,27,100,1,1,233.7,234.13,1200,400,1,1,233.66,234.15,1,26,1,1,233.58,234.17,505,1,2,1,233.53,234.25,10,100,1,1,233.5,234.41,100,600,1,2,233.45,234.43,15,105,1,2,233.4,234.5,110,63,2,4,AAPL,-400.0,-400.0,-100.0,-400.0,-26.0,-1.0,-100.0,-600.0,-105.0,-63.0,-1.0,-157.65484040819945,
2024-10-21T12:17:20.662910009Z,2024-10-21T12:17:20.662744252Z,10,2,38,C,A,0,234.05,100,130,165757,12621055,233.9,234.08,10,400,1,1,233.85,234.1,141,100,1,1,233.73,234.13,27,400,1,1,233.7,234.15,1200,26,1,1,233.66,234.17,1,1,1,1,233.58,234.25,505,100,2,1,233.53,234.41,10,600,1,2,233.5,234.43,100,105,1,2,233.45,234.5,15,63,1,4,233.4,234.75,110,1,2,1,AAPL,400.0,400.0,100.0,400.0,26.0,1.0,100.0,600.0,105.0,63.0,1.0,157.65484040819945,
2024-10-21T12:17:20.719927826Z,2024-10-21T12:17:20.719761250Z,10,2,38,C,A,0,234.08,200,130,166576,12621104,233.9,234.08,10,200,1,1,233.85,234.1,141,100,1,1,233.73,234.13,27,400,1,1,233.7,234.15,1200,26,1,1,233.66,234.17,1,1,1,1,233.58,234.25,505,100,2,1,233.53,234.41,10,600,1,2,233.5,234.43,100,105,1,2,233.45,234.5,15,63,1,4,233.4,234.75,110,1,2,1,AAPL,200.0,200.0,0.0,0.0,0.0,0.0,0.0,0.0,0.0,0.0,0.0,3.9761165292250036,
2024-10-21T12:17:20.762706336Z,2024-10-21T12:17:20.762539880Z,10,2,38,A,B,2,233.77,200,130,166456,12621151,233.9,234.08,10,200,1,1,233.85,234.1,141,100,1,1,233.77,234.13,200,400,1,1,233.73,234.15,27,26,1,1,233.7,234.17,1200,1,1,1,233.66,234.25,1,100,1,1,233.58,234.41,505,600,2,2,233.53,234.43,10,105,1,2,233.5,234.5,100,63,1,4,233.45,234.75,15,1,1,1,AAPL,0.0,0.0,0.0,200.0,27.0,1200.0,1.0,505.0,10.0,100.0,15.0,232.2420973076984,
2024-10-21T12:17:21.079070269Z,2024-10-21T12:17:21.078904005Z,10,2,38,A,B,2,233.77,200,130,166264,12621965,233.9,234.08,10,200,1,1,233.85,234.1,141,100,1,1,233.77,234.13,400,400,2,1,233.73,234.15,27,26,1,1,233.7,234.17,1200,1,1,1,233.66,234.25,1,100,1,1,233.58,234.41,505,600,2,2,233.53,234.43,10,105,1,2,233.5,234.5,100,63,1,4,233.45,234.75,15,1,1,1,AAPL,0.0,0.0,0.0,200.0,0.0,0.0,0.0,0.0,0.0,0.0,0.0,20.31651614720104,
2024-10-21T12:17:21.133776008Z,2024-10-21T12:17:21.133609901Z,10,2,38,C,B,2,233.77,200,130,166107,12622031,233.9,234.08,10,200,1,1,233.85,234.1,141,100,1,1,233.77,234.13,200,400,1,1,233.73,234.15,27,26,1,1,233.7,234.17,1200,1,1,1,233.66,234.25,1,100,1,1,233.58,234.41,505,600,2,2,233.53,234.43,10,105,1,2,233.5,234.5,100,63,1,4,233.45,234.75,15,1,1,1,AAPL,0.0,0.0,0.0,-200.0,0.0,0.0,0.0,0.0,0.0,0.0,0.0,-20.31651614720104,
2024-10-21T12:17:21.133789577Z,2024-10-21T12:17:21.133623109Z,10,2,38,A,B,2,233.8,400,130,166468,12622032,233.9,234.08,10,200,1,1,233.85,234.1,141,100,1,1,233.8,234.13,400,400,1,1,233.73,234.15,27,26,1,1,233.7,234.17,1200,1,1,1,233.66,234.25,1,100,1,1,233.58,234.41,505,600,2,2,233.53,234.43,10,105,1,2,233.5,234.5,100,63,1,4,233.45,234.75,15,1,1,1,AAPL,0.0,0.0,0.0,400.0,0.0,0.0,0.0,0.0,0.0,0.0,0.0,40.63303229440208,
2024-10-21T12:17:21.840377137Z,2024-10-21T12:17:21.840211165Z,10,2,38,C,A,0,234.08,200,130,165972,12622599,233.9,234.1,10,100,1,1,233.85,234.13,141,400,1,1,233.8,234.15,400,26,1,1,233.73,234.17,27,1,1,1,233.7,234.25,1200,100,1,1,233.66,234.41,1,600,1,2,233.58,234.43,505,105,2,2,233.53,234.5,10,63,1,4,233.5,234.75,100,1,1,1,233.45,234.79,15,2000,1,1,AAPL,100.0,100.0,400.0,26.0,1.0,100.0,600.0,105.0,63.0,1.0,2000.0,284.9404357919455,
2024-10-21T12:17:21.840390874Z,2024-10-21T12:17:21.840224418Z,10,2,38,A,A,2,234.14,200,130,166456,12622600,233.9,234.1,10,100,1,1,233.85,234.13,141,400,1,1,233.8,234.14,400,200,1,1,233.73,234.15,27,26,1,1,233.7,234.17,1200,1,1,1,233.66,234.25,1,100,1,1,233.58,234.41,505,600,2,2,233.53,234.43,10,105,1,2,233.5,234.5,100,63,1,4,233.45,234.75,15,1,1,1,AAPL,0.0,0.0,0.0,-26.0,-1.0,-100.0,-600.0,-105.0,-63.0,-1.0,-2000.0,-257.58591239578516,
2024-10-21T12:17:22.072471402Z,2024-10-21T12:17:22.072304747Z,10,2,38,A,A,1,234.13,200,130,166655,12622909,233.9,234.1,10,100,1,1,233.85,234.13,141,600,1,2,233.8,234.15,400,26,1,1,233.73,234.17,27,1,1,1,233.7,234.25,1200,100,1,1,233.66,234.41,1,600,1,2,233.58,234.43,505,105,2,2,233.53,234.5,10,63,1,4,233.5,234.75,100,1,1,1,233.45,234.79,15,2000,1,1,AAPL,0.0,0.0,-200.0,26.0,1.0,100.0,600.0,105.0,63.0,1.0,2000.0,244.90267983001124,
2024-10-21T12:17:22.085874150Z,2024-10-21T12:17:22.085707892Z,10,2,38,A,A,0,234.0,50,130,166258,12622918,233.9,234.0,10,50,1,1,233.85,234.1,141,100,1,1,233.8,234.13,400,600,1,2,233.73,234.15,27,26,1,1,233.7,234.17,1200,1,1,1,233.66,234.25,1,100,1,1,233.58,234.41,505,600,2,2,233.53,234.43,10,105,1,2,233.5,234.5,100,63,1,4,233.45,234.75,15,1,1,1,AAPL,-100.0,-100.0,-600.0,-26.0,-1.0,-100.0,-600.0,-105.0,-63.0,-1.0,-2000.0,-297.62366835771945,
2024-10-21T12:17:24.840534781Z,2024-10-21T12:17:24.840366131Z,10,2,38,A,A,2,234.13,200,130,168650,12624574,233.9,234.0,10,50,1,1,233.85,234.1,141,100,1,1,233.8,234.13,400,800,1,3,233.73,234.15,27,26,1,1,233.7,234.17,1200,1,1,1,233.66,234.25,1,100,1,1,233.58,234.41,505,600,2,2,233.53,234.43,10,105,1,2,233.5,234.5,100,63,1,4,233.45,234.75,15,1,1,1,AAPL,0.0,0.0,0.0,-200.0,0.0,0.0,0.0,0.0,0.0,0.0,0.0,-20.31651614720104,
2024-10-21T12:17:24.840961517Z,2024-10-21T12:17:24.840795392Z,10,2,38,A,A,1,234.1,28,130,166125,12624575,233.9,234.0,10,50,1,1,233.85,234.1,141,128,1,2,233.8,234.13,400,800,1,3,233.73,234.15,27,26,1,1,233.7,234.17,1200,1,1,1,233.66,234.25,1,100,1,1,233.58,234.41,505,600,2,2,233.53,234.43,10,105,1,2,233.5,234.5,100,63,1,4,233.45,234.75,15,1,1,1,AAPL,0.0,0.0,-28.0,0.0,0.0,0.0,0.0,0.0,0.0,0.0,0.0,-1.7756525592083483,
2024-10-21T12:17:24.840987330Z,2024-10-21T12:17:24.840821231Z,10,2,38,C,A,3,234.15,26,130,166099,12624576,233.9,234.0,10,50,1,1,233.85,234.1,141,128,1,2,233.8,234.13,400,800,1,3,233.73,234.17,27,1,1,1,233.7,234.25,1200,100,1,1,233.66,234.41,1,600,1,2,233.58,234.43,505,105,2,2,233.53,234.5,10,63,1,4,233.5,234.75,100,1,1,1,233.45,234.79,15,2000,1,1,AAPL,0.0,0.0,0.0,0.0,1.0,100.0,600.0,105.0,63.0,1.0,2000.0,254.94476529664902,
2024-10-21T12:17:24.896181576Z,2024-10-21T12:17:24.896015668Z,10,2,38,C,A,2,234.13,200,130,165908,12624585,233.9,234.0,10,50,1,1,233.85,234.1,141,128,1,2,233.8,234.13,400,600,1,2,233.73,234.17,27,1,1,1,233.7,234.25,1200,100,1,1,233.66,234.41,1,600,1,2,233.58,234.43,505,105,2,2,233.53,234.5,10,63,1,4,233.5,234.75,100,1,1,1,233.45,234.79,15,2000,1,1,AAPL,0.0,0.0,0.0,200.0,0.0,0.0,0.0,0.0,0.0,0.0,0.0,20.31651614720104,
2024-10-21T12:17:24.896197156Z,2024-10-21T12:17:24.896030774Z,10,2,38,A,A,1,234.04,200,130,166382,12624586,233.9,234.0,10,50,1,1,233.85,234.04,141,200,1,1,233.8,234.1,400,128,1,2,233.73,234.13,27,400,1,1,233.7,234.17,1200,1,1,1,233.66,234.25,1,100,1,1,233.58,234.41,505,600,2,2,233.53,234.43,10,105,1,2,233.5,234.5,100,63,1,4,233.45,234.75,15,1,1,1,AAPL,0.0,0.0,-128.0,-600.0,-1.0,-100.0,-600.0,-105.0,-63.0,-1.0,-2000.0,-324.0115825803474,
2024-10-21T12:17:26.219893772Z,2024-10-21T12:17:26.219727754Z,10,2,38,C,A,2,234.1,28,130,166018,12625936,233.9,234.0,10,50,1,1,233.85,234.04,141,200,1,1,233.8,234.1,400,100,1,1,233.73,234.13,27,400,1,1,233.7,234.17,1200,1,1,1,233.66,234.25,1,100,1,1,233.58,234.41,505,600,2,2,233.53,234.43,10,105,1,2,233.5,234.5,100,63,1,4,233.45,234.75,15,1,1,1,AAPL,0.0,0.0,0.0,28.0,0.0,0.0,0.0,0.0,0.0,0.0,0.0,2.8443122606081452,
2024-10-21T12:17:26.219990353Z,2024-10-21T12:17:26.219824269Z,10,2,38,A,A,2,234.09,27,130,166084,12625937,233.9,234.0,10,50,1,1,233.85,234.04,141,200,1,1,233.8,234.09,400,27,1,1,233.73,234.1,27,100,1,1,233.7,234.13,1200,400,1,1,233.66,234.17,1,1,1,1,233.58,234.25,505,100,2,1,233.53,234.41,10,600,1,2,233.5,234.43,100,105,1,2,233.45,234.5,15,63,1,4,AAPL,0.0,0.0,0.0,-100.0,-400.0,-1.0,-100.0,-600.0,-105.0,-63.0,-1.0,-189.58503542508126,
2024-10-21T12:17:26.287111991Z,2024-10-21T12:17:26.286945437Z,10,2,38,A,A,1,234.03,200,130,166554,12626109,233.9,234.0,10,50,1,1,233.85,234.03,141,200,1,1,233.8,234.09,400,27,1,1,233.73,234.1,27,100,1,1,233.7,234.13,1200,400,1,1,233.66,234.17,1,1,1,1,233.58,234.25,505,100,2,1,233.53,234.41,10,600,1,2,233.5,234.43,100,105,1,2,233.45,234.5,15,63,1,4,AAPL,0.0,0.0,-200.0,0.0,0.0,0.0,0.0,0.0,0.0,0.0,0.0,-12.683232565773917,
2024-10-21T12:17:30.761811610Z,2024-10-21T12:17:30.761645371Z,10,2,38,C,A,1,234.03,200,130,166239,12633053,233.9,234.0,10,50,1,1,233.85,234.09,141,27,1,1,233.8,234.1,400,100,1,1,233.73,234.13,27,400,1,1,233.7,234.17,1200,1,1,1,233.66,234.25,1,100,1,1,233.58,234.41,505,600,2,2,233.53,234.43,10,105,1,2,233.5,234.5,100,63,1,4,233.45,234.75,15,1,1,1,AAPL,0.0,0.0,27.0,100.0,400.0,1.0,100.0,600.0,105.0,63.0,1.0,191.29727182146073,
2024-10-21T12:17:30.761824012Z,2024-10-21T12:17:30.761657680Z,10,2,38,A,A,1,234.08,200,130,166332,12633054,233.9,234.0,10,50,1,1,233.85,234.08,141,200,1,1,233.8,234.09,400,27,1,1,233.73,234.1,27,100,1,1,233.7,234.13,1200,400,1,1,233.66,234.17,1,1,1,1,233.58,234.25,505,100,2,1,233.53,234.41,10,600,1,2,233.5,234.43,100,105,1,2,233.45,234.5,15,63,1,4,AAPL,0.0,0.0,-27.0,-100.0,-400.0,-1.0,-100.0,-600.0,-105.0,-63.0,-1.0,-191.29727182146073,
2024-10-21T12:17:30.763106554Z,2024-10-21T12:17:30.762940179Z,10,2,38,A,A,1,234.08,200,130,166375,12633055,233.9,234.0,10,50,1,1,233.85,234.08,141,400,1,2,233.8,234.09,400,27,1,1,233.73,234.1,27,100,1,1,233.7,234.13,1200,400,1,1,233.66,234.17,1,1,1,1,233.58,234.25,505,100,2,1,233.53,234.41,10,600,1,2,233.5,234.43,100,105,1,2,233.45,234.5,15,63,1,4,AAPL,0.0,0.0,-200.0,0.0,0.0,0.0,0.0,0.0,0.0,0.0,0.0,-12.683232565773917,
2024-10-21T12:17:30.764758511Z,2024-10-21T12:17:30.764592400Z,10,2,38,C,A,2,234.09,27,130,166111,12633057,233.9,234.0,10,50,1,1,233.85,234.08,141,400,1,2,233.8,234.1,400,100,1,1,233.73,234.13,27,400,1,1,233.7,234.17,1200,1,1,1,233.66,234.25,1,100,1,1,233.58,234.41,505,600,2,2,233.53,234.43,10,105,1,2,233.5,234.5,100,63,1,4,233.45,234.75,15,1,1,1,AAPL,0.0,0.0,0.0,100.0,400.0,1.0,100.0,600.0,105.0,63.0,1.0,189.58503542508126,
2024-10-21T12:17:30.764858610Z,2024-10-21T12:17:30.764692359Z,10,2,38,A,A,4,234.15,29,130,166251,12633058,233.9,234.0,10,50,1,1,233.85,234.08,141,400,1,2,233.8,234.1,400,100,1,1,233.73,234.13,27,400,1,1,233.7,234.15,1200,29,1,1,233.66,234.17,1,1,1,1,233.58,234.25,505,100,2,1,233.53,234.41,10,600,1,2,233.5,234.43,100,105,1,2,233.45,234.5,15,63,1,4,AAPL,0.0,0.0,0.0,0.0,0.0,-1.0,-100.0,-600.0,-105.0,-63.0,-1.0,-97.39595534183331,
2024-10-21T12:17:33.378449675Z,2024-10-21T12:17:33.378283593Z,10,2,38,C,B,2,233.8,400,130,166082,12636437,233.9,234.0,10,50,1,1,233.85,234.08,141,400,1,2,233.73,234.1,27,100,1,1,233.7,234.13,1200,400,1,1,233.66,234.15,1,29,1,1,233.58,234.17,505,1,2,1,233.53,234.25,10,100,1,1,233.5,234.41,100,600,1,2,233.45,234.43,15,105,1,2,233.4,234.5,110,63,2,4,AAPL,0.0,0.0,0.0,-400.0,-27.0,-1200.0,-1.0,-505.0,-10.0,-100.0,-15.0,-252.55861345489944,
2024-10-21T12:17:33.378463077Z,2024-10-21T12:17:33.378297030Z,10,2,38,A,B,2,233.77,200,130,166047,12636438,233.9,234.0,10,50,1,1,233.85,234.08,141,400,1,2,233.77,234.1,200,100,1,1,233.73,234.13,27,400,1,1,233.7,234.15,1200,29,1,1,233.66,234.17,1,1,1,1,233.58,234.25,505,100,2,1,233.53,234.41,10,600,1,2,233.5,234.43,100,105,1,2,233.45,234.5,15,63,1,4,AAPL,0.0,0.0,0.0,200.0,27.0,1200.0,1.0,505.0,10.0,100.0,15.0,232.2420973076984,
2024-10-21T12:17:33.764976450Z,2024-10-21T12:17:33.764809990Z,10,2,38,A,A,2,234.09,29,130,166460,12637750,233.9,234.0,10,50,1,1,233.85,234.08,141,400,1,2,233.77,234.09,200,29,1,1,233.73,234.1,27,100,1,1,233.7,234.13,1200,400,1,1,233.66,234.15,1,29,1,1,233.58,234.17,505,1,2,1,233.53,234.25,10,100,1,1,233.5,234.41,100,600,1,2,233.45,234.43,15,105,1,2,AAPL,0.0,0.0,0.0,-100.0,-400.0,-29.0,-1.0,-100.0,-600.0,-105.0,-63.0,-179.82528506633452,
2024-10-21T12:17:33.765000603Z,2024-10-21T12:17:33.764834502Z,10,2,38,C,A,5,234.15,29,130,166101,12637751,233.9,234.0,10,50,1,1,233.85,234.08,141,400,1,2,233.77,234.09,200,29,1,1,233.73,234.1,27,100,1,1,233.7,234.13,1200,400,1,1,233.66,234.17,1,1,1,1,233.58,234.25,505,100,2,1,233.53,234.41,10,600,1,2,233.5,234.43,100,105,1,2,233.45,234.5,15,63,1,4,AAPL,0.0,0.0,0.0,0.0,0.0,0.0,1.0,100.0,600.0,105.0,63.0,84.26096205025011,
2024-10-21T12:17:33.822988558Z,2024-10-21T12:17:33.822822391Z,10,2,38,C,A,1,234.08,200,130,166167,12637806,233.9,234.0,10,50,1,1,233.85,234.08,141,200,1,1,233.77,234.09,200,29,1,1,233.73,234.1,27,100,1,1,233.7,234.13,1200,400,1,1,233.66,234.17,1,1,1,1,233.58,234.25,505,100,2,1,233.53,234.41,10,600,1,2,233.5,234.43,100,105,1,2,233.45,234.5,15,63,1,4,AAPL,0.0,0.0,200.0,0.0,0.0,0.0,0.0,0.0,0.0,0.0,0.0,12.683232565773917,
2024-10-21T12:17:33.823002310Z,2024-10-21T12:17:33.822835795Z,10,2,38,A,A,1,234.03,200,130,166515,12637807,233.9,234.0,10,50,1,1,233.85,234.03,141,200,1,1,233.77,234.09,200,29,1,1,233.73,234.1,27,100,1,1,233.7,234.13,1200,400,1,1,233.66,234.17,1,1,1,1,233.58,234.25,505,100,2,1,233.53,234.41,10,600,1,2,233.5,234.43,100,105,1,2,233.45,234.5,15,63,1,4,AAPL,0.0,0.0,-200.0,0.0,0.0,0.0,0.0,0.0,0.0,0.0,0.0,-12.683232565773917,
2024-10-21T12:17:35.461566586Z,2024-10-21T12:17:35.461400679Z,10,2,38,C,A,1,234.03,200,130,165907,12639539,233.9,234.0,10,50,1,1,233.85,234.09,141,29,1,1,233.77,234.1,200,100,1,1,233.73,234.13,27,400,1,1,233.7,234.17,1200,1,1,1,233.66,234.25,1,100,1,1,233.58,234.41,505,600,2,2,233.53,234.43,10,105,1,2,233.5,234.5,100,63,1,4,233.45,234.75,15,1,1,1,AAPL,0.0,0.0,29.0,100.0,400.0,1.0,100.0,600.0,105.0,63.0,1.0,191.42410414711847,
2024-10-21T12:17:35.461578939Z,2024-10-21T12:17:35.461412055Z,10,2,38,A,A,1,234.08,400,130,166884,12639540,233.9,234.0,10,50,1,1,233.85,234.08,141,400,1,1,233.77,234.09,200,29,1,1,233.73,234.1,27,100,1,1,233.7,234.13,1200,400,1,1,233.66,234.17,1,1,1,1,233.58,234.25,505,100,2,1,233.53,234.41,10,600,1,2,233.5,234.43,100,105,1,2,233.45,234.5,15,63,1,4,AAPL,0.0,0.0,-29.0,-100.0,-400.0,-1.0,-100.0,-600.0,-105.0,-63.0,-1.0,-191.42410414711847,
2024-10-21T12:17:35.470157228Z,2024-10-21T12:17:35.469991264Z,10,2,38,C,A,2,234.09,29,130,165964,12639580,233.9,234.0,10,50,1,1,233.85,234.08,141,400,1,1,233.77,234.1,200,100,1,1,233.73,234.13,27,400,1,1,233.7,234.17,1200,1,1,1,233.66,234.25,1,100,1,1,233.58,234.41,505,600,2,2,233.53,234.43,10,105,1,2,233.5,234.5,100,63,1,4,233.45,234.75,15,1,1,1,AAPL,0.0,0.0,0.0,100.0,400.0,1.0,100.0,600.0,105.0,63.0,1.0,189.58503542508126,
2024-10-21T12:17:35.470212130Z,2024-10-21T12:17:35.470045707Z,10,2,38,A,A,4,234.15,28,130,166423,12639581,233.9,234.0,10,50,1,1,233.85,234.08,141,400,1,1,233.77,234.1,200,100,1,1,233.73,234.13,27,400,1,1,233.7,234.15,1200,28,1,1,233.66,234.17,1,1,1,1,233.58,234.25,505,100,2,1,233.53,234.41,10,600,1,2,233.5,234.43,100,105,1,2,233.45,234.5,15,63,1,4,AAPL,0.0,0.0,0.0,0.0,0.0,-1.0,-100.0,-600.0,-105.0,-63.0,-1.0,-97.39595534183331,
2024-10-21T12:17:37.663795596Z,2024-10-21T12:17:37.663629357Z,10,2,38,A,B,2,233.77,200,130,166239,12641761,233.9,234.0,10,50,1,1,233.85,234.08,141,400,1,1,233.77,234.1,400,100,2,1,233.73,234.13,27,400,1,1,233.7,234.15,1200,28,1,1,233.66,234.17,1,1,1,1,233.58,234.25,505,100,2,1,233.53,234.41,10,600,1,2,233.5,234.43,100,105,1,2,233.45,234.5,15,63,1,4,AAPL,0.0,0.0,0.0,200.0,0.0,0.0,0.0,0.0,0.0,0.0,0.0,20.31651614720104,
2024-10-21T12:17:37.718760543Z,2024-10-21T12:17:37.718594298Z,10,2,38,C,B,2,233.77,200,130,166245,12641892,233.9,234.0,10,50,1,1,233.85,234.08,141,400,1,1,233.77,234.1,200,100,1,1,233.73,234.13,27,400,1,1,233.7,234.15,1200,28,1,1,233.66,234.17,1,1,1,1,233.58,234.25,505,100,2,1,233.53,234.41,10,600,1,2,233.5,234.43,100,105,1,2,233.45,234.5,15,63,1,4,AAPL,0.0,0.0,0.0,-200.0,0.0,0.0,0.0,0.0,0.0,0.0,0.0,-20.31651614720104,
2024-10-21T12:17:37.718772651Z,2024-10-21T12:17:37.718605853Z,10,2,38,A,B,2,233.8,400,130,166798,12641893,233.9,234.0,10,50,1,1,233.85,234.08,141,400,1,1,233.8,234.1,400,100,1,1,233.73,234.13,27,400,1,1,233.7,234.15,1200,28,1,1,233.66,234.17,1,1,1,1,233.58,234.25,505,100,2,1,233.53,234.41,10,600,1,2,233.5,234.43,100,105,1,2,233.45,234.5,15,63,1,4,AAPL,0.0,0.0,0.0,400.0,0.0,0.0,0.0,0.0,0.0,0.0,0.0,40.63303229440208,
2024-10-21T12:17:38.521294530Z,2024-10-21T12:17:38.521127910Z,10,2,38,A,A,1,234.04,200,130,166620,12642639,233.9,234.0,10,50,1,1,233.85,234.04,141,200,1,1,233.8,234.1,400,100,1,1,233.73,234.13,27,400,1,1,233.7,234.15,1200,28,1,1,233.66,234.17,1,1,1,1,233.58,234.25,505,100,2,1,233.53,234.41,10,600,1,2,233.5,234.43,100,105,1,2,233.45,234.5,15,63,1,4,AAPL,0.0,0.0,-400.0,0.0,0.0,0.0,0.0,0.0,0.0,0.0,0.0,-25.366465131547834,
2024-10-21T12:17:39.973713394Z,2024-10-21T12:17:39.973547435Z,10,2,38,C,A,4,234.15,28,130,165959,12644151,233.9,234.0,10,50,1,1,233.85,234.04,141,200,1,1,233.8,234.1,400,100,1,1,233.73,234.13,27,400,1,1,233.7,234.17,1200,1,1,1,233.66,234.25,1,100,1,1,233.58,234.41,505,600,2,2,233.53,234.43,10,105,1,2,233.5,234.5,100,63,1,4,233.45,234.75,15,1,1,1,AAPL,0.0,0.0,0.0,0.0,0.0,1.0,100.0,600.0,105.0,63.0,1.0,97.39595534183331,
2024-10-21T12:17:39.973752037Z,2024-10-21T12:17:39.973585910Z,10,2,38,A,A,2,234.1,27,130,166127,12644152,233.9,234.0,10,50,1,1,233.85,234.04,141,200,1,1,233.8,234.1,400,127,1,2,233.73,234.13,27,400,1,1,233.7,234.17,1200,1,1,1,233.66,234.25,1,100,1,1,233.58,234.41,505,600,2,2,233.53,234.43,10,105,1,2,233.5,234.5,100,63,1,4,233.45,234.75,15,1,1,1,AAPL,0.0,0.0,0.0,-27.0,0.0,0.0,0.0,0.0,0.0,0.0,0.0,-2.74272967987214,
2024-10-21T12:17:47.136044765Z,2024-10-21T12:17:47.135873221Z,10,2,38,T,A,0,233.9,10,0,171544,12650095,233.9,234.0,10,50,1,1,233.85,234.04,141,200,1,1,233.8,234.1,400,127,1,2,233.73,234.13,27,400,1,1,233.7,234.17,1200,1,1,1,233.66,234.25,1,100,1,1,233.58,234.41,505,600,2,2,233.53,234.43,10,105,1,2,233.5,234.5,100,63,1,4,233.45,234.75,15,1,1,1,AAPL,0.0,0.0,0.0,0.0,0.0,0.0,0.0,0.0,0.0,0.0,0.0,0.0,
2024-10-21T12:17:47.136044765Z,2024-10-21T12:17:47.135873221Z,10,2,38,T,A,0,233.85,141,0,171544,12650096,233.85,234.0,141,50,1,1,233.8,234.04,400,200,1,1,233.73,234.1,27,127,1,2,233.7,234.13,1200,400,1,1,233.66,234.17,1,1,1,1,233.58,234.25,505,100,2,1,233.53,234.41,10,600,1,2,233.5,234.43,100,105,1,2,233.45,234.5,15,63,1,4,233.4,234.75,110,1,2,1,AAPL,-10.0,-10.0,-141.0,-400.0,-27.0,-1200.0,-1.0,-505.0,-10.0,-100.0,-15.0,-261.6990982402313,
2024-10-21T12:17:47.136044765Z,2024-10-21T12:17:47.135873221Z,10,2,38,T,N,0,233.85,50,130,171544,12650097,233.8,234.0,400,50,1,1,233.73,234.04,27,200,1,1,233.7,234.1,1200,127,1,2,233.66,234.13,1,400,1,1,233.58,234.17,505,1,2,1,233.53,234.25,10,100,1,1,233.5,234.41,100,600,1,2,233.45,234.43,15,105,1,2,233.4,234.5,110,63,2,4,233.39,234.75,10,1,1,1,AAPL,-141.0,-141.0,-400.0,-27.0,-1200.0,-1.0,-505.0,-10.0,-100.0,-15.0,-110.0,-366.8098709093658,
2024-10-21T12:17:47.136066911Z,2024-10-21T12:17:47.135900626Z,10,2,38,A,A,0,233.98,100,130,166285,12650098,233.8,233.98,400,100,1,1,233.73,234.0,27,50,1,1,233.7,234.04,1200,200,1,1,233.66,234.1,1,127,1,2,233.58,234.13,505,400,2,1,233.53,234.17,10,1,1,1,233.5,234.25,100,100,1,1,233.45,234.41,15,600,1,2,233.4,234.43,110,105,2,2,233.39,234.5,10,63,1,4,AAPL,-50.0,-50.0,-200.0,-127.0,-400.0,-1.0,-100.0,-600.0,-105.0,-63.0,-1.0,-206.00502680303356,
2024-10-21T12:17:47.136072149Z,2024-10-21T12:17:47.135905168Z,10,2,38,A,A,0,233.97,100,130,166981,12650099,233.8,233.97,400,100,1,1,233.73,233.98,27,100,1,1,233.7,234.0,1200,50,1,1,233.66,234.04,1,200,1,1,233.58,234.1,505,127,2,2,233.53,234.13,10,400,1,1,233.5,234.17,100,1,1,1,233.45,234.25,15,100,1,1,233.4,234.41,110,600,2,2,233.39,234.43,10,105,1,2,AAPL,-100.0,-100.0,-50.0,-200.0,-127.0,-400.0,-1.0,-100.0,-600.0,-105.0,-63.0,-182.33620552724523,
2024-10-21T12:17:47.136074817Z,2024-10-21T12:17:47.135906292Z,10,2,38,A,A,0,233.95,162,130,168525,12650101,233.8,233.95,400,162,1,1,233.73,233.97,27,200,1,2,233.7,233.98,1200,100,1,1,233.66,234.0,1,50,1,1,233.58,234.04,505,200,2,1,233.53,234.1,10,127,1,2,233.5,234.13,100,400,1,1,233.45,234.17,15,1,1,1,233.4,234.25,110,100,2,1,233.39,234.41,10,600,1,2,AAPL,-100.0,-100.0,-100.0,-50.0,-200.0,-127.0,-400.0,-1.0,-100.0,-600.0,-105.0,-183.60817420737888,
2024-10-21T12:17:47.136079816Z,2024-10-21T12:17:47.135913885Z,10,2,38,A,A,0,233.92,100,130,165931,12650102,233.8,233.92,400,100,1,1,233.73,233.95,27,162,1,1,233.7,233.97,1200,200,1,2,233.66,233.98,1,100,1,1,233.58,234.0,505,50,2,1,233.53,234.04,10,200,1,1,233.5,234.1,100,127,1,2,233.45,234.13,15,400,1,1,233.4,234.17,110,1,2,1,233.39,234.25,10,100,1,1,AAPL,-162.0,-162.0,-200.0,-100.0,-50.0,-200.0,-127.0,-400.0,-1.0,-100.0,-600.0,-172.32893551632262,
2024-10-21T12:17:47.136082565Z,2024-10-21T12:17:47.135916592Z,10,2,38,A,A,3,233.98,100,130,165973,12650103,233.8,233.92,400,100,1,1,233.73,233.95,27,162,1,1,233.7,233.97,1200,200,1,2,233.66,233.98,1,200,1,2,233.58,234.0,505,50,2,1,233.53,234.04,10,200,1,1,233.5,234.1,100,127,1,2,233.45,234.13,15,400,1,1,233.4,234.17,110,1,2,1,233.39,234.25,10,100,1,1,AAPL,0.0,0.0,0.0,0.0,-100.0,0.0,0.0,0.0,0.0,0.0,0.0,-20.507705502411852,
2024-10-21T12:17:47.136093537Z,2024-10-21T12:17:47.135925594Z,10,2,38,A,A,2,233.97,100,130,167943,12650104,233.8,233.92,400,100,1,1,233.73,233.95,27,162,1,1,233.7,233.97,1200,300,1,3,233.66,233.98,1,200,1,2,233.58,234.0,505,50,2,1,233.53,234.04,10,200,1,1,233.5,234.1,100,127,1,2,233.45,234.13,15,400,1,1,233.4,234.17,110,1,2,1,233.39,234.25,10,100,1,1,AAPL,0.0,0.0,0.0,-100.0,0.0,0.0,0.0,0.0,0.0,0.0,0.0,-10.15825807360052,
2024-10-21T12:17:47.136099687Z,2024-10-21T12:17:47.135933669Z,10,2,38,A,A,1,233.93,35,130,166018,12650105,233.8,233.92,400,100,1,1,233.73,233.93,27,35,1,1,233.7,233.95,1200,162,1,1,233.66,233.97,1,300,1,3,233.58,233.98,505,200,2,2,233.53,234.0,10,50,1,1,233.5,234.04,100,200,1,1,233.45,234.1,15,127,1,2,233.4,234.13,110,400,2,1,233.39,234.17,10,1,1,1,AAPL,0.0,0.0,-162.0,-300.0,-200.0,-50.0,-200.0,-127.0,-400.0,-1.0,-100.0,-177.4180275038209,
2024-10-21T12:17:47.136103482Z,2024-10-21T12:17:47.135937314Z,10,2,38,C,A,4,233.98,100,130,166168,12650106,233.8,233.92,400,100,1,1,233.73,233.93,27,35,1,1,233.7,233.95,1200,162,1,1,233.66,233.97,1,300,1,3,233.58,233.98,505,100,2,1,233.53,234.0,10,50,1,1,233.5,234.04,100,200,1,1,233.45,234.1,15,127,1,2,233.4,234.13,110,400,2,1,233.39,234.17,10,1,1,1,AAPL,0.0,0.0,0.0,0.0,0.0,100.0,0.0,0.0,0.0,0.0,0.0,11.638768733918756,
2024-10-21T12:17:47.136107460Z,2024-10-21T12:17:47.135940686Z,10,2,38,A,A,3,233.97,100,130,166774,12650107,233.8,233.92,400,100,1,1,233.73,233.93,27,35,1,1,233.7,233.95,1200,162,1,1,233.66,233.97,1,400,1,4,233.58,233.98,505,100,2,1,233.53,234.0,10,50,1,1,233.5,234.04,100,200,1,1,233.45,234.1,15,127,1,2,233.4,234.13,110,400,2,1,233.39,234.17,10,1,1,1,AAPL,0.0,0.0,0.0,0.0,-100.0,0.0,0.0,0.0,0.0,0.0,0.0,-20.507705502411852,
2024-10-21T12:17:47.136114326Z,2024-10-21T12:17:47.135946914Z,10,2,38,A,A,0,233.97,35,130,167412,12650109,233.8,233.93,400,35,1,1,233.73,233.95,27,162,1,1,233.7,233.97,1200,435,1,5,233.66,233.98,1,100,1,1,233.58,234.0,505,50,2,1,233.53,234.04,10,200,1,1,233.5,234.1,100,127,1,2,233.45,234.13,15,400,1,1,233.4,234.17,110,1,2,1,233.39,234.25,10,100,1,1,AAPL,35.0,35.0,162.0,435.0,100.0,50.0,200.0,127.0,400.0,1.0,100.0,171.31979079338413,
2024-10-21T12:17:47.136118512Z,2024-10-21T12:17:47.135952535Z,10,2,38,C,A,3,233.98,100,130,165977,12650110,233.8,233.93,400,35,1,1,233.73,233.95,27,162,1,1,233.7,233.97,1200,435,1,5,233.66,234.0,1,50,1,1,233.58,234.04,505,200,2,1,233.53,234.1,10,127,1,2,233.5,234.13,100,400,1,1,233.45,234.17,15,1,1,1,233.4,234.25,110,100,2,1,233.39,234.41,10,600,1,2,AAPL,0.0,0.0,0.0,0.0,50.0,200.0,127.0,400.0,1.0,100.0,600.0,146.26679048827592,
2024-10-21T12:17:47.136124318Z,2024-10-21T12:17:47.135958456Z,10,2,38,C,B,0,233.8,400,130,165862,12650111,233.73,233.93,27,35,1,1,233.7,233.95,1200,162,1,1,233.66,233.97,1,435,1,5,233.58,234.0,505,50,2,1,233.53,234.04,10,200,1,1,233.5,234.1,100,127,1,2,233.45,234.13,15,400,1,1,233.4,234.17,110,1,2,1,233.39,234.25,10,100,1,1,233.31,234.41,110,600,2,2,AAPL,-400.0,-400.0,-27.0,-1200.0,-1.0,-505.0,-10.0,-100.0,-15.0,-110.0,-10.0,-213.18154174996548,
2024-10-21T12:17:47.136134998Z,2024-10-21T12:17:47.135968023Z,10,2,38,C,A,1,233.95,162,128,166975,12650112,233.73,233.93,27,35,1,1,233.7,233.97,1200,435,1,5,233.66,234.0,1,50,1,1,233.58,234.04,505,200,2,1,233.53,234.1,10,127,1,2,233.5,234.13,100,400,1,1,233.45,234.17,15,1,1,1,233.4,234.25,110,100,2,1,233.39,234.41,10,600,1,2,233.31,234.43,110,105,2,2,AAPL,0.0,0.0,435.0,50.0,200.0,127.0,400.0,1.0,100.0,600.0,105.0,202.8645304904377,
2024-10-21T12:17:47.136176630Z,2024-10-21T12:17:47.136008874Z,10,2,38,C,A,1,233.97,100,130,167756,12650118,233.73,233.93,27,35,1,1,233.7,233.97,1200,335,1,4,233.66,234.0,1,50,1,1,233.58,234.04,505,200,2,1,233.53,234.1,10,127,1,2,233.5,234.13,100,400,1,1,233.45,234.17,15,1,1,1,233.4,234.25,110,100,2,1,233.39,234.41,10,600,1,2,233.31,234.43,110,105,2,2,AAPL,0.0,0.0,100.0,0.0,0.0,0.0,0.0,0.0,0.0,0.0,0.0,6.3416162828869584,
2024-10-21T12:17:47.136220660Z,2024-10-21T12:17:47.136054541Z,10,2,38,C,A,1,233.97,100,130,166119,12650119,233.73,233.93,27,35,1,1,233.7,233.97,1200,235,1,3,233.66,234.0,1,50,1,1,233.58,234.04,505,200,2,1,233.53,234.1,10,127,1,2,233.5,234.13,100,400,1,1,233.45,234.17,15,1,1,1,233.4,234.25,110,100,2,1,233.39,234.41,10,600,1,2,233.31,234.43,110,105,2,2,AAPL,0.0,0.0,100.0,0.0,0.0,0.0,0.0,0.0,0.0,0.0,0.0,6.3416162828869584,
2024-10-21T12:17:47.136384565Z,2024-10-21T12:17:47.136218636Z,10,2,38,C,A,1,233.97,100,130,165929,12650120,233.73,233.93,27,35,1,1,233.7,233.97,1200,135,1,2,233.66,234.0,1,50,1,1,233.58,234.04,505,200,2,1,233.53,234.1,10,127,1,2,233.5,234.13,100,400,1,1,233.45,234.17,15,1,1,1,233.4,234.25,110,100,2,1,233.39,234.41,10,600,1,2,233.31,234.43,110,105,2,2,AAPL,0.0,0.0,100.0,0.0,0.0,0.0,0.0,0.0,0.0,0.0,0.0,6.3416162828869584,
2024-10-21T12:17:47.136391264Z,2024-10-21T12:17:47.136225295Z,10,2,38,C,A,1,233.97,100,130,165969,12650121,233.73,233.93,27,35,1,1,233.7,233.97,1200,35,1,1,233.66,234.0,1,50,1,1,233.58,234.04,505,200,2,1,233.53,234.1,10,127,1,2,233.5,234.13,100,400,1,1,233.45,234.17,15,1,1,1,233.4,234.25,110,100,2,1,233.39,234.41,10,600,1,2,233.31,234.43,110,105,2,2,AAPL,0.0,0.0,100.0,0.0,0.0,0.0,0.0,0.0,0.0,0.0,0.0,6.3416162828869584,
2024-10-21T12:17:47.136731997Z,2024-10-21T12:17:47.136565013Z,10,2,38,A,A,0,233.92,100,130,166984,12650123,233.73,233.92,27,100,1,1,233.7,233.93,1200,35,1,1,233.66,233.97,1,35,1,1,233.58,234.0,505,50,2,1,233.53,234.04,10,200,1,1,233.5,234.1,100,127,1,2,233.45,234.13,15,400,1,1,233.4,234.17,110,1,2,1,233.39,234.25,10,100,1,1,233.31,234.41,110,600,2,2,AAPL,-35.0,-35.0,-35.0,-50.0,-200.0,-127.0,-400.0,-1.0,-100.0,-600.0,-105.0,-178.19388575150424,
2024-10-21T12:17:47.137204585Z,2024-10-21T12:17:47.137037920Z,10,2,38,C,A,0,233.92,100,130,166665,12650124,233.73,233.93,27,35,1,1,233.7,233.97,1200,35,1,1,233.66,234.0,1,50,1,1,233.58,234.04,505,200,2,1,233.53,234.1,10,127,1,2,233.5,234.13,100,400,1,1,233.45,234.17,15,1,1,1,233.4,234.25,110,100,2,1,233.39,234.41,10,600,1,2,233.31,234.43,110,105,2,2,AAPL,35.0,35.0,35.0,50.0,200.0,127.0,400.0,1.0,100.0,600.0,105.0,178.19388575150424,
2024-10-21T12:17:47.157056586Z,2024-10-21T12:17:47.156890091Z,10,2,38,A,B,0,233.8,200,130,166495,12650144,233.8,233.93,200,35,1,1,233.73,233.97,27,35,1,1,233.7,234.0,1200,50,1,1,233.66,234.04,1,200,1,1,233.58,234.1,505,127,2,2,233.53,234.13,10,400,1,1,233.5,234.17,100,1,1,1,233.45,234.25,15,100,1,1,233.4,234.41,110,600,2,2,233.39,234.43,10,105,1,2,AAPL,200.0,200.0,27.0,1200.0,1.0,505.0,10.0,100.0,15.0,110.0,10.0,209.20542522074052,
2024-10-21T12:17:47.189868393Z,2024-10-21T12:17:47.189701537Z,10,2,38,A,B,0,233.8,200,130,166856,12650170,233.8,233.93,400,35,2,1,233.73,233.97,27,35,1,1,233.7,234.0,1200,50,1,1,233.66,234.04,1,200,1,1,233.58,234.1,505,127,2,2,233.53,234.13,10,400,1,1,233.5,234.17,100,1,1,1,233.45,234.25,15,100,1,1,233.4,234.41,110,600,2,2,233.39,234.43,10,105,1,2,AAPL,200.0,200.0,0.0,0.0,0.0,0.0,0.0,0.0,0.0,0.0,0.0,3.9761165292250036,
2024-10-21T12:17:47.200204805Z,2024-10-21T12:17:47.200038724Z,10,2,38,C,B,0,233.8,200,130,166081,12650190,233.8,233.93,200,35,1,1,233.73,233.97,27,35,1,1,233.7,234.0,1200,50,1,1,233.66,234.04,1,200,1,1,233.58,234.1,505,127,2,2,233.53,234.13,10,400,1,1,233.5,234.17,100,1,1,1,233.45,234.25,15,100,1,1,233.4,234.41,110,600,2,2,233.39,234.43,10,105,1,2,AAPL,-200.0,-200.0,0.0,0.0,0.0,0.0,0.0,0.0,0.0,0.0,0.0,-3.9761165292250036,
2024-10-21T12:17:47.200214033Z,2024-10-21T12:17:47.200048226Z,10,2,38,C,B,0,233.8,200,130,165807,12650191,233.73,233.93,27,35,1,1,233.7,233.97,1200,35,1,1,233.66,234.0,1,50,1,1,233.58,234.04,505,200,2,1,233.53,234.1,10,127,1,2,233.5,234.13,100,400,1,1,233.45,234.17,15,1,1,1,233.4,234.25,110,100,2,1,233.39,234.41,10,600,1,2,233.31,234.43,110,105,2,2,AAPL,-200.0,-200.0,-27.0,-1200.0,-1.0,-505.0,-10.0,-100.0,-15.0,-110.0,-10.0,-209.20542522074052,
2024-10-21T12:17:47.200225833Z,2024-10-21T12:17:47.200058794Z,10,2,38,A,B,2,233.69,400,130,167039,12650192,233.73,233.93,27,35,1,1,233.7,233.97,1200,35,1,1,233.69,234.0,400,50,1,1,233.66,234.04,1,200,1,1,233.58,234.1,505,127,2,2,233.53,234.13,10,400,1,1,233.5,234.17,100,1,1,1,233.45,234.25,15,100,1,1,233.4,234.41,110,600,2,2,233.39,234.43,10,105,1,2,AAPL,0.0,0.0,0.0,400.0,1.0,505.0,10.0,100.0,15.0,110.0,10.0,122.25100770633186,
2024-10-21T12:17:47.203824313Z,2024-10-21T12:17:47.203657195Z,10,2,38,C,B,0,233.73,27,130,167118,12650207,233.7,233.93,1200,35,1,1,233.69,233.97,400,35,1,1,233.66,234.0,1,50,1,1,233.58,234.04,505,200,2,1,233.53,234.1,10,127,1,2,233.5,234.13,100,400,1,1,233.45,234.17,15,1,1,1,233.4,234.25,110,100,2,1,233.39,234.41,10,600,1,2,233.31,234.43,110,105,2,2,AAPL,-27.0,-27.0,-1200.0,-400.0,-1.0,-505.0,-10.0,-100.0,-15.0,-110.0,-10.0,-198.88717883242074,
2024-10-21T12:17:47.203896270Z,2024-10-21T12:17:47.203729908Z,10,2,38,A,B,2,233.67,28,130,166362,12650208,233.7,233.93,1200,35,1,1,233.69,233.97,400,35,1,1,233.67,234.0,28,50,1,1,233.66,234.04,1,200,1,1,233.58,234.1,505,127,2,2,233.53,234.13,10,400,1,1,233.5,234.17,100,1,1,1,233.45,234.25,15,100,1,1,233.4,234.41,110,600,2,2,233.39,234.43,10,105,1,2,AAPL,0.0,0.0,0.0,28.0,1.0,505.0,10.0,100.0,15.0,110.0,10.0,84.46228767253793,
2024-10-21T12:17:47.207242623Z,2024-10-21T12:17:47.207076580Z,10,2,38,C,B,1,233.69,400,130,166043,12650217,233.7,233.93,1200,35,1,1,233.67,233.97,28,35,1,1,233.66,234.0,1,50,1,1,233.58,234.04,505,200,2,1,233.53,234.1,10,127,1,2,233.5,234.13,100,400,1,1,233.45,234.17,15,1,1,1,233.4,234.25,110,100,2,1,233.39,234.41,10,600,1,2,233.31,234.43,110,105,2,2,AAPL,0.0,0.0,-400.0,-28.0,-1.0,-505.0,-10.0,-100.0,-15.0,-110.0,-10.0,-109.82875280408575,
2024-10-21T12:17:47.240203878Z,2024-10-21T12:17:47.240037346Z,10,2,38,A,B,1,233.68,200,130,166532,12650248,233.7,233.93,1200,35,1,1,233.68,233.97,200,35,1,1,233.67,234.0,28,50,1,1,233.66,234.04,1,200,1,1,233.58,234.1,505,127,2,2,233.53,234.13,10,400,1,1,233.5,234.17,100,1,1,1,233.45,234.25,15,100,1,1,233.4,234.41,110,600,2,2,233.39,234.43,10,105,1,2,AAPL,0.0,0.0,200.0,28.0,1.0,505.0,10.0,100.0,15.0,110.0,10.0,97.14552023831183,
2024-10-21T12:17:47.240232077Z,2024-10-21T12:17:47.240066169Z,10,2,38,C,A,1,233.97,35,130,165908,12650249,233.7,233.93,1200,35,1,1,233.68,234.0,200,50,1,1,233.67,234.04,28,200,1,1,233.66,234.1,1,127,1,2,233.58,234.13,505,400,2,1,233.53,234.17,10,1,1,1,233.5,234.25,100,100,1,1,233.45,234.41,15,600,1,2,233.4,234.43,110,105,2,2,233.39,234.5,10,63,1,4,AAPL,0.0,0.0,50.0,200.0,127.0,400.0,1.0,100.0,600.0,105.0,63.0,180.34814726263272,
2024-10-21T12:17:47.260251805Z,2024-10-21T12:17:47.260085243Z,10,2,38,A,A,2,234.03,200,130,166562,12650278,233.7,233.93,1200,35,1,1,233.68,234.0,200,50,1,1,233.67,234.03,28,200,1,1,233.66,234.1,1,127,1,2,233.58,234.13,505,400,2,1,233.53,234.17,10,1,1,1,233.5,234.25,100,100,1,1,233.45,234.41,15,600,1,2,233.4,234.43,110,105,2,2,233.39,234.5,10,63,1,4,AAPL,0.0,0.0,0.0,-200.0,0.0,0.0,0.0,0.0,0.0,0.0,0.0,-20.31651614720104,
2024-10-21T12:17:47.386630077Z,2024-10-21T12:17:47.386463721Z,10,2,38,C,A,0,233.93,35,130,166356,12650325,233.7,234.0,1200,50,1,1,233.68,234.03,200,200,1,1,233.67,234.1,28,127,1,2,233.66,234.13,1,400,1,1,233.58,234.17,505,1,2,1,233.53,234.25,10,100,1,1,233.5,234.41,100,600,1,2,233.45,234.43,15,105,1,2,233.4,234.5,110,63,2,4,233.39,234.75,10,1,1,1,AAPL,50.0,50.0,200.0,127.0,400.0,1.0,100.0,600.0,105.0,63.0,1.0,206.00502680303356,
2024-10-21T12:17:57.664077159Z,2024-10-21T12:17:57.663911195Z,10,2,38,C,A,2,234.1,27,130,165964,12660246,233.7,234.0,1200,50,1,1,233.68,234.03,200,200,1,1,233.67,234.1,28,100,1,1,233.66,234.13,1,400,1,1,233.58,234.17,505,1,2,1,233.53,234.25,10,100,1,1,233.5,234.41,100,600,1,2,233.45,234.43,15,105,1,2,233.4,234.5,110,63,2,4,233.39,234.75,10,1,1,1,AAPL,0.0,0.0,0.0,27.0,0.0,0.0,0.0,0.0,0.0,0.0,0.0,2.74272967987214,
2024-10-21T12:17:57.664183508Z,2024-10-21T12:17:57.664016909Z,10,2,38,A,A,2,234.09,28,130,166599,12660247,233.7,234.0,1200,50,1,1,233.68,234.03,200,200,1,1,233.67,234.09,28,28,1,1,233.66,234.1,1,100,1,1,233.58,234.13,505,400,2,1,233.53,234.17,10,1,1,1,233.5,234.25,100,100,1,1,233.45,234.41,15,600,1,2,233.4,234.43,110,105,2,2,233.39,234.5,10,63,1,4,AAPL,0.0,0.0,0.0,-100.0,-400.0,-1.0,-100.0,-600.0,-105.0,-63.0,-1.0,-189.58503542508126,
2024-10-21T12:17:57.861930731Z,2024-10-21T12:17:57.861764830Z,10,2,38,C,A,1,234.03,200,130,165901,12660371,233.7,234.0,1200,50,1,1,233.68,234.09,200,28,1,1,233.67,234.1,28,100,1,1,233.66,234.13,1,400,1,1,233.58,234.17,505,1,2,1,233.53,234.25,10,100,1,1,233.5,234.41,100,600,1,2,233.45,234.43,15,105,1,2,233.4,234.5,110,63,2,4,233.39,234.75,10,1,1,1,AAPL,0.0,0.0,28.0,100.0,400.0,1.0,100.0,600.0,105.0,63.0,1.0,191.3606879842896,
2024-10-21T12:17:57.861944318Z,2024-10-21T12:17:57.861778012Z,10,2,38,A,A,1,234.05,200,130,166306,12660372,233.7,234.0,1200,50,1,1,233.68,234.05,200,200,1,1,233.67,234.09,28,28,1,1,233.66,234.1,1,100,1,1,233.58,234.13,505,400,2,1,233.53,234.17,10,1,1,1,233.5,234.25,100,100,1,1,233.45,234.41,15,600,1,2,233.4,234.43,110,105,2,2,233.39,234.5,10,63,1,4,AAPL,0.0,0.0,-28.0,-100.0,-400.0,-1.0,-100.0,-600.0,-105.0,-63.0,-1.0,-191.3606879842896,
2024-10-21T12:17:57.861998569Z,2024-10-21T12:17:57.861832789Z,10,2,38,C,A,1,234.05,200,130,165780,12660373,233.7,234.0,1200,50,1,1,233.68,234.09,200,28,1,1,233.67,234.1,28,100,1,1,233.66,234.13,1,400,1,1,233.58,234.17,505,1,2,1,233.53,234.25,10,100,1,1,233.5,234.41,100,600,1,2,233.45,234.43,15,105,1,2,233.4,234.5,110,63,2,4,233.39,234.75,10,1,1,1,AAPL,0.0,0.0,28.0,100.0,400.0,1.0,100.0,600.0,105.0,63.0,1.0,191.3606879842896,
2024-10-21T12:17:57.862047558Z,2024-10-21T12:17:57.861881332Z,10,2,38,A,A,1,234.08,400,130,166226,12660374,233.7,234.0,1200,50,1,1,233.68,234.08,200,400,1,1,233.67,234.09,28,28,1,1,233.66,234.1,1,100,1,1,233.58,234.13,505,400,2,1,233.53,234.17,10,1,1,1,233.5,234.25,100,100,1,1,233.45,234.41,15,600,1,2,233.4,234.43,110,105,2,2,233.39,234.5,10,63,1,4,AAPL,0.0,0.0,-28.0,-100.0,-400.0,-1.0,-100.0,-600.0,-105.0,-63.0,-1.0,-191.3606879842896,
2024-10-21T12:17:57.862411573Z,2024-10-21T12:17:57.862245512Z,10,2,38,C,A,2,234.09,28,130,166061,12660376,233.7,234.0,1200,50,1,1,233.68,234.08,200,400,1,1,233.67,234.1,28,100,1,1,233.66,234.13,1,400,1,1,233.58,234.17,505,1,2,1,233.53,234.25,10,100,1,1,233.5,234.41,100,600,1,2,233.45,234.43,15,105,1,2,233.4,234.5,110,63,2,4,233.39,234.75,10,1,1,1,AAPL,0.0,0.0,0.0,100.0,400.0,1.0,100.0,600.0,105.0,63.0,1.0,189.58503542508126,
2024-10-21T12:17:57.917208666Z,2024-10-21T12:17:57.917042270Z,10,2,38,A,A,1,234.06,200,130,166396,12660452,233.7,234.0,1200,50,1,1,233.68,234.06,200,200,1,1,233.67,234.1,28,100,1,1,233.66,234.13,1,400,1,1,233.58,234.17,505,1,2,1,233.53,234.25,10,100,1,1,233.5,234.41,100,600,1,2,233.45,234.43,15,105,1,2,233.4,234.5,110,63,2,4,233.39,234.75,10,1,1,1,AAPL,0.0,0.0,-400.0,0.0,0.0,0.0,0.0,0.0,0.0,0.0,0.0,-25.366465131547834,
2024-10-21T12:17:58.077394143Z,2024-10-21T12:17:58.077227750Z,10,2,38,A,A,1,234.03,200,130,166393,12660553,233.7,234.0,1200,50,1,1,233.68,234.03,200,200,1,1,233.67,234.1,28,100,1,1,233.66,234.13,1,400,1,1,233.58,234.17,505,1,2,1,233.53,234.25,10,100,1,1,233.5,234.41,100,600,1,2,233.45,234.43,15,105,1,2,233.4,234.5,110,63,2,4,233.39,234.75,10,1,1,1,AAPL,0.0,0.0,-200.0,0.0,0.0,0.0,0.0,0.0,0.0,0.0,0.0,-12.683232565773917,
2024-10-21T12:18:00.232519967Z,2024-10-21T12:18:00.232353557Z,10,2,38,A,A,2,234.1,29,130,166410,12662424,233.7,234.0,1200,50,1,1,233.68,234.03,200,200,1,1,233.67,234.1,28,129,1,2,233.66,234.13,1,400,1,1,233.58,234.17,505,1,2,1,233.53,234.25,10,100,1,1,233.5,234.41,100,600,1,2,233.45,234.43,15,105,1,2,233.4,234.5,110,63,2,4,233.39,234.75,10,1,1,1,AAPL,0.0,0.0,0.0,-29.0,0.0,0.0,0.0,0.0,0.0,0.0,0.0,-2.945894841344151,
2024-10-21T12:18:00.862297139Z,2024-10-21T12:18:00.862130755Z,10,2,38,A,A,1,234.03,200,130,166384,12663334,233.7,234.0,1200,50,1,1,233.68,234.03,200,400,1,2,233.67,234.1,28,129,1,2,233.66,234.13,1,400,1,1,233.58,234.17,505,1,2,1,233.53,234.25,10,100,1,1,233.5,234.41,100,600,1,2,233.45,234.43,15,105,1,2,233.4,234.5,110,63,2,4,233.39,234.75,10,1,1,1,AAPL,0.0,0.0,-200.0,0.0,0.0,0.0,0.0,0.0,0.0,0.0,0.0,-12.683232565773917,
2024-10-21T12:18:01.682248451Z,2024-10-21T12:18:01.682081842Z,10,2,38,C,A,1,234.03,200,130,166609,12664484,233.7,234.0,1200,50,1,1,233.68,234.03,200,200,1,1,233.67,234.1,28,129,1,2,233.66,234.13,1,400,1,1,233.58,234.17,505,1,2,1,233.53,234.25,10,100,1,1,233.5,234.41,100,600,1,2,233.45,234.43,15,105,1,2,233.4,234.5,110,63,2,4,233.39,234.75,10,1,1,1,AAPL,0.0,0.0,200.0,0.0,0.0,0.0,0.0,0.0,0.0,0.0,0.0,12.683232565773917,
2024-10-21T12:18:01.684200005Z,2024-10-21T12:18:01.684033789Z,10,2,38,C,A,1,234.03,200,130,166216,12664487,233.7,234.0,1200,50,1,1,233.68,234.1,200,129,1,2,233.67,234.13,28,400,1,1,233.66,234.17,1,1,1,1,233.58,234.25,505,100,2,1,233.53,234.41,10,600,1,2,233.5,234.43,100,105,1,2,233.45,234.5,15,63,1,4,233.4,234.75,110,1,2,1,233.39,234.79,10,2000,1,1,AAPL,0.0,0.0,129.0,400.0,1.0,100.0,600.0,105.0,63.0,1.0,2000.0,303.75848259597524,
2024-10-21T12:18:01.684213363Z,2024-10-21T12:18:01.684046790Z,10,2,38,A,A,1,234.06,200,130,166573,12664488,233.7,234.0,1200,50,1,1,233.68,234.06,200,200,1,1,233.67,234.1,28,129,1,2,233.66,234.13,1,400,1,1,233.58,234.17,505,1,2,1,233.53,234.25,10,100,1,1,233.5,234.41,100,600,1,2,233.45,234.43,15,105,1,2,233.4,234.5,110,63,2,4,233.39,234.75,10,1,1,1,AAPL,0.0,0.0,-129.0,-400.0,-1.0,-100.0,-600.0,-105.0,-63.0,-1.0,-2000.0,-303.75848259597524,
2024-10-21T12:18:02.545235211Z,2024-10-21T12:18:02.545068859Z,10,2,38,A,A,1,234.05,200,130,166352,12665308,233.7,234.0,1200,50,1,1,233.68,234.05,200,200,1,1,233.67,234.1,28,129,1,2,233.66,234.13,1,400,1,1,233.58,234.17,505,1,2,1,233.53,234.25,10,100,1,1,233.5,234.41,100,600,1,2,233.45,234.43,15,105,1,2,233.4,234.5,110,63,2,4,233.39,234.75,10,1,1,1,AAPL,0.0,0.0,-200.0,0.0,0.0,0.0,0.0,0.0,0.0,0.0,0.0,-12.683232565773917,
2024-10-21T12:18:03.624266534Z,2024-10-21T12:18:03.624100762Z,10,2,38,C,A,1,234.05,200,130,165772,12666192,233.7,234.0,1200,50,1,1,233.68,234.1,200,129,1,2,233.67,234.13,28,400,1,1,233.66,234.17,1,1,1,1,233.58,234.25,505,100,2,1,233.53,234.41,10,600,1,2,233.5,234.43,100,105,1,2,233.45,234.5,15,63,1,4,233.4,234.75,110,1,2,1,233.39,234.79,10,2000,1,1,AAPL,0.0,0.0,129.0,400.0,1.0,100.0,600.0,105.0,63.0,1.0,2000.0,303.75848259597524,
2024-10-21T12:18:03.624278474Z,2024-10-21T12:18:03.624112266Z,10,2,38,A,A,1,234.07,200,130,166208,12666193,233.7,234.0,1200,50,1,1,233.68,234.07,200,200,1,1,233.67,234.1,28,129,1,2,233.66,234.13,1,400,1,1,233.58,234.17,505,1,2,1,233.53,234.25,10,100,1,1,233.5,234.41,100,600,1,2,233.45,234.43,15,105,1,2,233.4,234.5,110,63,2,4,233.39,234.75,10,1,1,1,AAPL,0.0,0.0,-129.0,-400.0,-1.0,-100.0,-600.0,-105.0,-63.0,-1.0,-2000.0,-303.75848259597524,
2024-10-21T12:18:03.629578910Z,2024-10-21T12:18:03.629412395Z,10,2,38,C,B,2,233.67,28,130,166515,12666256,233.7,234.0,1200,50,1,1,233.68,234.07,200,200,1,1,233.66,234.1,1,129,1,2,233.58,234.13,505,400,2,1,233.53,234.17,10,1,1,1,233.5,234.25,100,100,1,1,233.45,234.41,15,600,1,2,233.4,234.43,110,105,2,2,233.39,234.5,10,63,1,4,233.31,234.75,110,1,2,1,AAPL,0.0,0.0,0.0,-28.0,-1.0,-505.0,-10.0,-100.0,-15.0,-110.0,-10.0,-84.46228767253793,
2024-10-21T12:18:03.629664398Z,2024-10-21T12:18:03.629498033Z,10,2,38,A,B,1,233.68,26,130,166365,12666257,233.7,234.0,1200,50,1,1,233.68,234.07,226,200,2,1,233.66,234.1,1,129,1,2,233.58,234.13,505,400,2,1,233.53,234.17,10,1,1,1,233.5,234.25,100,100,1,1,233.45,234.41,15,600,1,2,233.4,234.43,110,105,2,2,233.39,234.5,10,63,1,4,233.31,234.75,110,1,2,1,AAPL,0.0,0.0,26.0,0.0,0.0,0.0,0.0,0.0,0.0,0.0,0.0,1.6488202335506092,
2024-10-21T12:18:03.696785108Z,2024-10-21T12:18:03.696618449Z,10,2,38,A,B,1,233.69,200,130,166659,12666492,233.7,234.0,1200,50,1,1,233.69,234.07,200,200,1,1,233.68,234.1,26,129,1,2,233.66,234.13,1,400,1,1,233.58,234.17,505,1,2,1,233.53,234.25,10,100,1,1,233.5,234.41,100,600,1,2,233.45,234.43,15,105,1,2,233.4,234.5,110,63,2,4,233.39,234.75,10,1,1,1,AAPL,0.0,0.0,200.0,26.0,1.0,505.0,10.0,100.0,15.0,110.0,10.0,96.94235507683983,
2024-10-21T12:18:04.737683350Z,2024-10-21T12:18:04.737516809Z,10,2,38,A,A,1,234.04,200,130,166541,12667659,233.7,234.0,1200,50,1,1,233.69,234.04,200,200,1,1,233.68,234.1,26,129,1,2,233.66,234.13,1,400,1,1,233.58,234.17,505,1,2,1,233.53,234.25,10,100,1,1,233.5,234.41,100,600,1,2,233.45,234.43,15,105,1,2,233.4,234.5,110,63,2,4,233.39,234.75,10,1,1,1,AAPL,0.0,0.0,-200.0,0.0,0.0,0.0,0.0,0.0,0.0,0.0,0.0,-12.683232565773917,
2024-10-21T12:18:05.203527442Z,2024-10-21T12:18:05.203361341Z,10,2,38,C,A,1,234.04,200,130,166101,12668336,233.7,234.0,1200,50,1,1,233.69,234.1,200,129,1,2,233.68,234.13,26,400,1,1,233.66,234.17,1,1,1,1,233.58,234.25,505,100,2,1,233.53,234.41,10,600,1,2,233.5,234.43,100,105,1,2,233.45,234.5,15,63,1,4,233.4,234.75,110,1,2,1,233.39,234.79,10,2000,1,1,AAPL,0.0,0.0,129.0,400.0,1.0,100.0,600.0,105.0,63.0,1.0,2000.0,303.75848259597524,
2024-10-21T12:18:05.203540356Z,2024-10-21T12:18:05.203373864Z,10,2,38,A,A,1,234.07,200,130,166492,12668337,233.7,234.0,1200,50,1,1,233.69,234.07,200,200,1,1,233.68,234.1,26,129,1,2,233.66,234.13,1,400,1,1,233.58,234.17,505,1,2,1,233.53,234.25,10,100,1,1,233.5,234.41,100,600,1,2,233.45,234.43,15,105,1,2,233.4,234.5,110,63,2,4,233.39,234.75,10,1,1,1,AAPL,0.0,0.0,-129.0,-400.0,-1.0,-100.0,-600.0,-105.0,-63.0,-1.0,-2000.0,-303.75848259597524,
2024-10-21T12:18:08.259175673Z,2024-10-21T12:18:08.259009052Z,10,2,38,A,A,1,234.04,200,130,166621,12670951,233.7,234.0,1200,50,1,1,233.69,234.04,200,200,1,1,233.68,234.1,26,129,1,2,233.66,234.13,1,400,1,1,233.58,234.17,505,1,2,1,233.53,234.25,10,100,1,1,233.5,234.41,100,600,1,2,233.45,234.43,15,105,1,2,233.4,234.5,110,63,2,4,233.39,234.75,10,1,1,1,AAPL,0.0,0.0,-200.0,0.0,0.0,0.0,0.0,0.0,0.0,0.0,0.0,-12.683232565773917,
2024-10-21T12:18:08.926701808Z,2024-10-21T12:18:08.926535769Z,10,2,38,C,A,1,234.04,200,130,166039,12671724,233.7,234.0,1200,50,1,1,233.69,234.1,200,129,1,2,233.68,234.13,26,400,1,1,233.66,234.17,1,1,1,1,233.58,234.25,505,100,2,1,233.53,234.41,10,600,1,2,233.5,234.43,100,105,1,2,233.45,234.5,15,63,1,4,233.4,234.75,110,1,2,1,233.39,234.79,10,2000,1,1,AAPL,0.0,0.0,129.0,400.0,1.0,100.0,600.0,105.0,63.0,1.0,2000.0,303.75848259597524,
2024-10-21T12:18:08.926714890Z,2024-10-21T12:18:08.926548505Z,10,2,38,A,A,1,234.07,200,130,166385,12671725,233.7,234.0,1200,50,1,1,233.69,234.07,200,200,1,1,233.68,234.1,26,129,1,2,233.66,234.13,1,400,1,1,233.58,234.17,505,1,2,1,233.53,234.25,10,100,1,1,233.5,234.41,100,600,1,2,233.45,234.43,15,105,1,2,233.4,234.5,110,63,2,4,233.39,234.75,10,1,1,1,AAPL,0.0,0.0,-129.0,-400.0,-1.0,-100.0,-600.0,-105.0,-63.0,-1.0,-2000.0,-303.75848259597524,
2024-10-21T12:18:10.662605099Z,2024-10-21T12:18:10.662438649Z,10,2,38,A,A,1,234.04,200,130,166450,12673023,233.7,234.0,1200,50,1,1,233.69,234.04,200,200,1,1,233.68,234.1,26,129,1,2,233.66,234.13,1,400,1,1,233.58,234.17,505,1,2,1,233.53,234.25,10,100,1,1,233.5,234.41,100,600,1,2,233.45,234.43,15,105,1,2,233.4,234.5,110,63,2,4,233.39,234.75,10,1,1,1,AAPL,0.0,0.0,-200.0,0.0,0.0,0.0,0.0,0.0,0.0,0.0,0.0,-12.683232565773917,
2024-10-21T12:18:11.927426711Z,2024-10-21T12:18:11.927260518Z,10,2,38,A,A,1,234.04,200,130,166193,12675018,233.7,234.0,1200,50,1,1,233.69,234.04,200,400,1,2,233.68,234.1,26,129,1,2,233.66,234.13,1,400,1,1,233.58,234.17,505,1,2,1,233.53,234.25,10,100,1,1,233.5,234.41,100,600,1,2,233.45,234.43,15,105,1,2,233.4,234.5,110,63,2,4,233.39,234.75,10,1,1,1,AAPL,0.0,0.0,-200.0,0.0,0.0,0.0,0.0,0.0,0.0,0.0,0.0,-12.683232565773917,
2024-10-21T12:18:20.285893902Z,2024-10-21T12:18:20.285727761Z,10,2,38,C,A,2,234.1,29,130,166141,12682022,233.7,234.0,1200,50,1,1,233.69,234.04,200,400,1,2,233.68,234.1,26,100,1,1,233.66,234.13,1,400,1,1,233.58,234.17,505,1,2,1,233.53,234.25,10,100,1,1,233.5,234.41,100,600,1,2,233.45,234.43,15,105,1,2,233.4,234.5,110,63,2,4,233.39,234.75,10,1,1,1,AAPL,0.0,0.0,0.0,29.0,0.0,0.0,0.0,0.0,0.0,0.0,0.0,2.945894841344151,
2024-10-21T12:18:20.285938798Z,2024-10-21T12:18:20.285772241Z,10,2,38,A,A,2,234.05,27,130,166557,12682023,233.7,234.0,1200,50,1,1,233.69,234.04,200,400,1,2,233.68,234.05,26,27,1,1,233.66,234.1,1,100,1,1,233.58,234.13,505,400,2,1,233.53,234.17,10,1,1,1,233.5,234.25,100,100,1,1,233.45,234.41,15,600,1,2,233.4,234.43,110,105,2,2,233.39,234.5,10,63,1,4,AAPL,0.0,0.0,0.0,-100.0,-400.0,-1.0,-100.0,-600.0,-105.0,-63.0,-1.0,-189.58503542508126,
2024-10-21T12:18:20.342261946Z,2024-10-21T12:18:20.342095696Z,10,2,38,C,A,1,234.04,200,130,166250,12682048,233.7,234.0,1200,50,1,1,233.69,234.04,200,200,1,1,233.68,234.05,26,27,1,1,233.66,234.1,1,100,1,1,233.58,234.13,505,400,2,1,233.53,234.17,10,1,1,1,233.5,234.25,100,100,1,1,233.45,234.41,15,600,1,2,233.4,234.43,110,105,2,2,233.39,234.5,10,63,1,4,AAPL,0.0,0.0,200.0,0.0,0.0,0.0,0.0,0.0,0.0,0.0,0.0,12.683232565773917,
2024-10-21T12:18:20.342275574Z,2024-10-21T12:18:20.342109232Z,10,2,38,A,A,0,233.99,200,130,166342,12682049,233.7,233.99,1200,200,1,1,233.69,234.0,200,50,1,1,233.68,234.05,26,27,1,1,233.66,234.1,1,100,1,1,233.58,234.13,505,400,2,1,233.53,234.17,10,1,1,1,233.5,234.25,100,100,1,1,233.45,234.41,15,600,1,2,233.4,234.43,110,105,2,2,233.39,234.5,10,63,1,4,AAPL,-50.0,-50.0,-200.0,0.0,0.0,0.0,0.0,0.0,0.0,0.0,0.0,-13.677261698080168,
2024-10-21T12:18:30.059661118Z,2024-10-21T12:18:30.059494751Z,10,2,38,A,A,0,233.98,200,130,166367,12688662,233.7,233.98,1200,200,1,1,233.69,234.0,200,50,1,1,233.68,234.05,26,27,1,1,233.66,234.1,1,100,1,1,233.58,234.13,505,400,2,1,233.53,234.17,10,1,1,1,233.5,234.25,100,100,1,1,233.45,234.41,15,600,1,2,233.4,234.43,110,105,2,2,233.39,234.5,10,63,1,4,AAPL,-200.0,-200.0,0.0,0.0,0.0,0.0,0.0,0.0,0.0,0.0,0.0,-3.9761165292250036,
2024-10-21T12:18:30.076685634Z,2024-10-21T12:18:30.076519305Z,10,2,38,A,A,0,233.97,200,130,166329,12688696,233.7,233.97,1200,200,1,1,233.69,234.0,200,50,1,1,233.68,234.05,26,27,1,1,233.66,234.1,1,100,1,1,233.58,234.13,505,400,2,1,233.53,234.17,10,1,1,1,233.5,234.25,100,100,1,1,233.45,234.41,15,600,1,2,233.4,234.43,110,105,2,2,233.39,234.5,10,63,1,4,AAPL,-200.0,-200.0,0.0,0.0,0.0,0.0,0.0,0.0,0.0,0.0,0.0,-3.9761165292250036,
2024-10-21T12:18:38.166025153Z,2024-10-21T12:18:38.165859345Z,10,2,38,C,A,0,233.97,200,130,165808,12695042,233.7,234.0,1200,50,1,1,233.69,234.05,200,27,1,1,233.68,234.1,26,100,1,1,233.66,234.13,1,400,1,1,233.58,234.17,505,1,2,1,233.53,234.25,10,100,1,1,233.5,234.41,100,600,1,2,233.45,234.43,15,105,1,2,233.4,234.5,110,63,2,4,233.39,234.75,10,1,1,1,AAPL,50.0,50.0,27.0,100.0,400.0,1.0,100.0,600.0,105.0,63.0,1.0,192.29130095376698,
2024-10-21T12:18:38.166038009Z,2024-10-21T12:18:38.165871291Z,10,2,38,A,A,0,233.99,200,130,166718,12695043,233.7,233.99,1200,200,1,1,233.69,234.0,200,50,1,1,233.68,234.05,26,27,1,1,233.66,234.1,1,100,1,1,233.58,234.13,505,400,2,1,233.53,234.17,10,1,1,1,233.5,234.25,100,100,1,1,233.45,234.41,15,600,1,2,233.4,234.43,110,105,2,2,233.39,234.5,10,63,1,4,AAPL,-50.0,-50.0,-27.0,-100.0,-400.0,-1.0,-100.0,-600.0,-105.0,-63.0,-1.0,-192.29130095376698,
2024-10-21T12:18:38.170948726Z,2024-10-21T12:18:38.170782768Z,10,2,38,C,B,1,233.69,200,130,165958,12695084,233.7,233.99,1200,200,1,1,233.68,234.0,26,50,1,1,233.66,234.05,1,27,1,1,233.58,234.1,505,100,2,1,233.53,234.13,10,400,1,1,233.5,234.17,100,1,1,1,233.45,234.25,15,100,1,1,233.4,234.41,110,600,2,2,233.39,234.43,10,105,1,2,233.31,234.5,110,63,2,4,AAPL,0.0,0.0,-200.0,-26.0,-1.0,-505.0,-10.0,-100.0,-15.0,-110.0,-10.0,-96.94235507683983,
2024-10-21T12:18:38.170958770Z,2024-10-21T12:18:38.170792741Z,10,2,38,A,B,2,233.66,200,130,166029,12695085,233.7,233.99,1200,200,1,1,233.68,234.0,26,50,1,1,233.66,234.05,201,27,2,1,233.58,234.1,505,100,2,1,233.53,234.13,10,400,1,1,233.5,234.17,100,1,1,1,233.45,234.25,15,100,1,1,233.4,234.41,110,600,2,2,233.39,234.43,10,105,1,2,233.31,234.5,110,63,2,4,AAPL,0.0,0.0,0.0,200.0,0.0,0.0,0.0,0.0,0.0,0.0,0.0,20.31651614720104,
2024-10-21T12:18:38.189860689Z,2024-10-21T12:18:38.189694615Z,10,2,38,C,B,1,233.68,26,130,166074,12695165,233.7,233.99,1200,200,1,1,233.66,234.0,201,50,2,1,233.58,234.05,505,27,2,1,233.53,234.1,10,100,1,1,233.5,234.13,100,400,1,1,233.45,234.17,15,1,1,1,233.4,234.25,110,100,2,1,233.39,234.41,10,600,1,2,233.31,234.43,110,105,2,2,233.3,234.5,100,63,1,4,AAPL,0.0,0.0,-26.0,-201.0,-505.0,-10.0,-100.0,-15.0,-110.0,-10.0,-110.0,-161.95744002995872,
2024-10-21T12:18:38.189958263Z,2024-10-21T12:18:38.189791855Z,10,2,38,A,B,2,233.62,28,130,166408,12695166,233.7,233.99,1200,200,1,1,233.66,234.0,201,50,2,1,233.62,234.05,28,27,1,1,233.58,234.1,505,100,2,1,233.53,234.13,10,400,1,1,233.5,234.17,100,1,1,1,233.45,234.25,15,100,1,1,233.4,234.41,110,600,2,2,233.39,234.43,10,105,1,2,233.31,234.5,110,63,2,4,AAPL,0.0,0.0,0.0,28.0,505.0,10.0,100.0,15.0,110.0,10.0,110.0,142.7348333290792,
2024-10-21T12:18:40.408253176Z,2024-10-21T12:18:40.408086849Z,10,2,38,C,B,2,233.62,28,130,166327,12697055,233.7,233.99,1200,200,1,1,233.66,234.0,201,50,2,1,233.58,234.05,505,27,2,1,233.53,234.1,10,100,1,1,233.5,234.13,100,400,1,1,233.45,234.17,15,1,1,1,233.4,234.25,110,100,2,1,233.39,234.41,10,600,1,2,233.31,234.43,110,105,2,2,233.3,234.5,100,63,1,4,AAPL,0.0,0.0,0.0,-28.0,-505.0,-10.0,-100.0,-15.0,-110.0,-10.0,-110.0,-142.7348333290792,
2024-10-21T12:18:40.408303418Z,2024-10-21T12:18:40.408137058Z,10,2,38,A,B,2,233.63,26,130,166360,12697056,233.7,233.99,1200,200,1,1,233.66,234.0,201,50,2,1,233.63,234.05,26,27,1,1,233.58,234.1,505,100,2,1,233.53,234.13,10,400,1,1,233.5,234.17,100,1,1,1,233.45,234.25,15,100,1,1,233.4,234.41,110,600,2,2,233.39,234.43,10,105,1,2,233.31,234.5,110,63,2,4,AAPL,0.0,0.0,0.0,26.0,505.0,10.0,100.0,15.0,110.0,10.0,110.0,142.5316681676072,
2024-10-21T12:18:41.180157281Z,2024-10-21T12:18:41.179991523Z,10,2,38,C,B,2,233.63,26,130,165758,12697907,233.7,233.99,1200,200,1,1,233.66,234.0,201,50,2,1,233.58,234.05,505,27,2,1,233.53,234.1,10,100,1,1,233.5,234.13,100,400,1,1,233.45,234.17,15,1,1,1,233.4,234.25,110,100,2,1,233.39,234.41,10,600,1,2,233.31,234.43,110,105,2,2,233.3,234.5,100,63,1,4,AAPL,0.0,0.0,0.0,-26.0,-505.0,-10.0,-100.0,-15.0,-110.0,-10.0,-110.0,-142.5316681676072,
2024-10-21T12:18:41.180284870Z,2024-10-21T12:18:41.180118662Z,10,2,38,A,B,1,233.68,30,130,166208,12697911,233.7,233.99,1200,200,1,1,233.68,234.0,30,50,1,1,233.66,234.05,201,27,2,1,233.58,234.1,505,100,2,1,233.53,234.13,10,400,1,1,233.5,234.17,100,1,1,1,233.45,234.25,15,100,1,1,233.4,234.41,110,600,2,2,233.39,234.43,10,105,1,2,233.31,234.5,110,63,2,4,AAPL,0.0,0.0,30.0,201.0,505.0,10.0,100.0,15.0,110.0,10.0,110.0,162.21110468127418,
2024-10-21T12:18:41.234091711Z,2024-10-21T12:18:41.233925482Z,10,2,38,A,B,0,233.74,200,130,166229,12697993,233.74,233.99,200,200,1,1,233.7,234.0,1200,50,1,1,233.68,234.05,30,27,1,1,233.66,234.1,1,100,1,1,233.58,234.13,505,400,2,1,233.53,234.17,10,1,1,1,233.5,234.25,100,100,1,1,233.45,234.41,15,600,1,2,233.4,234.43,110,105,2,2,233.39,234.5,10,63,1,4,AAPL,200.0,200.0,1200.0,30.0,1.0,505.0,10.0,100.0,15.0,110.0,10.0,164.74096475787846,
2024-10-21T12:18:44.453669428Z,2024-10-21T12:18:44.453502831Z,10,2,38,A,A,0,233.98,200,130,166597,12700269,233.74,233.98,200,200,1,1,233.7,234.0,1200,50,1,1,233.68,234.05,30,27,1,1,233.66,234.1,1,100,1,1,233.58,234.13,505,400,2,1,233.53,234.17,10,1,1,1,233.5,234.25,100,100,1,1,233.45,234.41,15,600,1,2,233.4,234.43,110,105,2,2,233.39,234.5,10,63,1,4,AAPL,-200.0,-200.0,0.0,0.0,0.0,0.0,0.0,0.0,0.0,0.0,0.0,-3.9761165292250036,
2024-10-21T12:18:44.458737649Z,2024-10-21T12:18:44.458571638Z,10,2,38,C,B,0,233.74,200,130,166011,12700368,233.7,233.98,1200,200,1,1,233.68,234.0,30,50,1,1,233.66,234.05,1,27,1,1,233.58,234.1,505,100,2,1,233.53,234.13,10,400,1,1,233.5,234.17,100,1,1,1,233.45,234.25,15,100,1,1,233.4,234.41,110,600,2,2,233.39,234.43,10,105,1,2,233.31,234.5,110,63,2,4,AAPL,-200.0,-200.0,-1200.0,-30.0,-1.0,-505.0,-10.0,-100.0,-15.0,-110.0,-10.0,-164.74096475787846,
2024-10-21T12:18:44.458749682Z,2024-10-21T12:18:44.458583443Z,10,2,38,A,B,2,233.66,200,130,166239,12700369,233.7,233.98,1200,200,1,1,233.68,234.0,30,50,1,1,233.66,234.05,201,27,2,1,233.58,234.1,505,100,2,1,233.53,234.13,10,400,1,1,233.5,234.17,100,1,1,1,233.45,234.25,15,100,1,1,233.4,234.41,110,600,2,2,233.39,234.43,10,105,1,2,233.31,234.5,110,63,2,4,AAPL,0.0,0.0,0.0,200.0,0.0,0.0,0.0,0.0,0.0,0.0,0.0,20.31651614720104,
2024-10-21T12:18:44.477985018Z,2024-10-21T12:18:44.477818456Z,10,2,38,C,B,1,233.68,30,130,166562,12700470,233.7,233.98,1200,200,1,1,233.66,234.0,201,50,2,1,233.58,234.05,505,27,2,1,233.53,234.1,10,100,1,1,233.5,234.13,100,400,1,1,233.45,234.17,15,1,1,1,233.4,234.25,110,100,2,1,233.39,234.41,10,600,1,2,233.31,234.43,110,105,2,2,233.3,234.5,100,63,1,4,AAPL,0.0,0.0,-30.0,-201.0,-505.0,-10.0,-100.0,-15.0,-110.0,-10.0,-110.0,-162.21110468127418,
2024-10-21T12:18:44.478091299Z,2024-10-21T12:18:44.477924999Z,10,2,38,A,B,2,233.62,28,130,166300,12700471,233.7,233.98,1200,200,1,1,233.66,234.0,201,50,2,1,233.62,234.05,28,27,1,1,233.58,234.1,505,100,2,1,233.53,234.13,10,400,1,1,233.5,234.17,100,1,1,1,233.45,234.25,15,100,1,1,233.4,234.41,110,600,2,2,233.39,234.43,10,105,1,2,233.31,234.5,110,63,2,4,AAPL,0.0,0.0,0.0,28.0,505.0,10.0,100.0,15.0,110.0,10.0,110.0,142.7348333290792,
2024-10-21T12:18:47.144655653Z,2024-10-21T12:18:47.144489374Z,10,2,38,A,A,0,233.97,200,130,166279,12703555,233.7,233.97,1200,200,1,1,233.66,234.0,201,50,2,1,233.62,234.05,28,27,1,1,233.58,234.1,505,100,2,1,233.53,234.13,10,400,1,1,233.5,234.17,100,1,1,1,233.45,234.25,15,100,1,1,233.4,234.41,110,600,2,2,233.39,234.43,10,105,1,2,233.31,234.5,110,63,2,4,AAPL,-200.0,-200.0,0.0,0.0,0.0,0.0,0.0,0.0,0.0,0.0,0.0,-3.9761165292250036,
2024-10-21T12:18:47.206489928Z,2024-10-21T12:18:47.206323404Z,10,2,38,A,B,1,233.66,200,130,166524,12703653,233.7,233.97,1200,200,1,1,233.66,234.0,401,50,3,1,233.62,234.05,28,27,1,1,233.58,234.1,505,100,2,1,233.53,234.13,10,400,1,1,233.5,234.17,100,1,1,1,233.45,234.25,15,100,1,1,233.4,234.41,110,600,2,2,233.39,234.43,10,105,1,2,233.31,234.5,110,63,2,4,AAPL,0.0,0.0,200.0,0.0,0.0,0.0,0.0,0.0,0.0,0.0,0.0,12.683232565773917,
2024-10-21T12:18:47.261027171Z,2024-10-21T12:18:47.260861161Z,10,2,38,C,B,1,233.66,200,130,166010,12703745,233.7,233.97,1200,200,1,1,233.66,234.0,201,50,2,1,233.62,234.05,28,27,1,1,233.58,234.1,505,100,2,1,233.53,234.13,10,400,1,1,233.5,234.17,100,1,1,1,233.45,234.25,15,100,1,1,233.4,234.41,110,600,2,2,233.39,234.43,10,105,1,2,233.31,234.5,110,63,2,4,AAPL,0.0,0.0,-200.0,0.0,0.0,0.0,0.0,0.0,0.0,0.0,0.0,-12.683232565773917,
2024-10-21T12:18:47.261040389Z,2024-10-21T12:18:47.260873969Z,10,2,38,A,B,0,233.7,200,130,166420,12703746,233.7,233.97,1400,200,2,1,233.66,234.0,1,50,1,1,233.62,234.05,28,27,1,1,233.58,234.1,505,100,2,1,233.53,234.13,10,400,1,1,233.5,234.17,100,1,1,1,233.45,234.25,15,100,1,1,233.4,234.41,110,600,2,2,233.39,234.43,10,105,1,2,233.31,234.5,110,63,2,4,AAPL,200.0,200.0,-200.0,0.0,0.0,0.0,0.0,0.0,0.0,0.0,0.0,-8.707116036548912,
2024-10-21T12:18:47.459627907Z,2024-10-21T12:18:47.459461214Z,10,2,38,A,B,0,233.7,200,130,166693,12703881,233.7,233.97,1600,200,3,1,233.66,234.0,1,50,1,1,233.62,234.05,28,27,1,1,233.58,234.1,505,100,2,1,233.53,234.13,10,400,1,1,233.5,234.17,100,1,1,1,233.45,234.25,15,100,1,1,233.4,234.41,110,600,2,2,233.39,234.43,10,105,1,2,233.31,234.5,110,63,2,4,AAPL,200.0,200.0,0.0,0.0,0.0,0.0,0.0,0.0,0.0,0.0,0.0,3.9761165292250036,
2024-10-21T12:18:47.514149868Z,2024-10-21T12:18:47.513983492Z,10,2,38,C,B,0,233.7,200,130,166376,12703892,233.7,233.97,1400,200,2,1,233.66,234.0,1,50,1,1,233.62,234.05,28,27,1,1,233.58,234.1,505,100,2,1,233.53,234.13,10,400,1,1,233.5,234.17,100,1,1,1,233.45,234.25,15,100,1,1,233.4,234.41,110,600,2,2,233.39,234.43,10,105,1,2,233.31,234.5,110,63,2,4,AAPL,-200.0,-200.0,0.0,0.0,0.0,0.0,0.0,0.0,0.0,0.0,0.0,-3.9761165292250036,
2024-10-21T12:18:47.514162028Z,2024-10-21T12:18:47.513995474Z,10,2,38,A,B,0,233.74,200,130,166554,12703893,233.74,233.97,200,200,1,1,233.7,234.0,1200,50,1,1,233.66,234.05,1,27,1,1,233.62,234.1,28,100,1,1,233.58,234.13,505,400,2,1,233.53,234.17,10,1,1,1,233.5,234.25,100,100,1,1,233.45,234.41,15,600,1,2,233.4,234.43,110,105,2,2,233.39,234.5,10,63,1,4,AAPL,200.0,200.0,1200.0,1.0,28.0,505.0,10.0,100.0,15.0,110.0,10.0,167.3321504021855,
2024-10-21T12:18:48.012823351Z,2024-10-21T12:18:48.012656935Z,10,2,38,C,A,0,233.97,200,130,166416,12704330,233.74,234.0,200,50,1,1,233.7,234.05,1200,27,1,1,233.66,234.1,1,100,1,1,233.62,234.13,28,400,1,1,233.58,234.17,505,1,2,1,233.53,234.25,10,100,1,1,233.5,234.41,100,600,1,2,233.45,234.43,15,105,1,2,233.4,234.5,110,63,2,4,233.39,234.75,10,1,1,1,AAPL,50.0,50.0,27.0,100.0,400.0,1.0,100.0,600.0,105.0,63.0,1.0,192.29130095376698,
2024-10-21T12:18:48.012837187Z,2024-10-21T12:18:48.012670562Z,10,2,38,A,A,1,234.03,200,130,166625,12704331,233.74,234.0,200,50,1,1,233.7,234.03,1200,200,1,1,233.66,234.05,1,27,1,1,233.62,234.1,28,100,1,1,233.58,234.13,505,400,2,1,233.53,234.17,10,1,1,1,233.5,234.25,100,100,1,1,233.45,234.41,15,600,1,2,233.4,234.43,110,105,2,2,233.39,234.5,10,63,1,4,AAPL,0.0,0.0,-27.0,-100.0,-400.0,-1.0,-100.0,-600.0,-105.0,-63.0,-1.0,-191.29727182146073,
2024-10-21T12:18:48.013001331Z,2024-10-21T12:18:48.012835297Z,10,2,38,A,A,1,234.03,200,130,166034,12704332,233.74,234.0,200,50,1,1,233.7,234.03,1200,400,1,2,233.66,234.05,1,27,1,1,233.62,234.1,28,100,1,1,233.58,234.13,505,400,2,1,233.53,234.17,10,1,1,1,233.5,234.25,100,100,1,1,233.45,234.41,15,600,1,2,233.4,234.43,110,105,2,2,233.39,234.5,10,63,1,4,AAPL,0.0,0.0,-200.0,0.0,0.0,0.0,0.0,0.0,0.0,0.0,0.0,-12.683232565773917,
2024-10-21T12:18:48.013375765Z,2024-10-21T12:18:48.013209412Z,10,2,38,C,A,2,234.05,27,130,166353,12704333,233.74,234.0,200,50,1,1,233.7,234.03,1200,400,1,2,233.66,234.1,1,100,1,1,233.62,234.13,28,400,1,1,233.58,234.17,505,1,2,1,233.53,234.25,10,100,1,1,233.5,234.41,100,600,1,2,233.45,234.43,15,105,1,2,233.4,234.5,110,63,2,4,233.39,234.75,10,1,1,1,AAPL,0.0,0.0,0.0,100.0,400.0,1.0,100.0,600.0,105.0,63.0,1.0,189.58503542508126,
2024-10-21T12:18:48.013479203Z,2024-10-21T12:18:48.013312876Z,10,2,38,A,A,2,234.1,28,130,166327,12704334,233.74,234.0,200,50,1,1,233.7,234.03,1200,400,1,2,233.66,234.1,1,128,1,2,233.62,234.13,28,400,1,1,233.58,234.17,505,1,2,1,233.53,234.25,10,100,1,1,233.5,234.41,100,600,1,2,233.45,234.43,15,105,1,2,233.4,234.5,110,63,2,4,233.39,234.75,10,1,1,1,AAPL,0.0,0.0,0.0,-28.0,0.0,0.0,0.0,0.0,0.0,0.0,0.0,-2.8443122606081452,
2024-10-21T12:18:48.070451078Z,2024-10-21T12:18:48.070285169Z,10,2,38,C,A,1,234.03,200,130,165909,12704401,233.74,234.0,200,50,1,1,233.7,234.03,1200,200,1,1,233.66,234.1,1,128,1,2,233.62,234.13,28,400,1,1,233.58,234.17,505,1,2,1,233.53,234.25,10,100,1,1,233.5,234.41,100,600,1,2,233.45,234.43,15,105,1,2,233.4,234.5,110,63,2,4,233.39,234.75,10,1,1,1,AAPL,0.0,0.0,200.0,0.0,0.0,0.0,0.0,0.0,0.0,0.0,0.0,12.683232565773917,
2024-10-21T12:18:48.070465807Z,2024-10-21T12:18:48.070297042Z,10,2,38,A,A,0,233.97,200,128,168765,12704402,233.74,233.97,200,200,1,1,233.7,234.0,1200,50,1,1,233.66,234.1,1,128,1,2,233.62,234.13,28,400,1,1,233.58,234.17,505,1,2,1,233.53,234.25,10,100,1,1,233.5,234.41,100,600,1,2,233.45,234.43,15,105,1,2,233.4,234.5,110,63,2,4,233.39,234.75,10,1,1,1,AAPL,-50.0,-50.0,-200.0,0.0,0.0,0.0,0.0,0.0,0.0,0.0,0.0,-13.677261698080168,
2024-10-21T12:18:48.200074274Z,2024-10-21T12:18:48.199908254Z,10,2,38,C,B,0,233.74,200,130,166020,12704576,233.7,233.97,1200,200,1,1,233.66,234.0,1,50,1,1,233.62,234.1,28,128,1,2,233.58,234.13,505,400,2,1,233.53,234.17,10,1,1,1,233.5,234.25,100,100,1,1,233.45,234.41,15,600,1,2,233.4,234.43,110,105,2,2,233.39,234.5,10,63,1,4,233.31,234.75,110,1,2,1,AAPL,-200.0,-200.0,-1200.0,-1.0,-28.0,-505.0,-10.0,-100.0,-15.0,-110.0,-10.0,-167.3321504021855,
2024-10-21T12:18:48.200087164Z,2024-10-21T12:18:48.199920865Z,10,2,38,A,B,1,233.68,200,130,166299,12704577,233.7,233.97,1200,200,1,1,233.68,234.0,200,50,1,1,233.66,234.1,1,128,1,2,233.62,234.13,28,400,1,1,233.58,234.17,505,1,2,1,233.53,234.25,10,100,1,1,233.5,234.41,100,600,1,2,233.45,234.43,15,105,1,2,233.4,234.5,110,63,2,4,233.39,234.75,10,1,1,1,AAPL,0.0,0.0,200.0,1.0,28.0,505.0,10.0,100.0,15.0,110.0,10.0,99.9398710440909,
2024-10-21T12:18:48.200108087Z,2024-10-21T12:18:48.199942139Z,10,2,38,C,B,1,233.68,200,130,165948,12704578,233.7,233.97,1200,200,1,1,233.66,234.0,1,50,1,1,233.62,234.1,28,128,1,2,233.58,234.13,505,400,2,1,233.53,234.17,10,1,1,1,233.5,234.25,100,100,1,1,233.45,234.41,15,600,1,2,233.4,234.43,110,105,2,2,233.39,234.5,10,63,1,4,233.31,234.75,110,1,2,1,AAPL,0.0,0.0,-200.0,-1.0,-28.0,-505.0,-10.0,-100.0,-15.0,-110.0,-10.0,-99.9398710440909,
2024-10-21T12:18:48.200195970Z,2024-10-21T12:18:48.200029266Z,10,2,38,A,B,2,233.65,200,130,166704,12704579,233.7,233.97,1200,200,1,1,233.66,234.0,1,50,1,1,233.65,234.1,200,128,1,2,233.62,234.13,28,400,1,1,233.58,234.17,505,1,2,1,233.53,234.25,10,100,1,1,233.5,234.41,100,600,1,2,233.45,234.43,15,105,1,2,233.4,234.5,110,63,2,4,233.39,234.75,10,1,1,1,AAPL,0.0,0.0,0.0,200.0,28.0,505.0,10.0,100.0,15.0,110.0,10.0,107.47157204478201,
2024-10-21T12:18:48.200668344Z,2024-10-21T12:18:48.200502296Z,10,2,38,C,B,3,233.62,28,130,166048,12704580,233.7,233.97,1200,200,1,1,233.66,234.0,1,50,1,1,233.65,234.1,200,128,1,2,233.58,234.13,505,400,2,1,233.53,234.17,10,1,1,1,233.5,234.25,100,100,1,1,233.45,234.41,15,600,1,2,233.4,234.43,110,105,2,2,233.39,234.5,10,63,1,4,233.31,234.75,110,1,2,1,AAPL,0.0,0.0,0.0,0.0,-28.0,-505.0,-10.0,-100.0,-15.0,-110.0,-10.0,-87.15505589758098,
2024-10-21T12:18:48.200720265Z,2024-10-21T12:18:48.200553666Z,10,2,38,A,B,1,233.67,27,130,166599,12704581,233.7,233.97,1200,200,1,1,233.67,234.0,27,50,1,1,233.66,234.1,1,128,1,2,233.65,234.13,200,400,1,1,233.58,234.17,505,1,2,1,233.53,234.25,10,100,1,1,233.5,234.41,100,600,1,2,233.45,234.43,15,105,1,2,233.4,234.5,110,63,2,4,233.39,234.75,10,1,1,1,AAPL,0.0,0.0,27.0,1.0,200.0,505.0,10.0,100.0,15.0,110.0,10.0,124.24212833884484,
2024-10-21T12:18:48.213389240Z,2024-10-21T12:18:48.213222660Z,10,2,38,C,B,1,233.67,27,130,166580,12704589,233.7,233.97,1200,200,1,1,233.66,234.0,1,50,1,1,233.65,234.1,200,128,1,2,233.58,234.13,505,400,2,1,233.53,234.17,10,1,1,1,233.5,234.25,100,100,1,1,233.45,234.41,15,600,1,2,233.4,234.43,110,105,2,2,233.39,234.5,10,63,1,4,233.31,234.75,110,1,2,1,AAPL,0.0,0.0,-27.0,-1.0,-200.0,-505.0,-10.0,-100.0,-15.0,-110.0,-10.0,-124.24212833884484,
2024-10-21T12:18:49.923109783Z,2024-10-21T12:18:49.922943623Z,10,2,38,C,A,2,234.1,28,130,166160,12706013,233.7,233.97,1200,200,1,1,233.66,234.0,1,50,1,1,233.65,234.1,200,100,1,1,233.58,234.13,505,400,2,1,233.53,234.17,10,1,1,1,233.5,234.25,100,100,1,1,233.45,234.41,15,600,1,2,233.4,234.43,110,105,2,2,233.39,234.5,10,63,1,4,233.31,234.75,110,1,2,1,AAPL,0.0,0.0,0.0,28.0,0.0,0.0,0.0,0.0,0.0,0.0,0.0,2.8443122606081452,
2024-10-21T12:18:49.923258127Z,2024-10-21T12:18:49.923091366Z,10,2,38,A,A,2,234.05,28,130,166761,12706014,233.7,233.97,1200,200,1,1,233.66,234.0,1,50,1,1,233.65,234.05,200,28,1,1,233.58,234.1,505,100,2,1,233.53,234.13,10,400,1,1,233.5,234.17,100,1,1,1,233.45,234.25,15,100,1,1,233.4,234.41,110,600,2,2,233.39,234.43,10,105,1,2,233.31,234.5,110,63,2,4,AAPL,0.0,0.0,0.0,-100.0,-400.0,-1.0,-100.0,-600.0,-105.0,-63.0,-1.0,-189.58503542508126,
2024-10-21T12:18:51.255092000Z,2024-10-21T12:18:51.254925630Z,10,2,38,A,B,1,233.69,200,130,166370,12707192,233.7,233.97,1200,200,1,1,233.69,234.0,200,50,1,1,233.66,234.05,1,28,1,1,233.58,234.1,505,100,2,1,233.53,234.13,10,400,1,1,233.5,234.17,100,1,1,1,233.45,234.25,15,100,1,1,233.4,234.41,110,600,2,2,233.39,234.43,10,105,1,2,233.31,234.5,110,63,2,4,AAPL,0.0,0.0,200.0,1.0,0.0,0.0,0.0,0.0,0.0,0.0,0.0,12.784815146509922,
2024-10-21T12:18:51.423495230Z,2024-10-21T12:18:51.423329256Z,10,2,38,C,A,2,234.05,28,130,165974,12707840,233.7,233.97,1200,200,1,1,233.69,234.0,200,50,1,1,233.66,234.1,1,100,1,1,233.58,234.13,505,400,2,1,233.53,234.17,10,1,1,1,233.5,234.25,100,100,1,1,233.45,234.41,15,600,1,2,233.4,234.43,110,105,2,2,233.39,234.5,10,63,1,4,233.31,234.75,110,1,2,1,AAPL,0.0,0.0,0.0,100.0,400.0,1.0,100.0,600.0,105.0,63.0,1.0,189.58503542508126,
2024-10-21T12:18:51.423548073Z,2024-10-21T12:18:51.423381788Z,10,2,38,A,A,2,234.04,30,130,166285,12707841,233.7,233.97,1200,200,1,1,233.69,234.0,200,50,1,1,233.66,234.04,1,30,1,1,233.58,234.1,505,100,2,1,233.53,234.13,10,400,1,1,233.5,234.17,100,1,1,1,233.45,234.25,15,100,1,1,233.4,234.41,110,600,2,2,233.39,234.43,10,105,1,2,233.31,234.5,110,63,2,4,AAPL,0.0,0.0,0.0,-100.0,-400.0,-1.0,-100.0,-600.0,-105.0,-63.0,-1.0,-189.58503542508126,
2024-10-21T12:18:51.430417250Z,2024-10-21T12:18:51.430250460Z,10,2,38,A,B,1,233.69,200,130,166790,12707856,233.7,233.97,1200,200,1,1,233.69,234.0,400,50,2,1,233.66,234.04,1,30,1,1,233.58,234.1,505,100,2,1,233.53,234.13,10,400,1,1,233.5,234.17,100,1,1,1,233.45,234.25,15,100,1,1,233.4,234.41,110,600,2,2,233.39,234.43,10,105,1,2,233.31,234.5,110,63,2,4,AAPL,0.0,0.0,200.0,0.0,0.0,0.0,0.0,0.0,0.0,0.0,0.0,12.683232565773917,
2024-10-21T12:18:53.923079620Z,2024-10-21T12:18:53.922913086Z,10,2,38,A,B,3,233.62,27,130,166534,12710377,233.7,233.97,1200,200,1,1,233.69,234.0,400,50,2,1,233.66,234.04,1,30,1,1,233.62,234.1,27,100,1,1,233.58,234.13,505,400,2,1,233.53,234.17,10,1,1,1,233.5,234.25,100,100,1,1,233.45,234.41,15,600,1,2,233.4,234.43,110,105,2,2,233.39,234.5,10,63,1,4,AAPL,0.0,0.0,0.0,0.0,27.0,505.0,10.0,100.0,15.0,110.0,10.0,86.94997884255686,
2024-10-21T12:19:00.084000089Z,2024-10-21T12:19:00.083834280Z,10,2,38,C,B,1,233.69,200,130,165809,12715313,233.7,233.97,1200,200,1,1,233.69,234.0,200,50,1,1,233.66,234.04,1,30,1,1,233.62,234.1,27,100,1,1,233.58,234.13,505,400,2,1,233.53,234.17,10,1,1,1,233.5,234.25,100,100,1,1,233.45,234.41,15,600,1,2,233.4,234.43,110,105,2,2,233.39,234.5,10,63,1,4,AAPL,0.0,0.0,-200.0,0.0,0.0,0.0,0.0,0.0,0.0,0.0,0.0,-12.683232565773917,
2024-10-21T12:19:00.084009808Z,2024-10-21T12:19:00.083843895Z,10,2,38,C,B,1,233.69,200,130,165913,12715314,233.7,233.97,1200,200,1,1,233.66,234.0,1,50,1,1,233.62,234.04,27,30,1,1,233.58,234.1,505,100,2,1,233.53,234.13,10,400,1,1,233.5,234.17,100,1,1,1,233.45,234.25,15,100,1,1,233.4,234.41,110,600,2,2,233.39,234.43,10,105,1,2,233.31,234.5,110,63,2,4,AAPL,0.0,0.0,-200.0,-1.0,-27.0,-505.0,-10.0,-100.0,-15.0,-110.0,-10.0,-99.73479398906677,
2024-10-21T12:19:00.084021335Z,2024-10-21T12:19:00.083854884Z,10,2,38,A,B,1,233.68,200,130,166451,12715315,233.7,233.97,1200,200,1,1,233.68,234.0,200,50,1,1,233.66,234.04,1,30,1,1,233.62,234.1,27,100,1,1,233.58,234.13,505,400,2,1,233.53,234.17,10,1,1,1,233.5,234.25,100,100,1,1,233.45,234.41,15,600,1,2,233.4,234.43,110,105,2,2,233.39,234.5,10,63,1,4,AAPL,0.0,0.0,200.0,1.0,27.0,505.0,10.0,100.0,15.0,110.0,10.0,99.73479398906677,
2024-10-21T12:19:00.143641105Z,2024-10-21T12:19:00.143474250Z,10,2,38,A,B,1,233.69,200,130,166855,12715619,233.7,233.97,1200,200,1,1,233.69,234.0,200,50,1,1,233.66,234.04,1,30,1,1,233.62,234.1,27,100,1,1,233.58,234.13,505,400,2,1,233.53,234.17,10,1,1,1,233.5,234.25,100,100,1,1,233.45,234.41,15,600,1,2,233.4,234.43,110,105,2,2,233.39,234.5,10,63,1,4,AAPL,0.0,0.0,200.0,0.0,0.0,0.0,0.0,0.0,0.0,0.0,0.0,12.683232565773917,
2024-10-21T12:19:00.197681940Z,2024-10-21T12:19:00.197516009Z,10,2,38,A,B,1,233.69,200,130,165931,12715801,233.7,233.97,1200,200,1,1,233.69,234.0,400,50,2,1,233.66,234.04,1,30,1,1,233.62,234.1,27,100,1,1,233.58,234.13,505,400,2,1,233.53,234.17,10,1,1,1,233.5,234.25,100,100,1,1,233.45,234.41,15,600,1,2,233.4,234.43,110,105,2,2,233.39,234.5,10,63,1,4,AAPL,0.0,0.0,200.0,0.0,0.0,0.0,0.0,0.0,0.0,0.0,0.0,12.683232565773917,
2024-10-21T12:19:00.198183165Z,2024-10-21T12:19:00.198016624Z,10,2,38,C,B,3,233.62,27,130,166541,12715804,233.7,233.97,1200,200,1,1,233.69,234.0,400,50,2,1,233.66,234.04,1,30,1,1,233.58,234.1,505,100,2,1,233.53,234.13,10,400,1,1,233.5,234.17,100,1,1,1,233.45,234.25,15,100,1,1,233.4,234.41,110,600,2,2,233.39,234.43,10,105,1,2,233.31,234.5,110,63,2,4,AAPL,0.0,0.0,0.0,0.0,-27.0,-505.0,-10.0,-100.0,-15.0,-110.0,-10.0,-86.94997884255686,
2024-10-21T12:19:00.198223152Z,2024-10-21T12:19:00.198056773Z,10,2,38,A,B,2,233.66,27,130,166379,12715805,233.7,233.97,1200,200,1,1,233.69,234.0,400,50,2,1,233.66,234.04,28,30,2,1,233.58,234.1,505,100,2,1,233.53,234.13,10,400,1,1,233.5,234.17,100,1,1,1,233.45,234.25,15,100,1,1,233.4,234.41,110,600,2,2,233.39,234.43,10,105,1,2,233.31,234.5,110,63,2,4,AAPL,0.0,0.0,0.0,27.0,0.0,0.0,0.0,0.0,0.0,0.0,0.0,2.74272967987214,
2024-10-21T12:19:00.251528734Z,2024-10-21T12:19:00.251362837Z,10,2,38,C,B,1,233.69,200,130,165897,12715921,233.7,233.97,1200,200,1,1,233.69,234.0,200,50,1,1,233.66,234.04,28,30,2,1,233.58,234.1,505,100,2,1,233.53,234.13,10,400,1,1,233.5,234.17,100,1,1,1,233.45,234.25,15,100,1,1,233.4,234.41,110,600,2,2,233.39,234.43,10,105,1,2,233.31,234.5,110,63,2,4,AAPL,0.0,0.0,-200.0,0.0,0.0,0.0,0.0,0.0,0.0,0.0,0.0,-12.683232565773917,
2024-10-21T12:19:00.251542039Z,2024-10-21T12:19:00.251375630Z,10,2,38,A,B,0,233.73,200,130,166409,12715922,233.73,233.97,200,200,1,1,233.7,234.0,1200,50,1,1,233.66,234.04,28,30,2,1,233.58,234.1,505,100,2,1,233.53,234.13,10,400,1,1,233.5,234.17,100,1,1,1,233.45,234.25,15,100,1,1,233.4,234.41,110,600,2,2,233.39,234.43,10,105,1,2,233.31,234.5,110,63,2,4,AAPL,200.0,200.0,1200.0,0.0,0.0,0.0,0.0,0.0,0.0,0.0,0.0,80.0755119238685,
2024-10-21T12:19:02.578905341Z,2024-10-21T12:19:02.578739513Z,10,2,38,C,B,0,233.73,200,130,165828,12718269,233.7,233.97,1200,200,1,1,233.66,234.0,28,50,2,1,233.58,234.04,505,30,2,1,233.53,234.1,10,100,1,1,233.5,234.13,100,400,1,1,233.45,234.17,15,1,1,1,233.4,234.25,110,100,2,1,233.39,234.41,10,600,1,2,233.31,234.43,110,105,2,2,233.3,234.5,100,63,1,4,AAPL,-200.0,-200.0,-1200.0,-28.0,-505.0,-10.0,-100.0,-15.0,-110.0,-10.0,-110.0,-222.8103452529477,
2024-10-21T12:19:02.578919174Z,2024-10-21T12:19:02.578752989Z,10,2,38,A,B,1,233.68,200,130,166185,12718270,233.7,233.97,1200,200,1,1,233.68,234.0,200,50,1,1,233.66,234.04,28,30,2,1,233.58,234.1,505,100,2,1,233.53,234.13,10,400,1,1,233.5,234.17,100,1,1,1,233.45,234.25,15,100,1,1,233.4,234.41,110,600,2,2,233.39,234.43,10,105,1,2,233.31,234.5,110,63,2,4,AAPL,0.0,0.0,200.0,28.0,505.0,10.0,100.0,15.0,110.0,10.0,110.0,155.41806589485313,
2024-10-21T12:19:02.578950637Z,2024-10-21T12:19:02.578784855Z,10,2,38,C,B,1,233.68,200,130,165782,12718271,233.7,233.97,1200,200,1,1,233.66,234.0,28,50,2,1,233.58,234.04,505,30,2,1,233.53,234.1,10,100,1,1,233.5,234.13,100,400,1,1,233.45,234.17,15,1,1,1,233.4,234.25,110,100,2,1,233.39,234.41,10,600,1,2,233.31,234.43,110,105,2,2,233.3,234.5,100,63,1,4,AAPL,0.0,0.0,-200.0,-28.0,-505.0,-10.0,-100.0,-15.0,-110.0,-10.0,-110.0,-155.41806589485313,
2024-10-21T12:19:02.583888440Z,2024-10-21T12:19:02.583722081Z,10,2,38,A,B,2,233.65,200,130,166359,12718279,233.7,233.97,1200,200,1,1,233.66,234.0,28,50,2,1,233.65,234.04,200,30,1,1,233.58,234.1,505,100,2,1,233.53,234.13,10,400,1,1,233.5,234.17,100,1,1,1,233.45,234.25,15,100,1,1,233.4,234.41,110,600,2,2,233.39,234.43,10,105,1,2,233.31,234.5,110,63,2,4,AAPL,0.0,0.0,0.0,200.0,505.0,10.0,100.0,15.0,110.0,10.0,110.0,160.2070372156721,
2024-10-21T12:19:05.634123171Z,2024-10-21T12:19:05.633956677Z,10,2,38,A,B,0,233.73,200,130,166494,12720933,233.73,233.97,200,200,1,1,233.7,234.0,1200,50,1,1,233.66,234.04,28,30,2,1,233.58,234.1,505,100,2,1,233.53,234.13,10,400,1,1,233.5,234.17,100,1,1,1,233.45,234.25,15,100,1,1,233.4,234.41,110,600,2,2,233.39,234.43,10,105,1,2,233.31,234.5,110,63,2,4,AAPL,200.0,200.0,1200.0,28.0,0.0,0.0,0.0,0.0,0.0,0.0,0.0,82.91982418447665,
2024-10-21T12:19:06.744727908Z,2024-10-21T12:19:06.744561325Z,10,2,38,A,A,0,233.96,200,130,166583,12722330,233.73,233.96,200,200,1,1,233.7,234.0,1200,50,1,1,233.66,234.04,28,30,2,1,233.58,234.1,505,100,2,1,233.53,234.13,10,400,1,1,233.5,234.17,100,1,1,1,233.45,234.25,15,100,1,1,233.4,234.41,110,600,2,2,233.39,234.43,10,105,1,2,233.31,234.5,110,63,2,4,AAPL,-200.0,-200.0,0.0,0.0,0.0,0.0,0.0,0.0,0.0,0.0,0.0,-3.9761165292250036,
2024-10-21T12:19:07.485333806Z,2024-10-21T12:19:07.485167707Z,10,2,38,C,B,0,233.73,200,130,166099,12723226,233.7,233.96,1200,200,1,1,233.66,234.0,28,50,2,1,233.58,234.04,505,30,2,1,233.53,234.1,10,100,1,1,233.5,234.13,100,400,1,1,233.45,234.17,15,1,1,1,233.4,234.25,110,100,2,1,233.39,234.41,10,600,1,2,233.31,234.43,110,105,2,2,233.3,234.5,100,63,1,4,AAPL,-200.0,-200.0,-1200.0,-28.0,-505.0,-10.0,-100.0,-15.0,-110.0,-10.0,-110.0,-222.8103452529477,
2024-10-21T12:19:07.485347068Z,2024-10-21T12:19:07.485180575Z,10,2,38,A,B,1,233.66,200,130,166493,12723227,233.7,233.96,1200,200,1,1,233.66,234.0,228,50,3,1,233.58,234.04,505,30,2,1,233.53,234.1,10,100,1,1,233.5,234.13,100,400,1,1,233.45,234.17,15,1,1,1,233.4,234.25,110,100,2,1,233.39,234.41,10,600,1,2,233.31,234.43,110,105,2,2,233.3,234.5,100,63,1,4,AAPL,0.0,0.0,200.0,0.0,0.0,0.0,0.0,0.0,0.0,0.0,0.0,12.683232565773917,
2024-10-21T12:19:07.567639201Z,2024-10-21T12:19:07.567472916Z,10,2,38,A,A,2,234.03,27,130,166285,12723377,233.7,233.96,1200,200,1,1,233.66,234.0,228,50,3,1,233.58,234.03,505,27,2,1,233.53,234.04,10,30,1,1,233.5,234.1,100,100,1,1,233.45,234.13,15,400,1,1,233.4,234.17,110,1,2,1,233.39,234.25,10,100,1,1,233.31,234.41,110,600,2,2,233.3,234.43,100,105,1,2,AAPL,0.0,0.0,0.0,-30.0,-100.0,-400.0,-1.0,-100.0,-600.0,-105.0,-63.0,-154.37121991041715,
2024-10-21T12:19:07.624787875Z,2024-10-21T12:19:07.624621845Z,10,2,38,C,A,3,234.04,30,130,166030,12723449,233.7,233.96,1200,200,1,1,233.66,234.0,228,50,3,1,233.58,234.03,505,27,2,1,233.53,234.1,10,100,1,1,233.5,234.13,100,400,1,1,233.45,234.17,15,1,1,1,233.4,234.25,110,100,2,1,233.39,234.41,10,600,1,2,233.31,234.43,110,105,2,2,233.3,234.5,100,63,1,4,AAPL,0.0,0.0,0.0,0.0,100.0,400.0,1.0,100.0,600.0,105.0,63.0,151.32374248833702,
2024-10-21T12:19:08.124149233Z,2024-10-21T12:19:08.123983275Z,10,2,38,C,A,0,233.96,200,130,165958,12724349,233.7,234.0,1200,50,1,1,233.66,234.03,228,27,3,1,233.58,234.1,505,100,2,1,233.53,234.13,10,400,1,1,233.5,234.17,100,1,1,1,233.45,234.25,15,100,1,1,233.4,234.41,110,600,2,2,233.39,234.43,10,105,1,2,233.31,234.5,110,63,2,4,233.3,234.75,100,1,1,1,AAPL,50.0,50.0,27.0,100.0,400.0,1.0,100.0,600.0,105.0,63.0,1.0,192.29130095376698,
2024-10-21T12:19:08.201876654Z,2024-10-21T12:19:08.201710146Z,10,2,38,A,A,0,233.96,200,130,166508,12724487,233.7,233.96,1200,200,1,1,233.66,234.0,228,50,3,1,233.58,234.03,505,27,2,1,233.53,234.1,10,100,1,1,233.5,234.13,100,400,1,1,233.45,234.17,15,1,1,1,233.4,234.25,110,100,2,1,233.39,234.41,10,600,1,2,233.31,234.43,110,105,2,2,233.3,234.5,100,63,1,4,AAPL,-50.0,-50.0,-27.0,-100.0,-400.0,-1.0,-100.0,-600.0,-105.0,-63.0,-1.0,-192.29130095376698,
2024-10-21T12:19:10.540539563Z,2024-10-21T12:19:10.540372657Z,10,2,38,A,B,1,233.68,200,130,166906,12726299,233.7,233.96,1200,200,1,1,233.68,234.0,200,50,1,1,233.66,234.03,28,27,2,1,233.58,234.1,505,100,2,1,233.53,234.13,10,400,1,1,233.5,234.17,100,1,1,1,233.45,234.25,15,100,1,1,233.4,234.41,110,600,2,2,233.39,234.43,10,105,1,2,233.31,234.5,110,63,2,4,AAPL,0.0,0.0,200.0,28.0,505.0,10.0,100.0,15.0,110.0,10.0,110.0,155.41806589485313,
2024-10-21T12:19:10.824581833Z,2024-10-21T12:19:10.824415398Z,10,2,38,C,A,7,234.41,39,130,166435,12726899,233.7,233.96,1200,200,1,1,233.68,234.0,200,50,1,1,233.66,234.03,28,27,2,1,233.58,234.1,505,100,2,1,233.53,234.13,10,400,1,1,233.5,234.17,100,1,1,1,233.45,234.25,15,100,1,1,233.4,234.41,110,561,2,2,233.39,234.43,10,105,1,2,233.31,234.5,110,63,2,4,AAPL,0.0,0.0,0.0,0.0,0.0,0.0,0.0,0.0,39.0,0.0,0.0,3.963034984624078,
2024-10-21T12:19:10.828328587Z,2024-10-21T12:19:10.828162441Z,10,2,38,A,A,7,234.41,39,130,166146,12726909,233.7,233.96,1200,200,1,1,233.68,234.0,200,50,1,1,233.66,234.03,28,27,2,1,233.58,234.1,505,100,2,1,233.53,234.13,10,400,1,1,233.5,234.17,100,1,1,1,233.45,234.25,15,100,1,1,233.4,234.41,110,600,2,3,233.39,234.43,10,105,1,2,233.31,234.5,110,63,2,4,AAPL,0.0,0.0,0.0,0.0,0.0,0.0,0.0,0.0,-39.0,0.0,0.0,-3.963034984624078,
2024-10-21T12:19:14.207607166Z,2024-10-21T12:19:14.207440891Z,10,2,38,A,B,1,233.68,200,130,166275,12730136,233.7,233.96,1200,200,1,1,233.68,234.0,400,50,2,1,233.66,234.03,28,27,2,1,233.58,234.1,505,100,2,1,233.53,234.13,10,400,1,1,233.5,234.17,100,1,1,1,233.45,234.25,15,100,1,1,233.4,234.41,110,600,2,3,233.39,234.43,10,105,1,2,233.31,234.5,110,63,2,4,AAPL,0.0,0.0,200.0,0.0,0.0,0.0,0.0,0.0,0.0,0.0,0.0,12.683232565773917,
2024-10-21T12:19:21.463822961Z,2024-10-21T12:19:21.463656720Z,10,2,38,C,A,7,234.41,39,130,166241,12734671,233.7,233.96,1200,200,1,1,233.68,234.0,400,50,2,1,233.66,234.03,28,27,2,1,233.58,234.1,505,100,2,1,233.53,234.13,10,400,1,1,233.5,234.17,100,1,1,1,233.45,234.25,15,100,1,1,233.4,234.41,110,561,2,2,233.39,234.43,10,105,1,2,233.31,234.5,110,63,2,4,AAPL,0.0,0.0,0.0,0.0,0.0,0.0,0.0,0.0,39.0,0.0,0.0,3.963034984624078,
2024-10-21T12:19:21.463929496Z,2024-10-21T12:19:21.463763491Z,10,2,38,C,A,7,234.41,61,130,166005,12734672,233.7,233.96,1200,200,1,1,233.68,234.0,400,50,2,1,233.66,234.03,28,27,2,1,233.58,234.1,505,100,2,1,233.53,234.13,10,400,1,1,233.5,234.17,100,1,1,1,233.45,234.25,15,100,1,1,233.4,234.41,110,500,2,1,233.39,234.43,10,105,1,2,233.31,234.5,110,63,2,4,AAPL,0.0,0.0,0.0,0.0,0.0,0.0,0.0,0.0,61.0,0.0,0.0,6.198593181078686,
2024-10-21T12:19:31.377488376Z,2024-10-21T12:19:31.377322230Z,10,2,38,C,A,0,233.96,200,130,166146,12742017,233.7,234.0,1200,50,1,1,233.68,234.03,400,27,2,1,233.66,234.1,28,100,2,1,233.58,234.13,505,400,2,1,233.53,234.17,10,1,1,1,233.5,234.25,100,100,1,1,233.45,234.41,15,500,1,1,233.4,234.43,110,105,2,2,233.39,234.5,10,63,1,4,233.31,234.75,110,1,2,1,AAPL,50.0,50.0,27.0,100.0,400.0,1.0,100.0,500.0,105.0,63.0,1.0,180.89091145672717,
2024-10-21T12:19:31.377500536Z,2024-10-21T12:19:31.377334380Z,10,2,38,A,A,0,233.98,200,130,166156,12742018,233.7,233.98,1200,200,1,1,233.68,234.0,400,50,2,1,233.66,234.03,28,27,2,1,233.58,234.1,505,100,2,1,233.53,234.13,10,400,1,1,233.5,234.17,100,1,1,1,233.45,234.25,15,100,1,1,233.4,234.41,110,500,2,1,233.39,234.43,10,105,1,2,233.31,234.5,110,63,2,4,AAPL,-50.0,-50.0,-27.0,-100.0,-400.0,-1.0,-100.0,-500.0,-105.0,-63.0,-1.0,-180.89091145672717,
2024-10-21T12:19:31.411013263Z,2024-10-21T12:19:31.410847128Z,10,2,38,C,A,0,233.98,200,130,166135,12742043,233.7,234.0,1200,50,1,1,233.68,234.03,400,27,2,1,233.66,234.1,28,100,2,1,233.58,234.13,505,400,2,1,233.53,234.17,10,1,1,1,233.5,234.25,100,100,1,1,233.45,234.41,15,500,1,1,233.4,234.43,110,105,2,2,233.39,234.5,10,63,1,4,233.31,234.75,110,1,2,1,AAPL,50.0,50.0,27.0,100.0,400.0,1.0,100.0,500.0,105.0,63.0,1.0,180.89091145672717,
2024-10-21T12:19:31.411026550Z,2024-10-21T12:19:31.410860369Z,10,2,38,A,A,1,234.03,200,130,166181,12742044,233.7,234.0,1200,50,1,1,233.68,234.03,400,227,2,2,233.66,234.1,28,100,2,1,233.58,234.13,505,400,2,1,233.53,234.17,10,1,1,1,233.5,234.25,100,100,1,1,233.45,234.41,15,500,1,1,233.4,234.43,110,105,2,2,233.39,234.5,10,63,1,4,233.31,234.75,110,1,2,1,AAPL,0.0,0.0,-200.0,0.0,0.0,0.0,0.0,0.0,0.0,0.0,0.0,-12.683232565773917,
2024-10-21T12:19:31.424898662Z,2024-10-21T12:19:31.424732441Z,10,2,38,C,B,2,233.66,27,130,166221,12742086,233.7,234.0,1200,50,1,1,233.68,234.03,400,227,2,2,233.66,234.1,1,100,1,1,233.58,234.13,505,400,2,1,233.53,234.17,10,1,1,1,233.5,234.25,100,100,1,1,233.45,234.41,15,500,1,1,233.4,234.43,110,105,2,2,233.39,234.5,10,63,1,4,233.31,234.75,110,1,2,1,AAPL,0.0,0.0,0.0,-27.0,0.0,0.0,0.0,0.0,0.0,0.0,0.0,-2.74272967987214,
2024-10-21T12:19:31.424956553Z,2024-10-21T12:19:31.424790390Z,10,2,38,A,B,2,233.67,30,130,166163,12742087,233.7,234.0,1200,50,1,1,233.68,234.03,400,227,2,2,233.67,234.1,30,100,1,1,233.66,234.13,1,400,1,1,233.58,234.17,505,1,2,1,233.53,234.25,10,100,1,1,233.5,234.41,100,500,1,1,233.45,234.43,15,105,1,2,233.4,234.5,110,63,2,4,233.39,234.75,10,1,1,1,AAPL,0.0,0.0,0.0,30.0,1.0,505.0,10.0,100.0,15.0,110.0,10.0,84.66545283400993,
2024-10-21T12:19:31.428289474Z,2024-10-21T12:19:31.428123190Z,10,2,38,C,A,1,234.03,27,130,166284,12742092,233.7,234.0,1200,50,1,1,233.68,234.03,400,200,2,1,233.67,234.1,30,100,1,1,233.66,234.13,1,400,1,1,233.58,234.17,505,1,2,1,233.53,234.25,10,100,1,1,233.5,234.41,100,500,1,1,233.45,234.43,15,105,1,2,233.4,234.5,110,63,2,4,233.39,234.75,10,1,1,1,AAPL,0.0,0.0,27.0,0.0,0.0,0.0,0.0,0.0,0.0,0.0,0.0,1.7122363963794787,
2024-10-21T12:19:31.428332471Z,2024-10-21T12:19:31.428166239Z,10,2,38,A,A,2,234.09,30,130,166232,12742093,233.7,234.0,1200,50,1,1,233.68,234.03,400,200,2,1,233.67,234.09,30,30,1,1,233.66,234.1,1,100,1,1,233.58,234.13,505,400,2,1,233.53,234.17,10,1,1,1,233.5,234.25,100,100,1,1,233.45,234.41,15,500,1,1,233.4,234.43,110,105,2,2,233.39,234.5,10,63,1,4,AAPL,0.0,0.0,0.0,-100.0,-400.0,-1.0,-100.0,-500.0,-105.0,-63.0,-1.0,-178.18464592804142,
2024-10-21T12:19:31.428343415Z,2024-10-21T12:19:31.428177171Z,10,2,38,C,B,1,233.68,200,130,166244,12742094,233.7,234.0,1200,50,1,1,233.68,234.03,200,200,1,1,233.67,234.09,30,30,1,1,233.66,234.1,1,100,1,1,233.58,234.13,505,400,2,1,233.53,234.17,10,1,1,1,233.5,234.25,100,100,1,1,233.45,234.41,15,500,1,1,233.4,234.43,110,105,2,2,233.39,234.5,10,63,1,4,AAPL,0.0,0.0,-200.0,0.0,0.0,0.0,0.0,0.0,0.0,0.0,0.0,-12.683232565773917,
2024-10-21T12:19:31.428357645Z,2024-10-21T12:19:31.428190903Z,10,2,38,A,B,1,233.69,400,130,166742,12742095,233.7,234.0,1200,50,1,1,233.69,234.03,400,200,1,1,233.67,234.09,30,30,1,1,233.66,234.1,1,100,1,1,233.58,234.13,505,400,2,1,233.53,234.17,10,1,1,1,233.5,234.25,100,100,1,1,233.45,234.41,15,500,1,1,233.4,234.43,110,105,2,2,233.39,234.5,10,63,1,4,AAPL,0.0,0.0,400.0,0.0,0.0,0.0,0.0,0.0,0.0,0.0,0.0,25.366465131547834,
2024-10-21T12:19:35.701715260Z,2024-10-21T12:19:35.701549120Z,10,2,38,C,B,1,233.69,200,130,166140,12745727,233.7,234.0,1200,50,1,1,233.69,234.03,200,200,1,1,233.67,234.09,30,30,1,1,233.66,234.1,1,100,1,1,233.58,234.13,505,400,2,1,233.53,234.17,10,1,1,1,233.5,234.25,100,100,1,1,233.45,234.41,15,500,1,1,233.4,234.43,110,105,2,2,233.39,234.5,10,63,1,4,AAPL,0.0,0.0,-200.0,0.0,0.0,0.0,0.0,0.0,0.0,0.0,0.0,-12.683232565773917,
2024-10-21T12:19:38.701844794Z,2024-10-21T12:19:38.701678685Z,10,2,38,A,B,1,233.69,200,130,166109,12748118,233.7,234.0,1200,50,1,1,233.69,234.03,400,200,2,1,233.67,234.09,30,30,1,1,233.66,234.1,1,100,1,1,233.58,234.13,505,400,2,1,233.53,234.17,10,1,1,1,233.5,234.25,100,100,1,1,233.45,234.41,15,500,1,1,233.4,234.43,110,105,2,2,233.39,234.5,10,63,1,4,AAPL,0.0,0.0,200.0,0.0,0.0,0.0,0.0,0.0,0.0,0.0,0.0,12.683232565773917,
2024-10-21T12:19:38.756345640Z,2024-10-21T12:19:38.756179281Z,10,2,38,C,B,1,233.69,200,130,166359,12748157,233.7,234.0,1200,50,1,1,233.69,234.03,200,200,1,1,233.67,234.09,30,30,1,1,233.66,234.1,1,100,1,1,233.58,234.13,505,400,2,1,233.53,234.17,10,1,1,1,233.5,234.25,100,100,1,1,233.45,234.41,15,500,1,1,233.4,234.43,110,105,2,2,233.39,234.5,10,63,1,4,AAPL,0.0,0.0,-200.0,0.0,0.0,0.0,0.0,0.0,0.0,0.0,0.0,-12.683232565773917,
2024-10-21T12:19:38.756358436Z,2024-10-21T12:19:38.756191248Z,10,2,38,A,B,0,233.73,200,130,167188,12748158,233.73,234.0,200,50,1,1,233.7,234.03,1200,200,1,1,233.67,234.09,30,30,1,1,233.66,234.1,1,100,1,1,233.58,234.13,505,400,2,1,233.53,234.17,10,1,1,1,233.5,234.25,100,100,1,1,233.45,234.41,15,500,1,1,233.4,234.43,110,105,2,2,233.39,234.5,10,63,1,4,AAPL,200.0,200.0,1200.0,0.0,0.0,0.0,0.0,0.0,0.0,0.0,0.0,80.0755119238685,
2024-10-21T12:19:40.083493208Z,2024-10-21T12:19:40.083326842Z,10,2,38,A,A,1,234.03,200,130,166366,12749182,233.73,234.0,200,50,1,1,233.7,234.03,1200,400,1,2,233.67,234.09,30,30,1,1,233.66,234.1,1,100,1,1,233.58,234.13,505,400,2,1,233.53,234.17,10,1,1,1,233.5,234.25,100,100,1,1,233.45,234.41,15,500,1,1,233.4,234.43,110,105,2,2,233.39,234.5,10,63,1,4,AAPL,0.0,0.0,-200.0,0.0,0.0,0.0,0.0,0.0,0.0,0.0,0.0,-12.683232565773917,
2024-10-21T12:19:40.138138274Z,2024-10-21T12:19:40.137972145Z,10,2,38,C,A,1,234.03,200,130,166129,12749218,233.73,234.0,200,50,1,1,233.7,234.03,1200,200,1,1,233.67,234.09,30,30,1,1,233.66,234.1,1,100,1,1,233.58,234.13,505,400,2,1,233.53,234.17,10,1,1,1,233.5,234.25,100,100,1,1,233.45,234.41,15,500,1,1,233.4,234.43,110,105,2,2,233.39,234.5,10,63,1,4,AAPL,0.0,0.0,200.0,0.0,0.0,0.0,0.0,0.0,0.0,0.0,0.0,12.683232565773917,
2024-10-21T12:19:40.138150186Z,2024-10-21T12:19:40.137983855Z,10,2,38,A,A,1,234.02,200,130,166331,12749219,233.73,234.0,200,50,1,1,233.7,234.02,1200,200,1,1,233.67,234.09,30,30,1,1,233.66,234.1,1,100,1,1,233.58,234.13,505,400,2,1,233.53,234.17,10,1,1,1,233.5,234.25,100,100,1,1,233.45,234.41,15,500,1,1,233.4,234.43,110,105,2,2,233.39,234.5,10,63,1,4,AAPL,0.0,0.0,-200.0,0.0,0.0,0.0,0.0,0.0,0.0,0.0,0.0,-12.683232565773917,
2024-10-21T12:19:42.737318215Z,2024-10-21T12:19:42.737152214Z,10,2,38,C,B,0,233.73,200,130,166001,12752002,233.7,234.0,1200,50,1,1,233.67,234.02,30,200,1,1,233.66,234.09,1,30,1,1,233.58,234.1,505,100,2,1,233.53,234.13,10,400,1,1,233.5,234.17,100,1,1,1,233.45,234.25,15,100,1,1,233.4,234.41,110,500,2,1,233.39,234.43,10,105,1,2,233.31,234.5,110,63,2,4,AAPL,-200.0,-200.0,-1200.0,-30.0,-1.0,-505.0,-10.0,-100.0,-15.0,-110.0,-10.0,-164.74096475787846,
2024-10-21T12:19:42.737331418Z,2024-10-21T12:19:42.737165303Z,10,2,38,A,B,1,233.68,200,130,166115,12752003,233.7,234.0,1200,50,1,1,233.68,234.02,200,200,1,1,233.67,234.09,30,30,1,1,233.66,234.1,1,100,1,1,233.58,234.13,505,400,2,1,233.53,234.17,10,1,1,1,233.5,234.25,100,100,1,1,233.45,234.41,15,500,1,1,233.4,234.43,110,105,2,2,233.39,234.5,10,63,1,4,AAPL,0.0,0.0,200.0,30.0,1.0,505.0,10.0,100.0,15.0,110.0,10.0,97.34868539978385,
2024-10-21T12:19:45.746085184Z,2024-10-21T12:19:45.745918365Z,10,2,38,A,B,1,233.68,200,130,166819,12754733,233.7,234.0,1200,50,1,1,233.68,234.02,400,200,2,1,233.67,234.09,30,30,1,1,233.66,234.1,1,100,1,1,233.58,234.13,505,400,2,1,233.53,234.17,10,1,1,1,233.5,234.25,100,100,1,1,233.45,234.41,15,500,1,1,233.4,234.43,110,105,2,2,233.39,234.5,10,63,1,4,AAPL,0.0,0.0,200.0,0.0,0.0,0.0,0.0,0.0,0.0,0.0,0.0,12.683232565773917,
2024-10-21T12:19:45.800644123Z,2024-10-21T12:19:45.800477942Z,10,2,38,C,B,1,233.68,200,130,166181,12754741,233.7,234.0,1200,50,1,1,233.68,234.02,200,200,1,1,233.67,234.09,30,30,1,1,233.66,234.1,1,100,1,1,233.58,234.13,505,400,2,1,233.53,234.17,10,1,1,1,233.5,234.25,100,100,1,1,233.45,234.41,15,500,1,1,233.4,234.43,110,105,2,2,233.39,234.5,10,63,1,4,AAPL,0.0,0.0,-200.0,0.0,0.0,0.0,0.0,0.0,0.0,0.0,0.0,-12.683232565773917,
2024-10-21T12:19:45.800657708Z,2024-10-21T12:19:45.800491117Z,10,2,38,A,B,0,233.72,200,130,166591,12754742,233.72,234.0,200,50,1,1,233.7,234.02,1200,200,1,1,233.67,234.09,30,30,1,1,233.66,234.1,1,100,1,1,233.58,234.13,505,400,2,1,233.53,234.17,10,1,1,1,233.5,234.25,100,100,1,1,233.45,234.41,15,500,1,1,233.4,234.43,110,105,2,2,233.39,234.5,10,63,1,4,AAPL,200.0,200.0,1200.0,0.0,0.0,0.0,0.0,0.0,0.0,0.0,0.0,80.0755119238685,
2024-10-21T12:19:57.871170937Z,2024-10-21T12:19:57.871002706Z,10,2,38,A,B,0,233.73,200,130,168231,12763861,233.73,234.0,200,50,1,1,233.7,234.02,1200,200,1,1,233.67,234.09,30,30,1,1,233.66,234.1,1,100,1,1,233.58,234.13,505,400,2,1,233.53,234.17,10,1,1,1,233.5,234.25,100,100,1,1,233.45,234.41,15,500,1,1,233.4,234.43,110,105,2,2,233.39,234.5,10,63,1,4,AAPL,200.0,200.0,0.0,0.0,0.0,0.0,0.0,0.0,0.0,0.0,0.0,3.9761165292250036,
2024-10-21T12:20:02.012956104Z,2024-10-21T12:20:02.012790106Z,10,2,38,C,B,0,233.73,200,130,165998,12769134,233.7,234.0,1200,50,1,1,233.67,234.02,30,200,1,1,233.66,234.09,1,30,1,1,233.58,234.1,505,100,2,1,233.53,234.13,10,400,1,1,233.5,234.17,100,1,1,1,233.45,234.25,15,100,1,1,233.4,234.41,110,500,2,1,233.39,234.43,10,105,1,2,233.31,234.5,110,63,2,4,AAPL,-200.0,-200.0,-1200.0,-30.0,-1.0,-505.0,-10.0,-100.0,-15.0,-110.0,-10.0,-164.74096475787846,
2024-10-21T12:20:02.012967271Z,2024-10-21T12:20:02.012801350Z,10,2,38,A,B,0,233.71,200,130,165921,12769136,233.71,234.0,200,50,1,1,233.7,234.02,1200,200,1,1,233.67,234.09,30,30,1,1,233.66,234.1,1,100,1,1,233.58,234.13,505,400,2,1,233.53,234.17,10,1,1,1,233.5,234.25,100,100,1,1,233.45,234.41,15,500,1,1,233.4,234.43,110,105,2,2,233.39,234.5,10,63,1,4,AAPL,200.0,200.0,1200.0,30.0,1.0,505.0,10.0,100.0,15.0,110.0,10.0,164.74096475787846,
2024-10-21T12:20:02.012989292Z,2024-10-21T12:20:02.012823085Z,10,2,38,A,A,1,234.02,200,130,166207,12769137,233.71,234.0,200,50,1,1,233.7,234.02,1200,400,1,2,233.67,234.09,30,30,1,1,233.66,234.1,1,100,1,1,233.58,234.13,505,400,2,1,233.53,234.17,10,1,1,1,233.5,234.25,100,100,1,1,233.45,234.41,15,500,1,1,233.4,234.43,110,105,2,2,233.39,234.5,10,63,1,4,AAPL,0.0,0.0,-200.0,0.0,0.0,0.0,0.0,0.0,0.0,0.0,0.0,-12.683232565773917,
2024-10-21T12:20:02.068369244Z,2024-10-21T12:20:02.068202840Z,10,2,38,A,B,0,233.72,200,130,166404,12769355,233.72,234.0,200,50,1,1,233.7,234.02,1200,400,1,2,233.67,234.09,30,30,1,1,233.66,234.1,1,100,1,1,233.58,234.13,505,400,2,1,233.53,234.17,10,1,1,1,233.5,234.25,100,100,1,1,233.45,234.41,15,500,1,1,233.4,234.43,110,105,2,2,233.39,234.5,10,63,1,4,AAPL,200.0,200.0,0.0,0.0,0.0,0.0,0.0,0.0,0.0,0.0,0.0,3.9761165292250036,
2024-10-21T12:20:02.174238719Z,2024-10-21T12:20:02.174072577Z,10,2,38,C,A,1,234.02,200,130,166142,12769566,233.72,234.0,200,50,1,1,233.7,234.02,1200,200,1,1,233.67,234.09,30,30,1,1,233.66,234.1,1,100,1,1,233.58,234.13,505,400,2,1,233.53,234.17,10,1,1,1,233.5,234.25,100,100,1,1,233.45,234.41,15,500,1,1,233.4,234.43,110,105,2,2,233.39,234.5,10,63,1,4,AAPL,0.0,0.0,200.0,0.0,0.0,0.0,0.0,0.0,0.0,0.0,0.0,12.683232565773917,
2024-10-21T12:20:02.174250737Z,2024-10-21T12:20:02.174084216Z,10,2,38,A,A,1,234.01,200,130,166521,12769567,233.72,234.0,200,50,1,1,233.7,234.01,1200,200,1,1,233.67,234.09,30,30,1,1,233.66,234.1,1,100,1,1,233.58,234.13,505,400,2,1,233.53,234.17,10,1,1,1,233.5,234.25,100,100,1,1,233.45,234.41,15,500,1,1,233.4,234.43,110,105,2,2,233.39,234.5,10,63,1,4,AAPL,0.0,0.0,-200.0,0.0,0.0,0.0,0.0,0.0,0.0,0.0,0.0,-12.683232565773917,
2024-10-21T12:20:02.195927659Z,2024-10-21T12:20:02.195761354Z,10,2,38,A,A,2,234.08,27,130,166305,12769699,233.72,234.0,200,50,1,1,233.7,234.01,1200,200,1,1,233.67,234.08,30,27,1,1,233.66,234.09,1,30,1,1,233.58,234.1,505,100,2,1,233.53,234.13,10,400,1,1,233.5,234.17,100,1,1,1,233.45,234.25,15,100,1,1,233.4,234.41,110,500,2,1,233.39,234.43,10,105,1,2,AAPL,0.0,0.0,0.0,-30.0,-100.0,-400.0,-1.0,-100.0,-500.0,-105.0,-63.0,-144.2095917447144,
2024-10-21T12:20:02.197265893Z,2024-10-21T12:20:02.197099790Z,10,2,38,C,A,3,234.09,30,130,166103,12769703,233.72,234.0,200,50,1,1,233.7,234.01,1200,200,1,1,233.67,234.08,30,27,1,1,233.66,234.1,1,100,1,1,233.58,234.13,505,400,2,1,233.53,234.17,10,1,1,1,233.5,234.25,100,100,1,1,233.45,234.41,15,500,1,1,233.4,234.43,110,105,2,2,233.39,234.5,10,63,1,4,AAPL,0.0,0.0,0.0,0.0,100.0,400.0,1.0,100.0,500.0,105.0,63.0,141.16211432263424,
2024-10-21T12:20:17.529825881Z,2024-10-21T12:20:17.529659579Z,10,2,38,C,A,1,234.01,200,130,166302,12783626,233.72,234.0,200,50,1,1,233.7,234.08,1200,27,1,1,233.67,234.1,30,100,1,1,233.66,234.13,1,400,1,1,233.58,234.17,505,1,2,1,233.53,234.25,10,100,1,1,233.5,234.41,100,500,1,1,233.45,234.43,15,105,1,2,233.4,234.5,110,63,2,4,233.39,234.75,10,1,1,1,AAPL,0.0,0.0,27.0,100.0,400.0,1.0,100.0,500.0,105.0,63.0,1.0,179.89688232442091,
2024-10-21T12:20:17.529838088Z,2024-10-21T12:20:17.529671598Z,10,2,38,A,A,1,234.02,200,130,166490,12783627,233.72,234.0,200,50,1,1,233.7,234.02,1200,200,1,1,233.67,234.08,30,27,1,1,233.66,234.1,1,100,1,1,233.58,234.13,505,400,2,1,233.53,234.17,10,1,1,1,233.5,234.25,100,100,1,1,233.45,234.41,15,500,1,1,233.4,234.43,110,105,2,2,233.39,234.5,10,63,1,4,AAPL,0.0,0.0,-27.0,-100.0,-400.0,-1.0,-100.0,-500.0,-105.0,-63.0,-1.0,-179.89688232442091,
2024-10-21T12:20:18.175318074Z,2024-10-21T12:20:18.175151492Z,10,2,38,A,B,0,233.73,200,130,166582,12784239,233.73,234.0,200,50,1,1,233.7,234.02,1200,200,1,1,233.67,234.08,30,27,1,1,233.66,234.1,1,100,1,1,233.58,234.13,505,400,2,1,233.53,234.17,10,1,1,1,233.5,234.25,100,100,1,1,233.45,234.41,15,500,1,1,233.4,234.43,110,105,2,2,233.39,234.5,10,63,1,4,AAPL,200.0,200.0,0.0,0.0,0.0,0.0,0.0,0.0,0.0,0.0,0.0,3.9761165292250036,
2024-10-21T12:20:26.003837302Z,2024-10-21T12:20:26.003671349Z,10,2,38,C,B,0,233.73,200,130,165953,12790391,233.7,234.0,1200,50,1,1,233.67,234.02,30,200,1,1,233.66,234.08,1,27,1,1,233.58,234.1,505,100,2,1,233.53,234.13,10,400,1,1,233.5,234.17,100,1,1,1,233.45,234.25,15,100,1,1,233.4,234.41,110,500,2,1,233.39,234.43,10,105,1,2,233.31,234.5,110,63,2,4,AAPL,-200.0,-200.0,-1200.0,-30.0,-1.0,-505.0,-10.0,-100.0,-15.0,-110.0,-10.0,-164.74096475787846,
2024-10-21T12:20:26.003850219Z,2024-10-21T12:20:26.003684074Z,10,2,38,A,B,1,233.69,200,130,166145,12790392,233.7,234.0,1200,50,1,1,233.69,234.02,200,200,1,1,233.67,234.08,30,27,1,1,233.66,234.1,1,100,1,1,233.58,234.13,505,400,2,1,233.53,234.17,10,1,1,1,233.5,234.25,100,100,1,1,233.45,234.41,15,500,1,1,233.4,234.43,110,105,2,2,233.39,234.5,10,63,1,4,AAPL,0.0,0.0,200.0,30.0,1.0,505.0,10.0,100.0,15.0,110.0,10.0,97.34868539978385,
2024-10-21T12:20:29.006015290Z,2024-10-21T12:20:29.005849003Z,10,2,38,A,B,1,233.69,200,130,166287,12792364,233.7,234.0,1200,50,1,1,233.69,234.02,400,200,2,1,233.67,234.08,30,27,1,1,233.66,234.1,1,100,1,1,233.58,234.13,505,400,2,1,233.53,234.17,10,1,1,1,233.5,234.25,100,100,1,1,233.45,234.41,15,500,1,1,233.4,234.43,110,105,2,2,233.39,234.5,10,63,1,4,AAPL,0.0,0.0,200.0,0.0,0.0,0.0,0.0,0.0,0.0,0.0,0.0,12.683232565773917,
2024-10-21T12:20:29.035628478Z,2024-10-21T12:20:29.035461864Z,10,2,38,A,B,0,233.8,5,130,166614,12792376,233.8,234.0,5,50,1,1,233.7,234.02,1200,200,1,1,233.69,234.08,400,27,2,1,233.67,234.1,30,100,1,1,233.66,234.13,1,400,1,1,233.58,234.17,505,1,2,1,233.53,234.25,10,100,1,1,233.5,234.41,100,500,1,1,233.45,234.43,15,105,1,2,233.4,234.5,110,63,2,4,AAPL,5.0,5.0,1200.0,400.0,30.0,1.0,505.0,10.0,100.0,15.0,110.0,212.7891901688997,
2024-10-21T12:20:32.534136508Z,2024-10-21T12:20:32.533970326Z,10,2,38,C,A,2,234.08,27,130,166182,12795434,233.8,234.0,5,50,1,1,233.7,234.02,1200,200,1,1,233.69,234.1,400,100,2,1,233.67,234.13,30,400,1,1,233.66,234.17,1,1,1,1,233.58,234.25,505,100,2,1,233.53,234.41,10,500,1,1,233.5,234.43,100,105,1,2,233.45,234.5,15,63,1,4,233.4,234.75,110,1,2,1,AAPL,0.0,0.0,0.0,100.0,400.0,1.0,100.0,500.0,105.0,63.0,1.0,178.18464592804142,
2024-10-21T12:20:32.534182863Z,2024-10-21T12:20:32.534015766Z,10,2,38,A,A,2,234.04,27,130,167097,12795435,233.8,234.0,5,50,1,1,233.7,234.02,1200,200,1,1,233.69,234.04,400,27,2,1,233.67,234.1,30,100,1,1,233.66,234.13,1,400,1,1,233.58,234.17,505,1,2,1,233.53,234.25,10,100,1,1,233.5,234.41,100,500,1,1,233.45,234.43,15,105,1,2,233.4,234.5,110,63,2,4,AAPL,0.0,0.0,0.0,-100.0,-400.0,-1.0,-100.0,-500.0,-105.0,-63.0,-1.0,-178.18464592804142,
2024-10-21T12:20:32.588752733Z,2024-10-21T12:20:32.588585911Z,10,2,38,A,A,0,233.99,200,130,166822,12795466,233.8,233.99,5,200,1,1,233.7,234.0,1200,50,1,1,233.69,234.04,400,27,2,1,233.67,234.1,30,100,1,1,233.66,234.13,1,400,1,1,233.58,234.17,505,1,2,1,233.53,234.25,10,100,1,1,233.5,234.41,100,500,1,1,233.45,234.43,15,105,1,2,233.4,234.5,110,63,2,4,AAPL,-50.0,-50.0,-200.0,0.0,0.0,0.0,0.0,0.0,0.0,0.0,0.0,-13.677261698080168,
2024-10-21T12:20:32.846479452Z,2024-10-21T12:20:32.846313500Z,10,2,38,C,A,0,233.99,200,130,165952,12795731,233.8,234.0,5,50,1,1,233.7,234.04,1200,27,1,1,233.69,234.1,400,100,2,1,233.67,234.13,30,400,1,1,233.66,234.17,1,1,1,1,233.58,234.25,505,100,2,1,233.53,234.41,10,500,1,1,233.5,234.43,100,105,1,2,233.45,234.5,15,63,1,4,233.4,234.75,110,1,2,1,AAPL,50.0,50.0,27.0,100.0,400.0,1.0,100.0,500.0,105.0,63.0,1.0,180.89091145672717,
2024-10-21T12:20:32.846490898Z,2024-10-21T12:20:32.846324686Z,10,2,38,A,A,1,234.03,400,130,166212,12795732,233.8,234.0,5,50,1,1,233.7,234.03,1200,400,1,1,233.69,234.04,400,27,2,1,233.67,234.1,30,100,1,1,233.66,234.13,1,400,1,1,233.58,234.17,505,1,2,1,233.53,234.25,10,100,1,1,233.5,234.41,100,500,1,1,233.45,234.43,15,105,1,2,233.4,234.5,110,63,2,4,AAPL,0.0,0.0,-27.0,-100.0,-400.0,-1.0,-100.0,-500.0,-105.0,-63.0,-1.0,-179.89688232442091,
2024-10-21T12:20:32.901109636Z,2024-10-21T12:20:32.900943370Z,10,2,38,A,A,0,233.98,200,130,166266,12795787,233.8,233.98,5,200,1,1,233.7,234.0,1200,50,1,1,233.69,234.04,400,27,2,1,233.67,234.1,30,100,1,1,233.66,234.13,1,400,1,1,233.58,234.17,505,1,2,1,233.53,234.25,10,100,1,1,233.5,234.41,100,500,1,1,233.45,234.43,15,105,1,2,233.4,234.5,110,63,2,4,AAPL,-50.0,-50.0,-400.0,0.0,0.0,0.0,0.0,0.0,0.0,0.0,0.0,-26.360494263854086,
2024-10-21T12:20:33.387963355Z,2024-10-21T12:20:33.387796787Z,10,2,38,A,A,0,233.97,200,130,166568,12796589,233.8,233.97,5,200,1,1,233.7,234.0,1200,50,1,1,233.69,234.04,400,27,2,1,233.67,234.1,30,100,1,1,233.66,234.13,1,400,1,1,233.58,234.17,505,1,2,1,233.53,234.25,10,100,1,1,233.5,234.41,100,500,1,1,233.45,234.43,15,105,1,2,233.4,234.5,110,63,2,4,AAPL,-200.0,-200.0,0.0,0.0,0.0,0.0,0.0,0.0,0.0,0.0,0.0,-3.9761165292250036,
2024-10-21T12:20:34.158685217Z,2024-10-21T12:20:34.158518772Z,10,2,38,A,A,0,233.97,200,130,166445,12797101,233.8,233.97,5,400,1,2,233.7,234.0,1200,50,1,1,233.69,234.04,400,27,2,1,233.67,234.1,30,100,1,1,233.66,234.13,1,400,1,1,233.58,234.17,505,1,2,1,233.53,234.25,10,100,1,1,233.5,234.41,100,500,1,1,233.45,234.43,15,105,1,2,233.4,234.5,110,63,2,4,AAPL,-200.0,-200.0,0.0,0.0,0.0,0.0,0.0,0.0,0.0,0.0,0.0,-3.9761165292250036,
