ts_recv,ts_event,rtype,publisher_id,instrument_id,action,side,depth,price,size,flags,ts_in_delta,sequence,bid_px_00,ask_px_00,bid_sz_00,ask_sz_00,bid_ct_00,ask_ct_00,bid_px_01,ask_px_01,bid_sz_01,ask_sz_01,bid_ct_01,ask_ct_01,bid_px_02,ask_px_02,bid_sz_02,ask_sz_02,bid_ct_02,ask_ct_02,bid_px_03,ask_px_03,bid_sz_03,ask_sz_03,bid_ct_03,ask_ct_03,bid_px_04,ask_px_04,bid_sz_04,ask_sz_04,bid_ct_04,ask_ct_04,bid_px_05,ask_px_05,bid_sz_05,ask_sz_05,bid_ct_05,ask_ct_05,bid_px_06,ask_px_06,bid_sz_06,ask_sz_06,bid_ct_06,ask_ct_06,bid_px_07,ask_px_07,bid_sz_07,ask_sz_07,bid_ct_07,ask_ct_07,bid_px_08,ask_px_08,bid_sz_08,ask_sz_08,bid_ct_08,ask_ct_08,bid_px_09,ask_px_09,bid_sz_09,ask_sz_09,bid_ct_09,ask_ct_09,symbol,best_level_ofi,ofi_00,ofi_01,ofi_02,ofi_03,ofi_04,ofi_05,ofi_06,ofi_07,ofi_08,ofi_09,integrated_ofi,cross_asset_ofi
2024-10-21T12:20:53.733069722Z,2024-10-21T12:20:53.732903004Z,10,2,38,A,B,0,233.86,750,130,166718,12809362,233.86,233.97,750,400,1,2,233.8,234.0,5,50,1,1,233.7,234.04,1200,27,1,1,233.69,234.1,400,100,2,1,233.67,234.13,30,400,1,1,233.66,234.17,1,1,1,1,233.58,234.25,505,100,2,1,233.53,234.41,10,500,1,1,233.5,234.43,100,105,1,2,233.45,234.5,15,63,1,4,AAPL,750.0,750.0,5.0,1200.0,400.0,30.0,1.0,505.0,10.0,100.0,15.0,289.3723431795885,
2024-10-21T12:20:54.066491305Z,2024-10-21T12:20:54.066325257Z,10,2,38,C,A,0,233.97,200,130,166048,12809626,233.86,233.97,750,200,1,1,233.8,234.0,5,50,1,1,233.7,234.04,1200,27,1,1,233.69,234.1,400,100,2,1,233.67,234.13,30,400,1,1,233.66,234.17,1,1,1,1,233.58,234.25,505,100,2,1,233.53,234.41,10,500,1,1,233.5,234.43,100,105,1,2,233.45,234.5,15,63,1,4,AAPL,200.0,200.0,0.0,0.0,0.0,0.0,0.0,0.0,0.0,0.0,0.0,3.9761165292250036,
2024-10-21T12:20:54.066706343Z,2024-10-21T12:20:54.066539893Z,10,2,38,C,A,0,233.97,200,130,166450,12809627,233.86,234.0,750,50,1,1,233.8,234.04,5,27,1,1,233.7,234.1,1200,100,1,1,233.69,234.13,400,400,2,1,233.67,234.17,30,1,1,1,233.66,234.25,1,100,1,1,233.58,234.41,505,500,2,1,233.53,234.43,10,105,1,2,233.5,234.5,100,63,1,4,233.45,234.75,15,1,1,1,AAPL,50.0,50.0,27.0,100.0,400.0,1.0,100.0,500.0,105.0,63.0,1.0,180.89091145672717,
2024-10-21T12:20:54.088050706Z,2024-10-21T12:20:54.087884313Z,10,2,38,A,A,0,233.97,200,130,166393,12809662,233.86,233.97,750,200,1,1,233.8,234.0,5,50,1,1,233.7,234.04,1200,27,1,1,233.69,234.1,400,100,2,1,233.67,234.13,30,400,1,1,233.66,234.17,1,1,1,1,233.58,234.25,505,100,2,1,233.53,234.41,10,500,1,1,233.5,234.43,100,105,1,2,233.45,234.5,15,63,1,4,AAPL,-50.0,-50.0,-27.0,-100.0,-400.0,-1.0,-100.0,-500.0,-105.0,-63.0,-1.0,-180.89091145672717,
2024-10-21T12:20:54.138176465Z,2024-10-21T12:20:54.138010479Z,10,2,38,C,A,0,233.97,200,130,165986,12809687,233.86,234.0,750,50,1,1,233.8,234.04,5,27,1,1,233.7,234.1,1200,100,1,1,233.69,234.13,400,400,2,1,233.67,234.17,30,1,1,1,233.66,234.25,1,100,1,1,233.58,234.41,505,500,2,1,233.53,234.43,10,105,1,2,233.5,234.5,100,63,1,4,233.45,234.75,15,1,1,1,AAPL,50.0,50.0,27.0,100.0,400.0,1.0,100.0,500.0,105.0,63.0,1.0,180.89091145672717,
2024-10-21T12:20:54.138190487Z,2024-10-21T12:20:54.138024196Z,10,2,38,A,A,1,234.03,200,130,166291,12809688,233.86,234.0,750,50,1,1,233.8,234.03,5,200,1,1,233.7,234.04,1200,27,1,1,233.69,234.1,400,100,2,1,233.67,234.13,30,400,1,1,233.66,234.17,1,1,1,1,233.58,234.25,505,100,2,1,233.53,234.41,10,500,1,1,233.5,234.43,100,105,1,2,233.45,234.5,15,63,1,4,AAPL,0.0,0.0,-27.0,-100.0,-400.0,-1.0,-100.0,-500.0,-105.0,-63.0,-1.0,-179.89688232442091,
2024-10-21T12:20:54.138801017Z,2024-10-21T12:20:54.138635039Z,10,2,38,C,A,2,234.04,27,130,165978,12809691,233.86,234.0,750,50,1,1,233.8,234.03,5,200,1,1,233.7,234.1,1200,100,1,1,233.69,234.13,400,400,2,1,233.67,234.17,30,1,1,1,233.66,234.25,1,100,1,1,233.58,234.41,505,500,2,1,233.53,234.43,10,105,1,2,233.5,234.5,100,63,1,4,233.45,234.75,15,1,1,1,AAPL,0.0,0.0,0.0,100.0,400.0,1.0,100.0,500.0,105.0,63.0,1.0,178.18464592804142,
2024-10-21T12:20:54.138845849Z,2024-10-21T12:20:54.138679423Z,10,2,38,A,A,2,234.1,29,130,166426,12809692,233.86,234.0,750,50,1,1,233.8,234.03,5,200,1,1,233.7,234.1,1200,129,1,2,233.69,234.13,400,400,2,1,233.67,234.17,30,1,1,1,233.66,234.25,1,100,1,1,233.58,234.41,505,500,2,1,233.53,234.43,10,105,1,2,233.5,234.5,100,63,1,4,233.45,234.75,15,1,1,1,AAPL,0.0,0.0,0.0,-29.0,0.0,0.0,0.0,0.0,0.0,0.0,0.0,-2.945894841344151,
2024-10-21T12:20:54.140867485Z,2024-10-21T12:20:54.140701289Z,10,2,38,A,A,1,234.03,200,130,166196,12809693,233.86,234.0,750,50,1,1,233.8,234.03,5,400,1,2,233.7,234.1,1200,129,1,2,233.69,234.13,400,400,2,1,233.67,234.17,30,1,1,1,233.66,234.25,1,100,1,1,233.58,234.41,505,500,2,1,233.53,234.43,10,105,1,2,233.5,234.5,100,63,1,4,233.45,234.75,15,1,1,1,AAPL,0.0,0.0,-200.0,0.0,0.0,0.0,0.0,0.0,0.0,0.0,0.0,-12.683232565773917,
2024-10-21T12:20:54.260089240Z,2024-10-21T12:20:54.259923109Z,10,2,38,C,A,1,234.03,200,130,166131,12809712,233.86,234.0,750,50,1,1,233.8,234.03,5,200,1,1,233.7,234.1,1200,129,1,2,233.69,234.13,400,400,2,1,233.67,234.17,30,1,1,1,233.66,234.25,1,100,1,1,233.58,234.41,505,500,2,1,233.53,234.43,10,105,1,2,233.5,234.5,100,63,1,4,233.45,234.75,15,1,1,1,AAPL,0.0,0.0,200.0,0.0,0.0,0.0,0.0,0.0,0.0,0.0,0.0,12.683232565773917,
2024-10-21T12:20:54.260102529Z,2024-10-21T12:20:54.259936081Z,10,2,38,A,A,0,233.97,400,130,166448,12809713,233.86,233.97,750,400,1,1,233.8,234.0,5,50,1,1,233.7,234.1,1200,129,1,2,233.69,234.13,400,400,2,1,233.67,234.17,30,1,1,1,233.66,234.25,1,100,1,1,233.58,234.41,505,500,2,1,233.53,234.43,10,105,1,2,233.5,234.5,100,63,1,4,233.45,234.75,15,1,1,1,AAPL,-50.0,-50.0,-200.0,0.0,0.0,0.0,0.0,0.0,0.0,0.0,0.0,-13.677261698080168,
2024-10-21T12:20:54.368140579Z,2024-10-21T12:20:54.367974373Z,10,2,38,C,B,3,233.69,200,130,166206,12809780,233.86,233.97,750,400,1,1,233.8,234.0,5,50,1,1,233.7,234.1,1200,129,1,2,233.69,234.13,200,400,1,1,233.67,234.17,30,1,1,1,233.66,234.25,1,100,1,1,233.58,234.41,505,500,2,1,233.53,234.43,10,105,1,2,233.5,234.5,100,63,1,4,233.45,234.75,15,1,1,1,AAPL,0.0,0.0,0.0,0.0,-200.0,0.0,0.0,0.0,0.0,0.0,0.0,-41.015411004823704,
2024-10-21T12:20:54.368154412Z,2024-10-21T12:20:54.367988079Z,10,2,38,A,B,2,233.71,200,130,166333,12809781,233.86,233.97,750,400,1,1,233.8,234.0,5,50,1,1,233.71,234.1,200,129,1,2,233.7,234.13,1200,400,1,1,233.67,234.17,30,1,1,1,233.66,234.25,1,100,1,1,233.58,234.41,505,500,2,1,233.53,234.43,10,105,1,2,233.5,234.5,100,63,1,4,233.45,234.75,15,1,1,1,AAPL,0.0,0.0,0.0,200.0,1200.0,0.0,0.0,0.0,0.0,0.0,0.0,266.40898217614324,
2024-10-21T12:20:54.646690573Z,2024-10-21T12:20:54.646524020Z,10,2,38,A,B,2,233.71,200,130,166553,12810164,233.86,233.97,750,400,1,1,233.8,234.0,5,50,1,1,233.71,234.1,400,129,2,2,233.7,234.13,1200,400,1,1,233.67,234.17,30,1,1,1,233.66,234.25,1,100,1,1,233.58,234.41,505,500,2,1,233.53,234.43,10,105,1,2,233.5,234.5,100,63,1,4,233.45,234.75,15,1,1,1,AAPL,0.0,0.0,0.0,200.0,0.0,0.0,0.0,0.0,0.0,0.0,0.0,20.31651614720104,
2024-10-21T12:20:54.647477883Z,2024-10-21T12:20:54.647311583Z,10,2,38,C,B,4,233.67,30,130,166300,12810165,233.86,233.97,750,400,1,1,233.8,234.0,5,50,1,1,233.71,234.1,400,129,2,2,233.7,234.13,1200,400,1,1,233.66,234.17,1,1,1,1,233.58,234.25,505,100,2,1,233.53,234.41,10,500,1,1,233.5,234.43,100,105,1,2,233.45,234.5,15,63,1,4,233.4,234.75,110,1,2,1,AAPL,0.0,0.0,0.0,0.0,0.0,-30.0,-1.0,-505.0,-10.0,-100.0,-15.0,-70.21490648799674,
2024-10-21T12:20:54.647518689Z,2024-10-21T12:20:54.647352236Z,10,2,38,A,B,2,233.73,26,130,166453,12810166,233.86,233.97,750,400,1,1,233.8,234.0,5,50,1,1,233.73,234.1,26,129,1,2,233.71,234.13,400,400,2,1,233.7,234.17,1200,1,1,1,233.66,234.25,1,100,1,1,233.58,234.41,505,500,2,1,233.53,234.43,10,105,1,2,233.5,234.5,100,63,1,4,233.45,234.75,15,1,1,1,AAPL,0.0,0.0,0.0,26.0,400.0,1200.0,1.0,505.0,10.0,100.0,15.0,291.06046978362974,
2024-10-21T12:20:54.647548709Z,2024-10-21T12:20:54.647382777Z,10,2,38,C,A,2,234.1,29,130,165932,12810167,233.86,233.97,750,400,1,1,233.8,234.0,5,50,1,1,233.73,234.1,26,100,1,1,233.71,234.13,400,400,2,1,233.7,234.17,1200,1,1,1,233.66,234.25,1,100,1,1,233.58,234.41,505,500,2,1,233.53,234.43,10,105,1,2,233.5,234.5,100,63,1,4,233.45,234.75,15,1,1,1,AAPL,0.0,0.0,0.0,29.0,0.0,0.0,0.0,0.0,0.0,0.0,0.0,2.945894841344151,
2024-10-21T12:20:54.647589469Z,2024-10-21T12:20:54.647423336Z,10,2,38,A,A,2,234.04,27,130,166133,12810168,233.86,233.97,750,400,1,1,233.8,234.0,5,50,1,1,233.73,234.04,26,27,1,1,233.71,234.1,400,100,2,1,233.7,234.13,1200,400,1,1,233.66,234.17,1,1,1,1,233.58,234.25,505,100,2,1,233.53,234.41,10,500,1,1,233.5,234.43,100,105,1,2,233.45,234.5,15,63,1,4,AAPL,0.0,0.0,0.0,-100.0,-400.0,-1.0,-100.0,-500.0,-105.0,-63.0,-1.0,-178.18464592804142,
2024-10-21T12:20:54.648089003Z,2024-10-21T12:20:54.647922749Z,10,2,38,C,A,0,233.97,200,130,166254,12810170,233.86,233.97,750,200,1,1,233.8,234.0,5,50,1,1,233.73,234.04,26,27,1,1,233.71,234.1,400,100,2,1,233.7,234.13,1200,400,1,1,233.66,234.17,1,1,1,1,233.58,234.25,505,100,2,1,233.53,234.41,10,500,1,1,233.5,234.43,100,105,1,2,233.45,234.5,15,63,1,4,AAPL,200.0,200.0,0.0,0.0,0.0,0.0,0.0,0.0,0.0,0.0,0.0,3.9761165292250036,
2024-10-21T12:20:54.648283192Z,2024-10-21T12:20:54.648117162Z,10,2,38,C,A,0,233.97,200,130,166030,12810171,233.86,234.0,750,50,1,1,233.8,234.04,5,27,1,1,233.73,234.1,26,100,1,1,233.71,234.13,400,400,2,1,233.7,234.17,1200,1,1,1,233.66,234.25,1,100,1,1,233.58,234.41,505,500,2,1,233.53,234.43,10,105,1,2,233.5,234.5,100,63,1,4,233.45,234.75,15,1,1,1,AAPL,50.0,50.0,27.0,100.0,400.0,1.0,100.0,500.0,105.0,63.0,1.0,180.89091145672717,
2024-10-21T12:20:54.648295052Z,2024-10-21T12:20:54.648128723Z,10,2,38,A,A,1,234.03,400,130,166329,12810172,233.86,234.0,750,50,1,1,233.8,234.03,5,400,1,1,233.73,234.04,26,27,1,1,233.71,234.1,400,100,2,1,233.7,234.13,1200,400,1,1,233.66,234.17,1,1,1,1,233.58,234.25,505,100,2,1,233.53,234.41,10,500,1,1,233.5,234.43,100,105,1,2,233.45,234.5,15,63,1,4,AAPL,0.0,0.0,-27.0,-100.0,-400.0,-1.0,-100.0,-500.0,-105.0,-63.0,-1.0,-179.89688232442091,
2024-10-21T12:20:54.648612547Z,2024-10-21T12:20:54.648446832Z,10,2,38,C,A,2,234.04,27,130,165715,12810176,233.86,234.0,750,50,1,1,233.8,234.03,5,400,1,1,233.73,234.1,26,100,1,1,233.71,234.13,400,400,2,1,233.7,234.17,1200,1,1,1,233.66,234.25,1,100,1,1,233.58,234.41,505,500,2,1,233.53,234.43,10,105,1,2,233.5,234.5,100,63,1,4,233.45,234.75,15,1,1,1,AAPL,0.0,0.0,0.0,100.0,400.0,1.0,100.0,500.0,105.0,63.0,1.0,178.18464592804142,
2024-10-21T12:20:54.697366809Z,2024-10-21T12:20:54.697200659Z,10,2,38,C,B,3,233.71,200,130,166150,12810217,233.86,234.0,750,50,1,1,233.8,234.03,5,400,1,1,233.73,234.1,26,100,1,1,233.71,234.13,200,400,1,1,233.7,234.17,1200,1,1,1,233.66,234.25,1,100,1,1,233.58,234.41,505,500,2,1,233.53,234.43,10,105,1,2,233.5,234.5,100,63,1,4,233.45,234.75,15,1,1,1,AAPL,0.0,0.0,0.0,0.0,-200.0,0.0,0.0,0.0,0.0,0.0,0.0,-41.015411004823704,
2024-10-21T12:20:54.697379987Z,2024-10-21T12:20:54.697212843Z,10,2,38,A,B,2,233.77,200,130,167144,12810218,233.86,234.0,750,50,1,1,233.8,234.03,5,400,1,1,233.77,234.1,200,100,1,1,233.73,234.13,26,400,1,1,233.7,234.17,1200,1,1,1,233.66,234.25,1,100,1,1,233.58,234.41,505,500,2,1,233.53,234.43,10,105,1,2,233.5,234.5,100,63,1,4,233.45,234.75,15,1,1,1,AAPL,0.0,0.0,0.0,200.0,26.0,0.0,0.0,0.0,0.0,0.0,0.0,25.64851957782812,
2024-10-21T12:20:54.708397951Z,2024-10-21T12:20:54.708231641Z,10,2,38,A,A,0,233.99,200,130,166310,12810231,233.86,233.99,750,200,1,1,233.8,234.0,5,50,1,1,233.77,234.1,200,100,1,1,233.73,234.13,26,400,1,1,233.7,234.17,1200,1,1,1,233.66,234.25,1,100,1,1,233.58,234.41,505,500,2,1,233.53,234.43,10,105,1,2,233.5,234.5,100,63,1,4,233.45,234.75,15,1,1,1,AAPL,-50.0,-50.0,-400.0,0.0,0.0,0.0,0.0,0.0,0.0,0.0,0.0,-26.360494263854086,
2024-10-21T12:20:56.393759280Z,2024-10-21T12:20:56.393593183Z,10,2,38,A,A,2,234.05,30,130,166097,12811166,233.86,233.99,750,200,1,1,233.8,234.0,5,50,1,1,233.77,234.05,200,30,1,1,233.73,234.1,26,100,1,1,233.7,234.13,1200,400,1,1,233.66,234.17,1,1,1,1,233.58,234.25,505,100,2,1,233.53,234.41,10,500,1,1,233.5,234.43,100,105,1,2,233.45,234.5,15,63,1,4,AAPL,0.0,0.0,0.0,-100.0,-400.0,-1.0,-100.0,-500.0,-105.0,-63.0,-1.0,-178.18464592804142,
2024-10-21T12:20:56.654514873Z,2024-10-21T12:20:56.654348888Z,10,2,38,C,A,0,233.99,200,130,165985,12811490,233.86,234.0,750,50,1,1,233.8,234.05,5,30,1,1,233.77,234.1,200,100,1,1,233.73,234.13,26,400,1,1,233.7,234.17,1200,1,1,1,233.66,234.25,1,100,1,1,233.58,234.41,505,500,2,1,233.53,234.43,10,105,1,2,233.5,234.5,100,63,1,4,233.45,234.75,15,1,1,1,AAPL,50.0,50.0,30.0,100.0,400.0,1.0,100.0,500.0,105.0,63.0,1.0,181.08115994521378,
2024-10-21T12:20:56.654527697Z,2024-10-21T12:20:56.654361253Z,10,2,38,A,A,1,234.03,400,130,166444,12811491,233.86,234.0,750,50,1,1,233.8,234.03,5,400,1,1,233.77,234.05,200,30,1,1,233.73,234.1,26,100,1,1,233.7,234.13,1200,400,1,1,233.66,234.17,1,1,1,1,233.58,234.25,505,100,2,1,233.53,234.41,10,500,1,1,233.5,234.43,100,105,1,2,233.45,234.5,15,63,1,4,AAPL,0.0,0.0,-30.0,-100.0,-400.0,-1.0,-100.0,-500.0,-105.0,-63.0,-1.0,-180.08713081290753,
2024-10-21T12:20:56.655842318Z,2024-10-21T12:20:56.655676466Z,10,2,38,C,A,2,234.05,30,130,165852,12811493,233.86,234.0,750,50,1,1,233.8,234.03,5,400,1,1,233.77,234.1,200,100,1,1,233.73,234.13,26,400,1,1,233.7,234.17,1200,1,1,1,233.66,234.25,1,100,1,1,233.58,234.41,505,500,2,1,233.53,234.43,10,105,1,2,233.5,234.5,100,63,1,4,233.45,234.75,15,1,1,1,AAPL,0.0,0.0,0.0,100.0,400.0,1.0,100.0,500.0,105.0,63.0,1.0,178.18464592804142,
2024-10-21T12:21:00.388479265Z,2024-10-21T12:21:00.388313049Z,10,2,38,A,A,2,234.1,26,130,166216,12815663,233.86,234.0,750,50,1,1,233.8,234.03,5,400,1,1,233.77,234.1,200,126,1,2,233.73,234.13,26,400,1,1,233.7,234.17,1200,1,1,1,233.66,234.25,1,100,1,1,233.58,234.41,505,500,2,1,233.53,234.43,10,105,1,2,233.5,234.5,100,63,1,4,233.45,234.75,15,1,1,1,AAPL,0.0,0.0,0.0,-26.0,0.0,0.0,0.0,0.0,0.0,0.0,0.0,-2.641147099136135,
2024-10-21T12:21:01.708023897Z,2024-10-21T12:21:01.707857424Z,10,2,38,A,A,0,234.0,200,130,166473,12817432,233.86,234.0,750,250,1,2,233.8,234.1,5,126,1,2,233.77,234.13,200,400,1,1,233.73,234.17,26,1,1,1,233.7,234.25,1200,100,1,1,233.66,234.41,1,500,1,1,233.58,234.43,505,105,2,2,233.53,234.5,10,63,1,4,233.5,234.75,100,1,1,1,233.45,234.79,15,2000,1,1,AAPL,-200.0,-200.0,126.0,400.0,1.0,100.0,500.0,105.0,63.0,1.0,2000.0,285.82285711825216,
2024-10-21T12:21:01.856991707Z,2024-10-21T12:21:01.856825426Z,10,2,38,C,A,0,234.0,200,130,166281,12817610,233.86,234.0,750,50,1,1,233.8,234.1,5,126,1,2,233.77,234.13,200,400,1,1,233.73,234.17,26,1,1,1,233.7,234.25,1200,100,1,1,233.66,234.41,1,500,1,1,233.58,234.43,505,105,2,2,233.53,234.5,10,63,1,4,233.5,234.75,100,1,1,1,233.45,234.79,15,2000,1,1,AAPL,200.0,200.0,0.0,0.0,0.0,0.0,0.0,0.0,0.0,0.0,0.0,3.9761165292250036,
2024-10-21T12:21:01.857003762Z,2024-10-21T12:21:01.856837629Z,10,2,38,A,A,1,234.03,400,130,166133,12817611,233.86,234.0,750,50,1,1,233.8,234.03,5,400,1,1,233.77,234.1,200,126,1,2,233.73,234.13,26,400,1,1,233.7,234.17,1200,1,1,1,233.66,234.25,1,100,1,1,233.58,234.41,505,500,2,1,233.53,234.43,10,105,1,2,233.5,234.5,100,63,1,4,233.45,234.75,15,1,1,1,AAPL,0.0,0.0,-126.0,-400.0,-1.0,-100.0,-500.0,-105.0,-63.0,-1.0,-2000.0,-289.7989736474771,
2024-10-21T12:21:06.854114356Z,2024-10-21T12:21:06.853945458Z,10,2,38,C,B,2,233.77,200,128,168898,12822045,233.86,234.0,750,50,1,1,233.8,234.03,5,400,1,1,233.73,234.1,26,126,1,2,233.7,234.13,1200,400,1,1,233.66,234.17,1,1,1,1,233.58,234.25,505,100,2,1,233.53,234.41,10,500,1,1,233.5,234.43,100,105,1,2,233.45,234.5,15,63,1,4,233.4,234.75,110,1,2,1,AAPL,0.0,0.0,0.0,-200.0,-26.0,-1200.0,-1.0,-505.0,-10.0,-100.0,-15.0,-232.0370202526743,
2024-10-21T12:21:06.917672196Z,2024-10-21T12:21:06.917506080Z,10,2,38,C,A,2,234.1,26,130,166116,12822954,233.86,234.0,750,50,1,1,233.8,234.03,5,400,1,1,233.73,234.1,26,100,1,1,233.7,234.13,1200,400,1,1,233.66,234.17,1,1,1,1,233.58,234.25,505,100,2,1,233.53,234.41,10,500,1,1,233.5,234.43,100,105,1,2,233.45,234.5,15,63,1,4,233.4,234.75,110,1,2,1,AAPL,0.0,0.0,0.0,26.0,0.0,0.0,0.0,0.0,0.0,0.0,0.0,2.641147099136135,
2024-10-21T12:21:06.917723950Z,2024-10-21T12:21:06.917557816Z,10,2,38,A,A,2,234.04,29,130,166134,12822956,233.86,234.0,750,50,1,1,233.8,234.03,5,400,1,1,233.73,234.04,26,29,1,1,233.7,234.1,1200,100,1,1,233.66,234.13,1,400,1,1,233.58,234.17,505,1,2,1,233.53,234.25,10,100,1,1,233.5,234.41,100,500,1,1,233.45,234.43,15,105,1,2,233.4,234.5,110,63,2,4,AAPL,0.0,0.0,0.0,-100.0,-400.0,-1.0,-100.0,-500.0,-105.0,-63.0,-1.0,-178.18464592804142,
2024-10-21T12:21:06.921436322Z,2024-10-21T12:21:06.921270364Z,10,2,38,C,A,2,234.04,29,130,165958,12822971,233.86,234.0,750,50,1,1,233.8,234.03,5,400,1,1,233.73,234.1,26,100,1,1,233.7,234.13,1200,400,1,1,233.66,234.17,1,1,1,1,233.58,234.25,505,100,2,1,233.53,234.41,10,500,1,1,233.5,234.43,100,105,1,2,233.45,234.5,15,63,1,4,233.4,234.75,110,1,2,1,AAPL,0.0,0.0,0.0,100.0,400.0,1.0,100.0,500.0,105.0,63.0,1.0,178.18464592804142,
2024-10-21T12:21:06.921907160Z,2024-10-21T12:21:06.921738635Z,10,2,38,A,B,4,233.67,30,130,168525,12822978,233.86,234.0,750,50,1,1,233.8,234.03,5,400,1,1,233.73,234.1,26,100,1,1,233.7,234.13,1200,400,1,1,233.67,234.17,30,1,1,1,233.66,234.25,1,100,1,1,233.58,234.41,505,500,2,1,233.53,234.43,10,105,1,2,233.5,234.5,100,63,1,4,233.45,234.75,15,1,1,1,AAPL,0.0,0.0,0.0,0.0,0.0,30.0,1.0,505.0,10.0,100.0,15.0,70.21490648799674,
2024-10-21T12:21:06.921927508Z,2024-10-21T12:21:06.921761416Z,10,2,38,C,B,2,233.73,26,130,166092,12822980,233.86,234.0,750,50,1,1,233.8,234.03,5,400,1,1,233.7,234.1,1200,100,1,1,233.67,234.13,30,400,1,1,233.66,234.17,1,1,1,1,233.58,234.25,505,100,2,1,233.53,234.41,10,500,1,1,233.5,234.43,100,105,1,2,233.45,234.5,15,63,1,4,233.4,234.75,110,1,2,1,AAPL,0.0,0.0,0.0,-26.0,-1200.0,-30.0,-1.0,-505.0,-10.0,-100.0,-15.0,-318.94851961607515,
2024-10-21T12:21:06.954339916Z,2024-10-21T12:21:06.954173708Z,10,2,38,A,B,2,233.72,200,130,166208,12823107,233.86,234.0,750,50,1,1,233.8,234.03,5,400,1,1,233.72,234.1,200,100,1,1,233.7,234.13,1200,400,1,1,233.67,234.17,30,1,1,1,233.66,234.25,1,100,1,1,233.58,234.41,505,500,2,1,233.53,234.43,10,105,1,2,233.5,234.5,100,63,1,4,233.45,234.75,15,1,1,1,AAPL,0.0,0.0,0.0,200.0,1200.0,30.0,1.0,505.0,10.0,100.0,15.0,336.62388866414,
2024-10-21T12:21:07.982871946Z,2024-10-21T12:21:07.982705400Z,10,2,38,A,B,4,233.68,29,130,166546,12824965,233.86,234.0,750,50,1,1,233.8,234.03,5,400,1,1,233.72,234.1,200,100,1,1,233.7,234.13,1200,400,1,1,233.68,234.17,29,1,1,1,233.67,234.25,30,100,1,1,233.66,234.41,1,500,1,1,233.58,234.43,505,105,2,2,233.53,234.5,10,63,1,4,233.5,234.75,100,1,1,1,AAPL,0.0,0.0,0.0,0.0,0.0,29.0,30.0,1.0,505.0,10.0,100.0,66.73164973976031,
2024-10-21T12:21:07.982898445Z,2024-10-21T12:21:07.982732401Z,10,2,38,C,B,5,233.67,30,130,166044,12824966,233.86,234.0,750,50,1,1,233.8,234.03,5,400,1,1,233.72,234.1,200,100,1,1,233.7,234.13,1200,400,1,1,233.68,234.17,29,1,1,1,233.66,234.25,1,100,1,1,233.58,234.41,505,500,2,1,233.53,234.43,10,105,1,2,233.5,234.5,100,63,1,4,233.45,234.75,15,1,1,1,AAPL,0.0,0.0,0.0,0.0,0.0,0.0,-30.0,-1.0,-505.0,-10.0,-100.0,-63.35640680692387,
2024-10-21T12:21:08.049635180Z,2024-10-21T12:21:08.049468728Z,10,2,38,A,B,2,233.73,200,130,166452,12825229,233.86,234.0,750,50,1,1,233.8,234.03,5,400,1,1,233.73,234.1,200,100,1,1,233.7,234.13,1200,400,1,1,233.68,234.17,29,1,1,1,233.66,234.25,1,100,1,1,233.58,234.41,505,500,2,1,233.53,234.43,10,105,1,2,233.5,234.5,100,63,1,4,233.45,234.75,15,1,1,1,AAPL,0.0,0.0,0.0,200.0,0.0,0.0,0.0,0.0,0.0,0.0,0.0,20.31651614720104,
2024-10-21T12:21:08.155903006Z,2024-10-21T12:21:08.155736487Z,10,2,38,A,B,2,233.73,200,130,166519,12825740,233.86,234.0,750,50,1,1,233.8,234.03,5,400,1,1,233.73,234.1,400,100,2,1,233.7,234.13,1200,400,1,1,233.68,234.17,29,1,1,1,233.66,234.25,1,100,1,1,233.58,234.41,505,500,2,1,233.53,234.43,10,105,1,2,233.5,234.5,100,63,1,4,233.45,234.75,15,1,1,1,AAPL,0.0,0.0,0.0,200.0,0.0,0.0,0.0,0.0,0.0,0.0,0.0,20.31651614720104,
2024-10-21T12:21:08.156442002Z,2024-10-21T12:21:08.156275244Z,10,2,38,A,B,0,233.86,100,130,166758,12825741,233.86,234.0,850,50,2,1,233.8,234.03,5,400,1,1,233.73,234.1,400,100,2,1,233.7,234.13,1200,400,1,1,233.68,234.17,29,1,1,1,233.66,234.25,1,100,1,1,233.58,234.41,505,500,2,1,233.53,234.43,10,105,1,2,233.5,234.5,100,63,1,4,233.45,234.75,15,1,1,1,AAPL,100.0,100.0,0.0,0.0,0.0,0.0,0.0,0.0,0.0,0.0,0.0,1.9880582646125018,
2024-10-21T12:21:08.214759234Z,2024-10-21T12:21:08.214593412Z,10,2,38,C,B,2,233.73,200,130,165822,12825863,233.86,234.0,850,50,2,1,233.8,234.03,5,400,1,1,233.73,234.1,200,100,1,1,233.7,234.13,1200,400,1,1,233.68,234.17,29,1,1,1,233.66,234.25,1,100,1,1,233.58,234.41,505,500,2,1,233.53,234.43,10,105,1,2,233.5,234.5,100,63,1,4,233.45,234.75,15,1,1,1,AAPL,0.0,0.0,0.0,-200.0,0.0,0.0,0.0,0.0,0.0,0.0,0.0,-20.31651614720104,
2024-10-21T12:21:08.214770994Z,2024-10-21T12:21:08.214604801Z,10,2,38,A,B,2,233.76,400,130,166193,12825864,233.86,234.0,850,50,2,1,233.8,234.03,5,400,1,1,233.76,234.1,400,100,1,1,233.7,234.13,1200,400,1,1,233.68,234.17,29,1,1,1,233.66,234.25,1,100,1,1,233.58,234.41,505,500,2,1,233.53,234.43,10,105,1,2,233.5,234.5,100,63,1,4,233.45,234.75,15,1,1,1,AAPL,0.0,0.0,0.0,400.0,0.0,0.0,0.0,0.0,0.0,0.0,0.0,40.63303229440208,
2024-10-21T12:21:09.374399277Z,2024-10-21T12:21:09.374232780Z,10,2,38,A,A,2,234.06,26,130,166497,12827250,233.86,234.0,850,50,2,1,233.8,234.03,5,400,1,1,233.76,234.06,400,26,1,1,233.7,234.1,1200,100,1,1,233.68,234.13,29,400,1,1,233.66,234.17,1,1,1,1,233.58,234.25,505,100,2,1,233.53,234.41,10,500,1,1,233.5,234.43,100,105,1,2,233.45,234.5,15,63,1,4,AAPL,0.0,0.0,0.0,-100.0,-400.0,-1.0,-100.0,-500.0,-105.0,-63.0,-1.0,-178.18464592804142,
2024-10-21T12:21:13.168706863Z,2024-10-21T12:21:13.168540873Z,10,2,38,C,B,0,233.86,100,130,165990,12830353,233.86,234.0,750,50,1,1,233.8,234.03,5,400,1,1,233.76,234.06,400,26,1,1,233.7,234.1,1200,100,1,1,233.68,234.13,29,400,1,1,233.66,234.17,1,1,1,1,233.58,234.25,505,100,2,1,233.53,234.41,10,500,1,1,233.5,234.43,100,105,1,2,233.45,234.5,15,63,1,4,AAPL,-100.0,-100.0,0.0,0.0,0.0,0.0,0.0,0.0,0.0,0.0,0.0,-1.9880582646125018,
2024-10-21T12:21:16.960190551Z,2024-10-21T12:21:16.960024614Z,10,2,38,C,B,2,233.76,400,130,165937,12834954,233.86,234.0,750,50,1,1,233.8,234.03,5,400,1,1,233.7,234.06,1200,26,1,1,233.68,234.1,29,100,1,1,233.66,234.13,1,400,1,1,233.58,234.17,505,1,2,1,233.53,234.25,10,100,1,1,233.5,234.41,100,500,1,1,233.45,234.43,15,105,1,2,233.4,234.5,110,63,2,4,AAPL,0.0,0.0,0.0,-400.0,-1200.0,-29.0,-1.0,-505.0,-10.0,-100.0,-15.0,-356.8240171240019,
2024-10-21T12:21:16.960203958Z,2024-10-21T12:21:16.960037598Z,10,2,38,A,B,2,233.73,200,130,166360,12834955,233.86,234.0,750,50,1,1,233.8,234.03,5,400,1,1,233.73,234.06,200,26,1,1,233.7,234.1,1200,100,1,1,233.68,234.13,29,400,1,1,233.66,234.17,1,1,1,1,233.58,234.25,505,100,2,1,233.53,234.41,10,500,1,1,233.5,234.43,100,105,1,2,233.45,234.5,15,63,1,4,AAPL,0.0,0.0,0.0,200.0,1200.0,29.0,1.0,505.0,10.0,100.0,15.0,336.5075009768008,
2024-10-21T12:21:17.838076240Z,2024-10-21T12:21:17.837910042Z,10,2,38,C,A,1,234.03,400,130,166198,12836232,233.86,234.0,750,50,1,1,233.8,234.06,5,26,1,1,233.73,234.1,200,100,1,1,233.7,234.13,1200,400,1,1,233.68,234.17,29,1,1,1,233.66,234.25,1,100,1,1,233.58,234.41,505,500,2,1,233.53,234.43,10,105,1,2,233.5,234.5,100,63,1,4,233.45,234.75,15,1,1,1,AAPL,0.0,0.0,26.0,100.0,400.0,1.0,100.0,500.0,105.0,63.0,1.0,179.83346616159204,
2024-10-21T12:21:17.838088673Z,2024-10-21T12:21:17.837922361Z,10,2,38,A,A,1,234.05,400,130,166312,12836233,233.86,234.0,750,50,1,1,233.8,234.05,5,400,1,1,233.73,234.06,200,26,1,1,233.7,234.1,1200,100,1,1,233.68,234.13,29,400,1,1,233.66,234.17,1,1,1,1,233.58,234.25,505,100,2,1,233.53,234.41,10,500,1,1,233.5,234.43,100,105,1,2,233.45,234.5,15,63,1,4,AAPL,0.0,0.0,-26.0,-100.0,-400.0,-1.0,-100.0,-500.0,-105.0,-63.0,-1.0,-179.83346616159204,
2024-10-21T12:21:17.892937930Z,2024-10-21T12:21:17.892771425Z,10,2,38,A,B,2,233.74,200,130,166505,12836353,233.86,234.0,750,50,1,1,233.8,234.05,5,400,1,1,233.74,234.06,200,26,1,1,233.7,234.1,1200,100,1,1,233.68,234.13,29,400,1,1,233.66,234.17,1,1,1,1,233.58,234.25,505,100,2,1,233.53,234.41,10,500,1,1,233.5,234.43,100,105,1,2,233.45,234.5,15,63,1,4,AAPL,0.0,0.0,0.0,200.0,0.0,0.0,0.0,0.0,0.0,0.0,0.0,20.31651614720104,
2024-10-21T12:21:18.021459648Z,2024-10-21T12:21:18.021293469Z,10,2,38,C,B,4,233.68,29,130,166179,12836833,233.86,234.0,750,50,1,1,233.8,234.05,5,400,1,1,233.74,234.06,200,26,1,1,233.7,234.1,1200,100,1,1,233.66,234.13,1,400,1,1,233.58,234.17,505,1,2,1,233.53,234.25,10,100,1,1,233.5,234.41,100,500,1,1,233.45,234.43,15,105,1,2,233.4,234.5,110,63,2,4,AAPL,0.0,0.0,0.0,0.0,0.0,-29.0,-1.0,-505.0,-10.0,-100.0,-15.0,-70.09851880065756,
2024-10-21T12:21:18.047995053Z,2024-10-21T12:21:18.047828600Z,10,2,38,A,B,2,233.74,200,130,166453,12836959,233.86,234.0,750,50,1,1,233.8,234.05,5,400,1,1,233.74,234.06,400,26,2,1,233.7,234.1,1200,100,1,1,233.66,234.13,1,400,1,1,233.58,234.17,505,1,2,1,233.53,234.25,10,100,1,1,233.5,234.41,100,500,1,1,233.45,234.43,15,105,1,2,233.4,234.5,110,63,2,4,AAPL,0.0,0.0,0.0,200.0,0.0,0.0,0.0,0.0,0.0,0.0,0.0,20.31651614720104,
2024-10-21T12:21:18.102567260Z,2024-10-21T12:21:18.102401275Z,10,2,38,C,B,2,233.74,200,130,165985,12837042,233.86,234.0,750,50,1,1,233.8,234.05,5,400,1,1,233.74,234.06,200,26,1,1,233.7,234.1,1200,100,1,1,233.66,234.13,1,400,1,1,233.58,234.17,505,1,2,1,233.53,234.25,10,100,1,1,233.5,234.41,100,500,1,1,233.45,234.43,15,105,1,2,233.4,234.5,110,63,2,4,AAPL,0.0,0.0,0.0,-200.0,0.0,0.0,0.0,0.0,0.0,0.0,0.0,-20.31651614720104,
2024-10-21T12:21:18.102579613Z,2024-10-21T12:21:18.102413183Z,10,2,38,A,B,2,233.77,400,130,166430,12837043,233.86,234.0,750,50,1,1,233.8,234.05,5,400,1,1,233.77,234.06,400,26,1,1,233.7,234.1,1200,100,1,1,233.66,234.13,1,400,1,1,233.58,234.17,505,1,2,1,233.53,234.25,10,100,1,1,233.5,234.41,100,500,1,1,233.45,234.43,15,105,1,2,233.4,234.5,110,63,2,4,AAPL,0.0,0.0,0.0,400.0,0.0,0.0,0.0,0.0,0.0,0.0,0.0,40.63303229440208,
2024-10-21T12:21:18.740047899Z,2024-10-21T12:21:18.739881846Z,10,2,38,C,A,1,234.05,200,130,166053,12837434,233.86,234.0,750,50,1,1,233.8,234.05,5,200,1,1,233.77,234.06,400,26,1,1,233.7,234.1,1200,100,1,1,233.66,234.13,1,400,1,1,233.58,234.17,505,1,2,1,233.53,234.25,10,100,1,1,233.5,234.41,100,500,1,1,233.45,234.43,15,105,1,2,233.4,234.5,110,63,2,4,AAPL,0.0,0.0,200.0,0.0,0.0,0.0,0.0,0.0,0.0,0.0,0.0,12.683232565773917,
2024-10-21T12:21:21.742938480Z,2024-10-21T12:21:21.742772097Z,10,2,38,A,A,1,234.05,200,130,166383,12841885,233.86,234.0,750,50,1,1,233.8,234.05,5,400,1,2,233.77,234.06,400,26,1,1,233.7,234.1,1200,100,1,1,233.66,234.13,1,400,1,1,233.58,234.17,505,1,2,1,233.53,234.25,10,100,1,1,233.5,234.41,100,500,1,1,233.45,234.43,15,105,1,2,233.4,234.5,110,63,2,4,AAPL,0.0,0.0,-200.0,0.0,0.0,0.0,0.0,0.0,0.0,0.0,0.0,-12.683232565773917,
2024-10-21T12:21:26.102361829Z,2024-10-21T12:21:26.102195386Z,10,2,38,A,B,2,233.78,400,130,166443,12846472,233.86,234.0,750,50,1,1,233.8,234.05,5,400,1,2,233.78,234.06,400,26,1,1,233.7,234.1,1200,100,1,1,233.66,234.13,1,400,1,1,233.58,234.17,505,1,2,1,233.53,234.25,10,100,1,1,233.5,234.41,100,500,1,1,233.45,234.43,15,105,1,2,233.4,234.5,110,63,2,4,AAPL,0.0,0.0,0.0,400.0,0.0,0.0,0.0,0.0,0.0,0.0,0.0,40.63303229440208,
2024-10-21T12:21:26.482529203Z,2024-10-21T12:21:26.482363138Z,10,2,38,C,B,2,233.78,200,130,166065,12846917,233.86,234.0,750,50,1,1,233.8,234.05,5,400,1,2,233.78,234.06,200,26,1,1,233.7,234.1,1200,100,1,1,233.66,234.13,1,400,1,1,233.58,234.17,505,1,2,1,233.53,234.25,10,100,1,1,233.5,234.41,100,500,1,1,233.45,234.43,15,105,1,2,233.4,234.5,110,63,2,4,AAPL,0.0,0.0,0.0,-200.0,0.0,0.0,0.0,0.0,0.0,0.0,0.0,-20.31651614720104,
2024-10-21T12:21:26.509714476Z,2024-10-21T12:21:26.509547941Z,10,2,38,A,B,2,233.78,200,130,166535,12846932,233.86,234.0,750,50,1,1,233.8,234.05,5,400,1,2,233.78,234.06,400,26,2,1,233.7,234.1,1200,100,1,1,233.66,234.13,1,400,1,1,233.58,234.17,505,1,2,1,233.53,234.25,10,100,1,1,233.5,234.41,100,500,1,1,233.45,234.43,15,105,1,2,233.4,234.5,110,63,2,4,AAPL,0.0,0.0,0.0,200.0,0.0,0.0,0.0,0.0,0.0,0.0,0.0,20.31651614720104,
2024-10-21T12:21:26.750930428Z,2024-10-21T12:21:26.750764565Z,10,2,38,C,B,2,233.78,200,130,165863,12847141,233.86,234.0,750,50,1,1,233.8,234.05,5,400,1,2,233.78,234.06,200,26,1,1,233.7,234.1,1200,100,1,1,233.66,234.13,1,400,1,1,233.58,234.17,505,1,2,1,233.53,234.25,10,100,1,1,233.5,234.41,100,500,1,1,233.45,234.43,15,105,1,2,233.4,234.5,110,63,2,4,AAPL,0.0,0.0,0.0,-200.0,0.0,0.0,0.0,0.0,0.0,0.0,0.0,-20.31651614720104,
2024-10-21T12:21:26.750938918Z,2024-10-21T12:21:26.750773173Z,10,2,38,C,B,2,233.78,200,130,165745,12847142,233.86,234.0,750,50,1,1,233.8,234.05,5,400,1,2,233.7,234.06,1200,26,1,1,233.66,234.1,1,100,1,1,233.58,234.13,505,400,2,1,233.53,234.17,10,1,1,1,233.5,234.25,100,100,1,1,233.45,234.41,15,500,1,1,233.4,234.43,110,105,2,2,233.39,234.5,10,63,1,4,AAPL,0.0,0.0,0.0,-200.0,-1200.0,-1.0,-505.0,-10.0,-100.0,-15.0,-110.0,-356.21403009204323,
2024-10-21T12:21:26.750951960Z,2024-10-21T12:21:26.750785721Z,10,2,38,A,B,2,233.75,400,130,166239,12847143,233.86,234.0,750,50,1,1,233.8,234.05,5,400,1,2,233.75,234.06,400,26,1,1,233.7,234.1,1200,100,1,1,233.66,234.13,1,400,1,1,233.58,234.17,505,1,2,1,233.53,234.25,10,100,1,1,233.5,234.41,100,500,1,1,233.45,234.43,15,105,1,2,233.4,234.5,110,63,2,4,AAPL,0.0,0.0,0.0,400.0,1200.0,1.0,505.0,10.0,100.0,15.0,110.0,376.5305462392443,
2024-10-21T12:21:26.804985162Z,2024-10-21T12:21:26.804818995Z,10,2,38,C,A,1,234.05,200,130,166167,12847412,233.86,234.0,750,50,1,1,233.8,234.05,5,200,1,1,233.75,234.06,400,26,1,1,233.7,234.1,1200,100,1,1,233.66,234.13,1,400,1,1,233.58,234.17,505,1,2,1,233.53,234.25,10,100,1,1,233.5,234.41,100,500,1,1,233.45,234.43,15,105,1,2,233.4,234.5,110,63,2,4,AAPL,0.0,0.0,200.0,0.0,0.0,0.0,0.0,0.0,0.0,0.0,0.0,12.683232565773917,
2024-10-21T12:21:26.804997390Z,2024-10-21T12:21:26.804831024Z,10,2,38,A,A,1,234.04,400,130,166366,12847413,233.86,234.0,750,50,1,1,233.8,234.04,5,400,1,1,233.75,234.06,400,26,1,1,233.7,234.1,1200,100,1,1,233.66,234.13,1,400,1,1,233.58,234.17,505,1,2,1,233.53,234.25,10,100,1,1,233.5,234.41,100,500,1,1,233.45,234.43,15,105,1,2,233.4,234.5,110,63,2,4,AAPL,0.0,0.0,-200.0,0.0,0.0,0.0,0.0,0.0,0.0,0.0,0.0,-12.683232565773917,
2024-10-21T12:21:26.876365981Z,2024-10-21T12:21:26.876199312Z,10,2,38,A,B,2,233.76,400,130,166669,12847641,233.86,234.0,750,50,1,1,233.8,234.04,5,400,1,1,233.76,234.06,400,26,1,1,233.7,234.1,1200,100,1,1,233.66,234.13,1,400,1,1,233.58,234.17,505,1,2,1,233.53,234.25,10,100,1,1,233.5,234.41,100,500,1,1,233.45,234.43,15,105,1,2,233.4,234.5,110,63,2,4,AAPL,0.0,0.0,0.0,400.0,0.0,0.0,0.0,0.0,0.0,0.0,0.0,40.63303229440208,
2024-10-21T12:21:28.271511190Z,2024-10-21T12:21:28.271344736Z,10,2,38,A,B,2,233.77,400,130,166454,12849143,233.86,234.0,750,50,1,1,233.8,234.04,5,400,1,1,233.77,234.06,400,26,1,1,233.7,234.1,1200,100,1,1,233.66,234.13,1,400,1,1,233.58,234.17,505,1,2,1,233.53,234.25,10,100,1,1,233.5,234.41,100,500,1,1,233.45,234.43,15,105,1,2,233.4,234.5,110,63,2,4,AAPL,0.0,0.0,0.0,400.0,0.0,0.0,0.0,0.0,0.0,0.0,0.0,40.63303229440208,
2024-10-21T12:21:29.830338711Z,2024-10-21T12:21:29.830172186Z,10,2,38,A,B,4,233.69,29,130,166525,12850583,233.86,234.0,750,50,1,1,233.8,234.04,5,400,1,1,233.77,234.06,400,26,1,1,233.7,234.1,1200,100,1,1,233.69,234.13,29,400,1,1,233.66,234.17,1,1,1,1,233.58,234.25,505,100,2,1,233.53,234.41,10,500,1,1,233.5,234.43,100,105,1,2,233.45,234.5,15,63,1,4,AAPL,0.0,0.0,0.0,0.0,0.0,29.0,1.0,505.0,10.0,100.0,15.0,70.09851880065756,
2024-10-21T12:21:43.255727052Z,2024-10-21T12:21:43.255561253Z,10,2,38,C,A,1,234.04,400,130,165799,12858522,233.86,234.0,750,50,1,1,233.8,234.06,5,26,1,1,233.77,234.1,400,100,1,1,233.7,234.13,1200,400,1,1,233.69,234.17,29,1,1,1,233.66,234.25,1,100,1,1,233.58,234.41,505,500,2,1,233.53,234.43,10,105,1,2,233.5,234.5,100,63,1,4,233.45,234.75,15,1,1,1,AAPL,0.0,0.0,26.0,100.0,400.0,1.0,100.0,500.0,105.0,63.0,1.0,179.83346616159204,
2024-10-21T12:21:43.255741694Z,2024-10-21T12:21:43.255575289Z,10,2,38,A,A,1,234.06,400,130,166405,12858523,233.86,234.0,750,50,1,1,233.8,234.06,5,426,1,2,233.77,234.1,400,100,1,1,233.7,234.13,1200,400,1,1,233.69,234.17,29,1,1,1,233.66,234.25,1,100,1,1,233.58,234.41,505,500,2,1,233.53,234.43,10,105,1,2,233.5,234.5,100,63,1,4,233.45,234.75,15,1,1,1,AAPL,0.0,0.0,-400.0,0.0,0.0,0.0,0.0,0.0,0.0,0.0,0.0,-25.366465131547834,
2024-10-21T12:21:43.311094812Z,2024-10-21T12:21:43.310928524Z,10,2,38,A,A,1,234.05,200,130,166288,12858622,233.86,234.0,750,50,1,1,233.8,234.05,5,200,1,1,233.77,234.06,400,26,1,1,233.7,234.1,1200,100,1,1,233.69,234.13,29,400,1,1,233.66,234.17,1,1,1,1,233.58,234.25,505,100,2,1,233.53,234.41,10,500,1,1,233.5,234.43,100,105,1,2,233.45,234.5,15,63,1,4,AAPL,0.0,0.0,-426.0,-100.0,-400.0,-1.0,-100.0,-500.0,-105.0,-63.0,-1.0,-205.19993129313988,
2024-10-21T12:21:45.092291237Z,2024-10-21T12:21:45.092124924Z,10,2,38,A,B,2,233.78,400,130,166313,12859898,233.86,234.0,750,50,1,1,233.8,234.05,5,200,1,1,233.78,234.06,400,26,1,1,233.7,234.1,1200,100,1,1,233.69,234.13,29,400,1,1,233.66,234.17,1,1,1,1,233.58,234.25,505,100,2,1,233.53,234.41,10,500,1,1,233.5,234.43,100,105,1,2,233.45,234.5,15,63,1,4,AAPL,0.0,0.0,0.0,400.0,0.0,0.0,0.0,0.0,0.0,0.0,0.0,40.63303229440208,
2024-10-21T12:21:45.108399049Z,2024-10-21T12:21:45.108232814Z,10,2,38,C,B,4,233.69,29,130,166235,12859978,233.86,234.0,750,50,1,1,233.8,234.05,5,200,1,1,233.78,234.06,400,26,1,1,233.7,234.1,1200,100,1,1,233.66,234.13,1,400,1,1,233.58,234.17,505,1,2,1,233.53,234.25,10,100,1,1,233.5,234.41,100,500,1,1,233.45,234.43,15,105,1,2,233.4,234.5,110,63,2,4,AAPL,0.0,0.0,0.0,0.0,0.0,-29.0,-1.0,-505.0,-10.0,-100.0,-15.0,-70.09851880065756,
2024-10-21T12:21:45.108462494Z,2024-10-21T12:21:45.108296167Z,10,2,38,A,B,3,233.7,29,130,166327,12859979,233.86,234.0,750,50,1,1,233.8,234.05,5,200,1,1,233.78,234.06,400,26,1,1,233.7,234.1,1229,100,2,1,233.66,234.13,1,400,1,1,233.58,234.17,505,1,2,1,233.53,234.25,10,100,1,1,233.5,234.41,100,500,1,1,233.45,234.43,15,105,1,2,233.4,234.5,110,63,2,4,AAPL,0.0,0.0,0.0,0.0,29.0,0.0,0.0,0.0,0.0,0.0,0.0,5.947234595699437,
2024-10-21T12:21:48.360796158Z,2024-10-21T12:21:48.360630060Z,10,2,38,C,A,1,234.05,200,130,166098,12862379,233.86,234.0,750,50,1,1,233.8,234.06,5,26,1,1,233.78,234.1,400,100,1,1,233.7,234.13,1229,400,2,1,233.66,234.17,1,1,1,1,233.58,234.25,505,100,2,1,233.53,234.41,10,500,1,1,233.5,234.43,100,105,1,2,233.45,234.5,15,63,1,4,233.4,234.75,110,1,2,1,AAPL,0.0,0.0,26.0,100.0,400.0,1.0,100.0,500.0,105.0,63.0,1.0,179.83346616159204,
2024-10-21T12:21:48.360808085Z,2024-10-21T12:21:48.360641832Z,10,2,38,A,A,2,234.07,200,130,166253,12862380,233.86,234.0,750,50,1,1,233.8,234.06,5,26,1,1,233.78,234.07,400,200,1,1,233.7,234.1,1229,100,2,1,233.66,234.13,1,400,1,1,233.58,234.17,505,1,2,1,233.53,234.25,10,100,1,1,233.5,234.41,100,500,1,1,233.45,234.43,15,105,1,2,233.4,234.5,110,63,2,4,AAPL,0.0,0.0,0.0,-100.0,-400.0,-1.0,-100.0,-500.0,-105.0,-63.0,-1.0,-178.18464592804142,
2024-10-21T12:21:48.415690677Z,2024-10-21T12:21:48.415524174Z,10,2,38,A,B,2,233.79,400,130,166503,12862494,233.86,234.0,750,50,1,1,233.8,234.06,5,26,1,1,233.79,234.07,400,200,1,1,233.7,234.1,1229,100,2,1,233.66,234.13,1,400,1,1,233.58,234.17,505,1,2,1,233.53,234.25,10,100,1,1,233.5,234.41,100,500,1,1,233.45,234.43,15,105,1,2,233.4,234.5,110,63,2,4,AAPL,0.0,0.0,0.0,400.0,0.0,0.0,0.0,0.0,0.0,0.0,0.0,40.63303229440208,
2024-10-21T12:21:48.426415426Z,2024-10-21T12:21:48.426249325Z,10,2,38,C,B,3,233.7,29,130,166101,12862632,233.86,234.0,750,50,1,1,233.8,234.06,5,26,1,1,233.79,234.07,400,200,1,1,233.7,234.1,1200,100,1,1,233.66,234.13,1,400,1,1,233.58,234.17,505,1,2,1,233.53,234.25,10,100,1,1,233.5,234.41,100,500,1,1,233.45,234.43,15,105,1,2,233.4,234.5,110,63,2,4,AAPL,0.0,0.0,0.0,0.0,-29.0,0.0,0.0,0.0,0.0,0.0,0.0,-5.947234595699437,
2024-10-21T12:21:48.426524915Z,2024-10-21T12:21:48.426358775Z,10,2,38,A,B,3,233.71,26,130,166140,12862634,233.86,234.0,750,50,1,1,233.8,234.06,5,26,1,1,233.79,234.07,400,200,1,1,233.71,234.1,26,100,1,1,233.7,234.13,1200,400,1,1,233.66,234.17,1,1,1,1,233.58,234.25,505,100,2,1,233.53,234.41,10,500,1,1,233.5,234.43,100,105,1,2,233.45,234.5,15,63,1,4,AAPL,0.0,0.0,0.0,0.0,26.0,1200.0,1.0,505.0,10.0,100.0,15.0,211.72050410547325,
2024-10-21T12:21:48.440507069Z,2024-10-21T12:21:48.440341021Z,10,2,38,C,A,1,234.06,26,130,166048,12862704,233.86,234.0,750,50,1,1,233.8,234.07,5,200,1,1,233.79,234.1,400,100,1,1,233.71,234.13,26,400,1,1,233.7,234.17,1200,1,1,1,233.66,234.25,1,100,1,1,233.58,234.41,505,500,2,1,233.53,234.43,10,105,1,2,233.5,234.5,100,63,1,4,233.45,234.75,15,1,1,1,AAPL,0.0,0.0,200.0,100.0,400.0,1.0,100.0,500.0,105.0,63.0,1.0,190.86787849381534,
2024-10-21T12:21:48.582611366Z,2024-10-21T12:21:48.582445356Z,10,2,38,C,B,2,233.79,400,130,166010,12862943,233.86,234.0,750,50,1,1,233.8,234.07,5,200,1,1,233.71,234.1,26,100,1,1,233.7,234.13,1200,400,1,1,233.66,234.17,1,1,1,1,233.58,234.25,505,100,2,1,233.53,234.41,10,500,1,1,233.5,234.43,100,105,1,2,233.45,234.5,15,63,1,4,233.4,234.75,110,1,2,1,AAPL,0.0,0.0,0.0,-400.0,-26.0,-1200.0,-1.0,-505.0,-10.0,-100.0,-15.0,-252.35353639987534,
2024-10-21T12:21:48.582623644Z,2024-10-21T12:21:48.582457462Z,10,2,38,A,B,2,233.76,200,130,166182,12862944,233.86,234.0,750,50,1,1,233.8,234.07,5,200,1,1,233.76,234.1,200,100,1,1,233.71,234.13,26,400,1,1,233.7,234.17,1200,1,1,1,233.66,234.25,1,100,1,1,233.58,234.41,505,500,2,1,233.53,234.43,10,105,1,2,233.5,234.5,100,63,1,4,233.45,234.75,15,1,1,1,AAPL,0.0,0.0,0.0,200.0,26.0,1200.0,1.0,505.0,10.0,100.0,15.0,232.0370202526743,
2024-10-21T12:21:48.969029036Z,2024-10-21T12:21:48.968862759Z,10,2,38,A,A,1,234.07,200,130,166277,12863250,233.86,234.0,750,50,1,1,233.8,234.07,5,400,1,2,233.76,234.1,200,100,1,1,233.71,234.13,26,400,1,1,233.7,234.17,1200,1,1,1,233.66,234.25,1,100,1,1,233.58,234.41,505,500,2,1,233.53,234.43,10,105,1,2,233.5,234.5,100,63,1,4,233.45,234.75,15,1,1,1,AAPL,0.0,0.0,-200.0,0.0,0.0,0.0,0.0,0.0,0.0,0.0,0.0,-12.683232565773917,
2024-10-21T12:21:49.023322916Z,2024-10-21T12:21:49.023156980Z,10,2,38,C,A,1,234.07,200,130,165936,12863318,233.86,234.0,750,50,1,1,233.8,234.07,5,200,1,1,233.76,234.1,200,100,1,1,233.71,234.13,26,400,1,1,233.7,234.17,1200,1,1,1,233.66,234.25,1,100,1,1,233.58,234.41,505,500,2,1,233.53,234.43,10,105,1,2,233.5,234.5,100,63,1,4,233.45,234.75,15,1,1,1,AAPL,0.0,0.0,200.0,0.0,0.0,0.0,0.0,0.0,0.0,0.0,0.0,12.683232565773917,
2024-10-21T12:21:49.023336867Z,2024-10-21T12:21:49.023170310Z,10,2,38,A,A,1,234.03,200,130,166557,12863319,233.86,234.0,750,50,1,1,233.8,234.03,5,200,1,1,233.76,234.1,200,100,1,1,233.71,234.13,26,400,1,1,233.7,234.17,1200,1,1,1,233.66,234.25,1,100,1,1,233.58,234.41,505,500,2,1,233.53,234.43,10,105,1,2,233.5,234.5,100,63,1,4,233.45,234.75,15,1,1,1,AAPL,0.0,0.0,-200.0,0.0,0.0,0.0,0.0,0.0,0.0,0.0,0.0,-12.683232565773917,
2024-10-21T12:21:53.593514833Z,2024-10-21T12:21:53.593348279Z,10,2,38,A,B,2,233.76,200,130,166554,12866345,233.86,234.0,750,50,1,1,233.8,234.03,5,200,1,1,233.76,234.1,400,100,2,1,233.71,234.13,26,400,1,1,233.7,234.17,1200,1,1,1,233.66,234.25,1,100,1,1,233.58,234.41,505,500,2,1,233.53,234.43,10,105,1,2,233.5,234.5,100,63,1,4,233.45,234.75,15,1,1,1,AAPL,0.0,0.0,0.0,200.0,0.0,0.0,0.0,0.0,0.0,0.0,0.0,20.31651614720104,
2024-10-21T12:21:53.648061859Z,2024-10-21T12:21:53.647894830Z,10,2,38,C,B,2,233.76,200,130,167029,12866372,233.86,234.0,750,50,1,1,233.8,234.03,5,200,1,1,233.76,234.1,200,100,1,1,233.71,234.13,26,400,1,1,233.7,234.17,1200,1,1,1,233.66,234.25,1,100,1,1,233.58,234.41,505,500,2,1,233.53,234.43,10,105,1,2,233.5,234.5,100,63,1,4,233.45,234.75,15,1,1,1,AAPL,0.0,0.0,0.0,-200.0,0.0,0.0,0.0,0.0,0.0,0.0,0.0,-20.31651614720104,
2024-10-21T12:21:53.648074342Z,2024-10-21T12:21:53.647907823Z,10,2,38,A,B,2,233.79,400,130,166519,12866373,233.86,234.0,750,50,1,1,233.8,234.03,5,200,1,1,233.79,234.1,400,100,1,1,233.71,234.13,26,400,1,1,233.7,234.17,1200,1,1,1,233.66,234.25,1,100,1,1,233.58,234.41,505,500,2,1,233.53,234.43,10,105,1,2,233.5,234.5,100,63,1,4,233.45,234.75,15,1,1,1,AAPL,0.0,0.0,0.0,400.0,0.0,0.0,0.0,0.0,0.0,0.0,0.0,40.63303229440208,
2024-10-21T12:21:55.660797064Z,2024-10-21T12:21:55.660629861Z,10,2,38,T,N,0,233.92,46,130,167203,12867692,233.86,234.0,750,50,1,1,233.8,234.03,5,200,1,1,233.79,234.1,400,100,1,1,233.71,234.13,26,400,1,1,233.7,234.17,1200,1,1,1,233.66,234.25,1,100,1,1,233.58,234.41,505,500,2,1,233.53,234.43,10,105,1,2,233.5,234.5,100,63,1,4,233.45,234.75,15,1,1,1,AAPL,0.0,0.0,0.0,0.0,0.0,0.0,0.0,0.0,0.0,0.0,0.0,0.0,
2024-10-21T12:22:01.338070399Z,2024-10-21T12:22:01.337904135Z,10,2,38,A,A,1,234.02,200,130,166264,12872899,233.86,234.0,750,50,1,1,233.8,234.02,5,200,1,1,233.79,234.1,400,100,1,1,233.71,234.13,26,400,1,1,233.7,234.17,1200,1,1,1,233.66,234.25,1,100,1,1,233.58,234.41,505,500,2,1,233.53,234.43,10,105,1,2,233.5,234.5,100,63,1,4,233.45,234.75,15,1,1,1,AAPL,0.0,0.0,-200.0,0.0,0.0,0.0,0.0,0.0,0.0,0.0,0.0,-12.683232565773917,
2024-10-21T12:22:03.706527389Z,2024-10-21T12:22:03.706361217Z,10,2,38,C,B,0,233.86,750,130,166172,12876552,233.8,234.0,5,50,1,1,233.79,234.02,400,200,1,1,233.71,234.1,26,100,1,1,233.7,234.13,1200,400,1,1,233.66,234.17,1,1,1,1,233.58,234.25,505,100,2,1,233.53,234.41,10,500,1,1,233.5,234.43,100,105,1,2,233.45,234.5,15,63,1,4,233.4,234.75,110,1,2,1,AAPL,-750.0,-750.0,-5.0,-400.0,-26.0,-1200.0,-1.0,-505.0,-10.0,-100.0,-15.0,-267.58105419861346,
2024-10-21T12:22:03.777683119Z,2024-10-21T12:22:03.777516702Z,10,2,38,C,B,1,233.79,400,130,166417,12876583,233.8,234.0,5,50,1,1,233.71,234.02,26,200,1,1,233.7,234.1,1200,100,1,1,233.66,234.13,1,400,1,1,233.58,234.17,505,1,2,1,233.53,234.25,10,100,1,1,233.5,234.41,100,500,1,1,233.45,234.43,15,105,1,2,233.4,234.5,110,63,2,4,233.39,234.75,10,1,1,1,AAPL,0.0,0.0,-400.0,-26.0,-1200.0,-1.0,-505.0,-10.0,-100.0,-15.0,-110.0,-363.90512617552616,
2024-10-21T12:22:03.777696253Z,2024-10-21T12:22:03.777529729Z,10,2,38,A,B,1,233.72,200,130,166524,12876584,233.8,234.0,5,50,1,1,233.72,234.02,200,200,1,1,233.71,234.1,26,100,1,1,233.7,234.13,1200,400,1,1,233.66,234.17,1,1,1,1,233.58,234.25,505,100,2,1,233.53,234.41,10,500,1,1,233.5,234.43,100,105,1,2,233.45,234.5,15,63,1,4,233.4,234.75,110,1,2,1,AAPL,0.0,0.0,200.0,26.0,1200.0,1.0,505.0,10.0,100.0,15.0,110.0,351.22189360975227,
2024-10-21T12:22:03.782147350Z,2024-10-21T12:22:03.781981187Z,10,2,38,A,A,1,234.02,200,130,166163,12876586,233.8,234.0,5,50,1,1,233.72,234.02,200,400,1,2,233.71,234.1,26,100,1,1,233.7,234.13,1200,400,1,1,233.66,234.17,1,1,1,1,233.58,234.25,505,100,2,1,233.53,234.41,10,500,1,1,233.5,234.43,100,105,1,2,233.45,234.5,15,63,1,4,233.4,234.75,110,1,2,1,AAPL,0.0,0.0,-200.0,0.0,0.0,0.0,0.0,0.0,0.0,0.0,0.0,-12.683232565773917,
2024-10-21T12:22:09.127475230Z,2024-10-21T12:22:09.127308929Z,10,2,38,A,A,2,234.08,28,130,166301,12879884,233.8,234.0,5,50,1,1,233.72,234.02,200,400,1,2,233.71,234.08,26,28,1,1,233.7,234.1,1200,100,1,1,233.66,234.13,1,400,1,1,233.58,234.17,505,1,2,1,233.53,234.25,10,100,1,1,233.5,234.41,100,500,1,1,233.45,234.43,15,105,1,2,233.4,234.5,110,63,2,4,AAPL,0.0,0.0,0.0,-100.0,-400.0,-1.0,-100.0,-500.0,-105.0,-63.0,-1.0,-178.18464592804142,
2024-10-21T12:22:16.157521352Z,2024-10-21T12:22:16.157355560Z,10,2,38,C,B,2,233.71,26,130,165792,12885019,233.8,234.0,5,50,1,1,233.72,234.02,200,400,1,2,233.7,234.08,1200,28,1,1,233.66,234.1,1,100,1,1,233.58,234.13,505,400,2,1,233.53,234.17,10,1,1,1,233.5,234.25,100,100,1,1,233.45,234.41,15,500,1,1,233.4,234.43,110,105,2,2,233.39,234.5,10,63,1,4,AAPL,0.0,0.0,0.0,-26.0,-1200.0,-1.0,-505.0,-10.0,-100.0,-15.0,-110.0,-338.5386610439783,
2024-10-21T12:22:16.158550111Z,2024-10-21T12:22:16.158383793Z,10,2,38,A,B,1,233.72,28,130,166318,12885021,233.8,234.0,5,50,1,1,233.72,234.02,228,400,2,2,233.7,234.08,1200,28,1,1,233.66,234.1,1,100,1,1,233.58,234.13,505,400,2,1,233.53,234.17,10,1,1,1,233.5,234.25,100,100,1,1,233.45,234.41,15,500,1,1,233.4,234.43,110,105,2,2,233.39,234.5,10,63,1,4,AAPL,0.0,0.0,28.0,0.0,0.0,0.0,0.0,0.0,0.0,0.0,0.0,1.7756525592083483,
2024-10-21T12:22:20.068588488Z,2024-10-21T12:22:20.068422134Z,10,2,38,A,B,1,233.73,200,130,166354,12888188,233.8,234.0,5,50,1,1,233.73,234.02,200,400,1,2,233.72,234.08,28,28,1,1,233.7,234.1,1200,100,1,1,233.66,234.13,1,400,1,1,233.58,234.17,505,1,2,1,233.53,234.25,10,100,1,1,233.5,234.41,100,500,1,1,233.45,234.43,15,105,1,2,233.4,234.5,110,63,2,4,AAPL,0.0,0.0,200.0,28.0,1200.0,1.0,505.0,10.0,100.0,15.0,110.0,351.42505877122426,
2024-10-21T12:22:20.078936626Z,2024-10-21T12:22:20.078770275Z,10,2,38,A,B,1,233.73,29,130,166351,12888325,233.8,234.0,5,50,1,1,233.73,234.02,229,400,2,2,233.72,234.08,28,28,1,1,233.7,234.1,1200,100,1,1,233.66,234.13,1,400,1,1,233.58,234.17,505,1,2,1,233.53,234.25,10,100,1,1,233.5,234.41,100,500,1,1,233.45,234.43,15,105,1,2,233.4,234.5,110,63,2,4,AAPL,0.0,0.0,29.0,0.0,0.0,0.0,0.0,0.0,0.0,0.0,0.0,1.839068722037218,
2024-10-21T12:22:20.079017156Z,2024-10-21T12:22:20.078850920Z,10,2,38,C,B,2,233.72,28,130,166236,12888328,233.8,234.0,5,50,1,1,233.73,234.02,229,400,2,2,233.7,234.08,1200,28,1,1,233.66,234.1,1,100,1,1,233.58,234.13,505,400,2,1,233.53,234.17,10,1,1,1,233.5,234.25,100,100,1,1,233.45,234.41,15,500,1,1,233.4,234.43,110,105,2,2,233.39,234.5,10,63,1,4,AAPL,0.0,0.0,0.0,-28.0,-1200.0,-1.0,-505.0,-10.0,-100.0,-15.0,-110.0,-338.74182620545037,
2024-10-21T12:22:20.140405333Z,2024-10-21T12:22:20.140239259Z,10,2,38,C,A,2,234.08,28,130,166074,12888403,233.8,234.0,5,50,1,1,233.73,234.02,229,400,2,2,233.7,234.1,1200,100,1,1,233.66,234.13,1,400,1,1,233.58,234.17,505,1,2,1,233.53,234.25,10,100,1,1,233.5,234.41,100,500,1,1,233.45,234.43,15,105,1,2,233.4,234.5,110,63,2,4,233.39,234.75,10,1,1,1,AAPL,0.0,0.0,0.0,100.0,400.0,1.0,100.0,500.0,105.0,63.0,1.0,178.18464592804142,
2024-10-21T12:22:20.140457549Z,2024-10-21T12:22:20.140291372Z,10,2,38,A,A,2,234.04,30,130,166177,12888404,233.8,234.0,5,50,1,1,233.73,234.02,229,400,2,2,233.7,234.04,1200,30,1,1,233.66,234.1,1,100,1,1,233.58,234.13,505,400,2,1,233.53,234.17,10,1,1,1,233.5,234.25,100,100,1,1,233.45,234.41,15,500,1,1,233.4,234.43,110,105,2,2,233.39,234.5,10,63,1,4,AAPL,0.0,0.0,0.0,-100.0,-400.0,-1.0,-100.0,-500.0,-105.0,-63.0,-1.0,-178.18464592804142,
2024-10-21T12:22:20.142691051Z,2024-10-21T12:22:20.142525001Z,10,2,38,C,A,1,234.02,200,130,166050,12888407,233.8,234.0,5,50,1,1,233.73,234.02,229,200,2,1,233.7,234.04,1200,30,1,1,233.66,234.1,1,100,1,1,233.58,234.13,505,400,2,1,233.53,234.17,10,1,1,1,233.5,234.25,100,100,1,1,233.45,234.41,15,500,1,1,233.4,234.43,110,105,2,2,233.39,234.5,10,63,1,4,AAPL,0.0,0.0,200.0,0.0,0.0,0.0,0.0,0.0,0.0,0.0,0.0,12.683232565773917,
2024-10-21T12:22:20.142701567Z,2024-10-21T12:22:20.142535602Z,10,2,38,C,A,1,234.02,200,130,165965,12888408,233.8,234.0,5,50,1,1,233.73,234.04,229,30,2,1,233.7,234.1,1200,100,1,1,233.66,234.13,1,400,1,1,233.58,234.17,505,1,2,1,233.53,234.25,10,100,1,1,233.5,234.41,100,500,1,1,233.45,234.43,15,105,1,2,233.4,234.5,110,63,2,4,233.39,234.75,10,1,1,1,AAPL,0.0,0.0,30.0,100.0,400.0,1.0,100.0,500.0,105.0,63.0,1.0,180.08713081290753,
2024-10-21T12:22:20.142712784Z,2024-10-21T12:22:20.142546696Z,10,2,38,A,A,1,234.03,200,130,166088,12888409,233.8,234.0,5,50,1,1,233.73,234.03,229,200,2,1,233.7,234.04,1200,30,1,1,233.66,234.1,1,100,1,1,233.58,234.13,505,400,2,1,233.53,234.17,10,1,1,1,233.5,234.25,100,100,1,1,233.45,234.41,15,500,1,1,233.4,234.43,110,105,2,2,233.39,234.5,10,63,1,4,AAPL,0.0,0.0,-30.0,-100.0,-400.0,-1.0,-100.0,-500.0,-105.0,-63.0,-1.0,-180.08713081290753,
2024-10-21T12:22:20.146400458Z,2024-10-21T12:22:20.146234448Z,10,2,38,C,A,2,234.04,30,130,166010,12888412,233.8,234.0,5,50,1,1,233.73,234.03,229,200,2,1,233.7,234.1,1200,100,1,1,233.66,234.13,1,400,1,1,233.58,234.17,505,1,2,1,233.53,234.25,10,100,1,1,233.5,234.41,100,500,1,1,233.45,234.43,15,105,1,2,233.4,234.5,110,63,2,4,233.39,234.75,10,1,1,1,AAPL,0.0,0.0,0.0,100.0,400.0,1.0,100.0,500.0,105.0,63.0,1.0,178.18464592804142,
2024-10-21T12:22:20.260912200Z,2024-10-21T12:22:20.260745295Z,10,2,38,A,A,1,234.02,200,130,166905,12888534,233.8,234.0,5,50,1,1,233.73,234.02,229,200,2,1,233.7,234.1,1200,100,1,1,233.66,234.13,1,400,1,1,233.58,234.17,505,1,2,1,233.53,234.25,10,100,1,1,233.5,234.41,100,500,1,1,233.45,234.43,15,105,1,2,233.4,234.5,110,63,2,4,233.39,234.75,10,1,1,1,AAPL,0.0,0.0,-200.0,0.0,0.0,0.0,0.0,0.0,0.0,0.0,0.0,-12.683232565773917,
2024-10-21T12:22:20.322389944Z,2024-10-21T12:22:20.322223273Z,10,2,38,A,A,1,234.02,200,130,166671,12888684,233.8,234.0,5,50,1,1,233.73,234.02,229,400,2,2,233.7,234.1,1200,100,1,1,233.66,234.13,1,400,1,1,233.58,234.17,505,1,2,1,233.53,234.25,10,100,1,1,233.5,234.41,100,500,1,1,233.45,234.43,15,105,1,2,233.4,234.5,110,63,2,4,233.39,234.75,10,1,1,1,AAPL,0.0,0.0,-200.0,0.0,0.0,0.0,0.0,0.0,0.0,0.0,0.0,-12.683232565773917,
2024-10-21T12:22:21.536173766Z,2024-10-21T12:22:21.536007375Z,10,2,38,A,A,2,234.04,26,130,166391,12890037,233.8,234.0,5,50,1,1,233.73,234.02,229,400,2,2,233.7,234.04,1200,26,1,1,233.66,234.1,1,100,1,1,233.58,234.13,505,400,2,1,233.53,234.17,10,1,1,1,233.5,234.25,100,100,1,1,233.45,234.41,15,500,1,1,233.4,234.43,110,105,2,2,233.39,234.5,10,63,1,4,AAPL,0.0,0.0,0.0,-100.0,-400.0,-1.0,-100.0,-500.0,-105.0,-63.0,-1.0,-178.18464592804142,
2024-10-21T12:22:21.539463374Z,2024-10-21T12:22:21.539297131Z,10,2,38,C,A,2,234.04,26,130,166243,12890041,233.8,234.0,5,50,1,1,233.73,234.02,229,400,2,2,233.7,234.1,1200,100,1,1,233.66,234.13,1,400,1,1,233.58,234.17,505,1,2,1,233.53,234.25,10,100,1,1,233.5,234.41,100,500,1,1,233.45,234.43,15,105,1,2,233.4,234.5,110,63,2,4,233.39,234.75,10,1,1,1,AAPL,0.0,0.0,0.0,100.0,400.0,1.0,100.0,500.0,105.0,63.0,1.0,178.18464592804142,
2024-10-21T12:22:21.583448421Z,2024-10-21T12:22:21.583281944Z,10,2,38,A,B,1,233.74,200,130,166477,12890469,233.8,234.0,5,50,1,1,233.74,234.02,200,400,1,2,233.73,234.1,29,100,1,1,233.7,234.13,1200,400,1,1,233.66,234.17,1,1,1,1,233.58,234.25,505,100,2,1,233.53,234.41,10,500,1,1,233.5,234.43,100,105,1,2,233.45,234.5,15,63,1,4,233.4,234.75,110,1,2,1,AAPL,0.0,0.0,200.0,29.0,1200.0,1.0,505.0,10.0,100.0,15.0,110.0,351.5266413519603,
2024-10-21T12:22:22.095429909Z,2024-10-21T12:22:22.095263170Z,10,2,38,A,A,2,234.09,27,130,166739,12891303,233.8,234.0,5,50,1,1,233.74,234.02,200,400,1,2,233.73,234.09,29,27,1,1,233.7,234.1,1200,100,1,1,233.66,234.13,1,400,1,1,233.58,234.17,505,1,2,1,233.53,234.25,10,100,1,1,233.5,234.41,100,500,1,1,233.45,234.43,15,105,1,2,233.4,234.5,110,63,2,4,AAPL,0.0,0.0,0.0,-100.0,-400.0,-1.0,-100.0,-500.0,-105.0,-63.0,-1.0,-178.18464592804142,
2024-10-21T12:22:22.945563810Z,2024-10-21T12:22:22.945397458Z,10,2,38,C,A,1,234.02,200,130,166352,12893143,233.8,234.0,5,50,1,1,233.74,234.02,200,200,1,1,233.73,234.09,29,27,1,1,233.7,234.1,1200,100,1,1,233.66,234.13,1,400,1,1,233.58,234.17,505,1,2,1,233.53,234.25,10,100,1,1,233.5,234.41,100,500,1,1,233.45,234.43,15,105,1,2,233.4,234.5,110,63,2,4,AAPL,0.0,0.0,200.0,0.0,0.0,0.0,0.0,0.0,0.0,0.0,0.0,12.683232565773917,
2024-10-21T12:22:22.945572707Z,2024-10-21T12:22:22.945406901Z,10,2,38,C,A,1,234.02,200,130,165806,12893145,233.8,234.0,5,50,1,1,233.74,234.09,200,27,1,1,233.73,234.1,29,100,1,1,233.7,234.13,1200,400,1,1,233.66,234.17,1,1,1,1,233.58,234.25,505,100,2,1,233.53,234.41,10,500,1,1,233.5,234.43,100,105,1,2,233.45,234.5,15,63,1,4,233.4,234.75,110,1,2,1,AAPL,0.0,0.0,27.0,100.0,400.0,1.0,100.0,500.0,105.0,63.0,1.0,179.89688232442091,
2024-10-21T12:22:22.945862943Z,2024-10-21T12:22:22.945697032Z,10,2,38,A,A,1,234.03,200,130,165911,12893175,233.8,234.0,5,50,1,1,233.74,234.03,200,200,1,1,233.73,234.09,29,27,1,1,233.7,234.1,1200,100,1,1,233.66,234.13,1,400,1,1,233.58,234.17,505,1,2,1,233.53,234.25,10,100,1,1,233.5,234.41,100,500,1,1,233.45,234.43,15,105,1,2,233.4,234.5,110,63,2,4,AAPL,0.0,0.0,-27.0,-100.0,-400.0,-1.0,-100.0,-500.0,-105.0,-63.0,-1.0,-179.89688232442091,
2024-10-21T12:22:22.986462573Z,2024-10-21T12:22:22.986296201Z,10,2,38,A,A,1,234.03,200,130,166372,12894197,233.8,234.0,5,50,1,1,233.74,234.03,200,400,1,2,233.73,234.09,29,27,1,1,233.7,234.1,1200,100,1,1,233.66,234.13,1,400,1,1,233.58,234.17,505,1,2,1,233.53,234.25,10,100,1,1,233.5,234.41,100,500,1,1,233.45,234.43,15,105,1,2,233.4,234.5,110,63,2,4,AAPL,0.0,0.0,-200.0,0.0,0.0,0.0,0.0,0.0,0.0,0.0,0.0,-12.683232565773917,
2024-10-21T12:22:23.024730389Z,2024-10-21T12:22:23.024563308Z,10,2,38,C,A,1,234.03,200,128,167081,12894812,233.8,234.0,5,50,1,1,233.74,234.03,200,200,1,1,233.73,234.09,29,27,1,1,233.7,234.1,1200,100,1,1,233.66,234.13,1,400,1,1,233.58,234.17,505,1,2,1,233.53,234.25,10,100,1,1,233.5,234.41,100,500,1,1,233.45,234.43,15,105,1,2,233.4,234.5,110,63,2,4,AAPL,0.0,0.0,200.0,0.0,0.0,0.0,0.0,0.0,0.0,0.0,0.0,12.683232565773917,
2024-10-21T12:22:23.029069095Z,2024-10-21T12:22:23.028903196Z,10,2,38,C,A,1,234.03,200,130,165899,12894909,233.8,234.0,5,50,1,1,233.74,234.09,200,27,1,1,233.73,234.1,29,100,1,1,233.7,234.13,1200,400,1,1,233.66,234.17,1,1,1,1,233.58,234.25,505,100,2,1,233.53,234.41,10,500,1,1,233.5,234.43,100,105,1,2,233.45,234.5,15,63,1,4,233.4,234.75,110,1,2,1,AAPL,0.0,0.0,27.0,100.0,400.0,1.0,100.0,500.0,105.0,63.0,1.0,179.89688232442091,
2024-10-21T12:22:23.029082382Z,2024-10-21T12:22:23.028915916Z,10,2,38,A,A,1,234.08,200,130,166466,12894910,233.8,234.0,5,50,1,1,233.74,234.08,200,200,1,1,233.73,234.09,29,27,1,1,233.7,234.1,1200,100,1,1,233.66,234.13,1,400,1,1,233.58,234.17,505,1,2,1,233.53,234.25,10,100,1,1,233.5,234.41,100,500,1,1,233.45,234.43,15,105,1,2,233.4,234.5,110,63,2,4,AAPL,0.0,0.0,-27.0,-100.0,-400.0,-1.0,-100.0,-500.0,-105.0,-63.0,-1.0,-179.89688232442091,
2024-10-21T12:22:23.079970068Z,2024-10-21T12:22:23.079803882Z,10,2,38,A,B,0,233.88,3,130,166186,12895304,233.88,234.0,3,50,1,1,233.8,234.08,5,200,1,1,233.74,234.09,200,27,1,1,233.73,234.1,29,100,1,1,233.7,234.13,1200,400,1,1,233.66,234.17,1,1,1,1,233.58,234.25,505,100,2,1,233.53,234.41,10,500,1,1,233.5,234.43,100,105,1,2,233.45,234.5,15,63,1,4,AAPL,3.0,3.0,5.0,200.0,29.0,1200.0,1.0,505.0,10.0,100.0,15.0,233.02897397982937,
2024-10-21T12:22:23.080018858Z,2024-10-21T12:22:23.079851405Z,10,2,38,T,N,0,233.92,17,130,167453,12895307,233.88,234.0,3,50,1,1,233.8,234.08,5,200,1,1,233.74,234.09,200,27,1,1,233.73,234.1,29,100,1,1,233.7,234.13,1200,400,1,1,233.66,234.17,1,1,1,1,233.58,234.25,505,100,2,1,233.53,234.41,10,500,1,1,233.5,234.43,100,105,1,2,233.45,234.5,15,63,1,4,AAPL,0.0,0.0,0.0,0.0,0.0,0.0,0.0,0.0,0.0,0.0,0.0,0.0,
2024-10-21T12:22:23.080043588Z,2024-10-21T12:22:23.079869699Z,10,2,38,C,A,0,234.0,48,128,173889,12895313,233.88,234.0,3,2,1,1,233.8,234.08,5,200,1,1,233.74,234.09,200,27,1,1,233.73,234.1,29,100,1,1,233.7,234.13,1200,400,1,1,233.66,234.17,1,1,1,1,233.58,234.25,505,100,2,1,233.53,234.41,10,500,1,1,233.5,234.43,100,105,1,2,233.45,234.5,15,63,1,4,AAPL,48.0,48.0,0.0,0.0,0.0,0.0,0.0,0.0,0.0,0.0,0.0,0.9542679670140009,
2024-10-21T12:22:23.080043588Z,2024-10-21T12:22:23.079869699Z,10,2,38,T,B,0,234.0,48,128,173889,12895313,233.88,234.0,3,50,1,1,233.8,234.08,5,200,1,1,233.74,234.09,200,27,1,1,233.73,234.1,29,100,1,1,233.7,234.13,1200,400,1,1,233.66,234.17,1,1,1,1,233.58,234.25,505,100,2,1,233.53,234.41,10,500,1,1,233.5,234.43,100,105,1,2,233.45,234.5,15,63,1,4,AAPL,-48.0,-48.0,0.0,0.0,0.0,0.0,0.0,0.0,0.0,0.0,0.0,-0.9542679670140009,
2024-10-21T12:22:23.080043588Z,2024-10-21T12:22:23.079869699Z,10,2,38,T,N,0,233.98,21,0,173889,12895311,233.88,234.0,3,50,1,1,233.8,234.08,5,200,1,1,233.74,234.09,200,27,1,1,233.73,234.1,29,100,1,1,233.7,234.13,1200,400,1,1,233.66,234.17,1,1,1,1,233.58,234.25,505,100,2,1,233.53,234.41,10,500,1,1,233.5,234.43,100,105,1,2,233.45,234.5,15,63,1,4,AAPL,0.0,0.0,0.0,0.0,0.0,0.0,0.0,0.0,0.0,0.0,0.0,0.0,
2024-10-21T12:22:23.080043588Z,2024-10-21T12:22:23.079869699Z,10,2,38,T,N,0,233.98,13,0,173889,12895310,233.88,234.0,3,50,1,1,233.8,234.08,5,200,1,1,233.74,234.09,200,27,1,1,233.73,234.1,29,100,1,1,233.7,234.13,1200,400,1,1,233.66,234.17,1,1,1,1,233.58,234.25,505,100,2,1,233.53,234.41,10,500,1,1,233.5,234.43,100,105,1,2,233.45,234.5,15,63,1,4,AAPL,0.0,0.0,0.0,0.0,0.0,0.0,0.0,0.0,0.0,0.0,0.0,0.0,
2024-10-21T12:22:23.080043588Z,2024-10-21T12:22:23.079869699Z,10,2,38,T,N,0,233.98,18,0,173889,12895312,233.88,234.0,3,50,1,1,233.8,234.08,5,200,1,1,233.74,234.09,200,27,1,1,233.73,234.1,29,100,1,1,233.7,234.13,1200,400,1,1,233.66,234.17,1,1,1,1,233.58,234.25,505,100,2,1,233.53,234.41,10,500,1,1,233.5,234.43,100,105,1,2,233.45,234.5,15,63,1,4,AAPL,0.0,0.0,0.0,0.0,0.0,0.0,0.0,0.0,0.0,0.0,0.0,0.0,
2024-10-21T12:22:23.080121046Z,2024-10-21T12:22:23.079955251Z,10,2,38,C,A,1,234.08,200,130,165795,12895319,233.88,234.0,3,2,1,1,233.8,234.09,5,27,1,1,233.74,234.1,200,100,1,1,233.73,234.13,29,400,1,1,233.7,234.17,1200,1,1,1,233.66,234.25,1,100,1,1,233.58,234.41,505,500,2,1,233.53,234.43,10,105,1,2,233.5,234.5,100,63,1,4,233.45,234.75,15,1,1,1,AAPL,48.0,48.0,27.0,100.0,400.0,1.0,100.0,500.0,105.0,63.0,1.0,180.8511502914349,
2024-10-21T12:22:23.084076713Z,2024-10-21T12:22:23.083910618Z,10,2,38,C,B,0,233.88,3,130,166095,12895336,233.8,234.0,5,2,1,1,233.74,234.09,200,27,1,1,233.73,234.1,29,100,1,1,233.7,234.13,1200,400,1,1,233.66,234.17,1,1,1,1,233.58,234.25,505,100,2,1,233.53,234.41,10,500,1,1,233.5,234.43,100,105,1,2,233.45,234.5,15,63,1,4,233.4,234.75,110,1,2,1,AAPL,-3.0,-3.0,-5.0,-200.0,-29.0,-1200.0,-1.0,-505.0,-10.0,-100.0,-15.0,-233.02897397982937,
2024-10-21T12:22:23.088319645Z,2024-10-21T12:22:23.088151194Z,10,2,38,A,B,0,233.91,100,128,168451,12895372,233.91,234.0,100,2,1,1,233.8,234.09,5,27,1,1,233.74,234.1,200,100,1,1,233.73,234.13,29,400,1,1,233.7,234.17,1200,1,1,1,233.66,234.25,1,100,1,1,233.58,234.41,505,500,2,1,233.53,234.43,10,105,1,2,233.5,234.5,100,63,1,4,233.45,234.75,15,1,1,1,AAPL,100.0,100.0,5.0,200.0,29.0,1200.0,1.0,505.0,10.0,100.0,15.0,234.9573904965035,
2024-10-21T12:22:23.116317544Z,2024-10-21T12:22:23.116151189Z,10,2,38,A,A,1,234.08,200,130,166355,12895511,233.91,234.0,100,2,1,1,233.8,234.08,5,200,1,1,233.74,234.09,200,27,1,1,233.73,234.1,29,100,1,1,233.7,234.13,1200,400,1,1,233.66,234.17,1,1,1,1,233.58,234.25,505,100,2,1,233.53,234.41,10,500,1,1,233.5,234.43,100,105,1,2,233.45,234.5,15,63,1,4,AAPL,0.0,0.0,-27.0,-100.0,-400.0,-1.0,-100.0,-500.0,-105.0,-63.0,-1.0,-179.89688232442091,
2024-10-21T12:22:23.242021318Z,2024-10-21T12:22:23.241854315Z,10,2,38,A,A,1,234.07,200,130,167003,12895969,233.91,234.0,100,2,1,1,233.8,234.07,5,200,1,1,233.74,234.09,200,27,1,1,233.73,234.1,29,100,1,1,233.7,234.13,1200,400,1,1,233.66,234.17,1,1,1,1,233.58,234.25,505,100,2,1,233.53,234.41,10,500,1,1,233.5,234.43,100,105,1,2,233.45,234.5,15,63,1,4,AAPL,0.0,0.0,-200.0,0.0,0.0,0.0,0.0,0.0,0.0,0.0,0.0,-12.683232565773917,
2024-10-21T12:22:26.043193578Z,2024-10-21T12:22:26.043027067Z,10,2,38,A,A,1,234.07,200,130,166511,12901196,233.91,234.0,100,2,1,1,233.8,234.07,5,400,1,2,233.74,234.09,200,27,1,1,233.73,234.1,29,100,1,1,233.7,234.13,1200,400,1,1,233.66,234.17,1,1,1,1,233.58,234.25,505,100,2,1,233.53,234.41,10,500,1,1,233.5,234.43,100,105,1,2,233.45,234.5,15,63,1,4,AAPL,0.0,0.0,-200.0,0.0,0.0,0.0,0.0,0.0,0.0,0.0,0.0,-12.683232565773917,
2024-10-21T12:22:26.221605392Z,2024-10-21T12:22:26.221438925Z,10,2,38,A,B,2,233.78,200,130,166467,12901441,233.91,234.0,100,2,1,1,233.8,234.07,5,400,1,2,233.78,234.09,200,27,1,1,233.73,234.1,29,100,1,1,233.7,234.13,1200,400,1,1,233.66,234.17,1,1,1,1,233.58,234.25,505,100,2,1,233.53,234.41,10,500,1,1,233.5,234.43,100,105,1,2,233.45,234.5,15,63,1,4,AAPL,0.0,0.0,0.0,200.0,0.0,0.0,0.0,0.0,0.0,0.0,0.0,20.31651614720104,
2024-10-21T12:22:29.394326484Z,2024-10-21T12:22:29.394160247Z,10,2,38,A,B,2,233.79,200,130,166237,12905660,233.91,234.0,100,2,1,1,233.8,234.07,5,400,1,2,233.79,234.09,200,27,1,1,233.73,234.1,29,100,1,1,233.7,234.13,1200,400,1,1,233.66,234.17,1,1,1,1,233.58,234.25,505,100,2,1,233.53,234.41,10,500,1,1,233.5,234.43,100,105,1,2,233.45,234.5,15,63,1,4,AAPL,0.0,0.0,0.0,200.0,0.0,0.0,0.0,0.0,0.0,0.0,0.0,20.31651614720104,
2024-10-21T12:22:36.707629405Z,2024-10-21T12:22:36.707463498Z,10,2,38,C,A,2,234.09,27,130,165907,12912830,233.91,234.0,100,2,1,1,233.8,234.07,5,400,1,2,233.79,234.1,200,100,1,1,233.73,234.13,29,400,1,1,233.7,234.17,1200,1,1,1,233.66,234.25,1,100,1,1,233.58,234.41,505,500,2,1,233.53,234.43,10,105,1,2,233.5,234.5,100,63,1,4,233.45,234.75,15,1,1,1,AAPL,0.0,0.0,0.0,100.0,400.0,1.0,100.0,500.0,105.0,63.0,1.0,178.18464592804142,
2024-10-21T12:22:36.707672458Z,2024-10-21T12:22:36.707506060Z,10,2,38,A,A,2,234.08,26,130,166398,12912831,233.91,234.0,100,2,1,1,233.8,234.07,5,400,1,2,233.79,234.08,200,26,1,1,233.73,234.1,29,100,1,1,233.7,234.13,1200,400,1,1,233.66,234.17,1,1,1,1,233.58,234.25,505,100,2,1,233.53,234.41,10,500,1,1,233.5,234.43,100,105,1,2,233.45,234.5,15,63,1,4,AAPL,0.0,0.0,0.0,-100.0,-400.0,-1.0,-100.0,-500.0,-105.0,-63.0,-1.0,-178.18464592804142,
2024-10-21T12:22:40.428593628Z,2024-10-21T12:22:40.428425309Z,10,2,38,T,N,0,233.92,100,0,168319,12916971,233.91,234.0,100,2,1,1,233.8,234.07,5,400,1,2,233.79,234.08,200,26,1,1,233.73,234.1,29,100,1,1,233.7,234.13,1200,400,1,1,233.66,234.17,1,1,1,1,233.58,234.25,505,100,2,1,233.53,234.41,10,500,1,1,233.5,234.43,100,105,1,2,233.45,234.5,15,63,1,4,AAPL,0.0,0.0,0.0,0.0,0.0,0.0,0.0,0.0,0.0,0.0,0.0,0.0,
2024-10-21T12:22:40.428593628Z,2024-10-21T12:22:40.428425309Z,10,2,38,T,N,0,233.92,40,130,168319,12916972,233.91,234.0,100,2,1,1,233.8,234.07,5,400,1,2,233.79,234.08,200,26,1,1,233.73,234.1,29,100,1,1,233.7,234.13,1200,400,1,1,233.66,234.17,1,1,1,1,233.58,234.25,505,100,2,1,233.53,234.41,10,500,1,1,233.5,234.43,100,105,1,2,233.45,234.5,15,63,1,4,AAPL,0.0,0.0,0.0,0.0,0.0,0.0,0.0,0.0,0.0,0.0,0.0,0.0,
2024-10-21T12:23:09.008779869Z,2024-10-21T12:23:09.008613373Z,10,2,38,A,B,0,233.93,4,130,166496,12947436,233.93,234.0,4,2,1,1,233.91,234.07,100,400,1,2,233.8,234.08,5,26,1,1,233.79,234.1,200,100,1,1,233.73,234.13,29,400,1,1,233.7,234.17,1200,1,1,1,233.66,234.25,1,100,1,1,233.58,234.41,505,500,2,1,233.53,234.43,10,105,1,2,233.5,234.5,100,63,1,4,AAPL,4.0,4.0,100.0,5.0,200.0,29.0,1200.0,1.0,505.0,10.0,100.0,275.7764596438707,
2024-10-21T12:23:09.008787962Z,2024-10-21T12:23:09.008621599Z,10,2,38,A,B,1,233.92,100,130,166363,12947438,233.93,234.0,4,2,1,1,233.92,234.07,100,400,1,2,233.91,234.08,100,26,1,1,233.8,234.1,5,100,1,1,233.79,234.13,200,400,1,1,233.73,234.17,29,1,1,1,233.7,234.25,1200,100,1,1,233.66,234.41,1,500,1,1,233.58,234.43,505,105,2,2,233.53,234.5,10,63,1,4,AAPL,0.0,0.0,100.0,100.0,5.0,200.0,29.0,1200.0,1.0,505.0,10.0,217.4196230356186,
2024-10-21T12:23:09.009139279Z,2024-10-21T12:23:09.008973422Z,10,2,38,C,B,1,233.92,100,130,165857,12947440,233.93,234.0,4,2,1,1,233.91,234.07,100,400,1,2,233.8,234.08,5,26,1,1,233.79,234.1,200,100,1,1,233.73,234.13,29,400,1,1,233.7,234.17,1200,1,1,1,233.66,234.25,1,100,1,1,233.58,234.41,505,500,2,1,233.53,234.43,10,105,1,2,233.5,234.5,100,63,1,4,AAPL,0.0,0.0,-100.0,-100.0,-5.0,-200.0,-29.0,-1200.0,-1.0,-505.0,-10.0,-217.4196230356186,
2024-10-21T12:23:09.009232105Z,2024-10-21T12:23:09.009065871Z,10,2,38,A,B,0,233.95,723,130,166234,12947441,233.95,234.0,723,2,1,1,233.93,234.07,4,400,1,2,233.91,234.08,100,26,1,1,233.8,234.1,5,100,1,1,233.79,234.13,200,400,1,1,233.73,234.17,29,1,1,1,233.7,234.25,1200,100,1,1,233.66,234.41,1,500,1,1,233.58,234.43,505,105,2,2,233.53,234.5,10,63,1,4,AAPL,723.0,723.0,4.0,100.0,5.0,200.0,29.0,1200.0,1.0,505.0,10.0,225.7053326571955,
2024-10-21T12:23:09.047215822Z,2024-10-21T12:23:09.047049975Z,10,2,38,C,B,1,233.93,4,130,165847,12947464,233.95,234.0,723,2,1,1,233.91,234.07,100,400,1,2,233.8,234.08,5,26,1,1,233.79,234.1,200,100,1,1,233.73,234.13,29,400,1,1,233.7,234.17,1200,1,1,1,233.66,234.25,1,100,1,1,233.58,234.41,505,500,2,1,233.53,234.43,10,105,1,2,233.5,234.5,100,63,1,4,AAPL,0.0,0.0,-4.0,-100.0,-5.0,-200.0,-29.0,-1200.0,-1.0,-505.0,-10.0,-211.3316714040471,
2024-10-21T12:23:09.047694600Z,2024-10-21T12:23:09.047528450Z,10,2,38,C,B,1,233.91,100,130,166150,12947466,233.95,234.0,723,2,1,1,233.8,234.07,5,400,1,2,233.79,234.08,200,26,1,1,233.73,234.1,29,100,1,1,233.7,234.13,1200,400,1,1,233.66,234.17,1,1,1,1,233.58,234.25,505,100,2,1,233.53,234.41,10,500,1,1,233.5,234.43,100,105,1,2,233.45,234.5,15,63,1,4,AAPL,0.0,0.0,-100.0,-5.0,-200.0,-29.0,-1200.0,-1.0,-505.0,-10.0,-100.0,-275.6969373132862,
2024-10-21T12:23:09.079945758Z,2024-10-21T12:23:09.079779485Z,10,2,38,C,A,1,234.07,200,130,166273,12947479,233.95,234.0,723,2,1,1,233.8,234.07,5,200,1,1,233.79,234.08,200,26,1,1,233.73,234.1,29,100,1,1,233.7,234.13,1200,400,1,1,233.66,234.17,1,1,1,1,233.58,234.25,505,100,2,1,233.53,234.41,10,500,1,1,233.5,234.43,100,105,1,2,233.45,234.5,15,63,1,4,AAPL,0.0,0.0,200.0,0.0,0.0,0.0,0.0,0.0,0.0,0.0,0.0,12.683232565773917,
2024-10-21T12:23:09.081865026Z,2024-10-21T12:23:09.081699019Z,10,2,38,A,B,2,233.79,200,130,166007,12947480,233.95,234.0,723,2,1,1,233.8,234.07,5,200,1,1,233.79,234.08,400,26,2,1,233.73,234.1,29,100,1,1,233.7,234.13,1200,400,1,1,233.66,234.17,1,1,1,1,233.58,234.25,505,100,2,1,233.53,234.41,10,500,1,1,233.5,234.43,100,105,1,2,233.45,234.5,15,63,1,4,AAPL,0.0,0.0,0.0,200.0,0.0,0.0,0.0,0.0,0.0,0.0,0.0,20.31651614720104,
2024-10-21T12:23:09.087941406Z,2024-10-21T12:23:09.087775155Z,10,2,38,C,B,2,233.79,200,130,166251,12947484,233.95,234.0,723,2,1,1,233.8,234.07,5,200,1,1,233.79,234.08,200,26,1,1,233.73,234.1,29,100,1,1,233.7,234.13,1200,400,1,1,233.66,234.17,1,1,1,1,233.58,234.25,505,100,2,1,233.53,234.41,10,500,1,1,233.5,234.43,100,105,1,2,233.45,234.5,15,63,1,4,AAPL,0.0,0.0,0.0,-200.0,0.0,0.0,0.0,0.0,0.0,0.0,0.0,-20.31651614720104,
2024-10-21T12:23:09.087951571Z,2024-10-21T12:23:09.087785825Z,10,2,38,C,B,2,233.79,200,130,165746,12947485,233.95,234.0,723,2,1,1,233.8,234.07,5,200,1,1,233.73,234.08,29,26,1,1,233.7,234.1,1200,100,1,1,233.66,234.13,1,400,1,1,233.58,234.17,505,1,2,1,233.53,234.25,10,100,1,1,233.5,234.41,100,500,1,1,233.45,234.43,15,105,1,2,233.4,234.5,110,63,2,4,AAPL,0.0,0.0,0.0,-200.0,-29.0,-1200.0,-1.0,-505.0,-10.0,-100.0,-15.0,-232.65225141774664,
2024-10-21T12:23:09.087963244Z,2024-10-21T12:23:09.087797026Z,10,2,38,A,B,2,233.78,200,130,166218,12947486,233.95,234.0,723,2,1,1,233.8,234.07,5,200,1,1,233.78,234.08,200,26,1,1,233.73,234.1,29,100,1,1,233.7,234.13,1200,400,1,1,233.66,234.17,1,1,1,1,233.58,234.25,505,100,2,1,233.53,234.41,10,500,1,1,233.5,234.43,100,105,1,2,233.45,234.5,15,63,1,4,AAPL,0.0,0.0,0.0,200.0,29.0,1200.0,1.0,505.0,10.0,100.0,15.0,232.65225141774664,
2024-10-21T12:23:09.133495750Z,2024-10-21T12:23:09.133329159Z,10,2,38,A,B,2,233.79,200,130,166591,12947507,233.95,234.0,723,2,1,1,233.8,234.07,5,200,1,1,233.79,234.08,200,26,1,1,233.73,234.1,29,100,1,1,233.7,234.13,1200,400,1,1,233.66,234.17,1,1,1,1,233.58,234.25,505,100,2,1,233.53,234.41,10,500,1,1,233.5,234.43,100,105,1,2,233.45,234.5,15,63,1,4,AAPL,0.0,0.0,0.0,200.0,0.0,0.0,0.0,0.0,0.0,0.0,0.0,20.31651614720104,
2024-10-21T12:23:09.155801329Z,2024-10-21T12:23:09.155634175Z,10,2,38,C,B,3,233.73,29,130,167154,12947520,233.95,234.0,723,2,1,1,233.8,234.07,5,200,1,1,233.79,234.08,200,26,1,1,233.7,234.1,1200,100,1,1,233.66,234.13,1,400,1,1,233.58,234.17,505,1,2,1,233.53,234.25,10,100,1,1,233.5,234.41,100,500,1,1,233.45,234.43,15,105,1,2,233.4,234.5,110,63,2,4,AAPL,0.0,0.0,0.0,0.0,-29.0,-1200.0,-1.0,-505.0,-10.0,-100.0,-15.0,-212.3357352705456,
2024-10-21T12:23:09.155898909Z,2024-10-21T12:23:09.155732424Z,10,2,38,A,B,3,233.77,26,130,166485,12947521,233.95,234.0,723,2,1,1,233.8,234.07,5,200,1,1,233.79,234.08,200,26,1,1,233.77,234.1,26,100,1,1,233.7,234.13,1200,400,1,1,233.66,234.17,1,1,1,1,233.58,234.25,505,100,2,1,233.53,234.41,10,500,1,1,233.5,234.43,100,105,1,2,233.45,234.5,15,63,1,4,AAPL,0.0,0.0,0.0,0.0,26.0,1200.0,1.0,505.0,10.0,100.0,15.0,211.72050410547325,
2024-10-21T12:23:09.242988929Z,2024-10-21T12:23:09.242822823Z,10,2,38,C,A,2,234.08,26,130,166106,12947586,233.95,234.0,723,2,1,1,233.8,234.07,5,200,1,1,233.79,234.1,200,100,1,1,233.77,234.13,26,400,1,1,233.7,234.17,1200,1,1,1,233.66,234.25,1,100,1,1,233.58,234.41,505,500,2,1,233.53,234.43,10,105,1,2,233.5,234.5,100,63,1,4,233.45,234.75,15,1,1,1,AAPL,0.0,0.0,0.0,100.0,400.0,1.0,100.0,500.0,105.0,63.0,1.0,178.18464592804142,
2024-10-21T12:23:09.243042523Z,2024-10-21T12:23:09.242876186Z,10,2,38,A,A,4,234.14,29,130,166337,12947587,233.95,234.0,723,2,1,1,233.8,234.07,5,200,1,1,233.79,234.1,200,100,1,1,233.77,234.13,26,400,1,1,233.7,234.14,1200,29,1,1,233.66,234.17,1,1,1,1,233.58,234.25,505,100,2,1,233.53,234.41,10,500,1,1,233.5,234.43,100,105,1,2,233.45,234.5,15,63,1,4,AAPL,0.0,0.0,0.0,0.0,0.0,-1.0,-100.0,-500.0,-105.0,-63.0,-1.0,-85.99556584479349,
2024-10-21T12:23:09.312801998Z,2024-10-21T12:23:09.312635376Z,10,2,38,A,B,1,233.81,200,130,166622,12947706,233.95,234.0,723,2,1,1,233.81,234.07,200,200,1,1,233.8,234.1,5,100,1,1,233.77,234.13,26,400,1,1,233.7,234.14,1200,29,1,1,233.66,234.17,1,1,1,1,233.58,234.25,505,100,2,1,233.53,234.41,10,500,1,1,233.5,234.43,100,105,1,2,233.45,234.5,15,63,1,4,AAPL,0.0,0.0,200.0,5.0,0.0,0.0,0.0,0.0,0.0,0.0,0.0,13.191145469453943,
2024-10-21T12:23:09.319634626Z,2024-10-21T12:23:09.319468618Z,10,2,38,A,A,1,234.07,200,130,166008,12947710,233.95,234.0,723,2,1,1,233.81,234.07,200,400,1,2,233.8,234.1,5,100,1,1,233.77,234.13,26,400,1,1,233.7,234.14,1200,29,1,1,233.66,234.17,1,1,1,1,233.58,234.25,505,100,2,1,233.53,234.41,10,500,1,1,233.5,234.43,100,105,1,2,233.45,234.5,15,63,1,4,AAPL,0.0,0.0,-200.0,0.0,0.0,0.0,0.0,0.0,0.0,0.0,0.0,-12.683232565773917,
2024-10-21T12:23:09.729631282Z,2024-10-21T12:23:09.729465211Z,10,2,38,C,A,1,234.07,200,130,166071,12947991,233.95,234.0,723,2,1,1,233.81,234.07,200,200,1,1,233.8,234.1,5,100,1,1,233.77,234.13,26,400,1,1,233.7,234.14,1200,29,1,1,233.66,234.17,1,1,1,1,233.58,234.25,505,100,2,1,233.53,234.41,10,500,1,1,233.5,234.43,100,105,1,2,233.45,234.5,15,63,1,4,AAPL,0.0,0.0,200.0,0.0,0.0,0.0,0.0,0.0,0.0,0.0,0.0,12.683232565773917,
2024-10-21T12:23:09.784241575Z,2024-10-21T12:23:09.784075201Z,10,2,38,A,B,1,233.82,200,130,166374,12948038,233.95,234.0,723,2,1,1,233.82,234.07,200,200,1,1,233.8,234.1,5,100,1,1,233.77,234.13,26,400,1,1,233.7,234.14,1200,29,1,1,233.66,234.17,1,1,1,1,233.58,234.25,505,100,2,1,233.53,234.41,10,500,1,1,233.5,234.43,100,105,1,2,233.45,234.5,15,63,1,4,AAPL,0.0,0.0,200.0,0.0,0.0,0.0,0.0,0.0,0.0,0.0,0.0,12.683232565773917,
2024-10-21T12:23:11.099239175Z,2024-10-21T12:23:11.099071185Z,10,2,38,T,A,0,233.95,200,130,167990,12949099,233.95,234.0,723,2,1,1,233.82,234.07,200,200,1,1,233.8,234.1,5,100,1,1,233.77,234.13,26,400,1,1,233.7,234.14,1200,29,1,1,233.66,234.17,1,1,1,1,233.58,234.25,505,100,2,1,233.53,234.41,10,500,1,1,233.5,234.43,100,105,1,2,233.45,234.5,15,63,1,4,AAPL,0.0,0.0,0.0,0.0,0.0,0.0,0.0,0.0,0.0,0.0,0.0,0.0,
2024-10-21T12:23:11.099239175Z,2024-10-21T12:23:11.099071185Z,10,2,38,C,B,0,233.95,200,130,167990,12949099,233.95,234.0,523,2,1,1,233.82,234.07,200,200,1,1,233.8,234.1,5,100,1,1,233.77,234.13,26,400,1,1,233.7,234.14,1200,29,1,1,233.66,234.17,1,1,1,1,233.58,234.25,505,100,2,1,233.53,234.41,10,500,1,1,233.5,234.43,100,105,1,2,233.45,234.5,15,63,1,4,AAPL,-200.0,-200.0,0.0,0.0,0.0,0.0,0.0,0.0,0.0,0.0,0.0,-3.9761165292250036,
2024-10-21T12:23:11.099304941Z,2024-10-21T12:23:11.099138993Z,10,2,38,C,B,1,233.82,200,130,165948,12949100,233.95,234.0,523,2,1,1,233.8,234.07,5,200,1,1,233.77,234.1,26,100,1,1,233.7,234.13,1200,400,1,1,233.66,234.14,1,29,1,1,233.58,234.17,505,1,2,1,233.53,234.25,10,100,1,1,233.5,234.41,100,500,1,1,233.45,234.43,15,105,1,2,233.4,234.5,110,63,2,4,AAPL,0.0,0.0,-200.0,-5.0,-26.0,-1200.0,-1.0,-505.0,-10.0,-100.0,-15.0,-224.9116495749272,
2024-10-21T12:23:11.172041039Z,2024-10-21T12:23:11.171874633Z,10,2,38,A,A,1,234.07,200,130,166406,12949158,233.95,234.0,523,2,1,1,233.8,234.07,5,400,1,2,233.77,234.1,26,100,1,1,233.7,234.13,1200,400,1,1,233.66,234.14,1,29,1,1,233.58,234.17,505,1,2,1,233.53,234.25,10,100,1,1,233.5,234.41,100,500,1,1,233.45,234.43,15,105,1,2,233.4,234.5,110,63,2,4,AAPL,0.0,0.0,-200.0,0.0,0.0,0.0,0.0,0.0,0.0,0.0,0.0,-12.683232565773917,
2024-10-21T12:23:11.208329414Z,2024-10-21T12:23:11.208162821Z,10,2,38,A,B,1,233.82,200,130,166593,12949167,233.95,234.0,523,2,1,1,233.82,234.07,200,400,1,2,233.8,234.1,5,100,1,1,233.77,234.13,26,400,1,1,233.7,234.14,1200,29,1,1,233.66,234.17,1,1,1,1,233.58,234.25,505,100,2,1,233.53,234.41,10,500,1,1,233.5,234.43,100,105,1,2,233.45,234.5,15,63,1,4,AAPL,0.0,0.0,200.0,5.0,26.0,1200.0,1.0,505.0,10.0,100.0,15.0,224.9116495749272,
2024-10-21T12:23:12.139769418Z,2024-10-21T12:23:12.139603042Z,10,2,38,A,B,1,233.84,200,130,166376,12950444,233.95,234.0,523,2,1,1,233.84,234.07,200,400,1,2,233.8,234.1,5,100,1,1,233.77,234.13,26,400,1,1,233.7,234.14,1200,29,1,1,233.66,234.17,1,1,1,1,233.58,234.25,505,100,2,1,233.53,234.41,10,500,1,1,233.5,234.43,100,105,1,2,233.45,234.5,15,63,1,4,AAPL,0.0,0.0,200.0,0.0,0.0,0.0,0.0,0.0,0.0,0.0,0.0,12.683232565773917,
2024-10-21T12:23:12.190290255Z,2024-10-21T12:23:12.190123660Z,10,2,38,C,A,4,234.14,29,130,166595,12950624,233.95,234.0,523,2,1,1,233.84,234.07,200,400,1,2,233.8,234.1,5,100,1,1,233.77,234.13,26,400,1,1,233.7,234.17,1200,1,1,1,233.66,234.25,1,100,1,1,233.58,234.41,505,500,2,1,233.53,234.43,10,105,1,2,233.5,234.5,100,63,1,4,233.45,234.75,15,1,1,1,AAPL,0.0,0.0,0.0,0.0,0.0,1.0,100.0,500.0,105.0,63.0,1.0,85.99556584479349,
2024-10-21T12:23:12.190410859Z,2024-10-21T12:23:12.190244811Z,10,2,38,A,A,2,234.09,28,130,166048,12950625,233.95,234.0,523,2,1,1,233.84,234.07,200,400,1,2,233.8,234.09,5,28,1,1,233.77,234.1,26,100,1,1,233.7,234.13,1200,400,1,1,233.66,234.17,1,1,1,1,233.58,234.25,505,100,2,1,233.53,234.41,10,500,1,1,233.5,234.43,100,105,1,2,233.45,234.5,15,63,1,4,AAPL,0.0,0.0,0.0,-100.0,-400.0,-1.0,-100.0,-500.0,-105.0,-63.0,-1.0,-178.18464592804142,
2024-10-21T12:23:12.195419708Z,2024-10-21T12:23:12.195254017Z,10,2,38,C,A,2,234.09,28,130,165691,12950641,233.95,234.0,523,2,1,1,233.84,234.07,200,400,1,2,233.8,234.1,5,100,1,1,233.77,234.13,26,400,1,1,233.7,234.17,1200,1,1,1,233.66,234.25,1,100,1,1,233.58,234.41,505,500,2,1,233.53,234.43,10,105,1,2,233.5,234.5,100,63,1,4,233.45,234.75,15,1,1,1,AAPL,0.0,0.0,0.0,100.0,400.0,1.0,100.0,500.0,105.0,63.0,1.0,178.18464592804142,
2024-10-21T12:23:13.923669862Z,2024-10-21T12:23:13.923503589Z,10,2,38,A,A,4,234.14,27,130,166273,12952557,233.95,234.0,523,2,1,1,233.84,234.07,200,400,1,2,233.8,234.1,5,100,1,1,233.77,234.13,26,400,1,1,233.7,234.14,1200,27,1,1,233.66,234.17,1,1,1,1,233.58,234.25,505,100,2,1,233.53,234.41,10,500,1,1,233.5,234.43,100,105,1,2,233.45,234.5,15,63,1,4,AAPL,0.0,0.0,0.0,0.0,0.0,-1.0,-100.0,-500.0,-105.0,-63.0,-1.0,-85.99556584479349,
2024-10-21T12:23:14.014291143Z,2024-10-21T12:23:14.014125157Z,10,2,38,C,B,1,233.84,200,130,165986,12953020,233.95,234.0,523,2,1,1,233.8,234.07,5,400,1,2,233.77,234.1,26,100,1,1,233.7,234.13,1200,400,1,1,233.66,234.14,1,27,1,1,233.58,234.17,505,1,2,1,233.53,234.25,10,100,1,1,233.5,234.41,100,500,1,1,233.45,234.43,15,105,1,2,233.4,234.5,110,63,2,4,AAPL,0.0,0.0,-200.0,-5.0,-26.0,-1200.0,-1.0,-505.0,-10.0,-100.0,-15.0,-224.9116495749272,
2024-10-21T12:23:14.014304377Z,2024-10-21T12:23:14.014138266Z,10,2,38,A,B,1,233.8,400,130,166111,12953021,233.95,234.0,523,2,1,1,233.8,234.07,405,400,2,2,233.77,234.1,26,100,1,1,233.7,234.13,1200,400,1,1,233.66,234.14,1,27,1,1,233.58,234.17,505,1,2,1,233.53,234.25,10,100,1,1,233.5,234.41,100,500,1,1,233.45,234.43,15,105,1,2,233.4,234.5,110,63,2,4,AAPL,0.0,0.0,400.0,0.0,0.0,0.0,0.0,0.0,0.0,0.0,0.0,25.366465131547834,
2024-10-21T12:23:24.180223668Z,2024-10-21T12:23:24.180057341Z,10,2,38,A,B,1,233.84,200,130,166327,12963680,233.95,234.0,523,2,1,1,233.84,234.07,200,400,1,2,233.8,234.1,5,100,1,1,233.77,234.13,26,400,1,1,233.7,234.14,1200,27,1,1,233.66,234.17,1,1,1,1,233.58,234.25,505,100,2,1,233.53,234.41,10,500,1,1,233.5,234.43,100,105,1,2,233.45,234.5,15,63,1,4,AAPL,0.0,0.0,200.0,5.0,26.0,1200.0,1.0,505.0,10.0,100.0,15.0,224.9116495749272,
2024-10-21T12:23:24.244554625Z,2024-10-21T12:23:24.244388472Z,10,2,38,C,B,3,233.77,26,130,166153,12963842,233.95,234.0,523,2,1,1,233.84,234.07,200,400,1,2,233.8,234.1,5,100,1,1,233.7,234.13,1200,400,1,1,233.66,234.14,1,27,1,1,233.58,234.17,505,1,2,1,233.53,234.25,10,100,1,1,233.5,234.41,100,500,1,1,233.45,234.43,15,105,1,2,233.4,234.5,110,63,2,4,AAPL,0.0,0.0,0.0,0.0,-26.0,-1200.0,-1.0,-505.0,-10.0,-100.0,-15.0,-211.72050410547325,
2024-10-21T12:23:24.244894113Z,2024-10-21T12:23:24.244727755Z,10,2,38,A,B,3,233.78,29,130,166358,12963846,233.95,234.0,523,2,1,1,233.84,234.07,200,400,1,2,233.8,234.1,5,100,1,1,233.78,234.13,29,400,1,1,233.7,234.14,1200,27,1,1,233.66,234.17,1,1,1,1,233.58,234.25,505,100,2,1,233.53,234.41,10,500,1,1,233.5,234.43,100,105,1,2,233.45,234.5,15,63,1,4,AAPL,0.0,0.0,0.0,0.0,29.0,1200.0,1.0,505.0,10.0,100.0,15.0,212.3357352705456,
2024-10-21T12:23:24.253991498Z,2024-10-21T12:23:24.253824768Z,10,2,38,A,B,1,233.85,200,130,166730,12963873,233.95,234.0,523,2,1,1,233.85,234.07,200,400,1,2,233.8,234.1,5,100,1,1,233.78,234.13,29,400,1,1,233.7,234.14,1200,27,1,1,233.66,234.17,1,1,1,1,233.58,234.25,505,100,2,1,233.53,234.41,10,500,1,1,233.5,234.43,100,105,1,2,233.45,234.5,15,63,1,4,AAPL,0.0,0.0,200.0,0.0,0.0,0.0,0.0,0.0,0.0,0.0,0.0,12.683232565773917,
2024-10-21T12:23:24.273314409Z,2024-10-21T12:23:24.273148439Z,10,2,38,C,A,4,234.14,27,130,165970,12963906,233.95,234.0,523,2,1,1,233.85,234.07,200,400,1,2,233.8,234.1,5,100,1,1,233.78,234.13,29,400,1,1,233.7,234.17,1200,1,1,1,233.66,234.25,1,100,1,1,233.58,234.41,505,500,2,1,233.53,234.43,10,105,1,2,233.5,234.5,100,63,1,4,233.45,234.75,15,1,1,1,AAPL,0.0,0.0,0.0,0.0,0.0,1.0,100.0,500.0,105.0,63.0,1.0,85.99556584479349,
2024-10-21T12:23:24.273365393Z,2024-10-21T12:23:24.273199301Z,10,2,38,A,A,2,234.09,30,130,166092,12963907,233.95,234.0,523,2,1,1,233.85,234.07,200,400,1,2,233.8,234.09,5,30,1,1,233.78,234.1,29,100,1,1,233.7,234.13,1200,400,1,1,233.66,234.17,1,1,1,1,233.58,234.25,505,100,2,1,233.53,234.41,10,500,1,1,233.5,234.43,100,105,1,2,233.45,234.5,15,63,1,4,AAPL,0.0,0.0,0.0,-100.0,-400.0,-1.0,-100.0,-500.0,-105.0,-63.0,-1.0,-178.18464592804142,
2024-10-21T12:23:24.281190133Z,2024-10-21T12:23:24.281024032Z,10,2,38,C,A,2,234.09,30,130,166101,12963913,233.95,234.0,523,2,1,1,233.85,234.07,200,400,1,2,233.8,234.1,5,100,1,1,233.78,234.13,29,400,1,1,233.7,234.17,1200,1,1,1,233.66,234.25,1,100,1,1,233.58,234.41,505,500,2,1,233.53,234.43,10,105,1,2,233.5,234.5,100,63,1,4,233.45,234.75,15,1,1,1,AAPL,0.0,0.0,0.0,100.0,400.0,1.0,100.0,500.0,105.0,63.0,1.0,178.18464592804142,
2024-10-21T12:23:25.923153392Z,2024-10-21T12:23:25.922987113Z,10,2,38,A,A,4,234.15,29,130,166279,12965330,233.95,234.0,523,2,1,1,233.85,234.07,200,400,1,2,233.8,234.1,5,100,1,1,233.78,234.13,29,400,1,1,233.7,234.15,1200,29,1,1,233.66,234.17,1,1,1,1,233.58,234.25,505,100,2,1,233.53,234.41,10,500,1,1,233.5,234.43,100,105,1,2,233.45,234.5,15,63,1,4,AAPL,0.0,0.0,0.0,0.0,0.0,-1.0,-100.0,-500.0,-105.0,-63.0,-1.0,-85.99556584479349,
2024-10-21T12:23:26.667650199Z,2024-10-21T12:23:26.667483730Z,10,2,38,C,A,4,234.15,29,130,166469,12965993,233.95,234.0,523,2,1,1,233.85,234.07,200,400,1,2,233.8,234.1,5,100,1,1,233.78,234.13,29,400,1,1,233.7,234.17,1200,1,1,1,233.66,234.25,1,100,1,1,233.58,234.41,505,500,2,1,233.53,234.43,10,105,1,2,233.5,234.5,100,63,1,4,233.45,234.75,15,1,1,1,AAPL,0.0,0.0,0.0,0.0,0.0,1.0,100.0,500.0,105.0,63.0,1.0,85.99556584479349,
2024-10-21T12:23:26.667733223Z,2024-10-21T12:23:26.667566801Z,10,2,38,A,A,2,234.09,26,130,166422,12965994,233.95,234.0,523,2,1,1,233.85,234.07,200,400,1,2,233.8,234.09,5,26,1,1,233.78,234.1,29,100,1,1,233.7,234.13,1200,400,1,1,233.66,234.17,1,1,1,1,233.58,234.25,505,100,2,1,233.53,234.41,10,500,1,1,233.5,234.43,100,105,1,2,233.45,234.5,15,63,1,4,AAPL,0.0,0.0,0.0,-100.0,-400.0,-1.0,-100.0,-500.0,-105.0,-63.0,-1.0,-178.18464592804142,
2024-10-21T12:23:26.671836031Z,2024-10-21T12:23:26.671669972Z,10,2,38,C,A,2,234.09,26,130,166059,12965998,233.95,234.0,523,2,1,1,233.85,234.07,200,400,1,2,233.8,234.1,5,100,1,1,233.78,234.13,29,400,1,1,233.7,234.17,1200,1,1,1,233.66,234.25,1,100,1,1,233.58,234.41,505,500,2,1,233.53,234.43,10,105,1,2,233.5,234.5,100,63,1,4,233.45,234.75,15,1,1,1,AAPL,0.0,0.0,0.0,100.0,400.0,1.0,100.0,500.0,105.0,63.0,1.0,178.18464592804142,
2024-10-21T12:23:29.923208530Z,2024-10-21T12:23:29.923042073Z,10,2,38,A,A,4,234.15,26,130,166457,12968315,233.95,234.0,523,2,1,1,233.85,234.07,200,400,1,2,233.8,234.1,5,100,1,1,233.78,234.13,29,400,1,1,233.7,234.15,1200,26,1,1,233.66,234.17,1,1,1,1,233.58,234.25,505,100,2,1,233.53,234.41,10,500,1,1,233.5,234.43,100,105,1,2,233.45,234.5,15,63,1,4,AAPL,0.0,0.0,0.0,0.0,0.0,-1.0,-100.0,-500.0,-105.0,-63.0,-1.0,-85.99556584479349,
2024-10-21T12:23:31.049437219Z,2024-10-21T12:23:31.049271170Z,10,2,38,C,B,1,233.85,200,130,166049,12969394,233.95,234.0,523,2,1,1,233.8,234.07,5,400,1,2,233.78,234.1,29,100,1,1,233.7,234.13,1200,400,1,1,233.66,234.15,1,26,1,1,233.58,234.17,505,1,2,1,233.53,234.25,10,100,1,1,233.5,234.41,100,500,1,1,233.45,234.43,15,105,1,2,233.4,234.5,110,63,2,4,AAPL,0.0,0.0,-200.0,-5.0,-29.0,-1200.0,-1.0,-505.0,-10.0,-100.0,-15.0,-225.52688073999954,
2024-10-21T12:23:31.049449290Z,2024-10-21T12:23:31.049283153Z,10,2,38,A,B,1,233.83,200,130,166137,12969395,233.95,234.0,523,2,1,1,233.83,234.07,200,400,1,2,233.8,234.1,5,100,1,1,233.78,234.13,29,400,1,1,233.7,234.15,1200,26,1,1,233.66,234.17,1,1,1,1,233.58,234.25,505,100,2,1,233.53,234.41,10,500,1,1,233.5,234.43,100,105,1,2,233.45,234.5,15,63,1,4,AAPL,0.0,0.0,200.0,5.0,29.0,1200.0,1.0,505.0,10.0,100.0,15.0,225.52688073999954,
2024-10-21T12:23:31.105367441Z,2024-10-21T12:23:31.105200821Z,10,2,38,A,B,1,233.84,200,130,166620,12969432,233.95,234.0,523,2,1,1,233.84,234.07,200,400,1,2,233.8,234.1,5,100,1,1,233.78,234.13,29,400,1,1,233.7,234.15,1200,26,1,1,233.66,234.17,1,1,1,1,233.58,234.25,505,100,2,1,233.53,234.41,10,500,1,1,233.5,234.43,100,105,1,2,233.45,234.5,15,63,1,4,AAPL,0.0,0.0,200.0,0.0,0.0,0.0,0.0,0.0,0.0,0.0,0.0,12.683232565773917,
2024-10-21T12:23:33.817991958Z,2024-10-21T12:23:33.817825903Z,10,2,38,C,B,1,233.84,200,130,166055,12972883,233.95,234.0,523,2,1,1,233.8,234.07,5,400,1,2,233.78,234.1,29,100,1,1,233.7,234.13,1200,400,1,1,233.66,234.15,1,26,1,1,233.58,234.17,505,1,2,1,233.53,234.25,10,100,1,1,233.5,234.41,100,500,1,1,233.45,234.43,15,105,1,2,233.4,234.5,110,63,2,4,AAPL,0.0,0.0,-200.0,-5.0,-29.0,-1200.0,-1.0,-505.0,-10.0,-100.0,-15.0,-225.52688073999954,
2024-10-21T12:23:33.818003417Z,2024-10-21T12:23:33.817837243Z,10,2,38,A,B,1,233.8,400,130,166174,12972884,233.95,234.0,523,2,1,1,233.8,234.07,405,400,2,2,233.78,234.1,29,100,1,1,233.7,234.13,1200,400,1,1,233.66,234.15,1,26,1,1,233.58,234.17,505,1,2,1,233.53,234.25,10,100,1,1,233.5,234.41,100,500,1,1,233.45,234.43,15,105,1,2,233.4,234.5,110,63,2,4,AAPL,0.0,0.0,400.0,0.0,0.0,0.0,0.0,0.0,0.0,0.0,0.0,25.366465131547834,
2024-10-21T12:23:34.381839108Z,2024-10-21T12:23:34.381673108Z,10,2,38,C,A,4,234.15,26,130,166000,12973267,233.95,234.0,523,2,1,1,233.8,234.07,405,400,2,2,233.78,234.1,29,100,1,1,233.7,234.13,1200,400,1,1,233.66,234.17,1,1,1,1,233.58,234.25,505,100,2,1,233.53,234.41,10,500,1,1,233.5,234.43,100,105,1,2,233.45,234.5,15,63,1,4,233.4,234.75,110,1,2,1,AAPL,0.0,0.0,0.0,0.0,0.0,1.0,100.0,500.0,105.0,63.0,1.0,85.99556584479349,
2024-10-21T12:23:34.381954269Z,2024-10-21T12:23:34.381786514Z,10,2,38,A,A,4,234.14,27,130,167755,12973268,233.95,234.0,523,2,1,1,233.8,234.07,405,400,2,2,233.78,234.1,29,100,1,1,233.7,234.13,1200,400,1,1,233.66,234.14,1,27,1,1,233.58,234.17,505,1,2,1,233.53,234.25,10,100,1,1,233.5,234.41,100,500,1,1,233.45,234.43,15,105,1,2,233.4,234.5,110,63,2,4,AAPL,0.0,0.0,0.0,0.0,0.0,-1.0,-100.0,-500.0,-105.0,-63.0,-1.0,-85.99556584479349,
2024-10-21T12:23:35.765246828Z,2024-10-21T12:23:35.765078516Z,10,2,38,C,B,0,233.95,100,130,168312,12974800,233.95,234.0,423,2,1,1,233.8,234.07,405,400,2,2,233.78,234.1,29,100,1,1,233.7,234.13,1200,400,1,1,233.66,234.14,1,27,1,1,233.58,234.17,505,1,2,1,233.53,234.25,10,100,1,1,233.5,234.41,100,500,1,1,233.45,234.43,15,105,1,2,233.4,234.5,110,63,2,4,AAPL,-100.0,-100.0,0.0,0.0,0.0,0.0,0.0,0.0,0.0,0.0,0.0,-1.9880582646125018,
2024-10-21T12:23:35.765246828Z,2024-10-21T12:23:35.765078516Z,10,2,38,T,A,0,233.95,100,130,168312,12974800,233.95,234.0,523,2,1,1,233.8,234.07,405,400,2,2,233.78,234.1,29,100,1,1,233.7,234.13,1200,400,1,1,233.66,234.14,1,27,1,1,233.58,234.17,505,1,2,1,233.53,234.25,10,100,1,1,233.5,234.41,100,500,1,1,233.45,234.43,15,105,1,2,233.4,234.5,110,63,2,4,AAPL,100.0,100.0,0.0,0.0,0.0,0.0,0.0,0.0,0.0,0.0,0.0,1.9880582646125018,
2024-10-21T12:23:35.765460271Z,2024-10-21T12:23:35.765293055Z,10,2,38,T,A,0,233.95,423,130,167216,12974807,233.95,234.0,423,2,1,1,233.8,234.07,405,400,2,2,233.78,234.1,29,100,1,1,233.7,234.13,1200,400,1,1,233.66,234.14,1,27,1,1,233.58,234.17,505,1,2,1,233.53,234.25,10,100,1,1,233.5,234.41,100,500,1,1,233.45,234.43,15,105,1,2,233.4,234.5,110,63,2,4,AAPL,-100.0,-100.0,0.0,0.0,0.0,0.0,0.0,0.0,0.0,0.0,0.0,-1.9880582646125018,
2024-10-21T12:23:35.765460271Z,2024-10-21T12:23:35.765293055Z,10,2,38,C,B,0,233.95,423,130,167216,12974807,233.8,234.0,405,2,2,1,233.78,234.07,29,400,1,2,233.7,234.1,1200,100,1,1,233.66,234.13,1,400,1,1,233.58,234.14,505,27,2,1,233.53,234.17,10,1,1,1,233.5,234.25,100,100,1,1,233.45,234.41,15,500,1,1,233.4,234.43,110,105,2,2,233.39,234.5,10,63,1,4,AAPL,-423.0,-423.0,-405.0,-29.0,-1200.0,-1.0,-505.0,-10.0,-100.0,-15.0,-110.0,-372.93644119118943,
2024-10-21T12:23:35.765484464Z,2024-10-21T12:23:35.765317844Z,10,2,38,A,A,0,233.98,24,130,166620,12974809,233.8,233.98,405,124,2,2,233.78,234.0,29,2,1,1,233.7,234.07,1200,400,1,2,233.66,234.1,1,100,1,1,233.58,234.13,505,400,2,1,233.53,234.14,10,27,1,1,233.5,234.17,100,1,1,1,233.45,234.25,15,100,1,1,233.4,234.41,110,500,2,1,233.39,234.43,10,105,1,2,AAPL,-2.0,-2.0,-400.0,-100.0,-400.0,-27.0,-1.0,-100.0,-500.0,-105.0,-63.0,-194.83710782279343,
2024-10-21T12:23:35.765485889Z,2024-10-21T12:23:35.765319866Z,10,2,38,A,A,1,233.99,100,130,166023,12974810,233.8,233.98,405,124,2,2,233.78,233.99,29,100,1,1,233.7,234.0,1200,2,1,1,233.66,234.07,1,400,1,2,233.58,234.1,505,100,2,1,233.53,234.13,10,400,1,1,233.5,234.14,100,27,1,1,233.45,234.17,15,1,1,1,233.4,234.25,110,100,2,1,233.39,234.41,10,500,1,1,AAPL,0.0,0.0,-2.0,-400.0,-100.0,-400.0,-27.0,-1.0,-100.0,-500.0,-105.0,-163.9339018877442,
2024-10-21T12:23:35.765493677Z,2024-10-21T12:23:35.765327695Z,10,2,38,A,A,1,233.99,100,130,165982,12974811,233.8,233.98,405,124,2,2,233.78,233.99,29,200,1,2,233.7,234.0,1200,2,1,1,233.66,234.07,1,400,1,2,233.58,234.1,505,100,2,1,233.53,234.13,10,400,1,1,233.5,234.14,100,27,1,1,233.45,234.17,15,1,1,1,233.4,234.25,110,100,2,1,233.39,234.41,10,500,1,1,AAPL,0.0,0.0,-100.0,0.0,0.0,0.0,0.0,0.0,0.0,0.0,0.0,-6.3416162828869584,
2024-10-21T12:23:35.765497059Z,2024-10-21T12:23:35.765330068Z,10,2,38,A,A,1,233.99,100,130,166991,12974812,233.8,233.98,405,124,2,2,233.78,233.99,29,300,1,3,233.7,234.0,1200,2,1,1,233.66,234.07,1,400,1,2,233.58,234.1,505,100,2,1,233.53,234.13,10,400,1,1,233.5,234.14,100,27,1,1,233.45,234.17,15,1,1,1,233.4,234.25,110,100,2,1,233.39,234.41,10,500,1,1,AAPL,0.0,0.0,-100.0,0.0,0.0,0.0,0.0,0.0,0.0,0.0,0.0,-6.3416162828869584,
2024-10-21T12:23:35.765503864Z,2024-10-21T12:23:35.765336405Z,10,2,38,A,A,1,233.99,38,130,167459,12974813,233.8,233.98,405,124,2,2,233.78,233.99,29,338,1,4,233.7,234.0,1200,2,1,1,233.66,234.07,1,400,1,2,233.58,234.1,505,100,2,1,233.53,234.13,10,400,1,1,233.5,234.14,100,27,1,1,233.45,234.17,15,1,1,1,233.4,234.25,110,100,2,1,233.39,234.41,10,500,1,1,AAPL,0.0,0.0,-38.0,0.0,0.0,0.0,0.0,0.0,0.0,0.0,0.0,-2.409814187497044,
2024-10-21T12:23:35.765520554Z,2024-10-21T12:23:35.765353728Z,10,2,38,C,A,1,233.99,100,130,166826,12974817,233.8,233.98,405,124,2,2,233.78,233.99,29,238,1,3,233.7,234.0,1200,2,1,1,233.66,234.07,1,400,1,2,233.58,234.1,505,100,2,1,233.53,234.13,10,400,1,1,233.5,234.14,100,27,1,1,233.45,234.17,15,1,1,1,233.4,234.25,110,100,2,1,233.39,234.41,10,500,1,1,AAPL,0.0,0.0,100.0,0.0,0.0,0.0,0.0,0.0,0.0,0.0,0.0,6.3416162828869584,
2024-10-21T12:23:35.765523939Z,2024-10-21T12:23:35.765358258Z,10,2,38,C,N,0,233.8,400,130,165681,12974819,233.8,233.98,5,24,1,1,233.78,233.99,29,238,1,3,233.7,234.0,1200,2,1,1,233.66,234.07,1,400,1,2,233.58,234.1,505,100,2,1,233.53,234.13,10,400,1,1,233.5,234.14,100,27,1,1,233.45,234.17,15,1,1,1,233.4,234.25,110,100,2,1,233.39,234.41,10,500,1,1,AAPL,-300.0,-300.0,0.0,0.0,0.0,0.0,0.0,0.0,0.0,0.0,0.0,-5.964174793837506,
2024-10-21T12:23:35.765545765Z,2024-10-21T12:23:35.765377342Z,10,2,38,C,A,1,233.99,100,128,168423,12974821,233.8,233.98,5,24,1,1,233.78,233.99,29,138,1,2,233.7,234.0,1200,2,1,1,233.66,234.07,1,400,1,2,233.58,234.1,505,100,2,1,233.53,234.13,10,400,1,1,233.5,234.14,100,27,1,1,233.45,234.17,15,1,1,1,233.4,234.25,110,100,2,1,233.39,234.41,10,500,1,1,AAPL,0.0,0.0,100.0,0.0,0.0,0.0,0.0,0.0,0.0,0.0,0.0,6.3416162828869584,
2024-10-21T12:23:35.765878037Z,2024-10-21T12:23:35.765712149Z,10,2,38,C,A,1,233.99,100,130,165888,12974836,233.8,233.98,5,24,1,1,233.78,233.99,29,38,1,1,233.7,234.0,1200,2,1,1,233.66,234.07,1,400,1,2,233.58,234.1,505,100,2,1,233.53,234.13,10,400,1,1,233.5,234.14,100,27,1,1,233.45,234.17,15,1,1,1,233.4,234.25,110,100,2,1,233.39,234.41,10,500,1,1,AAPL,0.0,0.0,100.0,0.0,0.0,0.0,0.0,0.0,0.0,0.0,0.0,6.3416162828869584,
2024-10-21T12:23:35.833393604Z,2024-10-21T12:23:35.833227941Z,10,2,38,C,B,1,233.78,29,130,165663,12975154,233.8,233.98,5,24,1,1,233.7,233.99,1200,38,1,1,233.66,234.0,1,2,1,1,233.58,234.07,505,400,2,2,233.53,234.1,10,100,1,1,233.5,234.13,100,400,1,1,233.45,234.14,15,27,1,1,233.4,234.17,110,1,2,1,233.39,234.25,10,100,1,1,233.31,234.41,110,500,2,1,AAPL,0.0,0.0,-29.0,-1200.0,-1.0,-505.0,-10.0,-100.0,-15.0,-110.0,-10.0,-205.35614101717326,
2024-10-21T12:23:35.833436011Z,2024-10-21T12:23:35.833269631Z,10,2,38,A,B,1,233.71,30,130,166380,12975155,233.8,233.98,5,24,1,1,233.71,233.99,30,38,1,1,233.7,234.0,1200,2,1,1,233.66,234.07,1,400,1,2,233.58,234.1,505,100,2,1,233.53,234.13,10,400,1,1,233.5,234.14,100,27,1,1,233.45,234.17,15,1,1,1,233.4,234.25,110,100,2,1,233.39,234.41,10,500,1,1,AAPL,0.0,0.0,30.0,1200.0,1.0,505.0,10.0,100.0,15.0,110.0,10.0,205.4195571800021,
2024-10-21T12:23:35.833941747Z,2024-10-21T12:23:35.833775320Z,10,2,38,A,B,0,233.91,100,130,166427,12975156,233.91,233.98,100,24,1,1,233.8,233.99,5,38,1,1,233.71,234.0,30,2,1,1,233.7,234.07,1200,400,1,2,233.66,234.1,1,100,1,1,233.58,234.13,505,400,2,1,233.53,234.14,10,27,1,1,233.5,234.17,100,1,1,1,233.45,234.25,15,100,1,1,233.4,234.41,110,500,2,1,AAPL,100.0,100.0,5.0,30.0,1200.0,1.0,505.0,10.0,100.0,15.0,110.0,341.2501304456792,
2024-10-21T12:23:35.833961308Z,2024-10-21T12:23:35.833795471Z,10,2,38,C,A,0,233.98,24,130,165837,12975157,233.91,233.99,100,38,1,1,233.8,234.0,5,2,1,1,233.71,234.07,30,400,1,2,233.7,234.1,1200,100,1,1,233.66,234.13,1,400,1,1,233.58,234.14,505,27,2,1,233.53,234.17,10,1,1,1,233.5,234.25,100,100,1,1,233.45,234.41,15,500,1,1,233.4,234.43,110,105,2,2,AAPL,38.0,38.0,2.0,400.0,100.0,400.0,27.0,1.0,100.0,500.0,105.0,164.68936402829698,
2024-10-21T12:23:35.836968752Z,2024-10-21T12:23:35.836802755Z,10,2,38,C,B,2,233.71,30,130,165997,12975162,233.91,233.99,100,38,1,1,233.8,234.0,5,2,1,1,233.7,234.07,1200,400,1,2,233.66,234.1,1,100,1,1,233.58,234.13,505,400,2,1,233.53,234.14,10,27,1,1,233.5,234.17,100,1,1,1,233.45,234.25,15,100,1,1,233.4,234.41,110,500,2,1,233.39,234.43,10,105,1,2,AAPL,0.0,0.0,0.0,-30.0,-1200.0,-1.0,-505.0,-10.0,-100.0,-15.0,-110.0,-338.94499136692235,
2024-10-21T12:23:35.873928834Z,2024-10-21T12:23:35.873762810Z,10,2,38,C,A,0,233.99,38,130,166024,12975242,233.91,234.0,100,2,1,1,233.8,234.07,5,400,1,2,233.7,234.1,1200,100,1,1,233.66,234.13,1,400,1,1,233.58,234.14,505,27,2,1,233.53,234.17,10,1,1,1,233.5,234.25,100,100,1,1,233.45,234.41,15,500,1,1,233.4,234.43,110,105,2,2,233.39,234.5,10,63,1,4,AAPL,2.0,2.0,400.0,100.0,400.0,27.0,1.0,100.0,500.0,105.0,63.0,194.83710782279343,
2024-10-21T12:23:35.901252464Z,2024-10-21T12:23:35.901086187Z,10,2,38,A,B,3,233.68,400,130,166277,12975273,233.91,234.0,100,2,1,1,233.8,234.07,5,400,1,2,233.7,234.1,1200,100,1,1,233.68,234.13,400,400,1,1,233.66,234.14,1,27,1,1,233.58,234.17,505,1,2,1,233.53,234.25,10,100,1,1,233.5,234.41,100,500,1,1,233.45,234.43,15,105,1,2,233.4,234.5,110,63,2,4,AAPL,0.0,0.0,0.0,0.0,400.0,1.0,505.0,10.0,100.0,15.0,110.0,171.83586992554737,
2024-10-21T12:23:35.969287724Z,2024-10-21T12:23:35.969121189Z,10,2,38,A,B,3,233.69,400,130,166535,12975451,233.91,234.0,100,2,1,1,233.8,234.07,5,400,1,2,233.7,234.1,1200,100,1,1,233.69,234.13,400,400,1,1,233.66,234.14,1,27,1,1,233.58,234.17,505,1,2,1,233.53,234.25,10,100,1,1,233.5,234.41,100,500,1,1,233.45,234.43,15,105,1,2,233.4,234.5,110,63,2,4,AAPL,0.0,0.0,0.0,0.0,400.0,0.0,0.0,0.0,0.0,0.0,0.0,82.03082200964741,
2024-10-21T12:23:36.000313609Z,2024-10-21T12:23:36.000147454Z,10,2,38,A,B,2,233.73,400,130,166155,12975478,233.91,234.0,100,2,1,1,233.8,234.07,5,400,1,2,233.73,234.1,400,100,1,1,233.7,234.13,1200,400,1,1,233.66,234.14,1,27,1,1,233.58,234.17,505,1,2,1,233.53,234.25,10,100,1,1,233.5,234.41,100,500,1,1,233.45,234.43,15,105,1,2,233.4,234.5,110,63,2,4,AAPL,0.0,0.0,0.0,400.0,1200.0,0.0,0.0,0.0,0.0,0.0,0.0,286.7254983233443,
2024-10-21T12:23:36.364494386Z,2024-10-21T12:23:36.364328399Z,10,2,38,A,B,3,233.71,27,130,165987,12975884,233.91,234.0,100,2,1,1,233.8,234.07,5,400,1,2,233.73,234.1,400,100,1,1,233.71,234.13,27,400,1,1,233.7,234.14,1200,27,1,1,233.66,234.17,1,1,1,1,233.58,234.25,505,100,2,1,233.53,234.41,10,500,1,1,233.5,234.43,100,105,1,2,233.45,234.5,15,63,1,4,AAPL,0.0,0.0,0.0,0.0,27.0,1200.0,1.0,505.0,10.0,100.0,15.0,211.92558116049736,
2024-10-21T12:23:36.418044070Z,2024-10-21T12:23:36.417876919Z,10,2,38,A,B,2,233.79,400,130,167151,12975910,233.91,234.0,100,2,1,1,233.8,234.07,5,400,1,2,233.79,234.1,400,100,1,1,233.71,234.13,27,400,1,1,233.7,234.14,1200,27,1,1,233.66,234.17,1,1,1,1,233.58,234.25,505,100,2,1,233.53,234.41,10,500,1,1,233.5,234.43,100,105,1,2,233.45,234.5,15,63,1,4,AAPL,0.0,0.0,0.0,400.0,0.0,0.0,0.0,0.0,0.0,0.0,0.0,40.63303229440208,
2024-10-21T12:23:37.809565585Z,2024-10-21T12:23:37.809399308Z,10,2,38,C,A,1,234.07,200,130,166277,12978420,233.91,234.0,100,2,1,1,233.8,234.07,5,200,1,1,233.79,234.1,400,100,1,1,233.71,234.13,27,400,1,1,233.7,234.14,1200,27,1,1,233.66,234.17,1,1,1,1,233.58,234.25,505,100,2,1,233.53,234.41,10,500,1,1,233.5,234.43,100,105,1,2,233.45,234.5,15,63,1,4,AAPL,0.0,0.0,200.0,0.0,0.0,0.0,0.0,0.0,0.0,0.0,0.0,12.683232565773917,
2024-10-21T12:23:37.809578123Z,2024-10-21T12:23:37.809411756Z,10,2,38,A,A,1,234.02,200,130,166367,12978421,233.91,234.0,100,2,1,1,233.8,234.02,5,200,1,1,233.79,234.1,400,100,1,1,233.71,234.13,27,400,1,1,233.7,234.14,1200,27,1,1,233.66,234.17,1,1,1,1,233.58,234.25,505,100,2,1,233.53,234.41,10,500,1,1,233.5,234.43,100,105,1,2,233.45,234.5,15,63,1,4,AAPL,0.0,0.0,-200.0,0.0,0.0,0.0,0.0,0.0,0.0,0.0,0.0,-12.683232565773917,
2024-10-21T12:23:37.892570179Z,2024-10-21T12:23:37.892403782Z,10,2,38,A,A,1,234.01,200,130,166397,12978809,233.91,234.0,100,2,1,1,233.8,234.01,5,200,1,1,233.79,234.1,400,100,1,1,233.71,234.13,27,400,1,1,233.7,234.14,1200,27,1,1,233.66,234.17,1,1,1,1,233.58,234.25,505,100,2,1,233.53,234.41,10,500,1,1,233.5,234.43,100,105,1,2,233.45,234.5,15,63,1,4,AAPL,0.0,0.0,-200.0,0.0,0.0,0.0,0.0,0.0,0.0,0.0,0.0,-12.683232565773917,
2024-10-21T12:23:39.411896692Z,2024-10-21T12:23:39.411730598Z,10,2,38,C,A,4,234.14,27,130,166094,12981148,233.91,234.0,100,2,1,1,233.8,234.01,5,200,1,1,233.79,234.1,400,100,1,1,233.71,234.13,27,400,1,1,233.7,234.17,1200,1,1,1,233.66,234.25,1,100,1,1,233.58,234.41,505,500,2,1,233.53,234.43,10,105,1,2,233.5,234.5,100,63,1,4,233.45,234.75,15,1,1,1,AAPL,0.0,0.0,0.0,0.0,0.0,1.0,100.0,500.0,105.0,63.0,1.0,85.99556584479349,
2024-10-21T12:23:39.411955539Z,2024-10-21T12:23:39.411789045Z,10,2,38,A,A,2,234.08,30,130,166494,12981149,233.91,234.0,100,2,1,1,233.8,234.01,5,200,1,1,233.79,234.08,400,30,1,1,233.71,234.1,27,100,1,1,233.7,234.13,1200,400,1,1,233.66,234.17,1,1,1,1,233.58,234.25,505,100,2,1,233.53,234.41,10,500,1,1,233.5,234.43,100,105,1,2,233.45,234.5,15,63,1,4,AAPL,0.0,0.0,0.0,-100.0,-400.0,-1.0,-100.0,-500.0,-105.0,-63.0,-1.0,-178.18464592804142,
2024-10-21T12:23:40.838628426Z,2024-10-21T12:23:40.838462060Z,10,2,38,C,B,3,233.71,27,130,166366,12982424,233.91,234.0,100,2,1,1,233.8,234.01,5,200,1,1,233.79,234.08,400,30,1,1,233.7,234.1,1200,100,1,1,233.66,234.13,1,400,1,1,233.58,234.17,505,1,2,1,233.53,234.25,10,100,1,1,233.5,234.41,100,500,1,1,233.45,234.43,15,105,1,2,233.4,234.5,110,63,2,4,AAPL,0.0,0.0,0.0,0.0,-27.0,-1200.0,-1.0,-505.0,-10.0,-100.0,-15.0,-211.92558116049736,
2024-10-21T12:23:40.838662378Z,2024-10-21T12:23:40.838495937Z,10,2,38,A,B,3,233.77,28,130,166441,12982425,233.91,234.0,100,2,1,1,233.8,234.01,5,200,1,1,233.79,234.08,400,30,1,1,233.77,234.1,28,100,1,1,233.7,234.13,1200,400,1,1,233.66,234.17,1,1,1,1,233.58,234.25,505,100,2,1,233.53,234.41,10,500,1,1,233.5,234.43,100,105,1,2,233.45,234.5,15,63,1,4,AAPL,0.0,0.0,0.0,0.0,28.0,1200.0,1.0,505.0,10.0,100.0,15.0,212.1306582155215,
2024-10-21T12:23:40.884021980Z,2024-10-21T12:23:40.883854903Z,10,2,38,A,B,1,233.82,200,130,167077,12982474,233.91,234.0,100,2,1,1,233.82,234.01,200,200,1,1,233.8,234.08,5,30,1,1,233.77,234.1,28,100,1,1,233.7,234.13,1200,400,1,1,233.66,234.17,1,1,1,1,233.58,234.25,505,100,2,1,233.53,234.41,10,500,1,1,233.5,234.43,100,105,1,2,233.45,234.5,15,63,1,4,AAPL,0.0,0.0,200.0,5.0,0.0,0.0,0.0,0.0,0.0,0.0,0.0,13.191145469453943,
2024-10-21T12:23:53.580666026Z,2024-10-21T12:23:53.580500087Z,10,2,38,A,A,0,233.97,4,130,165939,12991980,233.91,233.97,100,4,1,1,233.82,234.0,200,2,1,1,233.8,234.01,5,200,1,1,233.77,234.08,28,30,1,1,233.7,234.1,1200,100,1,1,233.66,234.13,1,400,1,1,233.58,234.17,505,1,2,1,233.53,234.25,10,100,1,1,233.5,234.41,100,500,1,1,233.45,234.43,15,105,1,2,AAPL,-2.0,-2.0,-200.0,-30.0,-100.0,-400.0,-1.0,-100.0,-500.0,-105.0,-63.0,-156.93258547578057,
2024-10-21T12:23:53.580697675Z,2024-10-21T12:23:53.580531557Z,10,2,38,C,B,1,233.82,200,130,166118,12991981,233.91,233.97,100,4,1,1,233.8,234.0,5,2,1,1,233.77,234.01,28,200,1,1,233.7,234.08,1200,30,1,1,233.66,234.1,1,100,1,1,233.58,234.13,505,400,2,1,233.53,234.17,10,1,1,1,233.5,234.25,100,100,1,1,233.45,234.41,15,500,1,1,233.4,234.43,110,105,2,2,AAPL,0.0,0.0,-200.0,-5.0,-28.0,-1200.0,-1.0,-505.0,-10.0,-100.0,-15.0,-225.32180368497544,
2024-10-21T12:23:53.584756226Z,2024-10-21T12:23:53.584590487Z,10,2,38,C,A,0,233.97,4,130,165739,12991991,233.91,234.0,100,2,1,1,233.8,234.01,5,200,1,1,233.77,234.08,28,30,1,1,233.7,234.1,1200,100,1,1,233.66,234.13,1,400,1,1,233.58,234.17,505,1,2,1,233.53,234.25,10,100,1,1,233.5,234.41,100,500,1,1,233.45,234.43,15,105,1,2,233.4,234.5,110,63,2,4,AAPL,2.0,2.0,200.0,30.0,100.0,400.0,1.0,100.0,500.0,105.0,63.0,156.93258547578057,
2024-10-21T12:23:53.687484901Z,2024-10-21T12:23:53.687318686Z,10,2,38,A,B,1,233.82,200,130,166215,12992039,233.91,234.0,100,2,1,1,233.82,234.01,200,200,1,1,233.8,234.08,5,30,1,1,233.77,234.1,28,100,1,1,233.7,234.13,1200,400,1,1,233.66,234.17,1,1,1,1,233.58,234.25,505,100,2,1,233.53,234.41,10,500,1,1,233.5,234.43,100,105,1,2,233.45,234.5,15,63,1,4,AAPL,0.0,0.0,200.0,5.0,28.0,1200.0,1.0,505.0,10.0,100.0,15.0,225.32180368497544,
2024-10-21T12:23:56.151884878Z,2024-10-21T12:23:56.151717030Z,10,2,38,T,A,0,233.91,100,130,167848,12994141,233.91,234.0,100,2,1,1,233.82,234.01,200,200,1,1,233.8,234.08,5,30,1,1,233.77,234.1,28,100,1,1,233.7,234.13,1200,400,1,1,233.66,234.17,1,1,1,1,233.58,234.25,505,100,2,1,233.53,234.41,10,500,1,1,233.5,234.43,100,105,1,2,233.45,234.5,15,63,1,4,AAPL,0.0,0.0,0.0,0.0,0.0,0.0,0.0,0.0,0.0,0.0,0.0,0.0,
2024-10-21T12:23:56.151884878Z,2024-10-21T12:23:56.151717030Z,10,2,38,C,B,0,233.91,100,130,167848,12994141,233.82,234.0,200,2,1,1,233.8,234.01,5,200,1,1,233.77,234.08,28,30,1,1,233.7,234.1,1200,100,1,1,233.66,234.13,1,400,1,1,233.58,234.17,505,1,2,1,233.53,234.25,10,100,1,1,233.5,234.41,100,500,1,1,233.45,234.43,15,105,1,2,233.4,234.5,110,63,2,4,AAPL,-100.0,-100.0,-200.0,-5.0,-28.0,-1200.0,-1.0,-505.0,-10.0,-100.0,-15.0,-227.30986194958794,
2024-10-21T12:23:56.151905940Z,2024-10-21T12:23:56.151739820Z,10,2,38,A,A,0,233.95,100,130,166120,12994142,233.82,233.95,200,100,1,1,233.8,234.0,5,2,1,1,233.77,234.01,28,200,1,1,233.7,234.08,1200,30,1,1,233.66,234.1,1,100,1,1,233.58,234.13,505,400,2,1,233.53,234.17,10,1,1,1,233.5,234.25,100,100,1,1,233.45,234.41,15,500,1,1,233.4,234.43,110,105,2,2,AAPL,-2.0,-2.0,-200.0,-30.0,-100.0,-400.0,-1.0,-100.0,-500.0,-105.0,-63.0,-156.93258547578057,
2024-10-21T12:23:56.151909152Z,2024-10-21T12:23:56.151743006Z,10,2,38,A,A,1,233.98,100,130,166146,12994143,233.82,233.95,200,100,1,1,233.8,233.98,5,100,1,1,233.77,234.0,28,2,1,1,233.7,234.01,1200,200,1,1,233.66,234.08,1,30,1,1,233.58,234.1,505,100,2,1,233.53,234.13,10,400,1,1,233.5,234.17,100,1,1,1,233.45,234.25,15,100,1,1,233.4,234.41,110,500,2,1,AAPL,0.0,0.0,-2.0,-200.0,-30.0,-100.0,-400.0,-1.0,-100.0,-500.0,-105.0,-145.70502720294172,
2024-10-21T12:23:56.151910443Z,2024-10-21T12:23:56.151744249Z,10,2,38,A,A,1,233.96,25,130,166194,12994144,233.82,233.95,200,100,1,1,233.8,233.96,5,25,1,1,233.77,233.98,28,100,1,1,233.7,234.0,1200,2,1,1,233.66,234.01,1,200,1,1,233.58,234.08,505,30,2,1,233.53,234.1,10,100,1,1,233.5,234.13,100,400,1,1,233.45,234.17,15,1,1,1,233.4,234.25,110,100,2,1,AAPL,0.0,0.0,-100.0,-2.0,-200.0,-30.0,-100.0,-400.0,-1.0,-100.0,-500.0,-152.96733297531043,
2024-10-21T12:23:56.151917914Z,2024-10-21T12:23:56.151751835Z,10,2,38,A,A,2,233.98,100,130,166079,12994145,233.82,233.95,200,100,1,1,233.8,233.96,5,25,1,1,233.77,233.98,28,200,1,2,233.7,234.0,1200,2,1,1,233.66,234.01,1,200,1,1,233.58,234.08,505,30,2,1,233.53,234.1,10,100,1,1,233.5,234.13,100,400,1,1,233.45,234.17,15,1,1,1,233.4,234.25,110,100,2,1,AAPL,0.0,0.0,0.0,-100.0,0.0,0.0,0.0,0.0,0.0,0.0,0.0,-10.15825807360052,
2024-10-21T12:23:56.151922395Z,2024-10-21T12:23:56.151753407Z,10,2,38,C,B,0,233.82,200,130,168988,12994147,233.8,233.95,5,100,1,1,233.77,233.96,28,25,1,1,233.7,233.98,1200,300,1,3,233.66,234.0,1,2,1,1,233.58,234.01,505,200,2,1,233.53,234.08,10,30,1,1,233.5,234.1,100,100,1,1,233.45,234.13,15,400,1,1,233.4,234.17,110,1,2,1,233.39,234.25,10,100,1,1,AAPL,-200.0,-200.0,-5.0,-128.0,-1200.0,-1.0,-505.0,-10.0,-100.0,-15.0,-110.0,-353.1932816224202,
2024-10-21T12:23:56.151926634Z,2024-10-21T12:23:56.151760470Z,10,2,38,A,A,1,233.96,30,130,166164,12994148,233.8,233.95,5,100,1,1,233.77,233.96,28,55,1,2,233.7,233.98,1200,300,1,3,233.66,234.0,1,2,1,1,233.58,234.01,505,200,2,1,233.53,234.08,10,30,1,1,233.5,234.1,100,100,1,1,233.45,234.13,15,400,1,1,233.4,234.17,110,1,2,1,233.39,234.25,10,100,1,1,AAPL,0.0,0.0,-30.0,0.0,0.0,0.0,0.0,0.0,0.0,0.0,0.0,-1.9024848848660874,
2024-10-21T12:23:56.151940792Z,2024-10-21T12:23:56.151774406Z,10,2,38,C,A,2,233.98,100,130,166386,12994150,233.8,233.95,5,100,1,1,233.77,233.96,28,55,1,2,233.7,233.98,1200,200,1,2,233.66,233.99,1,30,1,1,233.58,234.0,505,2,2,1,233.53,234.01,10,200,1,1,233.5,234.08,100,30,1,1,233.45,234.1,15,100,1,1,233.4,234.13,110,400,2,1,233.39,234.17,10,1,1,1,AAPL,0.0,0.0,0.0,100.0,-2.0,-200.0,-30.0,-100.0,-400.0,-1.0,-100.0,-76.8786250910242,
2024-10-21T12:23:56.151962295Z,2024-10-21T12:23:56.151794726Z,10,2,38,C,A,0,233.95,100,130,167569,12994152,233.8,233.96,5,55,1,2,233.77,233.98,28,200,1,2,233.7,233.99,1200,30,1,1,233.66,234.0,1,2,1,1,233.58,234.01,505,200,2,1,233.53,234.08,10,30,1,1,233.5,234.1,100,100,1,1,233.45,234.13,15,400,1,1,233.4,234.17,110,1,2,1,233.39,234.25,10,100,1,1,AAPL,55.0,55.0,200.0,30.0,2.0,200.0,30.0,100.0,400.0,1.0,100.0,103.86102519801567,
2024-10-21T12:23:56.151983196Z,2024-10-21T12:23:56.151815406Z,10,2,38,C,A,0,233.96,25,128,167790,12994153,233.8,233.96,5,30,1,1,233.77,233.98,28,200,1,2,233.7,233.99,1200,30,1,1,233.66,234.0,1,2,1,1,233.58,234.01,505,200,2,1,233.53,234.08,10,30,1,1,233.5,234.1,100,100,1,1,233.45,234.13,15,400,1,1,233.4,234.17,110,1,2,1,233.39,234.25,10,100,1,1,AAPL,25.0,25.0,0.0,0.0,0.0,0.0,0.0,0.0,0.0,0.0,0.0,0.49701456615312545,
2024-10-21T12:23:56.151984267Z,2024-10-21T12:23:56.151818053Z,10,2,38,C,A,1,233.98,100,130,166214,12994155,233.8,233.96,5,30,1,1,233.77,233.98,28,100,1,1,233.7,233.99,1200,30,1,1,233.66,234.0,1,2,1,1,233.58,234.01,505,200,2,1,233.53,234.08,10,30,1,1,233.5,234.1,100,100,1,1,233.45,234.13,15,400,1,1,233.4,234.17,110,1,2,1,233.39,234.25,10,100,1,1,AAPL,0.0,0.0,100.0,0.0,0.0,0.0,0.0,0.0,0.0,0.0,0.0,6.3416162828869584,
2024-10-21T12:23:56.152075526Z,2024-10-21T12:23:56.151908869Z,10,2,38,A,A,0,233.95,100,130,166657,12994157,233.8,233.95,5,100,1,1,233.77,233.96,28,30,1,1,233.7,233.98,1200,100,1,1,233.66,233.99,1,30,1,1,233.58,234.0,505,2,2,1,233.53,234.01,10,200,1,1,233.5,234.08,100,30,1,1,233.45,234.1,15,100,1,1,233.4,234.13,110,400,2,1,233.39,234.17,10,1,1,1,AAPL,-30.0,-30.0,-100.0,-30.0,-2.0,-200.0,-30.0,-100.0,-400.0,-1.0,-100.0,-97.02239434897558,
2024-10-21T12:23:56.152225403Z,2024-10-21T12:23:56.152059304Z,10,2,38,C,A,2,233.98,100,130,166099,12994158,233.8,233.95,5,100,1,1,233.77,233.96,28,30,1,1,233.7,233.99,1200,30,1,1,233.66,234.0,1,2,1,1,233.58,234.01,505,200,2,1,233.53,234.08,10,30,1,1,233.5,234.1,100,100,1,1,233.45,234.13,15,400,1,1,233.4,234.17,110,1,2,1,233.39,234.25,10,100,1,1,AAPL,0.0,0.0,0.0,30.0,2.0,200.0,30.0,100.0,400.0,1.0,100.0,90.08436058670488,
2024-10-21T12:23:56.152267246Z,2024-10-21T12:23:56.152100943Z,10,2,38,A,A,0,233.95,7,130,166303,12994159,233.8,233.95,5,107,1,2,233.77,233.96,28,30,1,1,233.7,233.99,1200,30,1,1,233.66,234.0,1,2,1,1,233.58,234.01,505,200,2,1,233.53,234.08,10,30,1,1,233.5,234.1,100,100,1,1,233.45,234.13,15,400,1,1,233.4,234.17,110,1,2,1,233.39,234.25,10,100,1,1,AAPL,-7.0,-7.0,0.0,0.0,0.0,0.0,0.0,0.0,0.0,0.0,0.0,-0.13916407852287513,
2024-10-21T12:23:56.152492907Z,2024-10-21T12:23:56.152326897Z,10,2,38,C,A,0,233.95,100,130,166010,12994160,233.8,233.95,5,7,1,1,233.77,233.96,28,30,1,1,233.7,233.99,1200,30,1,1,233.66,234.0,1,2,1,1,233.58,234.01,505,200,2,1,233.53,234.08,10,30,1,1,233.5,234.1,100,100,1,1,233.45,234.13,15,400,1,1,233.4,234.17,110,1,2,1,233.39,234.25,10,100,1,1,AAPL,100.0,100.0,0.0,0.0,0.0,0.0,0.0,0.0,0.0,0.0,0.0,1.9880582646125018,
2024-10-21T12:23:56.156361100Z,2024-10-21T12:23:56.156195112Z,10,2,38,C,A,0,233.95,7,130,165988,12994163,233.8,233.96,5,30,1,1,233.77,233.99,28,30,1,1,233.7,234.0,1200,2,1,1,233.66,234.01,1,200,1,1,233.58,234.08,505,30,2,1,233.53,234.1,10,100,1,1,233.5,234.13,100,400,1,1,233.45,234.17,15,1,1,1,233.4,234.25,110,100,2,1,233.39,234.41,10,500,1,1,AAPL,30.0,30.0,30.0,2.0,200.0,30.0,100.0,400.0,1.0,100.0,500.0,149.1246190566733,
2024-10-21T12:23:56.223030277Z,2024-10-21T12:23:56.222863616Z,10,2,38,A,B,2,233.73,400,130,166661,12994197,233.8,233.96,5,30,1,1,233.77,233.99,28,30,1,1,233.73,234.0,400,2,1,1,233.7,234.01,1200,200,1,1,233.66,234.08,1,30,1,1,233.58,234.1,505,100,2,1,233.53,234.13,10,400,1,1,233.5,234.17,100,1,1,1,233.45,234.25,15,100,1,1,233.4,234.41,110,500,2,1,AAPL,0.0,0.0,0.0,400.0,1200.0,1.0,505.0,10.0,100.0,15.0,110.0,376.5305462392443,
2024-10-21T12:23:56.223543885Z,2024-10-21T12:23:56.223377764Z,10,2,38,C,B,1,233.77,28,130,166121,12994198,233.8,233.96,5,30,1,1,233.73,233.99,400,30,1,1,233.7,234.0,1200,2,1,1,233.66,234.01,1,200,1,1,233.58,234.08,505,30,2,1,233.53,234.1,10,100,1,1,233.5,234.13,100,400,1,1,233.45,234.17,15,1,1,1,233.4,234.25,110,100,2,1,233.39,234.41,10,500,1,1,AAPL,0.0,0.0,-28.0,-400.0,-1200.0,-1.0,-505.0,-10.0,-100.0,-15.0,-110.0,-378.3061987984526,
2024-10-21T12:23:56.223614225Z,2024-10-21T12:23:56.223447893Z,10,2,38,A,B,2,233.71,29,130,166332,12994199,233.8,233.96,5,30,1,1,233.73,233.99,400,30,1,1,233.71,234.0,29,2,1,1,233.7,234.01,1200,200,1,1,233.66,234.08,1,30,1,1,233.58,234.1,505,100,2,1,233.53,234.13,10,400,1,1,233.5,234.17,100,1,1,1,233.45,234.25,15,100,1,1,233.4,234.41,110,500,2,1,AAPL,0.0,0.0,0.0,29.0,1200.0,1.0,505.0,10.0,100.0,15.0,110.0,338.84340878618633,
2024-10-21T12:23:56.253930823Z,2024-10-21T12:23:56.253764723Z,10,2,38,C,A,1,233.99,30,130,166100,12994211,233.8,233.96,5,30,1,1,233.73,234.0,400,2,1,1,233.71,234.01,29,200,1,1,233.7,234.08,1200,30,1,1,233.66,234.1,1,100,1,1,233.58,234.13,505,400,2,1,233.53,234.17,10,1,1,1,233.5,234.25,100,100,1,1,233.45,234.41,15,500,1,1,233.4,234.43,110,105,2,2,AAPL,0.0,0.0,2.0,200.0,30.0,100.0,400.0,1.0,100.0,500.0,105.0,145.70502720294172,
2024-10-21T12:23:56.403930641Z,2024-10-21T12:23:56.403764720Z,10,2,38,C,A,0,233.96,30,130,165921,12994800,233.8,234.0,5,2,1,1,233.73,234.01,400,200,1,1,233.71,234.08,29,30,1,1,233.7,234.1,1200,100,1,1,233.66,234.13,1,400,1,1,233.58,234.17,505,1,2,1,233.53,234.25,10,100,1,1,233.5,234.41,100,500,1,1,233.45,234.43,15,105,1,2,233.4,234.5,110,63,2,4,AAPL,2.0,2.0,200.0,30.0,100.0,400.0,1.0,100.0,500.0,105.0,63.0,156.93258547578057,
2024-10-21T12:23:59.005077193Z,2024-10-21T12:23:59.004911131Z,10,2,38,C,B,1,233.73,400,130,166062,12997239,233.8,234.0,5,2,1,1,233.71,234.01,29,200,1,1,233.7,234.08,1200,30,1,1,233.66,234.1,1,100,1,1,233.58,234.13,505,400,2,1,233.53,234.17,10,1,1,1,233.5,234.25,100,100,1,1,233.45,234.41,15,500,1,1,233.4,234.43,110,105,2,2,233.39,234.5,10,63,1,4,AAPL,0.0,0.0,-400.0,-29.0,-1200.0,-1.0,-505.0,-10.0,-100.0,-15.0,-110.0,-364.20987391773417,
2024-10-21T12:23:59.005089751Z,2024-10-21T12:23:59.004923443Z,10,2,38,A,B,3,233.68,400,130,166308,12997240,233.8,234.0,5,2,1,1,233.71,234.01,29,200,1,1,233.7,234.08,1200,30,1,1,233.68,234.1,400,100,1,1,233.66,234.13,1,400,1,1,233.58,234.17,505,1,2,1,233.53,234.25,10,100,1,1,233.5,234.41,100,500,1,1,233.45,234.43,15,105,1,2,233.4,234.5,110,63,2,4,AAPL,0.0,0.0,0.0,0.0,400.0,1.0,505.0,10.0,100.0,15.0,110.0,171.83586992554737,
2024-10-21T12:23:59.008446995Z,2024-10-21T12:23:59.008280403Z,10,2,38,A,A,2,234.03,29,130,166592,12997243,233.8,234.0,5,2,1,1,233.71,234.01,29,200,1,1,233.7,234.03,1200,29,1,1,233.68,234.08,400,30,1,1,233.66,234.1,1,100,1,1,233.58,234.13,505,400,2,1,233.53,234.17,10,1,1,1,233.5,234.25,100,100,1,1,233.45,234.41,15,500,1,1,233.4,234.43,110,105,2,2,AAPL,0.0,0.0,0.0,-30.0,-100.0,-400.0,-1.0,-100.0,-500.0,-105.0,-63.0,-144.2095917447144,
2024-10-21T12:23:59.008489006Z,2024-10-21T12:23:59.008322912Z,10,2,38,C,A,3,234.08,30,130,166094,12997244,233.8,234.0,5,2,1,1,233.71,234.01,29,200,1,1,233.7,234.03,1200,29,1,1,233.68,234.1,400,100,1,1,233.66,234.13,1,400,1,1,233.58,234.17,505,1,2,1,233.53,234.25,10,100,1,1,233.5,234.41,100,500,1,1,233.45,234.43,15,105,1,2,233.4,234.5,110,63,2,4,AAPL,0.0,0.0,0.0,0.0,100.0,400.0,1.0,100.0,500.0,105.0,63.0,141.16211432263424,
2024-10-21T12:23:59.012113870Z,2024-10-21T12:23:59.011947596Z,10,2,38,C,A,1,234.01,200,130,166274,12997249,233.8,234.0,5,2,1,1,233.71,234.03,29,29,1,1,233.7,234.1,1200,100,1,1,233.68,234.13,400,400,1,1,233.66,234.17,1,1,1,1,233.58,234.25,505,100,2,1,233.53,234.41,10,500,1,1,233.5,234.43,100,105,1,2,233.45,234.5,15,63,1,4,233.4,234.75,110,1,2,1,AAPL,0.0,0.0,29.0,100.0,400.0,1.0,100.0,500.0,105.0,63.0,1.0,180.02371465007863,
2024-10-21T12:23:59.012126464Z,2024-10-21T12:23:59.011960403Z,10,2,38,A,A,2,234.04,200,130,166061,12997250,233.8,234.0,5,2,1,1,233.71,234.03,29,29,1,1,233.7,234.04,1200,200,1,1,233.68,234.1,400,100,1,1,233.66,234.13,1,400,1,1,233.58,234.17,505,1,2,1,233.53,234.25,10,100,1,1,233.5,234.41,100,500,1,1,233.45,234.43,15,105,1,2,233.4,234.5,110,63,2,4,AAPL,0.0,0.0,0.0,-100.0,-400.0,-1.0,-100.0,-500.0,-105.0,-63.0,-1.0,-178.18464592804142,
2024-10-21T12:23:59.013684039Z,2024-10-21T12:23:59.013517894Z,10,2,38,C,A,2,234.04,200,130,166145,12997253,233.8,234.0,5,2,1,1,233.71,234.03,29,29,1,1,233.7,234.1,1200,100,1,1,233.68,234.13,400,400,1,1,233.66,234.17,1,1,1,1,233.58,234.25,505,100,2,1,233.53,234.41,10,500,1,1,233.5,234.43,100,105,1,2,233.45,234.5,15,63,1,4,233.4,234.75,110,1,2,1,AAPL,0.0,0.0,0.0,100.0,400.0,1.0,100.0,500.0,105.0,63.0,1.0,178.18464592804142,
2024-10-21T12:23:59.013696792Z,2024-10-21T12:23:59.013530559Z,10,2,38,A,A,2,234.07,400,130,166233,12997254,233.8,234.0,5,2,1,1,233.71,234.03,29,29,1,1,233.7,234.07,1200,400,1,1,233.68,234.1,400,100,1,1,233.66,234.13,1,400,1,1,233.58,234.17,505,1,2,1,233.53,234.25,10,100,1,1,233.5,234.41,100,500,1,1,233.45,234.43,15,105,1,2,233.4,234.5,110,63,2,4,AAPL,0.0,0.0,0.0,-100.0,-400.0,-1.0,-100.0,-500.0,-105.0,-63.0,-1.0,-178.18464592804142,
2024-10-21T12:23:59.014404565Z,2024-10-21T12:23:59.014238552Z,10,2,38,C,A,1,234.03,29,130,166013,12997255,233.8,234.0,5,2,1,1,233.71,234.07,29,400,1,1,233.7,234.1,1200,100,1,1,233.68,234.13,400,400,1,1,233.66,234.17,1,1,1,1,233.58,234.25,505,100,2,1,233.53,234.41,10,500,1,1,233.5,234.43,100,105,1,2,233.45,234.5,15,63,1,4,233.4,234.75,110,1,2,1,AAPL,0.0,0.0,400.0,100.0,400.0,1.0,100.0,500.0,105.0,63.0,1.0,203.55111105958926,
2024-10-21T12:23:59.017362837Z,2024-10-21T12:23:59.017196811Z,10,2,38,C,B,1,233.71,29,130,166026,12997256,233.8,234.0,5,2,1,1,233.7,234.07,1200,400,1,1,233.68,234.1,400,100,1,1,233.66,234.13,1,400,1,1,233.58,234.17,505,1,2,1,233.53,234.25,10,100,1,1,233.5,234.41,100,500,1,1,233.45,234.43,15,105,1,2,233.4,234.5,110,63,2,4,233.39,234.75,10,1,1,1,AAPL,0.0,0.0,-29.0,-1200.0,-400.0,-1.0,-505.0,-10.0,-100.0,-15.0,-110.0,-295.5740355307908,
2024-10-21T12:23:59.017449096Z,2024-10-21T12:23:59.017282783Z,10,2,38,A,B,4,233.61,27,130,166313,12997257,233.8,234.0,5,2,1,1,233.7,234.07,1200,400,1,1,233.68,234.1,400,100,1,1,233.66,234.13,1,400,1,1,233.61,234.17,27,1,1,1,233.58,234.25,505,100,2,1,233.53,234.41,10,500,1,1,233.5,234.43,100,105,1,2,233.45,234.5,15,63,1,4,233.4,234.75,110,1,2,1,AAPL,0.0,0.0,0.0,0.0,0.0,27.0,505.0,10.0,100.0,15.0,110.0,92.83112778671882,
2024-10-21T12:23:59.074684910Z,2024-10-21T12:23:59.074518650Z,10,2,38,A,A,1,234.02,200,130,166260,12997280,233.8,234.0,5,2,1,1,233.7,234.02,1200,200,1,1,233.68,234.1,400,100,1,1,233.66,234.13,1,400,1,1,233.61,234.17,27,1,1,1,233.58,234.25,505,100,2,1,233.53,234.41,10,500,1,1,233.5,234.43,100,105,1,2,233.45,234.5,15,63,1,4,233.4,234.75,110,1,2,1,AAPL,0.0,0.0,-400.0,0.0,0.0,0.0,0.0,0.0,0.0,0.0,0.0,-25.366465131547834,
2024-10-21T12:24:00.591711571Z,2024-10-21T12:24:00.591545399Z,10,2,38,A,B,3,233.66,27,130,166172,12999539,233.8,234.0,5,2,1,1,233.7,234.02,1200,200,1,1,233.68,234.1,400,100,1,1,233.66,234.13,28,400,2,1,233.61,234.17,27,1,1,1,233.58,234.25,505,100,2,1,233.53,234.41,10,500,1,1,233.5,234.43,100,105,1,2,233.45,234.5,15,63,1,4,233.4,234.75,110,1,2,1,AAPL,0.0,0.0,0.0,0.0,27.0,0.0,0.0,0.0,0.0,0.0,0.0,5.5370804856512,
2024-10-21T12:24:00.591743978Z,2024-10-21T12:24:00.591577923Z,10,2,38,C,B,4,233.61,27,130,166055,12999540,233.8,234.0,5,2,1,1,233.7,234.02,1200,200,1,1,233.68,234.1,400,100,1,1,233.66,234.13,28,400,2,1,233.58,234.17,505,1,2,1,233.53,234.25,10,100,1,1,233.5,234.41,100,500,1,1,233.45,234.43,15,105,1,2,233.4,234.5,110,63,2,4,233.39,234.75,10,1,1,1,AAPL,0.0,0.0,0.0,0.0,0.0,-27.0,-505.0,-10.0,-100.0,-15.0,-110.0,-92.83112778671882,
2024-10-21T12:24:00.591786574Z,2024-10-21T12:24:00.591620074Z,10,2,38,A,A,2,234.08,26,130,166500,12999541,233.8,234.0,5,2,1,1,233.7,234.02,1200,200,1,1,233.68,234.08,400,26,1,1,233.66,234.1,28,100,2,1,233.58,234.13,505,400,2,1,233.53,234.17,10,1,1,1,233.5,234.25,100,100,1,1,233.45,234.41,15,500,1,1,233.4,234.43,110,105,2,2,233.39,234.5,10,63,1,4,AAPL,0.0,0.0,0.0,-100.0,-400.0,-1.0,-100.0,-500.0,-105.0,-63.0,-1.0,-178.18464592804142,
2024-10-21T12:24:00.639172304Z,2024-10-21T12:24:00.639005885Z,10,2,38,A,B,1,233.72,400,130,166419,12999658,233.8,234.0,5,2,1,1,233.72,234.02,400,200,1,1,233.7,234.08,1200,26,1,1,233.66,234.1,28,100,2,1,233.58,234.13,505,400,2,1,233.53,234.17,10,1,1,1,233.5,234.25,100,100,1,1,233.45,234.41,15,500,1,1,233.4,234.43,110,105,2,2,233.39,234.5,10,63,1,4,AAPL,0.0,0.0,400.0,1200.0,0.0,0.0,0.0,0.0,0.0,0.0,0.0,147.26556201475407,
2024-10-21T12:24:00.649223162Z,2024-10-21T12:24:00.649056842Z,10,2,38,A,A,1,234.01,200,130,166320,12999723,233.8,234.0,5,2,1,1,233.72,234.01,400,200,1,1,233.7,234.08,1200,26,1,1,233.66,234.1,28,100,2,1,233.58,234.13,505,400,2,1,233.53,234.17,10,1,1,1,233.5,234.25,100,100,1,1,233.45,234.41,15,500,1,1,233.4,234.43,110,105,2,2,233.39,234.5,10,63,1,4,AAPL,0.0,0.0,-200.0,0.0,0.0,0.0,0.0,0.0,0.0,0.0,0.0,-12.683232565773917,
2024-10-21T12:24:02.009559726Z,2024-10-21T12:24:02.009392935Z,10,2,38,A,A,1,234.01,200,130,166791,13001036,233.8,234.0,5,2,1,1,233.72,234.01,400,400,1,2,233.7,234.08,1200,26,1,1,233.66,234.1,28,100,2,1,233.58,234.13,505,400,2,1,233.53,234.17,10,1,1,1,233.5,234.25,100,100,1,1,233.45,234.41,15,500,1,1,233.4,234.43,110,105,2,2,233.39,234.5,10,63,1,4,AAPL,0.0,0.0,-200.0,0.0,0.0,0.0,0.0,0.0,0.0,0.0,0.0,-12.683232565773917,
2024-10-21T12:24:03.014397743Z,2024-10-21T12:24:03.014231244Z,10,2,38,A,B,1,233.73,400,130,166499,13002474,233.8,234.0,5,2,1,1,233.73,234.01,400,400,1,2,233.7,234.08,1200,26,1,1,233.66,234.1,28,100,2,1,233.58,234.13,505,400,2,1,233.53,234.17,10,1,1,1,233.5,234.25,100,100,1,1,233.45,234.41,15,500,1,1,233.4,234.43,110,105,2,2,233.39,234.5,10,63,1,4,AAPL,0.0,0.0,400.0,0.0,0.0,0.0,0.0,0.0,0.0,0.0,0.0,25.366465131547834,
2024-10-21T12:24:12.705919587Z,2024-10-21T12:24:12.705753370Z,10,2,38,C,A,2,234.08,26,130,166217,13011148,233.8,234.0,5,2,1,1,233.73,234.01,400,400,1,2,233.7,234.1,1200,100,1,1,233.66,234.13,28,400,2,1,233.58,234.17,505,1,2,1,233.53,234.25,10,100,1,1,233.5,234.41,100,500,1,1,233.45,234.43,15,105,1,2,233.4,234.5,110,63,2,4,233.39,234.75,10,1,1,1,AAPL,0.0,0.0,0.0,100.0,400.0,1.0,100.0,500.0,105.0,63.0,1.0,178.18464592804142,
2024-10-21T12:24:12.705959304Z,2024-10-21T12:24:12.705792927Z,10,2,38,A,A,2,234.03,27,130,166377,13011149,233.8,234.0,5,2,1,1,233.73,234.01,400,400,1,2,233.7,234.03,1200,27,1,1,233.66,234.1,28,100,2,1,233.58,234.13,505,400,2,1,233.53,234.17,10,1,1,1,233.5,234.25,100,100,1,1,233.45,234.41,15,500,1,1,233.4,234.43,110,105,2,2,233.39,234.5,10,63,1,4,AAPL,0.0,0.0,0.0,-100.0,-400.0,-1.0,-100.0,-500.0,-105.0,-63.0,-1.0,-178.18464592804142,
2024-10-21T12:24:12.758818645Z,2024-10-21T12:24:12.758652350Z,10,2,38,C,A,1,234.01,200,130,166295,13011180,233.8,234.0,5,2,1,1,233.73,234.01,400,200,1,1,233.7,234.03,1200,27,1,1,233.66,234.1,28,100,2,1,233.58,234.13,505,400,2,1,233.53,234.17,10,1,1,1,233.5,234.25,100,100,1,1,233.45,234.41,15,500,1,1,233.4,234.43,110,105,2,2,233.39,234.5,10,63,1,4,AAPL,0.0,0.0,200.0,0.0,0.0,0.0,0.0,0.0,0.0,0.0,0.0,12.683232565773917,
2024-10-21T12:24:12.758831773Z,2024-10-21T12:24:12.758665302Z,10,2,38,A,A,0,233.96,200,130,166471,13011181,233.8,233.96,5,200,1,1,233.73,234.0,400,2,1,1,233.7,234.03,1200,27,1,1,233.66,234.1,28,100,2,1,233.58,234.13,505,400,2,1,233.53,234.17,10,1,1,1,233.5,234.25,100,100,1,1,233.45,234.41,15,500,1,1,233.4,234.43,110,105,2,2,233.39,234.5,10,63,1,4,AAPL,-2.0,-2.0,-200.0,0.0,0.0,0.0,0.0,0.0,0.0,0.0,0.0,-12.722993731066166,
2024-10-21T12:24:12.829962896Z,2024-10-21T12:24:12.829796906Z,10,2,38,C,B,1,233.73,400,130,165990,13011209,233.8,233.96,5,200,1,1,233.7,234.0,1200,2,1,1,233.66,234.03,28,27,2,1,233.58,234.1,505,100,2,1,233.53,234.13,10,400,1,1,233.5,234.17,100,1,1,1,233.45,234.25,15,100,1,1,233.4,234.41,110,500,2,1,233.39,234.43,10,105,1,2,233.31,234.5,110,63,2,4,AAPL,0.0,0.0,-400.0,-1200.0,-28.0,-505.0,-10.0,-100.0,-15.0,-110.0,-10.0,-234.42061791233508,
2024-10-21T12:24:12.829976396Z,2024-10-21T12:24:12.829810064Z,10,2,38,A,B,2,233.68,400,130,166332,13011211,233.8,233.96,5,200,1,1,233.7,234.0,1200,2,1,1,233.68,234.03,400,27,1,1,233.66,234.1,28,100,2,1,233.58,234.13,505,400,2,1,233.53,234.17,10,1,1,1,233.5,234.25,100,100,1,1,233.45,234.41,15,500,1,1,233.4,234.43,110,105,2,2,233.39,234.5,10,63,1,4,AAPL,0.0,0.0,0.0,400.0,28.0,505.0,10.0,100.0,15.0,110.0,10.0,127.78808819198305,
2024-10-21T12:24:12.887926720Z,2024-10-21T12:24:12.887759925Z,10,2,38,A,B,1,233.71,200,130,166795,13011280,233.8,233.96,5,200,1,1,233.71,234.0,200,2,1,1,233.7,234.03,1200,27,1,1,233.66,234.1,28,100,2,1,233.58,234.13,505,400,2,1,233.53,234.17,10,1,1,1,233.5,234.25,100,100,1,1,233.45,234.41,15,500,1,1,233.4,234.43,110,105,2,2,233.39,234.5,10,63,1,4,AAPL,0.0,0.0,200.0,1200.0,0.0,0.0,0.0,0.0,0.0,0.0,0.0,134.58232944898015,
2024-10-21T12:24:12.974238049Z,2024-10-21T12:24:12.974071654Z,10,2,38,A,A,0,233.96,200,130,166395,13011303,233.8,233.96,5,400,1,2,233.71,234.0,200,2,1,1,233.7,234.03,1200,27,1,1,233.66,234.1,28,100,2,1,233.58,234.13,505,400,2,1,233.53,234.17,10,1,1,1,233.5,234.25,100,100,1,1,233.45,234.41,15,500,1,1,233.4,234.43,110,105,2,2,233.39,234.5,10,63,1,4,AAPL,-200.0,-200.0,0.0,0.0,0.0,0.0,0.0,0.0,0.0,0.0,0.0,-3.9761165292250036,
2024-10-21T12:24:12.981903881Z,2024-10-21T12:24:12.981737142Z,10,2,38,A,A,0,233.94,6,130,166739,13011309,233.8,233.94,5,6,1,1,233.71,233.96,200,400,1,2,233.7,234.0,1200,2,1,1,233.66,234.03,28,27,2,1,233.58,234.1,505,100,2,1,233.53,234.13,10,400,1,1,233.5,234.17,100,1,1,1,233.45,234.25,15,100,1,1,233.4,234.41,110,500,2,1,233.39,234.43,10,105,1,2,AAPL,-400.0,-400.0,-2.0,-27.0,-100.0,-400.0,-1.0,-100.0,-500.0,-105.0,-63.0,-151.98390938661413,
2024-10-21T12:24:12.981949530Z,2024-10-21T12:24:12.981783591Z,10,2,38,C,B,1,233.71,200,130,165939,13011310,233.8,233.94,5,6,1,1,233.7,233.96,1200,400,1,2,233.66,234.0,28,2,2,1,233.58,234.03,505,27,2,1,233.53,234.1,10,100,1,1,233.5,234.13,100,400,1,1,233.45,234.17,15,1,1,1,233.4,234.25,110,100,2,1,233.39,234.41,10,500,1,1,233.31,234.43,110,105,2,2,AAPL,0.0,0.0,-200.0,-1200.0,-28.0,-505.0,-10.0,-100.0,-15.0,-110.0,-10.0,-221.73738534656113,
2024-10-21T12:24:12.985997932Z,2024-10-21T12:24:12.985831565Z,10,2,38,C,A,0,233.94,6,130,166367,13011317,233.8,233.96,5,400,1,2,233.7,234.0,1200,2,1,1,233.66,234.03,28,27,2,1,233.58,234.1,505,100,2,1,233.53,234.13,10,400,1,1,233.5,234.17,100,1,1,1,233.45,234.25,15,100,1,1,233.4,234.41,110,500,2,1,233.39,234.43,10,105,1,2,233.31,234.5,110,63,2,4,AAPL,400.0,400.0,2.0,27.0,100.0,400.0,1.0,100.0,500.0,105.0,63.0,151.98390938661413,
2024-10-21T12:24:13.052769828Z,2024-10-21T12:24:13.052603423Z,10,2,38,A,B,3,233.62,400,130,166405,13011374,233.8,233.96,5,400,1,2,233.7,234.0,1200,2,1,1,233.66,234.03,28,27,2,1,233.62,234.1,400,100,1,1,233.58,234.13,505,400,2,1,233.53,234.17,10,1,1,1,233.5,234.25,100,100,1,1,233.45,234.41,15,500,1,1,233.4,234.43,110,105,2,2,233.39,234.5,10,63,1,4,AAPL,0.0,0.0,0.0,0.0,400.0,505.0,10.0,100.0,15.0,110.0,10.0,163.4437203665531,
2024-10-21T12:24:13.053294920Z,2024-10-21T12:24:13.053128647Z,10,2,38,A,B,5,233.55,27,130,166273,13011375,233.8,233.96,5,400,1,2,233.7,234.0,1200,2,1,1,233.66,234.03,28,27,2,1,233.62,234.1,400,100,1,1,233.58,234.13,505,400,2,1,233.55,234.17,27,1,1,1,233.53,234.25,10,100,1,1,233.5,234.41,100,500,1,1,233.45,234.43,15,105,1,2,233.4,234.5,110,63,2,4,AAPL,0.0,0.0,0.0,0.0,0.0,0.0,27.0,10.0,100.0,15.0,110.0,23.871595229705537,
2024-10-21T12:24:13.053320162Z,2024-10-21T12:24:13.053154026Z,10,2,38,C,B,2,233.66,27,130,166136,13011376,233.8,233.96,5,400,1,2,233.7,234.0,1200,2,1,1,233.66,234.03,1,27,1,1,233.62,234.1,400,100,1,1,233.58,234.13,505,400,2,1,233.55,234.17,27,1,1,1,233.53,234.25,10,100,1,1,233.5,234.41,100,500,1,1,233.45,234.43,15,105,1,2,233.4,234.5,110,63,2,4,AAPL,0.0,0.0,0.0,-27.0,0.0,0.0,0.0,0.0,0.0,0.0,0.0,-2.74272967987214,
2024-10-21T12:24:13.185024995Z,2024-10-21T12:24:13.184858615Z,10,2,38,A,B,3,233.63,200,130,166380,13011463,233.8,233.96,5,400,1,2,233.7,234.0,1200,2,1,1,233.66,234.03,1,27,1,1,233.63,234.1,200,100,1,1,233.58,234.13,505,400,2,1,233.55,234.17,27,1,1,1,233.53,234.25,10,100,1,1,233.5,234.41,100,500,1,1,233.45,234.43,15,105,1,2,233.4,234.5,110,63,2,4,AAPL,0.0,0.0,0.0,0.0,200.0,0.0,0.0,0.0,0.0,0.0,0.0,41.015411004823704,
2024-10-21T12:24:13.203151981Z,2024-10-21T12:24:13.202985661Z,10,2,38,A,B,2,233.68,200,130,166320,13011562,233.8,233.96,5,400,1,2,233.7,234.0,1200,2,1,1,233.68,234.03,200,27,1,1,233.66,234.1,1,100,1,1,233.58,234.13,505,400,2,1,233.55,234.17,27,1,1,1,233.53,234.25,10,100,1,1,233.5,234.41,100,500,1,1,233.45,234.43,15,105,1,2,233.4,234.5,110,63,2,4,AAPL,0.0,0.0,0.0,200.0,1.0,0.0,0.0,0.0,0.0,0.0,0.0,20.52159320222516,
2024-10-21T12:24:13.538567140Z,2024-10-21T12:24:13.538400660Z,10,2,38,A,B,2,233.68,200,130,166480,13011788,233.8,233.96,5,400,1,2,233.7,234.0,1200,2,1,1,233.68,234.03,400,27,2,1,233.66,234.1,1,100,1,1,233.58,234.13,505,400,2,1,233.55,234.17,27,1,1,1,233.53,234.25,10,100,1,1,233.5,234.41,100,500,1,1,233.45,234.43,15,105,1,2,233.4,234.5,110,63,2,4,AAPL,0.0,0.0,0.0,200.0,0.0,0.0,0.0,0.0,0.0,0.0,0.0,20.31651614720104,
2024-10-21T12:24:13.589336955Z,2024-10-21T12:24:13.589170912Z,10,2,38,C,B,2,233.68,200,130,166043,13011843,233.8,233.96,5,400,1,2,233.7,234.0,1200,2,1,1,233.68,234.03,200,27,1,1,233.66,234.1,1,100,1,1,233.58,234.13,505,400,2,1,233.55,234.17,27,1,1,1,233.53,234.25,10,100,1,1,233.5,234.41,100,500,1,1,233.45,234.43,15,105,1,2,233.4,234.5,110,63,2,4,AAPL,0.0,0.0,0.0,-200.0,0.0,0.0,0.0,0.0,0.0,0.0,0.0,-20.31651614720104,
2024-10-21T12:24:13.589349547Z,2024-10-21T12:24:13.589183060Z,10,2,38,A,B,1,233.71,200,130,166487,13011844,233.8,233.96,5,400,1,2,233.71,234.0,200,2,1,1,233.7,234.03,1200,27,1,1,233.66,234.1,1,100,1,1,233.58,234.13,505,400,2,1,233.55,234.17,27,1,1,1,233.53,234.25,10,100,1,1,233.5,234.41,100,500,1,1,233.45,234.43,15,105,1,2,233.4,234.5,110,63,2,4,AAPL,0.0,0.0,200.0,1200.0,0.0,0.0,0.0,0.0,0.0,0.0,0.0,134.58232944898015,
2024-10-21T12:24:13.923159059Z,2024-10-21T12:24:13.922992508Z,10,2,38,C,B,5,233.55,27,130,166551,13011979,233.8,233.96,5,400,1,2,233.71,234.0,200,2,1,1,233.7,234.03,1200,27,1,1,233.66,234.1,1,100,1,1,233.58,234.13,505,400,2,1,233.53,234.17,10,1,1,1,233.5,234.25,100,100,1,1,233.45,234.41,15,500,1,1,233.4,234.43,110,105,2,2,233.39,234.5,10,63,1,4,AAPL,0.0,0.0,0.0,0.0,0.0,0.0,-27.0,-10.0,-100.0,-15.0,-110.0,-23.871595229705537,
2024-10-21T12:24:13.923293151Z,2024-10-21T12:24:13.923126726Z,10,2,38,A,B,3,233.66,30,130,166425,13011980,233.8,233.96,5,400,1,2,233.71,234.0,200,2,1,1,233.7,234.03,1200,27,1,1,233.66,234.1,31,100,2,1,233.58,234.13,505,400,2,1,233.53,234.17,10,1,1,1,233.5,234.25,100,100,1,1,233.45,234.41,15,500,1,1,233.4,234.43,110,105,2,2,233.39,234.5,10,63,1,4,AAPL,0.0,0.0,0.0,0.0,30.0,0.0,0.0,0.0,0.0,0.0,0.0,6.152311650723556,
2024-10-21T12:24:15.709004892Z,2024-10-21T12:24:15.708838775Z,10,2,38,C,A,2,234.03,27,130,166117,13013886,233.8,233.96,5,400,1,2,233.71,234.0,200,2,1,1,233.7,234.1,1200,100,1,1,233.66,234.13,31,400,2,1,233.58,234.17,505,1,2,1,233.53,234.25,10,100,1,1,233.5,234.41,100,500,1,1,233.45,234.43,15,105,1,2,233.4,234.5,110,63,2,4,233.39,234.75,10,1,1,1,AAPL,0.0,0.0,0.0,100.0,400.0,1.0,100.0,500.0,105.0,63.0,1.0,178.18464592804142,
2024-10-21T12:24:15.709139884Z,2024-10-21T12:24:15.708973640Z,10,2,38,A,A,1,233.98,29,130,166244,13013888,233.8,233.96,5,400,1,2,233.71,233.98,200,29,1,1,233.7,234.0,1200,2,1,1,233.66,234.1,31,100,2,1,233.58,234.13,505,400,2,1,233.53,234.17,10,1,1,1,233.5,234.25,100,100,1,1,233.45,234.41,15,500,1,1,233.4,234.43,110,105,2,2,233.39,234.5,10,63,1,4,AAPL,0.0,0.0,-2.0,-100.0,-400.0,-1.0,-100.0,-500.0,-105.0,-63.0,-1.0,-178.31147825369916,
2024-10-21T12:24:15.716746619Z,2024-10-21T12:24:15.716580295Z,10,2,38,C,A,1,233.98,29,130,166324,13013896,233.8,233.96,5,400,1,2,233.71,234.0,200,2,1,1,233.7,234.1,1200,100,1,1,233.66,234.13,31,400,2,1,233.58,234.17,505,1,2,1,233.53,234.25,10,100,1,1,233.5,234.41,100,500,1,1,233.45,234.43,15,105,1,2,233.4,234.5,110,63,2,4,233.39,234.75,10,1,1,1,AAPL,0.0,0.0,2.0,100.0,400.0,1.0,100.0,500.0,105.0,63.0,1.0,178.31147825369916,
2024-10-21T12:24:17.552123107Z,2024-10-21T12:24:17.551956961Z,10,2,38,A,A,2,234.03,27,130,166146,13015292,233.8,233.96,5,400,1,2,233.71,234.0,200,2,1,1,233.7,234.03,1200,27,1,1,233.66,234.1,31,100,2,1,233.58,234.13,505,400,2,1,233.53,234.17,10,1,1,1,233.5,234.25,100,100,1,1,233.45,234.41,15,500,1,1,233.4,234.43,110,105,2,2,233.39,234.5,10,63,1,4,AAPL,0.0,0.0,0.0,-100.0,-400.0,-1.0,-100.0,-500.0,-105.0,-63.0,-1.0,-178.18464592804142,
2024-10-21T12:24:18.858293636Z,2024-10-21T12:24:18.858127605Z,10,2,38,A,B,0,233.8,100,130,166031,13016509,233.8,233.96,105,400,2,2,233.71,234.0,200,2,1,1,233.7,234.03,1200,27,1,1,233.66,234.1,31,100,2,1,233.58,234.13,505,400,2,1,233.53,234.17,10,1,1,1,233.5,234.25,100,100,1,1,233.45,234.41,15,500,1,1,233.4,234.43,110,105,2,2,233.39,234.5,10,63,1,4,AAPL,100.0,100.0,0.0,0.0,0.0,0.0,0.0,0.0,0.0,0.0,0.0,1.9880582646125018,
2024-10-21T12:24:25.049504145Z,2024-10-21T12:24:25.049338154Z,10,2,38,C,A,2,234.03,27,130,165991,13021095,233.8,233.96,105,400,2,2,233.71,234.0,200,2,1,1,233.7,234.1,1200,100,1,1,233.66,234.13,31,400,2,1,233.58,234.17,505,1,2,1,233.53,234.25,10,100,1,1,233.5,234.41,100,500,1,1,233.45,234.43,15,105,1,2,233.4,234.5,110,63,2,4,233.39,234.75,10,1,1,1,AAPL,0.0,0.0,0.0,100.0,400.0,1.0,100.0,500.0,105.0,63.0,1.0,178.18464592804142,
2024-10-21T12:24:25.049548880Z,2024-10-21T12:24:25.049382422Z,10,2,38,A,A,1,233.98,28,130,166458,13021096,233.8,233.96,105,400,2,2,233.71,233.98,200,28,1,1,233.7,234.0,1200,2,1,1,233.66,234.1,31,100,2,1,233.58,234.13,505,400,2,1,233.53,234.17,10,1,1,1,233.5,234.25,100,100,1,1,233.45,234.41,15,500,1,1,233.4,234.43,110,105,2,2,233.39,234.5,10,63,1,4,AAPL,0.0,0.0,-2.0,-100.0,-400.0,-1.0,-100.0,-500.0,-105.0,-63.0,-1.0,-178.31147825369916,
2024-10-21T12:24:25.060245863Z,2024-10-21T12:24:25.060079940Z,10,2,38,C,A,1,233.98,28,130,165923,13021116,233.8,233.96,105,400,2,2,233.71,234.0,200,2,1,1,233.7,234.1,1200,100,1,1,233.66,234.13,31,400,2,1,233.58,234.17,505,1,2,1,233.53,234.25,10,100,1,1,233.5,234.41,100,500,1,1,233.45,234.43,15,105,1,2,233.4,234.5,110,63,2,4,233.39,234.75,10,1,1,1,AAPL,0.0,0.0,2.0,100.0,400.0,1.0,100.0,500.0,105.0,63.0,1.0,178.31147825369916,
2024-10-21T12:24:25.923090996Z,2024-10-21T12:24:25.922924503Z,10,2,38,A,A,2,234.03,26,130,166493,13021866,233.8,233.96,105,400,2,2,233.71,234.0,200,2,1,1,233.7,234.03,1200,26,1,1,233.66,234.1,31,100,2,1,233.58,234.13,505,400,2,1,233.53,234.17,10,1,1,1,233.5,234.25,100,100,1,1,233.45,234.41,15,500,1,1,233.4,234.43,110,105,2,2,233.39,234.5,10,63,1,4,AAPL,0.0,0.0,0.0,-100.0,-400.0,-1.0,-100.0,-500.0,-105.0,-63.0,-1.0,-178.18464592804142,
2024-10-21T12:24:33.385339105Z,2024-10-21T12:24:33.385173258Z,10,2,38,C,A,2,234.03,26,130,165847,13026898,233.8,233.96,105,400,2,2,233.71,234.0,200,2,1,1,233.7,234.1,1200,100,1,1,233.66,234.13,31,400,2,1,233.58,234.17,505,1,2,1,233.53,234.25,10,100,1,1,233.5,234.41,100,500,1,1,233.45,234.43,15,105,1,2,233.4,234.5,110,63,2,4,233.39,234.75,10,1,1,1,AAPL,0.0,0.0,0.0,100.0,400.0,1.0,100.0,500.0,105.0,63.0,1.0,178.18464592804142,
2024-10-21T12:24:33.385363270Z,2024-10-21T12:24:33.385196713Z,10,2,38,A,A,1,233.98,29,130,166557,13026899,233.8,233.96,105,400,2,2,233.71,233.98,200,29,1,1,233.7,234.0,1200,2,1,1,233.66,234.1,31,100,2,1,233.58,234.13,505,400,2,1,233.53,234.17,10,1,1,1,233.5,234.25,100,100,1,1,233.45,234.41,15,500,1,1,233.4,234.43,110,105,2,2,233.39,234.5,10,63,1,4,AAPL,0.0,0.0,-2.0,-100.0,-400.0,-1.0,-100.0,-500.0,-105.0,-63.0,-1.0,-178.31147825369916,
2024-10-21T12:24:33.391357628Z,2024-10-21T12:24:33.391191505Z,10,2,38,C,A,1,233.98,29,130,166123,13026904,233.8,233.96,105,400,2,2,233.71,234.0,200,2,1,1,233.7,234.1,1200,100,1,1,233.66,234.13,31,400,2,1,233.58,234.17,505,1,2,1,233.53,234.25,10,100,1,1,233.5,234.41,100,500,1,1,233.45,234.43,15,105,1,2,233.4,234.5,110,63,2,4,233.39,234.75,10,1,1,1,AAPL,0.0,0.0,2.0,100.0,400.0,1.0,100.0,500.0,105.0,63.0,1.0,178.31147825369916,
2024-10-21T12:24:33.923269202Z,2024-10-21T12:24:33.923102791Z,10,2,38,A,A,2,234.03,26,130,166411,13027549,233.8,233.96,105,400,2,2,233.71,234.0,200,2,1,1,233.7,234.03,1200,26,1,1,233.66,234.1,31,100,2,1,233.58,234.13,505,400,2,1,233.53,234.17,10,1,1,1,233.5,234.25,100,100,1,1,233.45,234.41,15,500,1,1,233.4,234.43,110,105,2,2,233.39,234.5,10,63,1,4,AAPL,0.0,0.0,0.0,-100.0,-400.0,-1.0,-100.0,-500.0,-105.0,-63.0,-1.0,-178.18464592804142,
2024-10-21T12:24:37.923110609Z,2024-10-21T12:24:37.922944460Z,10,2,38,C,A,2,234.03,26,130,166149,13030243,233.8,233.96,105,400,2,2,233.71,234.0,200,2,1,1,233.7,234.1,1200,100,1,1,233.66,234.13,31,400,2,1,233.58,234.17,505,1,2,1,233.53,234.25,10,100,1,1,233.5,234.41,100,500,1,1,233.45,234.43,15,105,1,2,233.4,234.5,110,63,2,4,233.39,234.75,10,1,1,1,AAPL,0.0,0.0,0.0,100.0,400.0,1.0,100.0,500.0,105.0,63.0,1.0,178.18464592804142,
2024-10-21T12:24:37.923194567Z,2024-10-21T12:24:37.923028006Z,10,2,38,A,A,1,233.98,27,130,166561,13030244,233.8,233.96,105,400,2,2,233.71,233.98,200,27,1,1,233.7,234.0,1200,2,1,1,233.66,234.1,31,100,2,1,233.58,234.13,505,400,2,1,233.53,234.17,10,1,1,1,233.5,234.25,100,100,1,1,233.45,234.41,15,500,1,1,233.4,234.43,110,105,2,2,233.39,234.5,10,63,1,4,AAPL,0.0,0.0,-2.0,-100.0,-400.0,-1.0,-100.0,-500.0,-105.0,-63.0,-1.0,-178.31147825369916,
2024-10-21T12:24:40.307842089Z,2024-10-21T12:24:40.307674730Z,10,2,38,T,N,0,233.84,127,130,167359,13031847,233.8,233.96,105,400,2,2,233.71,233.98,200,27,1,1,233.7,234.0,1200,2,1,1,233.66,234.1,31,100,2,1,233.58,234.13,505,400,2,1,233.53,234.17,10,1,1,1,233.5,234.25,100,100,1,1,233.45,234.41,15,500,1,1,233.4,234.43,110,105,2,2,233.39,234.5,10,63,1,4,AAPL,0.0,0.0,0.0,0.0,0.0,0.0,0.0,0.0,0.0,0.0,0.0,0.0,
2024-10-21T12:24:40.308161486Z,2024-10-21T12:24:40.307995193Z,10,2,38,A,B,0,233.8,2,130,166293,13031848,233.8,233.96,107,400,3,2,233.71,233.98,200,27,1,1,233.7,234.0,1200,2,1,1,233.66,234.1,31,100,2,1,233.58,234.13,505,400,2,1,233.53,234.17,10,1,1,1,233.5,234.25,100,100,1,1,233.45,234.41,15,500,1,1,233.4,234.43,110,105,2,2,233.39,234.5,10,63,1,4,AAPL,2.0,2.0,0.0,0.0,0.0,0.0,0.0,0.0,0.0,0.0,0.0,0.03976116529225004,
2024-10-21T12:24:40.308163000Z,2024-10-21T12:24:40.307996031Z,10,2,38,A,B,1,233.79,100,130,166969,13031849,233.8,233.96,107,400,3,2,233.79,233.98,100,27,1,1,233.71,234.0,200,2,1,1,233.7,234.1,1200,100,1,1,233.66,234.13,31,400,2,1,233.58,234.17,505,1,2,1,233.53,234.25,10,100,1,1,233.5,234.41,100,500,1,1,233.45,234.43,15,105,1,2,233.4,234.5,110,63,2,4,AAPL,0.0,0.0,100.0,200.0,1200.0,31.0,505.0,10.0,100.0,15.0,110.0,366.04727699510585,
2024-10-21T12:24:40.308173860Z,2024-10-21T12:24:40.308007727Z,10,2,38,C,B,0,233.8,2,130,166133,13031850,233.8,233.96,105,400,2,2,233.79,233.98,100,27,1,1,233.71,234.0,200,2,1,1,233.7,234.1,1200,100,1,1,233.66,234.13,31,400,2,1,233.58,234.17,505,1,2,1,233.53,234.25,10,100,1,1,233.5,234.41,100,500,1,1,233.45,234.43,15,105,1,2,233.4,234.5,110,63,2,4,AAPL,-2.0,-2.0,0.0,0.0,0.0,0.0,0.0,0.0,0.0,0.0,0.0,-0.03976116529225004,
2024-10-21T12:24:40.308191984Z,2024-10-21T12:24:40.308025276Z,10,2,38,C,A,0,233.96,200,130,166708,13031851,233.8,233.96,105,200,2,1,233.79,233.98,100,27,1,1,233.71,234.0,200,2,1,1,233.7,234.1,1200,100,1,1,233.66,234.13,31,400,2,1,233.58,234.17,505,1,2,1,233.53,234.25,10,100,1,1,233.5,234.41,100,500,1,1,233.45,234.43,15,105,1,2,233.4,234.5,110,63,2,4,AAPL,200.0,200.0,0.0,0.0,0.0,0.0,0.0,0.0,0.0,0.0,0.0,3.9761165292250036,
2024-10-21T12:24:40.308202091Z,2024-10-21T12:24:40.308036005Z,10,2,38,C,A,0,233.96,200,130,166086,13031852,233.8,233.98,105,27,2,1,233.79,234.0,100,2,1,1,233.71,234.1,200,100,1,1,233.7,234.13,1200,400,1,1,233.66,234.17,31,1,2,1,233.58,234.25,505,100,2,1,233.53,234.41,10,500,1,1,233.5,234.43,100,105,1,2,233.45,234.5,15,63,1,4,233.4,234.75,110,1,2,1,AAPL,27.0,27.0,2.0,100.0,400.0,1.0,100.0,500.0,105.0,63.0,1.0,178.84825398514457,
2024-10-21T12:24:40.308571346Z,2024-10-21T12:24:40.308405475Z,10,2,38,C,B,1,233.79,100,130,165871,13031857,233.8,233.98,105,27,2,1,233.71,234.0,200,2,1,1,233.7,234.1,1200,100,1,1,233.66,234.13,31,400,2,1,233.58,234.17,505,1,2,1,233.53,234.25,10,100,1,1,233.5,234.41,100,500,1,1,233.45,234.43,15,105,1,2,233.4,234.5,110,63,2,4,233.39,234.75,10,1,1,1,AAPL,0.0,0.0,-100.0,-200.0,-1200.0,-31.0,-505.0,-10.0,-100.0,-15.0,-110.0,-366.04727699510585,
2024-10-21T12:24:40.309914708Z,2024-10-21T12:24:40.309748359Z,10,2,38,A,B,1,233.79,100,130,166349,13031868,233.8,233.98,105,27,2,1,233.79,234.0,100,2,1,1,233.71,234.1,200,100,1,1,233.7,234.13,1200,400,1,1,233.66,234.17,31,1,2,1,233.58,234.25,505,100,2,1,233.53,234.41,10,500,1,1,233.5,234.43,100,105,1,2,233.45,234.5,15,63,1,4,233.4,234.75,110,1,2,1,AAPL,0.0,0.0,100.0,200.0,1200.0,31.0,505.0,10.0,100.0,15.0,110.0,366.04727699510585,
2024-10-21T12:24:40.310359600Z,2024-10-21T12:24:40.310193512Z,10,2,38,C,B,1,233.79,100,130,166088,13031873,233.8,233.98,105,27,2,1,233.71,234.0,200,2,1,1,233.7,234.1,1200,100,1,1,233.66,234.13,31,400,2,1,233.58,234.17,505,1,2,1,233.53,234.25,10,100,1,1,233.5,234.41,100,500,1,1,233.45,234.43,15,105,1,2,233.4,234.5,110,63,2,4,233.39,234.75,10,1,1,1,AAPL,0.0,0.0,-100.0,-200.0,-1200.0,-31.0,-505.0,-10.0,-100.0,-15.0,-110.0,-366.04727699510585,
2024-10-21T12:24:40.353976280Z,2024-10-21T12:24:40.353810051Z,10,2,38,A,A,0,233.96,200,130,166229,13031906,233.8,233.96,105,200,2,1,233.71,233.98,200,27,1,1,233.7,234.0,1200,2,1,1,233.66,234.1,31,100,2,1,233.58,234.13,505,400,2,1,233.53,234.17,10,1,1,1,233.5,234.25,100,100,1,1,233.45,234.41,15,500,1,1,233.4,234.43,110,105,2,2,233.39,234.5,10,63,1,4,AAPL,-27.0,-27.0,-2.0,-100.0,-400.0,-1.0,-100.0,-500.0,-105.0,-63.0,-1.0,-178.84825398514457,
2024-10-21T12:24:40.377414086Z,2024-10-21T12:24:40.377247665Z,10,2,38,C,A,0,233.96,200,130,166421,13031918,233.8,233.98,105,27,2,1,233.71,234.0,200,2,1,1,233.7,234.1,1200,100,1,1,233.66,234.13,31,400,2,1,233.58,234.17,505,1,2,1,233.53,234.25,10,100,1,1,233.5,234.41,100,500,1,1,233.45,234.43,15,105,1,2,233.4,234.5,110,63,2,4,233.39,234.75,10,1,1,1,AAPL,27.0,27.0,2.0,100.0,400.0,1.0,100.0,500.0,105.0,63.0,1.0,178.84825398514457,
2024-10-21T12:24:40.379975554Z,2024-10-21T12:24:40.379809120Z,10,2,38,C,A,0,233.98,27,130,166434,13031919,233.8,234.0,105,2,2,1,233.71,234.1,200,100,1,1,233.7,234.13,1200,400,1,1,233.66,234.17,31,1,2,1,233.58,234.25,505,100,2,1,233.53,234.41,10,500,1,1,233.5,234.43,100,105,1,2,233.45,234.5,15,63,1,4,233.4,234.75,110,1,2,1,233.39,234.79,10,2000,1,1,AAPL,2.0,2.0,100.0,400.0,1.0,100.0,500.0,105.0,63.0,1.0,2000.0,288.1899145792188,
2024-10-21T12:24:40.416037866Z,2024-10-21T12:24:40.415871461Z,10,2,38,A,A,1,234.02,200,130,166405,13031935,233.8,234.0,105,2,2,1,233.71,234.02,200,200,1,1,233.7,234.1,1200,100,1,1,233.66,234.13,31,400,2,1,233.58,234.17,505,1,2,1,233.53,234.25,10,100,1,1,233.5,234.41,100,500,1,1,233.45,234.43,15,105,1,2,233.4,234.5,110,63,2,4,233.39,234.75,10,1,1,1,AAPL,0.0,0.0,-100.0,-400.0,-1.0,-100.0,-500.0,-105.0,-63.0,-1.0,-2000.0,-288.15015341392655,
2024-10-21T12:24:40.464995283Z,2024-10-21T12:24:40.464828695Z,10,2,38,A,A,1,234.02,200,130,166588,13031977,233.8,234.0,105,2,2,1,233.71,234.02,200,400,1,2,233.7,234.1,1200,100,1,1,233.66,234.13,31,400,2,1,233.58,234.17,505,1,2,1,233.53,234.25,10,100,1,1,233.5,234.41,100,500,1,1,233.45,234.43,15,105,1,2,233.4,234.5,110,63,2,4,233.39,234.75,10,1,1,1,AAPL,0.0,0.0,-200.0,0.0,0.0,0.0,0.0,0.0,0.0,0.0,0.0,-12.683232565773917,
2024-10-21T12:24:40.657004232Z,2024-10-21T12:24:40.656837789Z,10,2,38,C,B,1,233.71,200,130,166443,13032132,233.8,234.0,105,2,2,1,233.7,234.02,1200,400,1,2,233.66,234.1,31,100,2,1,233.58,234.13,505,400,2,1,233.53,234.17,10,1,1,1,233.5,234.25,100,100,1,1,233.45,234.41,15,500,1,1,233.4,234.43,110,105,2,2,233.39,234.5,10,63,1,4,233.31,234.75,110,1,2,1,AAPL,0.0,0.0,-200.0,-1200.0,-31.0,-505.0,-10.0,-100.0,-15.0,-110.0,-10.0,-222.3526165116335,
2024-10-21T12:24:40.763757375Z,2024-10-21T12:24:40.763590881Z,10,2,38,A,B,1,233.71,200,130,166494,13032319,233.8,234.0,105,2,2,1,233.71,234.02,200,400,1,2,233.7,234.1,1200,100,1,1,233.66,234.13,31,400,2,1,233.58,234.17,505,1,2,1,233.53,234.25,10,100,1,1,233.5,234.41,100,500,1,1,233.45,234.43,15,105,1,2,233.4,234.5,110,63,2,4,233.39,234.75,10,1,1,1,AAPL,0.0,0.0,200.0,1200.0,31.0,505.0,10.0,100.0,15.0,110.0,10.0,222.3526165116335,
2024-10-21T12:24:43.066523534Z,2024-10-21T12:24:43.066357159Z,10,2,38,A,B,0,233.88,1,130,166375,13033852,233.88,234.0,1,2,1,1,233.8,234.02,105,400,2,2,233.71,234.1,200,100,1,1,233.7,234.13,1200,400,1,1,233.66,234.17,31,1,2,1,233.58,234.25,505,100,2,1,233.53,234.41,10,500,1,1,233.5,234.43,100,105,1,2,233.45,234.5,15,63,1,4,233.4,234.75,110,1,2,1,AAPL,1.0,1.0,105.0,200.0,1200.0,31.0,505.0,10.0,100.0,15.0,110.0,366.3842383918963,
2024-10-21T12:24:43.129607008Z,2024-10-21T12:24:43.129440388Z,10,2,38,A,A,2,234.09,27,130,166620,13033910,233.88,234.0,1,2,1,1,233.8,234.02,105,400,2,2,233.71,234.09,200,27,1,1,233.7,234.1,1200,100,1,1,233.66,234.13,31,400,2,1,233.58,234.17,505,1,2,1,233.53,234.25,10,100,1,1,233.5,234.41,100,500,1,1,233.45,234.43,15,105,1,2,233.4,234.5,110,63,2,4,AAPL,0.0,0.0,0.0,-100.0,-400.0,-1.0,-100.0,-500.0,-105.0,-63.0,-1.0,-178.18464592804142,
2024-10-21T12:24:55.150110202Z,2024-10-21T12:24:55.149943017Z,10,2,38,T,A,0,233.88,1,130,167185,13042533,233.88,234.0,1,2,1,1,233.8,234.02,105,400,2,2,233.71,234.09,200,27,1,1,233.7,234.1,1200,100,1,1,233.66,234.13,31,400,2,1,233.58,234.17,505,1,2,1,233.53,234.25,10,100,1,1,233.5,234.41,100,500,1,1,233.45,234.43,15,105,1,2,233.4,234.5,110,63,2,4,AAPL,0.0,0.0,0.0,0.0,0.0,0.0,0.0,0.0,0.0,0.0,0.0,0.0,
2024-10-21T12:24:55.150110202Z,2024-10-21T12:24:55.149943017Z,10,2,38,C,B,0,233.88,1,130,167185,13042533,233.8,234.0,105,2,2,1,233.71,234.02,200,400,1,2,233.7,234.09,1200,27,1,1,233.66,234.1,31,100,2,1,233.58,234.13,505,400,2,1,233.53,234.17,10,1,1,1,233.5,234.25,100,100,1,1,233.45,234.41,15,500,1,1,233.4,234.43,110,105,2,2,233.39,234.5,10,63,1,4,AAPL,-1.0,-1.0,-105.0,-200.0,-1200.0,-31.0,-505.0,-10.0,-100.0,-15.0,-110.0,-366.3842383918963,
2024-10-21T12:24:55.150138721Z,2024-10-21T12:24:55.149972348Z,10,2,38,A,A,0,233.94,38,130,166373,13042534,233.8,233.94,105,38,2,1,233.71,234.0,200,2,1,1,233.7,234.02,1200,400,1,2,233.66,234.09,31,27,2,1,233.58,234.1,505,100,2,1,233.53,234.13,10,400,1,1,233.5,234.17,100,1,1,1,233.45,234.25,15,100,1,1,233.4,234.41,110,500,2,1,233.39,234.43,10,105,1,2,AAPL,-2.0,-2.0,-400.0,-27.0,-100.0,-400.0,-1.0,-100.0,-500.0,-105.0,-63.0,-169.31107029934645,
2024-10-21T12:24:55.150156298Z,2024-10-21T12:24:55.149990092Z,10,2,38,A,A,0,233.94,26,130,166206,13042535,233.8,233.94,105,64,2,2,233.71,234.0,200,2,1,1,233.7,234.02,1200,400,1,2,233.66,234.09,31,27,2,1,233.58,234.1,505,100,2,1,233.53,234.13,10,400,1,1,233.5,234.17,100,1,1,1,233.45,234.25,15,100,1,1,233.4,234.41,110,500,2,1,233.39,234.43,10,105,1,2,AAPL,-26.0,-26.0,0.0,0.0,0.0,0.0,0.0,0.0,0.0,0.0,0.0,-0.5168951487992505,
2024-10-21T12:24:55.150170265Z,2024-10-21T12:24:55.150004189Z,10,2,38,A,A,1,233.98,26,130,166076,13042536,233.8,233.94,105,64,2,2,233.71,233.98,200,26,1,1,233.7,234.0,1200,2,1,1,233.66,234.02,31,400,2,2,233.58,234.09,505,27,2,1,233.53,234.1,10,100,1,1,233.5,234.13,100,400,1,1,233.45,234.17,15,1,1,1,233.4,234.25,110,100,2,1,233.39,234.41,10,500,1,1,AAPL,0.0,0.0,-2.0,-400.0,-27.0,-100.0,-400.0,-1.0,-100.0,-500.0,-105.0,-165.4063121850704,
2024-10-21T12:24:55.250218188Z,2024-10-21T12:24:55.250051974Z,10,2,38,C,A,0,233.94,38,130,166214,13042633,233.8,233.94,105,26,2,1,233.71,233.98,200,26,1,1,233.7,234.0,1200,2,1,1,233.66,234.02,31,400,2,2,233.58,234.09,505,27,2,1,233.53,234.1,10,100,1,1,233.5,234.13,100,400,1,1,233.45,234.17,15,1,1,1,233.4,234.25,110,100,2,1,233.39,234.41,10,500,1,1,AAPL,38.0,38.0,0.0,0.0,0.0,0.0,0.0,0.0,0.0,0.0,0.0,0.7554621405527507,
2024-10-21T12:24:55.250245636Z,2024-10-21T12:24:55.250079517Z,10,2,38,C,A,1,233.98,26,130,166119,13042634,233.8,233.94,105,26,2,1,233.71,234.0,200,2,1,1,233.7,234.02,1200,400,1,2,233.66,234.09,31,27,2,1,233.58,234.1,505,100,2,1,233.53,234.13,10,400,1,1,233.5,234.17,100,1,1,1,233.45,234.25,15,100,1,1,233.4,234.41,110,500,2,1,233.39,234.43,10,105,1,2,AAPL,0.0,0.0,2.0,400.0,27.0,100.0,400.0,1.0,100.0,500.0,105.0,165.4063121850704,
2024-10-21T12:24:55.403930872Z,2024-10-21T12:24:55.403764807Z,10,2,38,C,A,0,233.94,26,130,166065,13042985,233.8,234.0,105,2,2,1,233.71,234.02,200,400,1,2,233.7,234.09,1200,27,1,1,233.66,234.1,31,100,2,1,233.58,234.13,505,400,2,1,233.53,234.17,10,1,1,1,233.5,234.25,100,100,1,1,233.45,234.41,15,500,1,1,233.4,234.43,110,105,2,2,233.39,234.5,10,63,1,4,AAPL,2.0,2.0,400.0,27.0,100.0,400.0,1.0,100.0,500.0,105.0,63.0,169.31107029934645,
2024-10-21T12:24:58.867150506Z,2024-10-21T12:24:58.866984470Z,10,2,38,A,A,0,233.95,200,130,166036,13044827,233.8,233.95,105,200,2,1,233.71,234.0,200,2,1,1,233.7,234.02,1200,400,1,2,233.66,234.09,31,27,2,1,233.58,234.1,505,100,2,1,233.53,234.13,10,400,1,1,233.5,234.17,100,1,1,1,233.45,234.25,15,100,1,1,233.4,234.41,110,500,2,1,233.39,234.43,10,105,1,2,AAPL,-2.0,-2.0,-400.0,-27.0,-100.0,-400.0,-1.0,-100.0,-500.0,-105.0,-63.0,-169.31107029934645,
2024-10-21T12:25:00.039367879Z,2024-10-21T12:25:00.039201756Z,10,2,38,C,A,3,234.09,27,130,166123,13045779,233.8,233.95,105,200,2,1,233.71,234.0,200,2,1,1,233.7,234.02,1200,400,1,2,233.66,234.1,31,100,2,1,233.58,234.13,505,400,2,1,233.53,234.17,10,1,1,1,233.5,234.25,100,100,1,1,233.45,234.41,15,500,1,1,233.4,234.43,110,105,2,2,233.39,234.5,10,63,1,4,AAPL,0.0,0.0,0.0,0.0,100.0,400.0,1.0,100.0,500.0,105.0,63.0,141.16211432263424,
2024-10-21T12:25:00.039422307Z,2024-10-21T12:25:00.039255807Z,10,2,38,C,B,3,233.66,30,130,166500,13045782,233.8,233.95,105,200,2,1,233.71,234.0,200,2,1,1,233.7,234.02,1200,400,1,2,233.66,234.1,1,100,1,1,233.58,234.13,505,400,2,1,233.53,234.17,10,1,1,1,233.5,234.25,100,100,1,1,233.45,234.41,15,500,1,1,233.4,234.43,110,105,2,2,233.39,234.5,10,63,1,4,AAPL,0.0,0.0,0.0,0.0,-30.0,0.0,0.0,0.0,0.0,0.0,0.0,-6.152311650723556,
2024-10-21T12:25:00.940467712Z,2024-10-21T12:25:00.940301280Z,10,2,38,A,B,0,233.81,1,130,166432,13048050,233.81,233.95,1,200,1,1,233.8,234.0,105,2,2,1,233.71,234.02,200,400,1,2,233.7,234.1,1200,100,1,1,233.66,234.13,1,400,1,1,233.58,234.17,505,1,2,1,233.53,234.25,10,100,1,1,233.5,234.41,100,500,1,1,233.45,234.43,15,105,1,2,233.4,234.5,110,63,2,4,AAPL,1.0,1.0,105.0,200.0,1200.0,1.0,505.0,10.0,100.0,15.0,110.0,362.8926077717207,
2024-10-21T12:25:03.426126208Z,2024-10-21T12:25:03.425959742Z,10,2,38,A,A,1,233.97,7,130,166466,13052492,233.81,233.95,1,200,1,1,233.8,233.97,105,7,2,1,233.71,234.0,200,2,1,1,233.7,234.02,1200,400,1,2,233.66,234.1,1,100,1,1,233.58,234.13,505,400,2,1,233.53,234.17,10,1,1,1,233.5,234.25,100,100,1,1,233.45,234.41,15,500,1,1,233.4,234.43,110,105,2,2,AAPL,0.0,0.0,-2.0,-400.0,-100.0,-400.0,-1.0,-100.0,-500.0,-105.0,-63.0,-181.92197894269407,
2024-10-21T12:25:07.929188046Z,2024-10-21T12:25:07.929021771Z,10,2,38,C,A,3,234.02,200,130,166275,13057385,233.81,233.95,1,200,1,1,233.8,233.97,105,7,2,1,233.71,234.0,200,2,1,1,233.7,234.02,1200,200,1,1,233.66,234.1,1,100,1,1,233.58,234.13,505,400,2,1,233.53,234.17,10,1,1,1,233.5,234.25,100,100,1,1,233.45,234.41,15,500,1,1,233.4,234.43,110,105,2,2,AAPL,0.0,0.0,0.0,0.0,200.0,0.0,0.0,0.0,0.0,0.0,0.0,41.015411004823704,
2024-10-21T12:25:07.929203389Z,2024-10-21T12:25:07.929036599Z,10,2,38,A,A,3,234.01,400,130,166790,13057386,233.81,233.95,1,200,1,1,233.8,233.97,105,7,2,1,233.71,234.0,200,2,1,1,233.7,234.01,1200,400,1,1,233.66,234.1,1,100,1,1,233.58,234.13,505,400,2,1,233.53,234.17,10,1,1,1,233.5,234.25,100,100,1,1,233.45,234.41,15,500,1,1,233.4,234.43,110,105,2,2,AAPL,0.0,0.0,0.0,0.0,-200.0,0.0,0.0,0.0,0.0,0.0,0.0,-41.015411004823704,
2024-10-21T12:25:08.719128994Z,2024-10-21T12:25:08.718962947Z,10,2,38,C,A,1,233.97,7,130,166047,13057965,233.81,233.95,1,200,1,1,233.8,234.0,105,2,2,1,233.71,234.01,200,400,1,1,233.7,234.1,1200,100,1,1,233.66,234.13,1,400,1,1,233.58,234.17,505,1,2,1,233.53,234.25,10,100,1,1,233.5,234.41,100,500,1,1,233.45,234.43,15,105,1,2,233.4,234.5,110,63,2,4,AAPL,0.0,0.0,2.0,400.0,100.0,400.0,1.0,100.0,500.0,105.0,63.0,181.92197894269407,
2024-10-21T12:25:08.828580021Z,2024-10-21T12:25:08.828413687Z,10,2,38,A,B,0,233.85,100,130,166334,13058052,233.85,233.95,100,200,1,1,233.81,234.0,1,2,1,1,233.8,234.01,105,400,2,1,233.71,234.1,200,100,1,1,233.7,234.13,1200,400,1,1,233.66,234.17,1,1,1,1,233.58,234.25,505,100,2,1,233.53,234.41,10,500,1,1,233.5,234.43,100,105,1,2,233.45,234.5,15,63,1,4,AAPL,100.0,100.0,1.0,105.0,200.0,1200.0,1.0,505.0,10.0,100.0,15.0,260.1215570843918,
2024-10-21T12:25:09.010032581Z,2024-10-21T12:25:09.009866477Z,10,2,38,C,B,3,233.71,200,130,166104,13058226,233.85,233.95,100,200,1,1,233.81,234.0,1,2,1,1,233.8,234.01,105,400,2,1,233.7,234.1,1200,100,1,1,233.66,234.13,1,400,1,1,233.58,234.17,505,1,2,1,233.53,234.25,10,100,1,1,233.5,234.41,100,500,1,1,233.45,234.43,15,105,1,2,233.4,234.5,110,63,2,4,AAPL,0.0,0.0,0.0,0.0,-200.0,-1200.0,-1.0,-505.0,-10.0,-100.0,-15.0,-247.40391167966987,
2024-10-21T12:25:09.010056790Z,2024-10-21T12:25:09.009890544Z,10,2,38,A,B,4,233.69,200,130,166246,13058227,233.85,233.95,100,200,1,1,233.81,234.0,1,2,1,1,233.8,234.01,105,400,2,1,233.7,234.1,1200,100,1,1,233.69,234.13,200,400,1,1,233.66,234.17,1,1,1,1,233.58,234.25,505,100,2,1,233.53,234.41,10,500,1,1,233.5,234.43,100,105,1,2,233.45,234.5,15,63,1,4,AAPL,0.0,0.0,0.0,0.0,0.0,200.0,1.0,505.0,10.0,100.0,15.0,90.00081333565862,
2024-10-21T12:25:09.088943398Z,2024-10-21T12:25:09.088777165Z,10,2,38,A,B,4,233.69,200,130,166233,13058312,233.85,233.95,100,200,1,1,233.81,234.0,1,2,1,1,233.8,234.01,105,400,2,1,233.7,234.1,1200,100,1,1,233.69,234.13,400,400,2,1,233.66,234.17,1,1,1,1,233.58,234.25,505,100,2,1,233.53,234.41,10,500,1,1,233.5,234.43,100,105,1,2,233.45,234.5,15,63,1,4,AAPL,0.0,0.0,0.0,0.0,0.0,200.0,0.0,0.0,0.0,0.0,0.0,23.27753746783751,
2024-10-21T12:25:09.146843023Z,2024-10-21T12:25:09.146677151Z,10,2,38,C,B,4,233.69,200,130,165872,13058371,233.85,233.95,100,200,1,1,233.81,234.0,1,2,1,1,233.8,234.01,105,400,2,1,233.7,234.1,1200,100,1,1,233.69,234.13,200,400,1,1,233.66,234.17,1,1,1,1,233.58,234.25,505,100,2,1,233.53,234.41,10,500,1,1,233.5,234.43,100,105,1,2,233.45,234.5,15,63,1,4,AAPL,0.0,0.0,0.0,0.0,0.0,-200.0,0.0,0.0,0.0,0.0,0.0,-23.27753746783751,
2024-10-21T12:25:09.146855993Z,2024-10-21T12:25:09.146689798Z,10,2,38,A,B,3,233.72,400,130,166195,13058372,233.85,233.95,100,200,1,1,233.81,234.0,1,2,1,1,233.8,234.01,105,400,2,1,233.72,234.1,400,100,1,1,233.7,234.13,1200,400,1,1,233.66,234.17,1,1,1,1,233.58,234.25,505,100,2,1,233.53,234.41,10,500,1,1,233.5,234.43,100,105,1,2,233.45,234.5,15,63,1,4,AAPL,0.0,0.0,0.0,0.0,400.0,1200.0,0.0,0.0,0.0,0.0,0.0,221.69604681667246,
2024-10-21T12:25:09.325402278Z,2024-10-21T12:25:09.325236301Z,10,2,38,C,B,3,233.72,400,130,165977,13058695,233.85,233.95,100,200,1,1,233.81,234.0,1,2,1,1,233.8,234.01,105,400,2,1,233.7,234.1,1200,100,1,1,233.66,234.13,1,400,1,1,233.58,234.17,505,1,2,1,233.53,234.25,10,100,1,1,233.5,234.41,100,500,1,1,233.45,234.43,15,105,1,2,233.4,234.5,110,63,2,4,AAPL,0.0,0.0,0.0,0.0,-400.0,-1200.0,-1.0,-505.0,-10.0,-100.0,-15.0,-288.4193226844936,
2024-10-21T12:25:09.325415366Z,2024-10-21T12:25:09.325248668Z,10,2,38,A,B,4,233.69,200,130,166698,13058696,233.85,233.95,100,200,1,1,233.81,234.0,1,2,1,1,233.8,234.01,105,400,2,1,233.7,234.1,1200,100,1,1,233.69,234.13,200,400,1,1,233.66,234.17,1,1,1,1,233.58,234.25,505,100,2,1,233.53,234.41,10,500,1,1,233.5,234.43,100,105,1,2,233.45,234.5,15,63,1,4,AAPL,0.0,0.0,0.0,0.0,0.0,200.0,1.0,505.0,10.0,100.0,15.0,90.00081333565862,
2024-10-21T12:25:09.630196737Z,2024-10-21T12:25:09.630030450Z,10,2,38,A,B,4,233.69,200,130,166287,13059010,233.85,233.95,100,200,1,1,233.81,234.0,1,2,1,1,233.8,234.01,105,400,2,1,233.7,234.1,1200,100,1,1,233.69,234.13,400,400,2,1,233.66,234.17,1,1,1,1,233.58,234.25,505,100,2,1,233.53,234.41,10,500,1,1,233.5,234.43,100,105,1,2,233.45,234.5,15,63,1,4,AAPL,0.0,0.0,0.0,0.0,0.0,200.0,0.0,0.0,0.0,0.0,0.0,23.27753746783751,
2024-10-21T12:25:09.684458949Z,2024-10-21T12:25:09.684292780Z,10,2,38,C,B,4,233.69,200,130,166169,13059061,233.85,233.95,100,200,1,1,233.81,234.0,1,2,1,1,233.8,234.01,105,400,2,1,233.7,234.1,1200,100,1,1,233.69,234.13,200,400,1,1,233.66,234.17,1,1,1,1,233.58,234.25,505,100,2,1,233.53,234.41,10,500,1,1,233.5,234.43,100,105,1,2,233.45,234.5,15,63,1,4,AAPL,0.0,0.0,0.0,0.0,0.0,-200.0,0.0,0.0,0.0,0.0,0.0,-23.27753746783751,
2024-10-21T12:25:09.684472400Z,2024-10-21T12:25:09.684305729Z,10,2,38,A,B,3,233.72,400,130,166671,13059062,233.85,233.95,100,200,1,1,233.81,234.0,1,2,1,1,233.8,234.01,105,400,2,1,233.72,234.1,400,100,1,1,233.7,234.13,1200,400,1,1,233.66,234.17,1,1,1,1,233.58,234.25,505,100,2,1,233.53,234.41,10,500,1,1,233.5,234.43,100,105,1,2,233.45,234.5,15,63,1,4,AAPL,0.0,0.0,0.0,0.0,400.0,1200.0,0.0,0.0,0.0,0.0,0.0,221.69604681667246,
2024-10-21T12:25:10.726294001Z,2024-10-21T12:25:10.726127491Z,10,2,38,A,A,1,233.98,7,130,166510,13060271,233.85,233.95,100,200,1,1,233.81,233.98,1,7,1,1,233.8,234.0,105,2,2,1,233.72,234.01,400,400,1,1,233.7,234.1,1200,100,1,1,233.66,234.13,1,400,1,1,233.58,234.17,505,1,2,1,233.53,234.25,10,100,1,1,233.5,234.41,100,500,1,1,233.45,234.43,15,105,1,2,AAPL,0.0,0.0,-2.0,-400.0,-100.0,-400.0,-1.0,-100.0,-500.0,-105.0,-63.0,-181.92197894269407,
2024-10-21T12:25:16.348450351Z,2024-10-21T12:25:16.348283664Z,10,2,38,A,B,3,233.77,200,130,166687,13064852,233.85,233.95,100,200,1,1,233.81,233.98,1,7,1,1,233.8,234.0,105,2,2,1,233.77,234.01,200,400,1,1,233.7,234.1,1200,100,1,1,233.66,234.13,1,400,1,1,233.58,234.17,505,1,2,1,233.53,234.25,10,100,1,1,233.5,234.41,100,500,1,1,233.45,234.43,15,105,1,2,AAPL,0.0,0.0,0.0,0.0,200.0,0.0,0.0,0.0,0.0,0.0,0.0,41.015411004823704,
2024-10-21T12:25:25.279574162Z,2024-10-21T12:25:25.279408267Z,10,2,38,C,B,3,233.77,200,130,165895,13072236,233.85,233.95,100,200,1,1,233.81,233.98,1,7,1,1,233.8,234.0,105,2,2,1,233.7,234.01,1200,400,1,1,233.66,234.1,1,100,1,1,233.58,234.13,505,400,2,1,233.53,234.17,10,1,1,1,233.5,234.25,100,100,1,1,233.45,234.41,15,500,1,1,233.4,234.43,110,105,2,2,AAPL,0.0,0.0,0.0,0.0,-200.0,-1200.0,-1.0,-505.0,-10.0,-100.0,-15.0,-247.40391167966987,
2024-10-21T12:25:25.279586508Z,2024-10-21T12:25:25.279420038Z,10,2,38,A,B,3,233.75,200,130,166470,13072237,233.85,233.95,100,200,1,1,233.81,233.98,1,7,1,1,233.8,234.0,105,2,2,1,233.75,234.01,200,400,1,1,233.7,234.1,1200,100,1,1,233.66,234.13,1,400,1,1,233.58,234.17,505,1,2,1,233.53,234.25,10,100,1,1,233.5,234.41,100,500,1,1,233.45,234.43,15,105,1,2,AAPL,0.0,0.0,0.0,0.0,200.0,1200.0,1.0,505.0,10.0,100.0,15.0,247.40391167966987,
2024-10-21T12:25:25.341710080Z,2024-10-21T12:25:25.341543400Z,10,2,38,A,A,2,234.0,400,130,166680,13072382,233.85,233.95,100,200,1,1,233.81,233.98,1,7,1,1,233.8,234.0,105,402,2,2,233.75,234.1,200,100,1,1,233.7,234.13,1200,400,1,1,233.66,234.17,1,1,1,1,233.58,234.25,505,100,2,1,233.53,234.41,10,500,1,1,233.5,234.43,100,105,1,2,233.45,234.5,15,63,1,4,AAPL,0.0,0.0,0.0,-400.0,100.0,400.0,1.0,100.0,500.0,105.0,63.0,100.52908202823214,
2024-10-21T12:25:26.789385215Z,2024-10-21T12:25:26.789218710Z,10,2,38,A,A,2,233.99,400,130,166505,13074488,233.85,233.95,100,200,1,1,233.81,233.98,1,7,1,1,233.8,233.99,105,400,2,1,233.75,234.0,200,2,1,1,233.7,234.1,1200,100,1,1,233.66,234.13,1,400,1,1,233.58,234.17,505,1,2,1,233.53,234.25,10,100,1,1,233.5,234.41,100,500,1,1,233.45,234.43,15,105,1,2,AAPL,0.0,0.0,0.0,-402.0,-100.0,-400.0,-1.0,-100.0,-500.0,-105.0,-63.0,-181.9983117785083,
2024-10-21T12:25:34.806070616Z,2024-10-21T12:25:34.805904261Z,10,2,38,A,B,0,233.86,4,130,166355,13082761,233.86,233.95,4,200,1,1,233.85,233.98,100,7,1,1,233.81,233.99,1,400,1,1,233.8,234.0,105,2,2,1,233.75,234.1,200,100,1,1,233.7,234.13,1200,400,1,1,233.66,234.17,1,1,1,1,233.58,234.25,505,100,2,1,233.53,234.41,10,500,1,1,233.5,234.43,100,105,1,2,AAPL,4.0,4.0,100.0,1.0,105.0,200.0,1200.0,1.0,505.0,10.0,100.0,275.7901036286365,
2024-10-21T12:25:34.806829112Z,2024-10-21T12:25:34.806661445Z,10,2,38,C,B,0,233.86,4,130,167667,13082762,233.85,233.95,100,200,1,1,233.81,233.98,1,7,1,1,233.8,233.99,105,400,2,1,233.75,234.0,200,2,1,1,233.7,234.1,1200,100,1,1,233.66,234.13,1,400,1,1,233.58,234.17,505,1,2,1,233.53,234.25,10,100,1,1,233.5,234.41,100,500,1,1,233.45,234.43,15,105,1,2,AAPL,-4.0,-4.0,-100.0,-1.0,-105.0,-200.0,-1200.0,-1.0,-505.0,-10.0,-100.0,-275.7901036286365,
2024-10-21T12:25:34.807157514Z,2024-10-21T12:25:34.806990464Z,10,2,38,T,N,0,233.93,100,130,167050,13082763,233.85,233.95,100,200,1,1,233.81,233.98,1,7,1,1,233.8,233.99,105,400,2,1,233.75,234.0,200,2,1,1,233.7,234.1,1200,100,1,1,233.66,234.13,1,400,1,1,233.58,234.17,505,1,2,1,233.53,234.25,10,100,1,1,233.5,234.41,100,500,1,1,233.45,234.43,15,105,1,2,AAPL,0.0,0.0,0.0,0.0,0.0,0.0,0.0,0.0,0.0,0.0,0.0,0.0,
2024-10-21T12:25:35.054650784Z,2024-10-21T12:25:35.054480586Z,10,2,38,C,A,0,233.95,79,130,170198,13083005,233.85,233.95,100,121,1,1,233.81,233.98,1,7,1,1,233.8,233.99,105,400,2,1,233.75,234.0,200,2,1,1,233.7,234.1,1200,100,1,1,233.66,234.13,1,400,1,1,233.58,234.17,505,1,2,1,233.53,234.25,10,100,1,1,233.5,234.41,100,500,1,1,233.45,234.43,15,105,1,2,AAPL,79.0,79.0,0.0,0.0,0.0,0.0,0.0,0.0,0.0,0.0,0.0,1.5705660290438765,
2024-10-21T12:25:35.054650784Z,2024-10-21T12:25:35.054480586Z,10,2,38,T,B,0,233.95,79,130,170198,13083005,233.85,233.95,100,200,1,1,233.81,233.98,1,7,1,1,233.8,233.99,105,400,2,1,233.75,234.0,200,2,1,1,233.7,234.1,1200,100,1,1,233.66,234.13,1,400,1,1,233.58,234.17,505,1,2,1,233.53,234.25,10,100,1,1,233.5,234.41,100,500,1,1,233.45,234.43,15,105,1,2,AAPL,-79.0,-79.0,0.0,0.0,0.0,0.0,0.0,0.0,0.0,0.0,0.0,-1.5705660290438765,
2024-10-21T12:25:35.054650784Z,2024-10-21T12:25:35.054480586Z,10,2,38,T,N,0,233.91,101,0,170198,13083003,233.85,233.95,100,200,1,1,233.81,233.98,1,7,1,1,233.8,233.99,105,400,2,1,233.75,234.0,200,2,1,1,233.7,234.1,1200,100,1,1,233.66,234.13,1,400,1,1,233.58,234.17,505,1,2,1,233.53,234.25,10,100,1,1,233.5,234.41,100,500,1,1,233.45,234.43,15,105,1,2,AAPL,0.0,0.0,0.0,0.0,0.0,0.0,0.0,0.0,0.0,0.0,0.0,0.0,
2024-10-21T12:25:35.054650784Z,2024-10-21T12:25:35.054480586Z,10,2,38,T,N,0,233.93,50,0,170198,13083004,233.85,233.95,100,200,1,1,233.81,233.98,1,7,1,1,233.8,233.99,105,400,2,1,233.75,234.0,200,2,1,1,233.7,234.1,1200,100,1,1,233.66,234.13,1,400,1,1,233.58,234.17,505,1,2,1,233.53,234.25,10,100,1,1,233.5,234.41,100,500,1,1,233.45,234.43,15,105,1,2,AAPL,0.0,0.0,0.0,0.0,0.0,0.0,0.0,0.0,0.0,0.0,0.0,0.0,
2024-10-21T12:25:35.054724289Z,2024-10-21T12:25:35.054558163Z,10,2,38,C,A,2,233.99,400,130,166126,13083006,233.85,233.95,100,121,1,1,233.81,233.98,1,7,1,1,233.8,234.0,105,2,2,1,233.75,234.1,200,100,1,1,233.7,234.13,1200,400,1,1,233.66,234.17,1,1,1,1,233.58,234.25,505,100,2,1,233.53,234.41,10,500,1,1,233.5,234.43,100,105,1,2,233.45,234.5,15,63,1,4,AAPL,79.0,79.0,0.0,2.0,100.0,400.0,1.0,100.0,500.0,105.0,63.0,142.93584551315013,
2024-10-21T12:25:35.065068431Z,2024-10-21T12:25:35.064902310Z,10,2,38,A,A,2,234.0,200,130,166121,13083015,233.85,233.95,100,121,1,1,233.81,233.98,1,7,1,1,233.8,234.0,105,202,2,2,233.75,234.1,200,100,1,1,233.7,234.13,1200,400,1,1,233.66,234.17,1,1,1,1,233.58,234.25,505,100,2,1,233.53,234.41,10,500,1,1,233.5,234.43,100,105,1,2,233.45,234.5,15,63,1,4,AAPL,0.0,0.0,0.0,-200.0,0.0,0.0,0.0,0.0,0.0,0.0,0.0,-20.31651614720104,
2024-10-21T12:25:35.147837274Z,2024-10-21T12:25:35.147671307Z,10,2,38,A,A,2,234.0,200,130,165967,13083092,233.85,233.95,100,121,1,1,233.81,233.98,1,7,1,1,233.8,234.0,105,402,2,3,233.75,234.1,200,100,1,1,233.7,234.13,1200,400,1,1,233.66,234.17,1,1,1,1,233.58,234.25,505,100,2,1,233.53,234.41,10,500,1,1,233.5,234.43,100,105,1,2,233.45,234.5,15,63,1,4,AAPL,0.0,0.0,0.0,-200.0,0.0,0.0,0.0,0.0,0.0,0.0,0.0,-20.31651614720104,
2024-10-21T12:25:37.149278847Z,2024-10-21T12:25:37.149112390Z,10,2,38,C,A,1,233.98,7,130,166457,13084951,233.85,233.95,100,121,1,1,233.81,234.0,1,402,1,3,233.8,234.1,105,100,2,1,233.75,234.13,200,400,1,1,233.7,234.17,1200,1,1,1,233.66,234.25,1,100,1,1,233.58,234.41,505,500,2,1,233.53,234.43,10,105,1,2,233.5,234.5,100,63,1,4,233.45,234.59,15,60,1,1,AAPL,0.0,0.0,402.0,100.0,400.0,1.0,100.0,500.0,105.0,63.0,60.0,207.86823550830258,
2024-10-21T12:25:39.151956133Z,2024-10-21T12:25:39.151789847Z,10,2,38,A,A,8,234.44,7,130,166286,13087130,233.85,233.95,100,121,1,1,233.81,234.0,1,402,1,3,233.8,234.1,105,100,2,1,233.75,234.13,200,400,1,1,233.7,234.17,1200,1,1,1,233.66,234.25,1,100,1,1,233.58,234.41,505,500,2,1,233.53,234.43,10,105,1,2,233.5,234.44,100,7,1,1,233.45,234.5,15,63,1,4,AAPL,0.0,0.0,0.0,0.0,0.0,0.0,0.0,0.0,0.0,-63.0,-60.0,-8.628552761311305,
2024-10-21T12:25:43.597553367Z,2024-10-21T12:25:43.597387033Z,10,2,38,A,B,3,233.76,200,130,166334,13091002,233.85,233.95,100,121,1,1,233.81,234.0,1,402,1,3,233.8,234.1,105,100,2,1,233.76,234.13,200,400,1,1,233.7,234.17,1200,1,1,1,233.66,234.25,1,100,1,1,233.58,234.41,505,500,2,1,233.53,234.43,10,105,1,2,233.5,234.44,100,7,1,1,233.45,234.5,15,63,1,4,AAPL,0.0,0.0,0.0,0.0,200.0,0.0,0.0,0.0,0.0,0.0,0.0,41.015411004823704,
2024-10-21T12:25:45.063614991Z,2024-10-21T12:25:45.063448661Z,10,2,38,A,B,3,233.77,200,130,166330,13092718,233.85,233.95,100,121,1,1,233.81,234.0,1,402,1,3,233.8,234.1,105,100,2,1,233.77,234.13,200,400,1,1,233.7,234.17,1200,1,1,1,233.66,234.25,1,100,1,1,233.58,234.41,505,500,2,1,233.53,234.43,10,105,1,2,233.5,234.44,100,7,1,1,233.45,234.5,15,63,1,4,AAPL,0.0,0.0,0.0,0.0,200.0,0.0,0.0,0.0,0.0,0.0,0.0,41.015411004823704,
2024-10-21T12:25:52.757457183Z,2024-10-21T12:25:52.757291105Z,10,2,38,C,B,3,233.77,200,130,166078,13098338,233.85,233.95,100,121,1,1,233.81,234.0,1,402,1,3,233.8,234.1,105,100,2,1,233.7,234.13,1200,400,1,1,233.66,234.17,1,1,1,1,233.58,234.25,505,100,2,1,233.53,234.41,10,500,1,1,233.5,234.43,100,105,1,2,233.45,234.44,15,7,1,1,233.4,234.5,110,63,2,4,AAPL,0.0,0.0,0.0,0.0,-200.0,-1200.0,-1.0,-505.0,-10.0,-100.0,-15.0,-247.40391167966987,
2024-10-21T12:25:52.757470818Z,2024-10-21T12:25:52.757304269Z,10,2,38,A,B,3,233.75,200,130,166549,13098339,233.85,233.95,100,121,1,1,233.81,234.0,1,402,1,3,233.8,234.1,105,100,2,1,233.75,234.13,200,400,1,1,233.7,234.17,1200,1,1,1,233.66,234.25,1,100,1,1,233.58,234.41,505,500,2,1,233.53,234.43,10,105,1,2,233.5,234.44,100,7,1,1,233.45,234.5,15,63,1,4,AAPL,0.0,0.0,0.0,0.0,200.0,1200.0,1.0,505.0,10.0,100.0,15.0,247.40391167966987,
2024-10-21T12:25:54.873403967Z,2024-10-21T12:25:54.873237392Z,10,2,38,A,B,1,233.81,1,130,166575,13100599,233.85,233.95,100,121,1,1,233.81,234.0,2,402,2,3,233.8,234.1,105,100,2,1,233.75,234.13,200,400,1,1,233.7,234.17,1200,1,1,1,233.66,234.25,1,100,1,1,233.58,234.41,505,500,2,1,233.53,234.43,10,105,1,2,233.5,234.44,100,7,1,1,233.45,234.5,15,63,1,4,AAPL,0.0,0.0,1.0,0.0,0.0,0.0,0.0,0.0,0.0,0.0,0.0,0.06341616282886958,
2024-10-21T12:26:00.405862083Z,2024-10-21T12:26:00.405695962Z,10,2,38,C,A,8,234.44,7,130,166121,13106337,233.85,233.95,100,121,1,1,233.81,234.0,2,402,2,3,233.8,234.1,105,100,2,1,233.75,234.13,200,400,1,1,233.7,234.17,1200,1,1,1,233.66,234.25,1,100,1,1,233.58,234.41,505,500,2,1,233.53,234.43,10,105,1,2,233.5,234.5,100,63,1,4,233.45,234.59,15,60,1,1,AAPL,0.0,0.0,0.0,0.0,0.0,0.0,0.0,0.0,0.0,63.0,60.0,8.628552761311305,
2024-10-21T12:26:01.715446829Z,2024-10-21T12:26:01.715279752Z,10,2,38,A,B,3,233.76,200,130,167077,13108880,233.85,233.95,100,121,1,1,233.81,234.0,2,402,2,3,233.8,234.1,105,100,2,1,233.76,234.13,200,400,1,1,233.7,234.17,1200,1,1,1,233.66,234.25,1,100,1,1,233.58,234.41,505,500,2,1,233.53,234.43,10,105,1,2,233.5,234.5,100,63,1,4,233.45,234.59,15,60,1,1,AAPL,0.0,0.0,0.0,0.0,200.0,0.0,0.0,0.0,0.0,0.0,0.0,41.015411004823704,
2024-10-21T12:26:02.222090992Z,2024-10-21T12:26:02.221924482Z,10,2,38,A,B,3,233.77,200,130,166510,13109908,233.85,233.95,100,121,1,1,233.81,234.0,2,402,2,3,233.8,234.1,105,100,2,1,233.77,234.13,200,400,1,1,233.7,234.17,1200,1,1,1,233.66,234.25,1,100,1,1,233.58,234.41,505,500,2,1,233.53,234.43,10,105,1,2,233.5,234.5,100,63,1,4,233.45,234.59,15,60,1,1,AAPL,0.0,0.0,0.0,0.0,200.0,0.0,0.0,0.0,0.0,0.0,0.0,41.015411004823704,
2024-10-21T12:26:02.408702630Z,2024-10-21T12:26:02.408536304Z,10,2,38,A,A,2,234.07,7,130,166326,13110618,233.85,233.95,100,121,1,1,233.81,234.0,2,402,2,3,233.8,234.07,105,7,2,1,233.77,234.1,200,100,1,1,233.7,234.13,1200,400,1,1,233.66,234.17,1,1,1,1,233.58,234.25,505,100,2,1,233.53,234.41,10,500,1,1,233.5,234.43,100,105,1,2,233.45,234.5,15,63,1,4,AAPL,0.0,0.0,0.0,-100.0,-400.0,-1.0,-100.0,-500.0,-105.0,-63.0,-60.0,-182.374938051097,
2024-10-21T12:26:05.174048295Z,2024-10-21T12:26:05.173881544Z,10,2,38,A,B,0,233.86,100,130,166751,13112718,233.86,233.95,100,121,1,1,233.85,234.0,100,402,1,3,233.81,234.07,2,7,2,1,233.8,234.1,105,100,2,1,233.77,234.13,200,400,1,1,233.7,234.17,1200,1,1,1,233.66,234.25,1,100,1,1,233.58,234.41,505,500,2,1,233.53,234.43,10,105,1,2,233.5,234.5,100,63,1,4,AAPL,100.0,100.0,100.0,2.0,105.0,200.0,1200.0,1.0,505.0,10.0,100.0,277.8002221434005,
2024-10-21T12:26:05.247381714Z,2024-10-21T12:26:05.247215441Z,10,2,38,C,A,1,234.0,200,130,166273,13112835,233.86,233.95,100,121,1,1,233.85,234.0,100,202,1,2,233.81,234.07,2,7,2,1,233.8,234.1,105,100,2,1,233.77,234.13,200,400,1,1,233.7,234.17,1200,1,1,1,233.66,234.25,1,100,1,1,233.58,234.41,505,500,2,1,233.53,234.43,10,105,1,2,233.5,234.5,100,63,1,4,AAPL,0.0,0.0,200.0,0.0,0.0,0.0,0.0,0.0,0.0,0.0,0.0,12.683232565773917,
2024-10-21T12:26:05.247392056Z,2024-10-21T12:26:05.247226039Z,10,2,38,C,A,1,234.0,200,130,166017,13112836,233.86,233.95,100,121,1,1,233.85,234.0,100,2,1,1,233.81,234.07,2,7,2,1,233.8,234.1,105,100,2,1,233.77,234.13,200,400,1,1,233.7,234.17,1200,1,1,1,233.66,234.25,1,100,1,1,233.58,234.41,505,500,2,1,233.53,234.43,10,105,1,2,233.5,234.5,100,63,1,4,AAPL,0.0,0.0,200.0,0.0,0.0,0.0,0.0,0.0,0.0,0.0,0.0,12.683232565773917,
2024-10-21T12:26:05.247404052Z,2024-10-21T12:26:05.247237168Z,10,2,38,A,A,2,234.01,200,130,166884,13112837,233.86,233.95,100,121,1,1,233.85,234.0,100,2,1,1,233.81,234.01,2,200,2,1,233.8,234.07,105,7,2,1,233.77,234.1,200,100,1,1,233.7,234.13,1200,400,1,1,233.66,234.17,1,1,1,1,233.58,234.25,505,100,2,1,233.53,234.41,10,500,1,1,233.5,234.43,100,105,1,2,AAPL,0.0,0.0,0.0,-7.0,-100.0,-400.0,-1.0,-100.0,-500.0,-105.0,-63.0,-141.87319238778628,
2024-10-21T12:26:08.272617784Z,2024-10-21T12:26:08.272451351Z,10,2,38,A,B,4,233.78,200,130,166433,13116250,233.86,233.95,100,121,1,1,233.85,234.0,100,2,1,1,233.81,234.01,2,200,2,1,233.8,234.07,105,7,2,1,233.78,234.1,200,100,1,1,233.7,234.13,1200,400,1,1,233.66,234.17,1,1,1,1,233.58,234.25,505,100,2,1,233.53,234.41,10,500,1,1,233.5,234.43,100,105,1,2,AAPL,0.0,0.0,0.0,0.0,0.0,200.0,0.0,0.0,0.0,0.0,0.0,23.27753746783751,
2024-10-21T12:26:09.611069894Z,2024-10-21T12:26:09.610903498Z,10,2,38,C,B,1,233.85,100,130,166396,13117941,233.86,233.95,100,121,1,1,233.81,234.0,2,2,2,1,233.8,234.01,105,200,2,1,233.78,234.07,200,7,1,1,233.7,234.1,1200,100,1,1,233.66,234.13,1,400,1,1,233.58,234.17,505,1,2,1,233.53,234.25,10,100,1,1,233.5,234.41,100,500,1,1,233.45,234.43,15,105,1,2,AAPL,0.0,0.0,-100.0,-2.0,-105.0,-200.0,-1200.0,-1.0,-505.0,-10.0,-100.0,-275.812163878788,
2024-10-21T12:26:11.689942070Z,2024-10-21T12:26:11.689776041Z,10,2,38,C,A,2,234.01,200,130,166029,13119493,233.86,233.95,100,121,1,1,233.81,234.0,2,2,2,1,233.8,234.07,105,7,2,1,233.78,234.1,200,100,1,1,233.7,234.13,1200,400,1,1,233.66,234.17,1,1,1,1,233.58,234.25,505,100,2,1,233.53,234.41,10,500,1,1,233.5,234.43,100,105,1,2,233.45,234.5,15,63,1,4,AAPL,0.0,0.0,0.0,7.0,100.0,400.0,1.0,100.0,500.0,105.0,63.0,141.87319238778628,
2024-10-21T12:26:11.689954364Z,2024-10-21T12:26:11.689788127Z,10,2,38,A,A,2,234.03,200,130,166237,13119494,233.86,233.95,100,121,1,1,233.81,234.0,2,2,2,1,233.8,234.03,105,200,2,1,233.78,234.07,200,7,1,1,233.7,234.1,1200,100,1,1,233.66,234.13,1,400,1,1,233.58,234.17,505,1,2,1,233.53,234.25,10,100,1,1,233.5,234.41,100,500,1,1,233.45,234.43,15,105,1,2,AAPL,0.0,0.0,0.0,-7.0,-100.0,-400.0,-1.0,-100.0,-500.0,-105.0,-63.0,-141.87319238778628,
2024-10-21T12:26:11.691953516Z,2024-10-21T12:26:11.691787041Z,10,2,38,A,A,2,234.03,200,130,166475,13119500,233.86,233.95,100,121,1,1,233.81,234.0,2,2,2,1,233.8,234.03,105,400,2,2,233.78,234.07,200,7,1,1,233.7,234.1,1200,100,1,1,233.66,234.13,1,400,1,1,233.58,234.17,505,1,2,1,233.53,234.25,10,100,1,1,233.5,234.41,100,500,1,1,233.45,234.43,15,105,1,2,AAPL,0.0,0.0,0.0,-200.0,0.0,0.0,0.0,0.0,0.0,0.0,0.0,-20.31651614720104,
2024-10-21T12:26:11.746463267Z,2024-10-21T12:26:11.746296162Z,10,2,38,C,A,2,234.03,200,130,167105,13119630,233.86,233.95,100,121,1,1,233.81,234.0,2,2,2,1,233.8,234.03,105,200,2,1,233.78,234.07,200,7,1,1,233.7,234.1,1200,100,1,1,233.66,234.13,1,400,1,1,233.58,234.17,505,1,2,1,233.53,234.25,10,100,1,1,233.5,234.41,100,500,1,1,233.45,234.43,15,105,1,2,AAPL,0.0,0.0,0.0,200.0,0.0,0.0,0.0,0.0,0.0,0.0,0.0,20.31651614720104,
2024-10-21T12:26:11.746474261Z,2024-10-21T12:26:11.746308007Z,10,2,38,A,A,2,234.02,200,130,166254,13119632,233.86,233.95,100,121,1,1,233.81,234.0,2,2,2,1,233.8,234.02,105,200,2,1,233.78,234.07,200,7,1,1,233.7,234.1,1200,100,1,1,233.66,234.13,1,400,1,1,233.58,234.17,505,1,2,1,233.53,234.25,10,100,1,1,233.5,234.41,100,500,1,1,233.45,234.43,15,105,1,2,AAPL,0.0,0.0,0.0,-200.0,0.0,0.0,0.0,0.0,0.0,0.0,0.0,-20.31651614720104,
2024-10-21T12:26:13.045453100Z,2024-10-21T12:26:13.045285946Z,10,2,38,A,B,3,233.79,200,130,167154,13120862,233.86,233.95,100,121,1,1,233.81,234.0,2,2,2,1,233.8,234.02,105,200,2,1,233.79,234.07,200,7,1,1,233.7,234.1,1200,100,1,1,233.66,234.13,1,400,1,1,233.58,234.17,505,1,2,1,233.53,234.25,10,100,1,1,233.5,234.41,100,500,1,1,233.45,234.43,15,105,1,2,AAPL,0.0,0.0,0.0,0.0,200.0,0.0,0.0,0.0,0.0,0.0,0.0,41.015411004823704,
2024-10-21T12:26:20.829403397Z,2024-10-21T12:26:20.829236958Z,10,2,38,A,A,1,234.0,15,130,166439,13126283,233.86,233.95,100,121,1,1,233.81,234.0,2,17,2,2,233.8,234.02,105,200,2,1,233.79,234.07,200,7,1,1,233.7,234.1,1200,100,1,1,233.66,234.13,1,400,1,1,233.58,234.17,505,1,2,1,233.53,234.25,10,100,1,1,233.5,234.41,100,500,1,1,233.45,234.43,15,105,1,2,AAPL,0.0,0.0,-15.0,0.0,0.0,0.0,0.0,0.0,0.0,0.0,0.0,-0.9512424424330437,
2024-10-21T12:26:22.496516455Z,2024-10-21T12:26:22.496350258Z,10,2,38,C,A,3,234.07,7,130,166197,13127351,233.86,233.95,100,121,1,1,233.81,234.0,2,17,2,2,233.8,234.02,105,200,2,1,233.79,234.1,200,100,1,1,233.7,234.13,1200,400,1,1,233.66,234.17,1,1,1,1,233.58,234.25,505,100,2,1,233.53,234.41,10,500,1,1,233.5,234.43,100,105,1,2,233.45,234.5,15,63,1,4,AAPL,0.0,0.0,0.0,0.0,100.0,400.0,1.0,100.0,500.0,105.0,63.0,141.16211432263424,
2024-10-21T12:26:23.489058780Z,2024-10-21T12:26:23.488892465Z,10,2,38,C,B,3,233.79,200,130,166315,13128004,233.86,233.95,100,121,1,1,233.81,234.0,2,17,2,2,233.8,234.02,105,200,2,1,233.7,234.1,1200,100,1,1,233.66,234.13,1,400,1,1,233.58,234.17,505,1,2,1,233.53,234.25,10,100,1,1,233.5,234.41,100,500,1,1,233.45,234.43,15,105,1,2,233.4,234.5,110,63,2,4,AAPL,0.0,0.0,0.0,0.0,-200.0,-1200.0,-1.0,-505.0,-10.0,-100.0,-15.0,-247.40391167966987,
2024-10-21T12:26:23.498527505Z,2024-10-21T12:26:23.498360877Z,10,2,38,A,B,3,233.78,200,130,166628,13128006,233.86,233.95,100,121,1,1,233.81,234.0,2,17,2,2,233.8,234.02,105,200,2,1,233.78,234.1,200,100,1,1,233.7,234.13,1200,400,1,1,233.66,234.17,1,1,1,1,233.58,234.25,505,100,2,1,233.53,234.41,10,500,1,1,233.5,234.43,100,105,1,2,233.45,234.5,15,63,1,4,AAPL,0.0,0.0,0.0,0.0,200.0,1200.0,1.0,505.0,10.0,100.0,15.0,247.40391167966987,
2024-10-21T12:26:24.504603959Z,2024-10-21T12:26:24.504437465Z,10,2,38,A,A,7,234.41,7,130,166494,13128603,233.86,233.95,100,121,1,1,233.81,234.0,2,17,2,2,233.8,234.02,105,200,2,1,233.78,234.1,200,100,1,1,233.7,234.13,1200,400,1,1,233.66,234.17,1,1,1,1,233.58,234.25,505,100,2,1,233.53,234.41,10,507,1,2,233.5,234.43,100,105,1,2,233.45,234.5,15,63,1,4,AAPL,0.0,0.0,0.0,0.0,0.0,0.0,0.0,0.0,-7.0,0.0,0.0,-0.7113139715991935,
2024-10-21T12:26:25.077623504Z,2024-10-21T12:26:25.077457400Z,10,2,38,C,B,3,233.78,200,130,166104,13129240,233.86,233.95,100,121,1,1,233.81,234.0,2,17,2,2,233.8,234.02,105,200,2,1,233.7,234.1,1200,100,1,1,233.66,234.13,1,400,1,1,233.58,234.17,505,1,2,1,233.53,234.25,10,100,1,1,233.5,234.41,100,507,1,2,233.45,234.43,15,105,1,2,233.4,234.5,110,63,2,4,AAPL,0.0,0.0,0.0,0.0,-200.0,-1200.0,-1.0,-505.0,-10.0,-100.0,-15.0,-247.40391167966987,
2024-10-21T12:26:25.077635518Z,2024-10-21T12:26:25.077469095Z,10,2,38,A,B,3,233.76,200,130,166423,13129241,233.86,233.95,100,121,1,1,233.81,234.0,2,17,2,2,233.8,234.02,105,200,2,1,233.76,234.1,200,100,1,1,233.7,234.13,1200,400,1,1,233.66,234.17,1,1,1,1,233.58,234.25,505,100,2,1,233.53,234.41,10,507,1,2,233.5,234.43,100,105,1,2,233.45,234.5,15,63,1,4,AAPL,0.0,0.0,0.0,0.0,200.0,1200.0,1.0,505.0,10.0,100.0,15.0,247.40391167966987,
2024-10-21T12:26:25.077648690Z,2024-10-21T12:26:25.077482593Z,10,2,38,A,A,2,234.02,200,130,166097,13129242,233.86,233.95,100,121,1,1,233.81,234.0,2,17,2,2,233.8,234.02,105,400,2,2,233.76,234.1,200,100,1,1,233.7,234.13,1200,400,1,1,233.66,234.17,1,1,1,1,233.58,234.25,505,100,2,1,233.53,234.41,10,507,1,2,233.5,234.43,100,105,1,2,233.45,234.5,15,63,1,4,AAPL,0.0,0.0,0.0,-200.0,0.0,0.0,0.0,0.0,0.0,0.0,0.0,-20.31651614720104,
2024-10-21T12:26:25.129478069Z,2024-10-21T12:26:25.129312037Z,10,2,38,C,A,2,234.02,200,130,166032,13129411,233.86,233.95,100,121,1,1,233.81,234.0,2,17,2,2,233.8,234.02,105,200,2,1,233.76,234.1,200,100,1,1,233.7,234.13,1200,400,1,1,233.66,234.17,1,1,1,1,233.58,234.25,505,100,2,1,233.53,234.41,10,507,1,2,233.5,234.43,100,105,1,2,233.45,234.5,15,63,1,4,AAPL,0.0,0.0,0.0,200.0,0.0,0.0,0.0,0.0,0.0,0.0,0.0,20.31651614720104,
2024-10-21T12:26:25.129491036Z,2024-10-21T12:26:25.129324093Z,10,2,38,A,A,1,234.0,200,130,166943,13129412,233.86,233.95,100,121,1,1,233.81,234.0,2,217,2,3,233.8,234.1,105,100,2,1,233.76,234.13,200,400,1,1,233.7,234.17,1200,1,1,1,233.66,234.25,1,100,1,1,233.58,234.41,505,507,2,2,233.53,234.43,10,105,1,2,233.5,234.5,100,63,1,4,233.45,234.59,15,60,1,1,AAPL,0.0,0.0,-200.0,100.0,400.0,1.0,100.0,507.0,105.0,63.0,60.0,170.48973275011588,
2024-10-21T12:26:25.268804920Z,2024-10-21T12:26:25.268638479Z,10,2,38,A,B,3,233.77,200,130,166441,13129838,233.86,233.95,100,121,1,1,233.81,234.0,2,217,2,3,233.8,234.1,105,100,2,1,233.77,234.13,200,400,1,1,233.7,234.17,1200,1,1,1,233.66,234.25,1,100,1,1,233.58,234.41,505,507,2,2,233.53,234.43,10,105,1,2,233.5,234.5,100,63,1,4,233.45,234.59,15,60,1,1,AAPL,0.0,0.0,0.0,0.0,200.0,0.0,0.0,0.0,0.0,0.0,0.0,41.015411004823704,
2024-10-21T12:26:25.384254820Z,2024-10-21T12:26:25.384088744Z,10,2,38,C,A,1,234.0,200,130,166076,13130001,233.86,233.95,100,121,1,1,233.81,234.0,2,17,2,2,233.8,234.1,105,100,2,1,233.77,234.13,200,400,1,1,233.7,234.17,1200,1,1,1,233.66,234.25,1,100,1,1,233.58,234.41,505,507,2,2,233.53,234.43,10,105,1,2,233.5,234.5,100,63,1,4,233.45,234.59,15,60,1,1,AAPL,0.0,0.0,200.0,0.0,0.0,0.0,0.0,0.0,0.0,0.0,0.0,12.683232565773917,
2024-10-21T12:26:25.384266211Z,2024-10-21T12:26:25.384100277Z,10,2,38,A,A,2,234.02,200,130,165934,13130002,233.86,233.95,100,121,1,1,233.81,234.0,2,17,2,2,233.8,234.02,105,200,2,1,233.77,234.1,200,100,1,1,233.7,234.13,1200,400,1,1,233.66,234.17,1,1,1,1,233.58,234.25,505,100,2,1,233.53,234.41,10,507,1,2,233.5,234.43,100,105,1,2,233.45,234.5,15,63,1,4,AAPL,0.0,0.0,0.0,-100.0,-400.0,-1.0,-100.0,-507.0,-105.0,-63.0,-60.0,-183.1729653158898,
2024-10-21T12:26:25.439053026Z,2024-10-21T12:26:25.438886764Z,10,2,38,A,B,3,233.78,200,130,166262,13130072,233.86,233.95,100,121,1,1,233.81,234.0,2,17,2,2,233.8,234.02,105,200,2,1,233.78,234.1,200,100,1,1,233.7,234.13,1200,400,1,1,233.66,234.17,1,1,1,1,233.58,234.25,505,100,2,1,233.53,234.41,10,507,1,2,233.5,234.43,100,105,1,2,233.45,234.5,15,63,1,4,AAPL,0.0,0.0,0.0,0.0,200.0,0.0,0.0,0.0,0.0,0.0,0.0,41.015411004823704,
2024-10-21T12:26:25.519068296Z,2024-10-21T12:26:25.518902005Z,10,2,38,A,A,2,234.01,200,130,166291,13130195,233.86,233.95,100,121,1,1,233.81,234.0,2,17,2,2,233.8,234.01,105,200,2,1,233.78,234.1,200,100,1,1,233.7,234.13,1200,400,1,1,233.66,234.17,1,1,1,1,233.58,234.25,505,100,2,1,233.53,234.41,10,507,1,2,233.5,234.43,100,105,1,2,233.45,234.5,15,63,1,4,AAPL,0.0,0.0,0.0,-200.0,0.0,0.0,0.0,0.0,0.0,0.0,0.0,-20.31651614720104,
2024-10-21T12:26:31.593057846Z,2024-10-21T12:26:31.592891536Z,10,2,38,C,A,7,234.41,7,130,166310,13135066,233.86,233.95,100,121,1,1,233.81,234.0,2,17,2,2,233.8,234.01,105,200,2,1,233.78,234.1,200,100,1,1,233.7,234.13,1200,400,1,1,233.66,234.17,1,1,1,1,233.58,234.25,505,100,2,1,233.53,234.41,10,500,1,1,233.5,234.43,100,105,1,2,233.45,234.5,15,63,1,4,AAPL,0.0,0.0,0.0,0.0,0.0,0.0,0.0,0.0,7.0,0.0,0.0,0.7113139715991935,
2024-10-21T12:26:32.717599837Z,2024-10-21T12:26:32.717433050Z,10,2,38,A,A,0,233.95,10,130,166787,13137148,233.86,233.95,100,131,1,2,233.81,234.0,2,17,2,2,233.8,234.01,105,200,2,1,233.78,234.1,200,100,1,1,233.7,234.13,1200,400,1,1,233.66,234.17,1,1,1,1,233.58,234.25,505,100,2,1,233.53,234.41,10,500,1,1,233.5,234.43,100,105,1,2,233.45,234.5,15,63,1,4,AAPL,-10.0,-10.0,0.0,0.0,0.0,0.0,0.0,0.0,0.0,0.0,0.0,-0.1988058264612502,
2024-10-21T12:26:32.717638955Z,2024-10-21T12:26:32.717472823Z,10,2,38,C,B,3,233.78,200,130,166132,13137150,233.86,233.95,100,131,1,2,233.81,234.0,2,17,2,2,233.8,234.01,105,200,2,1,233.7,234.1,1200,100,1,1,233.66,234.13,1,400,1,1,233.58,234.17,505,1,2,1,233.53,234.25,10,100,1,1,233.5,234.41,100,500,1,1,233.45,234.43,15,105,1,2,233.4,234.5,110,63,2,4,AAPL,0.0,0.0,0.0,0.0,-200.0,-1200.0,-1.0,-505.0,-10.0,-100.0,-15.0,-247.40391167966987,
2024-10-21T12:26:32.721694410Z,2024-10-21T12:26:32.721528057Z,10,2,38,C,A,0,233.95,10,130,166353,13137153,233.86,233.95,100,121,1,1,233.81,234.0,2,17,2,2,233.8,234.01,105,200,2,1,233.7,234.1,1200,100,1,1,233.66,234.13,1,400,1,1,233.58,234.17,505,1,2,1,233.53,234.25,10,100,1,1,233.5,234.41,100,500,1,1,233.45,234.43,15,105,1,2,233.4,234.5,110,63,2,4,AAPL,10.0,10.0,0.0,0.0,0.0,0.0,0.0,0.0,0.0,0.0,0.0,0.1988058264612502,
2024-10-21T12:26:32.820850700Z,2024-10-21T12:26:32.820683999Z,10,2,38,A,B,3,233.78,200,130,166701,13137257,233.86,233.95,100,121,1,1,233.81,234.0,2,17,2,2,233.8,234.01,105,200,2,1,233.78,234.1,200,100,1,1,233.7,234.13,1200,400,1,1,233.66,234.17,1,1,1,1,233.58,234.25,505,100,2,1,233.53,234.41,10,500,1,1,233.5,234.43,100,105,1,2,233.45,234.5,15,63,1,4,AAPL,0.0,0.0,0.0,0.0,200.0,1200.0,1.0,505.0,10.0,100.0,15.0,247.40391167966987,
2024-10-21T12:26:33.596226968Z,2024-10-21T12:26:33.596060481Z,10,2,38,A,A,7,234.41,7,130,166487,13137944,233.86,233.95,100,121,1,1,233.81,234.0,2,17,2,2,233.8,234.01,105,200,2,1,233.78,234.1,200,100,1,1,233.7,234.13,1200,400,1,1,233.66,234.17,1,1,1,1,233.58,234.25,505,100,2,1,233.53,234.41,10,507,1,2,233.5,234.43,100,105,1,2,233.45,234.5,15,63,1,4,AAPL,0.0,0.0,0.0,0.0,0.0,0.0,0.0,0.0,-7.0,0.0,0.0,-0.7113139715991935,
2024-10-21T12:26:33.705462618Z,2024-10-21T12:26:33.705296257Z,10,2,38,C,B,3,233.78,200,130,166361,13138040,233.86,233.95,100,121,1,1,233.81,234.0,2,17,2,2,233.8,234.01,105,200,2,1,233.7,234.1,1200,100,1,1,233.66,234.13,1,400,1,1,233.58,234.17,505,1,2,1,233.53,234.25,10,100,1,1,233.5,234.41,100,507,1,2,233.45,234.43,15,105,1,2,233.4,234.5,110,63,2,4,AAPL,0.0,0.0,0.0,0.0,-200.0,-1200.0,-1.0,-505.0,-10.0,-100.0,-15.0,-247.40391167966987,
2024-10-21T12:26:33.705475821Z,2024-10-21T12:26:33.705309399Z,10,2,38,A,B,3,233.73,400,130,166422,13138041,233.86,233.95,100,121,1,1,233.81,234.0,2,17,2,2,233.8,234.01,105,200,2,1,233.73,234.1,400,100,1,1,233.7,234.13,1200,400,1,1,233.66,234.17,1,1,1,1,233.58,234.25,505,100,2,1,233.53,234.41,10,507,1,2,233.5,234.43,100,105,1,2,233.45,234.5,15,63,1,4,AAPL,0.0,0.0,0.0,0.0,400.0,1200.0,1.0,505.0,10.0,100.0,15.0,288.4193226844936,
2024-10-21T12:26:40.656300037Z,2024-10-21T12:26:40.656134264Z,10,2,38,C,A,2,234.01,200,130,165773,13145962,233.86,233.95,100,121,1,1,233.81,234.0,2,17,2,2,233.8,234.1,105,100,2,1,233.73,234.13,400,400,1,1,233.7,234.17,1200,1,1,1,233.66,234.25,1,100,1,1,233.58,234.41,505,507,2,2,233.53,234.43,10,105,1,2,233.5,234.5,100,63,1,4,233.45,234.59,15,60,1,1,AAPL,0.0,0.0,0.0,100.0,400.0,1.0,100.0,507.0,105.0,63.0,60.0,183.1729653158898,
2024-10-21T12:26:40.656313085Z,2024-10-21T12:26:40.656147028Z,10,2,38,A,A,2,234.03,400,130,166057,13145963,233.86,233.95,100,121,1,1,233.81,234.0,2,17,2,2,233.8,234.03,105,400,2,1,233.73,234.1,400,100,1,1,233.7,234.13,1200,400,1,1,233.66,234.17,1,1,1,1,233.58,234.25,505,100,2,1,233.53,234.41,10,507,1,2,233.5,234.43,100,105,1,2,233.45,234.5,15,63,1,4,AAPL,0.0,0.0,0.0,-100.0,-400.0,-1.0,-100.0,-507.0,-105.0,-63.0,-60.0,-183.1729653158898,
2024-10-21T12:26:40.707673608Z,2024-10-21T12:26:40.707506986Z,10,2,38,A,B,3,233.74,400,130,166622,13146198,233.86,233.95,100,121,1,1,233.81,234.0,2,17,2,2,233.8,234.03,105,400,2,1,233.74,234.1,400,100,1,1,233.7,234.13,1200,400,1,1,233.66,234.17,1,1,1,1,233.58,234.25,505,100,2,1,233.53,234.41,10,507,1,2,233.5,234.43,100,105,1,2,233.45,234.5,15,63,1,4,AAPL,0.0,0.0,0.0,0.0,400.0,0.0,0.0,0.0,0.0,0.0,0.0,82.03082200964741,
2024-10-21T12:26:40.896702274Z,2024-10-21T12:26:40.896535785Z,10,2,38,A,A,2,234.02,400,130,166489,13146521,233.86,233.95,100,121,1,1,233.81,234.0,2,17,2,2,233.8,234.02,105,400,2,1,233.74,234.1,400,100,1,1,233.7,234.13,1200,400,1,1,233.66,234.17,1,1,1,1,233.58,234.25,505,100,2,1,233.53,234.41,10,507,1,2,233.5,234.43,100,105,1,2,233.45,234.5,15,63,1,4,AAPL,0.0,0.0,0.0,-400.0,0.0,0.0,0.0,0.0,0.0,0.0,0.0,-40.63303229440208,
2024-10-21T12:26:42.392700431Z,2024-10-21T12:26:42.392534365Z,10,2,38,C,A,7,234.41,7,130,166066,13148175,233.86,233.95,100,121,1,1,233.81,234.0,2,17,2,2,233.8,234.02,105,400,2,1,233.74,234.1,400,100,1,1,233.7,234.13,1200,400,1,1,233.66,234.17,1,1,1,1,233.58,234.25,505,100,2,1,233.53,234.41,10,500,1,1,233.5,234.43,100,105,1,2,233.45,234.5,15,63,1,4,AAPL,0.0,0.0,0.0,0.0,0.0,0.0,0.0,0.0,7.0,0.0,0.0,0.7113139715991935,
2024-10-21T12:26:43.555781301Z,2024-10-21T12:26:43.555613825Z,10,2,38,C,B,0,233.86,100,130,167476,13148963,233.81,233.95,2,121,2,1,233.8,234.0,105,17,2,2,233.74,234.02,400,400,1,1,233.7,234.1,1200,100,1,1,233.66,234.13,1,400,1,1,233.58,234.17,505,1,2,1,233.53,234.25,10,100,1,1,233.5,234.41,100,500,1,1,233.45,234.43,15,105,1,2,233.4,234.5,110,63,2,4,AAPL,-100.0,-100.0,-2.0,-105.0,-400.0,-1200.0,-1.0,-505.0,-10.0,-100.0,-15.0,-301.2003842520444,
2024-10-21T12:26:43.555781301Z,2024-10-21T12:26:43.555613825Z,10,2,38,T,A,0,233.86,100,130,167476,13148963,233.86,233.95,100,121,1,1,233.81,234.0,2,17,2,2,233.8,234.02,105,400,2,1,233.74,234.1,400,100,1,1,233.7,234.13,1200,400,1,1,233.66,234.17,1,1,1,1,233.58,234.25,505,100,2,1,233.53,234.41,10,500,1,1,233.5,234.43,100,105,1,2,233.45,234.5,15,63,1,4,AAPL,100.0,100.0,2.0,105.0,400.0,1200.0,1.0,505.0,10.0,100.0,15.0,301.2003842520444,
2024-10-21T12:26:43.555792717Z,2024-10-21T12:26:43.555625145Z,10,2,38,A,B,0,233.86,100,130,167572,13148964,233.86,233.95,100,121,1,1,233.81,234.0,2,17,2,2,233.8,234.02,105,400,2,1,233.74,234.1,400,100,1,1,233.7,234.13,1200,400,1,1,233.66,234.17,1,1,1,1,233.58,234.25,505,100,2,1,233.53,234.41,10,500,1,1,233.5,234.43,100,105,1,2,233.45,234.5,15,63,1,4,AAPL,0.0,0.0,0.0,0.0,0.0,0.0,0.0,0.0,0.0,0.0,0.0,0.0,
2024-10-21T12:26:43.555803052Z,2024-10-21T12:26:43.555636531Z,10,2,38,A,A,0,233.9,100,130,166521,13148965,233.86,233.9,100,100,1,1,233.81,233.95,2,121,2,1,233.8,234.0,105,17,2,2,233.74,234.02,400,400,1,1,233.7,234.1,1200,100,1,1,233.66,234.13,1,400,1,1,233.58,234.17,505,1,2,1,233.53,234.25,10,100,1,1,233.5,234.41,100,500,1,1,233.45,234.43,15,105,1,2,AAPL,-121.0,-121.0,-17.0,-400.0,-100.0,-400.0,-1.0,-100.0,-500.0,-105.0,-63.0,-185.27877188530823,
2024-10-21T12:26:43.555807607Z,2024-10-21T12:26:43.555641373Z,10,2,38,A,A,1,233.91,200,130,166234,13148967,233.86,233.9,100,100,1,1,233.81,233.91,2,200,2,1,233.8,233.93,105,100,2,1,233.74,233.95,400,121,1,1,233.7,234.0,1200,17,1,2,233.66,234.02,1,400,1,1,233.58,234.1,505,100,2,1,233.53,234.13,10,400,1,1,233.5,234.17,100,1,1,1,233.45,234.25,15,100,1,1,AAPL,0.0,0.0,-121.0,-17.0,-400.0,-100.0,-400.0,-1.0,-100.0,-500.0,-105.0,-210.5404486638121,
2024-10-21T12:26:43.555814614Z,2024-10-21T12:26:43.555648065Z,10,2,38,A,A,2,233.93,100,130,166549,13148968,233.86,233.9,100,100,1,1,233.81,233.91,2,200,2,1,233.8,233.93,105,200,2,2,233.74,233.95,400,121,1,1,233.7,234.0,1200,17,1,2,233.66,234.02,1,400,1,1,233.58,234.1,505,100,2,1,233.53,234.13,10,400,1,1,233.5,234.17,100,1,1,1,233.45,234.25,15,100,1,1,AAPL,0.0,0.0,0.0,-100.0,0.0,0.0,0.0,0.0,0.0,0.0,0.0,-10.15825807360052,
2024-10-21T12:26:43.555816268Z,2024-10-21T12:26:43.555650058Z,10,2,38,A,A,2,233.93,100,130,166210,13148969,233.86,233.9,100,100,1,1,233.81,233.91,2,200,2,1,233.8,233.93,105,300,2,3,233.74,233.95,400,121,1,1,233.7,234.0,1200,17,1,2,233.66,234.02,1,400,1,1,233.58,234.1,505,100,2,1,233.53,234.13,10,400,1,1,233.5,234.17,100,1,1,1,233.45,234.25,15,100,1,1,AAPL,0.0,0.0,0.0,-100.0,0.0,0.0,0.0,0.0,0.0,0.0,0.0,-10.15825807360052,
2024-10-21T12:26:43.555819727Z,2024-10-21T12:26:43.555653371Z,10,2,38,C,A,1,233.91,200,130,166356,13148970,233.86,233.9,100,100,1,1,233.81,233.93,2,300,2,3,233.8,233.95,105,121,2,1,233.74,234.0,400,17,1,2,233.7,234.02,1200,400,1,1,233.66,234.1,1,100,1,1,233.58,234.13,505,400,2,1,233.53,234.17,10,1,1,1,233.5,234.25,100,100,1,1,233.45,234.41,15,500,1,1,AAPL,0.0,0.0,300.0,121.0,17.0,400.0,100.0,400.0,1.0,100.0,500.0,183.27323589475466,
2024-10-21T12:26:43.555829005Z,2024-10-21T12:26:43.555663089Z,10,2,38,A,A,1,233.91,23,130,165916,13148971,233.86,233.9,100,100,1,1,233.81,233.91,2,23,2,1,233.8,233.93,105,300,2,3,233.74,233.95,400,121,1,1,233.7,234.0,1200,17,1,2,233.66,234.02,1,400,1,1,233.58,234.1,505,100,2,1,233.53,234.13,10,400,1,1,233.5,234.17,100,1,1,1,233.45,234.25,15,100,1,1,AAPL,0.0,0.0,-300.0,-121.0,-17.0,-400.0,-100.0,-400.0,-1.0,-100.0,-500.0,-183.27323589475466,
2024-10-21T12:26:43.555844094Z,2024-10-21T12:26:43.555678324Z,10,2,38,C,A,0,233.9,100,130,165770,13148972,233.86,233.91,100,23,1,1,233.81,233.93,2,300,2,3,233.8,233.95,105,121,2,1,233.74,234.0,400,17,1,2,233.7,234.02,1200,400,1,1,233.66,234.1,1,100,1,1,233.58,234.13,505,400,2,1,233.53,234.17,10,1,1,1,233.5,234.25,100,100,1,1,233.45,234.41,15,500,1,1,AAPL,23.0,23.0,300.0,121.0,17.0,400.0,100.0,400.0,1.0,100.0,500.0,183.73048929561554,
2024-10-21T12:26:43.555858526Z,2024-10-21T12:26:43.555692383Z,10,2,38,C,A,1,233.93,100,130,166143,13148974,233.86,233.91,100,23,1,1,233.81,233.93,2,200,2,2,233.8,233.95,105,121,2,1,233.74,234.0,400,17,1,2,233.7,234.02,1200,400,1,1,233.66,234.1,1,100,1,1,233.58,234.13,505,400,2,1,233.53,234.17,10,1,1,1,233.5,234.25,100,100,1,1,233.45,234.41,15,500,1,1,AAPL,0.0,0.0,100.0,0.0,0.0,0.0,0.0,0.0,0.0,0.0,0.0,6.3416162828869584,
2024-10-21T12:26:43.555866497Z,2024-10-21T12:26:43.555700148Z,10,2,38,C,A,1,233.93,100,130,166349,13148976,233.86,233.91,100,23,1,1,233.81,233.93,2,100,2,1,233.8,233.94,105,23,2,1,233.74,233.95,400,121,1,1,233.7,234.0,1200,17,1,2,233.66,234.02,1,400,1,1,233.58,234.1,505,100,2,1,233.53,234.13,10,400,1,1,233.5,234.17,100,1,1,1,233.45,234.25,15,100,1,1,AAPL,0.0,0.0,100.0,-121.0,-17.0,-400.0,-100.0,-400.0,-1.0,-100.0,-500.0,-157.90677076320682,
2024-10-21T12:26:43.555879570Z,2024-10-21T12:26:43.555711164Z,10,2,38,T,A,0,233.86,50,130,168406,13148979,233.86,233.91,100,23,1,1,233.81,233.93,2,100,2,1,233.8,233.94,105,23,2,1,233.74,233.95,400,121,1,1,233.7,234.0,1200,17,1,2,233.66,234.02,1,400,1,1,233.58,234.1,505,100,2,1,233.53,234.13,10,400,1,1,233.5,234.17,100,1,1,1,233.45,234.25,15,100,1,1,AAPL,0.0,0.0,0.0,0.0,0.0,0.0,0.0,0.0,0.0,0.0,0.0,0.0,
2024-10-21T12:26:43.555879570Z,2024-10-21T12:26:43.555711164Z,10,2,38,C,B,0,233.86,50,130,168406,13148979,233.86,233.91,50,23,1,1,233.81,233.93,2,100,2,1,233.8,233.94,105,23,2,1,233.74,233.95,400,121,1,1,233.7,234.0,1200,17,1,2,233.66,234.02,1,400,1,1,233.58,234.1,505,100,2,1,233.53,234.13,10,400,1,1,233.5,234.17,100,1,1,1,233.45,234.25,15,100,1,1,AAPL,-50.0,-50.0,0.0,0.0,0.0,0.0,0.0,0.0,0.0,0.0,0.0,-0.9940291323062509,
2024-10-21T12:26:43.555892512Z,2024-10-21T12:26:43.555724858Z,10,2,38,A,B,0,233.86,100,130,167654,13148980,233.86,233.91,150,23,2,1,233.81,233.93,2,100,2,1,233.8,233.94,105,23,2,1,233.74,233.95,400,121,1,1,233.7,234.0,1200,17,1,2,233.66,234.02,1,400,1,1,233.58,234.1,505,100,2,1,233.53,234.13,10,400,1,1,233.5,234.17,100,1,1,1,233.45,234.25,15,100,1,1,AAPL,100.0,100.0,0.0,0.0,0.0,0.0,0.0,0.0,0.0,0.0,0.0,1.9880582646125018,
2024-10-21T12:26:43.555904815Z,2024-10-21T12:26:43.555737821Z,10,2,38,T,A,0,233.86,50,130,166994,13148981,233.86,233.91,150,23,2,1,233.81,233.93,2,100,2,1,233.8,233.94,105,23,2,1,233.74,233.95,400,121,1,1,233.7,234.0,1200,17,1,2,233.66,234.02,1,400,1,1,233.58,234.1,505,100,2,1,233.53,234.13,10,400,1,1,233.5,234.17,100,1,1,1,233.45,234.25,15,100,1,1,AAPL,0.0,0.0,0.0,0.0,0.0,0.0,0.0,0.0,0.0,0.0,0.0,0.0,
2024-10-21T12:26:43.555904815Z,2024-10-21T12:26:43.555737821Z,10,2,38,C,B,0,233.86,50,130,166994,13148981,233.86,233.91,100,23,1,1,233.81,233.93,2,100,2,1,233.8,233.94,105,23,2,1,233.74,233.95,400,121,1,1,233.7,234.0,1200,17,1,2,233.66,234.02,1,400,1,1,233.58,234.1,505,100,2,1,233.53,234.13,10,400,1,1,233.5,234.17,100,1,1,1,233.45,234.25,15,100,1,1,AAPL,-50.0,-50.0,0.0,0.0,0.0,0.0,0.0,0.0,0.0,0.0,0.0,-0.9940291323062509,
2024-10-21T12:26:43.555933449Z,2024-10-21T12:26:43.555767270Z,10,2,38,C,B,3,233.74,200,130,166179,13148982,233.86,233.91,100,23,1,1,233.81,233.93,2,100,2,1,233.8,233.94,105,23,2,1,233.74,233.95,200,121,1,1,233.7,234.0,1200,17,1,2,233.66,234.02,1,400,1,1,233.58,234.1,505,100,2,1,233.53,234.13,10,400,1,1,233.5,234.17,100,1,1,1,233.45,234.25,15,100,1,1,AAPL,0.0,0.0,0.0,0.0,-200.0,0.0,0.0,0.0,0.0,0.0,0.0,-41.015411004823704,
2024-10-21T12:26:43.555956286Z,2024-10-21T12:26:43.555789284Z,10,2,38,C,B,3,233.74,200,130,167002,13148983,233.86,233.91,100,23,1,1,233.81,233.93,2,100,2,1,233.8,233.94,105,23,2,1,233.7,233.95,1200,121,1,1,233.66,234.0,1,17,1,2,233.58,234.02,505,400,2,1,233.53,234.1,10,100,1,1,233.5,234.13,100,400,1,1,233.45,234.17,15,1,1,1,233.4,234.25,110,100,2,1,AAPL,0.0,0.0,0.0,0.0,-200.0,-1200.0,-1.0,-505.0,-10.0,-100.0,-15.0,-247.40391167966987,
2024-10-21T12:26:43.556155095Z,2024-10-21T12:26:43.555989102Z,10,2,38,C,A,1,233.93,100,130,165993,13148984,233.86,233.91,100,23,1,1,233.81,233.94,2,23,2,1,233.8,233.95,105,121,2,1,233.7,234.0,1200,17,1,2,233.66,234.02,1,400,1,1,233.58,234.1,505,100,2,1,233.53,234.13,10,400,1,1,233.5,234.17,100,1,1,1,233.45,234.25,15,100,1,1,233.4,234.41,110,500,2,1,AAPL,0.0,0.0,23.0,121.0,17.0,400.0,100.0,400.0,1.0,100.0,500.0,165.7069587911578,
2024-10-21T12:26:43.556502258Z,2024-10-21T12:26:43.556335122Z,10,2,38,C,B,0,233.86,5,130,167136,13148985,233.86,233.91,95,23,1,1,233.81,233.94,2,23,2,1,233.8,233.95,105,121,2,1,233.7,234.0,1200,17,1,2,233.66,234.02,1,400,1,1,233.58,234.1,505,100,2,1,233.53,234.13,10,400,1,1,233.5,234.17,100,1,1,1,233.45,234.25,15,100,1,1,233.4,234.41,110,500,2,1,AAPL,-5.0,-5.0,0.0,0.0,0.0,0.0,0.0,0.0,0.0,0.0,0.0,-0.0994029132306251,
2024-10-21T12:26:43.556502258Z,2024-10-21T12:26:43.556335122Z,10,2,38,T,A,0,233.86,5,130,167136,13148985,233.86,233.91,100,23,1,1,233.81,233.94,2,23,2,1,233.8,233.95,105,121,2,1,233.7,234.0,1200,17,1,2,233.66,234.02,1,400,1,1,233.58,234.1,505,100,2,1,233.53,234.13,10,400,1,1,233.5,234.17,100,1,1,1,233.45,234.25,15,100,1,1,233.4,234.41,110,500,2,1,AAPL,5.0,5.0,0.0,0.0,0.0,0.0,0.0,0.0,0.0,0.0,0.0,0.0994029132306251,
2024-10-21T12:26:43.556510636Z,2024-10-21T12:26:43.556344203Z,10,2,38,A,B,0,233.86,100,130,166433,13148986,233.86,233.91,195,23,2,1,233.81,233.94,2,23,2,1,233.8,233.95,105,121,2,1,233.7,234.0,1200,17,1,2,233.66,234.02,1,400,1,1,233.58,234.1,505,100,2,1,233.53,234.13,10,400,1,1,233.5,234.17,100,1,1,1,233.45,234.25,15,100,1,1,233.4,234.41,110,500,2,1,AAPL,95.0,95.0,0.0,0.0,0.0,0.0,0.0,0.0,0.0,0.0,0.0,1.888655351381877,
2024-10-21T12:26:43.603087151Z,2024-10-21T12:26:43.602920183Z,10,2,38,A,B,3,233.74,200,130,166968,13149063,233.86,233.91,195,23,2,1,233.81,233.94,2,23,2,1,233.8,233.95,105,121,2,1,233.74,234.0,200,17,1,2,233.7,234.02,1200,400,1,1,233.66,234.1,1,100,1,1,233.58,234.13,505,400,2,1,233.53,234.17,10,1,1,1,233.5,234.25,100,100,1,1,233.45,234.41,15,500,1,1,AAPL,0.0,0.0,0.0,0.0,200.0,1200.0,1.0,505.0,10.0,100.0,15.0,247.40391167966987,
2024-10-21T12:26:43.633097364Z,2024-10-21T12:26:43.632931005Z,10,2,38,A,B,3,233.74,200,130,166359,13149078,233.86,233.91,195,23,2,1,233.81,233.94,2,23,2,1,233.8,233.95,105,121,2,1,233.74,234.0,400,17,2,2,233.7,234.02,1200,400,1,1,233.66,234.1,1,100,1,1,233.58,234.13,505,400,2,1,233.53,234.17,10,1,1,1,233.5,234.25,100,100,1,1,233.45,234.41,15,500,1,1,AAPL,0.0,0.0,0.0,0.0,200.0,0.0,0.0,0.0,0.0,0.0,0.0,41.015411004823704,
2024-10-21T12:26:43.663930696Z,2024-10-21T12:26:43.663764676Z,10,2,38,C,A,1,233.94,23,130,166020,13149095,233.86,233.91,195,23,2,1,233.81,233.95,2,121,2,1,233.8,234.0,105,17,2,2,233.74,234.02,400,400,2,1,233.7,234.1,1200,100,1,1,233.66,234.13,1,400,1,1,233.58,234.17,505,1,2,1,233.53,234.25,10,100,1,1,233.5,234.41,100,500,1,1,233.45,234.43,15,105,1,2,AAPL,0.0,0.0,121.0,17.0,400.0,100.0,400.0,1.0,100.0,500.0,105.0,210.5404486638121,
2024-10-21T12:26:43.813930819Z,2024-10-21T12:26:43.813764689Z,10,2,38,C,A,0,233.91,23,130,166130,13149215,233.86,233.95,195,121,2,1,233.81,234.0,2,17,2,2,233.8,234.02,105,400,2,1,233.74,234.1,400,100,2,1,233.7,234.13,1200,400,1,1,233.66,234.17,1,1,1,1,233.58,234.25,505,100,2,1,233.53,234.41,10,500,1,1,233.5,234.43,100,105,1,2,233.45,234.5,15,63,1,4,AAPL,121.0,121.0,17.0,400.0,100.0,400.0,1.0,100.0,500.0,105.0,63.0,185.27877188530823,
2024-10-21T12:26:44.395306900Z,2024-10-21T12:26:44.395140599Z,10,2,38,A,A,1,233.97,7,130,166301,13149756,233.86,233.95,195,121,2,1,233.81,233.97,2,7,2,1,233.8,234.0,105,17,2,2,233.74,234.02,400,400,2,1,233.7,234.1,1200,100,1,1,233.66,234.13,1,400,1,1,233.58,234.17,505,1,2,1,233.53,234.25,10,100,1,1,233.5,234.41,100,500,1,1,233.45,234.43,15,105,1,2,AAPL,0.0,0.0,-17.0,-400.0,-100.0,-400.0,-1.0,-100.0,-500.0,-105.0,-63.0,-182.8732213851271,
2024-10-21T12:26:47.317000869Z,2024-10-21T12:26:47.316834945Z,10,2,38,C,A,3,234.02,400,130,165924,13152409,233.86,233.95,195,121,2,1,233.81,233.97,2,7,2,1,233.8,234.0,105,17,2,2,233.74,234.1,400,100,2,1,233.7,234.13,1200,400,1,1,233.66,234.17,1,1,1,1,233.58,234.25,505,100,2,1,233.53,234.41,10,500,1,1,233.5,234.43,100,105,1,2,233.45,234.5,15,63,1,4,AAPL,0.0,0.0,0.0,0.0,100.0,400.0,1.0,100.0,500.0,105.0,63.0,141.16211432263424,
2024-10-21T12:26:47.317013569Z,2024-10-21T12:26:47.316847348Z,10,2,38,A,A,3,234.04,400,130,166221,13152410,233.86,233.95,195,121,2,1,233.81,233.97,2,7,2,1,233.8,234.0,105,17,2,2,233.74,234.04,400,400,2,1,233.7,234.1,1200,100,1,1,233.66,234.13,1,400,1,1,233.58,234.17,505,1,2,1,233.53,234.25,10,100,1,1,233.5,234.41,100,500,1,1,233.45,234.43,15,105,1,2,AAPL,0.0,0.0,0.0,0.0,-100.0,-400.0,-1.0,-100.0,-500.0,-105.0,-63.0,-141.16211432263424,
2024-10-21T12:26:47.371614290Z,2024-10-21T12:26:47.371448271Z,10,2,38,C,B,3,233.74,200,130,166019,13152673,233.86,233.95,195,121,2,1,233.81,233.97,2,7,2,1,233.8,234.0,105,17,2,2,233.74,234.04,200,400,1,1,233.7,234.1,1200,100,1,1,233.66,234.13,1,400,1,1,233.58,234.17,505,1,2,1,233.53,234.25,10,100,1,1,233.5,234.41,100,500,1,1,233.45,234.43,15,105,1,2,AAPL,0.0,0.0,0.0,0.0,-200.0,0.0,0.0,0.0,0.0,0.0,0.0,-41.015411004823704,
2024-10-21T12:26:47.371627679Z,2024-10-21T12:26:47.371461367Z,10,2,38,A,B,3,233.76,400,130,166312,13152674,233.86,233.95,195,121,2,1,233.81,233.97,2,7,2,1,233.8,234.0,105,17,2,2,233.76,234.04,400,400,1,1,233.7,234.1,1200,100,1,1,233.66,234.13,1,400,1,1,233.58,234.17,505,1,2,1,233.53,234.25,10,100,1,1,233.5,234.41,100,500,1,1,233.45,234.43,15,105,1,2,AAPL,0.0,0.0,0.0,0.0,400.0,0.0,0.0,0.0,0.0,0.0,0.0,82.03082200964741,
2024-10-21T12:26:53.381817361Z,2024-10-21T12:26:53.381650546Z,10,2,38,A,B,3,233.77,400,130,166815,13157627,233.86,233.95,195,121,2,1,233.81,233.97,2,7,2,1,233.8,234.0,105,17,2,2,233.77,234.04,400,400,1,1,233.7,234.1,1200,100,1,1,233.66,234.13,1,400,1,1,233.58,234.17,505,1,2,1,233.53,234.25,10,100,1,1,233.5,234.41,100,500,1,1,233.45,234.43,15,105,1,2,AAPL,0.0,0.0,0.0,0.0,400.0,0.0,0.0,0.0,0.0,0.0,0.0,82.03082200964741,
2024-10-21T12:26:54.545889324Z,2024-10-21T12:26:54.545723322Z,10,2,38,C,B,3,233.77,400,130,166002,13158660,233.86,233.95,195,121,2,1,233.81,233.97,2,7,2,1,233.8,234.0,105,17,2,2,233.7,234.04,1200,400,1,1,233.66,234.1,1,100,1,1,233.58,234.13,505,400,2,1,233.53,234.17,10,1,1,1,233.5,234.25,100,100,1,1,233.45,234.41,15,500,1,1,233.4,234.43,110,105,2,2,AAPL,0.0,0.0,0.0,0.0,-400.0,-1200.0,-1.0,-505.0,-10.0,-100.0,-15.0,-288.4193226844936,
2024-10-21T12:26:54.545901500Z,2024-10-21T12:26:54.545735230Z,10,2,38,A,B,3,233.76,400,130,166270,13158661,233.86,233.95,195,121,2,1,233.81,233.97,2,7,2,1,233.8,234.0,105,17,2,2,233.76,234.04,400,400,1,1,233.7,234.1,1200,100,1,1,233.66,234.13,1,400,1,1,233.58,234.17,505,1,2,1,233.53,234.25,10,100,1,1,233.5,234.41,100,500,1,1,233.45,234.43,15,105,1,2,AAPL,0.0,0.0,0.0,0.0,400.0,1200.0,1.0,505.0,10.0,100.0,15.0,288.4193226844936,
2024-10-21T12:27:04.677969002Z,2024-10-21T12:27:04.677802802Z,10,2,38,A,B,3,233.77,400,130,166200,13168438,233.86,233.95,195,121,2,1,233.81,233.97,2,7,2,1,233.8,234.0,105,17,2,2,233.77,234.04,400,400,1,1,233.7,234.1,1200,100,1,1,233.66,234.13,1,400,1,1,233.58,234.17,505,1,2,1,233.53,234.25,10,100,1,1,233.5,234.41,100,500,1,1,233.45,234.43,15,105,1,2,AAPL,0.0,0.0,0.0,0.0,400.0,0.0,0.0,0.0,0.0,0.0,0.0,82.03082200964741,
2024-10-21T12:27:04.858352610Z,2024-10-21T12:27:04.858186427Z,10,2,38,C,B,3,233.77,200,130,166183,13168809,233.86,233.95,195,121,2,1,233.81,233.97,2,7,2,1,233.8,234.0,105,17,2,2,233.77,234.04,200,400,1,1,233.7,234.1,1200,100,1,1,233.66,234.13,1,400,1,1,233.58,234.17,505,1,2,1,233.53,234.25,10,100,1,1,233.5,234.41,100,500,1,1,233.45,234.43,15,105,1,2,AAPL,0.0,0.0,0.0,0.0,-200.0,0.0,0.0,0.0,0.0,0.0,0.0,-41.015411004823704,
2024-10-21T12:27:08.140351417Z,2024-10-21T12:27:08.140184917Z,10,2,38,A,B,0,233.86,100,130,166500,13171896,233.86,233.95,295,121,3,1,233.81,233.97,2,7,2,1,233.8,234.0,105,17,2,2,233.77,234.04,200,400,1,1,233.7,234.1,1200,100,1,1,233.66,234.13,1,400,1,1,233.58,234.17,505,1,2,1,233.53,234.25,10,100,1,1,233.5,234.41,100,500,1,1,233.45,234.43,15,105,1,2,AAPL,100.0,100.0,0.0,0.0,0.0,0.0,0.0,0.0,0.0,0.0,0.0,1.9880582646125018,
2024-10-21T12:27:08.267404175Z,2024-10-21T12:27:08.267237597Z,10,2,38,A,A,2,233.99,200,130,166578,13172040,233.86,233.95,295,121,3,1,233.81,233.97,2,7,2,1,233.8,233.99,105,200,2,1,233.77,234.0,200,17,1,2,233.7,234.1,1200,100,1,1,233.66,234.13,1,400,1,1,233.58,234.17,505,1,2,1,233.53,234.25,10,100,1,1,233.5,234.41,100,500,1,1,233.45,234.43,15,105,1,2,AAPL,0.0,0.0,0.0,-17.0,-400.0,0.0,0.0,0.0,0.0,0.0,0.0,-83.75772588215949,
2024-10-21T12:27:08.904013328Z,2024-10-21T12:27:08.903847050Z,10,2,38,A,B,3,233.77,200,130,166278,13172666,233.86,233.95,295,121,3,1,233.81,233.97,2,7,2,1,233.8,233.99,105,200,2,1,233.77,234.0,400,17,2,2,233.7,234.1,1200,100,1,1,233.66,234.13,1,400,1,1,233.58,234.17,505,1,2,1,233.53,234.25,10,100,1,1,233.5,234.41,100,500,1,1,233.45,234.43,15,105,1,2,AAPL,0.0,0.0,0.0,0.0,200.0,0.0,0.0,0.0,0.0,0.0,0.0,41.015411004823704,
2024-10-21T12:27:15.211190007Z,2024-10-21T12:27:15.211023662Z,10,2,38,C,A,1,233.97,7,130,166345,13177973,233.86,233.95,295,121,3,1,233.81,233.99,2,200,2,1,233.8,234.0,105,17,2,2,233.77,234.1,400,100,2,1,233.7,234.13,1200,400,1,1,233.66,234.17,1,1,1,1,233.58,234.25,505,100,2,1,233.53,234.41,10,500,1,1,233.5,234.43,100,105,1,2,233.45,234.5,15,63,1,4,AAPL,0.0,0.0,200.0,17.0,100.0,400.0,1.0,100.0,500.0,105.0,63.0,155.57225076092024,
2024-10-21T12:27:16.357351976Z,2024-10-21T12:27:16.357185731Z,10,2,38,C,A,0,233.95,121,130,166245,13178747,233.86,233.99,295,200,3,1,233.81,234.0,2,17,2,2,233.8,234.1,105,100,2,1,233.77,234.13,400,400,2,1,233.7,234.17,1200,1,1,1,233.66,234.25,1,100,1,1,233.58,234.41,505,500,2,1,233.53,234.43,10,105,1,2,233.5,234.5,100,63,1,4,233.45,234.59,15,60,1,1,AAPL,200.0,200.0,17.0,100.0,400.0,1.0,100.0,500.0,105.0,63.0,60.0,187.4291293484128,
2024-10-21T12:27:16.384048756Z,2024-10-21T12:27:16.383880298Z,10,2,38,T,N,0,233.87,50,0,168458,13178752,233.86,233.99,295,200,3,1,233.81,234.0,2,17,2,2,233.8,234.1,105,100,2,1,233.77,234.13,400,400,2,1,233.7,234.17,1200,1,1,1,233.66,234.25,1,100,1,1,233.58,234.41,505,500,2,1,233.53,234.43,10,105,1,2,233.5,234.5,100,63,1,4,233.45,234.59,15,60,1,1,AAPL,0.0,0.0,0.0,0.0,0.0,0.0,0.0,0.0,0.0,0.0,0.0,0.0,
2024-10-21T12:27:16.384048756Z,2024-10-21T12:27:16.383880298Z,10,2,38,T,N,0,233.87,71,130,168458,13178753,233.86,233.99,295,200,3,1,233.81,234.0,2,17,2,2,233.8,234.1,105,100,2,1,233.77,234.13,400,400,2,1,233.7,234.17,1200,1,1,1,233.66,234.25,1,100,1,1,233.58,234.41,505,500,2,1,233.53,234.43,10,105,1,2,233.5,234.5,100,63,1,4,233.45,234.59,15,60,1,1,AAPL,0.0,0.0,0.0,0.0,0.0,0.0,0.0,0.0,0.0,0.0,0.0,0.0,
2024-10-21T12:27:17.218399628Z,2024-10-21T12:27:17.218233083Z,10,2,38,A,A,0,233.98,7,130,166545,13179063,233.86,233.98,295,7,3,1,233.81,233.99,2,200,2,1,233.8,234.0,105,17,2,2,233.77,234.1,400,100,2,1,233.7,234.13,1200,400,1,1,233.66,234.17,1,1,1,1,233.58,234.25,505,100,2,1,233.53,234.41,10,500,1,1,233.5,234.43,100,105,1,2,233.45,234.5,15,63,1,4,AAPL,-200.0,-200.0,-17.0,-100.0,-400.0,-1.0,-100.0,-500.0,-105.0,-63.0,-60.0,-187.4291293484128,
2024-10-21T12:27:21.556157771Z,2024-10-21T12:27:21.555991612Z,10,2,38,C,B,3,233.77,200,130,166159,13183172,233.86,233.98,295,7,3,1,233.81,233.99,2,200,2,1,233.8,234.0,105,17,2,2,233.77,234.1,200,100,1,1,233.7,234.13,1200,400,1,1,233.66,234.17,1,1,1,1,233.58,234.25,505,100,2,1,233.53,234.41,10,500,1,1,233.5,234.43,100,105,1,2,233.45,234.5,15,63,1,4,AAPL,0.0,0.0,0.0,0.0,-200.0,0.0,0.0,0.0,0.0,0.0,0.0,-41.015411004823704,
2024-10-21T12:27:21.556172659Z,2024-10-21T12:27:21.556005910Z,10,2,38,A,B,1,233.81,200,130,166749,13183173,233.86,233.98,295,7,3,1,233.81,233.99,202,200,3,1,233.8,234.0,105,17,2,2,233.7,234.1,1200,100,1,1,233.66,234.13,1,400,1,1,233.58,234.17,505,1,2,1,233.53,234.25,10,100,1,1,233.5,234.41,100,500,1,1,233.45,234.43,15,105,1,2,233.4,234.5,110,63,2,4,AAPL,0.0,0.0,200.0,0.0,-200.0,-1200.0,-1.0,-505.0,-10.0,-100.0,-15.0,-234.72067911389595,
2024-10-21T12:27:21.983295309Z,2024-10-21T12:27:21.983129451Z,10,2,38,C,B,1,233.81,200,130,165858,13183374,233.86,233.98,295,7,3,1,233.81,233.99,2,200,2,1,233.8,234.0,105,17,2,2,233.7,234.1,1200,100,1,1,233.66,234.13,1,400,1,1,233.58,234.17,505,1,2,1,233.53,234.25,10,100,1,1,233.5,234.41,100,500,1,1,233.45,234.43,15,105,1,2,233.4,234.5,110,63,2,4,AAPL,0.0,0.0,-200.0,0.0,0.0,0.0,0.0,0.0,0.0,0.0,0.0,-12.683232565773917,
2024-10-21T12:27:21.983308878Z,2024-10-21T12:27:21.983142748Z,10,2,38,A,B,3,233.77,400,130,166130,13183375,233.86,233.98,295,7,3,1,233.81,233.99,2,200,2,1,233.8,234.0,105,17,2,2,233.77,234.1,400,100,1,1,233.7,234.13,1200,400,1,1,233.66,234.17,1,1,1,1,233.58,234.25,505,100,2,1,233.53,234.41,10,500,1,1,233.5,234.43,100,105,1,2,233.45,234.5,15,63,1,4,AAPL,0.0,0.0,0.0,0.0,400.0,1200.0,1.0,505.0,10.0,100.0,15.0,288.4193226844936,
